
#######################################################################
# +-----------------------------------------------------------------+ #
# |                            BO3 object                           | #
# +-----------------------------------------------------------------+ #
#######################################################################

# This is the config file of a custom object.
# If you add this object correctly to your BiomeConfigs, it will spawn in the world.

# This is the creator of this BO3 object
# See: https://imgur.com/a/JanPA
Author: Arcensoth, designed by McNoodlor

# A short description of this BO3 object
Description: No description given

# The BO3 version, don't change this! It can be used by external applications to do a version check.
Version: 3

# The settings mode, WriteAll, WriteWithoutComments or WriteDisable. See WorldConfig.
SettingsMode: WriteDisable


#######################################################################
# +-----------------------------------------------------------------+ #
# |                          Main settings                          | #
# +-----------------------------------------------------------------+ #
#######################################################################

# This needs to be set to true to spawn the object in the Tree and Sapling resources.
Tree: false

# The frequency of the BO3 from 1 to 200. Tries this many times to spawn this BO3 when using the CustomObject(...) resource.
# Ignored by Tree(..), Sapling(..) and CustomStructure(..)
Frequency: 1

# The rarity of the BO3 from 0 to 100. Each spawn attempt has rarity% chance to succeed when using the CustomObject(...) resource.
# Ignored by Tree(..), Sapling(..) and CustomStructure(..)
Rarity: 1.0

# If you set this to true, the BO3 will be placed with a random rotation.
RotateRandomly: false

# The spawn height of the BO3 - randomY, highestBlock or highestSolidBlock.
SpawnHeight: randomY

# The height limits for the BO3.
MinHeight: 0

MaxHeight: 255

# Objects can have other objects attacthed to it: branches. Branches can also
# have branches attached to it, which can also have branches, etc. This is the
# maximum branch depth for this objects.
MaxBranchDepth: 10

# When spawned with the UseWorld keyword, this BO3 should NOT spawn in the following biomes.
# If you writer.write the BO3 name directly in the BiomeConfigs, this will be ignored.
ExcludedBiomes: All


#######################################################################
# +-----------------------------------------------------------------+ #
# |                      Source block settings                      | #
# +-----------------------------------------------------------------+ #
#######################################################################

# The B(s) the BO3 should spawn in.
SourceBlocks: STONE,STONE:1,STONE:3,STONE:5,COBBLESTONE,MOSSY_COBBLESTONE,SANDSTONE,HARD_CLAY,STAINED_CLAY,PRISMARINE,DIRT,DIRT:1,GRASS,SAND,GRAVEL,CLAY,OBSIDIAN,COAL_ORE,IRON_ORE,GOLD_ORE,REDSTONE_ORE,DIAMOND_ORE,LAPIS_ORE,EMERALD_ORE,STATIONARY_WATER,STATIONARY_LAVA

# The maximum percentage of the BO3 that can be outside the SourceBlock.
# The BO3 won't be placed on a location with more blocks outside the SourceBlock than this percentage.
MaxPercentageOutsideSourceBlock: 45

# What to do when a block is about to be placed outside the SourceBlock? (dontPlace, placeAnyway)
OutsideSourceBlock: dontPlace


#######################################################################
# +-----------------------------------------------------------------+ #
# |                              Blocks                             | #
# +-----------------------------------------------------------------+ #
#######################################################################

# All the blocks used in the BO3 are listed here. Possible blocks:
# B(x,y,z,id[.data][,nbtfile.nbt)
# RB(x,y,z,id[:data][,nbtfile.nbt],chance[,id[:data][,nbtfile.nbt],chance[,...]])
# So RB(0,0,0,CHEST,chest.nbt,50,CHEST,anotherchest.nbt,100) will spawn a chest at
# the BO3 origin, and give it a 50% chance to have the contents of chest.nbt, or, if that
# fails, a 100% percent chance to have the contents of anotherchest.nbt.
B(0,0,0,STONEBRICK)
B(1,0,0,STONEBRICK)
B(2,0,0,STONEBRICK:1)
B(3,0,0,STONEBRICK:2)
B(4,0,0,STONEBRICK)
B(5,0,0,STONEBRICK)
B(6,0,0,STONEBRICK:1)
B(7,0,0,STONEBRICK)
B(8,0,0,STONEBRICK:1)
B(0,1,0,STONEBRICK)
B(1,1,0,STONE)
B(2,1,0,MOSSY_COBBLESTONE)
B(3,1,0,STONEBRICK)
B(5,1,0,STONEBRICK:2)
B(6,1,0,MOSSY_COBBLESTONE)
B(7,1,0,STONE)
B(8,1,0,STONEBRICK)
B(0,2,0,STONEBRICK:2)
B(1,2,0,MOSSY_COBBLESTONE)
B(2,2,0,STONE)
B(3,2,0,STONEBRICK:1)
B(5,2,0,STONEBRICK)
B(6,2,0,STONE)
B(7,2,0,MOSSY_COBBLESTONE)
B(8,2,0,STONEBRICK)
B(0,3,0,STONEBRICK:1)
B(1,3,0,STONE)
B(2,3,0,MOSSY_COBBLESTONE)
B(3,3,0,STONEBRICK:2)
B(5,3,0,STONEBRICK:2)
B(6,3,0,EMERALD_ORE)
B(7,3,0,MOSSY_COBBLESTONE)
B(8,3,0,STONEBRICK)
B(0,4,0,STONEBRICK)
B(1,4,0,STONE)
B(2,4,0,MOSSY_COBBLESTONE)
B(3,4,0,STONEBRICK:1)
B(4,4,0,STONEBRICK:1)
B(5,4,0,STONEBRICK:1)
B(6,4,0,MOSSY_COBBLESTONE)
B(7,4,0,STONE)
B(8,4,0,STONEBRICK:1)
B(0,5,0,STONEBRICK:1)
B(1,5,0,MOSSY_COBBLESTONE)
B(2,5,0,STONE)
B(3,5,0,EMERALD_ORE)
B(4,5,0,STONE)
B(5,5,0,MOSSY_COBBLESTONE)
B(6,5,0,STONE)
B(7,5,0,MOSSY_COBBLESTONE)
B(8,5,0,STONEBRICK)
B(0,6,0,STONEBRICK)
B(1,6,0,MOSSY_COBBLESTONE)
B(2,6,0,STONE)
B(3,6,0,STONE)
B(4,6,0,MOSSY_COBBLESTONE)
B(5,6,0,MOSSY_COBBLESTONE)
B(6,6,0,MOSSY_COBBLESTONE)
B(7,6,0,STONE)
B(8,6,0,STONEBRICK:1)
B(0,7,0,STONEBRICK)
B(1,7,0,MOSSY_COBBLESTONE)
B(2,7,0,STONE)
B(3,7,0,MOSSY_COBBLESTONE)
B(4,7,0,STONE)
B(5,7,0,STONE)
B(6,7,0,STONE)
B(7,7,0,STONE)
B(8,7,0,STONEBRICK)
B(0,8,0,STONEBRICK:1)
B(1,8,0,STONEBRICK:2)
B(2,8,0,STONEBRICK:2)
B(3,8,0,STONEBRICK:1)
B(4,8,0,STONEBRICK:2)
B(5,8,0,STONEBRICK:2)
B(6,8,0,STONEBRICK)
B(7,8,0,STONEBRICK:1)
B(8,8,0,STONEBRICK)
B(0,16,0,STONEBRICK:2)
B(1,16,0,STONEBRICK)
B(2,16,0,STONEBRICK:1)
B(3,16,0,STONEBRICK)
B(4,16,0,STONEBRICK:1)
B(5,16,0,STONEBRICK:2)
B(6,16,0,STONEBRICK)
B(7,16,0,STONEBRICK:1)
B(8,16,0,STONEBRICK)
B(0,17,0,STONEBRICK:2)
B(1,17,0,STONE)
B(2,17,0,STONE)
B(3,17,0,STONE)
B(4,17,0,EMERALD_ORE)
B(5,17,0,STONE)
B(6,17,0,STONE)
B(7,17,0,STONE)
B(8,17,0,STONEBRICK:1)
B(0,18,0,STONEBRICK:2)
B(1,18,0,MOSSY_COBBLESTONE)
B(2,18,0,MOSSY_COBBLESTONE)
B(3,18,0,MOSSY_COBBLESTONE)
B(4,18,0,MOSSY_COBBLESTONE)
B(5,18,0,MOSSY_COBBLESTONE)
B(6,18,0,STONE)
B(7,18,0,STONE)
B(8,18,0,STONEBRICK:1)
B(0,19,0,STONEBRICK:1)
B(1,19,0,MOSSY_COBBLESTONE)
B(2,19,0,MOSSY_COBBLESTONE)
B(3,19,0,MOSSY_COBBLESTONE)
B(4,19,0,MOSSY_COBBLESTONE)
B(5,19,0,STONE)
B(6,19,0,MOSSY_COBBLESTONE)
B(7,19,0,STONE)
B(8,19,0,STONEBRICK:1)
B(0,20,0,STONEBRICK:1)
B(1,20,0,MOSSY_COBBLESTONE)
B(2,20,0,MOSSY_COBBLESTONE)
B(3,20,0,MOSSY_COBBLESTONE)
B(4,20,0,MOSSY_COBBLESTONE)
B(5,20,0,MOSSY_COBBLESTONE)
B(6,20,0,MOSSY_COBBLESTONE)
B(7,20,0,STONE)
B(8,20,0,STONEBRICK)
B(0,21,0,STONEBRICK)
B(1,21,0,MOSSY_COBBLESTONE)
B(2,21,0,STONE)
B(3,21,0,MOSSY_COBBLESTONE)
B(4,21,0,STONE)
B(5,21,0,STONE)
B(6,21,0,EMERALD_ORE)
B(7,21,0,STONE)
B(8,21,0,STONEBRICK)
B(0,22,0,STONEBRICK:2)
B(1,22,0,MOSSY_COBBLESTONE)
B(2,22,0,MOSSY_COBBLESTONE)
B(3,22,0,STONE)
B(4,22,0,STONE)
B(5,22,0,STONE)
B(6,22,0,MOSSY_COBBLESTONE)
B(7,22,0,MOSSY_COBBLESTONE)
B(8,22,0,STONEBRICK:2)
B(0,23,0,STONEBRICK)
B(1,23,0,EMERALD_ORE)
B(2,23,0,MOSSY_COBBLESTONE)
B(3,23,0,MOSSY_COBBLESTONE)
B(4,23,0,MOSSY_COBBLESTONE)
B(5,23,0,MOSSY_COBBLESTONE)
B(6,23,0,STONE)
B(7,23,0,MOSSY_COBBLESTONE)
B(8,23,0,STONEBRICK:1)
B(0,24,0,STONEBRICK)
B(1,24,0,STONEBRICK:2)
B(2,24,0,STONEBRICK:1)
B(3,24,0,STONEBRICK)
B(4,24,0,STONEBRICK:2)
B(5,24,0,STONEBRICK:1)
B(6,24,0,STONEBRICK:1)
B(7,24,0,STONEBRICK:2)
B(8,24,0,STONEBRICK)
B(0,0,1,STONEBRICK)
B(1,0,1,STONEBRICK:2)
B(2,0,1,STONEBRICK:1)
B(3,0,1,STONEBRICK:2)
B(4,0,1,STONEBRICK)
B(5,0,1,STONEBRICK:1)
B(6,0,1,STONEBRICK:2)
B(7,0,1,STONEBRICK)
B(8,0,1,STONEBRICK)
B(0,1,1,MOSSY_COBBLESTONE)
B(1,1,1,STONE)
B(7,1,1,STONE)
B(8,1,1,STONE)
B(0,2,1,MOSSY_COBBLESTONE)
B(1,2,1,STONE)
B(7,2,1,MOSSY_COBBLESTONE)
B(8,2,1,STONE)
B(0,3,1,STONE)
B(1,3,1,STONE)
B(7,3,1,MOSSY_COBBLESTONE)
B(8,3,1,MOSSY_COBBLESTONE)
B(0,4,1,STONE)
B(1,4,1,STONEBRICK:2)
B(7,4,1,STONEBRICK:1)
B(8,4,1,STONE)
B(0,5,1,MOSSY_COBBLESTONE)
B(1,5,1,STONEBRICK)
B(7,5,1,STONEBRICK)
B(8,5,1,MOSSY_COBBLESTONE)
B(0,6,1,STONE)
B(1,6,1,STONEBRICK:2)
B(7,6,1,STONEBRICK)
B(8,6,1,STONE)
B(0,7,1,STONE)
B(1,7,1,STONEBRICK:2)
B(2,7,1,STONEBRICK:1)
B(3,7,1,STONEBRICK:2)
B(4,7,1,STONEBRICK:2)
B(5,7,1,STONEBRICK:2)
B(6,7,1,STONEBRICK:2)
B(7,7,1,STONEBRICK:2)
B(8,7,1,STONE)
B(0,8,1,STONEBRICK:1)
B(1,8,1,MOSSY_COBBLESTONE)
B(2,8,1,EMERALD_ORE)
B(3,8,1,STONE)
B(4,8,1,MOSSY_COBBLESTONE)
B(5,8,1,MOSSY_COBBLESTONE)
B(6,8,1,STONE)
B(7,8,1,STONE)
B(8,8,1,STONEBRICK)
B(0,16,1,STONEBRICK:2)
B(1,16,1,MOSSY_COBBLESTONE)
B(2,16,1,STONE)
B(3,16,1,MOSSY_COBBLESTONE)
B(4,16,1,MOSSY_COBBLESTONE)
B(5,16,1,STONE)
B(6,16,1,MOSSY_COBBLESTONE)
B(7,16,1,EMERALD_ORE)
B(8,16,1,STONEBRICK)
B(0,17,1,STONE)
B(1,17,1,STONE)
B(7,17,1,MOSSY_COBBLESTONE)
B(8,17,1,STONE)
B(0,18,1,STONE)
B(1,18,1,STONE)
B(7,18,1,MOSSY_COBBLESTONE)
B(8,18,1,STONE)
B(0,19,1,STONE)
B(1,19,1,MOSSY_COBBLESTONE)
B(7,19,1,MOSSY_COBBLESTONE)
B(8,19,1,MOSSY_COBBLESTONE)
B(0,20,1,STONE)
B(1,20,1,STONEBRICK:1)
B(7,20,1,STONEBRICK:1)
B(8,20,1,STONE)
B(0,21,1,MOSSY_COBBLESTONE)
B(1,21,1,STONEBRICK:1)
B(7,21,1,STONEBRICK:1)
B(8,21,1,MOSSY_COBBLESTONE)
B(0,22,1,STONE)
B(1,22,1,STONEBRICK:1)
B(7,22,1,STONEBRICK)
B(8,22,1,STONE)
B(0,23,1,MOSSY_COBBLESTONE)
B(1,23,1,STONEBRICK:1)
B(2,23,1,STONEBRICK:1)
B(3,23,1,STONEBRICK)
B(4,23,1,STONEBRICK:2)
B(5,23,1,STONEBRICK)
B(6,23,1,STONEBRICK:1)
B(7,23,1,STONEBRICK)
B(8,23,1,STONE)
B(0,24,1,STONEBRICK)
B(1,24,1,MOSSY_COBBLESTONE)
B(2,24,1,MOSSY_COBBLESTONE)
B(3,24,1,MOSSY_COBBLESTONE)
B(4,24,1,STONE)
B(5,24,1,STONE)
B(6,24,1,MOSSY_COBBLESTONE)
B(7,24,1,MOSSY_COBBLESTONE)
B(8,24,1,STONEBRICK:2)
B(0,0,2,STONEBRICK:2)
B(1,0,2,STONEBRICK:2)
B(2,0,2,STONEBRICK:2)
B(3,0,2,STONEBRICK:2)
B(4,0,2,STONEBRICK)
B(5,0,2,STONEBRICK)
B(6,0,2,STONEBRICK)
B(7,0,2,STONEBRICK)
B(8,0,2,STONEBRICK:1)
B(0,1,2,MOSSY_COBBLESTONE)
B(8,1,2,EMERALD_ORE)
B(0,2,2,STONE)
B(8,2,2,MOSSY_COBBLESTONE)
B(0,3,2,STONE)
B(8,3,2,STONE)
B(0,4,2,MOSSY_COBBLESTONE)
B(8,4,2,EMERALD_ORE)
B(0,5,2,STONE)
B(8,5,2,MOSSY_COBBLESTONE)
B(0,6,2,MOSSY_COBBLESTONE)
B(8,6,2,STONE)
B(0,7,2,MOSSY_COBBLESTONE)
B(1,7,2,STONEBRICK:1)
B(7,7,2,STONEBRICK:1)
B(8,7,2,STONE)
B(0,8,2,STONEBRICK)
B(1,8,2,MOSSY_COBBLESTONE)
B(2,8,2,STONEBRICK)
B(3,8,2,STONEBRICK:1)
B(4,8,2,STONEBRICK)
B(5,8,2,STONEBRICK)
B(6,8,2,STONEBRICK:1)
B(7,8,2,MOSSY_COBBLESTONE)
B(8,8,2,STONEBRICK:1)
B(2,9,2,STONEBRICK:1)
B(3,9,2,MOSSY_COBBLESTONE)
B(4,9,2,EMERALD_ORE)
B(5,9,2,STONE)
B(6,9,2,STONEBRICK:1)
B(2,10,2,STONEBRICK:1)
B(3,10,2,STONE)
B(4,10,2,STONE)
B(5,10,2,MOSSY_COBBLESTONE)
B(6,10,2,STONEBRICK)
B(2,11,2,STONEBRICK)
B(3,11,2,STONE)
B(4,11,2,STONE)
B(5,11,2,MOSSY_COBBLESTONE)
B(6,11,2,STONEBRICK:1)
B(2,12,2,STONEBRICK)
B(3,12,2,STONE)
B(4,12,2,STONE)
B(5,12,2,MOSSY_COBBLESTONE)
B(6,12,2,STONEBRICK)
B(2,13,2,STONEBRICK:2)
B(3,13,2,STONE)
B(4,13,2,MOSSY_COBBLESTONE)
B(5,13,2,MOSSY_COBBLESTONE)
B(6,13,2,STONEBRICK)
B(2,14,2,STONEBRICK)
B(3,14,2,EMERALD_ORE)
B(4,14,2,STONE)
B(5,14,2,MOSSY_COBBLESTONE)
B(6,14,2,STONEBRICK:2)
B(2,15,2,STONEBRICK:1)
B(3,15,2,STONE)
B(4,15,2,MOSSY_COBBLESTONE)
B(5,15,2,MOSSY_COBBLESTONE)
B(6,15,2,STONEBRICK:1)
B(0,16,2,STONEBRICK)
B(1,16,2,STONE)
B(2,16,2,STONEBRICK:1)
B(3,16,2,STONEBRICK)
B(4,16,2,STONEBRICK)
B(5,16,2,STONEBRICK)
B(6,16,2,STONEBRICK:1)
B(7,16,2,MOSSY_COBBLESTONE)
B(8,16,2,STONEBRICK:1)
B(0,17,2,STONE)
B(8,17,2,MOSSY_COBBLESTONE)
B(0,18,2,MOSSY_COBBLESTONE)
B(8,18,2,STONE)
B(0,19,2,EMERALD_ORE)
B(8,19,2,EMERALD_ORE)
B(0,20,2,STONE)
B(8,20,2,STONE)
B(0,21,2,MOSSY_COBBLESTONE)
B(8,21,2,STONE)
B(0,22,2,STONE)
B(8,22,2,STONE)
B(0,23,2,STONE)
B(1,23,2,STONEBRICK:1)
B(7,23,2,STONEBRICK:1)
B(8,23,2,MOSSY_COBBLESTONE)
B(0,24,2,STONEBRICK:2)
B(1,24,2,MOSSY_COBBLESTONE)
B(2,24,2,STONEBRICK:1)
B(3,24,2,STONEBRICK:2)
B(4,24,2,STONEBRICK:2)
B(5,24,2,STONEBRICK:1)
B(6,24,2,STONEBRICK:1)
B(7,24,2,STONE)
B(8,24,2,STONEBRICK:1)
B(0,0,3,STONEBRICK:2)
B(1,0,3,STONEBRICK:1)
B(2,0,3,STONEBRICK:1)
B(3,0,3,GRASS)
B(4,0,3,GRASS)
B(5,0,3,DIRT:1)
B(6,0,3,STONEBRICK:2)
B(7,0,3,STONEBRICK:1)
B(8,0,3,STONEBRICK:2)
B(0,1,3,EMERALD_ORE)
B(8,1,3,STONE)
B(0,2,3,STONE)
B(8,2,3,STONE)
B(0,3,3,EMERALD_ORE)
B(8,3,3,STONE)
B(0,4,3,MOSSY_COBBLESTONE)
B(8,4,3,MOSSY_COBBLESTONE)
B(0,5,3,STONE)
B(8,5,3,STONE)
B(0,6,3,STONE)
B(8,6,3,MOSSY_COBBLESTONE)
B(0,7,3,STONE)
B(1,7,3,STONEBRICK:2)
B(7,7,3,STONEBRICK:2)
B(8,7,3,STONE)
B(0,8,3,STONEBRICK)
B(1,8,3,MOSSY_COBBLESTONE)
B(2,8,3,STONEBRICK:1)
B(6,8,3,STONEBRICK:1)
B(7,8,3,STONE)
B(8,8,3,STONEBRICK:2)
B(2,9,3,MOSSY_COBBLESTONE)
B(6,9,3,EMERALD_ORE)
B(2,10,3,STONE)
B(6,10,3,STONE)
B(2,11,3,STONE)
B(6,11,3,MOSSY_COBBLESTONE)
B(2,12,3,STONE)
B(6,12,3,MOSSY_COBBLESTONE)
B(2,13,3,MOSSY_COBBLESTONE)
B(6,13,3,STONE)
B(2,14,3,MOSSY_COBBLESTONE)
B(6,14,3,STONE)
B(2,15,3,MOSSY_COBBLESTONE)
B(6,15,3,STONE)
B(0,16,3,STONEBRICK:2)
B(1,16,3,MOSSY_COBBLESTONE)
B(2,16,3,STONEBRICK)
B(6,16,3,STONEBRICK:2)
B(7,16,3,STONE)
B(8,16,3,STONEBRICK:2)
B(0,17,3,STONEBRICK:1)
B(8,17,3,STONEBRICK:2)
B(0,18,3,STONEBRICK:1)
B(8,18,3,STONEBRICK)
B(0,19,3,STONEBRICK)
B(8,19,3,STONEBRICK)
B(0,20,3,STONEBRICK:2)
B(8,20,3,STONEBRICK:2)
B(0,21,3,STONE)
B(8,21,3,STONE)
B(0,22,3,MOSSY_COBBLESTONE)
B(8,22,3,MOSSY_COBBLESTONE)
B(0,23,3,EMERALD_ORE)
B(1,23,3,STONEBRICK:2)
B(7,23,3,STONEBRICK)
B(8,23,3,MOSSY_COBBLESTONE)
B(0,24,3,STONEBRICK:1)
B(1,24,3,STONE)
B(2,24,3,STONEBRICK:2)
B(6,24,3,STONEBRICK:1)
B(7,24,3,EMERALD_ORE)
B(8,24,3,STONEBRICK)
B(0,0,4,STONEBRICK:2)
B(1,0,4,STONEBRICK)
B(2,0,4,STONEBRICK:2)
B(3,0,4,DIRT:1)
B(4,0,4,GRASS)
B(5,0,4,DIRT:1)
B(6,0,4,STONEBRICK)
B(7,0,4,STONEBRICK:1)
B(8,0,4,STONEBRICK:2)
B(0,1,4,STONE)
B(8,1,4,MOSSY_COBBLESTONE)
B(0,2,4,STONE)
B(8,2,4,STONE)
B(0,3,4,STONE)
B(8,3,4,EMERALD_ORE)
B(0,4,4,MOSSY_COBBLESTONE)
B(8,4,4,STONE)
B(0,5,4,MOSSY_COBBLESTONE)
B(8,5,4,STONE)
B(0,6,4,MOSSY_COBBLESTONE)
B(8,6,4,STONE)
B(0,7,4,MOSSY_COBBLESTONE)
B(1,7,4,STONEBRICK:1)
B(7,7,4,STONEBRICK:2)
B(8,7,4,STONE)
B(0,8,4,STONEBRICK)
B(1,8,4,EMERALD_ORE)
B(2,8,4,STONEBRICK:1)
B(6,8,4,STONEBRICK:1)
B(7,8,4,STONE)
B(8,8,4,STONEBRICK)
B(2,9,4,STONE)
B(6,9,4,MOSSY_COBBLESTONE)
B(2,10,4,STONE)
B(6,10,4,STONE)
B(2,11,4,MOSSY_COBBLESTONE)
B(6,11,4,STONE)
B(2,12,4,MOSSY_COBBLESTONE)
B(6,12,4,STONE)
B(2,13,4,MOSSY_COBBLESTONE)
B(6,13,4,MOSSY_COBBLESTONE)
B(2,14,4,MOSSY_COBBLESTONE)
B(6,14,4,STONE)
B(2,15,4,MOSSY_COBBLESTONE)
B(6,15,4,STONE)
B(0,16,4,STONEBRICK)
B(1,16,4,MOSSY_COBBLESTONE)
B(2,16,4,STONEBRICK:1)
B(6,16,4,STONEBRICK)
B(7,16,4,EMERALD_ORE)
B(8,16,4,STONEBRICK)
B(0,20,4,STONEBRICK:1)
B(8,20,4,STONEBRICK)
B(0,21,4,STONE)
B(8,21,4,MOSSY_COBBLESTONE)
B(0,22,4,MOSSY_COBBLESTONE)
B(8,22,4,STONE)
B(0,23,4,MOSSY_COBBLESTONE)
B(1,23,4,STONEBRICK)
B(7,23,4,STONEBRICK:1)
B(8,23,4,STONE)
B(0,24,4,STONEBRICK:1)
B(1,24,4,MOSSY_COBBLESTONE)
B(2,24,4,STONEBRICK:2)
B(6,24,4,STONEBRICK:2)
B(7,24,4,MOSSY_COBBLESTONE)
B(8,24,4,STONEBRICK:1)
B(0,0,5,STONEBRICK)
B(1,0,5,STONEBRICK:1)
B(2,0,5,STONEBRICK:1)
B(3,0,5,DIRT:1)
B(4,0,5,DIRT:1)
B(5,0,5,GRASS)
B(6,0,5,STONEBRICK:1)
B(7,0,5,STONEBRICK)
B(8,0,5,STONEBRICK:2)
B(0,1,5,STONE)
B(8,1,5,MOSSY_COBBLESTONE)
B(0,2,5,MOSSY_COBBLESTONE)
B(8,2,5,MOSSY_COBBLESTONE)
B(0,3,5,MOSSY_COBBLESTONE)
B(8,3,5,STONE)
B(0,4,5,MOSSY_COBBLESTONE)
B(8,4,5,MOSSY_COBBLESTONE)
B(0,5,5,STONE)
B(8,5,5,MOSSY_COBBLESTONE)
B(0,6,5,STONE)
B(8,6,5,STONE)
B(0,7,5,STONE)
B(1,7,5,STONEBRICK:2)
B(7,7,5,STONEBRICK:2)
B(8,7,5,MOSSY_COBBLESTONE)
B(0,8,5,STONEBRICK)
B(1,8,5,MOSSY_COBBLESTONE)
B(2,8,5,STONEBRICK)
B(6,8,5,STONEBRICK:1)
B(7,8,5,MOSSY_COBBLESTONE)
B(8,8,5,STONEBRICK)
B(2,9,5,MOSSY_COBBLESTONE)
B(6,9,5,EMERALD_ORE)
B(2,10,5,STONE)
B(6,10,5,MOSSY_COBBLESTONE)
B(2,11,5,EMERALD_ORE)
B(6,11,5,STONE)
B(2,12,5,EMERALD_ORE)
B(6,12,5,EMERALD_ORE)
B(2,13,5,MOSSY_COBBLESTONE)
B(6,13,5,MOSSY_COBBLESTONE)
B(2,14,5,EMERALD_ORE)
B(6,14,5,STONE)
B(2,15,5,STONE)
B(6,15,5,MOSSY_COBBLESTONE)
B(0,16,5,STONEBRICK)
B(1,16,5,MOSSY_COBBLESTONE)
B(2,16,5,STONEBRICK:1)
B(6,16,5,STONEBRICK:2)
B(7,16,5,MOSSY_COBBLESTONE)
B(8,16,5,STONEBRICK:2)
B(0,17,5,STONEBRICK:1)
B(8,17,5,STONEBRICK:2)
B(0,18,5,STONEBRICK)
B(8,18,5,STONEBRICK)
B(0,19,5,STONEBRICK:2)
B(8,19,5,STONEBRICK)
B(0,20,5,STONEBRICK:1)
B(8,20,5,STONEBRICK:2)
B(0,21,5,MOSSY_COBBLESTONE)
B(8,21,5,MOSSY_COBBLESTONE)
B(0,22,5,MOSSY_COBBLESTONE)
B(8,22,5,STONE)
B(0,23,5,STONE)
B(1,23,5,STONEBRICK:2)
B(7,23,5,STONEBRICK:1)
B(8,23,5,STONE)
B(0,24,5,STONEBRICK:2)
B(1,24,5,MOSSY_COBBLESTONE)
B(2,24,5,STONEBRICK:1)
B(6,24,5,STONEBRICK:2)
B(7,24,5,MOSSY_COBBLESTONE)
B(8,24,5,STONEBRICK)
B(0,0,6,STONEBRICK)
B(1,0,6,STONEBRICK)
B(2,0,6,STONEBRICK:1)
B(3,0,6,STONEBRICK:1)
B(4,0,6,STONEBRICK)
B(5,0,6,STONEBRICK)
B(6,0,6,STONEBRICK:1)
B(7,0,6,STONEBRICK)
B(8,0,6,STONEBRICK:1)
B(0,1,6,EMERALD_ORE)
B(8,1,6,MOSSY_COBBLESTONE)
B(0,2,6,MOSSY_COBBLESTONE)
B(8,2,6,MOSSY_COBBLESTONE)
B(0,3,6,STONE)
B(8,3,6,STONE)
B(0,4,6,STONE)
B(8,4,6,STONE)
B(0,5,6,STONE)
B(8,5,6,STONE)
B(0,6,6,STONE)
B(8,6,6,STONE)
B(0,7,6,MOSSY_COBBLESTONE)
B(1,7,6,STONEBRICK:2)
B(7,7,6,STONEBRICK:1)
B(8,7,6,MOSSY_COBBLESTONE)
B(0,8,6,STONEBRICK:2)
B(1,8,6,MOSSY_COBBLESTONE)
B(2,8,6,STONEBRICK:1)
B(3,8,6,STONEBRICK:2)
B(4,8,6,STONEBRICK:2)
B(5,8,6,STONEBRICK:2)
B(6,8,6,STONEBRICK)
B(7,8,6,STONE)
B(8,8,6,STONEBRICK:1)
B(2,9,6,STONEBRICK:1)
B(3,9,6,STONE)
B(4,9,6,MOSSY_COBBLESTONE)
B(5,9,6,STONE)
B(6,9,6,STONEBRICK:1)
B(2,10,6,STONEBRICK)
B(3,10,6,STONE)
B(4,10,6,STONE)
B(5,10,6,STONE)
B(6,10,6,STONEBRICK:1)
B(2,11,6,STONEBRICK:2)
B(3,11,6,EMERALD_ORE)
B(4,11,6,STONE)
B(5,11,6,MOSSY_COBBLESTONE)
B(6,11,6,STONEBRICK:2)
B(2,12,6,STONEBRICK)
B(3,12,6,STONE)
B(4,12,6,EMERALD_ORE)
B(5,12,6,STONE)
B(6,12,6,STONEBRICK)
B(2,13,6,STONEBRICK:2)
B(3,13,6,STONE)
B(4,13,6,STONE)
B(5,13,6,MOSSY_COBBLESTONE)
B(6,13,6,STONEBRICK:2)
B(2,14,6,STONEBRICK:1)
B(3,14,6,STONE)
B(4,14,6,MOSSY_COBBLESTONE)
B(5,14,6,MOSSY_COBBLESTONE)
B(6,14,6,STONEBRICK:1)
B(2,15,6,STONEBRICK)
B(3,15,6,MOSSY_COBBLESTONE)
B(4,15,6,MOSSY_COBBLESTONE)
B(5,15,6,STONE)
B(6,15,6,STONEBRICK:2)
B(0,16,6,STONEBRICK:1)
B(1,16,6,STONE)
B(2,16,6,STONEBRICK:1)
B(3,16,6,STONEBRICK:1)
B(4,16,6,STONEBRICK:1)
B(5,16,6,STONEBRICK)
B(6,16,6,STONEBRICK:1)
B(7,16,6,MOSSY_COBBLESTONE)
B(8,16,6,STONEBRICK:2)
B(0,17,6,STONE)
B(8,17,6,STONE)
B(0,18,6,MOSSY_COBBLESTONE)
B(8,18,6,MOSSY_COBBLESTONE)
B(0,19,6,STONE)
B(8,19,6,STONE)
B(0,20,6,STONE)
B(8,20,6,STONE)
B(0,21,6,MOSSY_COBBLESTONE)
B(8,21,6,STONE)
B(0,22,6,STONE)
B(8,22,6,MOSSY_COBBLESTONE)
B(0,23,6,STONE)
B(1,23,6,STONEBRICK:1)
B(7,23,6,STONEBRICK:1)
B(8,23,6,STONE)
B(0,24,6,STONEBRICK)
B(1,24,6,MOSSY_COBBLESTONE)
B(2,24,6,STONEBRICK:1)
B(3,24,6,STONEBRICK:2)
B(4,24,6,STONEBRICK)
B(5,24,6,STONEBRICK:2)
B(6,24,6,STONEBRICK:2)
B(7,24,6,MOSSY_COBBLESTONE)
B(8,24,6,STONEBRICK:2)
B(0,0,7,STONEBRICK:1)
B(1,0,7,STONEBRICK)
B(2,0,7,STONEBRICK)
B(3,0,7,STONEBRICK:1)
B(4,0,7,STONEBRICK)
B(5,0,7,STONEBRICK:2)
B(6,0,7,STONEBRICK:2)
B(7,0,7,STONEBRICK)
B(8,0,7,STONEBRICK)
B(0,1,7,MOSSY_COBBLESTONE)
B(1,1,7,MOSSY_COBBLESTONE)
B(7,1,7,STONE)
B(8,1,7,STONE)
B(0,2,7,STONE)
B(1,2,7,MOSSY_COBBLESTONE)
B(7,2,7,MOSSY_COBBLESTONE)
B(8,2,7,STONE)
B(0,3,7,STONE)
B(1,3,7,STONE)
B(7,3,7,MOSSY_COBBLESTONE)
B(8,3,7,STONE)
B(0,4,7,STONE)
B(1,4,7,STONEBRICK:2)
B(7,4,7,STONEBRICK:2)
B(8,4,7,STONE)
B(0,5,7,STONE)
B(1,5,7,STONEBRICK:1)
B(7,5,7,STONEBRICK:1)
B(8,5,7,STONE)
B(0,6,7,STONE)
B(1,6,7,STONEBRICK:1)
B(7,6,7,STONEBRICK:2)
B(8,6,7,MOSSY_COBBLESTONE)
B(0,7,7,MOSSY_COBBLESTONE)
B(1,7,7,STONEBRICK:1)
B(2,7,7,STONEBRICK:1)
B(3,7,7,STONEBRICK:2)
B(4,7,7,STONEBRICK:1)
B(5,7,7,STONEBRICK:1)
B(6,7,7,STONEBRICK:1)
B(7,7,7,STONEBRICK:1)
B(8,7,7,MOSSY_COBBLESTONE)
B(0,8,7,STONEBRICK:2)
B(1,8,7,STONE)
B(2,8,7,MOSSY_COBBLESTONE)
B(3,8,7,STONE)
B(4,8,7,EMERALD_ORE)
B(5,8,7,STONE)
B(6,8,7,MOSSY_COBBLESTONE)
B(7,8,7,MOSSY_COBBLESTONE)
B(8,8,7,STONEBRICK:2)
B(0,16,7,STONEBRICK)
B(1,16,7,STONE)
B(2,16,7,STONE)
B(3,16,7,MOSSY_COBBLESTONE)
B(4,16,7,STONE)
B(5,16,7,MOSSY_COBBLESTONE)
B(6,16,7,STONE)
B(7,16,7,MOSSY_COBBLESTONE)
B(8,16,7,STONEBRICK)
B(0,17,7,STONE)
B(1,17,7,STONE)
B(7,17,7,MOSSY_COBBLESTONE)
B(8,17,7,STONE)
B(0,18,7,MOSSY_COBBLESTONE)
B(1,18,7,MOSSY_COBBLESTONE)
B(7,18,7,MOSSY_COBBLESTONE)
B(8,18,7,MOSSY_COBBLESTONE)
B(0,19,7,STONE)
B(1,19,7,MOSSY_COBBLESTONE)
B(7,19,7,EMERALD_ORE)
B(8,19,7,MOSSY_COBBLESTONE)
B(0,20,7,STONE)
B(1,20,7,STONEBRICK:2)
B(7,20,7,STONEBRICK:1)
B(8,20,7,MOSSY_COBBLESTONE)
B(0,21,7,STONE)
B(1,21,7,STONEBRICK:2)
B(7,21,7,STONEBRICK:2)
B(8,21,7,STONE)
B(0,22,7,MOSSY_COBBLESTONE)
B(1,22,7,STONEBRICK:1)
B(7,22,7,STONEBRICK:2)
B(8,22,7,EMERALD_ORE)
B(0,23,7,MOSSY_COBBLESTONE)
B(1,23,7,STONEBRICK:1)
B(2,23,7,STONEBRICK)
B(3,23,7,STONEBRICK:2)
B(4,23,7,STONEBRICK:1)
B(5,23,7,STONEBRICK:2)
B(6,23,7,STONEBRICK)
B(7,23,7,STONEBRICK:2)
B(8,23,7,MOSSY_COBBLESTONE)
B(0,24,7,STONEBRICK:1)
B(1,24,7,MOSSY_COBBLESTONE)
B(2,24,7,STONE)
B(3,24,7,STONE)
B(4,24,7,MOSSY_COBBLESTONE)
B(5,24,7,STONE)
B(6,24,7,EMERALD_ORE)
B(7,24,7,STONE)
B(8,24,7,STONEBRICK:2)
B(0,0,8,STONEBRICK:2)
B(1,0,8,STONEBRICK)
B(2,0,8,STONEBRICK:2)
B(3,0,8,STONEBRICK)
B(4,0,8,STONEBRICK)
B(5,0,8,STONEBRICK)
B(6,0,8,STONEBRICK:1)
B(7,0,8,STONEBRICK:2)
B(8,0,8,STONEBRICK:1)
B(0,1,8,STONEBRICK:1)
B(1,1,8,EMERALD_ORE)
B(2,1,8,MOSSY_COBBLESTONE)
B(3,1,8,STONEBRICK:1)
B(5,1,8,STONEBRICK:2)
B(6,1,8,STONE)
B(7,1,8,MOSSY_COBBLESTONE)
B(8,1,8,STONEBRICK)
B(0,2,8,STONEBRICK:2)
B(1,2,8,EMERALD_ORE)
B(2,2,8,MOSSY_COBBLESTONE)
B(3,2,8,STONEBRICK)
B(5,2,8,STONEBRICK:1)
B(6,2,8,STONE)
B(7,2,8,MOSSY_COBBLESTONE)
B(8,2,8,STONEBRICK:1)
B(0,3,8,STONEBRICK:1)
B(1,3,8,EMERALD_ORE)
B(2,3,8,STONE)
B(3,3,8,STONEBRICK)
B(5,3,8,STONEBRICK:1)
B(6,3,8,STONE)
B(7,3,8,STONE)
B(8,3,8,STONEBRICK)
B(0,4,8,STONEBRICK:1)
B(1,4,8,MOSSY_COBBLESTONE)
B(2,4,8,MOSSY_COBBLESTONE)
B(3,4,8,STONEBRICK:1)
B(4,4,8,STONEBRICK:2)
B(5,4,8,STONEBRICK)
B(6,4,8,STONE)
B(7,4,8,EMERALD_ORE)
B(8,4,8,STONEBRICK:2)
B(0,5,8,STONEBRICK:2)
B(1,5,8,STONE)
B(2,5,8,MOSSY_COBBLESTONE)
B(3,5,8,STONE)
B(4,5,8,MOSSY_COBBLESTONE)
B(5,5,8,MOSSY_COBBLESTONE)
B(6,5,8,EMERALD_ORE)
B(7,5,8,EMERALD_ORE)
B(8,5,8,STONEBRICK)
B(0,6,8,STONEBRICK)
B(1,6,8,STONE)
B(2,6,8,MOSSY_COBBLESTONE)
B(3,6,8,STONE)
B(4,6,8,MOSSY_COBBLESTONE)
B(5,6,8,STONE)
B(6,6,8,STONE)
B(7,6,8,STONE)
B(8,6,8,STONEBRICK:1)
B(0,7,8,STONEBRICK)
B(1,7,8,STONE)
B(2,7,8,STONE)
B(3,7,8,EMERALD_ORE)
B(4,7,8,STONE)
B(5,7,8,MOSSY_COBBLESTONE)
B(6,7,8,STONE)
B(7,7,8,MOSSY_COBBLESTONE)
B(8,7,8,STONEBRICK:1)
B(0,8,8,STONEBRICK:2)
B(1,8,8,STONEBRICK)
B(2,8,8,STONEBRICK:2)
B(3,8,8,STONEBRICK)
B(4,8,8,STONEBRICK:2)
B(5,8,8,STONEBRICK)
B(6,8,8,STONEBRICK:1)
B(7,8,8,STONEBRICK)
B(8,8,8,STONEBRICK:2)
B(0,16,8,STONEBRICK:1)
B(1,16,8,STONEBRICK:2)
B(2,16,8,STONEBRICK)
B(3,16,8,STONEBRICK:1)
B(4,16,8,STONEBRICK)
B(5,16,8,STONEBRICK:2)
B(6,16,8,STONEBRICK:1)
B(7,16,8,STONEBRICK)
B(8,16,8,STONEBRICK:1)
B(0,17,8,STONEBRICK:1)
B(1,17,8,STONE)
B(2,17,8,MOSSY_COBBLESTONE)
B(3,17,8,EMERALD_ORE)
B(4,17,8,MOSSY_COBBLESTONE)
B(5,17,8,EMERALD_ORE)
B(6,17,8,MOSSY_COBBLESTONE)
B(7,17,8,MOSSY_COBBLESTONE)
B(8,17,8,STONEBRICK)
B(0,18,8,STONEBRICK)
B(1,18,8,STONE)
B(2,18,8,MOSSY_COBBLESTONE)
B(3,18,8,MOSSY_COBBLESTONE)
B(4,18,8,EMERALD_ORE)
B(5,18,8,MOSSY_COBBLESTONE)
B(6,18,8,STONE)
B(7,18,8,STONE)
B(8,18,8,STONEBRICK)
B(0,19,8,STONEBRICK:1)
B(1,19,8,EMERALD_ORE)
B(2,19,8,STONE)
B(3,19,8,MOSSY_COBBLESTONE)
B(4,19,8,MOSSY_COBBLESTONE)
B(5,19,8,MOSSY_COBBLESTONE)
B(6,19,8,STONE)
B(7,19,8,MOSSY_COBBLESTONE)
B(8,19,8,STONEBRICK:2)
B(0,20,8,STONEBRICK:1)
B(1,20,8,MOSSY_COBBLESTONE)
B(2,20,8,MOSSY_COBBLESTONE)
B(3,20,8,STONE)
B(4,20,8,EMERALD_ORE)
B(5,20,8,EMERALD_ORE)
B(6,20,8,MOSSY_COBBLESTONE)
B(7,20,8,MOSSY_COBBLESTONE)
B(8,20,8,STONEBRICK)
B(0,21,8,STONEBRICK:2)
B(1,21,8,MOSSY_COBBLESTONE)
B(2,21,8,EMERALD_ORE)
B(3,21,8,STONE)
B(4,21,8,STONE)
B(5,21,8,STONE)
B(6,21,8,MOSSY_COBBLESTONE)
B(7,21,8,STONE)
B(8,21,8,STONEBRICK)
B(0,22,8,STONEBRICK)
B(1,22,8,MOSSY_COBBLESTONE)
B(2,22,8,STONE)
B(3,22,8,MOSSY_COBBLESTONE)
B(4,22,8,STONE)
B(5,22,8,MOSSY_COBBLESTONE)
B(6,22,8,MOSSY_COBBLESTONE)
B(7,22,8,STONE)
B(8,22,8,STONEBRICK:1)
B(0,23,8,STONEBRICK:2)
B(1,23,8,MOSSY_COBBLESTONE)
B(2,23,8,MOSSY_COBBLESTONE)
B(3,23,8,STONE)
B(4,23,8,STONE)
B(5,23,8,MOSSY_COBBLESTONE)
B(6,23,8,EMERALD_ORE)
B(7,23,8,STONE)
B(8,23,8,STONEBRICK:1)
B(0,24,8,STONEBRICK:2)
B(1,24,8,STONEBRICK:2)
B(2,24,8,STONEBRICK)
B(3,24,8,STONEBRICK)
B(4,24,8,STONEBRICK)
B(5,24,8,STONEBRICK:2)
B(6,24,8,STONEBRICK:1)
B(7,24,8,STONEBRICK:2)
B(8,24,8,STONEBRICK:2)
B(4,1,0,AIR)
B(4,2,0,AIR)
B(4,3,0,AIR)
B(2,1,1,AIR)
B(3,1,1,AIR)
B(4,1,1,AIR)
B(5,1,1,AIR)
B(6,1,1,AIR)
B(2,2,1,AIR)
B(3,2,1,AIR)
B(4,2,1,AIR)
B(5,2,1,AIR)
B(6,2,1,AIR)
B(2,3,1,AIR)
B(3,3,1,AIR)
B(4,3,1,AIR)
B(5,3,1,AIR)
B(6,3,1,AIR)
B(2,4,1,AIR)
B(3,4,1,AIR)
B(4,4,1,AIR)
B(5,4,1,AIR)
B(6,4,1,AIR)
B(2,5,1,AIR)
B(3,5,1,AIR)
B(4,5,1,AIR)
B(5,5,1,AIR)
B(6,5,1,AIR)
B(2,6,1,STONE_BRICK_STAIRS:5)
B(3,6,1,AIR)
B(4,6,1,AIR)
B(5,6,1,AIR)
B(6,6,1,STONE_BRICK_STAIRS:4)
B(2,17,1,AIR)
B(3,17,1,AIR)
B(5,17,1,AIR)
B(6,17,1,AIR)
B(2,18,1,AIR)
B(3,18,1,AIR)
B(4,18,1,AIR)
B(5,18,1,AIR)
B(6,18,1,AIR)
B(2,19,1,AIR)
B(3,19,1,AIR)
B(4,19,1,AIR)
B(5,19,1,AIR)
B(6,19,1,AIR)
B(2,20,1,AIR)
B(3,20,1,AIR)
B(4,20,1,AIR)
B(5,20,1,AIR)
B(6,20,1,AIR)
B(2,21,1,AIR)
B(3,21,1,AIR)
B(4,21,1,AIR)
B(5,21,1,AIR)
B(6,21,1,AIR)
B(2,22,1,STONE_BRICK_STAIRS:5)
B(3,22,1,AIR)
B(4,22,1,AIR)
B(5,22,1,AIR)
B(6,22,1,STONE_BRICK_STAIRS:4)
B(1,1,2,AIR)
B(2,1,2,AIR)
B(3,1,2,AIR)
B(4,1,2,AIR)
B(5,1,2,AIR)
B(6,1,2,AIR)
B(7,1,2,AIR)
B(1,2,2,AIR)
B(2,2,2,AIR)
B(3,2,2,AIR)
B(4,2,2,AIR)
B(5,2,2,AIR)
B(6,2,2,AIR)
B(7,2,2,AIR)
B(1,3,2,AIR)
B(2,3,2,AIR)
B(3,3,2,AIR)
B(4,3,2,AIR)
B(5,3,2,AIR)
B(6,3,2,AIR)
B(7,3,2,AIR)
B(1,4,2,AIR)
B(2,4,2,AIR)
B(3,4,2,AIR)
B(4,4,2,AIR)
B(5,4,2,AIR)
B(6,4,2,AIR)
B(7,4,2,AIR)
B(1,5,2,AIR)
B(2,5,2,AIR)
B(3,5,2,AIR)
B(4,5,2,AIR)
B(5,5,2,AIR)
B(6,5,2,AIR)
B(7,5,2,AIR)
B(1,6,2,STONE_BRICK_STAIRS:7)
B(2,6,2,AIR)
B(3,6,2,AIR)
B(4,6,2,AIR)
B(5,6,2,AIR)
B(6,6,2,AIR)
B(7,6,2,STONE_BRICK_STAIRS:7)
B(2,7,2,AIR)
B(3,7,2,AIR)
B(4,7,2,AIR)
B(5,7,2,AIR)
B(6,7,2,AIR)
B(1,17,2,AIR)
B(2,17,2,AIR)
B(3,17,2,AIR)
B(4,17,2,AIR)
B(5,17,2,AIR)
B(6,17,2,AIR)
B(7,17,2,AIR)
B(1,18,2,AIR)
B(2,18,2,AIR)
B(3,18,2,AIR)
B(4,18,2,AIR)
B(5,18,2,AIR)
B(6,18,2,AIR)
B(7,18,2,AIR)
B(1,19,2,AIR)
B(2,19,2,AIR)
B(3,19,2,AIR)
B(4,19,2,AIR)
B(5,19,2,AIR)
B(6,19,2,AIR)
B(7,19,2,AIR)
B(1,20,2,AIR)
B(2,20,2,AIR)
B(3,20,2,AIR)
B(4,20,2,AIR)
B(5,20,2,AIR)
B(6,20,2,AIR)
B(7,20,2,AIR)
B(1,21,2,AIR)
B(2,21,2,AIR)
B(3,21,2,AIR)
B(4,21,2,AIR)
B(5,21,2,AIR)
B(6,21,2,AIR)
B(7,21,2,AIR)
B(1,22,2,STONE_BRICK_STAIRS:7)
B(2,22,2,AIR)
B(3,22,2,AIR)
B(4,22,2,AIR)
B(5,22,2,AIR)
B(6,22,2,AIR)
B(7,22,2,STONE_BRICK_STAIRS:7)
B(2,23,2,AIR)
B(3,23,2,AIR)
B(4,23,2,AIR)
B(5,23,2,AIR)
B(6,23,2,AIR)
B(1,1,3,AIR)
B(2,1,3,AIR)
B(3,1,3,TALLGRASS:2)
B(4,1,3,TALLGRASS:2)
B(5,1,3,TALLGRASS:2)
B(6,1,3,AIR)
B(7,1,3,AIR)
B(1,2,3,AIR)
B(2,2,3,AIR)
B(3,2,3,AIR)
B(4,2,3,AIR)
B(5,2,3,AIR)
B(6,2,3,AIR)
B(7,2,3,AIR)
B(1,3,3,AIR)
B(2,3,3,AIR)
B(3,3,3,AIR)
B(4,3,3,AIR)
B(5,3,3,AIR)
B(6,3,3,AIR)
B(7,3,3,AIR)
B(1,4,3,AIR)
B(2,4,3,AIR)
B(3,4,3,AIR)
B(4,4,3,AIR)
B(5,4,3,AIR)
B(6,4,3,AIR)
B(7,4,3,AIR)
B(1,5,3,AIR)
B(2,5,3,AIR)
B(3,5,3,AIR)
B(4,5,3,AIR)
B(5,5,3,AIR)
B(6,5,3,AIR)
B(7,5,3,AIR)
B(1,6,3,AIR)
B(2,6,3,AIR)
B(3,6,3,AIR)
B(4,6,3,AIR)
B(5,6,3,AIR)
B(6,6,3,AIR)
B(7,6,3,AIR)
B(2,7,3,AIR)
B(3,7,3,AIR)
B(4,7,3,AIR)
B(5,7,3,AIR)
B(6,7,3,AIR)
B(3,8,3,AIR)
B(4,8,3,AIR)
B(5,8,3,AIR)
B(3,9,3,AIR)
B(4,9,3,AIR)
B(5,9,3,AIR)
B(3,10,3,AIR)
B(4,10,3,AIR)
B(5,10,3,AIR)
B(3,11,3,AIR)
B(4,11,3,AIR)
B(5,11,3,AIR)
B(3,12,3,AIR)
B(4,12,3,AIR)
B(5,12,3,AIR)
B(3,13,3,AIR)
B(4,13,3,AIR)
B(5,13,3,AIR)
B(3,14,3,AIR)
B(4,14,3,AIR)
B(5,14,3,AIR)
B(3,15,3,AIR)
B(4,15,3,AIR)
B(5,15,3,AIR)
B(3,16,3,AIR)
B(4,16,3,AIR)
B(5,16,3,AIR)
B(1,17,3,AIR)
B(2,17,3,AIR)
B(3,17,3,AIR)
B(4,17,3,AIR)
B(5,17,3,AIR)
B(6,17,3,AIR)
B(7,17,3,AIR)
B(1,18,3,AIR)
B(2,18,3,AIR)
B(3,18,3,AIR)
B(4,18,3,AIR)
B(5,18,3,AIR)
B(6,18,3,AIR)
B(7,18,3,AIR)
B(1,19,3,AIR)
B(2,19,3,AIR)
B(3,19,3,AIR)
B(4,19,3,AIR)
B(5,19,3,AIR)
B(6,19,3,AIR)
B(7,19,3,AIR)
B(1,20,3,AIR)
B(2,20,3,AIR)
B(3,20,3,AIR)
B(4,20,3,AIR)
B(5,20,3,AIR)
B(6,20,3,AIR)
B(7,20,3,AIR)
B(1,21,3,AIR)
B(2,21,3,AIR)
B(3,21,3,AIR)
B(4,21,3,AIR)
B(5,21,3,AIR)
B(6,21,3,AIR)
B(7,21,3,AIR)
B(1,22,3,AIR)
B(2,22,3,AIR)
B(3,22,3,AIR)
B(4,22,3,AIR)
B(5,22,3,AIR)
B(6,22,3,AIR)
B(7,22,3,AIR)
B(2,23,3,AIR)
B(3,23,3,AIR)
B(4,23,3,AIR)
B(5,23,3,AIR)
B(6,23,3,AIR)
B(3,24,3,AIR)
B(4,24,3,AIR)
B(5,24,3,AIR)
B(2,1,4,AIR)
B(3,1,4,TALLGRASS:1)
B(5,1,4,TALLGRASS:2)
B(6,1,4,AIR)
B(1,2,4,AIR)
B(2,2,4,AIR)
B(3,2,4,AIR)
B(4,2,4,AIR)
B(5,2,4,AIR)
B(6,2,4,AIR)
B(7,2,4,AIR)
B(1,3,4,AIR)
B(2,3,4,AIR)
B(3,3,4,AIR)
B(4,3,4,AIR)
B(5,3,4,AIR)
B(6,3,4,AIR)
B(7,3,4,AIR)
B(1,4,4,AIR)
B(2,4,4,AIR)
B(3,4,4,AIR)
B(4,4,4,AIR)
B(5,4,4,AIR)
B(6,4,4,AIR)
B(7,4,4,AIR)
B(1,5,4,AIR)
B(2,5,4,AIR)
B(3,5,4,AIR)
B(4,5,4,AIR)
B(5,5,4,AIR)
B(6,5,4,AIR)
B(7,5,4,AIR)
B(1,6,4,AIR)
B(2,6,4,AIR)
B(3,6,4,AIR)
B(4,6,4,AIR)
B(5,6,4,AIR)
B(6,6,4,AIR)
B(7,6,4,AIR)
B(2,7,4,AIR)
B(3,7,4,AIR)
B(4,7,4,AIR)
B(5,7,4,AIR)
B(6,7,4,AIR)
B(3,8,4,AIR)
B(4,8,4,AIR)
B(5,8,4,AIR)
B(3,9,4,AIR)
B(4,9,4,AIR)
B(5,9,4,AIR)
B(3,10,4,AIR)
B(4,10,4,AIR)
B(5,10,4,AIR)
B(3,11,4,AIR)
B(4,11,4,AIR)
B(5,11,4,AIR)
B(3,12,4,AIR)
B(4,12,4,AIR)
B(5,12,4,AIR)
B(3,13,4,AIR)
B(4,13,4,AIR)
B(5,13,4,AIR)
B(3,14,4,AIR)
B(4,14,4,AIR)
B(5,14,4,AIR)
B(3,15,4,AIR)
B(4,15,4,AIR)
B(5,15,4,AIR)
B(3,16,4,AIR)
B(4,16,4,AIR)
B(5,16,4,AIR)
B(0,17,4,AIR)
B(1,17,4,AIR)
B(2,17,4,AIR)
B(3,17,4,AIR)
B(4,17,4,AIR)
B(5,17,4,AIR)
B(6,17,4,AIR)
B(7,17,4,AIR)
B(8,17,4,AIR)
B(0,18,4,AIR)
B(1,18,4,AIR)
B(2,18,4,AIR)
B(3,18,4,AIR)
B(4,18,4,AIR)
B(5,18,4,AIR)
B(6,18,4,AIR)
B(7,18,4,AIR)
B(8,18,4,AIR)
B(0,19,4,AIR)
B(1,19,4,AIR)
B(2,19,4,AIR)
B(3,19,4,AIR)
B(4,19,4,AIR)
B(5,19,4,AIR)
B(6,19,4,AIR)
B(7,19,4,AIR)
B(8,19,4,AIR)
B(1,20,4,AIR)
B(2,20,4,AIR)
B(3,20,4,AIR)
B(4,20,4,AIR)
B(5,20,4,AIR)
B(6,20,4,AIR)
B(7,20,4,AIR)
B(1,21,4,AIR)
B(2,21,4,AIR)
B(3,21,4,AIR)
B(4,21,4,AIR)
B(5,21,4,AIR)
B(6,21,4,AIR)
B(7,21,4,AIR)
B(1,22,4,AIR)
B(2,22,4,AIR)
B(3,22,4,AIR)
B(4,22,4,AIR)
B(5,22,4,AIR)
B(6,22,4,AIR)
B(7,22,4,AIR)
B(2,23,4,AIR)
B(3,23,4,AIR)
B(4,23,4,AIR)
B(5,23,4,AIR)
B(6,23,4,AIR)
B(3,24,4,AIR)
B(4,24,4,AIR)
B(5,24,4,AIR)
B(1,1,5,AIR)
B(2,1,5,AIR)
B(3,1,5,TALLGRASS:2)
B(4,1,5,AIR)
B(5,1,5,TALLGRASS:2)
B(6,1,5,AIR)
B(7,1,5,AIR)
B(1,2,5,AIR)
B(2,2,5,AIR)
B(3,2,5,AIR)
B(4,2,5,AIR)
B(5,2,5,AIR)
B(6,2,5,AIR)
B(7,2,5,AIR)
B(1,3,5,AIR)
B(2,3,5,AIR)
B(3,3,5,AIR)
B(4,3,5,AIR)
B(5,3,5,AIR)
B(6,3,5,AIR)
B(7,3,5,AIR)
B(1,4,5,AIR)
B(2,4,5,AIR)
B(3,4,5,AIR)
B(4,4,5,AIR)
B(5,4,5,AIR)
B(6,4,5,AIR)
B(7,4,5,AIR)
B(1,5,5,AIR)
B(2,5,5,AIR)
B(3,5,5,AIR)
B(4,5,5,AIR)
B(5,5,5,AIR)
B(6,5,5,AIR)
B(7,5,5,AIR)
B(1,6,5,AIR)
B(2,6,5,AIR)
B(3,6,5,AIR)
B(4,6,5,AIR)
B(5,6,5,AIR)
B(6,6,5,AIR)
B(7,6,5,AIR)
B(2,7,5,AIR)
B(3,7,5,AIR)
B(4,7,5,AIR)
B(5,7,5,AIR)
B(6,7,5,AIR)
B(3,8,5,AIR)
B(4,8,5,AIR)
B(5,8,5,AIR)
B(3,9,5,AIR)
B(4,9,5,AIR)
B(5,9,5,AIR)
B(3,10,5,AIR)
B(4,10,5,AIR)
B(5,10,5,AIR)
B(3,11,5,AIR)
B(4,11,5,AIR)
B(5,11,5,AIR)
B(3,12,5,AIR)
B(4,12,5,AIR)
B(5,12,5,AIR)
B(3,13,5,AIR)
B(4,13,5,AIR)
B(5,13,5,AIR)
B(3,14,5,AIR)
B(4,14,5,AIR)
B(5,14,5,AIR)
B(3,15,5,AIR)
B(4,15,5,AIR)
B(5,15,5,AIR)
B(3,16,5,AIR)
B(4,16,5,AIR)
B(5,16,5,AIR)
B(1,17,5,AIR)
B(2,17,5,AIR)
B(3,17,5,AIR)
B(4,17,5,AIR)
B(5,17,5,AIR)
B(6,17,5,AIR)
B(7,17,5,AIR)
B(1,18,5,AIR)
B(2,18,5,AIR)
B(3,18,5,AIR)
B(4,18,5,AIR)
B(5,18,5,AIR)
B(6,18,5,AIR)
B(7,18,5,AIR)
B(1,19,5,AIR)
B(2,19,5,AIR)
B(3,19,5,AIR)
B(4,19,5,AIR)
B(5,19,5,AIR)
B(6,19,5,AIR)
B(7,19,5,AIR)
B(1,20,5,AIR)
B(2,20,5,AIR)
B(3,20,5,AIR)
B(4,20,5,AIR)
B(5,20,5,AIR)
B(6,20,5,AIR)
B(7,20,5,AIR)
B(1,21,5,AIR)
B(2,21,5,AIR)
B(3,21,5,AIR)
B(4,21,5,AIR)
B(5,21,5,AIR)
B(6,21,5,AIR)
B(7,21,5,AIR)
B(1,22,5,AIR)
B(2,22,5,AIR)
B(3,22,5,AIR)
B(4,22,5,AIR)
B(5,22,5,AIR)
B(6,22,5,AIR)
B(7,22,5,AIR)
B(2,23,5,AIR)
B(3,23,5,AIR)
B(4,23,5,AIR)
B(5,23,5,AIR)
B(6,23,5,AIR)
B(3,24,5,AIR)
B(4,24,5,AIR)
B(5,24,5,AIR)
B(1,1,6,AIR)
B(2,1,6,AIR)
B(3,1,6,AIR)
B(4,1,6,AIR)
B(5,1,6,AIR)
B(6,1,6,AIR)
B(7,1,6,AIR)
B(1,2,6,AIR)
B(2,2,6,AIR)
B(3,2,6,AIR)
B(4,2,6,AIR)
B(5,2,6,AIR)
B(6,2,6,AIR)
B(7,2,6,AIR)
B(1,3,6,AIR)
B(2,3,6,AIR)
B(3,3,6,AIR)
B(4,3,6,AIR)
B(5,3,6,AIR)
B(6,3,6,AIR)
B(7,3,6,AIR)
B(1,4,6,AIR)
B(2,4,6,AIR)
B(3,4,6,AIR)
B(4,4,6,AIR)
B(5,4,6,AIR)
B(6,4,6,AIR)
B(7,4,6,AIR)
B(1,5,6,AIR)
B(2,5,6,AIR)
B(3,5,6,AIR)
B(4,5,6,AIR)
B(5,5,6,AIR)
B(6,5,6,AIR)
B(7,5,6,AIR)
B(1,6,6,STONE_BRICK_STAIRS:6)
B(2,6,6,AIR)
B(3,6,6,AIR)
B(4,6,6,AIR)
B(5,6,6,AIR)
B(6,6,6,AIR)
B(7,6,6,STONE_BRICK_STAIRS:6)
B(2,7,6,AIR)
B(3,7,6,AIR)
B(4,7,6,AIR)
B(5,7,6,AIR)
B(6,7,6,AIR)
B(1,17,6,AIR)
B(2,17,6,AIR)
B(3,17,6,AIR)
B(4,17,6,AIR)
B(5,17,6,AIR)
B(6,17,6,AIR)
B(7,17,6,AIR)
B(1,18,6,AIR)
B(2,18,6,AIR)
B(3,18,6,AIR)
B(4,18,6,AIR)
B(5,18,6,AIR)
B(6,18,6,AIR)
B(7,18,6,AIR)
B(1,19,6,AIR)
B(2,19,6,AIR)
B(3,19,6,AIR)
B(4,19,6,AIR)
B(5,19,6,AIR)
B(6,19,6,AIR)
B(7,19,6,AIR)
B(1,20,6,AIR)
B(2,20,6,AIR)
B(3,20,6,AIR)
B(4,20,6,AIR)
B(5,20,6,AIR)
B(6,20,6,AIR)
B(7,20,6,AIR)
B(1,21,6,AIR)
B(2,21,6,AIR)
B(3,21,6,AIR)
B(4,21,6,AIR)
B(5,21,6,AIR)
B(6,21,6,AIR)
B(7,21,6,AIR)
B(1,22,6,STONE_BRICK_STAIRS:6)
B(2,22,6,AIR)
B(3,22,6,AIR)
B(4,22,6,AIR)
B(5,22,6,AIR)
B(6,22,6,AIR)
B(7,22,6,STONE_BRICK_STAIRS:6)
B(2,23,6,AIR)
B(3,23,6,AIR)
B(4,23,6,AIR)
B(5,23,6,AIR)
B(6,23,6,AIR)
B(2,1,7,AIR)
B(3,1,7,AIR)
B(4,1,7,AIR)
B(5,1,7,AIR)
B(6,1,7,AIR)
B(2,2,7,AIR)
B(3,2,7,AIR)
B(4,2,7,AIR)
B(5,2,7,AIR)
B(6,2,7,AIR)
B(2,3,7,AIR)
B(3,3,7,AIR)
B(4,3,7,AIR)
B(5,3,7,AIR)
B(6,3,7,AIR)
B(2,4,7,AIR)
B(3,4,7,AIR)
B(4,4,7,AIR)
B(5,4,7,AIR)
B(6,4,7,AIR)
B(2,5,7,AIR)
B(3,5,7,AIR)
B(4,5,7,AIR)
B(5,5,7,AIR)
B(6,5,7,AIR)
B(2,6,7,STONE_BRICK_STAIRS:5)
B(3,6,7,AIR)
B(4,6,7,AIR)
B(5,6,7,AIR)
B(6,6,7,STONE_BRICK_STAIRS:4)
B(2,17,7,AIR)
B(3,17,7,AIR)
B(5,17,7,AIR)
B(6,17,7,AIR)
B(2,18,7,AIR)
B(3,18,7,AIR)
B(4,18,7,AIR)
B(5,18,7,AIR)
B(6,18,7,AIR)
B(2,19,7,AIR)
B(3,19,7,AIR)
B(4,19,7,AIR)
B(5,19,7,AIR)
B(6,19,7,AIR)
B(2,20,7,AIR)
B(3,20,7,AIR)
B(4,20,7,AIR)
B(5,20,7,AIR)
B(6,20,7,AIR)
B(2,21,7,AIR)
B(3,21,7,AIR)
B(4,21,7,AIR)
B(5,21,7,AIR)
B(6,21,7,AIR)
B(2,22,7,STONE_BRICK_STAIRS:5)
B(3,22,7,AIR)
B(4,22,7,AIR)
B(5,22,7,AIR)
B(6,22,7,STONE_BRICK_STAIRS:4)
B(4,1,8,AIR)
B(4,2,8,AIR)
B(4,3,8,AIR)

RB(4,1,4,MOB_SPAWNER,../../nbt/Spawner/Zombie.nbt,50,MOB_SPAWNER,../../nbt/Spawner/Skeleton.nbt,50,MOB_SPAWNER,../../nbt/Spawner/Spider.nbt,100)

B(4,17,1,CHEST:3,../../nbt/VanillaLoot/simple_dungeon.nbt)
B(1,1,4,CHEST:5,../../nbt/VanillaLoot/simple_dungeon.nbt)
B(7,1,4,CHEST:4,../../nbt/VanillaLoot/simple_dungeon.nbt)
B(4,17,7,CHEST:2,../../nbt/VanillaLoot/simple_dungeon.nbt)

# Size (X*Y*Z): 9*25*9

#######################################################################
# +-----------------------------------------------------------------+ #
# |                            BO3 checks                           | #
# +-----------------------------------------------------------------+ #
#######################################################################

# Require a condition at a certain location in order for the BO3 to be spawned.
# BlockCheck(x,y,z,BlockName[,BlockName[,...]]) - one of the blocks must be at the location
# BlockCheckNot(x,y,z,BlockName[,BlockName[,...]]) - all the blocks must not be at the location
# LightCheck(x,y,z,minLightLevel,maxLightLevel) - light must be between min and max (inclusive)

# You can use "Solid" as a BlockName for matching all solid blocks or "All" to match all blocks that aren't air.

# Examples:
#   BlockCheck(0,-1,0,GRASS,DIRT)  Require grass or dirt just below the object
#   BlockCheck(0,-1,0,Solid)       Require any solid block just below the object
#   BlockCheck(0,-1,0,WOOL)        Require any type of wool just below the object
#   BlockCheck(0,-1,0,WOOL:0)      Require white wool just below the object
#   BlockCheckNot(0,0,0,WOOL:0)   Require that there is no white wool below the object
#   LightCheck(0,0,0,0,1)          Require almost complete darkness just below the object

# Ensure the ceiling is sufficiently covered in solid blocks.
BlockCheck(0,25,0,Solid)
BlockCheck(0,25,9,Solid)
BlockCheck(9,25,0,Solid)
BlockCheck(9,25,9,Solid)

#######################################################################
# +-----------------------------------------------------------------+ #
# |                             Branches                            | #
# +-----------------------------------------------------------------+ #
#######################################################################

# Branches are objects that will spawn when this object spawns when it is used in
# the CustomStructure resource. Branches can also have branches, making complex
# structures possible. See the wiki for more details.

# Regular Branches spawn each branch with an independent chance of spawning.
# Branch(x,y,z,branchName,rotation,chance[,anotherBranchName,rotation,chance[,...]][IndividualChance])
# branchName - name of the object to spawn.
# rotation - NORTH, SOUTH, EAST or WEST.
# IndividualChance - The chance each branch has to spawn, assumed to be 100 when left blank

# Weighted Branches spawn branches with a dependent chance of spawning.
# WBR(x,y,z,branchName,rotation,chance[,anotherBranchName,rotation,chance[,...]][MaxChanceOutOf])
# MaxChanceOutOf - The chance all branches have to spawn out of, assumed to be 100 when left blank
