
#######################################################################
# +-----------------------------------------------------------------+ #
# |                            BO3 object                           | #
# +-----------------------------------------------------------------+ #
#######################################################################

# This is the config file of a custom object.
# If you add this object correctly to your BiomeConfigs, it will spawn in the world.

# This is the creator of this BO3 object
# See: https://imgur.com/a/JanPA
Author: Arcensoth, designed by McNoodlor

# A short description of this BO3 object
Description: No description given

# The BO3 version, don't change this! It can be used by external applications to do a version check.
Version: 3

# The settings mode, WriteAll, WriteWithoutComments or WriteDisable. See WorldConfig.
SettingsMode: WriteDisable


#######################################################################
# +-----------------------------------------------------------------+ #
# |                          Main settings                          | #
# +-----------------------------------------------------------------+ #
#######################################################################

# This needs to be set to true to spawn the object in the Tree and Sapling resources.
Tree: false

# The frequency of the BO3 from 1 to 200. Tries this many times to spawn this BO3 when using the CustomObject(...) resource.
# Ignored by Tree(..), Sapling(..) and CustomStructure(..)
Frequency: 1

# The rarity of the BO3 from 0 to 100. Each spawn attempt has rarity% chance to succeed when using the CustomObject(...) resource.
# Ignored by Tree(..), Sapling(..) and CustomStructure(..)
Rarity: 1.0

# If you set this to true, the BO3 will be placed with a random rotation.
RotateRandomly: false

# The spawn height of the BO3 - randomY, highestBlock or highestSolidBlock.
SpawnHeight: randomY

# The height limits for the BO3.
MinHeight: 0

MaxHeight: 255

# Objects can have other objects attacthed to it: branches. Branches can also
# have branches attached to it, which can also have branches, etc. This is the
# maximum branch depth for this objects.
MaxBranchDepth: 10

# When spawned with the UseWorld keyword, this BO3 should NOT spawn in the following biomes.
# If you writer.write the BO3 name directly in the BiomeConfigs, this will be ignored.
ExcludedBiomes: All


#######################################################################
# +-----------------------------------------------------------------+ #
# |                      Source block settings                      | #
# +-----------------------------------------------------------------+ #
#######################################################################

# The B(s) the BO3 should spawn in.
SourceBlocks: STONE,STONE:1,STONE:3,STONE:5,COBBLESTONE,MOSSY_COBBLESTONE,SANDSTONE,HARD_CLAY,STAINED_CLAY,PRISMARINE,DIRT,DIRT:1,GRASS,SAND,GRAVEL,CLAY,OBSIDIAN,COAL_ORE,IRON_ORE,GOLD_ORE,REDSTONE_ORE,DIAMOND_ORE,LAPIS_ORE,EMERALD_ORE,STATIONARY_WATER,STATIONARY_LAVA

# The maximum percentage of the BO3 that can be outside the SourceBlock.
# The BO3 won't be placed on a location with more blocks outside the SourceBlock than this percentage.
MaxPercentageOutsideSourceBlock: 45

# What to do when a block is about to be placed outside the SourceBlock? (dontPlace, placeAnyway)
OutsideSourceBlock: dontPlace


#######################################################################
# +-----------------------------------------------------------------+ #
# |                              Blocks                             | #
# +-----------------------------------------------------------------+ #
#######################################################################

# All the blocks used in the BO3 are listed here. Possible blocks:
# B(x,y,z,id[.data][,nbtfile.nbt)
# RB(x,y,z,id[:data][,nbtfile.nbt],chance[,id[:data][,nbtfile.nbt],chance[,...]])
# So RB(0,0,0,CHEST,chest.nbt,50,CHEST,anotherchest.nbt,100) will spawn a chest at
# the BO3 origin, and give it a 50% chance to have the contents of chest.nbt, or, if that
# fails, a 100% percent chance to have the contents of anotherchest.nbt.
B(0,0,0,STONEBRICK:2)
B(1,0,0,STONEBRICK:2)
B(2,0,0,STONEBRICK:2)
B(3,0,0,STONEBRICK)
B(4,0,0,STONEBRICK)
B(5,0,0,STONEBRICK:2)
B(6,0,0,STONEBRICK:1)
B(7,0,0,STONEBRICK:2)
B(8,0,0,STONEBRICK:1)
B(0,1,0,STONEBRICK:2)
B(1,1,0,MOSSY_COBBLESTONE)
B(2,1,0,STONE)
B(3,1,0,STONE)
B(4,1,0,STONE)
B(5,1,0,MOSSY_COBBLESTONE)
B(6,1,0,MOSSY_COBBLESTONE)
B(7,1,0,MOSSY_COBBLESTONE)
B(8,1,0,STONEBRICK:1)
B(0,2,0,STONEBRICK:1)
B(1,2,0,MOSSY_COBBLESTONE)
B(2,2,0,MOSSY_COBBLESTONE)
B(3,2,0,EMERALD_ORE)
B(4,2,0,MOSSY_COBBLESTONE)
B(5,2,0,EMERALD_ORE)
B(6,2,0,STONE)
B(7,2,0,STONE)
B(8,2,0,STONEBRICK:2)
B(0,3,0,STONEBRICK:2)
B(1,3,0,STONE)
B(2,3,0,MOSSY_COBBLESTONE)
B(3,3,0,MOSSY_COBBLESTONE)
B(4,3,0,MOSSY_COBBLESTONE)
B(5,3,0,MOSSY_COBBLESTONE)
B(6,3,0,STONE)
B(7,3,0,STONE)
B(8,3,0,STONEBRICK:2)
B(0,4,0,STONEBRICK:2)
B(1,4,0,STONE)
B(2,4,0,STONE)
B(3,4,0,MOSSY_COBBLESTONE)
B(4,4,0,STONE)
B(5,4,0,STONE)
B(6,4,0,MOSSY_COBBLESTONE)
B(7,4,0,MOSSY_COBBLESTONE)
B(8,4,0,STONEBRICK)
B(0,5,0,STONEBRICK:1)
B(1,5,0,STONE)
B(2,5,0,MOSSY_COBBLESTONE)
B(3,5,0,MOSSY_COBBLESTONE)
B(4,5,0,STONE)
B(5,5,0,EMERALD_ORE)
B(6,5,0,MOSSY_COBBLESTONE)
B(7,5,0,STONE)
B(8,5,0,STONEBRICK:2)
B(0,6,0,STONEBRICK:2)
B(1,6,0,STONE)
B(2,6,0,STONE)
B(3,6,0,MOSSY_COBBLESTONE)
B(4,6,0,MOSSY_COBBLESTONE)
B(5,6,0,STONE)
B(6,6,0,MOSSY_COBBLESTONE)
B(7,6,0,MOSSY_COBBLESTONE)
B(8,6,0,STONEBRICK:2)
B(0,7,0,STONEBRICK:1)
B(1,7,0,MOSSY_COBBLESTONE)
B(2,7,0,STONE)
B(3,7,0,EMERALD_ORE)
B(4,7,0,MOSSY_COBBLESTONE)
B(5,7,0,MOSSY_COBBLESTONE)
B(6,7,0,MOSSY_COBBLESTONE)
B(7,7,0,STONE)
B(8,7,0,STONEBRICK:1)
B(0,8,0,STONEBRICK:1)
B(1,8,0,STONEBRICK:2)
B(2,8,0,STONEBRICK:2)
B(3,8,0,STONEBRICK:1)
B(4,8,0,STONEBRICK:2)
B(5,8,0,STONEBRICK:1)
B(6,8,0,STONEBRICK:2)
B(7,8,0,STONEBRICK)
B(8,8,0,STONEBRICK)
B(0,9,0,STONEBRICK:1)
B(1,9,0,MOSSY_COBBLESTONE)
B(2,9,0,STONE)
B(3,9,0,EMERALD_ORE)
B(4,9,0,MOSSY_COBBLESTONE)
B(5,9,0,STONE)
B(6,9,0,STONE)
B(7,9,0,MOSSY_COBBLESTONE)
B(8,9,0,STONEBRICK:2)
B(0,10,0,STONEBRICK)
B(1,10,0,STONE)
B(2,10,0,MOSSY_COBBLESTONE)
B(3,10,0,STONE)
B(4,10,0,MOSSY_COBBLESTONE)
B(5,10,0,STONE)
B(6,10,0,MOSSY_COBBLESTONE)
B(7,10,0,MOSSY_COBBLESTONE)
B(8,10,0,STONEBRICK)
B(0,11,0,STONEBRICK:1)
B(1,11,0,STONE)
B(2,11,0,EMERALD_ORE)
B(3,11,0,STONE)
B(4,11,0,EMERALD_ORE)
B(5,11,0,STONE)
B(6,11,0,STONE)
B(7,11,0,STONE)
B(8,11,0,STONEBRICK)
B(0,12,0,STONEBRICK)
B(1,12,0,STONE)
B(2,12,0,EMERALD_ORE)
B(3,12,0,STONE)
B(4,12,0,STONE)
B(5,12,0,MOSSY_COBBLESTONE)
B(6,12,0,MOSSY_COBBLESTONE)
B(7,12,0,MOSSY_COBBLESTONE)
B(8,12,0,STONEBRICK:2)
B(0,13,0,STONEBRICK)
B(1,13,0,MOSSY_COBBLESTONE)
B(2,13,0,MOSSY_COBBLESTONE)
B(3,13,0,STONE)
B(4,13,0,STONE)
B(5,13,0,STONE)
B(6,13,0,MOSSY_COBBLESTONE)
B(7,13,0,MOSSY_COBBLESTONE)
B(8,13,0,STONEBRICK:1)
B(0,14,0,STONEBRICK:1)
B(1,14,0,STONE)
B(2,14,0,STONE)
B(3,14,0,MOSSY_COBBLESTONE)
B(4,14,0,STONE)
B(5,14,0,STONE)
B(6,14,0,STONE)
B(7,14,0,MOSSY_COBBLESTONE)
B(8,14,0,STONEBRICK)
B(0,15,0,STONEBRICK:1)
B(1,15,0,MOSSY_COBBLESTONE)
B(2,15,0,MOSSY_COBBLESTONE)
B(3,15,0,MOSSY_COBBLESTONE)
B(4,15,0,STONE)
B(5,15,0,MOSSY_COBBLESTONE)
B(6,15,0,MOSSY_COBBLESTONE)
B(7,15,0,MOSSY_COBBLESTONE)
B(8,15,0,STONEBRICK:2)
B(0,16,0,STONEBRICK:2)
B(1,16,0,STONEBRICK)
B(2,16,0,STONEBRICK)
B(3,16,0,STONEBRICK:1)
B(4,16,0,STONEBRICK:1)
B(5,16,0,STONEBRICK)
B(6,16,0,STONEBRICK:2)
B(7,16,0,STONEBRICK:1)
B(8,16,0,STONEBRICK:1)
B(0,0,1,STONEBRICK:1)
B(1,0,1,STONEBRICK:1)
B(2,0,1,STONEBRICK)
B(3,0,1,STONEBRICK:1)
B(4,0,1,STONEBRICK:2)
B(5,0,1,STONEBRICK:2)
B(6,0,1,STONEBRICK:1)
B(7,0,1,STONEBRICK:2)
B(8,0,1,STONEBRICK:1)
B(0,1,1,STONE)
B(1,1,1,MOSSY_COBBLESTONE)
B(7,1,1,STONE)
B(8,1,1,MOSSY_COBBLESTONE)
B(0,2,1,STONE)
B(1,2,1,STONE)
B(7,2,1,MOSSY_COBBLESTONE)
B(8,2,1,STONE)
B(0,3,1,STONE)
B(1,3,1,MOSSY_COBBLESTONE)
B(7,3,1,STONE)
B(8,3,1,STONE)
B(0,4,1,MOSSY_COBBLESTONE)
B(1,4,1,STONEBRICK:1)
B(7,4,1,STONEBRICK:2)
B(8,4,1,MOSSY_COBBLESTONE)
B(0,5,1,STONE)
B(1,5,1,STONEBRICK:1)
B(7,5,1,STONEBRICK:1)
B(8,5,1,STONE)
B(0,6,1,MOSSY_COBBLESTONE)
B(1,6,1,STONEBRICK:2)
B(7,6,1,STONEBRICK)
B(8,6,1,MOSSY_COBBLESTONE)
B(0,7,1,MOSSY_COBBLESTONE)
B(1,7,1,STONEBRICK)
B(2,7,1,STONEBRICK:2)
B(3,7,1,STONEBRICK)
B(4,7,1,STONEBRICK:1)
B(5,7,1,STONEBRICK:2)
B(6,7,1,STONEBRICK)
B(7,7,1,STONEBRICK)
B(8,7,1,STONE)
B(0,8,1,STONEBRICK)
B(1,8,1,MOSSY_COBBLESTONE)
B(2,8,1,STONE)
B(3,8,1,STONE)
B(4,8,1,MOSSY_COBBLESTONE)
B(5,8,1,MOSSY_COBBLESTONE)
B(6,8,1,STONE)
B(7,8,1,STONE)
B(8,8,1,STONEBRICK:2)
B(0,9,1,MOSSY_COBBLESTONE)
B(1,9,1,STONE)
B(7,9,1,EMERALD_ORE)
B(8,9,1,STONE)
B(0,10,1,MOSSY_COBBLESTONE)
B(1,10,1,STONE)
B(7,10,1,EMERALD_ORE)
B(8,10,1,STONE)
B(0,11,1,EMERALD_ORE)
B(1,11,1,MOSSY_COBBLESTONE)
B(7,11,1,MOSSY_COBBLESTONE)
B(8,11,1,STONE)
B(0,12,1,STONE)
B(1,12,1,STONEBRICK:2)
B(7,12,1,STONEBRICK:1)
B(8,12,1,MOSSY_COBBLESTONE)
B(0,13,1,MOSSY_COBBLESTONE)
B(1,13,1,STONEBRICK:2)
B(7,13,1,STONEBRICK:2)
B(8,13,1,STONE)
B(0,14,1,MOSSY_COBBLESTONE)
B(1,14,1,STONEBRICK:2)
B(7,14,1,STONEBRICK)
B(8,14,1,MOSSY_COBBLESTONE)
B(0,15,1,MOSSY_COBBLESTONE)
B(1,15,1,STONEBRICK:2)
B(2,15,1,STONEBRICK:2)
B(3,15,1,STONEBRICK:2)
B(4,15,1,STONEBRICK)
B(5,15,1,STONEBRICK:2)
B(6,15,1,STONEBRICK)
B(7,15,1,STONEBRICK)
B(8,15,1,MOSSY_COBBLESTONE)
B(0,16,1,STONEBRICK:2)
B(1,16,1,STONE)
B(2,16,1,STONE)
B(3,16,1,EMERALD_ORE)
B(4,16,1,MOSSY_COBBLESTONE)
B(5,16,1,EMERALD_ORE)
B(6,16,1,STONE)
B(7,16,1,STONE)
B(8,16,1,STONEBRICK:2)
B(0,0,2,STONEBRICK:1)
B(1,0,2,STONEBRICK:2)
B(2,0,2,STONEBRICK)
B(3,0,2,STONEBRICK:1)
B(4,0,2,STONEBRICK)
B(5,0,2,STONEBRICK:2)
B(6,0,2,STONEBRICK:1)
B(7,0,2,STONEBRICK)
B(8,0,2,STONEBRICK:1)
B(0,1,2,EMERALD_ORE)
B(8,1,2,MOSSY_COBBLESTONE)
B(0,2,2,MOSSY_COBBLESTONE)
B(8,2,2,MOSSY_COBBLESTONE)
B(0,3,2,STONE)
B(8,3,2,STONE)
B(0,4,2,STONE)
B(8,4,2,STONE)
B(0,5,2,STONE)
B(8,5,2,MOSSY_COBBLESTONE)
B(0,6,2,STONE)
B(8,6,2,MOSSY_COBBLESTONE)
B(0,7,2,MOSSY_COBBLESTONE)
B(1,7,2,STONEBRICK:2)
B(7,7,2,STONEBRICK:1)
B(8,7,2,MOSSY_COBBLESTONE)
B(0,8,2,STONEBRICK:1)
B(1,8,2,MOSSY_COBBLESTONE)
B(2,8,2,STONEBRICK:2)
B(3,8,2,STONEBRICK)
B(4,8,2,STONEBRICK:2)
B(5,8,2,STONEBRICK:1)
B(6,8,2,STONEBRICK:2)
B(7,8,2,MOSSY_COBBLESTONE)
B(8,8,2,STONEBRICK:1)
B(0,9,2,STONE)
B(8,9,2,STONE)
B(0,10,2,EMERALD_ORE)
B(8,10,2,MOSSY_COBBLESTONE)
B(0,11,2,STONE)
B(8,11,2,STONE)
B(0,12,2,STONE)
B(8,12,2,MOSSY_COBBLESTONE)
B(0,13,2,MOSSY_COBBLESTONE)
B(8,13,2,EMERALD_ORE)
B(0,14,2,MOSSY_COBBLESTONE)
B(8,14,2,MOSSY_COBBLESTONE)
B(0,15,2,MOSSY_COBBLESTONE)
B(1,15,2,STONEBRICK:1)
B(7,15,2,STONEBRICK:2)
B(8,15,2,STONE)
B(0,16,2,STONEBRICK:2)
B(1,16,2,MOSSY_COBBLESTONE)
B(2,16,2,STONEBRICK:1)
B(3,16,2,STONEBRICK:1)
B(4,16,2,STONEBRICK:1)
B(5,16,2,STONEBRICK:1)
B(6,16,2,STONEBRICK:2)
B(7,16,2,MOSSY_COBBLESTONE)
B(8,16,2,STONEBRICK:2)
B(0,0,3,STONEBRICK:1)
B(1,0,3,STONEBRICK:1)
B(2,0,3,STONEBRICK:1)
B(3,0,3,DIRT:1)
B(4,0,3,DIRT:1)
B(5,0,3,DIRT:1)
B(6,0,3,STONEBRICK:2)
B(7,0,3,STONEBRICK:1)
B(8,0,3,STONEBRICK:2)
B(9,0,3,STONEBRICK:1)
B(10,0,3,STONEBRICK:2)
B(11,0,3,STONEBRICK)
B(0,1,3,STONE)
B(8,1,3,STONEBRICK:2)
B(9,1,3,STONEBRICK:2)
B(10,1,3,STONEBRICK:2)
B(11,1,3,STONEBRICK:2)
B(0,2,3,STONE)
B(8,2,3,STONEBRICK:2)
B(9,2,3,STONEBRICK:1)
B(10,2,3,STONEBRICK:2)
B(11,2,3,STONEBRICK)
B(0,3,3,STONE)
B(8,3,3,STONEBRICK:2)
B(9,3,3,STONEBRICK:2)
B(10,3,3,STONEBRICK:1)
B(11,3,3,STONEBRICK:2)
B(0,4,3,STONE)
B(8,4,3,STONEBRICK:2)
B(9,4,3,STONEBRICK:2)
B(10,4,3,STONEBRICK:1)
B(11,4,3,STONEBRICK:2)
B(0,5,3,STONE)
B(8,5,3,STONE)
B(0,6,3,STONE)
B(8,6,3,STONE)
B(0,7,3,STONE)
B(1,7,3,STONEBRICK:1)
B(7,7,3,STONEBRICK:2)
B(8,7,3,STONE)
B(0,8,3,STONEBRICK:2)
B(1,8,3,STONE)
B(2,8,3,STONEBRICK:1)
B(6,8,3,STONEBRICK:1)
B(7,8,3,MOSSY_COBBLESTONE)
B(8,8,3,STONEBRICK:1)
B(9,8,3,STONEBRICK:2)
B(10,8,3,STONEBRICK:1)
B(11,8,3,STONEBRICK:2)
B(0,9,3,STONE)
B(8,9,3,STONEBRICK:2)
B(9,9,3,STONEBRICK:1)
B(10,9,3,STONEBRICK:2)
B(11,9,3,STONEBRICK:2)
B(0,10,3,STONE)
B(8,10,3,STONEBRICK:1)
B(9,10,3,STONEBRICK:2)
B(10,10,3,STONEBRICK)
B(11,10,3,STONEBRICK:2)
B(0,11,3,MOSSY_COBBLESTONE)
B(8,11,3,STONEBRICK)
B(9,11,3,STONEBRICK)
B(10,11,3,STONEBRICK:1)
B(11,11,3,STONEBRICK:1)
B(0,12,3,STONE)
B(8,12,3,STONEBRICK:1)
B(9,12,3,STONEBRICK:1)
B(10,12,3,STONEBRICK:2)
B(11,12,3,STONEBRICK:1)
B(0,13,3,MOSSY_COBBLESTONE)
B(8,13,3,MOSSY_COBBLESTONE)
B(0,14,3,MOSSY_COBBLESTONE)
B(8,14,3,MOSSY_COBBLESTONE)
B(0,15,3,EMERALD_ORE)
B(1,15,3,STONEBRICK:1)
B(7,15,3,STONEBRICK:1)
B(8,15,3,EMERALD_ORE)
B(0,16,3,STONEBRICK:2)
B(1,16,3,STONE)
B(2,16,3,STONEBRICK:2)
B(6,16,3,STONEBRICK)
B(7,16,3,MOSSY_COBBLESTONE)
B(8,16,3,STONEBRICK:2)
B(0,0,4,STONEBRICK)
B(1,0,4,STONEBRICK)
B(2,0,4,STONEBRICK:1)
B(3,0,4,DIRT:1)
B(4,0,4,DIRT:1)
B(5,0,4,GRASS)
B(6,0,4,STONEBRICK:2)
B(7,0,4,STONEBRICK:1)
B(8,0,4,STONEBRICK:2)
B(9,0,4,STONEBRICK)
B(10,0,4,STONEBRICK:1)
B(11,0,4,STONEBRICK:2)
B(0,1,4,MOSSY_COBBLESTONE)
B(0,2,4,MOSSY_COBBLESTONE)
B(0,3,4,STONE)
B(0,4,4,MOSSY_COBBLESTONE)
B(8,4,4,STONEBRICK:1)
B(9,4,4,STONEBRICK:1)
B(10,4,4,STONEBRICK)
B(11,4,4,STONEBRICK)
B(0,5,4,MOSSY_COBBLESTONE)
B(8,5,4,STONE)
B(0,6,4,EMERALD_ORE)
B(8,6,4,STONE)
B(0,7,4,STONE)
B(1,7,4,STONEBRICK)
B(7,7,4,STONEBRICK)
B(8,7,4,MOSSY_COBBLESTONE)
B(0,8,4,STONEBRICK:1)
B(1,8,4,MOSSY_COBBLESTONE)
B(2,8,4,STONEBRICK)
B(6,8,4,STONEBRICK:1)
B(7,8,4,MOSSY_COBBLESTONE)
B(8,8,4,STONEBRICK:2)
B(9,8,4,STONEBRICK)
B(10,8,4,STONEBRICK)
B(11,8,4,STONEBRICK:1)
B(0,9,4,STONE)
B(0,10,4,MOSSY_COBBLESTONE)
B(0,11,4,MOSSY_COBBLESTONE)
B(0,12,4,MOSSY_COBBLESTONE)
B(8,12,4,STONEBRICK:1)
B(9,12,4,STONEBRICK:2)
B(10,12,4,STONEBRICK:2)
B(11,12,4,STONEBRICK:2)
B(0,13,4,STONE)
B(8,13,4,STONE)
B(0,14,4,EMERALD_ORE)
B(8,14,4,STONE)
B(0,15,4,EMERALD_ORE)
B(1,15,4,STONEBRICK:1)
B(7,15,4,STONEBRICK:1)
B(8,15,4,STONE)
B(0,16,4,STONEBRICK:1)
B(1,16,4,MOSSY_COBBLESTONE)
B(2,16,4,STONEBRICK:1)
B(6,16,4,STONEBRICK:1)
B(7,16,4,MOSSY_COBBLESTONE)
B(8,16,4,STONEBRICK:2)
B(0,0,5,STONEBRICK:2)
B(1,0,5,STONEBRICK:2)
B(2,0,5,STONEBRICK)
B(3,0,5,GRASS)
B(4,0,5,DIRT:1)
B(5,0,5,GRASS)
B(6,0,5,STONEBRICK)
B(7,0,5,STONEBRICK)
B(8,0,5,STONEBRICK:2)
B(9,0,5,STONEBRICK)
B(10,0,5,STONEBRICK)
B(11,0,5,STONEBRICK:1)
B(0,1,5,MOSSY_COBBLESTONE)
B(8,1,5,STONEBRICK:1)
B(9,1,5,STONEBRICK:2)
B(10,1,5,STONEBRICK)
B(11,1,5,STONEBRICK:1)
B(0,2,5,MOSSY_COBBLESTONE)
B(8,2,5,STONEBRICK:2)
B(9,2,5,STONEBRICK:1)
B(10,2,5,STONEBRICK:1)
B(11,2,5,STONEBRICK)
B(0,3,5,EMERALD_ORE)
B(8,3,5,STONEBRICK)
B(9,3,5,STONEBRICK)
B(10,3,5,STONEBRICK)
B(11,3,5,STONEBRICK)
B(0,4,5,MOSSY_COBBLESTONE)
B(8,4,5,STONEBRICK)
B(9,4,5,STONEBRICK:2)
B(10,4,5,STONEBRICK:1)
B(11,4,5,STONEBRICK:2)
B(0,5,5,MOSSY_COBBLESTONE)
B(8,5,5,MOSSY_COBBLESTONE)
B(0,6,5,MOSSY_COBBLESTONE)
B(8,6,5,STONE)
B(0,7,5,MOSSY_COBBLESTONE)
B(1,7,5,STONEBRICK:1)
B(7,7,5,STONEBRICK:1)
B(8,7,5,MOSSY_COBBLESTONE)
B(0,8,5,STONEBRICK:2)
B(1,8,5,MOSSY_COBBLESTONE)
B(2,8,5,STONEBRICK:1)
B(6,8,5,STONEBRICK:2)
B(7,8,5,STONE)
B(8,8,5,STONEBRICK)
B(9,8,5,STONEBRICK:1)
B(10,8,5,STONEBRICK:1)
B(11,8,5,STONEBRICK)
B(0,9,5,MOSSY_COBBLESTONE)
B(8,9,5,STONEBRICK:2)
B(9,9,5,STONEBRICK:1)
B(10,9,5,STONEBRICK:1)
B(11,9,5,STONEBRICK:2)
B(0,10,5,STONE)
B(8,10,5,STONEBRICK:1)
B(9,10,5,STONEBRICK:1)
B(10,10,5,STONEBRICK:2)
B(11,10,5,STONEBRICK:1)
B(0,11,5,MOSSY_COBBLESTONE)
B(8,11,5,STONEBRICK:2)
B(9,11,5,STONEBRICK:1)
B(10,11,5,STONEBRICK)
B(11,11,5,STONEBRICK:1)
B(0,12,5,MOSSY_COBBLESTONE)
B(8,12,5,STONEBRICK)
B(9,12,5,STONEBRICK)
B(10,12,5,STONEBRICK)
B(11,12,5,STONEBRICK:2)
B(0,13,5,MOSSY_COBBLESTONE)
B(8,13,5,MOSSY_COBBLESTONE)
B(0,14,5,EMERALD_ORE)
B(8,14,5,MOSSY_COBBLESTONE)
B(0,15,5,MOSSY_COBBLESTONE)
B(1,15,5,STONEBRICK:2)
B(7,15,5,STONEBRICK:2)
B(8,15,5,STONE)
B(0,16,5,STONEBRICK:2)
B(1,16,5,MOSSY_COBBLESTONE)
B(2,16,5,STONEBRICK:1)
B(6,16,5,STONEBRICK)
B(7,16,5,MOSSY_COBBLESTONE)
B(8,16,5,STONEBRICK)
B(0,0,6,STONEBRICK)
B(1,0,6,STONEBRICK)
B(2,0,6,STONEBRICK:2)
B(3,0,6,STONEBRICK)
B(4,0,6,STONEBRICK:1)
B(5,0,6,STONEBRICK:1)
B(6,0,6,STONEBRICK)
B(7,0,6,STONEBRICK)
B(8,0,6,STONEBRICK:1)
B(0,1,6,MOSSY_COBBLESTONE)
B(8,1,6,EMERALD_ORE)
B(0,2,6,MOSSY_COBBLESTONE)
B(8,2,6,STONE)
B(0,3,6,MOSSY_COBBLESTONE)
B(8,3,6,STONE)
B(0,4,6,EMERALD_ORE)
B(8,4,6,MOSSY_COBBLESTONE)
B(0,5,6,STONE)
B(8,5,6,MOSSY_COBBLESTONE)
B(0,6,6,MOSSY_COBBLESTONE)
B(8,6,6,STONE)
B(0,7,6,STONE)
B(1,7,6,STONEBRICK)
B(7,7,6,STONEBRICK:1)
B(8,7,6,STONE)
B(0,8,6,STONEBRICK:2)
B(1,8,6,MOSSY_COBBLESTONE)
B(2,8,6,STONEBRICK)
B(3,8,6,STONEBRICK:2)
B(4,8,6,STONEBRICK:1)
B(5,8,6,STONEBRICK:1)
B(6,8,6,STONEBRICK)
B(7,8,6,STONE)
B(8,8,6,STONEBRICK)
B(0,9,6,EMERALD_ORE)
B(8,9,6,STONE)
B(0,10,6,EMERALD_ORE)
B(8,10,6,STONE)
B(0,11,6,MOSSY_COBBLESTONE)
B(8,11,6,STONE)
B(0,12,6,MOSSY_COBBLESTONE)
B(8,12,6,STONE)
B(0,13,6,STONE)
B(8,13,6,MOSSY_COBBLESTONE)
B(0,14,6,EMERALD_ORE)
B(8,14,6,STONE)
B(0,15,6,MOSSY_COBBLESTONE)
B(1,15,6,STONEBRICK:1)
B(7,15,6,STONEBRICK:2)
B(8,15,6,MOSSY_COBBLESTONE)
B(0,16,6,STONEBRICK:1)
B(1,16,6,STONE)
B(2,16,6,STONEBRICK:1)
B(3,16,6,STONEBRICK:1)
B(4,16,6,STONEBRICK)
B(5,16,6,STONEBRICK:1)
B(6,16,6,STONEBRICK:2)
B(7,16,6,STONE)
B(8,16,6,STONEBRICK:2)
B(0,0,7,STONEBRICK)
B(1,0,7,STONEBRICK:1)
B(2,0,7,STONEBRICK)
B(3,0,7,STONEBRICK)
B(4,0,7,STONEBRICK:1)
B(5,0,7,STONEBRICK:2)
B(6,0,7,STONEBRICK:1)
B(7,0,7,STONEBRICK)
B(8,0,7,STONEBRICK:1)
B(0,1,7,MOSSY_COBBLESTONE)
B(1,1,7,STONE)
B(7,1,7,MOSSY_COBBLESTONE)
B(8,1,7,MOSSY_COBBLESTONE)
B(0,2,7,STONE)
B(1,2,7,MOSSY_COBBLESTONE)
B(7,2,7,MOSSY_COBBLESTONE)
B(8,2,7,STONE)
B(0,3,7,STONE)
B(1,3,7,EMERALD_ORE)
B(7,3,7,EMERALD_ORE)
B(8,3,7,STONE)
B(0,4,7,MOSSY_COBBLESTONE)
B(1,4,7,STONEBRICK:1)
B(7,4,7,STONEBRICK)
B(8,4,7,MOSSY_COBBLESTONE)
B(0,5,7,MOSSY_COBBLESTONE)
B(1,5,7,STONEBRICK:1)
B(7,5,7,STONEBRICK)
B(8,5,7,EMERALD_ORE)
B(0,6,7,STONE)
B(1,6,7,STONEBRICK)
B(7,6,7,STONEBRICK:2)
B(8,6,7,MOSSY_COBBLESTONE)
B(0,7,7,MOSSY_COBBLESTONE)
B(1,7,7,STONEBRICK:1)
B(2,7,7,STONEBRICK:1)
B(3,7,7,STONEBRICK:2)
B(4,7,7,STONEBRICK:1)
B(5,7,7,STONEBRICK:1)
B(6,7,7,STONEBRICK:1)
B(7,7,7,STONEBRICK:2)
B(8,7,7,MOSSY_COBBLESTONE)
B(0,8,7,STONEBRICK)
B(1,8,7,MOSSY_COBBLESTONE)
B(2,8,7,STONE)
B(3,8,7,MOSSY_COBBLESTONE)
B(4,8,7,STONE)
B(5,8,7,MOSSY_COBBLESTONE)
B(6,8,7,MOSSY_COBBLESTONE)
B(7,8,7,STONE)
B(8,8,7,STONEBRICK:1)
B(0,9,7,MOSSY_COBBLESTONE)
B(1,9,7,STONE)
B(7,9,7,MOSSY_COBBLESTONE)
B(8,9,7,STONE)
B(0,10,7,EMERALD_ORE)
B(1,10,7,MOSSY_COBBLESTONE)
B(7,10,7,MOSSY_COBBLESTONE)
B(8,10,7,STONE)
B(0,11,7,MOSSY_COBBLESTONE)
B(1,11,7,STONE)
B(7,11,7,STONE)
B(8,11,7,STONE)
B(0,12,7,STONE)
B(1,12,7,STONEBRICK)
B(7,12,7,STONEBRICK:1)
B(8,12,7,STONE)
B(0,13,7,MOSSY_COBBLESTONE)
B(1,13,7,STONEBRICK:1)
B(7,13,7,STONEBRICK:1)
B(8,13,7,EMERALD_ORE)
B(0,14,7,STONE)
B(1,14,7,STONEBRICK)
B(7,14,7,STONEBRICK)
B(8,14,7,MOSSY_COBBLESTONE)
B(0,15,7,MOSSY_COBBLESTONE)
B(1,15,7,STONEBRICK)
B(2,15,7,STONEBRICK:1)
B(3,15,7,STONEBRICK)
B(4,15,7,STONEBRICK:2)
B(5,15,7,STONEBRICK:1)
B(6,15,7,STONEBRICK)
B(7,15,7,STONEBRICK)
B(8,15,7,MOSSY_COBBLESTONE)
B(0,16,7,STONEBRICK)
B(1,16,7,STONE)
B(2,16,7,EMERALD_ORE)
B(3,16,7,STONE)
B(4,16,7,EMERALD_ORE)
B(5,16,7,STONE)
B(6,16,7,MOSSY_COBBLESTONE)
B(7,16,7,STONE)
B(8,16,7,STONEBRICK:2)
B(0,0,8,STONEBRICK:2)
B(1,0,8,STONEBRICK:1)
B(2,0,8,STONEBRICK:2)
B(3,0,8,STONEBRICK:2)
B(4,0,8,STONEBRICK)
B(5,0,8,STONEBRICK:1)
B(6,0,8,STONEBRICK:1)
B(7,0,8,STONEBRICK:2)
B(8,0,8,STONEBRICK:2)
B(9,0,8,STONEBRICK:2)
B(10,0,8,STONEBRICK:1)
B(11,0,8,STONEBRICK)
B(12,0,8,STONEBRICK:1)
B(13,0,8,STONEBRICK:2)
B(14,0,8,STONEBRICK:2)
B(15,0,8,STONEBRICK:1)
B(16,0,8,STONEBRICK:1)
B(0,1,8,STONEBRICK)
B(1,1,8,MOSSY_COBBLESTONE)
B(2,1,8,MOSSY_COBBLESTONE)
B(3,1,8,STONEBRICK:1)
B(5,1,8,STONEBRICK:1)
B(6,1,8,STONE)
B(7,1,8,EMERALD_ORE)
B(8,1,8,STONEBRICK:1)
B(9,1,8,MOSSY_COBBLESTONE)
B(10,1,8,STONE)
B(11,1,8,STONE)
B(12,1,8,MOSSY_COBBLESTONE)
B(13,1,8,MOSSY_COBBLESTONE)
B(14,1,8,STONE)
B(15,1,8,STONE)
B(16,1,8,STONEBRICK:1)
B(0,2,8,STONEBRICK)
B(1,2,8,MOSSY_COBBLESTONE)
B(2,2,8,STONE)
B(3,2,8,STONEBRICK:1)
B(5,2,8,STONEBRICK:2)
B(6,2,8,STONE)
B(7,2,8,MOSSY_COBBLESTONE)
B(8,2,8,STONEBRICK:2)
B(9,2,8,MOSSY_COBBLESTONE)
B(10,2,8,STONE)
B(11,2,8,MOSSY_COBBLESTONE)
B(12,2,8,STONE)
B(13,2,8,MOSSY_COBBLESTONE)
B(14,2,8,MOSSY_COBBLESTONE)
B(15,2,8,MOSSY_COBBLESTONE)
B(16,2,8,STONEBRICK)
B(0,3,8,STONEBRICK)
B(1,3,8,MOSSY_COBBLESTONE)
B(2,3,8,MOSSY_COBBLESTONE)
B(3,3,8,STONEBRICK:1)
B(5,3,8,STONEBRICK:1)
B(6,3,8,MOSSY_COBBLESTONE)
B(7,3,8,STONE)
B(8,3,8,STONEBRICK:1)
B(9,3,8,STONE)
B(10,3,8,MOSSY_COBBLESTONE)
B(11,3,8,STONE)
B(12,3,8,STONE)
B(13,3,8,EMERALD_ORE)
B(14,3,8,STONE)
B(15,3,8,EMERALD_ORE)
B(16,3,8,STONEBRICK:2)
B(0,4,8,STONEBRICK:2)
B(1,4,8,MOSSY_COBBLESTONE)
B(2,4,8,MOSSY_COBBLESTONE)
B(3,4,8,STONEBRICK)
B(4,4,8,STONEBRICK)
B(5,4,8,STONEBRICK)
B(6,4,8,STONE)
B(7,4,8,STONE)
B(8,4,8,STONEBRICK)
B(9,4,8,MOSSY_COBBLESTONE)
B(10,4,8,MOSSY_COBBLESTONE)
B(11,4,8,MOSSY_COBBLESTONE)
B(12,4,8,MOSSY_COBBLESTONE)
B(13,4,8,MOSSY_COBBLESTONE)
B(14,4,8,EMERALD_ORE)
B(15,4,8,STONE)
B(16,4,8,STONEBRICK)
B(0,5,8,STONEBRICK)
B(1,5,8,STONE)
B(2,5,8,STONE)
B(3,5,8,MOSSY_COBBLESTONE)
B(4,5,8,STONE)
B(5,5,8,MOSSY_COBBLESTONE)
B(6,5,8,MOSSY_COBBLESTONE)
B(7,5,8,STONE)
B(8,5,8,STONEBRICK)
B(9,5,8,STONE)
B(10,5,8,MOSSY_COBBLESTONE)
B(11,5,8,MOSSY_COBBLESTONE)
B(12,5,8,STONE)
B(13,5,8,STONE)
B(14,5,8,STONE)
B(15,5,8,MOSSY_COBBLESTONE)
B(16,5,8,STONEBRICK:2)
B(0,6,8,STONEBRICK:2)
B(1,6,8,MOSSY_COBBLESTONE)
B(2,6,8,STONE)
B(3,6,8,STONE)
B(4,6,8,STONE)
B(5,6,8,MOSSY_COBBLESTONE)
B(6,6,8,MOSSY_COBBLESTONE)
B(7,6,8,MOSSY_COBBLESTONE)
B(8,6,8,STONEBRICK:2)
B(9,6,8,STONE)
B(10,6,8,STONE)
B(11,6,8,MOSSY_COBBLESTONE)
B(12,6,8,STONE)
B(13,6,8,MOSSY_COBBLESTONE)
B(14,6,8,STONE)
B(15,6,8,EMERALD_ORE)
B(16,6,8,STONEBRICK)
B(0,7,8,STONEBRICK:2)
B(1,7,8,MOSSY_COBBLESTONE)
B(2,7,8,MOSSY_COBBLESTONE)
B(3,7,8,STONE)
B(4,7,8,STONE)
B(5,7,8,STONE)
B(6,7,8,MOSSY_COBBLESTONE)
B(7,7,8,STONE)
B(8,7,8,STONEBRICK:1)
B(9,7,8,MOSSY_COBBLESTONE)
B(10,7,8,MOSSY_COBBLESTONE)
B(11,7,8,STONE)
B(12,7,8,STONE)
B(13,7,8,STONE)
B(14,7,8,STONE)
B(15,7,8,MOSSY_COBBLESTONE)
B(16,7,8,STONEBRICK)
B(0,8,8,STONEBRICK)
B(1,8,8,MOSSY_COBBLESTONE)
B(2,8,8,MOSSY_COBBLESTONE)
B(3,8,8,STONEBRICK:1)
B(4,8,8,STONEBRICK)
B(5,8,8,STONEBRICK:1)
B(6,8,8,MOSSY_COBBLESTONE)
B(7,8,8,STONE)
B(8,8,8,STONEBRICK:2)
B(9,8,8,MOSSY_COBBLESTONE)
B(10,8,8,STONE)
B(11,8,8,STONE)
B(12,8,8,STONE)
B(13,8,8,MOSSY_COBBLESTONE)
B(14,8,8,MOSSY_COBBLESTONE)
B(15,8,8,STONE)
B(16,8,8,STONEBRICK:1)
B(0,9,8,STONEBRICK:1)
B(1,9,8,STONE)
B(2,9,8,STONE)
B(3,9,8,STONEBRICK)
B(5,9,8,STONEBRICK)
B(6,9,8,MOSSY_COBBLESTONE)
B(7,9,8,EMERALD_ORE)
B(8,9,8,STONEBRICK:2)
B(9,9,8,STONE)
B(10,9,8,STONE)
B(11,9,8,MOSSY_COBBLESTONE)
B(12,9,8,MOSSY_COBBLESTONE)
B(13,9,8,MOSSY_COBBLESTONE)
B(14,9,8,STONE)
B(15,9,8,MOSSY_COBBLESTONE)
B(16,9,8,STONEBRICK:2)
B(0,10,8,STONEBRICK:1)
B(1,10,8,MOSSY_COBBLESTONE)
B(2,10,8,MOSSY_COBBLESTONE)
B(3,10,8,STONEBRICK:2)
B(5,10,8,STONEBRICK:2)
B(6,10,8,STONE)
B(7,10,8,MOSSY_COBBLESTONE)
B(8,10,8,STONEBRICK)
B(9,10,8,EMERALD_ORE)
B(10,10,8,STONE)
B(11,10,8,STONE)
B(12,10,8,STONE)
B(13,10,8,STONE)
B(14,10,8,STONE)
B(15,10,8,MOSSY_COBBLESTONE)
B(16,10,8,STONEBRICK)
B(0,11,8,STONEBRICK:1)
B(1,11,8,MOSSY_COBBLESTONE)
B(2,11,8,STONE)
B(3,11,8,STONEBRICK)
B(5,11,8,STONEBRICK:1)
B(6,11,8,MOSSY_COBBLESTONE)
B(7,11,8,MOSSY_COBBLESTONE)
B(8,11,8,STONEBRICK)
B(9,11,8,STONE)
B(10,11,8,MOSSY_COBBLESTONE)
B(11,11,8,MOSSY_COBBLESTONE)
B(12,11,8,MOSSY_COBBLESTONE)
B(13,11,8,MOSSY_COBBLESTONE)
B(14,11,8,STONE)
B(15,11,8,STONE)
B(16,11,8,STONEBRICK:2)
B(0,12,8,STONEBRICK)
B(1,12,8,STONE)
B(2,12,8,STONE)
B(3,12,8,STONEBRICK:1)
B(4,12,8,STONEBRICK:1)
B(5,12,8,STONEBRICK:1)
B(6,12,8,STONE)
B(7,12,8,MOSSY_COBBLESTONE)
B(8,12,8,STONEBRICK)
B(9,12,8,STONE)
B(10,12,8,MOSSY_COBBLESTONE)
B(11,12,8,MOSSY_COBBLESTONE)
B(12,12,8,MOSSY_COBBLESTONE)
B(13,12,8,EMERALD_ORE)
B(14,12,8,STONE)
B(15,12,8,STONE)
B(16,12,8,STONEBRICK:1)
B(0,13,8,STONEBRICK)
B(1,13,8,MOSSY_COBBLESTONE)
B(2,13,8,STONE)
B(3,13,8,STONE)
B(4,13,8,MOSSY_COBBLESTONE)
B(5,13,8,STONE)
B(6,13,8,STONE)
B(7,13,8,STONE)
B(8,13,8,STONEBRICK:2)
B(9,13,8,STONE)
B(10,13,8,STONE)
B(11,13,8,MOSSY_COBBLESTONE)
B(12,13,8,MOSSY_COBBLESTONE)
B(13,13,8,STONE)
B(14,13,8,STONE)
B(15,13,8,STONE)
B(16,13,8,STONEBRICK)
B(0,14,8,STONEBRICK)
B(1,14,8,MOSSY_COBBLESTONE)
B(2,14,8,EMERALD_ORE)
B(3,14,8,STONE)
B(4,14,8,MOSSY_COBBLESTONE)
B(5,14,8,STONE)
B(6,14,8,MOSSY_COBBLESTONE)
B(7,14,8,STONE)
B(8,14,8,STONEBRICK:2)
B(9,14,8,EMERALD_ORE)
B(10,14,8,STONE)
B(11,14,8,STONE)
B(12,14,8,MOSSY_COBBLESTONE)
B(13,14,8,MOSSY_COBBLESTONE)
B(14,14,8,STONE)
B(15,14,8,MOSSY_COBBLESTONE)
B(16,14,8,STONEBRICK:1)
B(0,15,8,STONEBRICK:1)
B(1,15,8,STONE)
B(2,15,8,STONE)
B(3,15,8,MOSSY_COBBLESTONE)
B(4,15,8,STONE)
B(5,15,8,STONE)
B(6,15,8,MOSSY_COBBLESTONE)
B(7,15,8,MOSSY_COBBLESTONE)
B(8,15,8,STONEBRICK:1)
B(9,15,8,STONE)
B(10,15,8,MOSSY_COBBLESTONE)
B(11,15,8,STONE)
B(12,15,8,STONE)
B(13,15,8,STONE)
B(14,15,8,MOSSY_COBBLESTONE)
B(15,15,8,STONE)
B(16,15,8,STONEBRICK)
B(0,16,8,STONEBRICK:2)
B(1,16,8,STONEBRICK:2)
B(2,16,8,STONEBRICK)
B(3,16,8,STONEBRICK:2)
B(4,16,8,STONEBRICK:2)
B(5,16,8,STONEBRICK)
B(6,16,8,STONEBRICK:2)
B(7,16,8,STONEBRICK:1)
B(8,16,8,STONEBRICK:2)
B(9,16,8,STONEBRICK:1)
B(10,16,8,STONEBRICK:2)
B(11,16,8,STONEBRICK:2)
B(12,16,8,STONEBRICK:2)
B(13,16,8,STONEBRICK)
B(14,16,8,STONEBRICK:1)
B(15,16,8,STONEBRICK:1)
B(16,16,8,STONEBRICK:2)
B(0,0,9,STONEBRICK)
B(1,0,9,STONEBRICK)
B(2,0,9,STONEBRICK:1)
B(3,0,9,STONEBRICK:1)
B(4,0,9,STONEBRICK)
B(5,0,9,STONEBRICK:1)
B(6,0,9,STONEBRICK)
B(7,0,9,STONEBRICK:2)
B(8,0,9,STONEBRICK:2)
B(9,0,9,STONEBRICK)
B(10,0,9,STONEBRICK)
B(11,0,9,STONEBRICK)
B(12,0,9,STONEBRICK:2)
B(13,0,9,STONEBRICK:2)
B(14,0,9,STONEBRICK:1)
B(15,0,9,STONEBRICK)
B(16,0,9,STONEBRICK)
B(0,1,9,MOSSY_COBBLESTONE)
B(1,1,9,MOSSY_COBBLESTONE)
B(7,1,9,MOSSY_COBBLESTONE)
B(8,1,9,EMERALD_ORE)
B(9,1,9,MOSSY_COBBLESTONE)
B(12,1,9,STONEBRICK:3)
B(15,1,9,MOSSY_COBBLESTONE)
B(16,1,9,STONE)
B(0,2,9,STONE)
B(1,2,9,STONE)
B(7,2,9,STONE)
B(8,2,9,EMERALD_ORE)
B(9,2,9,STONE)
B(15,2,9,MOSSY_COBBLESTONE)
B(16,2,9,MOSSY_COBBLESTONE)
B(0,3,9,STONE)
B(1,3,9,MOSSY_COBBLESTONE)
B(7,3,9,EMERALD_ORE)
B(8,3,9,EMERALD_ORE)
B(9,3,9,MOSSY_COBBLESTONE)
B(15,3,9,MOSSY_COBBLESTONE)
B(16,3,9,STONE)
B(0,4,9,MOSSY_COBBLESTONE)
B(1,4,9,MOSSY_COBBLESTONE)
B(7,4,9,EMERALD_ORE)
B(8,4,9,MOSSY_COBBLESTONE)
B(9,4,9,STONE)
B(15,4,9,MOSSY_COBBLESTONE)
B(16,4,9,MOSSY_COBBLESTONE)
B(0,5,9,MOSSY_COBBLESTONE)
B(1,5,9,MOSSY_COBBLESTONE)
B(7,5,9,MOSSY_COBBLESTONE)
B(8,5,9,STONE)
B(9,5,9,STONE)
B(15,5,9,STONE)
B(16,5,9,STONE)
B(0,6,9,MOSSY_COBBLESTONE)
B(1,6,9,STONE)
B(7,6,9,STONE)
B(8,6,9,STONE)
B(9,6,9,MOSSY_COBBLESTONE)
B(15,6,9,MOSSY_COBBLESTONE)
B(16,6,9,MOSSY_COBBLESTONE)
B(0,7,9,EMERALD_ORE)
B(1,7,9,EMERALD_ORE)
B(7,7,9,STONE)
B(8,7,9,STONE)
B(9,7,9,STONE)
B(15,7,9,MOSSY_COBBLESTONE)
B(16,7,9,STONE)
B(0,8,9,MOSSY_COBBLESTONE)
B(1,8,9,MOSSY_COBBLESTONE)
B(7,8,9,STONE)
B(8,8,9,MOSSY_COBBLESTONE)
B(9,8,9,MOSSY_COBBLESTONE)
B(15,8,9,EMERALD_ORE)
B(16,8,9,MOSSY_COBBLESTONE)
B(0,9,9,STONE)
B(1,9,9,STONE)
B(7,9,9,MOSSY_COBBLESTONE)
B(8,9,9,STONE)
B(9,9,9,MOSSY_COBBLESTONE)
B(15,9,9,MOSSY_COBBLESTONE)
B(16,9,9,MOSSY_COBBLESTONE)
B(0,10,9,STONE)
B(1,10,9,MOSSY_COBBLESTONE)
B(7,10,9,STONE)
B(8,10,9,STONE)
B(9,10,9,MOSSY_COBBLESTONE)
B(15,10,9,EMERALD_ORE)
B(16,10,9,STONE)
B(0,11,9,MOSSY_COBBLESTONE)
B(1,11,9,MOSSY_COBBLESTONE)
B(7,11,9,STONE)
B(8,11,9,MOSSY_COBBLESTONE)
B(9,11,9,STONE)
B(15,11,9,STONE)
B(16,11,9,MOSSY_COBBLESTONE)
B(0,12,9,EMERALD_ORE)
B(1,12,9,STONEBRICK)
B(7,12,9,STONEBRICK:1)
B(8,12,9,STONEBRICK:2)
B(9,12,9,STONEBRICK:2)
B(15,12,9,STONEBRICK)
B(16,12,9,MOSSY_COBBLESTONE)
B(0,13,9,MOSSY_COBBLESTONE)
B(1,13,9,STONEBRICK:1)
B(7,13,9,STONEBRICK:2)
B(8,13,9,STONEBRICK:1)
B(9,13,9,STONEBRICK:1)
B(15,13,9,STONEBRICK:1)
B(16,13,9,STONE)
B(0,14,9,STONE)
B(1,14,9,STONEBRICK:2)
B(7,14,9,STONEBRICK:1)
B(8,14,9,STONEBRICK:1)
B(9,14,9,STONEBRICK:1)
B(15,14,9,STONEBRICK:2)
B(16,14,9,EMERALD_ORE)
B(0,15,9,STONE)
B(1,15,9,STONEBRICK:2)
B(2,15,9,STONEBRICK:1)
B(3,15,9,STONEBRICK:1)
B(4,15,9,STONEBRICK)
B(5,15,9,STONEBRICK:2)
B(6,15,9,STONEBRICK)
B(7,15,9,STONEBRICK:1)
B(8,15,9,STONEBRICK:2)
B(9,15,9,STONEBRICK:2)
B(10,15,9,STONEBRICK:1)
B(11,15,9,STONEBRICK:1)
B(12,15,9,STONEBRICK:1)
B(13,15,9,STONEBRICK:2)
B(14,15,9,STONEBRICK:1)
B(15,15,9,STONEBRICK:2)
B(16,15,9,MOSSY_COBBLESTONE)
B(0,16,9,STONEBRICK:2)
B(1,16,9,MOSSY_COBBLESTONE)
B(2,16,9,MOSSY_COBBLESTONE)
B(3,16,9,STONE)
B(4,16,9,MOSSY_COBBLESTONE)
B(5,16,9,MOSSY_COBBLESTONE)
B(6,16,9,STONE)
B(7,16,9,MOSSY_COBBLESTONE)
B(8,16,9,STONEBRICK:2)
B(9,16,9,STONE)
B(10,16,9,STONE)
B(11,16,9,MOSSY_COBBLESTONE)
B(12,16,9,STONE)
B(13,16,9,MOSSY_COBBLESTONE)
B(14,16,9,MOSSY_COBBLESTONE)
B(15,16,9,STONE)
B(16,16,9,STONEBRICK:1)
B(0,0,10,STONEBRICK:2)
B(1,0,10,STONEBRICK:2)
B(2,0,10,STONEBRICK:1)
B(3,0,10,STONEBRICK:2)
B(4,0,10,STONEBRICK:2)
B(5,0,10,STONEBRICK)
B(6,0,10,STONEBRICK:2)
B(7,0,10,STONEBRICK)
B(8,0,10,STONEBRICK:2)
B(9,0,10,STONEBRICK)
B(10,0,10,STONEBRICK:1)
B(11,0,10,STONEBRICK)
B(12,0,10,STONEBRICK:1)
B(13,0,10,STONEBRICK:2)
B(14,0,10,STONEBRICK)
B(15,0,10,STONEBRICK:2)
B(16,0,10,STONEBRICK:1)
B(0,1,10,MOSSY_COBBLESTONE)
B(16,1,10,MOSSY_COBBLESTONE)
B(0,2,10,EMERALD_ORE)
B(16,2,10,STONE)
B(0,3,10,STONE)
B(16,3,10,EMERALD_ORE)
B(0,4,10,MOSSY_COBBLESTONE)
B(16,4,10,MOSSY_COBBLESTONE)
B(0,5,10,STONE)
B(16,5,10,STONE)
B(0,6,10,MOSSY_COBBLESTONE)
B(16,6,10,MOSSY_COBBLESTONE)
B(0,7,10,MOSSY_COBBLESTONE)
B(16,7,10,EMERALD_ORE)
B(0,8,10,STONE)
B(16,8,10,MOSSY_COBBLESTONE)
B(0,9,10,MOSSY_COBBLESTONE)
B(16,9,10,MOSSY_COBBLESTONE)
B(0,10,10,MOSSY_COBBLESTONE)
B(16,10,10,STONE)
B(0,11,10,STONE)
B(16,11,10,STONE)
B(0,12,10,MOSSY_COBBLESTONE)
B(16,12,10,STONE)
B(0,13,10,STONE)
B(16,13,10,STONE)
B(0,14,10,MOSSY_COBBLESTONE)
B(16,14,10,STONE)
B(0,15,10,STONE)
B(1,15,10,STONEBRICK:2)
B(7,15,10,STONEBRICK)
B(8,15,10,STONEBRICK:2)
B(9,15,10,STONEBRICK:2)
B(15,15,10,STONEBRICK)
B(16,15,10,STONE)
B(0,16,10,STONEBRICK:2)
B(1,16,10,MOSSY_COBBLESTONE)
B(2,16,10,STONEBRICK:1)
B(3,16,10,STONEBRICK:1)
B(4,16,10,STONEBRICK)
B(5,16,10,STONEBRICK)
B(6,16,10,STONEBRICK)
B(7,16,10,STONE)
B(8,16,10,STONEBRICK)
B(9,16,10,MOSSY_COBBLESTONE)
B(10,16,10,STONEBRICK:2)
B(11,16,10,STONEBRICK:2)
B(12,16,10,STONEBRICK:1)
B(13,16,10,STONEBRICK)
B(14,16,10,STONEBRICK:1)
B(15,16,10,STONE)
B(16,16,10,STONEBRICK:1)
B(0,0,11,STONEBRICK:1)
B(1,0,11,STONEBRICK:2)
B(2,0,11,STONEBRICK:2)
B(3,0,11,GRASS)
B(4,0,11,GRASS)
B(5,0,11,DIRT:1)
B(6,0,11,DIRT:1)
B(7,0,11,GRASS)
B(8,0,11,DIRT:1)
B(9,0,11,DIRT:1)
B(10,0,11,GRASS)
B(11,0,11,GRASS)
B(12,0,11,GRASS)
B(13,0,11,GRASS)
B(14,0,11,STONEBRICK:2)
B(15,0,11,STONEBRICK:1)
B(16,0,11,STONEBRICK:2)
B(0,1,11,STONEBRICK:2)
B(16,1,11,STONEBRICK)
B(0,2,11,STONEBRICK:1)
B(16,2,11,STONEBRICK:2)
B(0,3,11,STONEBRICK:1)
B(16,3,11,STONEBRICK:2)
B(0,4,11,STONEBRICK:1)
B(16,4,11,STONEBRICK:1)
B(0,5,11,MOSSY_COBBLESTONE)
B(16,5,11,STONE)
B(0,6,11,MOSSY_COBBLESTONE)
B(16,6,11,STONE)
B(0,7,11,MOSSY_COBBLESTONE)
B(16,7,11,STONE)
B(0,8,11,EMERALD_ORE)
B(16,8,11,STONE)
B(0,9,11,MOSSY_COBBLESTONE)
B(16,9,11,MOSSY_COBBLESTONE)
B(0,10,11,EMERALD_ORE)
B(16,10,11,MOSSY_COBBLESTONE)
B(0,11,11,MOSSY_COBBLESTONE)
B(16,11,11,MOSSY_COBBLESTONE)
B(0,12,11,STONE)
B(16,12,11,STONE)
B(0,13,11,STONE)
B(16,13,11,MOSSY_COBBLESTONE)
B(0,14,11,EMERALD_ORE)
B(16,14,11,STONE)
B(0,15,11,STONE)
B(1,15,11,STONEBRICK:1)
B(7,15,11,STONEBRICK:1)
B(8,15,11,STONEBRICK:2)
B(9,15,11,STONEBRICK:2)
B(15,15,11,STONEBRICK)
B(16,15,11,MOSSY_COBBLESTONE)
B(0,16,11,STONEBRICK)
B(1,16,11,STONE)
B(2,16,11,STONEBRICK:2)
B(6,16,11,STONEBRICK:2)
B(7,16,11,MOSSY_COBBLESTONE)
B(8,16,11,STONEBRICK)
B(9,16,11,STONE)
B(10,16,11,STONEBRICK:1)
B(14,16,11,STONEBRICK:2)
B(15,16,11,MOSSY_COBBLESTONE)
B(16,16,11,STONEBRICK)
B(0,0,12,STONEBRICK)
B(1,0,12,STONEBRICK)
B(2,0,12,STONEBRICK)
B(3,0,12,GRASS)
B(4,0,12,GRASS)
B(5,0,12,DIRT:1)
B(6,0,12,DIRT:1)
B(7,0,12,DIRT:1)
B(8,0,12,GRASS)
B(9,0,12,GRASS)
B(10,0,12,GRASS)
B(11,0,12,GRASS)
B(12,0,12,DIRT:1)
B(13,0,12,DIRT:1)
B(14,0,12,STONEBRICK:2)
B(15,0,12,STONEBRICK)
B(16,0,12,STONEBRICK)
B(0,4,12,STONEBRICK:2)
B(16,4,12,STONEBRICK:1)
B(0,5,12,MOSSY_COBBLESTONE)
B(16,5,12,MOSSY_COBBLESTONE)
B(0,6,12,STONE)
B(16,6,12,STONE)
B(0,7,12,STONE)
B(16,7,12,STONE)
B(0,8,12,MOSSY_COBBLESTONE)
B(16,8,12,MOSSY_COBBLESTONE)
B(0,9,12,EMERALD_ORE)
B(16,9,12,STONE)
B(0,10,12,MOSSY_COBBLESTONE)
B(16,10,12,MOSSY_COBBLESTONE)
B(0,11,12,STONE)
B(16,11,12,MOSSY_COBBLESTONE)
B(0,12,12,MOSSY_COBBLESTONE)
B(16,12,12,STONE)
B(0,13,12,STONE)
B(16,13,12,EMERALD_ORE)
B(0,14,12,MOSSY_COBBLESTONE)
B(16,14,12,MOSSY_COBBLESTONE)
B(0,15,12,MOSSY_COBBLESTONE)
B(1,15,12,STONEBRICK:1)
B(7,15,12,STONEBRICK:1)
B(8,15,12,STONEBRICK:1)
B(9,15,12,STONEBRICK)
B(15,15,12,STONEBRICK:1)
B(16,15,12,MOSSY_COBBLESTONE)
B(0,16,12,STONEBRICK:2)
B(1,16,12,MOSSY_COBBLESTONE)
B(2,16,12,STONEBRICK:1)
B(6,16,12,STONEBRICK:2)
B(7,16,12,MOSSY_COBBLESTONE)
B(8,16,12,STONEBRICK:1)
B(9,16,12,STONE)
B(10,16,12,STONEBRICK:2)
B(14,16,12,STONEBRICK:2)
B(15,16,12,MOSSY_COBBLESTONE)
B(16,16,12,STONEBRICK:1)
B(0,0,13,STONEBRICK:1)
B(1,0,13,STONEBRICK)
B(2,0,13,STONEBRICK:1)
B(3,0,13,GRASS)
B(4,0,13,DIRT:1)
B(5,0,13,GRASS)
B(6,0,13,GRASS)
B(7,0,13,DIRT:1)
B(8,0,13,DIRT:1)
B(9,0,13,GRASS)
B(10,0,13,DIRT:1)
B(11,0,13,GRASS)
B(12,0,13,GRASS)
B(13,0,13,DIRT:1)
B(14,0,13,STONEBRICK)
B(15,0,13,STONEBRICK)
B(16,0,13,STONEBRICK:2)
B(0,1,13,STONEBRICK:1)
B(16,1,13,STONEBRICK)
B(0,2,13,STONEBRICK)
B(16,2,13,STONEBRICK:1)
B(0,3,13,STONEBRICK)
B(16,3,13,STONEBRICK)
B(0,4,13,STONEBRICK:2)
B(16,4,13,STONEBRICK)
B(0,5,13,MOSSY_COBBLESTONE)
B(16,5,13,MOSSY_COBBLESTONE)
B(0,6,13,MOSSY_COBBLESTONE)
B(16,6,13,STONE)
B(0,7,13,STONE)
B(16,7,13,STONE)
B(0,8,13,STONE)
B(16,8,13,STONE)
B(0,9,13,MOSSY_COBBLESTONE)
B(16,9,13,STONE)
B(0,10,13,MOSSY_COBBLESTONE)
B(16,10,13,STONE)
B(0,11,13,MOSSY_COBBLESTONE)
B(16,11,13,MOSSY_COBBLESTONE)
B(0,12,13,STONE)
B(16,12,13,EMERALD_ORE)
B(0,13,13,STONE)
B(16,13,13,STONE)
B(0,14,13,STONE)
B(16,14,13,STONE)
B(0,15,13,STONE)
B(1,15,13,STONEBRICK:2)
B(7,15,13,STONEBRICK)
B(8,15,13,STONEBRICK:2)
B(9,15,13,STONEBRICK:1)
B(15,15,13,STONEBRICK:1)
B(16,15,13,STONE)
B(0,16,13,STONEBRICK:2)
B(1,16,13,MOSSY_COBBLESTONE)
B(2,16,13,STONEBRICK:1)
B(6,16,13,STONEBRICK:2)
B(7,16,13,STONE)
B(8,16,13,STONEBRICK)
B(9,16,13,MOSSY_COBBLESTONE)
B(10,16,13,STONEBRICK)
B(14,16,13,STONEBRICK:1)
B(15,16,13,STONE)
B(16,16,13,STONEBRICK:1)
B(0,0,14,STONEBRICK:1)
B(1,0,14,STONEBRICK:2)
B(2,0,14,STONEBRICK:1)
B(3,0,14,STONEBRICK)
B(4,0,14,STONEBRICK:1)
B(5,0,14,STONEBRICK:2)
B(6,0,14,STONEBRICK:2)
B(7,0,14,STONEBRICK)
B(8,0,14,STONEBRICK:1)
B(9,0,14,STONEBRICK:1)
B(10,0,14,STONEBRICK)
B(11,0,14,STONEBRICK:2)
B(12,0,14,STONEBRICK:2)
B(13,0,14,STONEBRICK:1)
B(14,0,14,STONEBRICK)
B(15,0,14,STONEBRICK)
B(16,0,14,STONEBRICK:2)
B(0,1,14,STONE)
B(16,1,14,EMERALD_ORE)
B(0,2,14,STONE)
B(16,2,14,STONE)
B(0,3,14,EMERALD_ORE)
B(16,3,14,STONE)
B(0,4,14,STONE)
B(16,4,14,STONE)
B(0,5,14,MOSSY_COBBLESTONE)
B(16,5,14,MOSSY_COBBLESTONE)
B(0,6,14,MOSSY_COBBLESTONE)
B(16,6,14,EMERALD_ORE)
B(0,7,14,EMERALD_ORE)
B(16,7,14,MOSSY_COBBLESTONE)
B(0,8,14,MOSSY_COBBLESTONE)
B(16,8,14,STONE)
B(0,9,14,STONE)
B(16,9,14,MOSSY_COBBLESTONE)
B(0,10,14,STONE)
B(16,10,14,EMERALD_ORE)
B(0,11,14,MOSSY_COBBLESTONE)
B(16,11,14,MOSSY_COBBLESTONE)
B(0,12,14,MOSSY_COBBLESTONE)
B(16,12,14,STONE)
B(0,13,14,STONE)
B(16,13,14,STONE)
B(0,14,14,MOSSY_COBBLESTONE)
B(16,14,14,MOSSY_COBBLESTONE)
B(0,15,14,MOSSY_COBBLESTONE)
B(1,15,14,STONEBRICK:2)
B(7,15,14,STONEBRICK)
B(8,15,14,STONEBRICK:2)
B(9,15,14,STONEBRICK)
B(15,15,14,STONEBRICK:2)
B(16,15,14,STONE)
B(0,16,14,STONEBRICK:1)
B(1,16,14,MOSSY_COBBLESTONE)
B(2,16,14,STONEBRICK:2)
B(3,16,14,STONEBRICK:1)
B(4,16,14,STONEBRICK:1)
B(5,16,14,STONEBRICK:1)
B(6,16,14,STONEBRICK:1)
B(7,16,14,MOSSY_COBBLESTONE)
B(8,16,14,STONEBRICK:2)
B(9,16,14,STONE)
B(10,16,14,STONEBRICK)
B(11,16,14,STONEBRICK)
B(12,16,14,STONEBRICK:1)
B(13,16,14,STONEBRICK)
B(14,16,14,STONEBRICK:1)
B(15,16,14,STONE)
B(16,16,14,STONEBRICK:2)
B(0,0,15,STONEBRICK:2)
B(1,0,15,STONEBRICK:1)
B(2,0,15,STONEBRICK:1)
B(3,0,15,STONEBRICK)
B(4,0,15,STONEBRICK:1)
B(5,0,15,STONEBRICK:1)
B(6,0,15,STONEBRICK:1)
B(7,0,15,STONEBRICK:1)
B(8,0,15,STONEBRICK:2)
B(9,0,15,STONEBRICK:2)
B(10,0,15,STONEBRICK:2)
B(11,0,15,STONEBRICK:1)
B(12,0,15,STONEBRICK:2)
B(13,0,15,STONEBRICK)
B(14,0,15,STONEBRICK:1)
B(15,0,15,STONEBRICK)
B(16,0,15,STONEBRICK)
B(0,1,15,MOSSY_COBBLESTONE)
B(1,1,15,MOSSY_COBBLESTONE)
B(4,1,15,STONEBRICK:3)
B(7,1,15,EMERALD_ORE)
B(8,1,15,MOSSY_COBBLESTONE)
B(9,1,15,STONE)
B(15,1,15,STONE)
B(16,1,15,MOSSY_COBBLESTONE)
B(0,2,15,MOSSY_COBBLESTONE)
B(1,2,15,MOSSY_COBBLESTONE)
B(7,2,15,EMERALD_ORE)
B(8,2,15,STONE)
B(9,2,15,MOSSY_COBBLESTONE)
B(15,2,15,MOSSY_COBBLESTONE)
B(16,2,15,MOSSY_COBBLESTONE)
B(0,3,15,MOSSY_COBBLESTONE)
B(1,3,15,STONE)
B(7,3,15,EMERALD_ORE)
B(8,3,15,STONE)
B(9,3,15,STONE)
B(15,3,15,STONE)
B(16,3,15,MOSSY_COBBLESTONE)
B(0,4,15,EMERALD_ORE)
B(1,4,15,STONE)
B(7,4,15,MOSSY_COBBLESTONE)
B(8,4,15,STONE)
B(9,4,15,STONE)
B(15,4,15,MOSSY_COBBLESTONE)
B(16,4,15,EMERALD_ORE)
B(0,5,15,STONE)
B(1,5,15,EMERALD_ORE)
B(7,5,15,EMERALD_ORE)
B(8,5,15,STONE)
B(9,5,15,MOSSY_COBBLESTONE)
B(15,5,15,MOSSY_COBBLESTONE)
B(16,5,15,STONE)
B(0,6,15,STONE)
B(1,6,15,STONE)
B(7,6,15,MOSSY_COBBLESTONE)
B(8,6,15,STONE)
B(9,6,15,STONE)
B(15,6,15,MOSSY_COBBLESTONE)
B(16,6,15,STONE)
B(0,7,15,STONE)
B(1,7,15,MOSSY_COBBLESTONE)
B(7,7,15,EMERALD_ORE)
B(8,7,15,STONE)
B(9,7,15,STONE)
B(15,7,15,MOSSY_COBBLESTONE)
B(16,7,15,MOSSY_COBBLESTONE)
B(0,8,15,MOSSY_COBBLESTONE)
B(1,8,15,STONE)
B(7,8,15,STONE)
B(8,8,15,STONE)
B(9,8,15,STONE)
B(15,8,15,MOSSY_COBBLESTONE)
B(16,8,15,STONE)
B(0,9,15,STONE)
B(1,9,15,STONE)
B(7,9,15,STONE)
B(8,9,15,MOSSY_COBBLESTONE)
B(9,9,15,MOSSY_COBBLESTONE)
B(15,9,15,MOSSY_COBBLESTONE)
B(16,9,15,MOSSY_COBBLESTONE)
B(0,10,15,STONE)
B(1,10,15,STONE)
B(7,10,15,STONE)
B(8,10,15,STONE)
B(9,10,15,STONE)
B(15,10,15,STONE)
B(16,10,15,STONE)
B(0,11,15,MOSSY_COBBLESTONE)
B(1,11,15,MOSSY_COBBLESTONE)
B(7,11,15,EMERALD_ORE)
B(8,11,15,STONE)
B(9,11,15,MOSSY_COBBLESTONE)
B(15,11,15,STONE)
B(16,11,15,MOSSY_COBBLESTONE)
B(0,12,15,STONE)
B(1,12,15,STONEBRICK:1)
B(7,12,15,STONEBRICK:1)
B(8,12,15,STONEBRICK:1)
B(9,12,15,STONEBRICK:1)
B(15,12,15,STONEBRICK)
B(16,12,15,EMERALD_ORE)
B(0,13,15,EMERALD_ORE)
B(1,13,15,STONEBRICK:1)
B(7,13,15,STONEBRICK)
B(8,13,15,STONEBRICK:1)
B(9,13,15,STONEBRICK)
B(15,13,15,STONEBRICK:1)
B(16,13,15,MOSSY_COBBLESTONE)
B(0,14,15,STONE)
B(1,14,15,STONEBRICK:1)
B(7,14,15,STONEBRICK:2)
B(8,14,15,STONEBRICK:1)
B(9,14,15,STONEBRICK)
B(15,14,15,STONEBRICK)
B(16,14,15,STONE)
B(0,15,15,MOSSY_COBBLESTONE)
B(1,15,15,STONEBRICK:2)
B(2,15,15,STONEBRICK)
B(3,15,15,STONEBRICK:2)
B(4,15,15,STONEBRICK:2)
B(5,15,15,STONEBRICK:2)
B(6,15,15,STONEBRICK)
B(7,15,15,STONEBRICK:1)
B(8,15,15,STONEBRICK:1)
B(9,15,15,STONEBRICK)
B(10,15,15,STONEBRICK:1)
B(11,15,15,STONEBRICK:2)
B(12,15,15,STONEBRICK:1)
B(13,15,15,STONEBRICK)
B(14,15,15,STONEBRICK)
B(15,15,15,STONEBRICK:2)
B(16,15,15,STONE)
B(0,16,15,STONEBRICK)
B(1,16,15,STONE)
B(2,16,15,MOSSY_COBBLESTONE)
B(3,16,15,STONE)
B(4,16,15,STONE)
B(5,16,15,EMERALD_ORE)
B(6,16,15,STONE)
B(7,16,15,MOSSY_COBBLESTONE)
B(8,16,15,STONEBRICK:2)
B(9,16,15,STONE)
B(10,16,15,STONE)
B(11,16,15,MOSSY_COBBLESTONE)
B(12,16,15,MOSSY_COBBLESTONE)
B(13,16,15,MOSSY_COBBLESTONE)
B(14,16,15,STONE)
B(15,16,15,MOSSY_COBBLESTONE)
B(16,16,15,STONEBRICK:1)
B(0,0,16,STONEBRICK:2)
B(1,0,16,STONEBRICK:2)
B(2,0,16,STONEBRICK:2)
B(3,0,16,STONEBRICK:1)
B(4,0,16,STONEBRICK:1)
B(5,0,16,STONEBRICK:2)
B(6,0,16,STONEBRICK:2)
B(7,0,16,STONEBRICK:1)
B(8,0,16,STONEBRICK:2)
B(9,0,16,STONEBRICK)
B(10,0,16,STONEBRICK:2)
B(11,0,16,STONEBRICK)
B(12,0,16,STONEBRICK:1)
B(13,0,16,STONEBRICK:1)
B(14,0,16,STONEBRICK)
B(15,0,16,STONEBRICK:1)
B(16,0,16,STONEBRICK:1)
B(0,1,16,STONEBRICK:1)
B(1,1,16,MOSSY_COBBLESTONE)
B(2,1,16,MOSSY_COBBLESTONE)
B(3,1,16,STONE)
B(4,1,16,MOSSY_COBBLESTONE)
B(5,1,16,STONE)
B(6,1,16,STONE)
B(7,1,16,STONE)
B(8,1,16,STONEBRICK:2)
B(9,1,16,MOSSY_COBBLESTONE)
B(10,1,16,MOSSY_COBBLESTONE)
B(11,1,16,STONEBRICK:2)
B(13,1,16,STONEBRICK:1)
B(14,1,16,MOSSY_COBBLESTONE)
B(15,1,16,STONE)
B(16,1,16,STONEBRICK)
B(0,2,16,STONEBRICK:1)
B(1,2,16,STONE)
B(2,2,16,STONE)
B(3,2,16,MOSSY_COBBLESTONE)
B(4,2,16,STONE)
B(5,2,16,MOSSY_COBBLESTONE)
B(6,2,16,STONE)
B(7,2,16,STONE)
B(8,2,16,STONEBRICK:2)
B(9,2,16,MOSSY_COBBLESTONE)
B(10,2,16,MOSSY_COBBLESTONE)
B(11,2,16,STONEBRICK:2)
B(13,2,16,STONEBRICK:2)
B(14,2,16,MOSSY_COBBLESTONE)
B(15,2,16,MOSSY_COBBLESTONE)
B(16,2,16,STONEBRICK:1)
B(0,3,16,STONEBRICK:1)
B(1,3,16,STONE)
B(2,3,16,MOSSY_COBBLESTONE)
B(3,3,16,STONE)
B(4,3,16,MOSSY_COBBLESTONE)
B(5,3,16,MOSSY_COBBLESTONE)
B(6,3,16,EMERALD_ORE)
B(7,3,16,MOSSY_COBBLESTONE)
B(8,3,16,STONEBRICK)
B(9,3,16,STONE)
B(10,3,16,MOSSY_COBBLESTONE)
B(11,3,16,STONEBRICK)
B(13,3,16,STONEBRICK)
B(14,3,16,MOSSY_COBBLESTONE)
B(15,3,16,MOSSY_COBBLESTONE)
B(16,3,16,STONEBRICK)
B(0,4,16,STONEBRICK)
B(1,4,16,STONE)
B(2,4,16,MOSSY_COBBLESTONE)
B(3,4,16,STONE)
B(4,4,16,STONE)
B(5,4,16,MOSSY_COBBLESTONE)
B(6,4,16,MOSSY_COBBLESTONE)
B(7,4,16,STONE)
B(8,4,16,STONEBRICK:1)
B(9,4,16,MOSSY_COBBLESTONE)
B(10,4,16,MOSSY_COBBLESTONE)
B(11,4,16,STONEBRICK:2)
B(12,4,16,STONEBRICK:2)
B(13,4,16,STONEBRICK:1)
B(14,4,16,STONE)
B(15,4,16,STONE)
B(16,4,16,STONEBRICK:2)
B(0,5,16,STONEBRICK)
B(1,5,16,EMERALD_ORE)
B(2,5,16,STONE)
B(3,5,16,MOSSY_COBBLESTONE)
B(4,5,16,STONE)
B(5,5,16,EMERALD_ORE)
B(6,5,16,STONE)
B(7,5,16,STONE)
B(8,5,16,STONEBRICK:1)
B(9,5,16,MOSSY_COBBLESTONE)
B(10,5,16,STONE)
B(11,5,16,STONE)
B(12,5,16,MOSSY_COBBLESTONE)
B(13,5,16,MOSSY_COBBLESTONE)
B(14,5,16,STONE)
B(15,5,16,STONE)
B(16,5,16,STONEBRICK:1)
B(0,6,16,STONEBRICK)
B(1,6,16,STONE)
B(2,6,16,STONE)
B(3,6,16,STONE)
B(4,6,16,STONE)
B(5,6,16,MOSSY_COBBLESTONE)
B(6,6,16,MOSSY_COBBLESTONE)
B(7,6,16,STONE)
B(8,6,16,STONEBRICK)
B(9,6,16,MOSSY_COBBLESTONE)
B(10,6,16,STONE)
B(11,6,16,STONE)
B(12,6,16,STONE)
B(13,6,16,MOSSY_COBBLESTONE)
B(14,6,16,MOSSY_COBBLESTONE)
B(15,6,16,MOSSY_COBBLESTONE)
B(16,6,16,STONEBRICK)
B(0,7,16,STONEBRICK:1)
B(1,7,16,STONE)
B(2,7,16,MOSSY_COBBLESTONE)
B(3,7,16,STONE)
B(4,7,16,STONE)
B(5,7,16,STONE)
B(6,7,16,STONE)
B(7,7,16,MOSSY_COBBLESTONE)
B(8,7,16,STONEBRICK)
B(9,7,16,MOSSY_COBBLESTONE)
B(10,7,16,MOSSY_COBBLESTONE)
B(11,7,16,STONE)
B(12,7,16,MOSSY_COBBLESTONE)
B(13,7,16,MOSSY_COBBLESTONE)
B(14,7,16,STONE)
B(15,7,16,MOSSY_COBBLESTONE)
B(16,7,16,STONEBRICK)
B(0,8,16,STONEBRICK:2)
B(1,8,16,STONE)
B(2,8,16,STONE)
B(3,8,16,MOSSY_COBBLESTONE)
B(4,8,16,MOSSY_COBBLESTONE)
B(5,8,16,STONE)
B(6,8,16,MOSSY_COBBLESTONE)
B(7,8,16,MOSSY_COBBLESTONE)
B(8,8,16,STONEBRICK)
B(9,8,16,STONE)
B(10,8,16,MOSSY_COBBLESTONE)
B(11,8,16,STONEBRICK)
B(12,8,16,STONEBRICK:2)
B(13,8,16,STONEBRICK)
B(14,8,16,STONE)
B(15,8,16,STONE)
B(16,8,16,STONEBRICK:1)
B(0,9,16,STONEBRICK:2)
B(1,9,16,STONE)
B(2,9,16,MOSSY_COBBLESTONE)
B(3,9,16,STONE)
B(4,9,16,MOSSY_COBBLESTONE)
B(5,9,16,MOSSY_COBBLESTONE)
B(6,9,16,EMERALD_ORE)
B(7,9,16,STONE)
B(8,9,16,STONEBRICK)
B(9,9,16,STONE)
B(10,9,16,MOSSY_COBBLESTONE)
B(11,9,16,STONEBRICK:2)
B(13,9,16,STONEBRICK)
B(14,9,16,EMERALD_ORE)
B(15,9,16,MOSSY_COBBLESTONE)
B(16,9,16,STONEBRICK:2)
B(0,10,16,STONEBRICK:1)
B(1,10,16,STONE)
B(2,10,16,MOSSY_COBBLESTONE)
B(3,10,16,STONE)
B(4,10,16,MOSSY_COBBLESTONE)
B(5,10,16,MOSSY_COBBLESTONE)
B(6,10,16,MOSSY_COBBLESTONE)
B(7,10,16,STONE)
B(8,10,16,STONEBRICK)
B(9,10,16,EMERALD_ORE)
B(10,10,16,STONE)
B(11,10,16,STONEBRICK)
B(13,10,16,STONEBRICK:2)
B(14,10,16,EMERALD_ORE)
B(15,10,16,STONE)
B(16,10,16,STONEBRICK)
B(0,11,16,STONEBRICK:1)
B(1,11,16,STONE)
B(2,11,16,STONE)
B(3,11,16,MOSSY_COBBLESTONE)
B(4,11,16,STONE)
B(5,11,16,MOSSY_COBBLESTONE)
B(6,11,16,STONE)
B(7,11,16,EMERALD_ORE)
B(8,11,16,STONEBRICK)
B(9,11,16,MOSSY_COBBLESTONE)
B(10,11,16,MOSSY_COBBLESTONE)
B(11,11,16,STONEBRICK)
B(13,11,16,STONEBRICK)
B(14,11,16,STONE)
B(15,11,16,STONE)
B(16,11,16,STONEBRICK:2)
B(0,12,16,STONEBRICK:1)
B(1,12,16,MOSSY_COBBLESTONE)
B(2,12,16,STONE)
B(3,12,16,MOSSY_COBBLESTONE)
B(4,12,16,STONE)
B(5,12,16,MOSSY_COBBLESTONE)
B(6,12,16,MOSSY_COBBLESTONE)
B(7,12,16,MOSSY_COBBLESTONE)
B(8,12,16,STONEBRICK:2)
B(9,12,16,STONE)
B(10,12,16,MOSSY_COBBLESTONE)
B(11,12,16,STONEBRICK:1)
B(12,12,16,STONEBRICK:2)
B(13,12,16,STONEBRICK)
B(14,12,16,STONE)
B(15,12,16,MOSSY_COBBLESTONE)
B(16,12,16,STONEBRICK)
B(0,13,16,STONEBRICK:1)
B(1,13,16,MOSSY_COBBLESTONE)
B(2,13,16,MOSSY_COBBLESTONE)
B(3,13,16,MOSSY_COBBLESTONE)
B(4,13,16,EMERALD_ORE)
B(5,13,16,EMERALD_ORE)
B(6,13,16,MOSSY_COBBLESTONE)
B(7,13,16,MOSSY_COBBLESTONE)
B(8,13,16,STONEBRICK:2)
B(9,13,16,EMERALD_ORE)
B(10,13,16,MOSSY_COBBLESTONE)
B(11,13,16,MOSSY_COBBLESTONE)
B(12,13,16,MOSSY_COBBLESTONE)
B(13,13,16,STONE)
B(14,13,16,EMERALD_ORE)
B(15,13,16,STONE)
B(16,13,16,STONEBRICK:2)
B(0,14,16,STONEBRICK)
B(1,14,16,MOSSY_COBBLESTONE)
B(2,14,16,MOSSY_COBBLESTONE)
B(3,14,16,STONE)
B(4,14,16,STONE)
B(5,14,16,EMERALD_ORE)
B(6,14,16,MOSSY_COBBLESTONE)
B(7,14,16,MOSSY_COBBLESTONE)
B(8,14,16,STONEBRICK)
B(9,14,16,MOSSY_COBBLESTONE)
B(10,14,16,STONE)
B(11,14,16,EMERALD_ORE)
B(12,14,16,EMERALD_ORE)
B(13,14,16,MOSSY_COBBLESTONE)
B(14,14,16,MOSSY_COBBLESTONE)
B(15,14,16,STONE)
B(16,14,16,STONEBRICK:2)
B(0,15,16,STONEBRICK:1)
B(1,15,16,MOSSY_COBBLESTONE)
B(2,15,16,MOSSY_COBBLESTONE)
B(3,15,16,MOSSY_COBBLESTONE)
B(4,15,16,MOSSY_COBBLESTONE)
B(5,15,16,STONE)
B(6,15,16,MOSSY_COBBLESTONE)
B(7,15,16,STONE)
B(8,15,16,STONEBRICK)
B(9,15,16,STONE)
B(10,15,16,MOSSY_COBBLESTONE)
B(11,15,16,MOSSY_COBBLESTONE)
B(12,15,16,STONE)
B(13,15,16,EMERALD_ORE)
B(14,15,16,MOSSY_COBBLESTONE)
B(15,15,16,STONE)
B(16,15,16,STONEBRICK:1)
B(0,16,16,STONEBRICK)
B(1,16,16,STONEBRICK)
B(2,16,16,STONEBRICK:2)
B(3,16,16,STONEBRICK)
B(4,16,16,STONEBRICK:1)
B(5,16,16,STONEBRICK:1)
B(6,16,16,STONEBRICK)
B(7,16,16,STONEBRICK:2)
B(8,16,16,STONEBRICK:2)
B(9,16,16,STONEBRICK)
B(10,16,16,STONEBRICK)
B(11,16,16,STONEBRICK)
B(12,16,16,STONEBRICK:1)
B(13,16,16,STONEBRICK)
B(14,16,16,STONEBRICK:2)
B(15,16,16,STONEBRICK)
B(16,16,16,STONEBRICK:1)
B(8,0,17,STONEBRICK)
B(9,0,17,STONEBRICK:2)
B(10,0,17,STONEBRICK:1)
B(11,0,17,STONEBRICK:1)
B(12,0,17,STONEBRICK)
B(13,0,17,STONEBRICK:2)
B(14,0,17,STONEBRICK:2)
B(15,0,17,STONEBRICK:2)
B(16,0,17,STONEBRICK:2)
B(8,1,17,STONE)
B(9,1,17,EMERALD_ORE)
B(15,1,17,MOSSY_COBBLESTONE)
B(16,1,17,EMERALD_ORE)
B(8,2,17,MOSSY_COBBLESTONE)
B(9,2,17,MOSSY_COBBLESTONE)
B(15,2,17,STONE)
B(16,2,17,STONE)
B(8,3,17,MOSSY_COBBLESTONE)
B(9,3,17,EMERALD_ORE)
B(15,3,17,MOSSY_COBBLESTONE)
B(16,3,17,STONE)
B(8,4,17,MOSSY_COBBLESTONE)
B(9,4,17,STONEBRICK:2)
B(15,4,17,STONEBRICK)
B(16,4,17,STONE)
B(8,5,17,STONE)
B(9,5,17,STONEBRICK:1)
B(15,5,17,STONEBRICK:1)
B(16,5,17,STONE)
B(8,6,17,MOSSY_COBBLESTONE)
B(9,6,17,STONEBRICK:2)
B(15,6,17,STONEBRICK)
B(16,6,17,STONE)
B(8,7,17,MOSSY_COBBLESTONE)
B(9,7,17,STONEBRICK:1)
B(10,7,17,STONEBRICK)
B(11,7,17,STONEBRICK)
B(12,7,17,STONEBRICK)
B(13,7,17,STONEBRICK)
B(14,7,17,STONEBRICK:2)
B(15,7,17,STONEBRICK:1)
B(16,7,17,STONE)
B(8,8,17,STONEBRICK:2)
B(9,8,17,STONEBRICK:1)
B(10,8,17,STONEBRICK:1)
B(11,8,17,STONEBRICK)
B(12,8,17,STONEBRICK)
B(13,8,17,STONEBRICK)
B(14,8,17,STONEBRICK)
B(15,8,17,STONEBRICK:2)
B(16,8,17,STONEBRICK:2)
B(8,9,17,EMERALD_ORE)
B(9,9,17,MOSSY_COBBLESTONE)
B(15,9,17,MOSSY_COBBLESTONE)
B(16,9,17,STONE)
B(8,10,17,STONE)
B(9,10,17,EMERALD_ORE)
B(15,10,17,MOSSY_COBBLESTONE)
B(16,10,17,MOSSY_COBBLESTONE)
B(8,11,17,MOSSY_COBBLESTONE)
B(9,11,17,STONE)
B(15,11,17,STONE)
B(16,11,17,STONE)
B(8,12,17,STONE)
B(9,12,17,STONEBRICK)
B(15,12,17,STONEBRICK:2)
B(16,12,17,STONE)
B(8,13,17,MOSSY_COBBLESTONE)
B(9,13,17,STONEBRICK:2)
B(15,13,17,STONEBRICK:1)
B(16,13,17,EMERALD_ORE)
B(8,14,17,MOSSY_COBBLESTONE)
B(9,14,17,STONEBRICK:2)
B(15,14,17,STONEBRICK:2)
B(16,14,17,EMERALD_ORE)
B(8,15,17,MOSSY_COBBLESTONE)
B(9,15,17,STONEBRICK:2)
B(10,15,17,STONEBRICK:1)
B(11,15,17,STONEBRICK)
B(12,15,17,STONEBRICK:2)
B(13,15,17,STONEBRICK)
B(14,15,17,STONEBRICK:1)
B(15,15,17,STONEBRICK:1)
B(16,15,17,EMERALD_ORE)
B(8,16,17,STONEBRICK:2)
B(9,16,17,STONE)
B(10,16,17,STONE)
B(11,16,17,STONE)
B(12,16,17,MOSSY_COBBLESTONE)
B(13,16,17,MOSSY_COBBLESTONE)
B(14,16,17,STONE)
B(15,16,17,MOSSY_COBBLESTONE)
B(16,16,17,STONEBRICK)
B(8,0,18,STONEBRICK)
B(9,0,18,STONEBRICK)
B(10,0,18,STONEBRICK:1)
B(11,0,18,STONEBRICK:1)
B(12,0,18,STONEBRICK)
B(13,0,18,STONEBRICK:1)
B(14,0,18,STONEBRICK)
B(15,0,18,STONEBRICK:2)
B(16,0,18,STONEBRICK:1)
B(8,1,18,EMERALD_ORE)
B(16,1,18,MOSSY_COBBLESTONE)
B(8,2,18,EMERALD_ORE)
B(16,2,18,EMERALD_ORE)
B(8,3,18,STONE)
B(16,3,18,MOSSY_COBBLESTONE)
B(8,4,18,MOSSY_COBBLESTONE)
B(16,4,18,STONE)
B(8,5,18,MOSSY_COBBLESTONE)
B(16,5,18,MOSSY_COBBLESTONE)
B(8,6,18,MOSSY_COBBLESTONE)
B(16,6,18,MOSSY_COBBLESTONE)
B(8,7,18,EMERALD_ORE)
B(9,7,18,STONEBRICK:1)
B(15,7,18,STONEBRICK:1)
B(16,7,18,MOSSY_COBBLESTONE)
B(8,8,18,STONEBRICK:1)
B(9,8,18,STONEBRICK:1)
B(10,8,18,STONEBRICK:1)
B(11,8,18,STONEBRICK:2)
B(12,8,18,STONEBRICK)
B(13,8,18,STONEBRICK:1)
B(14,8,18,STONEBRICK)
B(15,8,18,STONEBRICK:2)
B(16,8,18,STONEBRICK)
B(8,9,18,STONE)
B(16,9,18,MOSSY_COBBLESTONE)
B(8,10,18,STONE)
B(16,10,18,STONE)
B(8,11,18,STONE)
B(16,11,18,STONE)
B(8,12,18,EMERALD_ORE)
B(16,12,18,STONE)
B(8,13,18,STONE)
B(16,13,18,STONE)
B(8,14,18,MOSSY_COBBLESTONE)
B(16,14,18,STONE)
B(8,15,18,MOSSY_COBBLESTONE)
B(9,15,18,STONEBRICK:2)
B(15,15,18,STONEBRICK)
B(16,15,18,STONE)
B(8,16,18,STONEBRICK:2)
B(9,16,18,MOSSY_COBBLESTONE)
B(10,16,18,STONEBRICK:2)
B(11,16,18,STONEBRICK:2)
B(12,16,18,STONEBRICK:2)
B(13,16,18,STONEBRICK)
B(14,16,18,STONEBRICK:1)
B(15,16,18,EMERALD_ORE)
B(16,16,18,STONEBRICK)
B(5,0,19,STONEBRICK)
B(6,0,19,STONEBRICK:1)
B(7,0,19,STONEBRICK)
B(8,0,19,STONEBRICK:1)
B(9,0,19,STONEBRICK)
B(10,0,19,STONEBRICK:2)
B(11,0,19,DIRT:1)
B(12,0,19,GRASS)
B(13,0,19,DIRT:1)
B(14,0,19,STONEBRICK)
B(15,0,19,STONEBRICK:1)
B(16,0,19,STONEBRICK:1)
B(5,1,19,STONEBRICK:2)
B(6,1,19,STONEBRICK)
B(7,1,19,STONEBRICK:2)
B(8,1,19,STONEBRICK:1)
B(16,1,19,MOSSY_COBBLESTONE)
B(5,2,19,STONEBRICK)
B(6,2,19,STONEBRICK:2)
B(7,2,19,STONEBRICK)
B(8,2,19,STONEBRICK:2)
B(16,2,19,STONE)
B(5,3,19,STONEBRICK)
B(6,3,19,STONEBRICK:2)
B(7,3,19,STONEBRICK:2)
B(8,3,19,STONEBRICK:2)
B(16,3,19,MOSSY_COBBLESTONE)
B(5,4,19,STONEBRICK:1)
B(6,4,19,STONEBRICK:2)
B(7,4,19,STONEBRICK:2)
B(8,4,19,STONEBRICK:1)
B(16,4,19,STONE)
B(8,5,19,STONE)
B(16,5,19,MOSSY_COBBLESTONE)
B(8,6,19,MOSSY_COBBLESTONE)
B(16,6,19,STONE)
B(8,7,19,STONE)
B(9,7,19,STONEBRICK)
B(15,7,19,STONEBRICK)
B(16,7,19,STONE)
B(5,8,19,STONEBRICK:2)
B(6,8,19,STONEBRICK)
B(7,8,19,STONEBRICK:1)
B(8,8,19,STONEBRICK)
B(9,8,19,STONEBRICK)
B(10,8,19,STONEBRICK)
B(14,8,19,STONEBRICK:1)
B(15,8,19,STONEBRICK:2)
B(16,8,19,STONEBRICK:1)
B(5,9,19,STONEBRICK:1)
B(6,9,19,STONEBRICK:2)
B(7,9,19,STONEBRICK)
B(8,9,19,STONEBRICK:2)
B(16,9,19,MOSSY_COBBLESTONE)
B(5,10,19,STONEBRICK:2)
B(6,10,19,STONEBRICK)
B(7,10,19,STONEBRICK:2)
B(8,10,19,STONEBRICK)
B(16,10,19,STONE)
B(5,11,19,STONEBRICK:2)
B(6,11,19,STONEBRICK:1)
B(7,11,19,STONEBRICK:2)
B(8,11,19,STONEBRICK)
B(16,11,19,STONE)
B(5,12,19,STONEBRICK)
B(6,12,19,STONEBRICK)
B(7,12,19,STONEBRICK:2)
B(8,12,19,STONEBRICK:2)
B(16,12,19,STONE)
B(8,13,19,STONE)
B(16,13,19,STONE)
B(8,14,19,MOSSY_COBBLESTONE)
B(16,14,19,MOSSY_COBBLESTONE)
B(8,15,19,STONE)
B(9,15,19,STONEBRICK:2)
B(15,15,19,STONEBRICK)
B(16,15,19,MOSSY_COBBLESTONE)
B(8,16,19,STONEBRICK:2)
B(9,16,19,EMERALD_ORE)
B(10,16,19,STONEBRICK)
B(14,16,19,STONEBRICK:1)
B(15,16,19,EMERALD_ORE)
B(16,16,19,STONEBRICK)
B(5,0,20,STONEBRICK:2)
B(6,0,20,STONEBRICK)
B(7,0,20,STONEBRICK:2)
B(8,0,20,STONEBRICK:2)
B(9,0,20,STONEBRICK)
B(10,0,20,STONEBRICK:2)
B(11,0,20,DIRT:1)
B(12,0,20,DIRT:1)
B(13,0,20,GRASS)
B(14,0,20,STONEBRICK)
B(15,0,20,STONEBRICK:1)
B(16,0,20,STONEBRICK:2)
B(16,1,20,STONE)
B(16,2,20,MOSSY_COBBLESTONE)
B(16,3,20,STONE)
B(5,4,20,STONEBRICK:1)
B(6,4,20,STONEBRICK)
B(7,4,20,STONEBRICK)
B(8,4,20,STONEBRICK:2)
B(16,4,20,STONE)
B(8,5,20,MOSSY_COBBLESTONE)
B(16,5,20,STONE)
B(8,6,20,MOSSY_COBBLESTONE)
B(16,6,20,EMERALD_ORE)
B(8,7,20,STONE)
B(9,7,20,STONEBRICK:1)
B(15,7,20,STONEBRICK:2)
B(16,7,20,MOSSY_COBBLESTONE)
B(5,8,20,STONEBRICK:2)
B(6,8,20,STONEBRICK:2)
B(7,8,20,STONEBRICK:2)
B(8,8,20,STONEBRICK)
B(9,8,20,STONEBRICK)
B(10,8,20,STONEBRICK:2)
B(14,8,20,STONEBRICK)
B(15,8,20,STONEBRICK)
B(16,8,20,STONEBRICK:2)
B(16,9,20,MOSSY_COBBLESTONE)
B(16,10,20,STONE)
B(16,11,20,STONE)
B(5,12,20,STONEBRICK)
B(6,12,20,STONEBRICK)
B(7,12,20,STONEBRICK:1)
B(8,12,20,STONEBRICK:1)
B(16,12,20,MOSSY_COBBLESTONE)
B(8,13,20,MOSSY_COBBLESTONE)
B(16,13,20,STONE)
B(8,14,20,STONE)
B(16,14,20,MOSSY_COBBLESTONE)
B(8,15,20,STONE)
B(9,15,20,STONEBRICK)
B(15,15,20,STONEBRICK:2)
B(16,15,20,MOSSY_COBBLESTONE)
B(8,16,20,STONEBRICK)
B(9,16,20,STONE)
B(10,16,20,STONEBRICK:1)
B(14,16,20,STONEBRICK)
B(15,16,20,STONE)
B(16,16,20,STONEBRICK)
B(5,0,21,STONEBRICK)
B(6,0,21,STONEBRICK:1)
B(7,0,21,STONEBRICK:2)
B(8,0,21,STONEBRICK)
B(9,0,21,STONEBRICK:1)
B(10,0,21,STONEBRICK:1)
B(11,0,21,GRASS)
B(12,0,21,GRASS)
B(13,0,21,DIRT:1)
B(14,0,21,STONEBRICK:1)
B(15,0,21,STONEBRICK:2)
B(16,0,21,STONEBRICK)
B(5,1,21,STONEBRICK:1)
B(6,1,21,STONEBRICK:1)
B(7,1,21,STONEBRICK)
B(8,1,21,STONEBRICK:2)
B(16,1,21,MOSSY_COBBLESTONE)
B(5,2,21,STONEBRICK:2)
B(6,2,21,STONEBRICK:2)
B(7,2,21,STONEBRICK:1)
B(8,2,21,STONEBRICK:2)
B(16,2,21,STONE)
B(5,3,21,STONEBRICK:2)
B(6,3,21,STONEBRICK)
B(7,3,21,STONEBRICK:1)
B(8,3,21,STONEBRICK:2)
B(16,3,21,EMERALD_ORE)
B(5,4,21,STONEBRICK)
B(6,4,21,STONEBRICK:2)
B(7,4,21,STONEBRICK:2)
B(8,4,21,STONEBRICK:1)
B(16,4,21,STONE)
B(8,5,21,MOSSY_COBBLESTONE)
B(16,5,21,MOSSY_COBBLESTONE)
B(8,6,21,MOSSY_COBBLESTONE)
B(16,6,21,EMERALD_ORE)
B(8,7,21,EMERALD_ORE)
B(9,7,21,STONEBRICK:2)
B(15,7,21,STONEBRICK)
B(16,7,21,EMERALD_ORE)
B(5,8,21,STONEBRICK)
B(6,8,21,STONEBRICK:1)
B(7,8,21,STONEBRICK:1)
B(8,8,21,STONEBRICK:2)
B(9,8,21,STONEBRICK:2)
B(10,8,21,STONEBRICK:1)
B(14,8,21,STONEBRICK:1)
B(15,8,21,STONEBRICK)
B(16,8,21,STONEBRICK)
B(5,9,21,STONEBRICK:2)
B(6,9,21,STONEBRICK:1)
B(7,9,21,STONEBRICK)
B(8,9,21,STONEBRICK)
B(16,9,21,MOSSY_COBBLESTONE)
B(5,10,21,STONEBRICK:2)
B(6,10,21,STONEBRICK:1)
B(7,10,21,STONEBRICK:2)
B(8,10,21,STONEBRICK)
B(16,10,21,MOSSY_COBBLESTONE)
B(5,11,21,STONEBRICK)
B(6,11,21,STONEBRICK:2)
B(7,11,21,STONEBRICK)
B(8,11,21,STONEBRICK:1)
B(16,11,21,MOSSY_COBBLESTONE)
B(5,12,21,STONEBRICK)
B(6,12,21,STONEBRICK:2)
B(7,12,21,STONEBRICK)
B(8,12,21,STONEBRICK:2)
B(16,12,21,STONE)
B(8,13,21,STONE)
B(16,13,21,STONE)
B(8,14,21,STONE)
B(16,14,21,STONE)
B(8,15,21,MOSSY_COBBLESTONE)
B(9,15,21,STONEBRICK:2)
B(15,15,21,STONEBRICK:1)
B(16,15,21,STONE)
B(8,16,21,STONEBRICK:1)
B(9,16,21,STONE)
B(10,16,21,STONEBRICK:1)
B(14,16,21,STONEBRICK:2)
B(15,16,21,STONE)
B(16,16,21,STONEBRICK)
B(8,0,22,STONEBRICK:2)
B(9,0,22,STONEBRICK)
B(10,0,22,STONEBRICK:1)
B(11,0,22,STONEBRICK:2)
B(12,0,22,STONEBRICK:1)
B(13,0,22,STONEBRICK)
B(14,0,22,STONEBRICK)
B(15,0,22,STONEBRICK)
B(16,0,22,STONEBRICK:1)
B(8,1,22,MOSSY_COBBLESTONE)
B(16,1,22,STONE)
B(8,2,22,STONE)
B(16,2,22,MOSSY_COBBLESTONE)
B(8,3,22,STONE)
B(16,3,22,STONE)
B(8,4,22,STONE)
B(16,4,22,MOSSY_COBBLESTONE)
B(8,5,22,MOSSY_COBBLESTONE)
B(16,5,22,MOSSY_COBBLESTONE)
B(8,6,22,MOSSY_COBBLESTONE)
B(16,6,22,MOSSY_COBBLESTONE)
B(8,7,22,STONE)
B(9,7,22,STONEBRICK)
B(15,7,22,STONEBRICK)
B(16,7,22,MOSSY_COBBLESTONE)
B(8,8,22,STONEBRICK:1)
B(9,8,22,STONEBRICK:2)
B(10,8,22,STONEBRICK)
B(11,8,22,STONEBRICK:2)
B(12,8,22,STONEBRICK:2)
B(13,8,22,STONEBRICK)
B(14,8,22,STONEBRICK)
B(15,8,22,STONEBRICK:2)
B(16,8,22,STONEBRICK:2)
B(8,9,22,STONE)
B(16,9,22,MOSSY_COBBLESTONE)
B(8,10,22,STONE)
B(16,10,22,MOSSY_COBBLESTONE)
B(8,11,22,STONE)
B(16,11,22,MOSSY_COBBLESTONE)
B(8,12,22,STONE)
B(16,12,22,STONE)
B(8,13,22,EMERALD_ORE)
B(16,13,22,STONE)
B(8,14,22,STONE)
B(16,14,22,STONE)
B(8,15,22,MOSSY_COBBLESTONE)
B(9,15,22,STONEBRICK:2)
B(15,15,22,STONEBRICK:1)
B(16,15,22,MOSSY_COBBLESTONE)
B(8,16,22,STONEBRICK)
B(9,16,22,MOSSY_COBBLESTONE)
B(10,16,22,STONEBRICK:2)
B(11,16,22,STONEBRICK:1)
B(12,16,22,STONEBRICK)
B(13,16,22,STONEBRICK:1)
B(14,16,22,STONEBRICK:1)
B(15,16,22,STONE)
B(16,16,22,STONEBRICK)
B(8,0,23,STONEBRICK:1)
B(9,0,23,STONEBRICK)
B(10,0,23,STONEBRICK:1)
B(11,0,23,STONEBRICK:1)
B(12,0,23,STONEBRICK)
B(13,0,23,STONEBRICK)
B(14,0,23,STONEBRICK:2)
B(15,0,23,STONEBRICK)
B(16,0,23,STONEBRICK)
B(8,1,23,MOSSY_COBBLESTONE)
B(9,1,23,STONE)
B(15,1,23,MOSSY_COBBLESTONE)
B(16,1,23,STONE)
B(8,2,23,STONE)
B(9,2,23,MOSSY_COBBLESTONE)
B(15,2,23,STONE)
B(16,2,23,STONE)
B(8,3,23,STONE)
B(9,3,23,EMERALD_ORE)
B(15,3,23,MOSSY_COBBLESTONE)
B(16,3,23,STONE)
B(8,4,23,EMERALD_ORE)
B(9,4,23,STONEBRICK:2)
B(15,4,23,STONEBRICK:2)
B(16,4,23,MOSSY_COBBLESTONE)
B(8,5,23,STONE)
B(9,5,23,STONEBRICK:2)
B(15,5,23,STONEBRICK:2)
B(16,5,23,STONE)
B(8,6,23,MOSSY_COBBLESTONE)
B(9,6,23,STONEBRICK)
B(15,6,23,STONEBRICK)
B(16,6,23,STONE)
B(8,7,23,MOSSY_COBBLESTONE)
B(9,7,23,STONEBRICK:1)
B(10,7,23,STONEBRICK:2)
B(11,7,23,STONEBRICK)
B(12,7,23,STONEBRICK:2)
B(13,7,23,STONEBRICK)
B(14,7,23,STONEBRICK:1)
B(15,7,23,STONEBRICK:1)
B(16,7,23,MOSSY_COBBLESTONE)
B(8,8,23,STONEBRICK:1)
B(9,8,23,STONEBRICK)
B(10,8,23,STONEBRICK)
B(11,8,23,STONEBRICK:2)
B(12,8,23,STONEBRICK:1)
B(13,8,23,STONEBRICK:2)
B(14,8,23,STONEBRICK)
B(15,8,23,STONEBRICK)
B(16,8,23,STONEBRICK)
B(8,9,23,STONE)
B(9,9,23,MOSSY_COBBLESTONE)
B(15,9,23,MOSSY_COBBLESTONE)
B(16,9,23,MOSSY_COBBLESTONE)
B(8,10,23,STONE)
B(9,10,23,MOSSY_COBBLESTONE)
B(15,10,23,STONE)
B(16,10,23,MOSSY_COBBLESTONE)
B(8,11,23,EMERALD_ORE)
B(9,11,23,EMERALD_ORE)
B(15,11,23,EMERALD_ORE)
B(16,11,23,MOSSY_COBBLESTONE)
B(8,12,23,MOSSY_COBBLESTONE)
B(9,12,23,STONEBRICK:2)
B(15,12,23,STONEBRICK:2)
B(16,12,23,STONE)
B(8,13,23,STONE)
B(9,13,23,STONEBRICK:2)
B(15,13,23,STONEBRICK:2)
B(16,13,23,MOSSY_COBBLESTONE)
B(8,14,23,MOSSY_COBBLESTONE)
B(9,14,23,STONEBRICK:1)
B(15,14,23,STONEBRICK)
B(16,14,23,STONE)
B(8,15,23,STONE)
B(9,15,23,STONEBRICK:2)
B(10,15,23,STONEBRICK:1)
B(11,15,23,STONEBRICK:2)
B(12,15,23,STONEBRICK:1)
B(13,15,23,STONEBRICK:2)
B(14,15,23,STONEBRICK:2)
B(15,15,23,STONEBRICK:2)
B(16,15,23,EMERALD_ORE)
B(8,16,23,STONEBRICK)
B(9,16,23,MOSSY_COBBLESTONE)
B(10,16,23,STONE)
B(11,16,23,MOSSY_COBBLESTONE)
B(12,16,23,EMERALD_ORE)
B(13,16,23,STONE)
B(14,16,23,EMERALD_ORE)
B(15,16,23,STONE)
B(16,16,23,STONEBRICK:1)
B(8,0,24,STONEBRICK:2)
B(9,0,24,STONEBRICK)
B(10,0,24,STONEBRICK)
B(11,0,24,STONEBRICK)
B(12,0,24,STONEBRICK:1)
B(13,0,24,STONEBRICK:2)
B(14,0,24,STONEBRICK:1)
B(15,0,24,STONEBRICK)
B(16,0,24,STONEBRICK:2)
B(8,1,24,STONEBRICK:2)
B(9,1,24,EMERALD_ORE)
B(10,1,24,STONE)
B(11,1,24,STONE)
B(12,1,24,STONE)
B(13,1,24,EMERALD_ORE)
B(14,1,24,MOSSY_COBBLESTONE)
B(15,1,24,MOSSY_COBBLESTONE)
B(16,1,24,STONEBRICK:2)
B(8,2,24,STONEBRICK:2)
B(9,2,24,EMERALD_ORE)
B(10,2,24,MOSSY_COBBLESTONE)
B(11,2,24,MOSSY_COBBLESTONE)
B(12,2,24,MOSSY_COBBLESTONE)
B(13,2,24,EMERALD_ORE)
B(14,2,24,STONE)
B(15,2,24,MOSSY_COBBLESTONE)
B(16,2,24,STONEBRICK)
B(8,3,24,STONEBRICK)
B(9,3,24,MOSSY_COBBLESTONE)
B(10,3,24,MOSSY_COBBLESTONE)
B(11,3,24,MOSSY_COBBLESTONE)
B(12,3,24,STONE)
B(13,3,24,STONE)
B(14,3,24,MOSSY_COBBLESTONE)
B(15,3,24,STONE)
B(16,3,24,STONEBRICK:1)
B(8,4,24,STONEBRICK)
B(9,4,24,STONE)
B(10,4,24,MOSSY_COBBLESTONE)
B(11,4,24,MOSSY_COBBLESTONE)
B(12,4,24,MOSSY_COBBLESTONE)
B(13,4,24,MOSSY_COBBLESTONE)
B(14,4,24,STONE)
B(15,4,24,MOSSY_COBBLESTONE)
B(16,4,24,STONEBRICK:2)
B(8,5,24,STONEBRICK)
B(9,5,24,MOSSY_COBBLESTONE)
B(10,5,24,EMERALD_ORE)
B(11,5,24,STONE)
B(12,5,24,STONE)
B(13,5,24,EMERALD_ORE)
B(14,5,24,STONE)
B(15,5,24,EMERALD_ORE)
B(16,5,24,STONEBRICK:1)
B(8,6,24,STONEBRICK:2)
B(9,6,24,STONE)
B(10,6,24,STONE)
B(11,6,24,STONE)
B(12,6,24,STONE)
B(13,6,24,MOSSY_COBBLESTONE)
B(14,6,24,MOSSY_COBBLESTONE)
B(15,6,24,STONE)
B(16,6,24,STONEBRICK:2)
B(8,7,24,STONEBRICK:1)
B(9,7,24,EMERALD_ORE)
B(10,7,24,STONE)
B(11,7,24,MOSSY_COBBLESTONE)
B(12,7,24,MOSSY_COBBLESTONE)
B(13,7,24,MOSSY_COBBLESTONE)
B(14,7,24,MOSSY_COBBLESTONE)
B(15,7,24,EMERALD_ORE)
B(16,7,24,STONEBRICK:2)
B(8,8,24,STONEBRICK)
B(9,8,24,STONEBRICK:1)
B(10,8,24,STONEBRICK)
B(11,8,24,STONEBRICK:1)
B(12,8,24,STONEBRICK)
B(13,8,24,STONEBRICK:1)
B(14,8,24,STONEBRICK:2)
B(15,8,24,STONEBRICK:1)
B(16,8,24,STONEBRICK:1)
B(8,9,24,STONEBRICK:1)
B(9,9,24,STONE)
B(10,9,24,MOSSY_COBBLESTONE)
B(11,9,24,STONE)
B(12,9,24,EMERALD_ORE)
B(13,9,24,STONE)
B(14,9,24,STONE)
B(15,9,24,STONE)
B(16,9,24,STONEBRICK:2)
B(8,10,24,STONEBRICK:2)
B(9,10,24,MOSSY_COBBLESTONE)
B(10,10,24,EMERALD_ORE)
B(11,10,24,STONE)
B(12,10,24,MOSSY_COBBLESTONE)
B(13,10,24,EMERALD_ORE)
B(14,10,24,STONE)
B(15,10,24,STONE)
B(16,10,24,STONEBRICK:1)
B(8,11,24,STONEBRICK:1)
B(9,11,24,MOSSY_COBBLESTONE)
B(10,11,24,STONE)
B(11,11,24,STONE)
B(12,11,24,STONE)
B(13,11,24,STONE)
B(14,11,24,STONE)
B(15,11,24,MOSSY_COBBLESTONE)
B(16,11,24,STONEBRICK)
B(8,12,24,STONEBRICK:2)
B(9,12,24,MOSSY_COBBLESTONE)
B(10,12,24,MOSSY_COBBLESTONE)
B(11,12,24,STONE)
B(12,12,24,MOSSY_COBBLESTONE)
B(13,12,24,STONE)
B(14,12,24,STONE)
B(15,12,24,MOSSY_COBBLESTONE)
B(16,12,24,STONEBRICK)
B(8,13,24,STONEBRICK:1)
B(9,13,24,STONE)
B(10,13,24,MOSSY_COBBLESTONE)
B(11,13,24,EMERALD_ORE)
B(12,13,24,STONE)
B(13,13,24,STONE)
B(14,13,24,MOSSY_COBBLESTONE)
B(15,13,24,STONE)
B(16,13,24,STONEBRICK:1)
B(8,14,24,STONEBRICK:1)
B(9,14,24,MOSSY_COBBLESTONE)
B(10,14,24,MOSSY_COBBLESTONE)
B(11,14,24,EMERALD_ORE)
B(12,14,24,MOSSY_COBBLESTONE)
B(13,14,24,MOSSY_COBBLESTONE)
B(14,14,24,STONE)
B(15,14,24,MOSSY_COBBLESTONE)
B(16,14,24,STONEBRICK:1)
B(8,15,24,STONEBRICK:1)
B(9,15,24,MOSSY_COBBLESTONE)
B(10,15,24,MOSSY_COBBLESTONE)
B(11,15,24,STONE)
B(12,15,24,STONE)
B(13,15,24,STONE)
B(14,15,24,MOSSY_COBBLESTONE)
B(15,15,24,MOSSY_COBBLESTONE)
B(16,15,24,STONEBRICK)
B(8,16,24,STONEBRICK:2)
B(9,16,24,STONEBRICK:1)
B(10,16,24,STONEBRICK)
B(11,16,24,STONEBRICK:2)
B(12,16,24,STONEBRICK)
B(13,16,24,STONEBRICK:1)
B(14,16,24,STONEBRICK:2)
B(15,16,24,STONEBRICK:2)
B(16,16,24,STONEBRICK)
B(2,1,1,AIR)
B(3,1,1,AIR)
B(5,1,1,AIR)
B(6,1,1,AIR)
B(2,2,1,AIR)
B(3,2,1,AIR)
B(4,2,1,AIR)
B(5,2,1,AIR)
B(6,2,1,AIR)
B(2,3,1,AIR)
B(3,3,1,AIR)
B(4,3,1,AIR)
B(5,3,1,AIR)
B(6,3,1,AIR)
B(2,4,1,AIR)
B(3,4,1,AIR)
B(4,4,1,AIR)
B(5,4,1,AIR)
B(6,4,1,AIR)
B(2,5,1,AIR)
B(3,5,1,AIR)
B(4,5,1,AIR)
B(5,5,1,AIR)
B(6,5,1,AIR)
B(2,6,1,STONE_BRICK_STAIRS:5)
B(3,6,1,AIR)
B(4,6,1,AIR)
B(5,6,1,AIR)
B(6,6,1,STONE_BRICK_STAIRS:4)
B(2,9,1,AIR)
B(3,9,1,AIR)
B(5,9,1,AIR)
B(6,9,1,AIR)
B(2,10,1,AIR)
B(3,10,1,AIR)
B(4,10,1,AIR)
B(5,10,1,AIR)
B(6,10,1,AIR)
B(2,11,1,AIR)
B(3,11,1,AIR)
B(4,11,1,AIR)
B(5,11,1,AIR)
B(6,11,1,AIR)
B(2,12,1,AIR)
B(3,12,1,AIR)
B(4,12,1,AIR)
B(5,12,1,AIR)
B(6,12,1,AIR)
B(2,13,1,AIR)
B(3,13,1,AIR)
B(4,13,1,AIR)
B(5,13,1,AIR)
B(6,13,1,AIR)
B(2,14,1,STONE_BRICK_STAIRS:5)
B(3,14,1,AIR)
B(4,14,1,AIR)
B(5,14,1,AIR)
B(6,14,1,STONE_BRICK_STAIRS:4)
B(1,1,2,AIR)
B(2,1,2,AIR)
B(3,1,2,AIR)
B(4,1,2,AIR)
B(5,1,2,AIR)
B(6,1,2,AIR)
B(7,1,2,AIR)
B(1,2,2,AIR)
B(2,2,2,AIR)
B(3,2,2,AIR)
B(4,2,2,AIR)
B(5,2,2,AIR)
B(6,2,2,AIR)
B(7,2,2,AIR)
B(1,3,2,AIR)
B(2,3,2,AIR)
B(3,3,2,AIR)
B(4,3,2,AIR)
B(5,3,2,AIR)
B(6,3,2,AIR)
B(7,3,2,AIR)
B(1,4,2,AIR)
B(2,4,2,AIR)
B(3,4,2,AIR)
B(4,4,2,AIR)
B(5,4,2,AIR)
B(6,4,2,AIR)
B(7,4,2,AIR)
B(1,5,2,AIR)
B(2,5,2,AIR)
B(3,5,2,AIR)
B(4,5,2,AIR)
B(5,5,2,AIR)
B(6,5,2,AIR)
B(7,5,2,AIR)
B(1,6,2,STONE_BRICK_STAIRS:7)
B(2,6,2,AIR)
B(3,6,2,AIR)
B(4,6,2,AIR)
B(5,6,2,AIR)
B(6,6,2,AIR)
B(7,6,2,STONE_BRICK_STAIRS:7)
B(2,7,2,AIR)
B(3,7,2,AIR)
B(4,7,2,AIR)
B(5,7,2,AIR)
B(6,7,2,AIR)
B(1,9,2,AIR)
B(2,9,2,AIR)
B(3,9,2,AIR)
B(4,9,2,AIR)
B(5,9,2,AIR)
B(6,9,2,AIR)
B(7,9,2,AIR)
B(1,10,2,AIR)
B(2,10,2,AIR)
B(3,10,2,AIR)
B(4,10,2,AIR)
B(5,10,2,AIR)
B(6,10,2,AIR)
B(7,10,2,AIR)
B(1,11,2,AIR)
B(2,11,2,AIR)
B(3,11,2,AIR)
B(4,11,2,AIR)
B(5,11,2,AIR)
B(6,11,2,AIR)
B(7,11,2,AIR)
B(1,12,2,AIR)
B(2,12,2,AIR)
B(3,12,2,AIR)
B(4,12,2,AIR)
B(5,12,2,AIR)
B(6,12,2,AIR)
B(7,12,2,AIR)
B(1,13,2,AIR)
B(2,13,2,AIR)
B(3,13,2,AIR)
B(4,13,2,AIR)
B(5,13,2,AIR)
B(6,13,2,AIR)
B(7,13,2,AIR)
B(1,14,2,STONE_BRICK_STAIRS:7)
B(2,14,2,AIR)
B(3,14,2,AIR)
B(4,14,2,AIR)
B(5,14,2,AIR)
B(6,14,2,AIR)
B(7,14,2,STONE_BRICK_STAIRS:7)
B(2,15,2,AIR)
B(3,15,2,AIR)
B(4,15,2,AIR)
B(5,15,2,AIR)
B(6,15,2,AIR)
B(1,1,3,AIR)
B(2,1,3,AIR)
B(3,1,3,TALLGRASS:1)
B(4,1,3,TALLGRASS:2)
B(5,1,3,AIR)
B(6,1,3,AIR)
B(7,1,3,AIR)
B(1,2,3,AIR)
B(2,2,3,AIR)
B(3,2,3,AIR)
B(4,2,3,AIR)
B(5,2,3,AIR)
B(6,2,3,AIR)
B(7,2,3,AIR)
B(1,3,3,AIR)
B(2,3,3,AIR)
B(3,3,3,AIR)
B(4,3,3,AIR)
B(5,3,3,AIR)
B(6,3,3,AIR)
B(7,3,3,AIR)
B(1,4,3,AIR)
B(2,4,3,AIR)
B(3,4,3,AIR)
B(4,4,3,AIR)
B(5,4,3,AIR)
B(6,4,3,AIR)
B(7,4,3,AIR)
B(1,5,3,AIR)
B(2,5,3,AIR)
B(3,5,3,AIR)
B(4,5,3,AIR)
B(5,5,3,AIR)
B(6,5,3,AIR)
B(7,5,3,AIR)
B(1,6,3,AIR)
B(2,6,3,AIR)
B(3,6,3,AIR)
B(4,6,3,AIR)
B(5,6,3,AIR)
B(6,6,3,AIR)
B(7,6,3,AIR)
B(2,7,3,AIR)
B(3,7,3,AIR)
B(4,7,3,AIR)
B(5,7,3,AIR)
B(6,7,3,AIR)
B(3,8,3,AIR)
B(4,8,3,AIR)
B(5,8,3,AIR)
B(1,9,3,AIR)
B(2,9,3,AIR)
B(3,9,3,AIR)
B(4,9,3,AIR)
B(5,9,3,AIR)
B(6,9,3,AIR)
B(7,9,3,AIR)
B(1,10,3,AIR)
B(2,10,3,AIR)
B(3,10,3,AIR)
B(4,10,3,AIR)
B(5,10,3,AIR)
B(6,10,3,AIR)
B(7,10,3,AIR)
B(1,11,3,AIR)
B(2,11,3,AIR)
B(3,11,3,AIR)
B(4,11,3,AIR)
B(5,11,3,AIR)
B(6,11,3,AIR)
B(7,11,3,AIR)
B(1,12,3,AIR)
B(2,12,3,AIR)
B(3,12,3,AIR)
B(4,12,3,AIR)
B(5,12,3,AIR)
B(6,12,3,AIR)
B(7,12,3,AIR)
B(1,13,3,AIR)
B(2,13,3,AIR)
B(3,13,3,AIR)
B(4,13,3,AIR)
B(5,13,3,AIR)
B(6,13,3,AIR)
B(7,13,3,AIR)
B(1,14,3,AIR)
B(2,14,3,AIR)
B(3,14,3,AIR)
B(4,14,3,AIR)
B(5,14,3,AIR)
B(6,14,3,AIR)
B(7,14,3,AIR)
B(2,15,3,AIR)
B(3,15,3,AIR)
B(4,15,3,AIR)
B(5,15,3,AIR)
B(6,15,3,AIR)
B(3,16,3,AIR)
B(4,16,3,AIR)
B(5,16,3,AIR)
B(2,1,4,AIR)
B(3,1,4,TALLGRASS:2)
B(5,1,4,TALLGRASS:1)
B(6,1,4,AIR)
B(7,1,4,AIR)
B(8,1,4,AIR)
B(9,1,4,AIR)
B(10,1,4,AIR)
B(11,1,4,AIR)
B(1,2,4,AIR)
B(2,2,4,AIR)
B(3,2,4,AIR)
B(4,2,4,AIR)
B(5,2,4,AIR)
B(6,2,4,AIR)
B(7,2,4,AIR)
B(8,2,4,AIR)
B(9,2,4,AIR)
B(10,2,4,AIR)
B(11,2,4,AIR)
B(1,3,4,AIR)
B(2,3,4,AIR)
B(3,3,4,AIR)
B(4,3,4,AIR)
B(5,3,4,AIR)
B(6,3,4,AIR)
B(7,3,4,AIR)
B(8,3,4,AIR)
B(9,3,4,AIR)
B(10,3,4,AIR)
B(11,3,4,AIR)
B(1,4,4,AIR)
B(2,4,4,AIR)
B(3,4,4,AIR)
B(4,4,4,AIR)
B(5,4,4,AIR)
B(6,4,4,AIR)
B(7,4,4,AIR)
B(1,5,4,AIR)
B(2,5,4,AIR)
B(3,5,4,AIR)
B(4,5,4,AIR)
B(5,5,4,AIR)
B(6,5,4,AIR)
B(7,5,4,AIR)
B(1,6,4,AIR)
B(2,6,4,AIR)
B(3,6,4,AIR)
B(4,6,4,AIR)
B(5,6,4,AIR)
B(6,6,4,AIR)
B(7,6,4,AIR)
B(2,7,4,AIR)
B(3,7,4,AIR)
B(4,7,4,AIR)
B(5,7,4,AIR)
B(6,7,4,AIR)
B(3,8,4,AIR)
B(4,8,4,AIR)
B(5,8,4,AIR)
B(2,9,4,AIR)
B(3,9,4,AIR)
B(4,9,4,AIR)
B(5,9,4,AIR)
B(6,9,4,AIR)
B(7,9,4,AIR)
B(8,9,4,AIR)
B(9,9,4,AIR)
B(10,9,4,AIR)
B(11,9,4,AIR)
B(1,10,4,AIR)
B(2,10,4,AIR)
B(3,10,4,AIR)
B(4,10,4,AIR)
B(5,10,4,AIR)
B(6,10,4,AIR)
B(7,10,4,AIR)
B(8,10,4,AIR)
B(9,10,4,AIR)
B(10,10,4,AIR)
B(11,10,4,AIR)
B(1,11,4,AIR)
B(2,11,4,AIR)
B(3,11,4,AIR)
B(4,11,4,AIR)
B(5,11,4,AIR)
B(6,11,4,AIR)
B(7,11,4,AIR)
B(8,11,4,AIR)
B(9,11,4,AIR)
B(10,11,4,AIR)
B(11,11,4,AIR)
B(1,12,4,AIR)
B(2,12,4,AIR)
B(3,12,4,AIR)
B(4,12,4,AIR)
B(5,12,4,AIR)
B(6,12,4,AIR)
B(7,12,4,AIR)
B(1,13,4,AIR)
B(2,13,4,AIR)
B(3,13,4,AIR)
B(4,13,4,AIR)
B(5,13,4,AIR)
B(6,13,4,AIR)
B(7,13,4,AIR)
B(1,14,4,AIR)
B(2,14,4,AIR)
B(3,14,4,AIR)
B(4,14,4,AIR)
B(5,14,4,AIR)
B(6,14,4,AIR)
B(7,14,4,AIR)
B(2,15,4,AIR)
B(3,15,4,AIR)
B(4,15,4,AIR)
B(5,15,4,AIR)
B(6,15,4,AIR)
B(3,16,4,AIR)
B(4,16,4,AIR)
B(5,16,4,AIR)
B(1,1,5,AIR)
B(2,1,5,AIR)
B(3,1,5,AIR)
B(4,1,5,TALLGRASS:1)
B(5,1,5,TALLGRASS:1)
B(6,1,5,AIR)
B(7,1,5,AIR)
B(1,2,5,AIR)
B(2,2,5,AIR)
B(3,2,5,AIR)
B(4,2,5,AIR)
B(5,2,5,AIR)
B(6,2,5,AIR)
B(7,2,5,AIR)
B(1,3,5,AIR)
B(2,3,5,AIR)
B(3,3,5,AIR)
B(4,3,5,AIR)
B(5,3,5,AIR)
B(6,3,5,AIR)
B(7,3,5,AIR)
B(1,4,5,AIR)
B(2,4,5,AIR)
B(3,4,5,AIR)
B(4,4,5,AIR)
B(5,4,5,AIR)
B(6,4,5,AIR)
B(7,4,5,AIR)
B(1,5,5,AIR)
B(2,5,5,AIR)
B(3,5,5,AIR)
B(4,5,5,AIR)
B(5,5,5,AIR)
B(6,5,5,AIR)
B(7,5,5,AIR)
B(1,6,5,AIR)
B(2,6,5,AIR)
B(3,6,5,AIR)
B(4,6,5,AIR)
B(5,6,5,AIR)
B(6,6,5,AIR)
B(7,6,5,AIR)
B(2,7,5,AIR)
B(3,7,5,AIR)
B(4,7,5,AIR)
B(5,7,5,AIR)
B(6,7,5,AIR)
B(3,8,5,AIR)
B(4,8,5,AIR)
B(5,8,5,AIR)
B(1,9,5,AIR)
B(2,9,5,AIR)
B(3,9,5,AIR)
B(4,9,5,AIR)
B(5,9,5,AIR)
B(6,9,5,AIR)
B(7,9,5,AIR)
B(1,10,5,AIR)
B(2,10,5,AIR)
B(3,10,5,AIR)
B(4,10,5,AIR)
B(5,10,5,AIR)
B(6,10,5,AIR)
B(7,10,5,AIR)
B(1,11,5,AIR)
B(2,11,5,AIR)
B(3,11,5,AIR)
B(4,11,5,AIR)
B(5,11,5,AIR)
B(6,11,5,AIR)
B(7,11,5,AIR)
B(1,12,5,AIR)
B(2,12,5,AIR)
B(3,12,5,AIR)
B(4,12,5,AIR)
B(5,12,5,AIR)
B(6,12,5,AIR)
B(7,12,5,AIR)
B(1,13,5,AIR)
B(2,13,5,AIR)
B(3,13,5,AIR)
B(4,13,5,AIR)
B(5,13,5,AIR)
B(6,13,5,AIR)
B(7,13,5,AIR)
B(1,14,5,AIR)
B(2,14,5,AIR)
B(3,14,5,AIR)
B(4,14,5,AIR)
B(5,14,5,AIR)
B(6,14,5,AIR)
B(7,14,5,AIR)
B(2,15,5,AIR)
B(3,15,5,AIR)
B(4,15,5,AIR)
B(5,15,5,AIR)
B(6,15,5,AIR)
B(3,16,5,AIR)
B(4,16,5,AIR)
B(5,16,5,AIR)
B(1,1,6,AIR)
B(2,1,6,AIR)
B(3,1,6,AIR)
B(4,1,6,AIR)
B(5,1,6,AIR)
B(6,1,6,AIR)
B(7,1,6,AIR)
B(1,2,6,AIR)
B(2,2,6,AIR)
B(3,2,6,AIR)
B(4,2,6,AIR)
B(5,2,6,AIR)
B(6,2,6,AIR)
B(7,2,6,AIR)
B(1,3,6,AIR)
B(2,3,6,AIR)
B(3,3,6,AIR)
B(4,3,6,AIR)
B(5,3,6,AIR)
B(6,3,6,AIR)
B(7,3,6,AIR)
B(1,4,6,AIR)
B(2,4,6,AIR)
B(3,4,6,AIR)
B(4,4,6,AIR)
B(5,4,6,AIR)
B(6,4,6,AIR)
B(7,4,6,AIR)
B(1,5,6,AIR)
B(2,5,6,AIR)
B(3,5,6,AIR)
B(4,5,6,AIR)
B(5,5,6,AIR)
B(6,5,6,AIR)
B(7,5,6,AIR)
B(1,6,6,STONE_BRICK_STAIRS:6)
B(2,6,6,AIR)
B(3,6,6,AIR)
B(4,6,6,AIR)
B(5,6,6,AIR)
B(6,6,6,AIR)
B(7,6,6,STONE_BRICK_STAIRS:6)
B(2,7,6,AIR)
B(3,7,6,AIR)
B(4,7,6,AIR)
B(5,7,6,AIR)
B(6,7,6,AIR)
B(1,9,6,AIR)
B(2,9,6,AIR)
B(3,9,6,AIR)
B(4,9,6,AIR)
B(5,9,6,AIR)
B(6,9,6,AIR)
B(7,9,6,AIR)
B(1,10,6,AIR)
B(2,10,6,AIR)
B(3,10,6,AIR)
B(4,10,6,AIR)
B(5,10,6,AIR)
B(6,10,6,AIR)
B(7,10,6,AIR)
B(1,11,6,AIR)
B(2,11,6,AIR)
B(3,11,6,AIR)
B(4,11,6,AIR)
B(5,11,6,AIR)
B(6,11,6,AIR)
B(7,11,6,AIR)
B(1,12,6,AIR)
B(2,12,6,AIR)
B(3,12,6,AIR)
B(4,12,6,AIR)
B(5,12,6,AIR)
B(6,12,6,AIR)
B(7,12,6,AIR)
B(1,13,6,AIR)
B(2,13,6,AIR)
B(3,13,6,AIR)
B(4,13,6,AIR)
B(5,13,6,AIR)
B(6,13,6,AIR)
B(7,13,6,AIR)
B(1,14,6,STONE_BRICK_STAIRS:6)
B(2,14,6,AIR)
B(3,14,6,AIR)
B(4,14,6,AIR)
B(5,14,6,AIR)
B(6,14,6,AIR)
B(7,14,6,STONE_BRICK_STAIRS:6)
B(2,15,6,AIR)
B(3,15,6,AIR)
B(4,15,6,AIR)
B(5,15,6,AIR)
B(6,15,6,AIR)
B(2,1,7,AIR)
B(3,1,7,AIR)
B(4,1,7,AIR)
B(5,1,7,AIR)
B(6,1,7,AIR)
B(2,2,7,AIR)
B(3,2,7,AIR)
B(4,2,7,AIR)
B(5,2,7,AIR)
B(6,2,7,AIR)
B(2,3,7,AIR)
B(3,3,7,AIR)
B(4,3,7,AIR)
B(5,3,7,AIR)
B(6,3,7,AIR)
B(2,4,7,AIR)
B(3,4,7,AIR)
B(4,4,7,AIR)
B(5,4,7,AIR)
B(6,4,7,AIR)
B(2,5,7,AIR)
B(3,5,7,AIR)
B(4,5,7,AIR)
B(5,5,7,AIR)
B(6,5,7,AIR)
B(2,6,7,STONE_BRICK_STAIRS:5)
B(3,6,7,AIR)
B(4,6,7,AIR)
B(5,6,7,AIR)
B(6,6,7,STONE_BRICK_STAIRS:4)
B(2,9,7,AIR)
B(3,9,7,AIR)
B(4,9,7,AIR)
B(5,9,7,AIR)
B(6,9,7,AIR)
B(2,10,7,AIR)
B(3,10,7,AIR)
B(4,10,7,AIR)
B(5,10,7,AIR)
B(6,10,7,AIR)
B(2,11,7,AIR)
B(3,11,7,AIR)
B(4,11,7,AIR)
B(5,11,7,AIR)
B(6,11,7,AIR)
B(2,12,7,AIR)
B(3,12,7,AIR)
B(4,12,7,AIR)
B(5,12,7,AIR)
B(6,12,7,AIR)
B(2,13,7,AIR)
B(3,13,7,AIR)
B(4,13,7,AIR)
B(5,13,7,AIR)
B(6,13,7,AIR)
B(2,14,7,STONE_BRICK_STAIRS:5)
B(3,14,7,AIR)
B(4,14,7,AIR)
B(5,14,7,AIR)
B(6,14,7,STONE_BRICK_STAIRS:4)
B(4,1,8,AIR)
B(4,2,8,AIR)
B(4,3,8,AIR)
B(4,9,8,AIR)
B(4,10,8,AIR)
B(4,11,8,AIR)
B(2,1,9,AIR)
B(3,1,9,AIR)
B(4,1,9,AIR)
B(5,1,9,AIR)
B(6,1,9,AIR)
B(10,1,9,AIR)
B(11,1,9,AIR)
B(13,1,9,AIR)
B(14,1,9,AIR)
B(2,2,9,AIR)
B(3,2,9,AIR)
B(4,2,9,AIR)
B(5,2,9,AIR)
B(6,2,9,AIR)
B(10,2,9,AIR)
B(11,2,9,AIR)
B(13,2,9,AIR)
B(14,2,9,AIR)
B(2,3,9,AIR)
B(3,3,9,AIR)
B(4,3,9,AIR)
B(5,3,9,AIR)
B(6,3,9,AIR)
B(10,3,9,AIR)
B(11,3,9,AIR)
B(12,3,9,AIR)
B(13,3,9,AIR)
B(14,3,9,AIR)
B(2,4,9,AIR)
B(3,4,9,AIR)
B(4,4,9,AIR)
B(5,4,9,AIR)
B(6,4,9,AIR)
B(10,4,9,AIR)
B(11,4,9,AIR)
B(12,4,9,AIR)
B(13,4,9,AIR)
B(14,4,9,AIR)
B(2,5,9,AIR)
B(3,5,9,AIR)
B(4,5,9,AIR)
B(5,5,9,AIR)
B(6,5,9,AIR)
B(10,5,9,AIR)
B(11,5,9,AIR)
B(12,5,9,AIR)
B(13,5,9,AIR)
B(14,5,9,AIR)
B(2,6,9,AIR)
B(3,6,9,AIR)
B(4,6,9,AIR)
B(5,6,9,AIR)
B(6,6,9,AIR)
B(10,6,9,AIR)
B(11,6,9,AIR)
B(12,6,9,AIR)
B(13,6,9,AIR)
B(14,6,9,AIR)
B(2,7,9,AIR)
B(3,7,9,AIR)
B(4,7,9,AIR)
B(5,7,9,AIR)
B(6,7,9,AIR)
B(10,7,9,AIR)
B(11,7,9,AIR)
B(12,7,9,AIR)
B(13,7,9,AIR)
B(14,7,9,AIR)
B(2,8,9,AIR)
B(3,8,9,STONE_BRICK_STAIRS:7)
B(4,8,9,STONE_BRICK_STAIRS:7)
B(5,8,9,STONE_BRICK_STAIRS:7)
B(6,8,9,AIR)
B(10,8,9,AIR)
B(11,8,9,AIR)
B(12,8,9,AIR)
B(13,8,9,AIR)
B(14,8,9,AIR)
B(2,9,9,AIR)
B(3,9,9,AIR)
B(4,9,9,AIR)
B(5,9,9,AIR)
B(6,9,9,AIR)
B(10,9,9,AIR)
B(11,9,9,AIR)
B(12,9,9,AIR)
B(13,9,9,AIR)
B(14,9,9,AIR)
B(2,10,9,AIR)
B(3,10,9,AIR)
B(4,10,9,AIR)
B(5,10,9,AIR)
B(6,10,9,AIR)
B(10,10,9,AIR)
B(11,10,9,AIR)
B(12,10,9,AIR)
B(13,10,9,AIR)
B(14,10,9,AIR)
B(2,11,9,AIR)
B(3,11,9,AIR)
B(4,11,9,AIR)
B(5,11,9,AIR)
B(6,11,9,AIR)
B(10,11,9,AIR)
B(11,11,9,AIR)
B(12,11,9,AIR)
B(13,11,9,AIR)
B(14,11,9,AIR)
B(2,12,9,AIR)
B(3,12,9,AIR)
B(4,12,9,AIR)
B(5,12,9,AIR)
B(6,12,9,AIR)
B(10,12,9,AIR)
B(11,12,9,AIR)
B(12,12,9,AIR)
B(13,12,9,AIR)
B(14,12,9,AIR)
B(2,13,9,AIR)
B(3,13,9,AIR)
B(4,13,9,AIR)
B(5,13,9,AIR)
B(6,13,9,AIR)
B(10,13,9,AIR)
B(11,13,9,AIR)
B(12,13,9,AIR)
B(13,13,9,AIR)
B(14,13,9,AIR)
B(2,14,9,STONE_BRICK_STAIRS:5)
B(3,14,9,AIR)
B(4,14,9,AIR)
B(5,14,9,AIR)
B(6,14,9,STONE_BRICK_STAIRS:4)
B(10,14,9,STONE_BRICK_STAIRS:5)
B(11,14,9,AIR)
B(12,14,9,AIR)
B(13,14,9,AIR)
B(14,14,9,STONE_BRICK_STAIRS:4)
B(1,1,10,AIR)
B(2,1,10,AIR)
B(3,1,10,AIR)
B(4,1,10,AIR)
B(5,1,10,AIR)
B(6,1,10,AIR)
B(7,1,10,AIR)
B(8,1,10,AIR)
B(9,1,10,AIR)
B(10,1,10,AIR)
B(11,1,10,AIR)
B(12,1,10,AIR)
B(13,1,10,AIR)
B(14,1,10,AIR)
B(15,1,10,AIR)
B(1,2,10,AIR)
B(2,2,10,AIR)
B(3,2,10,AIR)
B(4,2,10,AIR)
B(5,2,10,AIR)
B(6,2,10,AIR)
B(7,2,10,AIR)
B(8,2,10,AIR)
B(9,2,10,AIR)
B(10,2,10,AIR)
B(11,2,10,AIR)
B(12,2,10,AIR)
B(13,2,10,AIR)
B(14,2,10,AIR)
B(15,2,10,AIR)
B(1,3,10,AIR)
B(2,3,10,AIR)
B(3,3,10,AIR)
B(4,3,10,AIR)
B(5,3,10,AIR)
B(6,3,10,AIR)
B(7,3,10,AIR)
B(8,3,10,AIR)
B(9,3,10,AIR)
B(10,3,10,AIR)
B(11,3,10,AIR)
B(12,3,10,AIR)
B(13,3,10,AIR)
B(14,3,10,AIR)
B(15,3,10,AIR)
B(1,4,10,AIR)
B(2,4,10,AIR)
B(3,4,10,AIR)
B(4,4,10,AIR)
B(5,4,10,AIR)
B(6,4,10,AIR)
B(7,4,10,AIR)
B(8,4,10,AIR)
B(9,4,10,AIR)
B(10,4,10,AIR)
B(11,4,10,AIR)
B(12,4,10,AIR)
B(13,4,10,AIR)
B(14,4,10,AIR)
B(15,4,10,AIR)
B(1,5,10,AIR)
B(2,5,10,AIR)
B(3,5,10,AIR)
B(4,5,10,AIR)
B(5,5,10,AIR)
B(6,5,10,AIR)
B(7,5,10,AIR)
B(8,5,10,AIR)
B(9,5,10,AIR)
B(10,5,10,AIR)
B(11,5,10,AIR)
B(12,5,10,AIR)
B(13,5,10,AIR)
B(14,5,10,AIR)
B(15,5,10,AIR)
B(1,6,10,AIR)
B(2,6,10,AIR)
B(3,6,10,AIR)
B(4,6,10,AIR)
B(5,6,10,AIR)
B(6,6,10,AIR)
B(7,6,10,AIR)
B(8,6,10,AIR)
B(9,6,10,AIR)
B(10,6,10,AIR)
B(11,6,10,AIR)
B(12,6,10,AIR)
B(13,6,10,AIR)
B(14,6,10,AIR)
B(15,6,10,AIR)
B(1,7,10,AIR)
B(2,7,10,AIR)
B(3,7,10,AIR)
B(4,7,10,AIR)
B(5,7,10,AIR)
B(6,7,10,AIR)
B(7,7,10,AIR)
B(8,7,10,AIR)
B(9,7,10,AIR)
B(10,7,10,AIR)
B(11,7,10,AIR)
B(12,7,10,AIR)
B(13,7,10,AIR)
B(14,7,10,AIR)
B(15,7,10,AIR)
B(1,8,10,AIR)
B(2,8,10,AIR)
B(3,8,10,AIR)
B(4,8,10,AIR)
B(5,8,10,AIR)
B(6,8,10,AIR)
B(7,8,10,AIR)
B(8,8,10,AIR)
B(9,8,10,AIR)
B(10,8,10,AIR)
B(11,8,10,AIR)
B(12,8,10,AIR)
B(13,8,10,AIR)
B(14,8,10,AIR)
B(15,8,10,AIR)
B(1,9,10,AIR)
B(2,9,10,AIR)
B(3,9,10,AIR)
B(4,9,10,AIR)
B(5,9,10,AIR)
B(6,9,10,AIR)
B(7,9,10,AIR)
B(8,9,10,AIR)
B(9,9,10,AIR)
B(10,9,10,AIR)
B(11,9,10,AIR)
B(12,9,10,AIR)
B(13,9,10,AIR)
B(14,9,10,AIR)
B(15,9,10,AIR)
B(1,10,10,AIR)
B(2,10,10,AIR)
B(3,10,10,AIR)
B(4,10,10,AIR)
B(5,10,10,AIR)
B(6,10,10,AIR)
B(7,10,10,AIR)
B(8,10,10,AIR)
B(9,10,10,AIR)
B(10,10,10,AIR)
B(11,10,10,AIR)
B(12,10,10,AIR)
B(13,10,10,AIR)
B(14,10,10,AIR)
B(15,10,10,AIR)
B(1,11,10,AIR)
B(2,11,10,AIR)
B(3,11,10,AIR)
B(4,11,10,AIR)
B(5,11,10,AIR)
B(6,11,10,AIR)
B(7,11,10,AIR)
B(8,11,10,AIR)
B(9,11,10,AIR)
B(10,11,10,AIR)
B(11,11,10,AIR)
B(12,11,10,AIR)
B(13,11,10,AIR)
B(14,11,10,AIR)
B(15,11,10,AIR)
B(1,12,10,AIR)
B(2,12,10,AIR)
B(3,12,10,AIR)
B(4,12,10,AIR)
B(5,12,10,AIR)
B(6,12,10,AIR)
B(7,12,10,AIR)
B(8,12,10,AIR)
B(9,12,10,AIR)
B(10,12,10,AIR)
B(11,12,10,AIR)
B(12,12,10,AIR)
B(13,12,10,AIR)
B(14,12,10,AIR)
B(15,12,10,AIR)
B(1,13,10,AIR)
B(2,13,10,AIR)
B(3,13,10,AIR)
B(4,13,10,AIR)
B(5,13,10,AIR)
B(6,13,10,AIR)
B(7,13,10,AIR)
B(8,13,10,AIR)
B(9,13,10,AIR)
B(10,13,10,AIR)
B(11,13,10,AIR)
B(12,13,10,AIR)
B(13,13,10,AIR)
B(14,13,10,AIR)
B(15,13,10,AIR)
B(1,14,10,STONE_BRICK_STAIRS:7)
B(2,14,10,AIR)
B(3,14,10,AIR)
B(4,14,10,AIR)
B(5,14,10,AIR)
B(6,14,10,AIR)
B(7,14,10,STONE_BRICK_STAIRS:7)
B(8,14,10,STONE_BRICK_STAIRS:7)
B(9,14,10,STONE_BRICK_STAIRS:7)
B(10,14,10,AIR)
B(11,14,10,AIR)
B(12,14,10,AIR)
B(13,14,10,AIR)
B(14,14,10,AIR)
B(15,14,10,STONE_BRICK_STAIRS:7)
B(2,15,10,AIR)
B(3,15,10,AIR)
B(4,15,10,AIR)
B(5,15,10,AIR)
B(6,15,10,AIR)
B(10,15,10,AIR)
B(11,15,10,AIR)
B(12,15,10,AIR)
B(13,15,10,AIR)
B(14,15,10,AIR)
B(1,1,11,AIR)
B(2,1,11,AIR)
B(3,1,11,TALLGRASS:1)
B(4,1,11,TALLGRASS:1)
B(5,1,11,TALLGRASS:2)
B(6,1,11,TALLGRASS:1)
B(7,1,11,TALLGRASS:1)
B(8,1,11,TALLGRASS:1)
B(9,1,11,AIR)
B(10,1,11,TALLGRASS:1)
B(11,1,11,AIR)
B(12,1,11,TALLGRASS:1)
B(13,1,11,AIR)
B(14,1,11,AIR)
B(15,1,11,AIR)
B(1,2,11,AIR)
B(2,2,11,AIR)
B(3,2,11,AIR)
B(4,2,11,AIR)
B(5,2,11,AIR)
B(6,2,11,AIR)
B(7,2,11,AIR)
B(8,2,11,AIR)
B(9,2,11,AIR)
B(10,2,11,AIR)
B(11,2,11,AIR)
B(12,2,11,AIR)
B(13,2,11,AIR)
B(14,2,11,AIR)
B(15,2,11,AIR)
B(1,3,11,AIR)
B(2,3,11,AIR)
B(3,3,11,AIR)
B(4,3,11,AIR)
B(5,3,11,AIR)
B(6,3,11,AIR)
B(7,3,11,AIR)
B(8,3,11,AIR)
B(9,3,11,AIR)
B(10,3,11,AIR)
B(11,3,11,AIR)
B(12,3,11,AIR)
B(13,3,11,AIR)
B(14,3,11,AIR)
B(15,3,11,AIR)
B(1,4,11,AIR)
B(2,4,11,AIR)
B(3,4,11,AIR)
B(4,4,11,AIR)
B(5,4,11,AIR)
B(6,4,11,AIR)
B(7,4,11,AIR)
B(8,4,11,AIR)
B(9,4,11,AIR)
B(10,4,11,AIR)
B(11,4,11,AIR)
B(12,4,11,AIR)
B(13,4,11,AIR)
B(14,4,11,AIR)
B(15,4,11,AIR)
B(1,5,11,AIR)
B(2,5,11,AIR)
B(3,5,11,AIR)
B(4,5,11,AIR)
B(5,5,11,AIR)
B(6,5,11,AIR)
B(7,5,11,AIR)
B(8,5,11,AIR)
B(9,5,11,AIR)
B(10,5,11,AIR)
B(11,5,11,AIR)
B(12,5,11,AIR)
B(13,5,11,AIR)
B(14,5,11,AIR)
B(15,5,11,AIR)
B(1,6,11,AIR)
B(2,6,11,AIR)
B(3,6,11,AIR)
B(4,6,11,AIR)
B(5,6,11,AIR)
B(6,6,11,AIR)
B(7,6,11,AIR)
B(8,6,11,AIR)
B(9,6,11,AIR)
B(10,6,11,AIR)
B(11,6,11,AIR)
B(12,6,11,AIR)
B(13,6,11,AIR)
B(14,6,11,AIR)
B(15,6,11,AIR)
B(1,7,11,AIR)
B(2,7,11,AIR)
B(3,7,11,AIR)
B(4,7,11,AIR)
B(5,7,11,AIR)
B(6,7,11,AIR)
B(7,7,11,AIR)
B(8,7,11,AIR)
B(9,7,11,AIR)
B(10,7,11,AIR)
B(11,7,11,AIR)
B(12,7,11,AIR)
B(13,7,11,AIR)
B(14,7,11,AIR)
B(15,7,11,AIR)
B(1,8,11,AIR)
B(2,8,11,AIR)
B(3,8,11,AIR)
B(4,8,11,AIR)
B(5,8,11,AIR)
B(6,8,11,AIR)
B(7,8,11,AIR)
B(8,8,11,AIR)
B(9,8,11,AIR)
B(10,8,11,AIR)
B(11,8,11,AIR)
B(12,8,11,AIR)
B(13,8,11,AIR)
B(14,8,11,AIR)
B(15,8,11,AIR)
B(1,9,11,AIR)
B(2,9,11,AIR)
B(3,9,11,AIR)
B(4,9,11,AIR)
B(5,9,11,AIR)
B(6,9,11,AIR)
B(7,9,11,AIR)
B(8,9,11,AIR)
B(9,9,11,AIR)
B(10,9,11,AIR)
B(11,9,11,AIR)
B(12,9,11,AIR)
B(13,9,11,AIR)
B(14,9,11,AIR)
B(15,9,11,AIR)
B(1,10,11,AIR)
B(2,10,11,AIR)
B(3,10,11,AIR)
B(4,10,11,AIR)
B(5,10,11,AIR)
B(6,10,11,AIR)
B(7,10,11,AIR)
B(8,10,11,AIR)
B(9,10,11,AIR)
B(10,10,11,AIR)
B(11,10,11,AIR)
B(12,10,11,AIR)
B(13,10,11,AIR)
B(14,10,11,AIR)
B(15,10,11,AIR)
B(1,11,11,AIR)
B(2,11,11,AIR)
B(3,11,11,AIR)
B(4,11,11,AIR)
B(5,11,11,AIR)
B(6,11,11,AIR)
B(7,11,11,AIR)
B(8,11,11,AIR)
B(9,11,11,AIR)
B(10,11,11,AIR)
B(11,11,11,AIR)
B(12,11,11,AIR)
B(13,11,11,AIR)
B(14,11,11,AIR)
B(15,11,11,AIR)
B(1,12,11,AIR)
B(2,12,11,AIR)
B(3,12,11,AIR)
B(4,12,11,AIR)
B(5,12,11,AIR)
B(6,12,11,AIR)
B(7,12,11,AIR)
B(8,12,11,AIR)
B(9,12,11,AIR)
B(10,12,11,AIR)
B(11,12,11,AIR)
B(12,12,11,AIR)
B(13,12,11,AIR)
B(14,12,11,AIR)
B(15,12,11,AIR)
B(1,13,11,AIR)
B(2,13,11,AIR)
B(3,13,11,AIR)
B(4,13,11,AIR)
B(5,13,11,AIR)
B(6,13,11,AIR)
B(7,13,11,AIR)
B(8,13,11,AIR)
B(9,13,11,AIR)
B(10,13,11,AIR)
B(11,13,11,AIR)
B(12,13,11,AIR)
B(13,13,11,AIR)
B(14,13,11,AIR)
B(15,13,11,AIR)
B(1,14,11,AIR)
B(2,14,11,AIR)
B(3,14,11,AIR)
B(4,14,11,AIR)
B(5,14,11,AIR)
B(6,14,11,AIR)
B(7,14,11,AIR)
B(8,14,11,AIR)
B(9,14,11,AIR)
B(10,14,11,AIR)
B(11,14,11,AIR)
B(12,14,11,AIR)
B(13,14,11,AIR)
B(14,14,11,AIR)
B(15,14,11,AIR)
B(2,15,11,AIR)
B(3,15,11,AIR)
B(4,15,11,AIR)
B(5,15,11,AIR)
B(6,15,11,AIR)
B(10,15,11,AIR)
B(11,15,11,AIR)
B(12,15,11,AIR)
B(13,15,11,AIR)
B(14,15,11,AIR)
B(3,16,11,AIR)
B(4,16,11,AIR)
B(5,16,11,AIR)
B(11,16,11,AIR)
B(12,16,11,AIR)
B(13,16,11,AIR)
B(0,1,12,AIR)
B(1,1,12,AIR)
B(2,1,12,AIR)
B(3,1,12,TALLGRASS:1)
B(4,1,12,AIR)
B(5,1,12,TALLGRASS:1)
B(6,1,12,AIR)
B(7,1,12,AIR)
B(8,1,12,TALLGRASS:1)
B(9,1,12,TALLGRASS:2)
B(10,1,12,TALLGRASS:2)
B(11,1,12,TALLGRASS:1)
B(12,1,12,TALLGRASS:2)
B(13,1,12,TALLGRASS:2)
B(14,1,12,AIR)
B(15,1,12,AIR)
B(16,1,12,AIR)
B(0,2,12,AIR)
B(1,2,12,AIR)
B(2,2,12,AIR)
B(3,2,12,AIR)
B(4,2,12,AIR)
B(5,2,12,AIR)
B(6,2,12,AIR)
B(7,2,12,AIR)
B(8,2,12,AIR)
B(9,2,12,AIR)
B(10,2,12,AIR)
B(11,2,12,AIR)
B(12,2,12,AIR)
B(13,2,12,AIR)
B(14,2,12,AIR)
B(15,2,12,AIR)
B(16,2,12,AIR)
B(0,3,12,AIR)
B(1,3,12,AIR)
B(2,3,12,AIR)
B(3,3,12,AIR)
B(4,3,12,AIR)
B(5,3,12,AIR)
B(6,3,12,AIR)
B(7,3,12,AIR)
B(8,3,12,AIR)
B(9,3,12,AIR)
B(10,3,12,AIR)
B(11,3,12,AIR)
B(12,3,12,AIR)
B(13,3,12,AIR)
B(14,3,12,AIR)
B(15,3,12,AIR)
B(16,3,12,AIR)
B(1,4,12,AIR)
B(2,4,12,AIR)
B(3,4,12,AIR)
B(4,4,12,AIR)
B(5,4,12,AIR)
B(6,4,12,AIR)
B(7,4,12,AIR)
B(8,4,12,AIR)
B(9,4,12,AIR)
B(10,4,12,AIR)
B(11,4,12,AIR)
B(12,4,12,AIR)
B(13,4,12,AIR)
B(14,4,12,AIR)
B(15,4,12,AIR)
B(1,5,12,AIR)
B(2,5,12,AIR)
B(3,5,12,AIR)
B(4,5,12,AIR)
B(5,5,12,AIR)
B(6,5,12,AIR)
B(7,5,12,AIR)
B(8,5,12,AIR)
B(9,5,12,AIR)
B(10,5,12,AIR)
B(11,5,12,AIR)
B(12,5,12,AIR)
B(13,5,12,AIR)
B(14,5,12,AIR)
B(15,5,12,AIR)
B(1,6,12,AIR)
B(2,6,12,AIR)
B(3,6,12,AIR)
B(4,6,12,AIR)
B(5,6,12,AIR)
B(6,6,12,AIR)
B(7,6,12,AIR)
B(8,6,12,AIR)
B(9,6,12,AIR)
B(10,6,12,AIR)
B(11,6,12,AIR)
B(12,6,12,AIR)
B(13,6,12,AIR)
B(14,6,12,AIR)
B(15,6,12,AIR)
B(1,7,12,AIR)
B(2,7,12,AIR)
B(3,7,12,AIR)
B(4,7,12,AIR)
B(5,7,12,AIR)
B(6,7,12,AIR)
B(7,7,12,AIR)
B(8,7,12,AIR)
B(9,7,12,AIR)
B(10,7,12,AIR)
B(11,7,12,AIR)
B(12,7,12,AIR)
B(13,7,12,AIR)
B(14,7,12,AIR)
B(15,7,12,AIR)
B(1,8,12,AIR)
B(2,8,12,AIR)
B(3,8,12,AIR)
B(4,8,12,AIR)
B(5,8,12,AIR)
B(6,8,12,AIR)
B(7,8,12,AIR)
B(8,8,12,AIR)
B(9,8,12,AIR)
B(10,8,12,AIR)
B(11,8,12,AIR)
B(12,8,12,AIR)
B(13,8,12,AIR)
B(14,8,12,AIR)
B(15,8,12,AIR)
B(1,9,12,AIR)
B(2,9,12,AIR)
B(3,9,12,AIR)
B(4,9,12,AIR)
B(5,9,12,AIR)
B(6,9,12,AIR)
B(7,9,12,AIR)
B(8,9,12,AIR)
B(9,9,12,AIR)
B(10,9,12,AIR)
B(11,9,12,AIR)
B(12,9,12,AIR)
B(13,9,12,AIR)
B(14,9,12,AIR)
B(15,9,12,AIR)
B(1,10,12,AIR)
B(2,10,12,AIR)
B(3,10,12,AIR)
B(4,10,12,AIR)
B(5,10,12,AIR)
B(6,10,12,AIR)
B(7,10,12,AIR)
B(8,10,12,AIR)
B(9,10,12,AIR)
B(10,10,12,AIR)
B(11,10,12,AIR)
B(12,10,12,AIR)
B(13,10,12,AIR)
B(14,10,12,AIR)
B(15,10,12,AIR)
B(1,11,12,AIR)
B(2,11,12,AIR)
B(3,11,12,AIR)
B(4,11,12,AIR)
B(5,11,12,AIR)
B(6,11,12,AIR)
B(7,11,12,AIR)
B(8,11,12,AIR)
B(9,11,12,AIR)
B(10,11,12,AIR)
B(11,11,12,AIR)
B(12,11,12,AIR)
B(13,11,12,AIR)
B(14,11,12,AIR)
B(15,11,12,AIR)
B(1,12,12,AIR)
B(2,12,12,AIR)
B(3,12,12,AIR)
B(4,12,12,AIR)
B(5,12,12,AIR)
B(6,12,12,AIR)
B(7,12,12,AIR)
B(8,12,12,AIR)
B(9,12,12,AIR)
B(10,12,12,AIR)
B(11,12,12,AIR)
B(12,12,12,AIR)
B(13,12,12,AIR)
B(14,12,12,AIR)
B(15,12,12,AIR)
B(1,13,12,AIR)
B(2,13,12,AIR)
B(3,13,12,AIR)
B(4,13,12,AIR)
B(5,13,12,AIR)
B(6,13,12,AIR)
B(7,13,12,AIR)
B(8,13,12,AIR)
B(9,13,12,AIR)
B(10,13,12,AIR)
B(11,13,12,AIR)
B(12,13,12,AIR)
B(13,13,12,AIR)
B(14,13,12,AIR)
B(15,13,12,AIR)
B(1,14,12,AIR)
B(2,14,12,AIR)
B(3,14,12,AIR)
B(4,14,12,AIR)
B(5,14,12,AIR)
B(6,14,12,AIR)
B(7,14,12,AIR)
B(8,14,12,AIR)
B(9,14,12,AIR)
B(10,14,12,AIR)
B(11,14,12,AIR)
B(12,14,12,AIR)
B(13,14,12,AIR)
B(14,14,12,AIR)
B(15,14,12,AIR)
B(2,15,12,AIR)
B(3,15,12,AIR)
B(4,15,12,AIR)
B(5,15,12,AIR)
B(6,15,12,AIR)
B(10,15,12,AIR)
B(11,15,12,AIR)
B(12,15,12,AIR)
B(13,15,12,AIR)
B(14,15,12,AIR)
B(3,16,12,AIR)
B(4,16,12,AIR)
B(5,16,12,AIR)
B(11,16,12,AIR)
B(12,16,12,AIR)
B(13,16,12,AIR)
B(1,1,13,AIR)
B(2,1,13,AIR)
B(3,1,13,TALLGRASS:2)
B(4,1,13,AIR)
B(5,1,13,TALLGRASS:2)
B(6,1,13,TALLGRASS:1)
B(7,1,13,TALLGRASS:2)
B(8,1,13,AIR)
B(9,1,13,TALLGRASS:1)
B(10,1,13,AIR)
B(11,1,13,TALLGRASS:1)
B(12,1,13,TALLGRASS:1)
B(13,1,13,AIR)
B(14,1,13,AIR)
B(15,1,13,AIR)
B(1,2,13,AIR)
B(2,2,13,AIR)
B(3,2,13,AIR)
B(4,2,13,AIR)
B(5,2,13,AIR)
B(6,2,13,AIR)
B(7,2,13,AIR)
B(8,2,13,AIR)
B(9,2,13,AIR)
B(10,2,13,AIR)
B(11,2,13,AIR)
B(12,2,13,AIR)
B(13,2,13,AIR)
B(14,2,13,AIR)
B(15,2,13,AIR)
B(1,3,13,AIR)
B(2,3,13,AIR)
B(3,3,13,AIR)
B(4,3,13,AIR)
B(5,3,13,AIR)
B(6,3,13,AIR)
B(7,3,13,AIR)
B(8,3,13,AIR)
B(9,3,13,AIR)
B(10,3,13,AIR)
B(11,3,13,AIR)
B(12,3,13,AIR)
B(13,3,13,AIR)
B(14,3,13,AIR)
B(15,3,13,AIR)
B(1,4,13,AIR)
B(2,4,13,AIR)
B(3,4,13,AIR)
B(4,4,13,AIR)
B(5,4,13,AIR)
B(6,4,13,AIR)
B(7,4,13,AIR)
B(8,4,13,AIR)
B(9,4,13,AIR)
B(10,4,13,AIR)
B(11,4,13,AIR)
B(12,4,13,AIR)
B(13,4,13,AIR)
B(14,4,13,AIR)
B(15,4,13,AIR)
B(1,5,13,AIR)
B(2,5,13,AIR)
B(3,5,13,AIR)
B(4,5,13,AIR)
B(5,5,13,AIR)
B(6,5,13,AIR)
B(7,5,13,AIR)
B(8,5,13,AIR)
B(9,5,13,AIR)
B(10,5,13,AIR)
B(11,5,13,AIR)
B(12,5,13,AIR)
B(13,5,13,AIR)
B(14,5,13,AIR)
B(15,5,13,AIR)
B(1,6,13,AIR)
B(2,6,13,AIR)
B(3,6,13,AIR)
B(4,6,13,AIR)
B(5,6,13,AIR)
B(6,6,13,AIR)
B(7,6,13,AIR)
B(8,6,13,AIR)
B(9,6,13,AIR)
B(10,6,13,AIR)
B(11,6,13,AIR)
B(12,6,13,AIR)
B(13,6,13,AIR)
B(14,6,13,AIR)
B(15,6,13,AIR)
B(1,7,13,AIR)
B(2,7,13,AIR)
B(3,7,13,AIR)
B(4,7,13,AIR)
B(5,7,13,AIR)
B(6,7,13,AIR)
B(7,7,13,AIR)
B(8,7,13,AIR)
B(9,7,13,AIR)
B(10,7,13,AIR)
B(11,7,13,AIR)
B(12,7,13,AIR)
B(13,7,13,AIR)
B(14,7,13,AIR)
B(15,7,13,AIR)
B(1,8,13,AIR)
B(2,8,13,AIR)
B(3,8,13,AIR)
B(4,8,13,AIR)
B(5,8,13,AIR)
B(6,8,13,AIR)
B(7,8,13,AIR)
B(8,8,13,AIR)
B(9,8,13,AIR)
B(10,8,13,AIR)
B(11,8,13,AIR)
B(12,8,13,AIR)
B(13,8,13,AIR)
B(14,8,13,AIR)
B(15,8,13,AIR)
B(1,9,13,AIR)
B(2,9,13,AIR)
B(3,9,13,AIR)
B(4,9,13,AIR)
B(5,9,13,AIR)
B(6,9,13,AIR)
B(7,9,13,AIR)
B(8,9,13,AIR)
B(9,9,13,AIR)
B(10,9,13,AIR)
B(11,9,13,AIR)
B(12,9,13,AIR)
B(13,9,13,AIR)
B(14,9,13,AIR)
B(15,9,13,AIR)
B(1,10,13,AIR)
B(2,10,13,AIR)
B(3,10,13,AIR)
B(4,10,13,AIR)
B(5,10,13,AIR)
B(6,10,13,AIR)
B(7,10,13,AIR)
B(8,10,13,AIR)
B(9,10,13,AIR)
B(10,10,13,AIR)
B(11,10,13,AIR)
B(12,10,13,AIR)
B(13,10,13,AIR)
B(14,10,13,AIR)
B(15,10,13,AIR)
B(1,11,13,AIR)
B(2,11,13,AIR)
B(3,11,13,AIR)
B(4,11,13,AIR)
B(5,11,13,AIR)
B(6,11,13,AIR)
B(7,11,13,AIR)
B(8,11,13,AIR)
B(9,11,13,AIR)
B(10,11,13,AIR)
B(11,11,13,AIR)
B(12,11,13,AIR)
B(13,11,13,AIR)
B(14,11,13,AIR)
B(15,11,13,AIR)
B(1,12,13,AIR)
B(2,12,13,AIR)
B(3,12,13,AIR)
B(4,12,13,AIR)
B(5,12,13,AIR)
B(6,12,13,AIR)
B(7,12,13,AIR)
B(8,12,13,AIR)
B(9,12,13,AIR)
B(10,12,13,AIR)
B(11,12,13,AIR)
B(12,12,13,AIR)
B(13,12,13,AIR)
B(14,12,13,AIR)
B(15,12,13,AIR)
B(1,13,13,AIR)
B(2,13,13,AIR)
B(3,13,13,AIR)
B(4,13,13,AIR)
B(5,13,13,AIR)
B(6,13,13,AIR)
B(7,13,13,AIR)
B(8,13,13,AIR)
B(9,13,13,AIR)
B(10,13,13,AIR)
B(11,13,13,AIR)
B(12,13,13,AIR)
B(13,13,13,AIR)
B(14,13,13,AIR)
B(15,13,13,AIR)
B(1,14,13,AIR)
B(2,14,13,AIR)
B(3,14,13,AIR)
B(4,14,13,AIR)
B(5,14,13,AIR)
B(6,14,13,AIR)
B(7,14,13,AIR)
B(8,14,13,AIR)
B(9,14,13,AIR)
B(10,14,13,AIR)
B(11,14,13,AIR)
B(12,14,13,AIR)
B(13,14,13,AIR)
B(14,14,13,AIR)
B(15,14,13,AIR)
B(2,15,13,AIR)
B(3,15,13,AIR)
B(4,15,13,AIR)
B(5,15,13,AIR)
B(6,15,13,AIR)
B(10,15,13,AIR)
B(11,15,13,AIR)
B(12,15,13,AIR)
B(13,15,13,AIR)
B(14,15,13,AIR)
B(3,16,13,AIR)
B(4,16,13,AIR)
B(5,16,13,AIR)
B(11,16,13,AIR)
B(12,16,13,AIR)
B(13,16,13,AIR)
B(1,1,14,AIR)
B(2,1,14,AIR)
B(3,1,14,AIR)
B(4,1,14,AIR)
B(5,1,14,AIR)
B(6,1,14,AIR)
B(7,1,14,AIR)
B(8,1,14,AIR)
B(9,1,14,AIR)
B(10,1,14,AIR)
B(11,1,14,AIR)
B(12,1,14,AIR)
B(13,1,14,AIR)
B(14,1,14,AIR)
B(15,1,14,AIR)
B(1,2,14,AIR)
B(2,2,14,AIR)
B(3,2,14,AIR)
B(4,2,14,AIR)
B(5,2,14,AIR)
B(6,2,14,AIR)
B(7,2,14,AIR)
B(8,2,14,AIR)
B(9,2,14,AIR)
B(10,2,14,AIR)
B(11,2,14,AIR)
B(12,2,14,AIR)
B(13,2,14,AIR)
B(14,2,14,AIR)
B(15,2,14,AIR)
B(1,3,14,AIR)
B(2,3,14,AIR)
B(3,3,14,AIR)
B(4,3,14,AIR)
B(5,3,14,AIR)
B(6,3,14,AIR)
B(7,3,14,AIR)
B(8,3,14,AIR)
B(9,3,14,AIR)
B(10,3,14,AIR)
B(11,3,14,AIR)
B(12,3,14,AIR)
B(13,3,14,AIR)
B(14,3,14,AIR)
B(15,3,14,AIR)
B(1,4,14,AIR)
B(2,4,14,AIR)
B(3,4,14,AIR)
B(4,4,14,AIR)
B(5,4,14,AIR)
B(6,4,14,AIR)
B(7,4,14,AIR)
B(8,4,14,AIR)
B(9,4,14,AIR)
B(10,4,14,AIR)
B(11,4,14,AIR)
B(12,4,14,AIR)
B(13,4,14,AIR)
B(14,4,14,AIR)
B(15,4,14,AIR)
B(1,5,14,AIR)
B(2,5,14,AIR)
B(3,5,14,AIR)
B(4,5,14,AIR)
B(5,5,14,AIR)
B(6,5,14,AIR)
B(7,5,14,AIR)
B(8,5,14,AIR)
B(9,5,14,AIR)
B(10,5,14,AIR)
B(11,5,14,AIR)
B(12,5,14,AIR)
B(13,5,14,AIR)
B(14,5,14,AIR)
B(15,5,14,AIR)
B(1,6,14,AIR)
B(2,6,14,AIR)
B(3,6,14,AIR)
B(4,6,14,AIR)
B(5,6,14,AIR)
B(6,6,14,AIR)
B(7,6,14,AIR)
B(8,6,14,AIR)
B(9,6,14,AIR)
B(10,6,14,AIR)
B(11,6,14,AIR)
B(12,6,14,AIR)
B(13,6,14,AIR)
B(14,6,14,AIR)
B(15,6,14,AIR)
B(1,7,14,AIR)
B(2,7,14,AIR)
B(3,7,14,AIR)
B(4,7,14,AIR)
B(5,7,14,AIR)
B(6,7,14,AIR)
B(7,7,14,AIR)
B(8,7,14,AIR)
B(9,7,14,AIR)
B(10,7,14,AIR)
B(11,7,14,AIR)
B(12,7,14,AIR)
B(13,7,14,AIR)
B(14,7,14,AIR)
B(15,7,14,AIR)
B(1,8,14,AIR)
B(2,8,14,AIR)
B(3,8,14,AIR)
B(4,8,14,AIR)
B(5,8,14,AIR)
B(6,8,14,AIR)
B(7,8,14,AIR)
B(8,8,14,AIR)
B(9,8,14,AIR)
B(10,8,14,AIR)
B(11,8,14,AIR)
B(12,8,14,AIR)
B(13,8,14,AIR)
B(14,8,14,AIR)
B(15,8,14,AIR)
B(1,9,14,AIR)
B(2,9,14,AIR)
B(3,9,14,AIR)
B(4,9,14,AIR)
B(5,9,14,AIR)
B(6,9,14,AIR)
B(7,9,14,AIR)
B(8,9,14,AIR)
B(9,9,14,AIR)
B(10,9,14,AIR)
B(11,9,14,AIR)
B(12,9,14,AIR)
B(13,9,14,AIR)
B(14,9,14,AIR)
B(15,9,14,AIR)
B(1,10,14,AIR)
B(2,10,14,AIR)
B(3,10,14,AIR)
B(4,10,14,AIR)
B(5,10,14,AIR)
B(6,10,14,AIR)
B(7,10,14,AIR)
B(8,10,14,AIR)
B(9,10,14,AIR)
B(10,10,14,AIR)
B(11,10,14,AIR)
B(12,10,14,AIR)
B(13,10,14,AIR)
B(14,10,14,AIR)
B(15,10,14,AIR)
B(1,11,14,AIR)
B(2,11,14,AIR)
B(3,11,14,AIR)
B(4,11,14,AIR)
B(5,11,14,AIR)
B(6,11,14,AIR)
B(7,11,14,AIR)
B(8,11,14,AIR)
B(9,11,14,AIR)
B(10,11,14,AIR)
B(11,11,14,AIR)
B(12,11,14,AIR)
B(13,11,14,AIR)
B(14,11,14,AIR)
B(15,11,14,AIR)
B(1,12,14,AIR)
B(2,12,14,AIR)
B(3,12,14,AIR)
B(4,12,14,AIR)
B(5,12,14,AIR)
B(6,12,14,AIR)
B(7,12,14,AIR)
B(8,12,14,AIR)
B(9,12,14,AIR)
B(10,12,14,AIR)
B(11,12,14,AIR)
B(12,12,14,AIR)
B(13,12,14,AIR)
B(14,12,14,AIR)
B(15,12,14,AIR)
B(1,13,14,AIR)
B(2,13,14,AIR)
B(3,13,14,AIR)
B(4,13,14,AIR)
B(5,13,14,AIR)
B(6,13,14,AIR)
B(7,13,14,AIR)
B(8,13,14,AIR)
B(9,13,14,AIR)
B(10,13,14,AIR)
B(11,13,14,AIR)
B(12,13,14,AIR)
B(13,13,14,AIR)
B(14,13,14,AIR)
B(15,13,14,AIR)
B(1,14,14,STONE_BRICK_STAIRS:6)
B(2,14,14,AIR)
B(3,14,14,AIR)
B(4,14,14,AIR)
B(5,14,14,AIR)
B(6,14,14,AIR)
B(7,14,14,STONE_BRICK_STAIRS:6)
B(8,14,14,STONE_BRICK_STAIRS:6)
B(9,14,14,STONE_BRICK_STAIRS:6)
B(10,14,14,AIR)
B(11,14,14,AIR)
B(12,14,14,AIR)
B(13,14,14,AIR)
B(14,14,14,AIR)
B(15,14,14,STONE_BRICK_STAIRS:6)
B(2,15,14,AIR)
B(3,15,14,AIR)
B(4,15,14,AIR)
B(5,15,14,AIR)
B(6,15,14,AIR)
B(10,15,14,AIR)
B(11,15,14,AIR)
B(12,15,14,AIR)
B(13,15,14,AIR)
B(14,15,14,AIR)
B(2,1,15,AIR)
B(3,1,15,AIR)
B(5,1,15,AIR)
B(6,1,15,AIR)
B(10,1,15,AIR)
B(11,1,15,AIR)
B(12,1,15,AIR)
B(13,1,15,AIR)
B(14,1,15,AIR)
B(2,2,15,AIR)
B(3,2,15,AIR)
B(5,2,15,AIR)
B(6,2,15,AIR)
B(10,2,15,AIR)
B(11,2,15,AIR)
B(12,2,15,AIR)
B(13,2,15,AIR)
B(14,2,15,AIR)
B(2,3,15,AIR)
B(3,3,15,AIR)
B(4,3,15,AIR)
B(5,3,15,AIR)
B(6,3,15,AIR)
B(10,3,15,AIR)
B(11,3,15,AIR)
B(12,3,15,AIR)
B(13,3,15,AIR)
B(14,3,15,AIR)
B(2,4,15,AIR)
B(3,4,15,AIR)
B(4,4,15,AIR)
B(5,4,15,AIR)
B(6,4,15,AIR)
B(10,4,15,AIR)
B(11,4,15,AIR)
B(12,4,15,AIR)
B(13,4,15,AIR)
B(14,4,15,AIR)
B(2,5,15,AIR)
B(3,5,15,AIR)
B(4,5,15,AIR)
B(5,5,15,AIR)
B(6,5,15,AIR)
B(10,5,15,AIR)
B(11,5,15,AIR)
B(12,5,15,AIR)
B(13,5,15,AIR)
B(14,5,15,AIR)
B(2,6,15,AIR)
B(3,6,15,AIR)
B(4,6,15,AIR)
B(5,6,15,AIR)
B(6,6,15,AIR)
B(10,6,15,AIR)
B(11,6,15,AIR)
B(12,6,15,AIR)
B(13,6,15,AIR)
B(14,6,15,AIR)
B(2,7,15,AIR)
B(3,7,15,AIR)
B(4,7,15,AIR)
B(5,7,15,AIR)
B(6,7,15,AIR)
B(10,7,15,AIR)
B(11,7,15,AIR)
B(12,7,15,AIR)
B(13,7,15,AIR)
B(14,7,15,AIR)
B(2,8,15,AIR)
B(3,8,15,AIR)
B(4,8,15,AIR)
B(5,8,15,AIR)
B(6,8,15,AIR)
B(10,8,15,AIR)
B(11,8,15,STONE_BRICK_STAIRS:6)
B(12,8,15,STONE_BRICK_STAIRS:6)
B(13,8,15,STONE_BRICK_STAIRS:6)
B(14,8,15,AIR)
B(2,9,15,AIR)
B(3,9,15,AIR)
B(4,9,15,AIR)
B(5,9,15,AIR)
B(6,9,15,AIR)
B(10,9,15,AIR)
B(11,9,15,AIR)
B(12,9,15,AIR)
B(13,9,15,AIR)
B(14,9,15,AIR)
B(2,10,15,AIR)
B(3,10,15,AIR)
B(4,10,15,AIR)
B(5,10,15,AIR)
B(6,10,15,AIR)
B(10,10,15,AIR)
B(11,10,15,AIR)
B(12,10,15,AIR)
B(13,10,15,AIR)
B(14,10,15,AIR)
B(2,11,15,AIR)
B(3,11,15,AIR)
B(4,11,15,AIR)
B(5,11,15,AIR)
B(6,11,15,AIR)
B(10,11,15,AIR)
B(11,11,15,AIR)
B(12,11,15,AIR)
B(13,11,15,AIR)
B(14,11,15,AIR)
B(2,12,15,AIR)
B(3,12,15,AIR)
B(4,12,15,AIR)
B(5,12,15,AIR)
B(6,12,15,AIR)
B(10,12,15,AIR)
B(11,12,15,AIR)
B(12,12,15,AIR)
B(13,12,15,AIR)
B(14,12,15,AIR)
B(2,13,15,AIR)
B(3,13,15,AIR)
B(4,13,15,AIR)
B(5,13,15,AIR)
B(6,13,15,AIR)
B(10,13,15,AIR)
B(11,13,15,AIR)
B(12,13,15,AIR)
B(13,13,15,AIR)
B(14,13,15,AIR)
B(2,14,15,STONE_BRICK_STAIRS:5)
B(3,14,15,AIR)
B(4,14,15,AIR)
B(5,14,15,AIR)
B(6,14,15,STONE_BRICK_STAIRS:4)
B(10,14,15,STONE_BRICK_STAIRS:5)
B(11,14,15,AIR)
B(12,14,15,AIR)
B(13,14,15,AIR)
B(14,14,15,STONE_BRICK_STAIRS:4)
B(12,1,16,AIR)
B(12,2,16,AIR)
B(12,3,16,AIR)
B(12,9,16,AIR)
B(12,10,16,AIR)
B(12,11,16,AIR)
B(10,1,17,AIR)
B(11,1,17,AIR)
B(12,1,17,AIR)
B(13,1,17,AIR)
B(14,1,17,AIR)
B(10,2,17,AIR)
B(11,2,17,AIR)
B(12,2,17,AIR)
B(13,2,17,AIR)
B(14,2,17,AIR)
B(10,3,17,AIR)
B(11,3,17,AIR)
B(12,3,17,AIR)
B(13,3,17,AIR)
B(14,3,17,AIR)
B(10,4,17,AIR)
B(11,4,17,AIR)
B(12,4,17,AIR)
B(13,4,17,AIR)
B(14,4,17,AIR)
B(10,5,17,AIR)
B(11,5,17,AIR)
B(12,5,17,AIR)
B(13,5,17,AIR)
B(14,5,17,AIR)
B(10,6,17,STONE_BRICK_STAIRS:5)
B(11,6,17,AIR)
B(12,6,17,AIR)
B(13,6,17,AIR)
B(14,6,17,STONE_BRICK_STAIRS:4)
B(10,9,17,AIR)
B(11,9,17,AIR)
B(12,9,17,AIR)
B(13,9,17,AIR)
B(14,9,17,AIR)
B(10,10,17,AIR)
B(11,10,17,AIR)
B(12,10,17,AIR)
B(13,10,17,AIR)
B(14,10,17,AIR)
B(10,11,17,AIR)
B(11,11,17,AIR)
B(12,11,17,AIR)
B(13,11,17,AIR)
B(14,11,17,AIR)
B(10,12,17,AIR)
B(11,12,17,AIR)
B(12,12,17,AIR)
B(13,12,17,AIR)
B(14,12,17,AIR)
B(10,13,17,AIR)
B(11,13,17,AIR)
B(12,13,17,AIR)
B(13,13,17,AIR)
B(14,13,17,AIR)
B(10,14,17,STONE_BRICK_STAIRS:5)
B(11,14,17,AIR)
B(12,14,17,AIR)
B(13,14,17,AIR)
B(14,14,17,STONE_BRICK_STAIRS:4)
B(9,1,18,AIR)
B(10,1,18,AIR)
B(11,1,18,AIR)
B(12,1,18,AIR)
B(13,1,18,AIR)
B(14,1,18,AIR)
B(15,1,18,AIR)
B(9,2,18,AIR)
B(10,2,18,AIR)
B(11,2,18,AIR)
B(12,2,18,AIR)
B(13,2,18,AIR)
B(14,2,18,AIR)
B(15,2,18,AIR)
B(9,3,18,AIR)
B(10,3,18,AIR)
B(11,3,18,AIR)
B(12,3,18,AIR)
B(13,3,18,AIR)
B(14,3,18,AIR)
B(15,3,18,AIR)
B(9,4,18,AIR)
B(10,4,18,AIR)
B(11,4,18,AIR)
B(12,4,18,AIR)
B(13,4,18,AIR)
B(14,4,18,AIR)
B(15,4,18,AIR)
B(9,5,18,AIR)
B(10,5,18,AIR)
B(11,5,18,AIR)
B(12,5,18,AIR)
B(13,5,18,AIR)
B(14,5,18,AIR)
B(15,5,18,AIR)
B(9,6,18,STONE_BRICK_STAIRS:7)
B(10,6,18,AIR)
B(11,6,18,AIR)
B(12,6,18,AIR)
B(13,6,18,AIR)
B(14,6,18,AIR)
B(15,6,18,STONE_BRICK_STAIRS:7)
B(10,7,18,AIR)
B(11,7,18,AIR)
B(12,7,18,AIR)
B(13,7,18,AIR)
B(14,7,18,AIR)
B(9,9,18,AIR)
B(10,9,18,AIR)
B(11,9,18,AIR)
B(12,9,18,AIR)
B(13,9,18,AIR)
B(14,9,18,AIR)
B(15,9,18,AIR)
B(9,10,18,AIR)
B(10,10,18,AIR)
B(11,10,18,AIR)
B(12,10,18,AIR)
B(13,10,18,AIR)
B(14,10,18,AIR)
B(15,10,18,AIR)
B(9,11,18,AIR)
B(10,11,18,AIR)
B(11,11,18,AIR)
B(12,11,18,AIR)
B(13,11,18,AIR)
B(14,11,18,AIR)
B(15,11,18,AIR)
B(9,12,18,AIR)
B(10,12,18,AIR)
B(11,12,18,AIR)
B(12,12,18,AIR)
B(13,12,18,AIR)
B(14,12,18,AIR)
B(15,12,18,AIR)
B(9,13,18,AIR)
B(10,13,18,AIR)
B(11,13,18,AIR)
B(12,13,18,AIR)
B(13,13,18,AIR)
B(14,13,18,AIR)
B(15,13,18,AIR)
B(9,14,18,STONE_BRICK_STAIRS:7)
B(10,14,18,AIR)
B(11,14,18,AIR)
B(12,14,18,AIR)
B(13,14,18,AIR)
B(14,14,18,AIR)
B(15,14,18,STONE_BRICK_STAIRS:7)
B(10,15,18,AIR)
B(11,15,18,AIR)
B(12,15,18,AIR)
B(13,15,18,AIR)
B(14,15,18,AIR)
B(9,1,19,AIR)
B(10,1,19,AIR)
B(11,1,19,TALLGRASS:2)
B(12,1,19,TALLGRASS:2)
B(13,1,19,AIR)
B(14,1,19,AIR)
B(15,1,19,AIR)
B(9,2,19,AIR)
B(10,2,19,AIR)
B(11,2,19,AIR)
B(12,2,19,AIR)
B(13,2,19,AIR)
B(14,2,19,AIR)
B(15,2,19,AIR)
B(9,3,19,AIR)
B(10,3,19,AIR)
B(11,3,19,AIR)
B(12,3,19,AIR)
B(13,3,19,AIR)
B(14,3,19,AIR)
B(15,3,19,AIR)
B(9,4,19,AIR)
B(10,4,19,AIR)
B(11,4,19,AIR)
B(12,4,19,AIR)
B(13,4,19,AIR)
B(14,4,19,AIR)
B(15,4,19,AIR)
B(9,5,19,AIR)
B(10,5,19,AIR)
B(11,5,19,AIR)
B(12,5,19,AIR)
B(13,5,19,AIR)
B(14,5,19,AIR)
B(15,5,19,AIR)
B(9,6,19,AIR)
B(10,6,19,AIR)
B(11,6,19,AIR)
B(12,6,19,AIR)
B(13,6,19,AIR)
B(14,6,19,AIR)
B(15,6,19,AIR)
B(10,7,19,AIR)
B(11,7,19,AIR)
B(12,7,19,AIR)
B(13,7,19,AIR)
B(14,7,19,AIR)
B(11,8,19,AIR)
B(12,8,19,AIR)
B(13,8,19,AIR)
B(9,9,19,AIR)
B(10,9,19,AIR)
B(11,9,19,AIR)
B(12,9,19,AIR)
B(13,9,19,AIR)
B(14,9,19,AIR)
B(15,9,19,AIR)
B(9,10,19,AIR)
B(10,10,19,AIR)
B(11,10,19,AIR)
B(12,10,19,AIR)
B(13,10,19,AIR)
B(14,10,19,AIR)
B(15,10,19,AIR)
B(9,11,19,AIR)
B(10,11,19,AIR)
B(11,11,19,AIR)
B(12,11,19,AIR)
B(13,11,19,AIR)
B(14,11,19,AIR)
B(15,11,19,AIR)
B(9,12,19,AIR)
B(10,12,19,AIR)
B(11,12,19,AIR)
B(12,12,19,AIR)
B(13,12,19,AIR)
B(14,12,19,AIR)
B(15,12,19,AIR)
B(9,13,19,AIR)
B(10,13,19,AIR)
B(11,13,19,AIR)
B(12,13,19,AIR)
B(13,13,19,AIR)
B(14,13,19,AIR)
B(15,13,19,AIR)
B(9,14,19,AIR)
B(10,14,19,AIR)
B(11,14,19,AIR)
B(12,14,19,AIR)
B(13,14,19,AIR)
B(14,14,19,AIR)
B(15,14,19,AIR)
B(10,15,19,AIR)
B(11,15,19,AIR)
B(12,15,19,AIR)
B(13,15,19,AIR)
B(14,15,19,AIR)
B(11,16,19,AIR)
B(12,16,19,AIR)
B(13,16,19,AIR)
B(5,1,20,AIR)
B(6,1,20,AIR)
B(7,1,20,AIR)
B(8,1,20,AIR)
B(9,1,20,AIR)
B(10,1,20,AIR)
B(11,1,20,TALLGRASS:1)
B(13,1,20,AIR)
B(14,1,20,AIR)
B(5,2,20,AIR)
B(6,2,20,AIR)
B(7,2,20,AIR)
B(8,2,20,AIR)
B(9,2,20,AIR)
B(10,2,20,AIR)
B(11,2,20,AIR)
B(12,2,20,AIR)
B(13,2,20,AIR)
B(14,2,20,AIR)
B(15,2,20,AIR)
B(5,3,20,AIR)
B(6,3,20,AIR)
B(7,3,20,AIR)
B(8,3,20,AIR)
B(9,3,20,AIR)
B(10,3,20,AIR)
B(11,3,20,AIR)
B(12,3,20,AIR)
B(13,3,20,AIR)
B(14,3,20,AIR)
B(15,3,20,AIR)
B(9,4,20,AIR)
B(10,4,20,AIR)
B(11,4,20,AIR)
B(12,4,20,AIR)
B(13,4,20,AIR)
B(14,4,20,AIR)
B(15,4,20,AIR)
B(9,5,20,AIR)
B(10,5,20,AIR)
B(11,5,20,AIR)
B(12,5,20,AIR)
B(13,5,20,AIR)
B(14,5,20,AIR)
B(15,5,20,AIR)
B(9,6,20,AIR)
B(10,6,20,AIR)
B(11,6,20,AIR)
B(12,6,20,AIR)
B(13,6,20,AIR)
B(14,6,20,AIR)
B(15,6,20,AIR)
B(10,7,20,AIR)
B(11,7,20,AIR)
B(12,7,20,AIR)
B(13,7,20,AIR)
B(14,7,20,AIR)
B(11,8,20,AIR)
B(12,8,20,AIR)
B(13,8,20,AIR)
B(5,9,20,AIR)
B(6,9,20,AIR)
B(7,9,20,AIR)
B(8,9,20,AIR)
B(9,9,20,AIR)
B(10,9,20,AIR)
B(11,9,20,AIR)
B(12,9,20,AIR)
B(13,9,20,AIR)
B(14,9,20,AIR)
B(5,10,20,AIR)
B(6,10,20,AIR)
B(7,10,20,AIR)
B(8,10,20,AIR)
B(9,10,20,AIR)
B(10,10,20,AIR)
B(11,10,20,AIR)
B(12,10,20,AIR)
B(13,10,20,AIR)
B(14,10,20,AIR)
B(15,10,20,AIR)
B(5,11,20,AIR)
B(6,11,20,AIR)
B(7,11,20,AIR)
B(8,11,20,AIR)
B(9,11,20,AIR)
B(10,11,20,AIR)
B(11,11,20,AIR)
B(12,11,20,AIR)
B(13,11,20,AIR)
B(14,11,20,AIR)
B(15,11,20,AIR)
B(9,12,20,AIR)
B(10,12,20,AIR)
B(11,12,20,AIR)
B(12,12,20,AIR)
B(13,12,20,AIR)
B(14,12,20,AIR)
B(15,12,20,AIR)
B(9,13,20,AIR)
B(10,13,20,AIR)
B(11,13,20,AIR)
B(12,13,20,AIR)
B(13,13,20,AIR)
B(14,13,20,AIR)
B(15,13,20,AIR)
B(9,14,20,AIR)
B(10,14,20,AIR)
B(11,14,20,AIR)
B(12,14,20,AIR)
B(13,14,20,AIR)
B(14,14,20,AIR)
B(15,14,20,AIR)
B(10,15,20,AIR)
B(11,15,20,AIR)
B(12,15,20,AIR)
B(13,15,20,AIR)
B(14,15,20,AIR)
B(11,16,20,AIR)
B(12,16,20,AIR)
B(13,16,20,AIR)
B(9,1,21,AIR)
B(10,1,21,AIR)
B(11,1,21,TALLGRASS:2)
B(12,1,21,AIR)
B(13,1,21,AIR)
B(14,1,21,AIR)
B(15,1,21,AIR)
B(9,2,21,AIR)
B(10,2,21,AIR)
B(11,2,21,AIR)
B(12,2,21,AIR)
B(13,2,21,AIR)
B(14,2,21,AIR)
B(15,2,21,AIR)
B(9,3,21,AIR)
B(10,3,21,AIR)
B(11,3,21,AIR)
B(12,3,21,AIR)
B(13,3,21,AIR)
B(14,3,21,AIR)
B(15,3,21,AIR)
B(9,4,21,AIR)
B(10,4,21,AIR)
B(11,4,21,AIR)
B(12,4,21,AIR)
B(13,4,21,AIR)
B(14,4,21,AIR)
B(15,4,21,AIR)
B(9,5,21,AIR)
B(10,5,21,AIR)
B(11,5,21,AIR)
B(12,5,21,AIR)
B(13,5,21,AIR)
B(14,5,21,AIR)
B(15,5,21,AIR)
B(9,6,21,AIR)
B(10,6,21,AIR)
B(11,6,21,AIR)
B(12,6,21,AIR)
B(13,6,21,AIR)
B(14,6,21,AIR)
B(15,6,21,AIR)
B(10,7,21,AIR)
B(11,7,21,AIR)
B(12,7,21,AIR)
B(13,7,21,AIR)
B(14,7,21,AIR)
B(11,8,21,AIR)
B(12,8,21,AIR)
B(13,8,21,AIR)
B(9,9,21,AIR)
B(10,9,21,AIR)
B(11,9,21,AIR)
B(12,9,21,AIR)
B(13,9,21,AIR)
B(14,9,21,AIR)
B(15,9,21,AIR)
B(9,10,21,AIR)
B(10,10,21,AIR)
B(11,10,21,AIR)
B(12,10,21,AIR)
B(13,10,21,AIR)
B(14,10,21,AIR)
B(15,10,21,AIR)
B(9,11,21,AIR)
B(10,11,21,AIR)
B(11,11,21,AIR)
B(12,11,21,AIR)
B(13,11,21,AIR)
B(14,11,21,AIR)
B(15,11,21,AIR)
B(9,12,21,AIR)
B(10,12,21,AIR)
B(11,12,21,AIR)
B(12,12,21,AIR)
B(13,12,21,AIR)
B(14,12,21,AIR)
B(15,12,21,AIR)
B(9,13,21,AIR)
B(10,13,21,AIR)
B(11,13,21,AIR)
B(12,13,21,AIR)
B(13,13,21,AIR)
B(14,13,21,AIR)
B(15,13,21,AIR)
B(9,14,21,AIR)
B(10,14,21,AIR)
B(11,14,21,AIR)
B(12,14,21,AIR)
B(13,14,21,AIR)
B(14,14,21,AIR)
B(15,14,21,AIR)
B(10,15,21,AIR)
B(11,15,21,AIR)
B(12,15,21,AIR)
B(13,15,21,AIR)
B(14,15,21,AIR)
B(11,16,21,AIR)
B(12,16,21,AIR)
B(13,16,21,AIR)
B(9,1,22,AIR)
B(10,1,22,AIR)
B(11,1,22,AIR)
B(12,1,22,AIR)
B(13,1,22,AIR)
B(14,1,22,AIR)
B(15,1,22,AIR)
B(9,2,22,AIR)
B(10,2,22,AIR)
B(11,2,22,AIR)
B(12,2,22,AIR)
B(13,2,22,AIR)
B(14,2,22,AIR)
B(15,2,22,AIR)
B(9,3,22,AIR)
B(10,3,22,AIR)
B(11,3,22,AIR)
B(12,3,22,AIR)
B(13,3,22,AIR)
B(14,3,22,AIR)
B(15,3,22,AIR)
B(9,4,22,AIR)
B(10,4,22,AIR)
B(11,4,22,AIR)
B(12,4,22,AIR)
B(13,4,22,AIR)
B(14,4,22,AIR)
B(15,4,22,AIR)
B(9,5,22,AIR)
B(10,5,22,AIR)
B(11,5,22,AIR)
B(12,5,22,AIR)
B(13,5,22,AIR)
B(14,5,22,AIR)
B(15,5,22,AIR)
B(9,6,22,STONE_BRICK_STAIRS:6)
B(10,6,22,AIR)
B(11,6,22,AIR)
B(12,6,22,AIR)
B(13,6,22,AIR)
B(14,6,22,AIR)
B(15,6,22,STONE_BRICK_STAIRS:6)
B(10,7,22,AIR)
B(11,7,22,AIR)
B(12,7,22,AIR)
B(13,7,22,AIR)
B(14,7,22,AIR)
B(9,9,22,AIR)
B(10,9,22,AIR)
B(11,9,22,AIR)
B(12,9,22,AIR)
B(13,9,22,AIR)
B(14,9,22,AIR)
B(15,9,22,AIR)
B(9,10,22,AIR)
B(10,10,22,AIR)
B(11,10,22,AIR)
B(12,10,22,AIR)
B(13,10,22,AIR)
B(14,10,22,AIR)
B(15,10,22,AIR)
B(9,11,22,AIR)
B(10,11,22,AIR)
B(11,11,22,AIR)
B(12,11,22,AIR)
B(13,11,22,AIR)
B(14,11,22,AIR)
B(15,11,22,AIR)
B(9,12,22,AIR)
B(10,12,22,AIR)
