
#######################################################################
# +-----------------------------------------------------------------+ #
# |                            BO3 object                           | #
# +-----------------------------------------------------------------+ #
#######################################################################

# This is the config file of a custom object.
# If you add this object correctly to your BiomeConfigs, it will spawn in the world.

# This is the creator of this BO3 object
# See: https://imgur.com/a/JanPA
Author: Arcensoth, designed by McNoodlor

# A short description of this BO3 object
Description: No description given

# The BO3 version, don't change this! It can be used by external applications to do a version check.
Version: 3

# The settings mode, WriteAll, WriteWithoutComments or WriteDisable. See WorldConfig.
SettingsMode: WriteDisable


#######################################################################
# +-----------------------------------------------------------------+ #
# |                          Main settings                          | #
# +-----------------------------------------------------------------+ #
#######################################################################

# This needs to be set to true to spawn the object in the Tree and Sapling resources.
Tree: false

# The frequency of the BO3 from 1 to 200. Tries this many times to spawn this BO3 when using the CustomObject(...) resource.
# Ignored by Tree(..), Sapling(..) and CustomStructure(..)
Frequency: 1

# The rarity of the BO3 from 0 to 100. Each spawn attempt has rarity% chance to succeed when using the CustomObject(...) resource.
# Ignored by Tree(..), Sapling(..) and CustomStructure(..)
Rarity: 1.0

# If you set this to true, the BO3 will be placed with a random rotation.
RotateRandomly: false

# The spawn height of the BO3 - randomY, highestBlock or highestSolidBlock.
SpawnHeight: randomY

# The height limits for the BO3.
MinHeight: 0

MaxHeight: 255

# Objects can have other objects attacthed to it: branches. Branches can also
# have branches attached to it, which can also have branches, etc. This is the
# maximum branch depth for this objects.
MaxBranchDepth: 10

# When spawned with the UseWorld keyword, this BO3 should NOT spawn in the following biomes.
# If you writer.write the BO3 name directly in the BiomeConfigs, this will be ignored.
ExcludedBiomes: All


#######################################################################
# +-----------------------------------------------------------------+ #
# |                      Source block settings                      | #
# +-----------------------------------------------------------------+ #
#######################################################################

# The B(s) the BO3 should spawn in.
SourceBlocks: STONE,STONE:1,STONE:3,STONE:5,COBBLESTONE,MOSSY_COBBLESTONE,SANDSTONE,HARD_CLAY,STAINED_CLAY,PRISMARINE,DIRT,DIRT:1,GRASS,SAND,GRAVEL,CLAY,OBSIDIAN,COAL_ORE,IRON_ORE,GOLD_ORE,REDSTONE_ORE,DIAMOND_ORE,LAPIS_ORE,EMERALD_ORE,STATIONARY_WATER,STATIONARY_LAVA

# The maximum percentage of the BO3 that can be outside the SourceBlock.
# The BO3 won't be placed on a location with more blocks outside the SourceBlock than this percentage.
MaxPercentageOutsideSourceBlock: 45

# What to do when a block is about to be placed outside the SourceBlock? (dontPlace, placeAnyway)
OutsideSourceBlock: dontPlace


#######################################################################
# +-----------------------------------------------------------------+ #
# |                              Blocks                             | #
# +-----------------------------------------------------------------+ #
#######################################################################

# All the blocks used in the BO3 are listed here. Possible blocks:
# B(x,y,z,id[.data][,nbtfile.nbt)
# RB(x,y,z,id[:data][,nbtfile.nbt],chance[,id[:data][,nbtfile.nbt],chance[,...]])
# So RB(0,0,0,CHEST,chest.nbt,50,CHEST,anotherchest.nbt,100) will spawn a chest at
# the BO3 origin, and give it a 50% chance to have the contents of chest.nbt, or, if that
# fails, a 100% percent chance to have the contents of anotherchest.nbt.
B(8,0,0,STONEBRICK)
B(9,0,0,STONEBRICK:2)
B(10,0,0,STONEBRICK:1)
B(11,0,0,STONEBRICK)
B(12,0,0,STONEBRICK)
B(13,0,0,STONEBRICK)
B(14,0,0,STONEBRICK)
B(15,0,0,STONEBRICK:1)
B(16,0,0,STONEBRICK)
B(8,1,0,STONEBRICK)
B(9,1,0,MOSSY_COBBLESTONE)
B(10,1,0,MOSSY_COBBLESTONE)
B(11,1,0,EMERALD_ORE)
B(12,1,0,MOSSY_COBBLESTONE)
B(13,1,0,STONE)
B(14,1,0,EMERALD_ORE)
B(15,1,0,STONE)
B(16,1,0,STONEBRICK:2)
B(8,2,0,STONEBRICK:2)
B(9,2,0,MOSSY_COBBLESTONE)
B(10,2,0,EMERALD_ORE)
B(11,2,0,MOSSY_COBBLESTONE)
B(12,2,0,MOSSY_COBBLESTONE)
B(13,2,0,EMERALD_ORE)
B(14,2,0,MOSSY_COBBLESTONE)
B(15,2,0,MOSSY_COBBLESTONE)
B(16,2,0,STONEBRICK:2)
B(8,3,0,STONEBRICK:1)
B(9,3,0,STONE)
B(10,3,0,STONE)
B(11,3,0,STONE)
B(12,3,0,STONE)
B(13,3,0,MOSSY_COBBLESTONE)
B(14,3,0,STONE)
B(15,3,0,STONE)
B(16,3,0,STONEBRICK)
B(8,4,0,STONEBRICK:2)
B(9,4,0,MOSSY_COBBLESTONE)
B(10,4,0,STONE)
B(11,4,0,STONE)
B(12,4,0,STONE)
B(13,4,0,MOSSY_COBBLESTONE)
B(14,4,0,STONE)
B(15,4,0,EMERALD_ORE)
B(16,4,0,STONEBRICK)
B(8,5,0,STONEBRICK)
B(9,5,0,STONE)
B(10,5,0,STONE)
B(11,5,0,EMERALD_ORE)
B(12,5,0,MOSSY_COBBLESTONE)
B(13,5,0,MOSSY_COBBLESTONE)
B(14,5,0,STONE)
B(15,5,0,MOSSY_COBBLESTONE)
B(16,5,0,STONEBRICK:2)
B(8,6,0,STONEBRICK)
B(9,6,0,MOSSY_COBBLESTONE)
B(10,6,0,STONE)
B(11,6,0,MOSSY_COBBLESTONE)
B(12,6,0,MOSSY_COBBLESTONE)
B(13,6,0,EMERALD_ORE)
B(14,6,0,MOSSY_COBBLESTONE)
B(15,6,0,STONE)
B(16,6,0,STONEBRICK)
B(8,7,0,STONEBRICK)
B(9,7,0,STONE)
B(10,7,0,MOSSY_COBBLESTONE)
B(11,7,0,MOSSY_COBBLESTONE)
B(12,7,0,STONE)
B(13,7,0,STONE)
B(14,7,0,MOSSY_COBBLESTONE)
B(15,7,0,STONE)
B(16,7,0,STONEBRICK:2)
B(8,8,0,STONEBRICK:2)
B(9,8,0,STONEBRICK:1)
B(10,8,0,STONEBRICK:2)
B(11,8,0,STONEBRICK:1)
B(12,8,0,STONEBRICK:2)
B(13,8,0,STONEBRICK:1)
B(14,8,0,STONEBRICK)
B(15,8,0,STONEBRICK)
B(16,8,0,STONEBRICK:1)
B(8,0,1,STONEBRICK:2)
B(9,0,1,STONEBRICK:1)
B(10,0,1,STONEBRICK:2)
B(11,0,1,STONEBRICK)
B(12,0,1,STONEBRICK:1)
B(13,0,1,STONEBRICK)
B(14,0,1,STONEBRICK:2)
B(15,0,1,STONEBRICK:2)
B(16,0,1,STONEBRICK:1)
B(8,1,1,MOSSY_COBBLESTONE)
B(9,1,1,EMERALD_ORE)
B(15,1,1,STONE)
B(16,1,1,MOSSY_COBBLESTONE)
B(8,2,1,MOSSY_COBBLESTONE)
B(9,2,1,MOSSY_COBBLESTONE)
B(15,2,1,STONE)
B(16,2,1,STONE)
B(8,3,1,MOSSY_COBBLESTONE)
B(9,3,1,EMERALD_ORE)
B(15,3,1,STONE)
B(16,3,1,MOSSY_COBBLESTONE)
B(8,4,1,MOSSY_COBBLESTONE)
B(9,4,1,STONEBRICK)
B(15,4,1,STONEBRICK:1)
B(16,4,1,STONE)
B(8,5,1,STONE)
B(9,5,1,STONEBRICK:1)
B(15,5,1,STONEBRICK:1)
B(16,5,1,MOSSY_COBBLESTONE)
B(8,6,1,STONE)
B(9,6,1,STONEBRICK)
B(15,6,1,STONEBRICK:2)
B(16,6,1,STONE)
B(8,7,1,MOSSY_COBBLESTONE)
B(9,7,1,STONEBRICK:2)
B(10,7,1,STONEBRICK)
B(11,7,1,STONEBRICK:2)
B(12,7,1,STONEBRICK)
B(13,7,1,STONEBRICK:2)
B(14,7,1,STONEBRICK:2)
B(15,7,1,STONEBRICK:1)
B(16,7,1,STONE)
B(8,8,1,STONEBRICK)
B(9,8,1,MOSSY_COBBLESTONE)
B(10,8,1,MOSSY_COBBLESTONE)
B(11,8,1,STONE)
B(12,8,1,STONE)
B(13,8,1,STONE)
B(14,8,1,STONE)
B(15,8,1,STONE)
B(16,8,1,STONEBRICK)
B(8,0,2,STONEBRICK:2)
B(9,0,2,STONEBRICK:2)
B(10,0,2,STONEBRICK:1)
B(11,0,2,STONEBRICK:2)
B(12,0,2,STONEBRICK)
B(13,0,2,STONEBRICK)
B(14,0,2,STONEBRICK)
B(15,0,2,STONEBRICK:1)
B(16,0,2,STONEBRICK:1)
B(8,1,2,STONE)
B(16,1,2,STONE)
B(8,2,2,MOSSY_COBBLESTONE)
B(16,2,2,MOSSY_COBBLESTONE)
B(8,3,2,MOSSY_COBBLESTONE)
B(16,3,2,EMERALD_ORE)
B(8,4,2,STONE)
B(16,4,2,STONE)
B(8,5,2,STONE)
B(16,5,2,MOSSY_COBBLESTONE)
B(8,6,2,STONE)
B(16,6,2,MOSSY_COBBLESTONE)
B(8,7,2,EMERALD_ORE)
B(9,7,2,STONEBRICK:1)
B(15,7,2,STONEBRICK:2)
B(16,7,2,STONE)
B(8,8,2,STONEBRICK:2)
B(9,8,2,MOSSY_COBBLESTONE)
B(10,8,2,STONEBRICK)
B(11,8,2,STONEBRICK:1)
B(12,8,2,STONEBRICK:2)
B(13,8,2,STONEBRICK:2)
B(14,8,2,STONEBRICK)
B(15,8,2,MOSSY_COBBLESTONE)
B(16,8,2,STONEBRICK:1)
B(5,0,3,STONEBRICK)
B(6,0,3,STONEBRICK:1)
B(7,0,3,STONEBRICK:1)
B(8,0,3,STONEBRICK:2)
B(9,0,3,STONEBRICK:1)
B(10,0,3,STONEBRICK)
B(11,0,3,GRASS)
B(12,0,3,GRASS)
B(13,0,3,DIRT:1)
B(14,0,3,STONEBRICK)
B(15,0,3,STONEBRICK:2)
B(16,0,3,STONEBRICK:2)
B(17,0,3,STONEBRICK:1)
B(18,0,3,STONEBRICK:1)
B(19,0,3,STONEBRICK:1)
B(5,1,3,STONEBRICK:2)
B(6,1,3,STONEBRICK)
B(7,1,3,STONEBRICK:1)
B(8,1,3,STONEBRICK:2)
B(16,1,3,STONEBRICK:1)
B(17,1,3,STONEBRICK)
B(18,1,3,STONEBRICK:2)
B(19,1,3,STONEBRICK)
B(5,2,3,STONEBRICK:2)
B(6,2,3,STONEBRICK)
B(7,2,3,STONEBRICK)
B(8,2,3,STONEBRICK)
B(16,2,3,STONEBRICK)
B(17,2,3,STONEBRICK:2)
B(18,2,3,STONEBRICK:1)
B(19,2,3,STONEBRICK:1)
B(5,3,3,STONEBRICK)
B(6,3,3,STONEBRICK:1)
B(7,3,3,STONEBRICK)
B(8,3,3,STONEBRICK:2)
B(16,3,3,STONEBRICK:2)
B(17,3,3,STONEBRICK)
B(18,3,3,STONEBRICK)
B(19,3,3,STONEBRICK:2)
B(5,4,3,STONEBRICK:1)
B(6,4,3,STONEBRICK)
B(7,4,3,STONEBRICK)
B(8,4,3,STONEBRICK)
B(16,4,3,STONEBRICK:1)
B(17,4,3,STONEBRICK:1)
B(18,4,3,STONEBRICK:1)
B(19,4,3,STONEBRICK:1)
B(8,5,3,STONE)
B(16,5,3,MOSSY_COBBLESTONE)
B(8,6,3,STONE)
B(16,6,3,MOSSY_COBBLESTONE)
B(8,7,3,STONE)
B(9,7,3,STONEBRICK:2)
B(15,7,3,STONEBRICK:2)
B(16,7,3,MOSSY_COBBLESTONE)
B(8,8,3,STONEBRICK:1)
B(9,8,3,EMERALD_ORE)
B(10,8,3,STONEBRICK)
B(14,8,3,STONEBRICK:2)
B(15,8,3,STONE)
B(16,8,3,STONEBRICK)
B(5,0,4,STONEBRICK:1)
B(6,0,4,STONEBRICK:2)
B(7,0,4,STONEBRICK)
B(8,0,4,STONEBRICK:2)
B(9,0,4,STONEBRICK:1)
B(10,0,4,STONEBRICK:2)
B(11,0,4,GRASS)
B(12,0,4,GRASS)
B(13,0,4,DIRT:1)
B(14,0,4,STONEBRICK:2)
B(15,0,4,STONEBRICK:2)
B(16,0,4,STONEBRICK:2)
B(17,0,4,STONEBRICK:1)
B(18,0,4,STONEBRICK:2)
B(19,0,4,STONEBRICK)
B(5,4,4,STONEBRICK:1)
B(6,4,4,STONEBRICK)
B(7,4,4,STONEBRICK:1)
B(8,4,4,STONEBRICK:2)
B(16,4,4,STONEBRICK:2)
B(17,4,4,STONEBRICK:2)
B(18,4,4,STONEBRICK:2)
B(19,4,4,STONEBRICK)
B(8,5,4,STONE)
B(16,5,4,STONE)
B(8,6,4,MOSSY_COBBLESTONE)
B(16,6,4,STONE)
B(8,7,4,STONE)
B(9,7,4,STONEBRICK:1)
B(15,7,4,STONEBRICK:1)
B(16,7,4,MOSSY_COBBLESTONE)
B(8,8,4,STONEBRICK)
B(9,8,4,MOSSY_COBBLESTONE)
B(10,8,4,STONEBRICK:1)
B(14,8,4,STONEBRICK)
B(15,8,4,MOSSY_COBBLESTONE)
B(16,8,4,STONEBRICK:2)
B(5,0,5,STONEBRICK:1)
B(6,0,5,STONEBRICK)
B(7,0,5,STONEBRICK:2)
B(8,0,5,STONEBRICK:1)
B(9,0,5,STONEBRICK:2)
B(10,0,5,STONEBRICK)
B(11,0,5,DIRT:1)
B(12,0,5,DIRT:1)
B(13,0,5,GRASS)
B(14,0,5,STONEBRICK)
B(15,0,5,STONEBRICK)
B(16,0,5,STONEBRICK:2)
B(17,0,5,STONEBRICK:2)
B(18,0,5,STONEBRICK)
B(19,0,5,STONEBRICK:1)
B(5,1,5,STONEBRICK)
B(6,1,5,STONEBRICK)
B(7,1,5,STONEBRICK:1)
B(8,1,5,STONEBRICK)
B(16,1,5,STONEBRICK)
B(17,1,5,STONEBRICK:1)
B(18,1,5,STONEBRICK:1)
B(19,1,5,STONEBRICK:2)
B(5,2,5,STONEBRICK)
B(6,2,5,STONEBRICK:1)
B(7,2,5,STONEBRICK:2)
B(8,2,5,STONEBRICK)
B(16,2,5,STONEBRICK:2)
B(17,2,5,STONEBRICK:1)
B(18,2,5,STONEBRICK:2)
B(19,2,5,STONEBRICK:1)
B(5,3,5,STONEBRICK:2)
B(6,3,5,STONEBRICK)
B(7,3,5,STONEBRICK:1)
B(8,3,5,STONEBRICK)
B(16,3,5,STONEBRICK:1)
B(17,3,5,STONEBRICK:2)
B(18,3,5,STONEBRICK:2)
B(19,3,5,STONEBRICK)
B(5,4,5,STONEBRICK:1)
B(6,4,5,STONEBRICK:2)
B(7,4,5,STONEBRICK)
B(8,4,5,STONEBRICK)
B(16,4,5,STONEBRICK:1)
B(17,4,5,STONEBRICK:2)
B(18,4,5,STONEBRICK)
B(19,4,5,STONEBRICK:1)
B(8,5,5,STONE)
B(16,5,5,STONE)
B(8,6,5,MOSSY_COBBLESTONE)
B(16,6,5,STONE)
B(8,7,5,STONE)
B(9,7,5,STONEBRICK:1)
B(15,7,5,STONEBRICK)
B(16,7,5,EMERALD_ORE)
B(8,8,5,STONEBRICK:1)
B(9,8,5,MOSSY_COBBLESTONE)
B(10,8,5,STONEBRICK:2)
B(14,8,5,STONEBRICK:2)
B(15,8,5,STONE)
B(16,8,5,STONEBRICK)
B(8,0,6,STONEBRICK:1)
B(9,0,6,STONEBRICK:1)
B(10,0,6,STONEBRICK)
B(11,0,6,STONEBRICK)
B(12,0,6,STONEBRICK)
B(13,0,6,STONEBRICK:2)
B(14,0,6,STONEBRICK:2)
B(15,0,6,STONEBRICK)
B(16,0,6,STONEBRICK:1)
B(8,1,6,STONE)
B(16,1,6,MOSSY_COBBLESTONE)
B(8,2,6,STONE)
B(16,2,6,STONE)
B(8,3,6,MOSSY_COBBLESTONE)
B(16,3,6,STONE)
B(8,4,6,MOSSY_COBBLESTONE)
B(16,4,6,STONE)
B(8,5,6,MOSSY_COBBLESTONE)
B(16,5,6,STONE)
B(8,6,6,MOSSY_COBBLESTONE)
B(16,6,6,MOSSY_COBBLESTONE)
B(8,7,6,STONE)
B(9,7,6,STONEBRICK)
B(15,7,6,STONEBRICK)
B(16,7,6,MOSSY_COBBLESTONE)
B(8,8,6,STONEBRICK)
B(9,8,6,MOSSY_COBBLESTONE)
B(10,8,6,STONEBRICK:1)
B(11,8,6,STONEBRICK)
B(12,8,6,STONEBRICK:2)
B(13,8,6,STONEBRICK:1)
B(14,8,6,STONEBRICK)
B(15,8,6,STONE)
B(16,8,6,STONEBRICK)
B(8,0,7,STONEBRICK:2)
B(9,0,7,STONEBRICK:2)
B(10,0,7,STONEBRICK:1)
B(11,0,7,STONEBRICK:2)
B(12,0,7,STONEBRICK:1)
B(13,0,7,STONEBRICK:1)
B(14,0,7,STONEBRICK)
B(15,0,7,STONEBRICK)
B(16,0,7,STONEBRICK:2)
B(8,1,7,STONE)
B(9,1,7,MOSSY_COBBLESTONE)
B(15,1,7,MOSSY_COBBLESTONE)
B(16,1,7,STONE)
B(8,2,7,STONE)
B(9,2,7,MOSSY_COBBLESTONE)
B(15,2,7,MOSSY_COBBLESTONE)
B(16,2,7,STONE)
B(8,3,7,MOSSY_COBBLESTONE)
B(9,3,7,MOSSY_COBBLESTONE)
B(15,3,7,STONE)
B(16,3,7,STONE)
B(8,4,7,STONE)
B(9,4,7,STONEBRICK:1)
B(15,4,7,STONEBRICK)
B(16,4,7,MOSSY_COBBLESTONE)
B(8,5,7,STONE)
B(9,5,7,STONEBRICK)
B(15,5,7,STONEBRICK:1)
B(16,5,7,STONE)
B(8,6,7,MOSSY_COBBLESTONE)
B(9,6,7,STONEBRICK:1)
B(15,6,7,STONEBRICK:2)
B(16,6,7,STONE)
B(8,7,7,MOSSY_COBBLESTONE)
B(9,7,7,STONEBRICK:2)
B(10,7,7,STONEBRICK:1)
B(11,7,7,STONEBRICK)
B(12,7,7,STONEBRICK:2)
B(13,7,7,STONEBRICK:1)
B(14,7,7,STONEBRICK:2)
B(15,7,7,STONEBRICK:2)
B(16,7,7,MOSSY_COBBLESTONE)
B(8,8,7,STONEBRICK:1)
B(9,8,7,MOSSY_COBBLESTONE)
B(10,8,7,STONE)
B(11,8,7,STONE)
B(12,8,7,STONE)
B(13,8,7,MOSSY_COBBLESTONE)
B(14,8,7,MOSSY_COBBLESTONE)
B(15,8,7,MOSSY_COBBLESTONE)
B(16,8,7,STONEBRICK)
B(0,0,8,STONEBRICK)
B(1,0,8,STONEBRICK)
B(2,0,8,STONEBRICK)
B(3,0,8,STONEBRICK:1)
B(4,0,8,STONEBRICK:1)
B(5,0,8,STONEBRICK:1)
B(6,0,8,STONEBRICK:2)
B(7,0,8,STONEBRICK)
B(8,0,8,STONEBRICK:1)
B(9,0,8,STONEBRICK)
B(10,0,8,STONEBRICK:1)
B(11,0,8,STONEBRICK)
B(12,0,8,STONEBRICK)
B(13,0,8,STONEBRICK:2)
B(14,0,8,STONEBRICK:2)
B(15,0,8,STONEBRICK:2)
B(16,0,8,STONEBRICK:2)
B(17,0,8,STONEBRICK)
B(18,0,8,STONEBRICK:1)
B(19,0,8,STONEBRICK)
B(20,0,8,STONEBRICK:2)
B(21,0,8,STONEBRICK:1)
B(22,0,8,STONEBRICK)
B(23,0,8,STONEBRICK:2)
B(24,0,8,STONEBRICK)
B(0,1,8,STONEBRICK:2)
B(1,1,8,STONE)
B(2,1,8,STONE)
B(3,1,8,STONE)
B(4,1,8,STONE)
B(5,1,8,STONE)
B(6,1,8,STONE)
B(7,1,8,MOSSY_COBBLESTONE)
B(8,1,8,STONEBRICK:1)
B(9,1,8,STONE)
B(10,1,8,STONE)
B(11,1,8,STONEBRICK)
B(13,1,8,STONEBRICK:1)
B(14,1,8,MOSSY_COBBLESTONE)
B(15,1,8,MOSSY_COBBLESTONE)
B(16,1,8,STONEBRICK:1)
B(17,1,8,EMERALD_ORE)
B(18,1,8,MOSSY_COBBLESTONE)
B(19,1,8,STONE)
B(20,1,8,MOSSY_COBBLESTONE)
B(21,1,8,MOSSY_COBBLESTONE)
B(22,1,8,STONE)
B(23,1,8,STONE)
B(24,1,8,STONEBRICK)
B(0,2,8,STONEBRICK:1)
B(1,2,8,MOSSY_COBBLESTONE)
B(2,2,8,MOSSY_COBBLESTONE)
B(3,2,8,EMERALD_ORE)
B(4,2,8,STONE)
B(5,2,8,STONE)
B(6,2,8,EMERALD_ORE)
B(7,2,8,MOSSY_COBBLESTONE)
B(8,2,8,STONEBRICK)
B(9,2,8,EMERALD_ORE)
B(10,2,8,STONE)
B(11,2,8,STONEBRICK:2)
B(13,2,8,STONEBRICK:2)
B(14,2,8,STONE)
B(15,2,8,STONE)
B(16,2,8,STONEBRICK:1)
B(17,2,8,STONE)
B(18,2,8,MOSSY_COBBLESTONE)
B(19,2,8,STONE)
B(20,2,8,STONE)
B(21,2,8,MOSSY_COBBLESTONE)
B(22,2,8,EMERALD_ORE)
B(23,2,8,STONE)
B(24,2,8,STONEBRICK:1)
B(0,3,8,STONEBRICK)
B(1,3,8,STONE)
B(2,3,8,MOSSY_COBBLESTONE)
B(3,3,8,MOSSY_COBBLESTONE)
B(4,3,8,MOSSY_COBBLESTONE)
B(5,3,8,MOSSY_COBBLESTONE)
B(6,3,8,MOSSY_COBBLESTONE)
B(7,3,8,MOSSY_COBBLESTONE)
B(8,3,8,STONEBRICK)
B(9,3,8,MOSSY_COBBLESTONE)
B(10,3,8,MOSSY_COBBLESTONE)
B(11,3,8,STONEBRICK:1)
B(13,3,8,STONEBRICK)
B(14,3,8,STONE)
B(15,3,8,MOSSY_COBBLESTONE)
B(16,3,8,STONEBRICK:1)
B(17,3,8,EMERALD_ORE)
B(18,3,8,MOSSY_COBBLESTONE)
B(19,3,8,STONE)
B(20,3,8,STONE)
B(21,3,8,EMERALD_ORE)
B(22,3,8,MOSSY_COBBLESTONE)
B(23,3,8,MOSSY_COBBLESTONE)
B(24,3,8,STONEBRICK)
B(0,4,8,STONEBRICK:2)
B(1,4,8,EMERALD_ORE)
B(2,4,8,STONE)
B(3,4,8,MOSSY_COBBLESTONE)
B(4,4,8,MOSSY_COBBLESTONE)
B(5,4,8,MOSSY_COBBLESTONE)
B(6,4,8,STONE)
B(7,4,8,EMERALD_ORE)
B(8,4,8,STONEBRICK:2)
B(9,4,8,EMERALD_ORE)
B(10,4,8,STONE)
B(11,4,8,STONEBRICK:2)
B(12,4,8,STONEBRICK)
B(13,4,8,STONEBRICK)
B(14,4,8,EMERALD_ORE)
B(15,4,8,EMERALD_ORE)
B(16,4,8,STONEBRICK:1)
B(17,4,8,MOSSY_COBBLESTONE)
B(18,4,8,STONE)
B(19,4,8,EMERALD_ORE)
B(20,4,8,EMERALD_ORE)
B(21,4,8,MOSSY_COBBLESTONE)
B(22,4,8,MOSSY_COBBLESTONE)
B(23,4,8,STONE)
B(24,4,8,STONEBRICK:1)
B(0,5,8,STONEBRICK:1)
B(1,5,8,MOSSY_COBBLESTONE)
B(2,5,8,MOSSY_COBBLESTONE)
B(3,5,8,MOSSY_COBBLESTONE)
B(4,5,8,MOSSY_COBBLESTONE)
B(5,5,8,MOSSY_COBBLESTONE)
B(6,5,8,STONE)
B(7,5,8,STONE)
B(8,5,8,STONEBRICK:2)
B(9,5,8,MOSSY_COBBLESTONE)
B(10,5,8,MOSSY_COBBLESTONE)
B(11,5,8,STONE)
B(12,5,8,MOSSY_COBBLESTONE)
B(13,5,8,STONE)
B(14,5,8,MOSSY_COBBLESTONE)
B(15,5,8,MOSSY_COBBLESTONE)
B(16,5,8,STONEBRICK:1)
B(17,5,8,MOSSY_COBBLESTONE)
B(18,5,8,MOSSY_COBBLESTONE)
B(19,5,8,EMERALD_ORE)
B(20,5,8,MOSSY_COBBLESTONE)
B(21,5,8,STONE)
B(22,5,8,MOSSY_COBBLESTONE)
B(23,5,8,EMERALD_ORE)
B(24,5,8,STONEBRICK)
B(0,6,8,STONEBRICK:1)
B(1,6,8,MOSSY_COBBLESTONE)
B(2,6,8,MOSSY_COBBLESTONE)
B(3,6,8,MOSSY_COBBLESTONE)
B(4,6,8,STONE)
B(5,6,8,MOSSY_COBBLESTONE)
B(6,6,8,STONE)
B(7,6,8,MOSSY_COBBLESTONE)
B(8,6,8,STONEBRICK:1)
B(9,6,8,MOSSY_COBBLESTONE)
B(10,6,8,STONE)
B(11,6,8,STONE)
B(12,6,8,EMERALD_ORE)
B(13,6,8,MOSSY_COBBLESTONE)
B(14,6,8,STONE)
B(15,6,8,MOSSY_COBBLESTONE)
B(16,6,8,STONEBRICK)
B(17,6,8,EMERALD_ORE)
B(18,6,8,MOSSY_COBBLESTONE)
B(19,6,8,MOSSY_COBBLESTONE)
B(20,6,8,STONE)
B(21,6,8,MOSSY_COBBLESTONE)
B(22,6,8,STONE)
B(23,6,8,STONE)
B(24,6,8,STONEBRICK:2)
B(0,7,8,STONEBRICK:1)
B(1,7,8,STONE)
B(2,7,8,MOSSY_COBBLESTONE)
B(3,7,8,MOSSY_COBBLESTONE)
B(4,7,8,EMERALD_ORE)
B(5,7,8,MOSSY_COBBLESTONE)
B(6,7,8,MOSSY_COBBLESTONE)
B(7,7,8,MOSSY_COBBLESTONE)
B(8,7,8,STONEBRICK)
B(9,7,8,STONE)
B(10,7,8,STONE)
B(11,7,8,STONE)
B(12,7,8,STONE)
B(13,7,8,MOSSY_COBBLESTONE)
B(14,7,8,STONE)
B(15,7,8,MOSSY_COBBLESTONE)
B(16,7,8,STONEBRICK:2)
B(17,7,8,MOSSY_COBBLESTONE)
B(18,7,8,MOSSY_COBBLESTONE)
B(19,7,8,MOSSY_COBBLESTONE)
B(20,7,8,STONE)
B(21,7,8,STONE)
B(22,7,8,STONE)
B(23,7,8,MOSSY_COBBLESTONE)
B(24,7,8,STONEBRICK)
B(0,8,8,STONEBRICK:2)
B(1,8,8,STONEBRICK)
B(2,8,8,STONEBRICK:2)
B(3,8,8,STONEBRICK:1)
B(4,8,8,STONEBRICK:2)
B(5,8,8,STONEBRICK:1)
B(6,8,8,STONEBRICK:1)
B(7,8,8,STONEBRICK:2)
B(8,8,8,STONEBRICK:2)
B(9,8,8,STONEBRICK)
B(10,8,8,STONEBRICK)
B(11,8,8,STONEBRICK)
B(12,8,8,STONEBRICK:2)
B(13,8,8,STONEBRICK:2)
B(14,8,8,STONEBRICK:1)
B(15,8,8,STONEBRICK:1)
B(16,8,8,STONEBRICK)
B(17,8,8,STONEBRICK:2)
B(18,8,8,STONEBRICK:1)
B(19,8,8,STONEBRICK:2)
B(20,8,8,STONEBRICK)
B(21,8,8,STONEBRICK:1)
B(22,8,8,STONEBRICK:2)
B(23,8,8,STONEBRICK)
B(24,8,8,STONEBRICK:2)
B(0,0,9,STONEBRICK:1)
B(1,0,9,STONEBRICK:2)
B(2,0,9,STONEBRICK)
B(3,0,9,STONEBRICK:1)
B(4,0,9,STONEBRICK:1)
B(5,0,9,STONEBRICK)
B(6,0,9,STONEBRICK:1)
B(7,0,9,STONEBRICK:1)
B(8,0,9,STONEBRICK:2)
B(9,0,9,STONEBRICK:2)
B(10,0,9,STONEBRICK)
B(11,0,9,STONEBRICK)
B(12,0,9,STONEBRICK:1)
B(13,0,9,STONEBRICK)
B(14,0,9,STONEBRICK)
B(15,0,9,STONEBRICK:1)
B(16,0,9,STONEBRICK:2)
B(17,0,9,STONEBRICK:2)
B(18,0,9,STONEBRICK)
B(19,0,9,STONEBRICK)
B(20,0,9,STONEBRICK:1)
B(21,0,9,STONEBRICK:2)
B(22,0,9,STONEBRICK)
B(23,0,9,STONEBRICK:1)
B(24,0,9,STONEBRICK:2)
B(0,1,9,MOSSY_COBBLESTONE)
B(1,1,9,STONE)
B(4,1,9,STONEBRICK:3)
B(7,1,9,MOSSY_COBBLESTONE)
B(8,1,9,STONE)
B(9,1,9,EMERALD_ORE)
B(15,1,9,MOSSY_COBBLESTONE)
B(16,1,9,MOSSY_COBBLESTONE)
B(17,1,9,STONE)
B(20,1,9,STONEBRICK:3)
B(23,1,9,MOSSY_COBBLESTONE)
B(24,1,9,STONE)
B(0,2,9,STONE)
B(1,2,9,MOSSY_COBBLESTONE)
B(7,2,9,STONE)
B(8,2,9,STONE)
B(9,2,9,MOSSY_COBBLESTONE)
B(15,2,9,EMERALD_ORE)
B(16,2,9,MOSSY_COBBLESTONE)
B(17,2,9,MOSSY_COBBLESTONE)
B(23,2,9,MOSSY_COBBLESTONE)
B(24,2,9,STONE)
B(0,3,9,MOSSY_COBBLESTONE)
B(1,3,9,MOSSY_COBBLESTONE)
B(7,3,9,EMERALD_ORE)
B(8,3,9,MOSSY_COBBLESTONE)
B(9,3,9,MOSSY_COBBLESTONE)
B(15,3,9,MOSSY_COBBLESTONE)
B(16,3,9,STONE)
B(17,3,9,STONE)
B(23,3,9,MOSSY_COBBLESTONE)
B(24,3,9,STONE)
B(0,4,9,MOSSY_COBBLESTONE)
B(1,4,9,STONEBRICK)
B(7,4,9,STONEBRICK:2)
B(8,4,9,STONEBRICK:2)
B(9,4,9,STONEBRICK:2)
B(15,4,9,STONEBRICK:2)
B(16,4,9,STONEBRICK:2)
B(17,4,9,STONEBRICK:1)
B(23,4,9,STONEBRICK:2)
B(24,4,9,MOSSY_COBBLESTONE)
B(0,5,9,MOSSY_COBBLESTONE)
B(1,5,9,STONEBRICK)
B(7,5,9,STONEBRICK:1)
B(8,5,9,STONEBRICK:1)
B(9,5,9,STONEBRICK)
B(15,5,9,STONEBRICK)
B(16,5,9,STONEBRICK)
B(17,5,9,STONEBRICK:1)
B(23,5,9,STONEBRICK:2)
B(24,5,9,MOSSY_COBBLESTONE)
B(0,6,9,MOSSY_COBBLESTONE)
B(1,6,9,STONEBRICK)
B(7,6,9,STONEBRICK:2)
B(8,6,9,STONEBRICK:1)
B(9,6,9,STONEBRICK)
B(15,6,9,STONEBRICK:2)
B(16,6,9,STONEBRICK:2)
B(17,6,9,STONEBRICK:2)
B(23,6,9,STONEBRICK:2)
B(24,6,9,STONE)
B(0,7,9,STONE)
B(1,7,9,STONEBRICK)
B(2,7,9,STONEBRICK)
B(3,7,9,STONEBRICK)
B(4,7,9,STONEBRICK)
B(5,7,9,STONEBRICK:1)
B(6,7,9,STONEBRICK:2)
B(7,7,9,STONEBRICK:2)
B(8,7,9,STONEBRICK:2)
B(9,7,9,STONEBRICK:2)
B(10,7,9,STONEBRICK:2)
B(11,7,9,STONEBRICK)
B(12,7,9,STONEBRICK)
B(13,7,9,STONEBRICK:1)
B(14,7,9,STONEBRICK)
B(15,7,9,STONEBRICK:1)
B(16,7,9,STONEBRICK:1)
B(17,7,9,STONEBRICK)
B(18,7,9,STONEBRICK:1)
B(19,7,9,STONEBRICK:2)
B(20,7,9,STONEBRICK)
B(21,7,9,STONEBRICK:2)
B(22,7,9,STONEBRICK:2)
B(23,7,9,STONEBRICK)
B(24,7,9,MOSSY_COBBLESTONE)
B(0,8,9,STONEBRICK:1)
B(1,8,9,EMERALD_ORE)
B(2,8,9,MOSSY_COBBLESTONE)
B(3,8,9,STONE)
B(4,8,9,STONE)
B(5,8,9,MOSSY_COBBLESTONE)
B(6,8,9,MOSSY_COBBLESTONE)
B(7,8,9,MOSSY_COBBLESTONE)
B(8,8,9,STONEBRICK:2)
B(9,8,9,MOSSY_COBBLESTONE)
B(10,8,9,MOSSY_COBBLESTONE)
B(11,8,9,MOSSY_COBBLESTONE)
B(12,8,9,STONE)
B(13,8,9,STONE)
B(14,8,9,EMERALD_ORE)
B(15,8,9,STONE)
B(16,8,9,STONEBRICK:2)
B(17,8,9,MOSSY_COBBLESTONE)
B(18,8,9,MOSSY_COBBLESTONE)
B(19,8,9,STONE)
B(20,8,9,STONE)
B(21,8,9,STONE)
B(22,8,9,MOSSY_COBBLESTONE)
B(23,8,9,MOSSY_COBBLESTONE)
B(24,8,9,STONEBRICK:1)
B(0,0,10,STONEBRICK:1)
B(1,0,10,STONEBRICK)
B(2,0,10,STONEBRICK)
B(3,0,10,STONEBRICK:2)
B(4,0,10,STONEBRICK:1)
B(5,0,10,STONEBRICK:2)
B(6,0,10,STONEBRICK:1)
B(7,0,10,STONEBRICK)
B(8,0,10,STONEBRICK:1)
B(9,0,10,STONEBRICK:1)
B(10,0,10,STONEBRICK)
B(11,0,10,STONEBRICK:1)
B(12,0,10,STONEBRICK:1)
B(13,0,10,STONEBRICK)
B(14,0,10,STONEBRICK:2)
B(15,0,10,STONEBRICK)
B(16,0,10,STONEBRICK:2)
B(17,0,10,STONEBRICK:2)
B(18,0,10,STONEBRICK:2)
B(19,0,10,STONEBRICK:1)
B(20,0,10,STONEBRICK)
B(21,0,10,STONEBRICK)
B(22,0,10,STONEBRICK:2)
B(23,0,10,STONEBRICK)
B(24,0,10,STONEBRICK:1)
B(0,1,10,STONE)
B(24,1,10,MOSSY_COBBLESTONE)
B(0,2,10,MOSSY_COBBLESTONE)
B(24,2,10,STONE)
B(0,3,10,STONE)
B(24,3,10,STONE)
B(0,4,10,MOSSY_COBBLESTONE)
B(24,4,10,MOSSY_COBBLESTONE)
B(0,5,10,STONE)
B(24,5,10,MOSSY_COBBLESTONE)
B(0,6,10,MOSSY_COBBLESTONE)
B(24,6,10,STONE)
B(0,7,10,MOSSY_COBBLESTONE)
B(1,7,10,STONEBRICK)
B(7,7,10,STONEBRICK:2)
B(8,7,10,STONEBRICK:2)
B(9,7,10,STONEBRICK:1)
B(15,7,10,STONEBRICK:1)
B(16,7,10,STONEBRICK:2)
B(17,7,10,STONEBRICK)
B(23,7,10,STONEBRICK:2)
B(24,7,10,STONE)
B(0,8,10,STONEBRICK:1)
B(1,8,10,STONE)
B(2,8,10,STONEBRICK:1)
B(3,8,10,STONEBRICK)
B(4,8,10,STONEBRICK)
B(5,8,10,STONEBRICK:1)
B(6,8,10,STONEBRICK)
B(7,8,10,STONE)
B(8,8,10,STONEBRICK)
B(9,8,10,STONE)
B(10,8,10,STONEBRICK:1)
B(11,8,10,STONEBRICK)
B(12,8,10,STONEBRICK:1)
B(13,8,10,STONEBRICK:2)
B(14,8,10,STONEBRICK:2)
B(15,8,10,STONE)
B(16,8,10,STONEBRICK)
B(17,8,10,STONE)
B(18,8,10,STONEBRICK:1)
B(19,8,10,STONEBRICK:1)
B(20,8,10,STONEBRICK:1)
B(21,8,10,STONEBRICK:2)
B(22,8,10,STONEBRICK:1)
B(23,8,10,STONE)
B(24,8,10,STONEBRICK:1)
B(0,0,11,STONEBRICK)
B(1,0,11,STONEBRICK:1)
B(2,0,11,STONEBRICK:2)
B(3,0,11,GRASS)
B(4,0,11,GRASS)
B(5,0,11,GRASS)
B(6,0,11,DIRT:1)
B(7,0,11,GRASS)
B(8,0,11,GRASS)
B(9,0,11,GRASS)
B(10,0,11,GRASS)
B(11,0,11,GRASS)
B(12,0,11,GRASS)
B(13,0,11,GRASS)
B(14,0,11,DIRT:1)
B(15,0,11,GRASS)
B(16,0,11,GRASS)
B(17,0,11,DIRT:1)
B(18,0,11,DIRT:1)
B(19,0,11,GRASS)
B(20,0,11,DIRT:1)
B(21,0,11,GRASS)
B(22,0,11,STONEBRICK)
B(23,0,11,STONEBRICK)
B(24,0,11,STONEBRICK:2)
B(0,1,11,STONEBRICK:2)
B(24,1,11,STONEBRICK:2)
B(0,2,11,STONEBRICK:1)
B(24,2,11,STONEBRICK)
B(0,3,11,STONEBRICK)
B(24,3,11,STONEBRICK:2)
B(0,4,11,STONEBRICK)
B(24,4,11,STONEBRICK)
B(0,5,11,MOSSY_COBBLESTONE)
B(24,5,11,MOSSY_COBBLESTONE)
B(0,6,11,STONE)
B(24,6,11,EMERALD_ORE)
B(0,7,11,STONE)
B(1,7,11,STONEBRICK:1)
B(7,7,11,STONEBRICK:1)
B(8,7,11,STONEBRICK:1)
B(9,7,11,STONEBRICK)
B(15,7,11,STONEBRICK)
B(16,7,11,STONEBRICK:2)
B(17,7,11,STONEBRICK:2)
B(23,7,11,STONEBRICK:2)
B(24,7,11,MOSSY_COBBLESTONE)
B(0,8,11,STONEBRICK)
B(1,8,11,STONE)
B(2,8,11,STONEBRICK:1)
B(6,8,11,STONEBRICK:1)
B(7,8,11,STONE)
B(8,8,11,STONEBRICK:2)
B(9,8,11,STONE)
B(10,8,11,STONEBRICK:2)
B(14,8,11,STONEBRICK:1)
B(15,8,11,MOSSY_COBBLESTONE)
B(16,8,11,STONEBRICK:2)
B(17,8,11,MOSSY_COBBLESTONE)
B(18,8,11,STONEBRICK)
B(22,8,11,STONEBRICK:2)
B(23,8,11,MOSSY_COBBLESTONE)
B(24,8,11,STONEBRICK:2)
B(0,0,12,STONEBRICK:1)
B(1,0,12,STONEBRICK:1)
B(2,0,12,STONEBRICK:2)
B(3,0,12,DIRT:1)
B(4,0,12,GRASS)
B(5,0,12,GRASS)
B(6,0,12,GRASS)
B(7,0,12,GRASS)
B(8,0,12,DIRT:1)
B(9,0,12,GRASS)
B(10,0,12,GRASS)
B(11,0,12,DIRT:1)
B(12,0,12,DIRT:1)
B(13,0,12,DIRT:1)
B(14,0,12,GRASS)
B(15,0,12,GRASS)
B(16,0,12,GRASS)
B(17,0,12,DIRT:1)
B(18,0,12,GRASS)
B(19,0,12,GRASS)
B(20,0,12,GRASS)
B(21,0,12,GRASS)
B(22,0,12,STONEBRICK)
B(23,0,12,STONEBRICK:2)
B(24,0,12,STONEBRICK:2)
B(0,4,12,STONEBRICK)
B(24,4,12,STONEBRICK:1)
B(0,5,12,MOSSY_COBBLESTONE)
B(24,5,12,STONE)
B(0,6,12,MOSSY_COBBLESTONE)
B(24,6,12,STONE)
B(0,7,12,MOSSY_COBBLESTONE)
B(1,7,12,STONEBRICK:1)
B(7,7,12,STONEBRICK)
B(8,7,12,STONEBRICK)
B(9,7,12,STONEBRICK:1)
B(15,7,12,STONEBRICK:2)
B(16,7,12,STONEBRICK:2)
B(17,7,12,STONEBRICK:1)
B(23,7,12,STONEBRICK)
B(24,7,12,STONE)
B(0,8,12,STONEBRICK)
B(1,8,12,MOSSY_COBBLESTONE)
B(2,8,12,STONEBRICK)
B(6,8,12,STONEBRICK)
B(7,8,12,MOSSY_COBBLESTONE)
B(8,8,12,STONEBRICK:1)
B(9,8,12,STONE)
B(10,8,12,STONEBRICK:2)
B(14,8,12,STONEBRICK:1)
B(15,8,12,MOSSY_COBBLESTONE)
B(16,8,12,STONEBRICK:2)
B(17,8,12,MOSSY_COBBLESTONE)
B(18,8,12,STONEBRICK)
B(22,8,12,STONEBRICK:1)
B(23,8,12,MOSSY_COBBLESTONE)
B(24,8,12,STONEBRICK)
B(0,0,13,STONEBRICK:2)
B(1,0,13,STONEBRICK:1)
B(2,0,13,STONEBRICK:2)
B(3,0,13,GRASS)
B(4,0,13,DIRT:1)
B(5,0,13,GRASS)
B(6,0,13,DIRT:1)
B(7,0,13,GRASS)
B(8,0,13,GRASS)
B(9,0,13,DIRT:1)
B(10,0,13,DIRT:1)
B(11,0,13,DIRT:1)
B(12,0,13,DIRT:1)
B(13,0,13,GRASS)
B(14,0,13,GRASS)
B(15,0,13,DIRT:1)
B(16,0,13,GRASS)
B(17,0,13,GRASS)
B(18,0,13,DIRT:1)
B(19,0,13,DIRT:1)
B(20,0,13,DIRT:1)
B(21,0,13,GRASS)
B(22,0,13,STONEBRICK)
B(23,0,13,STONEBRICK:2)
B(24,0,13,STONEBRICK)
B(0,1,13,STONEBRICK:1)
B(24,1,13,STONEBRICK:2)
B(0,2,13,STONEBRICK:2)
B(24,2,13,STONEBRICK:2)
B(0,3,13,STONEBRICK:2)
B(24,3,13,STONEBRICK:1)
B(0,4,13,STONEBRICK)
B(24,4,13,STONEBRICK)
B(0,5,13,STONE)
B(24,5,13,STONE)
B(0,6,13,STONE)
B(24,6,13,STONE)
B(0,7,13,MOSSY_COBBLESTONE)
B(1,7,13,STONEBRICK)
B(7,7,13,STONEBRICK)
B(8,7,13,STONEBRICK:1)
B(9,7,13,STONEBRICK:1)
B(15,7,13,STONEBRICK:2)
B(16,7,13,STONEBRICK:2)
B(17,7,13,STONEBRICK:1)
B(23,7,13,STONEBRICK:2)
B(24,7,13,MOSSY_COBBLESTONE)
B(0,8,13,STONEBRICK:1)
B(1,8,13,EMERALD_ORE)
B(2,8,13,STONEBRICK:2)
B(6,8,13,STONEBRICK:2)
B(7,8,13,STONE)
B(8,8,13,STONEBRICK:1)
B(9,8,13,STONE)
B(10,8,13,STONEBRICK)
B(14,8,13,STONEBRICK:1)
B(15,8,13,MOSSY_COBBLESTONE)
B(16,8,13,STONEBRICK:1)
B(17,8,13,STONE)
B(18,8,13,STONEBRICK:1)
B(22,8,13,STONEBRICK:1)
B(23,8,13,STONE)
B(24,8,13,STONEBRICK:2)
B(0,0,14,STONEBRICK:1)
B(1,0,14,STONEBRICK:2)
B(2,0,14,STONEBRICK)
B(3,0,14,STONEBRICK:2)
B(4,0,14,STONEBRICK)
B(5,0,14,STONEBRICK)
B(6,0,14,STONEBRICK)
B(7,0,14,STONEBRICK:1)
B(8,0,14,STONEBRICK)
B(9,0,14,STONEBRICK:1)
B(10,0,14,STONEBRICK:1)
B(11,0,14,STONEBRICK:1)
B(12,0,14,STONEBRICK)
B(13,0,14,STONEBRICK:1)
B(14,0,14,STONEBRICK)
B(15,0,14,STONEBRICK:1)
B(16,0,14,STONEBRICK:2)
B(17,0,14,STONEBRICK:1)
B(18,0,14,STONEBRICK)
B(19,0,14,STONEBRICK:2)
B(20,0,14,STONEBRICK:1)
B(21,0,14,STONEBRICK)
B(22,0,14,STONEBRICK:2)
B(23,0,14,STONEBRICK:2)
B(24,0,14,STONEBRICK:2)
B(0,1,14,MOSSY_COBBLESTONE)
B(24,1,14,MOSSY_COBBLESTONE)
B(0,2,14,MOSSY_COBBLESTONE)
B(24,2,14,MOSSY_COBBLESTONE)
B(0,3,14,STONE)
B(24,3,14,STONE)
B(0,4,14,STONE)
B(24,4,14,STONE)
B(0,5,14,STONE)
B(24,5,14,STONE)
B(0,6,14,STONE)
B(24,6,14,STONE)
B(0,7,14,MOSSY_COBBLESTONE)
B(1,7,14,STONEBRICK:1)
B(7,7,14,STONEBRICK:1)
B(8,7,14,STONEBRICK)
B(9,7,14,STONEBRICK:1)
B(15,7,14,STONEBRICK:1)
B(16,7,14,STONEBRICK)
B(17,7,14,STONEBRICK)
B(23,7,14,STONEBRICK:1)
B(24,7,14,STONE)
B(0,8,14,STONEBRICK)
B(1,8,14,MOSSY_COBBLESTONE)
B(2,8,14,STONEBRICK:2)
B(3,8,14,STONEBRICK)
B(4,8,14,STONEBRICK:1)
B(5,8,14,STONEBRICK:1)
B(6,8,14,STONEBRICK:1)
B(7,8,14,STONE)
B(8,8,14,STONEBRICK:1)
B(9,8,14,STONE)
B(10,8,14,STONEBRICK:1)
B(11,8,14,STONEBRICK:1)
B(12,8,14,STONEBRICK)
B(13,8,14,STONEBRICK:1)
B(14,8,14,STONEBRICK)
B(15,8,14,MOSSY_COBBLESTONE)
B(16,8,14,STONEBRICK)
B(17,8,14,STONE)
B(18,8,14,STONEBRICK)
B(19,8,14,STONEBRICK:1)
B(20,8,14,STONEBRICK:1)
B(21,8,14,STONEBRICK)
B(22,8,14,STONEBRICK)
B(23,8,14,STONE)
B(24,8,14,STONEBRICK:1)
B(0,0,15,STONEBRICK:1)
B(1,0,15,STONEBRICK:1)
B(2,0,15,STONEBRICK)
B(3,0,15,STONEBRICK:2)
B(4,0,15,STONEBRICK:1)
B(5,0,15,STONEBRICK:1)
B(6,0,15,STONEBRICK)
B(7,0,15,STONEBRICK)
B(8,0,15,STONEBRICK)
B(9,0,15,STONEBRICK:1)
B(10,0,15,STONEBRICK:2)
B(11,0,15,STONEBRICK)
B(12,0,15,STONEBRICK:2)
B(13,0,15,STONEBRICK)
B(14,0,15,STONEBRICK)
B(15,0,15,STONEBRICK)
B(16,0,15,STONEBRICK:1)
B(17,0,15,STONEBRICK:1)
B(18,0,15,STONEBRICK)
B(19,0,15,STONEBRICK)
B(20,0,15,STONEBRICK)
B(21,0,15,STONEBRICK:1)
B(22,0,15,STONEBRICK:1)
B(23,0,15,STONEBRICK:1)
B(24,0,15,STONEBRICK:2)
B(0,1,15,STONE)
B(1,1,15,MOSSY_COBBLESTONE)
B(4,1,15,STONEBRICK:3)
B(7,1,15,MOSSY_COBBLESTONE)
B(8,1,15,EMERALD_ORE)
B(9,1,15,MOSSY_COBBLESTONE)
B(15,1,15,STONE)
B(16,1,15,EMERALD_ORE)
B(17,1,15,MOSSY_COBBLESTONE)
B(20,1,15,STONEBRICK:3)
B(23,1,15,MOSSY_COBBLESTONE)
B(24,1,15,STONE)
B(0,2,15,MOSSY_COBBLESTONE)
B(1,2,15,STONE)
B(7,2,15,STONE)
B(8,2,15,STONE)
B(9,2,15,MOSSY_COBBLESTONE)
B(15,2,15,MOSSY_COBBLESTONE)
B(16,2,15,STONE)
B(17,2,15,MOSSY_COBBLESTONE)
B(23,2,15,MOSSY_COBBLESTONE)
B(24,2,15,STONE)
B(0,3,15,STONE)
B(1,3,15,STONE)
B(7,3,15,MOSSY_COBBLESTONE)
B(8,3,15,STONE)
B(9,3,15,MOSSY_COBBLESTONE)
B(15,3,15,MOSSY_COBBLESTONE)
B(16,3,15,MOSSY_COBBLESTONE)
B(17,3,15,STONE)
B(23,3,15,STONE)
B(24,3,15,MOSSY_COBBLESTONE)
B(0,4,15,EMERALD_ORE)
B(1,4,15,STONEBRICK)
B(7,4,15,STONEBRICK:1)
B(8,4,15,STONEBRICK:1)
B(9,4,15,STONEBRICK)
B(15,4,15,STONEBRICK:2)
B(16,4,15,STONEBRICK:2)
B(17,4,15,STONEBRICK)
B(23,4,15,STONEBRICK:1)
B(24,4,15,EMERALD_ORE)
B(0,5,15,MOSSY_COBBLESTONE)
B(1,5,15,STONEBRICK)
B(7,5,15,STONEBRICK:2)
B(8,5,15,STONEBRICK:1)
B(9,5,15,STONEBRICK)
B(15,5,15,STONEBRICK)
B(16,5,15,STONEBRICK:1)
B(17,5,15,STONEBRICK:2)
B(23,5,15,STONEBRICK:1)
B(24,5,15,MOSSY_COBBLESTONE)
B(0,6,15,STONE)
B(1,6,15,STONEBRICK:2)
B(7,6,15,STONEBRICK:2)
B(8,6,15,STONEBRICK:1)
B(9,6,15,STONEBRICK:2)
B(15,6,15,STONEBRICK:1)
B(16,6,15,STONEBRICK:2)
B(17,6,15,STONEBRICK:2)
B(23,6,15,STONEBRICK)
B(24,6,15,EMERALD_ORE)
B(0,7,15,STONE)
B(1,7,15,STONEBRICK)
B(2,7,15,STONEBRICK:2)
B(3,7,15,STONEBRICK:1)
B(4,7,15,STONEBRICK:1)
B(5,7,15,STONEBRICK:2)
B(6,7,15,STONEBRICK)
B(7,7,15,STONEBRICK:1)
B(8,7,15,MOSSY_COBBLESTONE)
B(9,7,15,STONEBRICK:2)
B(10,7,15,STONEBRICK)
B(11,7,15,STONEBRICK:2)
B(12,7,15,STONEBRICK:1)
B(13,7,15,STONEBRICK:1)
B(14,7,15,STONEBRICK:2)
B(15,7,15,STONEBRICK)
B(16,7,15,STONEBRICK)
B(17,7,15,STONEBRICK)
B(18,7,15,STONEBRICK:2)
B(19,7,15,STONEBRICK:2)
B(20,7,15,STONEBRICK:2)
B(21,7,15,STONEBRICK)
B(22,7,15,STONEBRICK:1)
B(23,7,15,STONEBRICK)
B(24,7,15,STONE)
B(0,8,15,STONEBRICK:1)
B(1,8,15,STONE)
B(2,8,15,MOSSY_COBBLESTONE)
B(3,8,15,MOSSY_COBBLESTONE)
B(4,8,15,STONE)
B(5,8,15,MOSSY_COBBLESTONE)
B(6,8,15,EMERALD_ORE)
B(7,8,15,STONE)
B(8,8,15,STONEBRICK:2)
B(9,8,15,MOSSY_COBBLESTONE)
B(10,8,15,MOSSY_COBBLESTONE)
B(11,8,15,STONE)
B(12,8,15,MOSSY_COBBLESTONE)
B(13,8,15,MOSSY_COBBLESTONE)
B(14,8,15,MOSSY_COBBLESTONE)
B(15,8,15,STONE)
B(16,8,15,STONEBRICK:1)
B(17,8,15,STONE)
B(18,8,15,MOSSY_COBBLESTONE)
B(19,8,15,MOSSY_COBBLESTONE)
B(20,8,15,STONE)
B(21,8,15,STONE)
B(22,8,15,MOSSY_COBBLESTONE)
B(23,8,15,STONE)
B(24,8,15,STONEBRICK)
B(0,0,16,STONEBRICK)
B(1,0,16,STONEBRICK:2)
B(2,0,16,STONEBRICK:2)
B(3,0,16,STONEBRICK:1)
B(4,0,16,STONEBRICK:1)
B(5,0,16,STONEBRICK:2)
B(6,0,16,STONEBRICK)
B(7,0,16,STONEBRICK)
B(8,0,16,STONEBRICK)
B(9,0,16,STONEBRICK:2)
B(10,0,16,STONEBRICK:1)
B(11,0,16,STONEBRICK:1)
B(12,0,16,STONEBRICK:1)
B(13,0,16,STONEBRICK:1)
B(14,0,16,STONEBRICK:1)
B(15,0,16,STONEBRICK:2)
B(16,0,16,STONEBRICK:1)
B(17,0,16,STONEBRICK:1)
B(18,0,16,STONEBRICK)
B(19,0,16,STONEBRICK)
B(20,0,16,STONEBRICK:1)
B(21,0,16,STONEBRICK)
B(22,0,16,STONEBRICK)
B(23,0,16,STONEBRICK:2)
B(24,0,16,STONEBRICK:1)
B(0,1,16,STONEBRICK:1)
B(1,1,16,MOSSY_COBBLESTONE)
B(2,1,16,STONE)
B(3,1,16,STONE)
B(4,1,16,MOSSY_COBBLESTONE)
B(5,1,16,MOSSY_COBBLESTONE)
B(6,1,16,MOSSY_COBBLESTONE)
B(7,1,16,STONE)
B(8,1,16,STONEBRICK)
B(9,1,16,STONE)
B(10,1,16,STONE)
B(11,1,16,STONEBRICK)
B(13,1,16,STONEBRICK:1)
B(14,1,16,STONE)
B(15,1,16,STONE)
B(16,1,16,STONEBRICK:2)
B(17,1,16,STONE)
B(18,1,16,STONE)
B(19,1,16,STONE)
B(20,1,16,STONE)
B(21,1,16,STONE)
B(22,1,16,EMERALD_ORE)
B(23,1,16,MOSSY_COBBLESTONE)
B(24,1,16,STONEBRICK)
B(0,2,16,STONEBRICK)
B(1,2,16,MOSSY_COBBLESTONE)
B(2,2,16,MOSSY_COBBLESTONE)
B(3,2,16,MOSSY_COBBLESTONE)
B(4,2,16,EMERALD_ORE)
B(5,2,16,MOSSY_COBBLESTONE)
B(6,2,16,STONE)
B(7,2,16,MOSSY_COBBLESTONE)
B(8,2,16,STONEBRICK:1)
B(9,2,16,STONE)
B(10,2,16,MOSSY_COBBLESTONE)
B(11,2,16,STONEBRICK:1)
B(13,2,16,STONEBRICK)
B(14,2,16,MOSSY_COBBLESTONE)
B(15,2,16,STONE)
B(16,2,16,STONEBRICK:1)
B(17,2,16,STONE)
B(18,2,16,STONE)
B(19,2,16,STONE)
B(20,2,16,MOSSY_COBBLESTONE)
B(21,2,16,STONE)
B(22,2,16,MOSSY_COBBLESTONE)
B(23,2,16,STONE)
B(24,2,16,STONEBRICK)
B(0,3,16,STONEBRICK:1)
B(1,3,16,MOSSY_COBBLESTONE)
B(2,3,16,STONE)
B(3,3,16,EMERALD_ORE)
B(4,3,16,EMERALD_ORE)
B(5,3,16,MOSSY_COBBLESTONE)
B(6,3,16,STONE)
B(7,3,16,STONE)
B(8,3,16,STONEBRICK:1)
B(9,3,16,MOSSY_COBBLESTONE)
B(10,3,16,EMERALD_ORE)
B(11,3,16,STONEBRICK)
B(13,3,16,STONEBRICK:2)
B(14,3,16,STONE)
B(15,3,16,MOSSY_COBBLESTONE)
B(16,3,16,STONEBRICK:1)
B(17,3,16,EMERALD_ORE)
B(18,3,16,STONE)
B(19,3,16,STONE)
B(20,3,16,EMERALD_ORE)
B(21,3,16,EMERALD_ORE)
B(22,3,16,EMERALD_ORE)
B(23,3,16,MOSSY_COBBLESTONE)
B(24,3,16,STONEBRICK:2)
B(0,4,16,STONEBRICK:2)
B(1,4,16,STONE)
B(2,4,16,STONE)
B(3,4,16,MOSSY_COBBLESTONE)
B(4,4,16,STONE)
B(5,4,16,EMERALD_ORE)
B(6,4,16,STONE)
B(7,4,16,STONE)
B(8,4,16,STONEBRICK:1)
B(9,4,16,STONE)
B(10,4,16,STONE)
B(11,4,16,STONEBRICK:1)
B(12,4,16,STONEBRICK:2)
B(13,4,16,STONEBRICK)
B(14,4,16,STONE)
B(15,4,16,MOSSY_COBBLESTONE)
B(16,4,16,STONEBRICK:2)
B(17,4,16,STONE)
B(18,4,16,STONE)
B(19,4,16,MOSSY_COBBLESTONE)
B(20,4,16,STONE)
B(21,4,16,STONE)
B(22,4,16,STONE)
B(23,4,16,STONE)
B(24,4,16,STONEBRICK:1)
B(0,5,16,STONEBRICK)
B(1,5,16,STONE)
B(2,5,16,MOSSY_COBBLESTONE)
B(3,5,16,MOSSY_COBBLESTONE)
B(4,5,16,EMERALD_ORE)
B(5,5,16,STONE)
B(6,5,16,STONE)
B(7,5,16,STONE)
B(8,5,16,STONEBRICK:1)
B(9,5,16,STONE)
B(10,5,16,MOSSY_COBBLESTONE)
B(11,5,16,EMERALD_ORE)
B(12,5,16,STONE)
B(13,5,16,MOSSY_COBBLESTONE)
B(14,5,16,STONE)
B(15,5,16,STONE)
B(16,5,16,STONEBRICK)
B(17,5,16,STONE)
B(18,5,16,MOSSY_COBBLESTONE)
B(19,5,16,MOSSY_COBBLESTONE)
B(20,5,16,MOSSY_COBBLESTONE)
B(21,5,16,STONE)
B(22,5,16,MOSSY_COBBLESTONE)
B(23,5,16,STONE)
B(24,5,16,STONEBRICK:2)
B(0,6,16,STONEBRICK)
B(1,6,16,MOSSY_COBBLESTONE)
B(2,6,16,STONE)
B(3,6,16,STONE)
B(4,6,16,MOSSY_COBBLESTONE)
B(5,6,16,STONE)
B(6,6,16,STONE)
B(7,6,16,MOSSY_COBBLESTONE)
B(8,6,16,STONEBRICK:2)
B(9,6,16,STONE)
B(10,6,16,MOSSY_COBBLESTONE)
B(11,6,16,MOSSY_COBBLESTONE)
B(12,6,16,EMERALD_ORE)
B(13,6,16,STONE)
B(14,6,16,MOSSY_COBBLESTONE)
B(15,6,16,MOSSY_COBBLESTONE)
B(16,6,16,STONEBRICK:1)
B(17,6,16,MOSSY_COBBLESTONE)
B(18,6,16,STONE)
B(19,6,16,MOSSY_COBBLESTONE)
B(20,6,16,MOSSY_COBBLESTONE)
B(21,6,16,STONE)
B(22,6,16,EMERALD_ORE)
B(23,6,16,EMERALD_ORE)
B(24,6,16,STONEBRICK)
B(0,7,16,STONEBRICK:1)
B(1,7,16,MOSSY_COBBLESTONE)
B(2,7,16,STONE)
B(3,7,16,STONE)
B(4,7,16,MOSSY_COBBLESTONE)
B(5,7,16,EMERALD_ORE)
B(6,7,16,MOSSY_COBBLESTONE)
B(7,7,16,MOSSY_COBBLESTONE)
B(8,7,16,STONEBRICK:1)
B(9,7,16,STONE)
B(10,7,16,EMERALD_ORE)
B(11,7,16,STONE)
B(12,7,16,MOSSY_COBBLESTONE)
B(13,7,16,MOSSY_COBBLESTONE)
B(14,7,16,MOSSY_COBBLESTONE)
B(15,7,16,MOSSY_COBBLESTONE)
B(16,7,16,STONEBRICK:1)
B(17,7,16,MOSSY_COBBLESTONE)
B(18,7,16,MOSSY_COBBLESTONE)
B(19,7,16,MOSSY_COBBLESTONE)
B(20,7,16,STONE)
B(21,7,16,STONE)
B(22,7,16,MOSSY_COBBLESTONE)
B(23,7,16,STONE)
B(24,7,16,STONEBRICK:2)
B(0,8,16,STONEBRICK:2)
B(1,8,16,STONEBRICK:1)
B(2,8,16,STONEBRICK:1)
B(3,8,16,STONEBRICK:2)
B(4,8,16,STONEBRICK:1)
B(5,8,16,STONEBRICK:1)
B(6,8,16,STONEBRICK:1)
B(7,8,16,STONEBRICK:2)
B(8,8,16,STONEBRICK)
B(9,8,16,STONEBRICK:2)
B(10,8,16,STONEBRICK:1)
B(11,8,16,STONEBRICK:2)
B(12,8,16,STONEBRICK)
B(13,8,16,STONEBRICK:2)
B(14,8,16,STONEBRICK:1)
B(15,8,16,STONEBRICK)
B(16,8,16,STONEBRICK)
B(17,8,16,STONEBRICK)
B(18,8,16,STONEBRICK)
B(19,8,16,STONEBRICK:2)
B(20,8,16,STONEBRICK:1)
B(21,8,16,STONEBRICK:2)
B(22,8,16,STONEBRICK)
B(23,8,16,STONEBRICK:2)
B(24,8,16,STONEBRICK:1)
B(8,0,17,STONEBRICK:1)
B(9,0,17,STONEBRICK:2)
B(10,0,17,STONEBRICK:2)
B(11,0,17,STONEBRICK:1)
B(12,0,17,STONEBRICK:1)
B(13,0,17,STONEBRICK:1)
B(14,0,17,STONEBRICK:2)
B(15,0,17,STONEBRICK:2)
B(16,0,17,STONEBRICK)
B(8,1,17,EMERALD_ORE)
B(9,1,17,MOSSY_COBBLESTONE)
B(15,1,17,STONE)
B(16,1,17,STONE)
B(8,2,17,MOSSY_COBBLESTONE)
B(9,2,17,STONE)
B(15,2,17,STONE)
B(16,2,17,STONE)
B(8,3,17,MOSSY_COBBLESTONE)
B(9,3,17,MOSSY_COBBLESTONE)
B(15,3,17,STONE)
B(16,3,17,STONE)
B(8,4,17,MOSSY_COBBLESTONE)
B(9,4,17,STONEBRICK:1)
B(15,4,17,STONEBRICK)
B(16,4,17,STONE)
B(8,5,17,STONE)
B(9,5,17,STONEBRICK:2)
B(15,5,17,STONEBRICK:2)
B(16,5,17,STONE)
B(8,6,17,EMERALD_ORE)
B(9,6,17,STONEBRICK:1)
B(15,6,17,STONEBRICK:1)
B(16,6,17,STONE)
B(8,7,17,MOSSY_COBBLESTONE)
B(9,7,17,STONEBRICK)
B(10,7,17,STONEBRICK:2)
B(11,7,17,STONEBRICK:1)
B(12,7,17,STONEBRICK:1)
B(13,7,17,STONEBRICK:2)
B(14,7,17,STONEBRICK:1)
B(15,7,17,STONEBRICK)
B(16,7,17,MOSSY_COBBLESTONE)
B(8,8,17,STONEBRICK:1)
B(9,8,17,MOSSY_COBBLESTONE)
B(10,8,17,MOSSY_COBBLESTONE)
B(11,8,17,STONE)
B(12,8,17,STONE)
B(13,8,17,MOSSY_COBBLESTONE)
B(14,8,17,MOSSY_COBBLESTONE)
B(15,8,17,STONE)
B(16,8,17,STONEBRICK:1)
B(8,0,18,STONEBRICK:2)
B(9,0,18,STONEBRICK:2)
B(10,0,18,STONEBRICK:2)
B(11,0,18,STONEBRICK:2)
B(12,0,18,STONEBRICK)
B(13,0,18,STONEBRICK:1)
B(14,0,18,STONEBRICK:2)
B(15,0,18,STONEBRICK)
B(16,0,18,STONEBRICK:2)
B(8,1,18,STONE)
B(16,1,18,MOSSY_COBBLESTONE)
B(8,2,18,MOSSY_COBBLESTONE)
B(16,2,18,STONE)
B(8,3,18,STONE)
B(16,3,18,STONE)
B(8,4,18,MOSSY_COBBLESTONE)
B(16,4,18,STONE)
B(8,5,18,STONE)
B(16,5,18,STONE)
B(8,6,18,MOSSY_COBBLESTONE)
B(16,6,18,STONE)
B(8,7,18,STONE)
B(9,7,18,STONEBRICK:2)
B(15,7,18,STONEBRICK:2)
B(16,7,18,MOSSY_COBBLESTONE)
B(8,8,18,STONEBRICK:2)
B(9,8,18,STONE)
B(10,8,18,STONEBRICK)
B(11,8,18,STONEBRICK)
B(12,8,18,STONEBRICK:2)
B(13,8,18,STONEBRICK)
B(14,8,18,STONEBRICK:1)
B(15,8,18,MOSSY_COBBLESTONE)
B(16,8,18,STONEBRICK:1)
B(5,0,19,STONEBRICK:2)
B(6,0,19,STONEBRICK)
B(7,0,19,STONEBRICK)
B(8,0,19,STONEBRICK:2)
B(9,0,19,STONEBRICK)
B(10,0,19,STONEBRICK:2)
B(11,0,19,GRASS)
B(12,0,19,DIRT:1)
B(13,0,19,DIRT:1)
B(14,0,19,STONEBRICK:1)
B(15,0,19,STONEBRICK:1)
B(16,0,19,STONEBRICK:2)
B(17,0,19,STONEBRICK)
B(18,0,19,STONEBRICK:1)
B(19,0,19,STONEBRICK)
B(5,1,19,STONEBRICK:2)
B(6,1,19,STONEBRICK:1)
B(7,1,19,STONEBRICK)
B(8,1,19,STONEBRICK)
B(16,1,19,STONEBRICK:2)
B(17,1,19,STONEBRICK)
B(18,1,19,STONEBRICK:1)
B(19,1,19,STONEBRICK:2)
B(5,2,19,STONEBRICK)
B(6,2,19,STONEBRICK:2)
B(7,2,19,STONEBRICK)
B(8,2,19,STONEBRICK)
B(16,2,19,STONEBRICK:1)
B(17,2,19,STONEBRICK)
B(18,2,19,STONEBRICK)
B(19,2,19,STONEBRICK:1)
B(5,3,19,STONEBRICK)
B(6,3,19,STONEBRICK:1)
B(7,3,19,STONEBRICK)
B(8,3,19,STONEBRICK:1)
B(16,3,19,STONEBRICK:2)
B(17,3,19,STONEBRICK:1)
B(18,3,19,STONEBRICK)
B(19,3,19,STONEBRICK)
B(5,4,19,STONEBRICK:2)
B(6,4,19,STONEBRICK:2)
B(7,4,19,STONEBRICK:1)
B(8,4,19,STONEBRICK:1)
B(16,4,19,STONEBRICK:1)
B(17,4,19,STONEBRICK:1)
B(18,4,19,STONEBRICK)
B(19,4,19,STONEBRICK)
B(8,5,19,STONE)
B(16,5,19,MOSSY_COBBLESTONE)
B(8,6,19,STONE)
B(16,6,19,STONE)
B(8,7,19,MOSSY_COBBLESTONE)
B(9,7,19,STONEBRICK)
B(15,7,19,STONEBRICK:1)
B(16,7,19,MOSSY_COBBLESTONE)
B(8,8,19,STONEBRICK:2)
B(9,8,19,EMERALD_ORE)
B(10,8,19,STONEBRICK)
B(14,8,19,STONEBRICK:2)
B(15,8,19,MOSSY_COBBLESTONE)
B(16,8,19,STONEBRICK:1)
B(5,0,20,STONEBRICK)
B(6,0,20,STONEBRICK:2)
B(7,0,20,STONEBRICK:2)
B(8,0,20,STONEBRICK:1)
B(9,0,20,STONEBRICK:2)
B(10,0,20,STONEBRICK)
B(11,0,20,GRASS)
B(12,0,20,DIRT:1)
B(13,0,20,GRASS)
B(14,0,20,STONEBRICK:2)
B(15,0,20,STONEBRICK)
B(16,0,20,STONEBRICK:2)
B(17,0,20,STONEBRICK:1)
B(18,0,20,STONEBRICK)
B(19,0,20,STONEBRICK)
B(5,4,20,STONEBRICK:1)
B(6,4,20,STONEBRICK:1)
B(7,4,20,STONEBRICK:2)
B(8,4,20,STONEBRICK:2)
B(16,4,20,STONEBRICK:1)
B(17,4,20,STONEBRICK:1)
B(18,4,20,STONEBRICK:1)
B(19,4,20,STONEBRICK:2)
B(8,5,20,MOSSY_COBBLESTONE)
B(16,5,20,STONE)
B(8,6,20,MOSSY_COBBLESTONE)
B(16,6,20,EMERALD_ORE)
B(8,7,20,STONE)
B(9,7,20,STONEBRICK:1)
B(15,7,20,STONEBRICK:2)
B(16,7,20,MOSSY_COBBLESTONE)
B(8,8,20,STONEBRICK:1)
B(9,8,20,MOSSY_COBBLESTONE)
B(10,8,20,STONEBRICK:1)
B(14,8,20,STONEBRICK)
B(15,8,20,EMERALD_ORE)
B(16,8,20,STONEBRICK)
B(5,0,21,STONEBRICK)
B(6,0,21,STONEBRICK)
B(7,0,21,STONEBRICK:2)
B(8,0,21,STONEBRICK:2)
B(9,0,21,STONEBRICK:1)
B(10,0,21,STONEBRICK:2)
B(11,0,21,DIRT:1)
B(12,0,21,GRASS)
B(13,0,21,DIRT:1)
B(14,0,21,STONEBRICK:2)
B(15,0,21,STONEBRICK:1)
B(16,0,21,STONEBRICK:1)
B(17,0,21,STONEBRICK:1)
B(18,0,21,STONEBRICK:2)
B(19,0,21,STONEBRICK)
B(5,1,21,STONEBRICK:2)
B(6,1,21,STONEBRICK)
B(7,1,21,STONEBRICK)
B(8,1,21,STONEBRICK:1)
B(16,1,21,STONEBRICK)
B(17,1,21,STONEBRICK:2)
B(18,1,21,STONEBRICK)
B(19,1,21,STONEBRICK)
B(5,2,21,STONEBRICK:1)
B(6,2,21,STONEBRICK)
B(7,2,21,STONEBRICK:1)
B(8,2,21,STONEBRICK:1)
B(16,2,21,STONEBRICK:2)
B(17,2,21,STONEBRICK:1)
B(18,2,21,STONEBRICK:2)
B(19,2,21,STONEBRICK)
B(5,3,21,STONEBRICK)
B(6,3,21,STONEBRICK:1)
B(7,3,21,STONEBRICK)
B(8,3,21,STONEBRICK:2)
B(16,3,21,STONEBRICK:1)
B(17,3,21,STONEBRICK)
B(18,3,21,STONEBRICK:2)
B(19,3,21,STONEBRICK:1)
B(5,4,21,STONEBRICK:1)
B(6,4,21,STONEBRICK:2)
B(7,4,21,STONEBRICK)
B(8,4,21,STONEBRICK)
B(16,4,21,STONEBRICK:1)
B(17,4,21,STONEBRICK:2)
B(18,4,21,STONEBRICK:2)
B(19,4,21,STONEBRICK)
B(8,5,21,EMERALD_ORE)
B(16,5,21,MOSSY_COBBLESTONE)
B(8,6,21,STONE)
B(16,6,21,STONE)
B(8,7,21,MOSSY_COBBLESTONE)
B(9,7,21,STONEBRICK)
B(15,7,21,STONEBRICK)
B(16,7,21,STONE)
B(8,8,21,STONEBRICK:2)
B(9,8,21,STONE)
B(10,8,21,STONEBRICK:2)
B(14,8,21,STONEBRICK:1)
B(15,8,21,MOSSY_COBBLESTONE)
B(16,8,21,STONEBRICK:1)
B(8,0,22,STONEBRICK:1)
B(9,0,22,STONEBRICK:2)
B(10,0,22,STONEBRICK)
B(11,0,22,STONEBRICK:2)
B(12,0,22,STONEBRICK:1)
B(13,0,22,STONEBRICK)
B(14,0,22,STONEBRICK:2)
B(15,0,22,STONEBRICK:1)
B(16,0,22,STONEBRICK:2)
B(8,1,22,MOSSY_COBBLESTONE)
B(16,1,22,STONE)
B(8,2,22,STONE)
B(16,2,22,STONE)
B(8,3,22,MOSSY_COBBLESTONE)
B(16,3,22,MOSSY_COBBLESTONE)
B(8,4,22,STONE)
B(16,4,22,MOSSY_COBBLESTONE)
B(8,5,22,MOSSY_COBBLESTONE)
B(16,5,22,MOSSY_COBBLESTONE)
B(8,6,22,STONE)
B(16,6,22,MOSSY_COBBLESTONE)
B(8,7,22,MOSSY_COBBLESTONE)
B(9,7,22,STONEBRICK:1)
B(15,7,22,STONEBRICK:2)
B(16,7,22,MOSSY_COBBLESTONE)
B(8,8,22,STONEBRICK)
B(9,8,22,EMERALD_ORE)
B(10,8,22,STONEBRICK:2)
B(11,8,22,STONEBRICK)
B(12,8,22,STONEBRICK:1)
B(13,8,22,STONEBRICK)
B(14,8,22,STONEBRICK:2)
B(15,8,22,STONE)
B(16,8,22,STONEBRICK:2)
B(8,0,23,STONEBRICK:1)
B(9,0,23,STONEBRICK:1)
B(10,0,23,STONEBRICK:2)
B(11,0,23,STONEBRICK)
B(12,0,23,STONEBRICK)
B(13,0,23,STONEBRICK:1)
B(14,0,23,STONEBRICK:1)
B(15,0,23,STONEBRICK:1)
B(16,0,23,STONEBRICK)
B(8,1,23,STONE)
B(9,1,23,MOSSY_COBBLESTONE)
B(15,1,23,STONE)
B(16,1,23,MOSSY_COBBLESTONE)
B(8,2,23,STONE)
B(9,2,23,MOSSY_COBBLESTONE)
B(15,2,23,STONE)
B(16,2,23,EMERALD_ORE)
B(8,3,23,EMERALD_ORE)
B(9,3,23,STONE)
B(15,3,23,STONE)
B(16,3,23,STONE)
B(8,4,23,STONE)
B(9,4,23,STONEBRICK:2)
B(15,4,23,STONEBRICK)
B(16,4,23,STONE)
B(8,5,23,MOSSY_COBBLESTONE)
B(9,5,23,STONEBRICK:1)
B(15,5,23,STONEBRICK)
B(16,5,23,EMERALD_ORE)
B(8,6,23,STONE)
B(9,6,23,STONEBRICK:1)
B(15,6,23,STONEBRICK:2)
B(16,6,23,MOSSY_COBBLESTONE)
B(8,7,23,MOSSY_COBBLESTONE)
B(9,7,23,STONEBRICK:1)
B(10,7,23,STONEBRICK:1)
B(11,7,23,STONEBRICK:2)
B(12,7,23,STONEBRICK)
B(13,7,23,STONEBRICK:2)
B(14,7,23,STONEBRICK:1)
B(15,7,23,STONEBRICK:2)
B(16,7,23,MOSSY_COBBLESTONE)
B(8,8,23,STONEBRICK:2)
B(9,8,23,MOSSY_COBBLESTONE)
B(10,8,23,MOSSY_COBBLESTONE)
B(11,8,23,STONE)
B(12,8,23,STONE)
B(13,8,23,EMERALD_ORE)
B(14,8,23,STONE)
B(15,8,23,MOSSY_COBBLESTONE)
B(16,8,23,STONEBRICK)
B(8,0,24,STONEBRICK:2)
B(9,0,24,STONEBRICK:1)
B(10,0,24,STONEBRICK)
B(11,0,24,STONEBRICK)
B(12,0,24,STONEBRICK:2)
B(13,0,24,STONEBRICK:2)
B(14,0,24,STONEBRICK:2)
B(15,0,24,STONEBRICK:2)
B(16,0,24,STONEBRICK:1)
B(8,1,24,STONEBRICK:1)
B(9,1,24,EMERALD_ORE)
B(10,1,24,MOSSY_COBBLESTONE)
B(11,1,24,MOSSY_COBBLESTONE)
B(12,1,24,STONE)
B(13,1,24,MOSSY_COBBLESTONE)
B(14,1,24,STONE)
B(15,1,24,MOSSY_COBBLESTONE)
B(16,1,24,STONEBRICK)
B(8,2,24,STONEBRICK:1)
B(9,2,24,STONE)
B(10,2,24,EMERALD_ORE)
B(11,2,24,MOSSY_COBBLESTONE)
B(12,2,24,MOSSY_COBBLESTONE)
B(13,2,24,MOSSY_COBBLESTONE)
B(14,2,24,MOSSY_COBBLESTONE)
B(15,2,24,MOSSY_COBBLESTONE)
B(16,2,24,STONEBRICK:1)
B(8,3,24,STONEBRICK:1)
B(9,3,24,STONE)
B(10,3,24,STONE)
B(11,3,24,STONE)
B(12,3,24,MOSSY_COBBLESTONE)
B(13,3,24,EMERALD_ORE)
B(14,3,24,MOSSY_COBBLESTONE)
B(15,3,24,STONE)
B(16,3,24,STONEBRICK)
B(8,4,24,STONEBRICK:1)
B(9,4,24,MOSSY_COBBLESTONE)
B(10,4,24,STONE)
B(11,4,24,STONE)
B(12,4,24,MOSSY_COBBLESTONE)
B(13,4,24,MOSSY_COBBLESTONE)
B(14,4,24,MOSSY_COBBLESTONE)
B(15,4,24,STONE)
B(16,4,24,STONEBRICK:1)
B(8,5,24,STONEBRICK:2)
B(9,5,24,MOSSY_COBBLESTONE)
B(10,5,24,STONE)
B(11,5,24,STONE)
B(12,5,24,MOSSY_COBBLESTONE)
B(13,5,24,STONE)
B(14,5,24,STONE)
B(15,5,24,MOSSY_COBBLESTONE)
B(16,5,24,STONEBRICK:1)
B(8,6,24,STONEBRICK:1)
B(9,6,24,MOSSY_COBBLESTONE)
B(10,6,24,MOSSY_COBBLESTONE)
B(11,6,24,STONE)
B(12,6,24,STONE)
B(13,6,24,STONE)
B(14,6,24,STONE)
B(15,6,24,STONE)
B(16,6,24,STONEBRICK)
B(8,7,24,STONEBRICK)
B(9,7,24,STONE)
B(10,7,24,MOSSY_COBBLESTONE)
B(11,7,24,EMERALD_ORE)
B(12,7,24,MOSSY_COBBLESTONE)
B(13,7,24,STONE)
B(14,7,24,STONE)
B(15,7,24,STONE)
B(16,7,24,STONEBRICK:2)
B(8,8,24,STONEBRICK:2)
B(9,8,24,STONEBRICK:1)
B(10,8,24,STONEBRICK:2)
B(11,8,24,STONEBRICK:2)
B(12,8,24,STONEBRICK:2)
B(13,8,24,STONEBRICK:2)
B(14,8,24,STONEBRICK:2)
B(15,8,24,STONEBRICK:2)
B(16,8,24,STONEBRICK:2)
B(10,1,1,AIR)
B(11,1,1,AIR)
B(13,1,1,AIR)
B(14,1,1,AIR)
B(10,2,1,AIR)
B(11,2,1,AIR)
B(12,2,1,AIR)
B(13,2,1,AIR)
B(14,2,1,AIR)
B(10,3,1,AIR)
B(11,3,1,AIR)
B(12,3,1,AIR)
B(13,3,1,AIR)
B(14,3,1,AIR)
B(10,4,1,AIR)
B(11,4,1,AIR)
B(12,4,1,AIR)
B(13,4,1,AIR)
B(14,4,1,AIR)
B(10,5,1,AIR)
B(11,5,1,AIR)
B(12,5,1,AIR)
B(13,5,1,AIR)
B(14,5,1,AIR)
B(10,6,1,STONE_BRICK_STAIRS:5)
B(11,6,1,AIR)
B(12,6,1,AIR)
B(13,6,1,AIR)
B(14,6,1,STONE_BRICK_STAIRS:4)
B(9,1,2,AIR)
B(10,1,2,AIR)
B(11,1,2,AIR)
B(12,1,2,AIR)
B(13,1,2,AIR)
B(14,1,2,AIR)
B(15,1,2,AIR)
B(9,2,2,AIR)
B(10,2,2,AIR)
B(11,2,2,AIR)
B(12,2,2,AIR)
B(13,2,2,AIR)
B(14,2,2,AIR)
B(15,2,2,AIR)
B(9,3,2,AIR)
B(10,3,2,AIR)
B(11,3,2,AIR)
B(12,3,2,AIR)
B(13,3,2,AIR)
B(14,3,2,AIR)
B(15,3,2,AIR)
B(9,4,2,AIR)
B(10,4,2,AIR)
B(11,4,2,AIR)
B(12,4,2,AIR)
B(13,4,2,AIR)
B(14,4,2,AIR)
B(15,4,2,AIR)
B(9,5,2,AIR)
B(10,5,2,AIR)
B(11,5,2,AIR)
B(12,5,2,AIR)
B(13,5,2,AIR)
B(14,5,2,AIR)
B(15,5,2,AIR)
B(9,6,2,STONE_BRICK_STAIRS:7)
B(10,6,2,AIR)
B(11,6,2,AIR)
B(12,6,2,AIR)
B(13,6,2,AIR)
B(14,6,2,AIR)
B(15,6,2,STONE_BRICK_STAIRS:7)
B(10,7,2,AIR)
B(11,7,2,AIR)
B(12,7,2,AIR)
B(13,7,2,AIR)
B(14,7,2,AIR)
B(9,1,3,AIR)
B(10,1,3,AIR)
B(11,1,3,TALLGRASS:2)
B(12,1,3,TALLGRASS:2)
B(13,1,3,TALLGRASS:1)
B(14,1,3,AIR)
B(15,1,3,AIR)
B(9,2,3,AIR)
B(10,2,3,AIR)
B(11,2,3,AIR)
B(12,2,3,AIR)
B(13,2,3,AIR)
B(14,2,3,AIR)
B(15,2,3,AIR)
B(9,3,3,AIR)
B(10,3,3,AIR)
B(11,3,3,AIR)
B(12,3,3,AIR)
B(13,3,3,AIR)
B(14,3,3,AIR)
B(15,3,3,AIR)
B(9,4,3,AIR)
B(10,4,3,AIR)
B(11,4,3,AIR)
B(12,4,3,AIR)
B(13,4,3,AIR)
B(14,4,3,AIR)
B(15,4,3,AIR)
B(9,5,3,AIR)
B(10,5,3,AIR)
B(11,5,3,AIR)
B(12,5,3,AIR)
B(13,5,3,AIR)
B(14,5,3,AIR)
B(15,5,3,AIR)
B(9,6,3,AIR)
B(10,6,3,AIR)
B(11,6,3,AIR)
B(12,6,3,AIR)
B(13,6,3,AIR)
B(14,6,3,AIR)
B(15,6,3,AIR)
B(10,7,3,AIR)
B(11,7,3,AIR)
B(12,7,3,AIR)
B(13,7,3,AIR)
B(14,7,3,AIR)
B(11,8,3,AIR)
B(12,8,3,AIR)
B(13,8,3,AIR)
B(5,1,4,AIR)
B(6,1,4,AIR)
B(7,1,4,AIR)
B(8,1,4,AIR)
B(9,1,4,AIR)
B(10,1,4,AIR)
B(11,1,4,TALLGRASS:2)
B(13,1,4,TALLGRASS:2)
B(14,1,4,AIR)
B(15,1,4,AIR)
B(16,1,4,AIR)
B(17,1,4,AIR)
B(18,1,4,AIR)
B(19,1,4,AIR)
B(5,2,4,AIR)
B(6,2,4,AIR)
B(7,2,4,AIR)
B(8,2,4,AIR)
B(9,2,4,AIR)
B(10,2,4,AIR)
B(11,2,4,AIR)
B(12,2,4,AIR)
B(13,2,4,AIR)
B(14,2,4,AIR)
B(15,2,4,AIR)
B(16,2,4,AIR)
B(17,2,4,AIR)
B(18,2,4,AIR)
B(19,2,4,AIR)
B(5,3,4,AIR)
B(6,3,4,AIR)
B(7,3,4,AIR)
B(8,3,4,AIR)
B(9,3,4,AIR)
B(10,3,4,AIR)
B(11,3,4,AIR)
B(12,3,4,AIR)
B(13,3,4,AIR)
B(14,3,4,AIR)
B(15,3,4,AIR)
B(16,3,4,AIR)
B(17,3,4,AIR)
B(18,3,4,AIR)
B(19,3,4,AIR)
B(9,4,4,AIR)
B(10,4,4,AIR)
B(11,4,4,AIR)
B(12,4,4,AIR)
B(13,4,4,AIR)
B(14,4,4,AIR)
B(15,4,4,AIR)
B(9,5,4,AIR)
B(10,5,4,AIR)
B(11,5,4,AIR)
B(12,5,4,AIR)
B(13,5,4,AIR)
B(14,5,4,AIR)
B(15,5,4,AIR)
B(9,6,4,AIR)
B(10,6,4,AIR)
B(11,6,4,AIR)
B(12,6,4,AIR)
B(13,6,4,AIR)
B(14,6,4,AIR)
B(15,6,4,AIR)
B(10,7,4,AIR)
B(11,7,4,AIR)
B(12,7,4,AIR)
B(13,7,4,AIR)
B(14,7,4,AIR)
B(11,8,4,AIR)
B(12,8,4,AIR)
B(13,8,4,AIR)
B(9,1,5,AIR)
B(10,1,5,AIR)
B(11,1,5,AIR)
B(12,1,5,TALLGRASS:2)
B(13,1,5,TALLGRASS:2)
B(14,1,5,AIR)
B(15,1,5,AIR)
B(9,2,5,AIR)
B(10,2,5,AIR)
B(11,2,5,AIR)
B(12,2,5,AIR)
B(13,2,5,AIR)
B(14,2,5,AIR)
B(15,2,5,AIR)
B(9,3,5,AIR)
B(10,3,5,AIR)
B(11,3,5,AIR)
B(12,3,5,AIR)
B(13,3,5,AIR)
B(14,3,5,AIR)
B(15,3,5,AIR)
B(9,4,5,AIR)
B(10,4,5,AIR)
B(11,4,5,AIR)
B(12,4,5,AIR)
B(13,4,5,AIR)
B(14,4,5,AIR)
B(15,4,5,AIR)
B(9,5,5,AIR)
B(10,5,5,AIR)
B(11,5,5,AIR)
B(12,5,5,AIR)
B(13,5,5,AIR)
B(14,5,5,AIR)
B(15,5,5,AIR)
B(9,6,5,AIR)
B(10,6,5,AIR)
B(11,6,5,AIR)
B(12,6,5,AIR)
B(13,6,5,AIR)
B(14,6,5,AIR)
B(15,6,5,AIR)
B(10,7,5,AIR)
B(11,7,5,AIR)
B(12,7,5,AIR)
B(13,7,5,AIR)
B(14,7,5,AIR)
B(11,8,5,AIR)
B(12,8,5,AIR)
B(13,8,5,AIR)
B(9,1,6,AIR)
B(10,1,6,AIR)
B(11,1,6,AIR)
B(12,1,6,AIR)
B(13,1,6,AIR)
B(14,1,6,AIR)
B(15,1,6,AIR)
B(9,2,6,AIR)
B(10,2,6,AIR)
B(11,2,6,AIR)
B(12,2,6,AIR)
B(13,2,6,AIR)
B(14,2,6,AIR)
B(15,2,6,AIR)
B(9,3,6,AIR)
B(10,3,6,AIR)
B(11,3,6,AIR)
B(12,3,6,AIR)
B(13,3,6,AIR)
B(14,3,6,AIR)
B(15,3,6,AIR)
B(9,4,6,AIR)
B(10,4,6,AIR)
B(11,4,6,AIR)
B(12,4,6,AIR)
B(13,4,6,AIR)
B(14,4,6,AIR)
B(15,4,6,AIR)
B(9,5,6,AIR)
B(10,5,6,AIR)
B(11,5,6,AIR)
B(12,5,6,AIR)
B(13,5,6,AIR)
B(14,5,6,AIR)
B(15,5,6,AIR)
B(9,6,6,STONE_BRICK_STAIRS:6)
B(10,6,6,AIR)
B(11,6,6,AIR)
B(12,6,6,AIR)
B(13,6,6,AIR)
B(14,6,6,AIR)
B(15,6,6,STONE_BRICK_STAIRS:6)
B(10,7,6,AIR)
B(11,7,6,AIR)
B(12,7,6,AIR)
B(13,7,6,AIR)
B(14,7,6,AIR)
B(10,1,7,AIR)
B(11,1,7,AIR)
B(12,1,7,AIR)
B(13,1,7,AIR)
B(14,1,7,AIR)
B(10,2,7,AIR)
B(11,2,7,AIR)
B(12,2,7,AIR)
B(13,2,7,AIR)
B(14,2,7,AIR)
B(10,3,7,AIR)
B(11,3,7,AIR)
B(12,3,7,AIR)
B(13,3,7,AIR)
B(14,3,7,AIR)
B(10,4,7,AIR)
B(11,4,7,AIR)
B(12,4,7,AIR)
B(13,4,7,AIR)
B(14,4,7,AIR)
B(10,5,7,AIR)
B(11,5,7,AIR)
B(12,5,7,AIR)
B(13,5,7,AIR)
B(14,5,7,AIR)
B(10,6,7,STONE_BRICK_STAIRS:5)
B(11,6,7,AIR)
B(12,6,7,AIR)
B(13,6,7,AIR)
B(14,6,7,STONE_BRICK_STAIRS:4)
B(12,1,8,AIR)
B(12,2,8,AIR)
B(12,3,8,AIR)
B(2,1,9,AIR)
B(3,1,9,AIR)
B(5,1,9,AIR)
B(6,1,9,AIR)
B(10,1,9,AIR)
B(11,1,9,AIR)
B(12,1,9,AIR)
B(13,1,9,AIR)
B(14,1,9,AIR)
B(18,1,9,AIR)
B(19,1,9,AIR)
B(21,1,9,AIR)
B(22,1,9,AIR)
B(2,2,9,AIR)
B(3,2,9,AIR)
B(5,2,9,AIR)
B(6,2,9,AIR)
B(10,2,9,AIR)
B(11,2,9,AIR)
B(12,2,9,AIR)
B(13,2,9,AIR)
B(14,2,9,AIR)
B(18,2,9,AIR)
B(19,2,9,AIR)
B(21,2,9,AIR)
B(22,2,9,AIR)
B(2,3,9,AIR)
B(3,3,9,AIR)
B(4,3,9,AIR)
B(5,3,9,AIR)
B(6,3,9,AIR)
B(10,3,9,AIR)
B(11,3,9,AIR)
B(12,3,9,AIR)
B(13,3,9,AIR)
B(14,3,9,AIR)
B(18,3,9,AIR)
B(19,3,9,AIR)
B(20,3,9,AIR)
B(21,3,9,AIR)
B(22,3,9,AIR)
B(2,4,9,AIR)
B(3,4,9,AIR)
B(4,4,9,AIR)
B(5,4,9,AIR)
B(6,4,9,AIR)
B(10,4,9,AIR)
B(11,4,9,AIR)
B(12,4,9,AIR)
B(13,4,9,AIR)
B(14,4,9,AIR)
B(18,4,9,AIR)
B(19,4,9,AIR)
B(20,4,9,AIR)
B(21,4,9,AIR)
B(22,4,9,AIR)
B(2,5,9,AIR)
B(3,5,9,AIR)
B(4,5,9,AIR)
B(5,5,9,AIR)
B(6,5,9,AIR)
B(10,5,9,AIR)
B(11,5,9,AIR)
B(12,5,9,AIR)
B(13,5,9,AIR)
B(14,5,9,AIR)
B(18,5,9,AIR)
B(19,5,9,AIR)
B(20,5,9,AIR)
B(21,5,9,AIR)
B(22,5,9,AIR)
B(2,6,9,STONE_BRICK_STAIRS:5)
B(3,6,9,AIR)
B(4,6,9,AIR)
B(5,6,9,AIR)
B(6,6,9,STONE_BRICK_STAIRS:4)
B(10,6,9,STONE_BRICK_STAIRS:5)
B(11,6,9,AIR)
B(12,6,9,AIR)
B(13,6,9,AIR)
B(14,6,9,STONE_BRICK_STAIRS:4)
B(18,6,9,STONE_BRICK_STAIRS:5)
B(19,6,9,AIR)
B(20,6,9,AIR)
B(21,6,9,AIR)
B(22,6,9,STONE_BRICK_STAIRS:4)
B(1,1,10,AIR)
B(2,1,10,AIR)
B(3,1,10,AIR)
B(4,1,10,AIR)
B(5,1,10,AIR)
B(6,1,10,AIR)
B(7,1,10,AIR)
B(8,1,10,AIR)
B(9,1,10,AIR)
B(10,1,10,AIR)
B(11,1,10,AIR)
B(12,1,10,AIR)
B(13,1,10,AIR)
B(14,1,10,AIR)
B(15,1,10,AIR)
B(16,1,10,AIR)
B(17,1,10,AIR)
B(18,1,10,AIR)
B(19,1,10,AIR)
B(20,1,10,AIR)
B(21,1,10,AIR)
B(22,1,10,AIR)
B(23,1,10,AIR)
B(1,2,10,AIR)
B(2,2,10,AIR)
B(3,2,10,AIR)
B(4,2,10,AIR)
B(5,2,10,AIR)
B(6,2,10,AIR)
B(7,2,10,AIR)
B(8,2,10,AIR)
B(9,2,10,AIR)
B(10,2,10,AIR)
B(11,2,10,AIR)
B(12,2,10,AIR)
B(13,2,10,AIR)
B(14,2,10,AIR)
B(15,2,10,AIR)
B(16,2,10,AIR)
B(17,2,10,AIR)
B(18,2,10,AIR)
B(19,2,10,AIR)
B(20,2,10,AIR)
B(21,2,10,AIR)
B(22,2,10,AIR)
B(23,2,10,AIR)
B(1,3,10,AIR)
B(2,3,10,AIR)
B(3,3,10,AIR)
B(4,3,10,AIR)
B(5,3,10,AIR)
B(6,3,10,AIR)
B(7,3,10,AIR)
B(8,3,10,AIR)
B(9,3,10,AIR)
B(10,3,10,AIR)
B(11,3,10,AIR)
B(12,3,10,AIR)
B(13,3,10,AIR)
B(14,3,10,AIR)
B(15,3,10,AIR)
B(16,3,10,AIR)
B(17,3,10,AIR)
B(18,3,10,AIR)
B(19,3,10,AIR)
B(20,3,10,AIR)
B(21,3,10,AIR)
B(22,3,10,AIR)
B(23,3,10,AIR)
B(1,4,10,AIR)
B(2,4,10,AIR)
B(3,4,10,AIR)
B(4,4,10,AIR)
B(5,4,10,AIR)
B(6,4,10,AIR)
B(7,4,10,AIR)
B(8,4,10,AIR)
B(9,4,10,AIR)
B(10,4,10,AIR)
B(11,4,10,AIR)
B(12,4,10,AIR)
B(13,4,10,AIR)
B(14,4,10,AIR)
B(15,4,10,AIR)
B(16,4,10,AIR)
B(17,4,10,AIR)
B(18,4,10,AIR)
B(19,4,10,AIR)
B(20,4,10,AIR)
B(21,4,10,AIR)
B(22,4,10,AIR)
B(23,4,10,AIR)
B(1,5,10,AIR)
B(2,5,10,AIR)
B(3,5,10,AIR)
B(4,5,10,AIR)
B(5,5,10,AIR)
B(6,5,10,AIR)
B(7,5,10,AIR)
B(8,5,10,AIR)
B(9,5,10,AIR)
B(10,5,10,AIR)
B(11,5,10,AIR)
B(12,5,10,AIR)
B(13,5,10,AIR)
B(14,5,10,AIR)
B(15,5,10,AIR)
B(16,5,10,AIR)
B(17,5,10,AIR)
B(18,5,10,AIR)
B(19,5,10,AIR)
B(20,5,10,AIR)
B(21,5,10,AIR)
B(22,5,10,AIR)
B(23,5,10,AIR)
B(1,6,10,STONE_BRICK_STAIRS:7)
B(2,6,10,AIR)
B(3,6,10,AIR)
B(4,6,10,AIR)
B(5,6,10,AIR)
B(6,6,10,AIR)
B(7,6,10,STONE_BRICK_STAIRS:7)
B(8,6,10,STONE_BRICK_STAIRS:7)
B(9,6,10,STONE_BRICK_STAIRS:7)
B(10,6,10,AIR)
B(11,6,10,AIR)
B(12,6,10,AIR)
B(13,6,10,AIR)
B(14,6,10,AIR)
B(15,6,10,STONE_BRICK_STAIRS:7)
B(16,6,10,STONE_BRICK_STAIRS:7)
B(17,6,10,STONE_BRICK_STAIRS:7)
B(18,6,10,AIR)
B(19,6,10,AIR)
B(20,6,10,AIR)
B(21,6,10,AIR)
B(22,6,10,AIR)
B(23,6,10,STONE_BRICK_STAIRS:7)
B(2,7,10,AIR)
B(3,7,10,AIR)
B(4,7,10,AIR)
B(5,7,10,AIR)
B(6,7,10,AIR)
B(10,7,10,AIR)
B(11,7,10,AIR)
B(12,7,10,AIR)
B(13,7,10,AIR)
B(14,7,10,AIR)
B(18,7,10,AIR)
B(19,7,10,AIR)
B(20,7,10,AIR)
B(21,7,10,AIR)
B(22,7,10,AIR)
B(1,1,11,AIR)
B(2,1,11,AIR)
B(3,1,11,TALLGRASS:1)
B(4,1,11,TALLGRASS:2)
B(5,1,11,TALLGRASS:1)
B(6,1,11,AIR)
B(7,1,11,AIR)
B(8,1,11,AIR)
B(9,1,11,AIR)
B(10,1,11,AIR)
B(11,1,11,AIR)
B(12,1,11,TALLGRASS:2)
B(13,1,11,TALLGRASS:1)
B(14,1,11,TALLGRASS:2)
B(15,1,11,TALLGRASS:1)
B(16,1,11,TALLGRASS:2)
B(17,1,11,TALLGRASS:1)
B(18,1,11,TALLGRASS:1)
B(19,1,11,TALLGRASS:1)
B(20,1,11,TALLGRASS:2)
B(21,1,11,TALLGRASS:2)
B(22,1,11,AIR)
B(23,1,11,AIR)
B(1,2,11,AIR)
B(2,2,11,AIR)
B(3,2,11,AIR)
B(4,2,11,AIR)
B(5,2,11,AIR)
B(6,2,11,AIR)
B(7,2,11,AIR)
B(8,2,11,AIR)
B(9,2,11,AIR)
B(10,2,11,AIR)
B(11,2,11,AIR)
B(12,2,11,AIR)
B(13,2,11,AIR)
B(14,2,11,AIR)
B(15,2,11,AIR)
B(16,2,11,AIR)
B(17,2,11,AIR)
B(18,2,11,AIR)
B(19,2,11,AIR)
B(20,2,11,AIR)
B(21,2,11,AIR)
B(22,2,11,AIR)
B(23,2,11,AIR)
B(1,3,11,AIR)
B(2,3,11,AIR)
B(3,3,11,AIR)
B(4,3,11,AIR)
B(5,3,11,AIR)
B(6,3,11,AIR)
B(7,3,11,AIR)
B(8,3,11,AIR)
B(9,3,11,AIR)
B(10,3,11,AIR)
B(11,3,11,AIR)
B(12,3,11,AIR)
B(13,3,11,AIR)
B(14,3,11,AIR)
B(15,3,11,AIR)
B(16,3,11,AIR)
B(17,3,11,AIR)
B(18,3,11,AIR)
B(19,3,11,AIR)
B(20,3,11,AIR)
B(21,3,11,AIR)
B(22,3,11,AIR)
B(23,3,11,AIR)
B(1,4,11,AIR)
B(2,4,11,AIR)
B(3,4,11,AIR)
B(4,4,11,AIR)
B(5,4,11,AIR)
B(6,4,11,AIR)
B(7,4,11,AIR)
B(8,4,11,AIR)
B(9,4,11,AIR)
B(10,4,11,AIR)
B(11,4,11,AIR)
B(12,4,11,AIR)
B(13,4,11,AIR)
B(14,4,11,AIR)
B(15,4,11,AIR)
B(16,4,11,AIR)
B(17,4,11,AIR)
B(18,4,11,AIR)
B(19,4,11,AIR)
B(20,4,11,AIR)
B(21,4,11,AIR)
B(22,4,11,AIR)
B(23,4,11,AIR)
B(1,5,11,AIR)
B(2,5,11,AIR)
B(3,5,11,AIR)
B(4,5,11,AIR)
B(5,5,11,AIR)
B(6,5,11,AIR)
B(7,5,11,AIR)
B(8,5,11,AIR)
B(9,5,11,AIR)
B(10,5,11,AIR)
B(11,5,11,AIR)
B(12,5,11,AIR)
B(13,5,11,AIR)
B(14,5,11,AIR)
B(15,5,11,AIR)
B(16,5,11,AIR)
B(17,5,11,AIR)
B(18,5,11,AIR)
B(19,5,11,AIR)
B(20,5,11,AIR)
B(21,5,11,AIR)
B(22,5,11,AIR)
B(23,5,11,AIR)
B(1,6,11,AIR)
B(2,6,11,AIR)
B(3,6,11,AIR)
B(4,6,11,AIR)
B(5,6,11,AIR)
B(6,6,11,AIR)
B(7,6,11,AIR)
B(8,6,11,AIR)
B(9,6,11,AIR)
B(10,6,11,AIR)
B(11,6,11,AIR)
B(12,6,11,AIR)
B(13,6,11,AIR)
B(14,6,11,AIR)
B(15,6,11,AIR)
B(16,6,11,AIR)
B(17,6,11,AIR)
B(18,6,11,AIR)
B(19,6,11,AIR)
B(20,6,11,AIR)
B(21,6,11,AIR)
B(22,6,11,AIR)
B(23,6,11,AIR)
B(2,7,11,AIR)
B(3,7,11,AIR)
B(4,7,11,AIR)
B(5,7,11,AIR)
B(6,7,11,AIR)
B(10,7,11,AIR)
B(11,7,11,AIR)
B(12,7,11,AIR)
B(13,7,11,AIR)
B(14,7,11,AIR)
B(18,7,11,AIR)
B(19,7,11,AIR)
B(20,7,11,AIR)
B(21,7,11,AIR)
B(22,7,11,AIR)
B(3,8,11,AIR)
B(4,8,11,AIR)
B(5,8,11,AIR)
B(11,8,11,AIR)
B(12,8,11,AIR)
B(13,8,11,AIR)
B(19,8,11,AIR)
B(20,8,11,AIR)
B(21,8,11,AIR)
B(0,1,12,AIR)
B(1,1,12,AIR)
B(2,1,12,AIR)
B(3,1,12,TALLGRASS:2)
B(4,1,12,TALLGRASS:2)
B(5,1,12,AIR)
B(6,1,12,TALLGRASS:1)
B(7,1,12,TALLGRASS:1)
B(8,1,12,AIR)
B(9,1,12,AIR)
B(10,1,12,TALLGRASS:1)
B(11,1,12,AIR)
B(12,1,12,TALLGRASS:1)
B(13,1,12,TALLGRASS:2)
B(14,1,12,TALLGRASS:2)
B(15,1,12,AIR)
B(16,1,12,TALLGRASS:2)
B(17,1,12,AIR)
B(18,1,12,AIR)
B(19,1,12,AIR)
B(20,1,12,TALLGRASS:2)
B(21,1,12,TALLGRASS:2)
B(22,1,12,AIR)
B(23,1,12,AIR)
B(24,1,12,AIR)
B(0,2,12,AIR)
B(1,2,12,AIR)
B(2,2,12,AIR)
B(3,2,12,AIR)
B(4,2,12,AIR)
B(5,2,12,AIR)
B(6,2,12,AIR)
B(7,2,12,AIR)
B(8,2,12,AIR)
B(9,2,12,AIR)
B(10,2,12,AIR)
B(11,2,12,AIR)
B(12,2,12,AIR)
B(13,2,12,AIR)
B(14,2,12,AIR)
B(15,2,12,AIR)
B(16,2,12,AIR)
B(17,2,12,AIR)
B(18,2,12,AIR)
B(19,2,12,AIR)
B(20,2,12,AIR)
B(21,2,12,AIR)
B(22,2,12,AIR)
B(23,2,12,AIR)
B(24,2,12,AIR)
B(0,3,12,AIR)
B(1,3,12,AIR)
B(2,3,12,AIR)
B(3,3,12,AIR)
B(4,3,12,AIR)
B(5,3,12,AIR)
B(6,3,12,AIR)
B(7,3,12,AIR)
B(8,3,12,AIR)
B(9,3,12,AIR)
B(10,3,12,AIR)
B(11,3,12,AIR)
B(12,3,12,AIR)
B(13,3,12,AIR)
B(14,3,12,AIR)
B(15,3,12,AIR)
B(16,3,12,AIR)
B(17,3,12,AIR)
B(18,3,12,AIR)
B(19,3,12,AIR)
B(20,3,12,AIR)
B(21,3,12,AIR)
B(22,3,12,AIR)
B(23,3,12,AIR)
B(24,3,12,AIR)
B(1,4,12,AIR)
B(2,4,12,AIR)
B(3,4,12,AIR)
B(4,4,12,AIR)
B(5,4,12,AIR)
B(6,4,12,AIR)
B(7,4,12,AIR)
B(8,4,12,AIR)
B(9,4,12,AIR)
B(10,4,12,AIR)
B(11,4,12,AIR)
B(12,4,12,AIR)
B(13,4,12,AIR)
B(14,4,12,AIR)
B(15,4,12,AIR)
B(16,4,12,AIR)
B(17,4,12,AIR)
B(18,4,12,AIR)
B(19,4,12,AIR)
B(20,4,12,AIR)
B(21,4,12,AIR)
B(22,4,12,AIR)
B(23,4,12,AIR)
B(1,5,12,AIR)
B(2,5,12,AIR)
B(3,5,12,AIR)
B(4,5,12,AIR)
B(5,5,12,AIR)
B(6,5,12,AIR)
B(7,5,12,AIR)
B(8,5,12,AIR)
B(9,5,12,AIR)
B(10,5,12,AIR)
B(11,5,12,AIR)
B(12,5,12,AIR)
B(13,5,12,AIR)
B(14,5,12,AIR)
B(15,5,12,AIR)
B(16,5,12,AIR)
B(17,5,12,AIR)
B(18,5,12,AIR)
B(19,5,12,AIR)
B(20,5,12,AIR)
B(21,5,12,AIR)
B(22,5,12,AIR)
B(23,5,12,AIR)
B(1,6,12,AIR)
B(2,6,12,AIR)
B(3,6,12,AIR)
B(4,6,12,AIR)
B(5,6,12,AIR)
B(6,6,12,AIR)
B(7,6,12,AIR)
B(8,6,12,AIR)
B(9,6,12,AIR)
B(10,6,12,AIR)
B(11,6,12,AIR)
B(12,6,12,AIR)
B(13,6,12,AIR)
B(14,6,12,AIR)
B(15,6,12,AIR)
B(16,6,12,AIR)
B(17,6,12,AIR)
B(18,6,12,AIR)
B(19,6,12,AIR)
B(20,6,12,AIR)
B(21,6,12,AIR)
B(22,6,12,AIR)
B(23,6,12,AIR)
B(2,7,12,AIR)
B(3,7,12,AIR)
B(4,7,12,AIR)
B(5,7,12,AIR)
B(6,7,12,AIR)
B(10,7,12,AIR)
B(11,7,12,AIR)
B(12,7,12,AIR)
B(13,7,12,AIR)
B(14,7,12,AIR)
B(18,7,12,AIR)
B(19,7,12,AIR)
B(20,7,12,AIR)
B(21,7,12,AIR)
B(22,7,12,AIR)
B(3,8,12,AIR)
B(4,8,12,AIR)
B(5,8,12,AIR)
B(11,8,12,AIR)
B(12,8,12,AIR)
B(13,8,12,AIR)
B(19,8,12,AIR)
B(20,8,12,AIR)
B(21,8,12,AIR)
B(1,1,13,AIR)
B(2,1,13,AIR)
B(3,1,13,TALLGRASS:1)
B(4,1,13,TALLGRASS:1)
B(5,1,13,TALLGRASS:1)
B(6,1,13,AIR)
B(7,1,13,TALLGRASS:2)
B(8,1,13,TALLGRASS:1)
B(9,1,13,TALLGRASS:1)
B(10,1,13,TALLGRASS:1)
B(11,1,13,TALLGRASS:2)
B(12,1,13,TALLGRASS:1)
B(13,1,13,AIR)
B(14,1,13,TALLGRASS:1)
B(15,1,13,TALLGRASS:2)
B(16,1,13,TALLGRASS:1)
B(17,1,13,TALLGRASS:2)
B(18,1,13,TALLGRASS:1)
B(19,1,13,TALLGRASS:2)
B(20,1,13,AIR)
B(21,1,13,AIR)
B(22,1,13,AIR)
B(23,1,13,AIR)
B(1,2,13,AIR)
B(2,2,13,AIR)
B(3,2,13,AIR)
B(4,2,13,AIR)
B(5,2,13,AIR)
B(6,2,13,AIR)
B(7,2,13,AIR)
B(8,2,13,AIR)
B(9,2,13,AIR)
B(10,2,13,AIR)
B(11,2,13,AIR)
B(12,2,13,AIR)
B(13,2,13,AIR)
B(14,2,13,AIR)
B(15,2,13,AIR)
B(16,2,13,AIR)
B(17,2,13,AIR)
B(18,2,13,AIR)
B(19,2,13,AIR)
B(20,2,13,AIR)
B(21,2,13,AIR)
B(22,2,13,AIR)
B(23,2,13,AIR)
B(1,3,13,AIR)
B(2,3,13,AIR)
B(3,3,13,AIR)
B(4,3,13,AIR)
B(5,3,13,AIR)
B(6,3,13,AIR)
B(7,3,13,AIR)
B(8,3,13,AIR)
B(9,3,13,AIR)
B(10,3,13,AIR)
B(11,3,13,AIR)
B(12,3,13,AIR)
B(13,3,13,AIR)
B(14,3,13,AIR)
B(15,3,13,AIR)
B(16,3,13,AIR)
B(17,3,13,AIR)
B(18,3,13,AIR)
B(19,3,13,AIR)
B(20,3,13,AIR)
B(21,3,13,AIR)
B(22,3,13,AIR)
B(23,3,13,AIR)
B(1,4,13,AIR)
B(2,4,13,AIR)
B(3,4,13,AIR)
B(4,4,13,AIR)
B(5,4,13,AIR)
B(6,4,13,AIR)
B(7,4,13,AIR)
B(8,4,13,AIR)
B(9,4,13,AIR)
B(10,4,13,AIR)
B(11,4,13,AIR)
B(12,4,13,AIR)
B(13,4,13,AIR)
B(14,4,13,AIR)
B(15,4,13,AIR)
B(16,4,13,AIR)
B(17,4,13,AIR)
B(18,4,13,AIR)
B(19,4,13,AIR)
B(20,4,13,AIR)
B(21,4,13,AIR)
B(22,4,13,AIR)
B(23,4,13,AIR)
B(1,5,13,AIR)
B(2,5,13,AIR)
B(3,5,13,AIR)
B(4,5,13,AIR)
B(5,5,13,AIR)
B(6,5,13,AIR)
B(7,5,13,AIR)
B(8,5,13,AIR)
B(9,5,13,AIR)
B(10,5,13,AIR)
B(11,5,13,AIR)
B(12,5,13,AIR)
B(13,5,13,AIR)
B(14,5,13,AIR)
B(15,5,13,AIR)
B(16,5,13,AIR)
B(17,5,13,AIR)
B(18,5,13,AIR)
B(19,5,13,AIR)
B(20,5,13,AIR)
B(21,5,13,AIR)
B(22,5,13,AIR)
B(23,5,13,AIR)
B(1,6,13,AIR)
B(2,6,13,AIR)
B(3,6,13,AIR)
B(4,6,13,AIR)
B(5,6,13,AIR)
B(6,6,13,AIR)
B(7,6,13,AIR)
B(8,6,13,AIR)
B(9,6,13,AIR)
B(10,6,13,AIR)
B(11,6,13,AIR)
B(12,6,13,AIR)
B(13,6,13,AIR)
B(14,6,13,AIR)
B(15,6,13,AIR)
B(16,6,13,AIR)
B(17,6,13,AIR)
B(18,6,13,AIR)
B(19,6,13,AIR)
B(20,6,13,AIR)
B(21,6,13,AIR)
B(22,6,13,AIR)
B(23,6,13,AIR)
B(2,7,13,AIR)
B(3,7,13,AIR)
B(4,7,13,AIR)
B(5,7,13,AIR)
B(6,7,13,AIR)
B(10,7,13,AIR)
B(11,7,13,AIR)
B(12,7,13,AIR)
B(13,7,13,AIR)
B(14,7,13,AIR)
B(18,7,13,AIR)
B(19,7,13,AIR)
B(20,7,13,AIR)
B(21,7,13,AIR)
B(22,7,13,AIR)
B(3,8,13,AIR)
B(4,8,13,AIR)
B(5,8,13,AIR)
B(11,8,13,AIR)
B(12,8,13,AIR)
B(13,8,13,AIR)
B(19,8,13,AIR)
B(20,8,13,AIR)
B(21,8,13,AIR)
B(1,1,14,AIR)
B(2,1,14,AIR)
B(3,1,14,AIR)
B(4,1,14,AIR)
B(5,1,14,AIR)
B(6,1,14,AIR)
B(7,1,14,AIR)
B(8,1,14,AIR)
B(9,1,14,AIR)
B(10,1,14,AIR)
B(11,1,14,AIR)
B(12,1,14,AIR)
B(13,1,14,AIR)
B(14,1,14,AIR)
B(15,1,14,AIR)
B(16,1,14,AIR)
B(17,1,14,AIR)
B(18,1,14,AIR)
B(19,1,14,AIR)
B(20,1,14,AIR)
B(21,1,14,AIR)
B(22,1,14,AIR)
B(23,1,14,AIR)
B(1,2,14,AIR)
B(2,2,14,AIR)
B(3,2,14,AIR)
B(4,2,14,AIR)
B(5,2,14,AIR)
B(6,2,14,AIR)
B(7,2,14,AIR)
B(8,2,14,AIR)
B(9,2,14,AIR)
B(10,2,14,AIR)
B(11,2,14,AIR)
B(12,2,14,AIR)
B(13,2,14,AIR)
B(14,2,14,AIR)
B(15,2,14,AIR)
B(16,2,14,AIR)
B(17,2,14,AIR)
B(18,2,14,AIR)
B(19,2,14,AIR)
B(20,2,14,AIR)
B(21,2,14,AIR)
B(22,2,14,AIR)
B(23,2,14,AIR)
B(1,3,14,AIR)
B(2,3,14,AIR)
B(3,3,14,AIR)
B(4,3,14,AIR)
B(5,3,14,AIR)
B(6,3,14,AIR)
B(7,3,14,AIR)
B(8,3,14,AIR)
B(9,3,14,AIR)
B(10,3,14,AIR)
B(11,3,14,AIR)
B(12,3,14,AIR)
B(13,3,14,AIR)
B(14,3,14,AIR)
B(15,3,14,AIR)
B(16,3,14,AIR)
B(17,3,14,AIR)
B(18,3,14,AIR)
B(19,3,14,AIR)
B(20,3,14,AIR)
B(21,3,14,AIR)
B(22,3,14,AIR)
B(23,3,14,AIR)
B(1,4,14,AIR)
B(2,4,14,AIR)
B(3,4,14,AIR)
B(4,4,14,AIR)
B(5,4,14,AIR)
B(6,4,14,AIR)
B(7,4,14,AIR)
B(8,4,14,AIR)
B(9,4,14,AIR)
B(10,4,14,AIR)
B(11,4,14,AIR)
B(12,4,14,AIR)
B(13,4,14,AIR)
B(14,4,14,AIR)
B(15,4,14,AIR)
B(16,4,14,AIR)
B(17,4,14,AIR)
B(18,4,14,AIR)
B(19,4,14,AIR)
B(20,4,14,AIR)
B(21,4,14,AIR)
B(22,4,14,AIR)
B(23,4,14,AIR)
B(1,5,14,AIR)
B(2,5,14,AIR)
B(3,5,14,AIR)
B(4,5,14,AIR)
B(5,5,14,AIR)
B(6,5,14,AIR)
B(7,5,14,AIR)
B(8,5,14,AIR)
B(9,5,14,AIR)
B(10,5,14,AIR)
B(11,5,14,AIR)
B(12,5,14,AIR)
B(13,5,14,AIR)
B(14,5,14,AIR)
B(15,5,14,AIR)
B(16,5,14,AIR)
B(17,5,14,AIR)
B(18,5,14,AIR)
B(19,5,14,AIR)
B(20,5,14,AIR)
B(21,5,14,AIR)
B(22,5,14,AIR)
B(23,5,14,AIR)
B(1,6,14,STONE_BRICK_STAIRS:6)
B(2,6,14,AIR)
B(3,6,14,AIR)
B(4,6,14,AIR)
B(5,6,14,AIR)
B(6,6,14,AIR)
B(7,6,14,STONE_BRICK_STAIRS:6)
B(8,6,14,STONE_BRICK_STAIRS:6)
B(9,6,14,STONE_BRICK_STAIRS:6)
B(10,6,14,AIR)
B(11,6,14,AIR)
B(12,6,14,AIR)
B(13,6,14,AIR)
B(14,6,14,AIR)
B(15,6,14,STONE_BRICK_STAIRS:6)
B(16,6,14,STONE_BRICK_STAIRS:6)
B(17,6,14,STONE_BRICK_STAIRS:6)
B(18,6,14,AIR)
B(19,6,14,AIR)
B(20,6,14,AIR)
B(21,6,14,AIR)
B(22,6,14,AIR)
B(23,6,14,STONE_BRICK_STAIRS:6)
B(2,7,14,AIR)
B(3,7,14,AIR)
B(4,7,14,AIR)
B(5,7,14,AIR)
B(6,7,14,AIR)
B(10,7,14,AIR)
B(11,7,14,AIR)
B(12,7,14,AIR)
B(13,7,14,AIR)
B(14,7,14,AIR)
B(18,7,14,AIR)
B(19,7,14,AIR)
B(20,7,14,AIR)
B(21,7,14,AIR)
B(22,7,14,AIR)
B(2,1,15,AIR)
B(3,1,15,AIR)
B(5,1,15,AIR)
B(6,1,15,AIR)
B(10,1,15,AIR)
B(11,1,15,AIR)
B(12,1,15,AIR)
B(13,1,15,AIR)
B(14,1,15,AIR)
B(18,1,15,AIR)
B(19,1,15,AIR)
B(21,1,15,AIR)
B(22,1,15,AIR)
B(2,2,15,AIR)
B(3,2,15,AIR)
B(5,2,15,AIR)
B(6,2,15,AIR)
B(10,2,15,AIR)
B(11,2,15,AIR)
B(12,2,15,AIR)
B(13,2,15,AIR)
B(14,2,15,AIR)
B(18,2,15,AIR)
B(19,2,15,AIR)
B(21,2,15,AIR)
B(22,2,15,AIR)
B(2,3,15,AIR)
B(3,3,15,AIR)
B(4,3,15,AIR)
B(5,3,15,AIR)
B(6,3,15,AIR)
B(10,3,15,AIR)
B(11,3,15,AIR)
B(12,3,15,AIR)
B(13,3,15,AIR)
B(14,3,15,AIR)
B(18,3,15,AIR)
B(19,3,15,AIR)
B(20,3,15,AIR)
B(21,3,15,AIR)
B(22,3,15,AIR)
B(2,4,15,AIR)
B(3,4,15,AIR)
B(4,4,15,AIR)
B(5,4,15,AIR)
B(6,4,15,AIR)
B(10,4,15,AIR)
B(11,4,15,AIR)
B(12,4,15,AIR)
B(13,4,15,AIR)
B(14,4,15,AIR)
B(18,4,15,AIR)
B(19,4,15,AIR)
B(20,4,15,AIR)
B(21,4,15,AIR)
B(22,4,15,AIR)
B(2,5,15,AIR)
B(3,5,15,AIR)
B(4,5,15,AIR)
B(5,5,15,AIR)
B(6,5,15,AIR)
B(10,5,15,AIR)
B(11,5,15,AIR)
B(12,5,15,AIR)
B(13,5,15,AIR)
B(14,5,15,AIR)
B(18,5,15,AIR)
B(19,5,15,AIR)
B(20,5,15,AIR)
B(21,5,15,AIR)
B(22,5,15,AIR)
B(2,6,15,STONE_BRICK_STAIRS:5)
B(3,6,15,AIR)
B(4,6,15,AIR)
B(5,6,15,AIR)
B(6,6,15,STONE_BRICK_STAIRS:4)
B(10,6,15,STONE_BRICK_STAIRS:5)
B(11,6,15,AIR)
B(12,6,15,AIR)
B(13,6,15,AIR)
B(14,6,15,STONE_BRICK_STAIRS:4)
B(18,6,15,STONE_BRICK_STAIRS:5)
B(19,6,15,AIR)
B(20,6,15,AIR)
B(21,6,15,AIR)
B(22,6,15,STONE_BRICK_STAIRS:4)
B(12,1,16,AIR)
B(12,2,16,AIR)
B(12,3,16,AIR)
B(10,1,17,AIR)
B(11,1,17,AIR)
B(12,1,17,AIR)
B(13,1,17,AIR)
B(14,1,17,AIR)
B(10,2,17,AIR)
B(11,2,17,AIR)
B(12,2,17,AIR)
B(13,2,17,AIR)
B(14,2,17,AIR)
B(10,3,17,AIR)
B(11,3,17,AIR)
B(12,3,17,AIR)
B(13,3,17,AIR)
B(14,3,17,AIR)
B(10,4,17,AIR)
B(11,4,17,AIR)
B(12,4,17,AIR)
B(13,4,17,AIR)
B(14,4,17,AIR)
B(10,5,17,AIR)
B(11,5,17,AIR)
B(12,5,17,AIR)
B(13,5,17,AIR)
B(14,5,17,AIR)
B(10,6,17,STONE_BRICK_STAIRS:5)
B(11,6,17,AIR)
B(12,6,17,AIR)
B(13,6,17,AIR)
B(14,6,17,STONE_BRICK_STAIRS:4)
B(9,1,18,AIR)
B(10,1,18,AIR)
B(11,1,18,AIR)
B(12,1,18,AIR)
B(13,1,18,AIR)
B(14,1,18,AIR)
B(15,1,18,AIR)
B(9,2,18,AIR)
B(10,2,18,AIR)
B(11,2,18,AIR)
B(12,2,18,AIR)
B(13,2,18,AIR)
B(14,2,18,AIR)
B(15,2,18,AIR)
B(9,3,18,AIR)
B(10,3,18,AIR)
B(11,3,18,AIR)
B(12,3,18,AIR)
B(13,3,18,AIR)
B(14,3,18,AIR)
B(15,3,18,AIR)
B(9,4,18,AIR)
B(10,4,18,AIR)
B(11,4,18,AIR)
B(12,4,18,AIR)
B(13,4,18,AIR)
B(14,4,18,AIR)
B(15,4,18,AIR)
B(9,5,18,AIR)
B(10,5,18,AIR)
B(11,5,18,AIR)
B(12,5,18,AIR)
B(13,5,18,AIR)
B(14,5,18,AIR)
B(15,5,18,AIR)
B(9,6,18,STONE_BRICK_STAIRS:7)
B(10,6,18,AIR)
B(11,6,18,AIR)
B(12,6,18,AIR)
B(13,6,18,AIR)
B(14,6,18,AIR)
B(15,6,18,STONE_BRICK_STAIRS:7)
B(10,7,18,AIR)
B(11,7,18,AIR)
B(12,7,18,AIR)
B(13,7,18,AIR)
B(14,7,18,AIR)
B(9,1,19,AIR)
B(10,1,19,AIR)
B(11,1,19,AIR)
B(12,1,19,TALLGRASS:1)
B(13,1,19,TALLGRASS:1)
B(14,1,19,AIR)
B(15,1,19,AIR)
B(9,2,19,AIR)
B(10,2,19,AIR)
B(11,2,19,AIR)
B(12,2,19,AIR)
B(13,2,19,AIR)
B(14,2,19,AIR)
B(15,2,19,AIR)
B(9,3,19,AIR)
B(10,3,19,AIR)
B(11,3,19,AIR)
B(12,3,19,AIR)
B(13,3,19,AIR)
B(14,3,19,AIR)
B(15,3,19,AIR)
B(9,4,19,AIR)
B(10,4,19,AIR)
B(11,4,19,AIR)
B(12,4,19,AIR)
B(13,4,19,AIR)
B(14,4,19,AIR)
B(15,4,19,AIR)
B(9,5,19,AIR)
B(10,5,19,AIR)
B(11,5,19,AIR)
B(12,5,19,AIR)
B(13,5,19,AIR)
B(14,5,19,AIR)
B(15,5,19,AIR)
B(9,6,19,AIR)
B(10,6,19,AIR)
B(11,6,19,AIR)
B(12,6,19,AIR)
B(13,6,19,AIR)
B(14,6,19,AIR)
B(15,6,19,AIR)
B(10,7,19,AIR)
B(11,7,19,AIR)
B(12,7,19,AIR)
B(13,7,19,AIR)
B(14,7,19,AIR)
B(11,8,19,AIR)
B(12,8,19,AIR)
B(13,8,19,AIR)
B(5,1,20,AIR)
B(6,1,20,AIR)
B(7,1,20,AIR)
B(8,1,20,AIR)
B(9,1,20,AIR)
B(10,1,20,AIR)
B(11,1,20,TALLGRASS:1)
B(13,1,20,AIR)
B(14,1,20,AIR)
B(15,1,20,AIR)
B(16,1,20,AIR)
B(17,1,20,AIR)
B(18,1,20,AIR)
B(19,1,20,AIR)
B(5,2,20,AIR)
B(6,2,20,AIR)
B(7,2,20,AIR)
B(8,2,20,AIR)
B(9,2,20,AIR)
B(10,2,20,AIR)
B(11,2,20,AIR)
B(12,2,20,AIR)
B(13,2,20,AIR)
B(14,2,20,AIR)
B(15,2,20,AIR)
B(16,2,20,AIR)
B(17,2,20,AIR)
B(18,2,20,AIR)
B(19,2,20,AIR)
B(5,3,20,AIR)
B(6,3,20,AIR)
B(7,3,20,AIR)
B(8,3,20,AIR)
B(9,3,20,AIR)
B(10,3,20,AIR)
B(11,3,20,AIR)
B(12,3,20,AIR)
B(13,3,20,AIR)
B(14,3,20,AIR)
B(15,3,20,AIR)
B(16,3,20,AIR)
B(17,3,20,AIR)
B(18,3,20,AIR)
B(19,3,20,AIR)
B(9,4,20,AIR)
B(10,4,20,AIR)
B(11,4,20,AIR)
B(12,4,20,AIR)
B(13,4,20,AIR)
B(14,4,20,AIR)
B(15,4,20,AIR)
B(9,5,20,AIR)
B(10,5,20,AIR)
B(11,5,20,AIR)
B(12,5,20,AIR)
B(13,5,20,AIR)
B(14,5,20,AIR)
B(15,5,20,AIR)
B(9,6,20,AIR)
B(10,6,20,AIR)
B(11,6,20,AIR)
B(12,6,20,AIR)
B(13,6,20,AIR)
B(14,6,20,AIR)
B(15,6,20,AIR)
B(10,7,20,AIR)
B(11,7,20,AIR)
B(12,7,20,AIR)
B(13,7,20,AIR)
B(14,7,20,AIR)
B(11,8,20,AIR)
B(12,8,20,AIR)
B(13,8,20,AIR)
B(9,1,21,AIR)
B(10,1,21,AIR)
B(11,1,21,TALLGRASS:2)
B(12,1,21,TALLGRASS:2)
B(13,1,21,TALLGRASS:1)
B(14,1,21,AIR)
B(15,1,21,AIR)
B(9,2,21,AIR)
B(10,2,21,AIR)
B(11,2,21,AIR)
B(12,2,21,AIR)
B(13,2,21,AIR)
B(14,2,21,AIR)
B(15,2,21,AIR)
B(9,3,21,AIR)
B(10,3,21,AIR)
B(11,3,21,AIR)
B(12,3,21,AIR)
B(13,3,21,AIR)
B(14,3,21,AIR)
B(15,3,21,AIR)
B(9,4,21,AIR)
B(10,4,21,AIR)
B(11,4,21,AIR)
B(12,4,21,AIR)
B(13,4,21,AIR)
B(14,4,21,AIR)
B(15,4,21,AIR)
B(9,5,21,AIR)
B(10,5,21,AIR)
B(11,5,21,AIR)
B(12,5,21,AIR)
B(13,5,21,AIR)
B(14,5,21,AIR)
B(15,5,21,AIR)
B(9,6,21,AIR)
B(10,6,21,AIR)
B(11,6,21,AIR)
B(12,6,21,AIR)
B(13,6,21,AIR)
B(14,6,21,AIR)
B(15,6,21,AIR)
B(10,7,21,AIR)
B(11,7,21,AIR)
B(12,7,21,AIR)
B(13,7,21,AIR)
B(14,7,21,AIR)
B(11,8,21,AIR)
B(12,8,21,AIR)
B(13,8,21,AIR)
B(9,1,22,AIR)
B(10,1,22,AIR)
B(11,1,22,AIR)
B(12,1,22,AIR)
B(13,1,22,AIR)
B(14,1,22,AIR)
B(15,1,22,AIR)
B(9,2,22,AIR)
B(10,2,22,AIR)
B(11,2,22,AIR)
B(12,2,22,AIR)
B(13,2,22,AIR)
B(14,2,22,AIR)
B(15,2,22,AIR)
B(9,3,22,AIR)
B(10,3,22,AIR)
B(11,3,22,AIR)
B(12,3,22,AIR)
B(13,3,22,AIR)
B(14,3,22,AIR)
B(15,3,22,AIR)
B(9,4,22,AIR)
B(10,4,22,AIR)
B(11,4,22,AIR)
B(12,4,22,AIR)
B(13,4,22,AIR)
B(14,4,22,AIR)
B(15,4,22,AIR)
B(9,5,22,AIR)
B(10,5,22,AIR)
B(11,5,22,AIR)
B(12,5,22,AIR)
B(13,5,22,AIR)
B(14,5,22,AIR)
B(15,5,22,AIR)
B(9,6,22,STONE_BRICK_STAIRS:6)
B(10,6,22,AIR)
B(11,6,22,AIR)
B(12,6,22,AIR)
B(13,6,22,AIR)
B(14,6,22,AIR)
B(15,6,22,STONE_BRICK_STAIRS:6)
B(10,7,22,AIR)
B(11,7,22,AIR)
B(12,7,22,AIR)
B(13,7,22,AIR)
B(14,7,22,AIR)
B(10,1,23,AIR)
B(11,1,23,AIR)
B(13,1,23,AIR)
B(14,1,23,AIR)
B(10,2,23,AIR)
B(11,2,23,AIR)
B(12,2,23,AIR)
B(13,2,23,AIR)
B(14,2,23,AIR)
B(10,3,23,AIR)
B(11,3,23,AIR)
B(12,3,23,AIR)
B(13,3,23,AIR)
B(14,3,23,AIR)
B(10,4,23,AIR)
B(11,4,23,AIR)
B(12,4,23,AIR)
B(13,4,23,AIR)
B(14,4,23,AIR)
B(10,5,23,AIR)
B(11,5,23,AIR)
B(12,5,23,AIR)
B(13,5,23,AIR)
B(14,5,23,AIR)
B(10,6,23,STONE_BRICK_STAIRS:5)
B(11,6,23,AIR)
B(12,6,23,AIR)
B(13,6,23,AIR)
B(14,6,23,STONE_BRICK_STAIRS:4)

B(4,2,9,SKULL:1,../../NBT/Skull/Skeleton8.nbt)
B(20,2,9,SKULL:1,../../NBT/Skull/Skeleton8.nbt)
B(4,2,15,SKULL:1,../../NBT/Skull/Skeleton0.nbt)
B(20,2,15,SKULL:1,../../NBT/Skull/Skeleton0.nbt)

RB(12,1,4,MOB_SPAWNER,../../NBT/Spawners/Zombie.nbt,50,MOB_SPAWNER,../../NBT/Spawners/Skeleton.nbt,50,MOB_SPAWNER,../../NBT/Spawners/Spider.nbt,100)
RB(12,1,20,MOB_SPAWNER,../../NBT/Spawners/Zombie.nbt,50,MOB_SPAWNER,../../NBT/Spawners/Skeleton.nbt,50,MOB_SPAWNER,../../NBT/Spawners/Spider.nbt,100)

B(12,1,1,CHEST:3,../../NBT/Chests/SimpleDungeon.nbt)
B(12,1,23,CHEST:2,../../NBT/Chests/SimpleDungeon.nbt)

# Size (X*Y*Z): 25*9*25

#######################################################################
# +-----------------------------------------------------------------+ #
# |                            BO3 checks                           | #
# +-----------------------------------------------------------------+ #
#######################################################################

# Require a condition at a certain location in order for the BO3 to be spawned.
# BlockCheck(x,y,z,BlockName[,BlockName[,...]]) - one of the blocks must be at the location
# BlockCheckNot(x,y,z,BlockName[,BlockName[,...]]) - all the blocks must not be at the location
# LightCheck(x,y,z,minLightLevel,maxLightLevel) - light must be between min and max (inclusive)

# You can use "Solid" as a BlockName for matching all solid blocks or "All" to match all blocks that aren't air.

# Examples:
#   BlockCheck(0,-1,0,GRASS,DIRT)  Require grass or dirt just below the object
#   BlockCheck(0,-1,0,Solid)       Require any solid block just below the object
#   BlockCheck(0,-1,0,WOOL)        Require any type of wool just below the object
#   BlockCheck(0,-1,0,WOOL:0)      Require white wool just below the object
#   BlockCheckNot(0,0,0,WOOL:0)   Require that there is no white wool below the object
#   LightCheck(0,0,0,0,1)          Require almost complete darkness just below the object

# Ensure the ceiling is sufficiently covered in solid blocks.
BlockCheck(0,9,0,Solid)
BlockCheck(0,9,25,Solid)
BlockCheck(25,9,0,Solid)
BlockCheck(25,9,25,Solid)

#######################################################################
# +-----------------------------------------------------------------+ #
# |                             Branches                            | #
# +-----------------------------------------------------------------+ #
#######################################################################

# Branches are objects that will spawn when this object spawns when it is used in
# the CustomStructure resource. Branches can also have branches, making complex
# structures possible. See the wiki for more details.

# Regular Branches spawn each branch with an independent chance of spawning.
# Branch(x,y,z,branchName,rotation,chance[,anotherBranchName,rotation,chance[,...]][IndividualChance])
# branchName - name of the object to spawn.
# rotation - NORTH, SOUTH, EAST or WEST.
# IndividualChance - The chance each branch has to spawn, assumed to be 100 when left blank

# Weighted Branches spawn branches with a dependent chance of spawning.
# WBR(x,y,z,branchName,rotation,chance[,anotherBranchName,rotation,chance[,...]][MaxChanceOutOf])
# MaxChanceOutOf - The chance all branches have to spawn out of, assumed to be 100 when left blank
