
#######################################################################
# +-----------------------------------------------------------------+ #
# |                            BO3 object                           | #
# +-----------------------------------------------------------------+ #
#######################################################################

# This is the config file of a custom object.
# If you add this object correctly to your BiomeConfigs, it will spawn in the world.

# This is the creator of this BO3 object
# See: https://imgur.com/a/JanPA
Author: Arcensoth, designed by McNoodlor

# A short description of this BO3 object
Description: No description given

# The BO3 version, don't change this! It can be used by external applications to do a version check.
Version: 3

# The settings mode, WriteAll, WriteWithoutComments or WriteDisable. See WorldConfig.
SettingsMode: WriteDisable


#######################################################################
# +-----------------------------------------------------------------+ #
# |                          Main settings                          | #
# +-----------------------------------------------------------------+ #
#######################################################################

# This needs to be set to true to spawn the object in the Tree and Sapling resources.
Tree: false

# The frequency of the BO3 from 1 to 200. Tries this many times to spawn this BO3 when using the CustomObject(...) resource.
# Ignored by Tree(..), Sapling(..) and CustomStructure(..)
Frequency: 1

# The rarity of the BO3 from 0 to 100. Each spawn attempt has rarity% chance to succeed when using the CustomObject(...) resource.
# Ignored by Tree(..), Sapling(..) and CustomStructure(..)
Rarity: 1.0

# If you set this to true, the BO3 will be placed with a random rotation.
RotateRandomly: false

# The spawn height of the BO3 - randomY, highestBlock or highestSolidBlock.
SpawnHeight: randomY

# The height limits for the BO3.
MinHeight: 0

MaxHeight: 255

# Objects can have other objects attacthed to it: branches. Branches can also
# have branches attached to it, which can also have branches, etc. This is the
# maximum branch depth for this objects.
MaxBranchDepth: 10

# When spawned with the UseWorld keyword, this BO3 should NOT spawn in the following biomes.
# If you writer.write the BO3 name directly in the BiomeConfigs, this will be ignored.
ExcludedBiomes: All


#######################################################################
# +-----------------------------------------------------------------+ #
# |                      Source block settings                      | #
# +-----------------------------------------------------------------+ #
#######################################################################

# The B(s) the BO3 should spawn in.
SourceBlocks: STONE,STONE:1,STONE:3,STONE:5,COBBLESTONE,MOSSY_COBBLESTONE,SANDSTONE,HARD_CLAY,STAINED_CLAY,PRISMARINE,DIRT,DIRT:1,GRASS,SAND,GRAVEL,CLAY,OBSIDIAN,COAL_ORE,IRON_ORE,GOLD_ORE,REDSTONE_ORE,DIAMOND_ORE,LAPIS_ORE,EMERALD_ORE,STATIONARY_WATER,STATIONARY_LAVA

# The maximum percentage of the BO3 that can be outside the SourceBlock.
# The BO3 won't be placed on a location with more blocks outside the SourceBlock than this percentage.
MaxPercentageOutsideSourceBlock: 45

# What to do when a block is about to be placed outside the SourceBlock? (dontPlace, placeAnyway)
OutsideSourceBlock: dontPlace


#######################################################################
# +-----------------------------------------------------------------+ #
# |                              Blocks                             | #
# +-----------------------------------------------------------------+ #
#######################################################################

# All the blocks used in the BO3 are listed here. Possible blocks:
# B(x,y,z,id[.data][,nbtfile.nbt)
# RB(x,y,z,id[:data][,nbtfile.nbt],chance[,id[:data][,nbtfile.nbt],chance[,...]])
# So RB(0,0,0,CHEST,chest.nbt,50,CHEST,anotherchest.nbt,100) will spawn a chest at
# the BO3 origin, and give it a 50% chance to have the contents of chest.nbt, or, if that
# fails, a 100% percent chance to have the contents of anotherchest.nbt.
B(8,4,0,STONEBRICK:2)
B(9,4,0,STONEBRICK)
B(10,4,0,STONEBRICK:1)
B(11,4,0,STONEBRICK:1)
B(12,4,0,STONEBRICK:1)
B(13,4,0,STONEBRICK:2)
B(14,4,0,STONEBRICK:2)
B(15,4,0,STONEBRICK:1)
B(16,4,0,STONEBRICK:2)
B(8,5,0,STONEBRICK)
B(9,5,0,STONE)
B(10,5,0,MOSSY_COBBLESTONE)
B(11,5,0,EMERALD_ORE)
B(12,5,0,STONE)
B(13,5,0,EMERALD_ORE)
B(14,5,0,STONE)
B(15,5,0,MOSSY_COBBLESTONE)
B(16,5,0,STONEBRICK:2)
B(8,6,0,STONEBRICK:1)
B(9,6,0,MOSSY_COBBLESTONE)
B(10,6,0,MOSSY_COBBLESTONE)
B(11,6,0,MOSSY_COBBLESTONE)
B(12,6,0,STONE)
B(13,6,0,MOSSY_COBBLESTONE)
B(14,6,0,MOSSY_COBBLESTONE)
B(15,6,0,STONE)
B(16,6,0,STONEBRICK)
B(8,7,0,STONEBRICK:2)
B(9,7,0,MOSSY_COBBLESTONE)
B(10,7,0,STONE)
B(11,7,0,STONE)
B(12,7,0,STONE)
B(13,7,0,MOSSY_COBBLESTONE)
B(14,7,0,STONE)
B(15,7,0,STONE)
B(16,7,0,STONEBRICK)
B(8,8,0,STONEBRICK:2)
B(9,8,0,MOSSY_COBBLESTONE)
B(10,8,0,STONE)
B(11,8,0,STONE)
B(12,8,0,MOSSY_COBBLESTONE)
B(13,8,0,MOSSY_COBBLESTONE)
B(14,8,0,EMERALD_ORE)
B(15,8,0,EMERALD_ORE)
B(16,8,0,STONEBRICK)
B(8,9,0,STONEBRICK:1)
B(9,9,0,MOSSY_COBBLESTONE)
B(10,9,0,MOSSY_COBBLESTONE)
B(11,9,0,STONE)
B(12,9,0,STONE)
B(13,9,0,STONE)
B(14,9,0,MOSSY_COBBLESTONE)
B(15,9,0,STONE)
B(16,9,0,STONEBRICK:2)
B(8,10,0,STONEBRICK:2)
B(9,10,0,MOSSY_COBBLESTONE)
B(10,10,0,MOSSY_COBBLESTONE)
B(11,10,0,STONE)
B(12,10,0,MOSSY_COBBLESTONE)
B(13,10,0,STONE)
B(14,10,0,MOSSY_COBBLESTONE)
B(15,10,0,EMERALD_ORE)
B(16,10,0,STONEBRICK:1)
B(8,11,0,STONEBRICK:2)
B(9,11,0,EMERALD_ORE)
B(10,11,0,MOSSY_COBBLESTONE)
B(11,11,0,STONE)
B(12,11,0,STONE)
B(13,11,0,EMERALD_ORE)
B(14,11,0,EMERALD_ORE)
B(15,11,0,MOSSY_COBBLESTONE)
B(16,11,0,STONEBRICK:1)
B(8,12,0,STONEBRICK:2)
B(9,12,0,STONEBRICK:2)
B(10,12,0,STONEBRICK:2)
B(11,12,0,STONEBRICK)
B(12,12,0,STONEBRICK:1)
B(13,12,0,STONEBRICK:1)
B(14,12,0,STONEBRICK)
B(15,12,0,STONEBRICK)
B(16,12,0,STONEBRICK:2)
B(8,4,1,STONEBRICK:2)
B(9,4,1,STONEBRICK:2)
B(10,4,1,STONEBRICK:1)
B(11,4,1,STONEBRICK:1)
B(12,4,1,STONEBRICK:2)
B(13,4,1,STONEBRICK)
B(14,4,1,STONEBRICK)
B(15,4,1,STONEBRICK:1)
B(16,4,1,STONEBRICK:2)
B(8,5,1,STONE)
B(9,5,1,MOSSY_COBBLESTONE)
B(15,5,1,STONE)
B(16,5,1,MOSSY_COBBLESTONE)
B(8,6,1,STONE)
B(9,6,1,MOSSY_COBBLESTONE)
B(15,6,1,STONE)
B(16,6,1,MOSSY_COBBLESTONE)
B(8,7,1,MOSSY_COBBLESTONE)
B(9,7,1,EMERALD_ORE)
B(15,7,1,MOSSY_COBBLESTONE)
B(16,7,1,STONE)
B(8,8,1,STONE)
B(9,8,1,STONEBRICK:1)
B(15,8,1,STONEBRICK)
B(16,8,1,STONE)
B(8,9,1,EMERALD_ORE)
B(9,9,1,STONEBRICK:2)
B(15,9,1,STONEBRICK:1)
B(16,9,1,STONE)
B(8,10,1,MOSSY_COBBLESTONE)
B(9,10,1,STONEBRICK)
B(15,10,1,STONEBRICK:2)
B(16,10,1,EMERALD_ORE)
B(8,11,1,MOSSY_COBBLESTONE)
B(9,11,1,STONEBRICK:1)
B(10,11,1,STONEBRICK:2)
B(11,11,1,STONEBRICK:2)
B(12,11,1,STONEBRICK:1)
B(13,11,1,STONEBRICK)
B(14,11,1,STONEBRICK:2)
B(15,11,1,STONEBRICK)
B(16,11,1,MOSSY_COBBLESTONE)
B(8,12,1,STONEBRICK:1)
B(9,12,1,STONE)
B(10,12,1,MOSSY_COBBLESTONE)
B(11,12,1,STONE)
B(12,12,1,STONE)
B(13,12,1,STONE)
B(14,12,1,STONE)
B(15,12,1,STONE)
B(16,12,1,STONEBRICK)
B(8,4,2,STONEBRICK:2)
B(9,4,2,STONEBRICK:2)
B(10,4,2,STONEBRICK)
B(11,4,2,STONEBRICK:2)
B(12,4,2,STONEBRICK)
B(13,4,2,STONEBRICK:2)
B(14,4,2,STONEBRICK:2)
B(15,4,2,STONEBRICK:1)
B(16,4,2,STONEBRICK:1)
B(8,5,2,MOSSY_COBBLESTONE)
B(16,5,2,MOSSY_COBBLESTONE)
B(8,6,2,MOSSY_COBBLESTONE)
B(16,6,2,STONE)
B(8,7,2,MOSSY_COBBLESTONE)
B(16,7,2,STONE)
B(8,8,2,MOSSY_COBBLESTONE)
B(16,8,2,MOSSY_COBBLESTONE)
B(8,9,2,STONE)
B(16,9,2,MOSSY_COBBLESTONE)
B(8,10,2,MOSSY_COBBLESTONE)
B(16,10,2,MOSSY_COBBLESTONE)
B(8,11,2,STONE)
B(9,11,2,STONEBRICK:1)
B(15,11,2,STONEBRICK)
B(16,11,2,MOSSY_COBBLESTONE)
B(8,12,2,STONEBRICK)
B(9,12,2,STONE)
B(10,12,2,STONEBRICK:1)
B(11,12,2,STONEBRICK)
B(12,12,2,STONEBRICK)
B(13,12,2,STONEBRICK)
B(14,12,2,STONEBRICK:2)
B(15,12,2,STONE)
B(16,12,2,STONEBRICK)
B(3,2,3,STONEBRICK:2)
B(4,2,3,STONEBRICK:1)
B(5,2,3,STONEBRICK)
B(3,3,3,STONEBRICK:2)
B(4,3,3,STONEBRICK:1)
B(5,3,3,STONEBRICK:1)
B(6,3,3,STONEBRICK:1)
B(7,3,3,STONEBRICK:1)
B(3,4,3,STONEBRICK)
B(4,4,3,STONEBRICK:1)
B(5,4,3,STONEBRICK:2)
B(6,4,3,STONEBRICK)
B(7,4,3,STONEBRICK:2)
B(8,4,3,STONEBRICK:2)
B(9,4,3,STONEBRICK:1)
B(10,4,3,STONEBRICK)
B(11,4,3,GRASS)
B(12,4,3,DIRT:1)
B(13,4,3,DIRT:1)
B(14,4,3,STONEBRICK)
B(15,4,3,STONEBRICK:2)
B(16,4,3,STONEBRICK)
B(3,5,3,STONEBRICK:2)
B(4,5,3,STONEBRICK)
B(5,5,3,STONEBRICK)
B(6,5,3,STONEBRICK)
B(7,5,3,STONEBRICK:1)
B(8,5,3,STONEBRICK:2)
B(16,5,3,MOSSY_COBBLESTONE)
B(3,6,3,STONEBRICK:1)
B(4,6,3,STONEBRICK:1)
B(5,6,3,STONEBRICK:2)
B(6,6,3,STONEBRICK)
B(7,6,3,STONEBRICK:2)
B(8,6,3,STONEBRICK)
B(16,6,3,STONE)
B(5,7,3,STONEBRICK:2)
B(6,7,3,STONEBRICK)
B(7,7,3,STONEBRICK:1)
B(8,7,3,STONEBRICK:2)
B(16,7,3,STONE)
B(7,8,3,STONEBRICK)
B(8,8,3,STONEBRICK:1)
B(16,8,3,STONE)
B(8,9,3,MOSSY_COBBLESTONE)
B(16,9,3,STONE)
B(8,10,3,MOSSY_COBBLESTONE)
B(16,10,3,STONE)
B(8,11,3,EMERALD_ORE)
B(9,11,3,STONEBRICK:2)
B(15,11,3,STONEBRICK)
B(16,11,3,STONE)
B(8,12,3,STONEBRICK:2)
B(9,12,3,STONE)
B(10,12,3,STONEBRICK:1)
B(14,12,3,STONEBRICK)
B(15,12,3,EMERALD_ORE)
B(16,12,3,STONEBRICK:1)
B(3,2,4,STONEBRICK:2)
B(4,2,4,STONEBRICK:2)
B(5,2,4,STONEBRICK:1)
B(3,3,4,STONEBRICK)
B(6,3,4,STONEBRICK:2)
B(7,3,4,STONEBRICK:2)
B(3,4,4,STONEBRICK:2)
B(8,4,4,STONEBRICK)
B(9,4,4,STONEBRICK:1)
B(10,4,4,STONEBRICK:1)
B(11,4,4,GRASS)
B(12,4,4,DIRT:1)
B(13,4,4,DIRT:1)
B(14,4,4,STONEBRICK)
B(15,4,4,STONEBRICK:2)
B(16,4,4,STONEBRICK)
B(3,5,4,STONEBRICK:1)
B(16,5,4,EMERALD_ORE)
B(3,6,4,STONEBRICK:1)
B(4,6,4,STONEBRICK:2)
B(16,6,4,MOSSY_COBBLESTONE)
B(5,7,4,STONEBRICK)
B(6,7,4,STONEBRICK:2)
B(16,7,4,MOSSY_COBBLESTONE)
B(7,8,4,STONEBRICK)
B(8,8,4,STONEBRICK:1)
B(16,8,4,MOSSY_COBBLESTONE)
B(8,9,4,MOSSY_COBBLESTONE)
B(16,9,4,EMERALD_ORE)
B(8,10,4,MOSSY_COBBLESTONE)
B(16,10,4,MOSSY_COBBLESTONE)
B(8,11,4,STONE)
B(9,11,4,STONEBRICK:1)
B(15,11,4,STONEBRICK:2)
B(16,11,4,STONE)
B(8,12,4,STONEBRICK)
B(9,12,4,STONE)
B(10,12,4,STONEBRICK:1)
B(14,12,4,STONEBRICK)
B(15,12,4,STONE)
B(16,12,4,STONEBRICK)
B(3,1,5,STONEBRICK:1)
B(4,1,5,STONEBRICK:1)
B(5,1,5,STONEBRICK:2)
B(3,2,5,STONEBRICK:1)
B(5,2,5,STONEBRICK)
B(3,3,5,STONEBRICK:2)
B(5,3,5,STONEBRICK:1)
B(6,3,5,STONEBRICK:2)
B(7,3,5,STONEBRICK:2)
B(3,4,5,STONEBRICK:2)
B(5,4,5,STONEBRICK)
B(6,4,5,STONEBRICK:1)
B(7,4,5,STONEBRICK:1)
B(8,4,5,STONEBRICK)
B(9,4,5,STONEBRICK:2)
B(10,4,5,STONEBRICK:2)
B(11,4,5,GRASS)
B(12,4,5,DIRT:1)
B(13,4,5,DIRT:1)
B(14,4,5,STONEBRICK:2)
B(15,4,5,STONEBRICK:1)
B(16,4,5,STONEBRICK:2)
B(3,5,5,STONEBRICK:2)
B(5,5,5,STONEBRICK:2)
B(6,5,5,STONEBRICK:2)
B(7,5,5,STONEBRICK:2)
B(8,5,5,STONEBRICK:2)
B(16,5,5,STONE)
B(3,6,5,STONEBRICK:2)
B(4,6,5,STONEBRICK:2)
B(5,6,5,STONEBRICK)
B(6,6,5,STONEBRICK:1)
B(7,6,5,STONEBRICK)
B(8,6,5,STONEBRICK)
B(16,6,5,MOSSY_COBBLESTONE)
B(5,7,5,STONEBRICK:1)
B(6,7,5,STONEBRICK)
B(7,7,5,STONEBRICK:1)
B(8,7,5,STONEBRICK)
B(16,7,5,MOSSY_COBBLESTONE)
B(7,8,5,STONEBRICK)
B(8,8,5,STONEBRICK:1)
B(16,8,5,EMERALD_ORE)
B(8,9,5,STONE)
B(16,9,5,EMERALD_ORE)
B(8,10,5,EMERALD_ORE)
B(16,10,5,STONE)
B(8,11,5,MOSSY_COBBLESTONE)
B(9,11,5,STONEBRICK)
B(15,11,5,STONEBRICK)
B(16,11,5,STONE)
B(8,12,5,STONEBRICK)
B(9,12,5,MOSSY_COBBLESTONE)
B(10,12,5,STONEBRICK:2)
B(14,12,5,STONEBRICK:1)
B(15,12,5,STONE)
B(16,12,5,STONEBRICK)
B(3,1,6,STONEBRICK:1)
B(4,1,6,STONEBRICK:1)
B(5,1,6,STONEBRICK:1)
B(3,2,6,STONEBRICK:1)
B(5,2,6,STONEBRICK)
B(3,3,6,STONEBRICK:1)
B(5,3,6,STONEBRICK)
B(3,4,6,STONEBRICK:1)
B(5,4,6,STONEBRICK:2)
B(8,4,6,STONEBRICK:1)
B(9,4,6,STONEBRICK:1)
B(10,4,6,STONEBRICK:1)
B(11,4,6,STONEBRICK:1)
B(12,4,6,STONEBRICK:2)
B(13,4,6,STONEBRICK)
B(14,4,6,STONEBRICK:2)
B(15,4,6,STONEBRICK:2)
B(16,4,6,STONEBRICK:1)
B(3,5,6,STONEBRICK:2)
B(4,5,6,STONEBRICK:1)
B(5,5,6,STONEBRICK)
B(8,5,6,STONE)
B(16,5,6,STONE)
B(8,6,6,STONE)
B(16,6,6,EMERALD_ORE)
B(8,7,6,MOSSY_COBBLESTONE)
B(16,7,6,STONE)
B(8,8,6,MOSSY_COBBLESTONE)
B(16,8,6,STONE)
B(8,9,6,MOSSY_COBBLESTONE)
B(16,9,6,EMERALD_ORE)
B(8,10,6,MOSSY_COBBLESTONE)
B(16,10,6,MOSSY_COBBLESTONE)
B(8,11,6,EMERALD_ORE)
B(9,11,6,STONEBRICK)
B(15,11,6,STONEBRICK:1)
B(16,11,6,MOSSY_COBBLESTONE)
B(8,12,6,STONEBRICK:1)
B(9,12,6,STONE)
B(10,12,6,STONEBRICK)
B(11,12,6,STONEBRICK:2)
B(12,12,6,STONEBRICK)
B(13,12,6,STONEBRICK:1)
B(14,12,6,STONEBRICK:2)
B(15,12,6,MOSSY_COBBLESTONE)
B(16,12,6,STONEBRICK:2)
B(3,0,7,STONEBRICK:1)
B(4,0,7,STONEBRICK:1)
B(5,0,7,STONEBRICK)
B(3,1,7,STONEBRICK:1)
B(5,1,7,STONEBRICK:2)
B(3,2,7,STONEBRICK:1)
B(5,2,7,STONEBRICK)
B(3,3,7,STONEBRICK)
B(5,3,7,STONEBRICK:2)
B(3,4,7,STONEBRICK:1)
B(5,4,7,STONEBRICK)
B(8,4,7,STONEBRICK:1)
B(9,4,7,STONEBRICK:2)
B(10,4,7,STONEBRICK:2)
B(11,4,7,STONEBRICK:2)
B(12,4,7,STONEBRICK)
B(13,4,7,STONEBRICK:2)
B(14,4,7,STONEBRICK:2)
B(15,4,7,STONEBRICK:1)
B(16,4,7,STONEBRICK)
B(3,5,7,STONEBRICK)
B(4,5,7,STONEBRICK:2)
B(5,5,7,STONEBRICK)
B(8,5,7,STONE)
B(9,5,7,MOSSY_COBBLESTONE)
B(15,5,7,STONE)
B(16,5,7,MOSSY_COBBLESTONE)
B(8,6,7,MOSSY_COBBLESTONE)
B(9,6,7,STONE)
B(15,6,7,STONE)
B(16,6,7,MOSSY_COBBLESTONE)
B(8,7,7,MOSSY_COBBLESTONE)
B(9,7,7,EMERALD_ORE)
B(15,7,7,MOSSY_COBBLESTONE)
B(16,7,7,MOSSY_COBBLESTONE)
B(8,8,7,STONE)
B(9,8,7,STONEBRICK)
B(15,8,7,STONEBRICK:2)
B(16,8,7,MOSSY_COBBLESTONE)
B(8,9,7,EMERALD_ORE)
B(9,9,7,STONEBRICK:1)
B(15,9,7,STONEBRICK)
B(16,9,7,MOSSY_COBBLESTONE)
B(8,10,7,MOSSY_COBBLESTONE)
B(9,10,7,STONEBRICK:1)
B(15,10,7,STONEBRICK:1)
B(16,10,7,MOSSY_COBBLESTONE)
B(8,11,7,STONE)
B(9,11,7,STONEBRICK:2)
B(10,11,7,STONEBRICK)
B(11,11,7,STONEBRICK)
B(12,11,7,STONEBRICK:1)
B(13,11,7,STONEBRICK)
B(14,11,7,STONEBRICK:1)
B(15,11,7,STONEBRICK)
B(16,11,7,STONE)
B(8,12,7,STONEBRICK)
B(9,12,7,MOSSY_COBBLESTONE)
B(10,12,7,MOSSY_COBBLESTONE)
B(11,12,7,MOSSY_COBBLESTONE)
B(12,12,7,STONE)
B(13,12,7,STONE)
B(14,12,7,STONE)
B(15,12,7,STONE)
B(16,12,7,STONEBRICK:1)
B(0,0,8,STONEBRICK)
B(1,0,8,STONEBRICK:2)
B(2,0,8,STONEBRICK)
B(3,0,8,STONEBRICK)
B(4,0,8,STONEBRICK:2)
B(5,0,8,STONEBRICK:1)
B(6,0,8,STONEBRICK:2)
B(7,0,8,STONEBRICK:1)
B(8,0,8,STONEBRICK)
B(0,1,8,STONEBRICK)
B(1,1,8,MOSSY_COBBLESTONE)
B(2,1,8,MOSSY_COBBLESTONE)
B(3,1,8,STONEBRICK:2)
B(5,1,8,STONEBRICK:2)
B(6,1,8,MOSSY_COBBLESTONE)
B(7,1,8,EMERALD_ORE)
B(8,1,8,STONEBRICK:2)
B(0,2,8,STONEBRICK:1)
B(1,2,8,STONE)
B(2,2,8,EMERALD_ORE)
B(3,2,8,STONEBRICK:2)
B(5,2,8,STONEBRICK:2)
B(6,2,8,MOSSY_COBBLESTONE)
B(7,2,8,MOSSY_COBBLESTONE)
B(8,2,8,STONEBRICK:1)
B(0,3,8,STONEBRICK:1)
B(1,3,8,MOSSY_COBBLESTONE)
B(2,3,8,STONE)
B(3,3,8,STONEBRICK:1)
B(5,3,8,STONEBRICK:1)
B(6,3,8,STONE)
B(7,3,8,STONE)
B(8,3,8,STONEBRICK)
B(0,4,8,STONEBRICK:2)
B(1,4,8,STONE)
B(2,4,8,STONE)
B(3,4,8,STONEBRICK:1)
B(4,4,8,STONEBRICK:1)
B(5,4,8,STONEBRICK)
B(6,4,8,MOSSY_COBBLESTONE)
B(7,4,8,STONE)
B(8,4,8,STONEBRICK:2)
B(9,4,8,STONEBRICK:2)
B(10,4,8,STONEBRICK:1)
B(11,4,8,STONEBRICK)
B(12,4,8,STONEBRICK:1)
B(13,4,8,STONEBRICK:1)
B(14,4,8,STONEBRICK:1)
B(15,4,8,STONEBRICK)
B(16,4,8,STONEBRICK)
B(0,5,8,STONEBRICK:2)
B(1,5,8,STONE)
B(2,5,8,MOSSY_COBBLESTONE)
B(3,5,8,EMERALD_ORE)
B(4,5,8,MOSSY_COBBLESTONE)
B(5,5,8,MOSSY_COBBLESTONE)
B(6,5,8,MOSSY_COBBLESTONE)
B(7,5,8,MOSSY_COBBLESTONE)
B(8,5,8,STONEBRICK:2)
B(9,5,8,MOSSY_COBBLESTONE)
B(10,5,8,MOSSY_COBBLESTONE)
B(11,5,8,STONEBRICK)
B(13,5,8,STONEBRICK:2)
B(14,5,8,EMERALD_ORE)
B(15,5,8,MOSSY_COBBLESTONE)
B(16,5,8,STONEBRICK:1)
B(0,6,8,STONEBRICK:2)
B(1,6,8,STONE)
B(2,6,8,MOSSY_COBBLESTONE)
B(3,6,8,EMERALD_ORE)
B(4,6,8,STONE)
B(5,6,8,MOSSY_COBBLESTONE)
B(6,6,8,STONE)
B(7,6,8,EMERALD_ORE)
B(8,6,8,STONEBRICK)
B(9,6,8,STONE)
B(10,6,8,EMERALD_ORE)
B(11,6,8,STONEBRICK:1)
B(13,6,8,STONEBRICK)
B(14,6,8,MOSSY_COBBLESTONE)
B(15,6,8,STONE)
B(16,6,8,STONEBRICK:1)
B(0,7,8,STONEBRICK:2)
B(1,7,8,MOSSY_COBBLESTONE)
B(2,7,8,EMERALD_ORE)
B(3,7,8,MOSSY_COBBLESTONE)
B(4,7,8,EMERALD_ORE)
B(5,7,8,STONE)
B(6,7,8,MOSSY_COBBLESTONE)
B(7,7,8,STONE)
B(8,7,8,STONEBRICK:1)
B(9,7,8,STONE)
B(10,7,8,STONE)
B(11,7,8,STONEBRICK:1)
B(13,7,8,STONEBRICK:1)
B(14,7,8,STONE)
B(15,7,8,STONE)
B(16,7,8,STONEBRICK:1)
B(0,8,8,STONEBRICK)
B(1,8,8,STONEBRICK)
B(2,8,8,STONEBRICK:1)
B(3,8,8,STONEBRICK)
B(4,8,8,STONEBRICK)
B(5,8,8,STONEBRICK:1)
B(6,8,8,STONEBRICK:2)
B(7,8,8,STONEBRICK:1)
B(8,8,8,STONEBRICK)
B(9,8,8,STONE)
B(10,8,8,MOSSY_COBBLESTONE)
B(11,8,8,STONEBRICK:1)
B(12,8,8,STONEBRICK:2)
B(13,8,8,STONEBRICK:1)
B(14,8,8,STONE)
B(15,8,8,STONE)
B(16,8,8,STONEBRICK)
B(0,9,8,STONEBRICK:2)
B(1,9,8,MOSSY_COBBLESTONE)
B(2,9,8,MOSSY_COBBLESTONE)
B(3,9,8,MOSSY_COBBLESTONE)
B(4,9,8,MOSSY_COBBLESTONE)
B(5,9,8,STONE)
B(6,9,8,STONE)
B(7,9,8,MOSSY_COBBLESTONE)
B(8,9,8,STONEBRICK:2)
B(9,9,8,MOSSY_COBBLESTONE)
B(10,9,8,MOSSY_COBBLESTONE)
B(11,9,8,MOSSY_COBBLESTONE)
B(12,9,8,MOSSY_COBBLESTONE)
B(13,9,8,STONE)
B(14,9,8,EMERALD_ORE)
B(15,9,8,STONE)
B(16,9,8,STONEBRICK:1)
B(0,10,8,STONEBRICK:1)
B(1,10,8,MOSSY_COBBLESTONE)
B(2,10,8,MOSSY_COBBLESTONE)
B(3,10,8,MOSSY_COBBLESTONE)
B(4,10,8,MOSSY_COBBLESTONE)
B(5,10,8,EMERALD_ORE)
B(6,10,8,MOSSY_COBBLESTONE)
B(7,10,8,STONE)
B(8,10,8,STONEBRICK)
B(9,10,8,STONE)
B(10,10,8,MOSSY_COBBLESTONE)
B(11,10,8,STONE)
B(12,10,8,MOSSY_COBBLESTONE)
B(13,10,8,STONE)
B(14,10,8,STONE)
B(15,10,8,MOSSY_COBBLESTONE)
B(16,10,8,STONEBRICK:2)
B(0,11,8,STONEBRICK:2)
B(1,11,8,MOSSY_COBBLESTONE)
B(2,11,8,EMERALD_ORE)
B(3,11,8,EMERALD_ORE)
B(4,11,8,STONE)
B(5,11,8,STONE)
B(6,11,8,STONE)
B(7,11,8,STONE)
B(8,11,8,STONEBRICK:1)
B(9,11,8,EMERALD_ORE)
B(10,11,8,MOSSY_COBBLESTONE)
B(11,11,8,STONE)
B(12,11,8,STONE)
B(13,11,8,STONE)
B(14,11,8,MOSSY_COBBLESTONE)
B(15,11,8,MOSSY_COBBLESTONE)
B(16,11,8,STONEBRICK)
B(0,12,8,STONEBRICK:1)
B(1,12,8,STONE)
B(2,12,8,STONE)
B(3,12,8,STONE)
B(4,12,8,EMERALD_ORE)
B(5,12,8,MOSSY_COBBLESTONE)
B(6,12,8,MOSSY_COBBLESTONE)
B(7,12,8,STONE)
B(8,12,8,STONEBRICK:1)
B(9,12,8,STONEBRICK)
B(10,12,8,STONEBRICK:2)
B(11,12,8,STONEBRICK)
B(12,12,8,STONEBRICK:2)
B(13,12,8,STONEBRICK:1)
B(14,12,8,STONEBRICK:1)
B(15,12,8,STONEBRICK:2)
B(16,12,8,STONEBRICK:1)
B(0,13,8,STONEBRICK)
B(1,13,8,STONE)
B(2,13,8,STONE)
B(3,13,8,STONE)
B(4,13,8,EMERALD_ORE)
B(5,13,8,MOSSY_COBBLESTONE)
B(6,13,8,EMERALD_ORE)
B(7,13,8,EMERALD_ORE)
B(8,13,8,STONEBRICK:1)
B(0,14,8,STONEBRICK)
B(1,14,8,MOSSY_COBBLESTONE)
B(2,14,8,MOSSY_COBBLESTONE)
B(3,14,8,MOSSY_COBBLESTONE)
B(4,14,8,MOSSY_COBBLESTONE)
B(5,14,8,STONE)
B(6,14,8,STONE)
B(7,14,8,STONE)
B(8,14,8,STONEBRICK:2)
B(0,15,8,STONEBRICK:2)
B(1,15,8,STONE)
B(2,15,8,STONE)
B(3,15,8,STONE)
B(4,15,8,MOSSY_COBBLESTONE)
B(5,15,8,MOSSY_COBBLESTONE)
B(6,15,8,MOSSY_COBBLESTONE)
B(7,15,8,STONE)
B(8,15,8,STONEBRICK)
B(0,16,8,STONEBRICK:1)
B(1,16,8,STONEBRICK)
B(2,16,8,STONEBRICK:1)
B(3,16,8,STONEBRICK)
B(4,16,8,STONEBRICK)
B(5,16,8,STONEBRICK:1)
B(6,16,8,STONEBRICK:1)
B(7,16,8,STONEBRICK:2)
B(8,16,8,STONEBRICK:1)
B(0,0,9,STONEBRICK:2)
B(1,0,9,STONEBRICK:1)
B(2,0,9,STONEBRICK)
B(3,0,9,STONEBRICK:2)
B(4,0,9,STONEBRICK:2)
B(5,0,9,STONEBRICK:2)
B(6,0,9,STONEBRICK:1)
B(7,0,9,STONEBRICK:2)
B(8,0,9,STONEBRICK:2)
B(0,1,9,STONE)
B(1,1,9,STONE)
B(7,1,9,STONE)
B(8,1,9,MOSSY_COBBLESTONE)
B(0,2,9,EMERALD_ORE)
B(1,2,9,EMERALD_ORE)
B(7,2,9,MOSSY_COBBLESTONE)
B(8,2,9,MOSSY_COBBLESTONE)
B(0,3,9,STONE)
B(1,3,9,MOSSY_COBBLESTONE)
B(7,3,9,STONE)
B(8,3,9,STONE)
B(0,4,9,MOSSY_COBBLESTONE)
B(1,4,9,STONEBRICK:1)
B(7,4,9,STONEBRICK:2)
B(8,4,9,MOSSY_COBBLESTONE)
B(11,4,9,STONEBRICK:2)
B(12,4,9,STONEBRICK)
B(13,4,9,STONEBRICK)
B(0,5,9,MOSSY_COBBLESTONE)
B(1,5,9,STONEBRICK:2)
B(7,5,9,STONEBRICK:2)
B(8,5,9,STONE)
B(11,5,9,STONEBRICK:1)
B(13,5,9,STONEBRICK)
B(0,6,9,STONE)
B(1,6,9,STONEBRICK:2)
B(7,6,9,STONEBRICK)
B(8,6,9,MOSSY_COBBLESTONE)
B(11,6,9,STONEBRICK:2)
B(13,6,9,STONEBRICK)
B(0,7,9,MOSSY_COBBLESTONE)
B(1,7,9,STONEBRICK)
B(2,7,9,STONEBRICK:2)
B(3,7,9,STONEBRICK:1)
B(4,7,9,STONEBRICK)
B(5,7,9,STONEBRICK:1)
B(6,7,9,STONEBRICK:1)
B(7,7,9,STONEBRICK)
B(8,7,9,MOSSY_COBBLESTONE)
B(11,7,9,STONEBRICK:1)
B(13,7,9,STONEBRICK)
B(0,8,9,STONEBRICK)
B(1,8,9,STONEBRICK:1)
B(2,8,9,STONEBRICK:2)
B(3,8,9,STONEBRICK:1)
B(4,8,9,STONEBRICK)
B(5,8,9,STONEBRICK:1)
B(6,8,9,STONEBRICK)
B(7,8,9,STONEBRICK:2)
B(8,8,9,STONEBRICK:2)
B(11,8,9,STONEBRICK:1)
B(13,8,9,STONEBRICK:1)
B(0,9,9,STONE)
B(1,9,9,EMERALD_ORE)
B(7,9,9,STONE)
B(8,9,9,MOSSY_COBBLESTONE)
B(11,9,9,STONEBRICK:1)
B(12,9,9,STONEBRICK:2)
B(13,9,9,STONEBRICK:1)
B(0,10,9,STONE)
B(1,10,9,MOSSY_COBBLESTONE)
B(7,10,9,MOSSY_COBBLESTONE)
B(8,10,9,MOSSY_COBBLESTONE)
B(0,11,9,MOSSY_COBBLESTONE)
B(1,11,9,STONE)
B(7,11,9,STONE)
B(8,11,9,MOSSY_COBBLESTONE)
B(0,12,9,STONE)
B(1,12,9,STONEBRICK)
B(7,12,9,STONEBRICK)
B(8,12,9,MOSSY_COBBLESTONE)
B(0,13,9,MOSSY_COBBLESTONE)
B(1,13,9,STONEBRICK:2)
B(7,13,9,STONEBRICK:2)
B(8,13,9,STONE)
B(0,14,9,STONE)
B(1,14,9,STONEBRICK:1)
B(7,14,9,STONEBRICK:2)
B(8,14,9,STONE)
B(0,15,9,STONE)
B(1,15,9,STONEBRICK:1)
B(2,15,9,STONEBRICK)
B(3,15,9,STONEBRICK)
B(4,15,9,STONEBRICK)
B(5,15,9,STONEBRICK:2)
B(6,15,9,STONEBRICK:2)
B(7,15,9,STONEBRICK:2)
B(8,15,9,STONE)
B(0,16,9,STONEBRICK:1)
B(1,16,9,MOSSY_COBBLESTONE)
B(2,16,9,STONE)
B(3,16,9,STONE)
B(4,16,9,STONE)
B(5,16,9,STONE)
B(6,16,9,STONE)
B(7,16,9,MOSSY_COBBLESTONE)
B(8,16,9,STONEBRICK:1)
B(0,0,10,STONEBRICK)
B(1,0,10,STONEBRICK)
B(2,0,10,STONEBRICK:1)
B(3,0,10,STONEBRICK:2)
B(4,0,10,STONEBRICK)
B(5,0,10,STONEBRICK)
B(6,0,10,STONEBRICK:2)
B(7,0,10,STONEBRICK:2)
B(8,0,10,STONEBRICK)
B(0,1,10,STONE)
B(8,1,10,MOSSY_COBBLESTONE)
B(0,2,10,MOSSY_COBBLESTONE)
B(8,2,10,STONE)
B(0,3,10,MOSSY_COBBLESTONE)
B(8,3,10,MOSSY_COBBLESTONE)
B(0,4,10,STONE)
B(8,4,10,STONE)
B(0,5,10,MOSSY_COBBLESTONE)
B(8,5,10,STONE)
B(11,5,10,STONEBRICK)
B(12,5,10,STONEBRICK:2)
B(13,5,10,STONEBRICK:2)
B(0,6,10,MOSSY_COBBLESTONE)
B(8,6,10,MOSSY_COBBLESTONE)
B(11,6,10,STONEBRICK:2)
B(13,6,10,STONEBRICK)
B(0,7,10,MOSSY_COBBLESTONE)
B(1,7,10,STONEBRICK:1)
B(7,7,10,STONEBRICK)
B(8,7,10,STONE)
B(11,7,10,STONEBRICK:2)
B(13,7,10,STONEBRICK)
B(0,8,10,STONEBRICK)
B(1,8,10,STONEBRICK:1)
B(2,8,10,STONEBRICK:2)
B(3,8,10,STONEBRICK)
B(4,8,10,STONEBRICK:1)
B(5,8,10,STONEBRICK:1)
B(6,8,10,STONEBRICK:2)
B(7,8,10,STONEBRICK)
B(8,8,10,STONEBRICK)
B(11,8,10,STONEBRICK)
B(13,8,10,STONEBRICK:1)
B(0,9,10,MOSSY_COBBLESTONE)
B(8,9,10,STONE)
B(11,9,10,STONEBRICK)
B(12,9,10,STONEBRICK:2)
B(13,9,10,STONEBRICK)
B(0,10,10,STONE)
B(8,10,10,MOSSY_COBBLESTONE)
B(0,11,10,STONE)
B(8,11,10,STONE)
B(0,12,10,STONE)
B(8,12,10,MOSSY_COBBLESTONE)
B(0,13,10,STONE)
B(8,13,10,STONE)
B(0,14,10,STONE)
B(8,14,10,STONE)
B(0,15,10,MOSSY_COBBLESTONE)
B(1,15,10,STONEBRICK:1)
B(7,15,10,STONEBRICK)
B(8,15,10,STONE)
B(0,16,10,STONEBRICK:2)
B(1,16,10,EMERALD_ORE)
B(2,16,10,STONEBRICK)
B(3,16,10,STONEBRICK:2)
B(4,16,10,STONEBRICK:1)
B(5,16,10,STONEBRICK:2)
B(6,16,10,STONEBRICK)
B(7,16,10,EMERALD_ORE)
B(8,16,10,STONEBRICK:1)
B(0,0,11,STONEBRICK:2)
B(1,0,11,STONEBRICK:1)
B(2,0,11,STONEBRICK:2)
B(3,0,11,GRASS)
B(4,0,11,DIRT:1)
B(5,0,11,GRASS)
B(6,0,11,STONEBRICK)
B(7,0,11,STONEBRICK:1)
B(8,0,11,STONEBRICK)
B(0,1,11,MOSSY_COBBLESTONE)
B(8,1,11,STONE)
B(0,2,11,STONE)
B(8,2,11,STONE)
B(0,3,11,STONE)
B(8,3,11,STONE)
B(0,4,11,MOSSY_COBBLESTONE)
B(8,4,11,MOSSY_COBBLESTONE)
B(0,5,11,STONE)
B(8,5,11,MOSSY_COBBLESTONE)
B(11,5,11,STONEBRICK:2)
B(12,5,11,STONEBRICK:1)
B(13,5,11,STONEBRICK)
B(0,6,11,STONE)
B(8,6,11,STONE)
B(11,6,11,STONEBRICK:2)
B(13,6,11,STONEBRICK:2)
B(0,7,11,STONE)
B(1,7,11,STONEBRICK:1)
B(7,7,11,STONEBRICK:1)
B(8,7,11,MOSSY_COBBLESTONE)
B(9,7,11,STONEBRICK:2)
B(10,7,11,STONEBRICK:2)
B(11,7,11,STONEBRICK:2)
B(13,7,11,STONEBRICK)
B(0,8,11,STONEBRICK:1)
B(1,8,11,STONEBRICK:2)
B(2,8,11,STONEBRICK:2)
B(6,8,11,STONEBRICK:1)
B(7,8,11,STONEBRICK:2)
B(8,8,11,STONEBRICK:2)
B(9,8,11,STONEBRICK:1)
B(10,8,11,STONEBRICK:1)
B(11,8,11,STONEBRICK:1)
B(13,8,11,STONEBRICK:1)
B(0,9,11,STONEBRICK:1)
B(8,9,11,STONEBRICK)
B(9,9,11,STONEBRICK)
B(10,9,11,STONEBRICK:1)
B(11,9,11,STONEBRICK:1)
B(13,9,11,STONEBRICK:1)
B(0,10,11,STONEBRICK:1)
B(8,10,11,STONEBRICK)
B(9,10,11,STONEBRICK:1)
B(10,10,11,STONEBRICK)
B(11,10,11,STONEBRICK:2)
B(12,10,11,STONEBRICK)
B(13,10,11,STONEBRICK:1)
B(0,11,11,STONEBRICK:1)
B(8,11,11,STONEBRICK:1)
B(9,11,11,STONEBRICK:2)
B(10,11,11,STONEBRICK:1)
B(11,11,11,STONEBRICK)
B(0,12,11,STONEBRICK:1)
B(8,12,11,STONEBRICK:1)
B(9,12,11,STONEBRICK)
B(0,13,11,MOSSY_COBBLESTONE)
B(8,13,11,STONE)
B(0,14,11,STONE)
B(8,14,11,STONE)
B(0,15,11,MOSSY_COBBLESTONE)
B(1,15,11,STONEBRICK:1)
B(7,15,11,STONEBRICK)
B(8,15,11,STONE)
B(0,16,11,STONEBRICK)
B(1,16,11,STONE)
B(2,16,11,STONEBRICK)
B(6,16,11,STONEBRICK:2)
B(7,16,11,STONE)
B(8,16,11,STONEBRICK:1)
B(0,0,12,STONEBRICK:2)
B(1,0,12,STONEBRICK:1)
B(2,0,12,STONEBRICK)
B(3,0,12,DIRT:1)
B(4,0,12,DIRT:1)
B(5,0,12,GRASS)
B(6,0,12,STONEBRICK:2)
B(7,0,12,STONEBRICK:1)
B(8,0,12,STONEBRICK)
B(0,1,12,MOSSY_COBBLESTONE)
B(8,1,12,MOSSY_COBBLESTONE)
B(0,2,12,MOSSY_COBBLESTONE)
B(8,2,12,STONE)
B(0,3,12,STONE)
B(8,3,12,STONE)
B(0,4,12,MOSSY_COBBLESTONE)
B(8,4,12,STONE)
B(0,5,12,EMERALD_ORE)
B(8,5,12,STONE)
B(0,6,12,STONE)
B(8,6,12,EMERALD_ORE)
B(11,6,12,STONEBRICK:1)
B(12,6,12,STONEBRICK)
B(13,6,12,STONEBRICK:2)
B(0,7,12,MOSSY_COBBLESTONE)
B(1,7,12,STONEBRICK:2)
B(7,7,12,STONEBRICK:1)
B(8,7,12,STONE)
B(9,7,12,STONEBRICK:1)
B(10,7,12,STONEBRICK:2)
B(13,7,12,STONEBRICK)
B(0,8,12,STONEBRICK:1)
B(1,8,12,STONEBRICK)
B(2,8,12,STONEBRICK:2)
B(6,8,12,STONEBRICK:1)
B(7,8,12,STONEBRICK:1)
B(8,8,12,STONEBRICK:1)
B(13,8,12,STONEBRICK)
B(13,9,12,STONEBRICK:1)
B(12,10,12,STONEBRICK:1)
B(13,10,12,STONEBRICK:2)
B(10,11,12,STONEBRICK)
B(11,11,12,STONEBRICK)
B(0,12,12,STONEBRICK:2)
B(8,12,12,STONEBRICK:2)
B(9,12,12,STONEBRICK)
B(0,13,12,STONE)
B(8,13,12,STONE)
B(0,14,12,MOSSY_COBBLESTONE)
B(8,14,12,EMERALD_ORE)
B(0,15,12,MOSSY_COBBLESTONE)
B(1,15,12,STONEBRICK)
B(7,15,12,STONEBRICK:1)
B(8,15,12,MOSSY_COBBLESTONE)
B(0,16,12,STONEBRICK:1)
B(1,16,12,EMERALD_ORE)
B(2,16,12,STONEBRICK:2)
B(6,16,12,STONEBRICK)
B(7,16,12,EMERALD_ORE)
B(8,16,12,STONEBRICK:2)
B(0,0,13,STONEBRICK:1)
B(1,0,13,STONEBRICK:1)
B(2,0,13,STONEBRICK:2)
B(3,0,13,DIRT:1)
B(4,0,13,DIRT:1)
B(5,0,13,DIRT:1)
B(6,0,13,STONEBRICK:2)
B(7,0,13,STONEBRICK:1)
B(8,0,13,STONEBRICK:1)
B(0,1,13,STONE)
B(8,1,13,MOSSY_COBBLESTONE)
B(0,2,13,STONE)
B(8,2,13,STONE)
B(0,3,13,MOSSY_COBBLESTONE)
B(8,3,13,STONE)
B(0,4,13,STONE)
B(8,4,13,MOSSY_COBBLESTONE)
B(0,5,13,STONE)
B(8,5,13,MOSSY_COBBLESTONE)
B(0,6,13,STONE)
B(8,6,13,MOSSY_COBBLESTONE)
B(11,6,13,STONEBRICK:1)
B(12,6,13,STONEBRICK)
B(13,6,13,STONEBRICK:2)
B(0,7,13,EMERALD_ORE)
B(1,7,13,STONEBRICK:1)
B(7,7,13,STONEBRICK:1)
B(8,7,13,STONE)
B(9,7,13,STONEBRICK:1)
B(10,7,13,STONEBRICK:1)
B(11,7,13,STONEBRICK:1)
B(12,7,13,STONEBRICK)
B(13,7,13,STONEBRICK:2)
B(0,8,13,STONEBRICK)
B(1,8,13,STONEBRICK)
B(2,8,13,STONEBRICK:1)
B(6,8,13,STONEBRICK)
B(7,8,13,STONEBRICK:2)
B(8,8,13,STONEBRICK:2)
B(9,8,13,STONEBRICK:1)
B(10,8,13,STONEBRICK:1)
B(11,8,13,STONEBRICK)
B(12,8,13,STONEBRICK)
B(13,8,13,STONEBRICK:2)
B(0,9,13,STONEBRICK)
B(8,9,13,STONEBRICK:1)
B(9,9,13,STONEBRICK)
B(10,9,13,STONEBRICK:1)
B(11,9,13,STONEBRICK:1)
B(12,9,13,STONEBRICK:1)
B(13,9,13,STONEBRICK)
B(0,10,13,STONEBRICK:2)
B(8,10,13,STONEBRICK:1)
B(9,10,13,STONEBRICK:2)
B(10,10,13,STONEBRICK:1)
B(11,10,13,STONEBRICK:1)
B(12,10,13,STONEBRICK)
B(13,10,13,STONEBRICK:2)
B(0,11,13,STONEBRICK:2)
B(8,11,13,STONEBRICK)
B(9,11,13,STONEBRICK:1)
B(10,11,13,STONEBRICK)
B(11,11,13,STONEBRICK:2)
B(0,12,13,STONEBRICK:2)
B(8,12,13,STONEBRICK:1)
B(9,12,13,STONEBRICK:2)
B(0,13,13,MOSSY_COBBLESTONE)
B(8,13,13,EMERALD_ORE)
B(0,14,13,MOSSY_COBBLESTONE)
B(8,14,13,STONE)
B(0,15,13,STONE)
B(1,15,13,STONEBRICK)
B(7,15,13,STONEBRICK)
B(8,15,13,EMERALD_ORE)
B(0,16,13,STONEBRICK)
B(1,16,13,STONE)
B(2,16,13,STONEBRICK:1)
B(6,16,13,STONEBRICK:1)
B(7,16,13,STONE)
B(8,16,13,STONEBRICK:2)
B(0,0,14,STONEBRICK)
B(1,0,14,STONEBRICK:1)
B(2,0,14,STONEBRICK:1)
B(3,0,14,STONEBRICK:2)
B(4,0,14,STONEBRICK:1)
B(5,0,14,STONEBRICK:1)
B(6,0,14,STONEBRICK:2)
B(7,0,14,STONEBRICK:2)
B(8,0,14,STONEBRICK)
B(0,1,14,MOSSY_COBBLESTONE)
B(8,1,14,MOSSY_COBBLESTONE)
B(0,2,14,MOSSY_COBBLESTONE)
B(8,2,14,MOSSY_COBBLESTONE)
B(0,3,14,STONE)
B(8,3,14,STONE)
B(0,4,14,STONE)
B(8,4,14,MOSSY_COBBLESTONE)
B(0,5,14,STONE)
B(8,5,14,STONE)
B(0,6,14,MOSSY_COBBLESTONE)
B(8,6,14,EMERALD_ORE)
B(0,7,14,MOSSY_COBBLESTONE)
B(1,7,14,STONEBRICK:2)
B(7,7,14,STONEBRICK:1)
B(8,7,14,MOSSY_COBBLESTONE)
B(0,8,14,STONEBRICK:2)
B(1,8,14,STONEBRICK:1)
B(2,8,14,STONEBRICK:1)
B(3,8,14,STONEBRICK:2)
B(4,8,14,STONEBRICK:1)
B(5,8,14,STONEBRICK:2)
B(6,8,14,STONEBRICK:1)
B(7,8,14,STONEBRICK)
B(8,8,14,STONEBRICK:2)
B(0,9,14,STONE)
B(8,9,14,EMERALD_ORE)
B(0,10,14,STONE)
B(8,10,14,STONE)
B(0,11,14,MOSSY_COBBLESTONE)
B(8,11,14,MOSSY_COBBLESTONE)
B(0,12,14,MOSSY_COBBLESTONE)
B(8,12,14,MOSSY_COBBLESTONE)
B(0,13,14,MOSSY_COBBLESTONE)
B(8,13,14,STONE)
B(0,14,14,STONE)
B(8,14,14,EMERALD_ORE)
B(0,15,14,EMERALD_ORE)
B(1,15,14,STONEBRICK)
B(7,15,14,STONEBRICK:1)
B(8,15,14,STONE)
B(0,16,14,STONEBRICK:1)
B(1,16,14,STONE)
B(2,16,14,STONEBRICK:2)
B(3,16,14,STONEBRICK:1)
B(4,16,14,STONEBRICK:1)
B(5,16,14,STONEBRICK:2)
B(6,16,14,STONEBRICK)
B(7,16,14,MOSSY_COBBLESTONE)
B(8,16,14,STONEBRICK)
B(0,0,15,STONEBRICK)
B(1,0,15,STONEBRICK:1)
B(2,0,15,STONEBRICK)
B(3,0,15,STONEBRICK:1)
B(4,0,15,STONEBRICK:2)
B(5,0,15,STONEBRICK:1)
B(6,0,15,STONEBRICK)
B(7,0,15,STONEBRICK:2)
B(8,0,15,STONEBRICK:2)
B(0,1,15,MOSSY_COBBLESTONE)
B(1,1,15,MOSSY_COBBLESTONE)
B(7,1,15,MOSSY_COBBLESTONE)
B(8,1,15,STONE)
B(0,2,15,MOSSY_COBBLESTONE)
B(1,2,15,STONE)
B(7,2,15,MOSSY_COBBLESTONE)
B(8,2,15,MOSSY_COBBLESTONE)
B(0,3,15,STONE)
B(1,3,15,MOSSY_COBBLESTONE)
B(7,3,15,MOSSY_COBBLESTONE)
B(8,3,15,STONE)
B(0,4,15,MOSSY_COBBLESTONE)
B(1,4,15,STONEBRICK:2)
B(7,4,15,STONEBRICK)
B(8,4,15,EMERALD_ORE)
B(0,5,15,STONE)
B(1,5,15,STONEBRICK:2)
B(7,5,15,STONEBRICK)
B(8,5,15,STONE)
B(0,6,15,STONE)
B(1,6,15,STONEBRICK:1)
B(7,6,15,STONEBRICK:1)
B(8,6,15,STONE)
B(0,7,15,MOSSY_COBBLESTONE)
B(1,7,15,STONEBRICK:2)
B(2,7,15,STONEBRICK:1)
B(3,7,15,STONEBRICK:2)
B(4,7,15,STONEBRICK:2)
B(5,7,15,STONEBRICK:2)
B(6,7,15,STONEBRICK:1)
B(7,7,15,STONEBRICK:1)
B(8,7,15,MOSSY_COBBLESTONE)
B(0,8,15,STONEBRICK)
B(1,8,15,STONEBRICK:2)
B(2,8,15,STONEBRICK:2)
B(3,8,15,STONEBRICK)
B(4,8,15,STONEBRICK:1)
B(5,8,15,STONEBRICK)
B(6,8,15,STONEBRICK)
B(7,8,15,STONEBRICK:2)
B(8,8,15,STONEBRICK)
B(0,9,15,MOSSY_COBBLESTONE)
B(1,9,15,STONE)
B(7,9,15,MOSSY_COBBLESTONE)
B(8,9,15,MOSSY_COBBLESTONE)
B(0,10,15,MOSSY_COBBLESTONE)
B(1,10,15,EMERALD_ORE)
B(7,10,15,MOSSY_COBBLESTONE)
B(8,10,15,STONE)
B(0,11,15,MOSSY_COBBLESTONE)
B(1,11,15,MOSSY_COBBLESTONE)
B(7,11,15,MOSSY_COBBLESTONE)
B(8,11,15,STONE)
B(0,12,15,MOSSY_COBBLESTONE)
B(1,12,15,STONEBRICK:2)
B(7,12,15,STONEBRICK)
B(8,12,15,STONE)
B(0,13,15,STONE)
B(1,13,15,STONEBRICK:1)
B(7,13,15,STONEBRICK)
B(8,13,15,EMERALD_ORE)
B(0,14,15,EMERALD_ORE)
B(1,14,15,STONEBRICK)
B(7,14,15,STONEBRICK:1)
B(8,14,15,STONE)
B(0,15,15,STONE)
B(1,15,15,STONEBRICK:1)
B(2,15,15,STONEBRICK:1)
B(3,15,15,STONEBRICK:2)
B(4,15,15,STONEBRICK:1)
B(5,15,15,STONEBRICK:1)
B(6,15,15,STONEBRICK)
B(7,15,15,STONEBRICK)
B(8,15,15,MOSSY_COBBLESTONE)
B(0,16,15,STONEBRICK)
B(1,16,15,STONE)
B(2,16,15,MOSSY_COBBLESTONE)
B(3,16,15,EMERALD_ORE)
B(4,16,15,STONE)
B(5,16,15,STONE)
B(6,16,15,STONE)
B(7,16,15,MOSSY_COBBLESTONE)
B(8,16,15,STONEBRICK:2)
B(0,0,16,STONEBRICK:2)
B(1,0,16,STONEBRICK:1)
B(2,0,16,STONEBRICK:1)
B(3,0,16,STONEBRICK:1)
B(4,0,16,STONEBRICK:2)
B(5,0,16,STONEBRICK:2)
B(6,0,16,STONEBRICK:1)
B(7,0,16,STONEBRICK)
B(8,0,16,STONEBRICK)
B(0,1,16,STONEBRICK:1)
B(1,1,16,MOSSY_COBBLESTONE)
B(2,1,16,STONE)
B(3,1,16,STONEBRICK:1)
B(5,1,16,STONEBRICK:1)
B(6,1,16,MOSSY_COBBLESTONE)
B(7,1,16,STONE)
B(8,1,16,STONEBRICK)
B(0,2,16,STONEBRICK)
B(1,2,16,MOSSY_COBBLESTONE)
B(2,2,16,STONE)
B(3,2,16,STONEBRICK:2)
B(5,2,16,STONEBRICK:2)
B(6,2,16,STONE)
B(7,2,16,STONE)
B(8,2,16,STONEBRICK:1)
B(0,3,16,STONEBRICK)
B(1,3,16,STONE)
B(2,3,16,MOSSY_COBBLESTONE)
B(3,3,16,STONEBRICK)
B(5,3,16,STONEBRICK:1)
B(6,3,16,EMERALD_ORE)
B(7,3,16,STONE)
B(8,3,16,STONEBRICK)
B(0,4,16,STONEBRICK)
B(1,4,16,MOSSY_COBBLESTONE)
B(2,4,16,MOSSY_COBBLESTONE)
B(3,4,16,STONEBRICK:1)
B(4,4,16,STONEBRICK:1)
B(5,4,16,STONEBRICK:2)
B(6,4,16,MOSSY_COBBLESTONE)
B(7,4,16,STONE)
B(8,4,16,STONEBRICK)
B(0,5,16,STONEBRICK)
B(1,5,16,STONE)
B(2,5,16,STONE)
B(3,5,16,MOSSY_COBBLESTONE)
B(4,5,16,EMERALD_ORE)
B(5,5,16,STONE)
B(6,5,16,STONE)
B(7,5,16,STONE)
B(8,5,16,STONEBRICK:1)
B(0,6,16,STONEBRICK)
B(1,6,16,STONE)
B(2,6,16,EMERALD_ORE)
B(3,6,16,STONE)
B(4,6,16,MOSSY_COBBLESTONE)
B(5,6,16,STONE)
B(6,6,16,MOSSY_COBBLESTONE)
B(7,6,16,STONE)
B(8,6,16,STONEBRICK:2)
B(0,7,16,STONEBRICK:2)
B(1,7,16,MOSSY_COBBLESTONE)
B(2,7,16,STONE)
B(3,7,16,MOSSY_COBBLESTONE)
B(4,7,16,STONE)
B(5,7,16,STONE)
B(6,7,16,MOSSY_COBBLESTONE)
B(7,7,16,STONE)
B(8,7,16,STONEBRICK:2)
B(0,8,16,STONEBRICK)
B(1,8,16,STONEBRICK)
B(2,8,16,STONEBRICK:2)
B(3,8,16,STONEBRICK:2)
B(4,8,16,STONEBRICK:1)
B(5,8,16,STONEBRICK)
B(6,8,16,STONEBRICK:2)
B(7,8,16,STONEBRICK)
B(8,8,16,STONEBRICK:2)
B(0,9,16,STONEBRICK:2)
B(1,9,16,STONE)
B(2,9,16,STONE)
B(3,9,16,MOSSY_COBBLESTONE)
B(4,9,16,MOSSY_COBBLESTONE)
B(5,9,16,MOSSY_COBBLESTONE)
B(6,9,16,MOSSY_COBBLESTONE)
B(7,9,16,MOSSY_COBBLESTONE)
B(8,9,16,STONEBRICK:2)
B(0,10,16,STONEBRICK:2)
B(1,10,16,STONE)
B(2,10,16,MOSSY_COBBLESTONE)
B(3,10,16,STONE)
B(4,10,16,STONE)
B(5,10,16,MOSSY_COBBLESTONE)
B(6,10,16,MOSSY_COBBLESTONE)
B(7,10,16,MOSSY_COBBLESTONE)
B(8,10,16,STONEBRICK)
B(0,11,16,STONEBRICK:1)
B(1,11,16,MOSSY_COBBLESTONE)
B(2,11,16,STONE)
B(3,11,16,STONE)
B(4,11,16,MOSSY_COBBLESTONE)
B(5,11,16,MOSSY_COBBLESTONE)
B(6,11,16,MOSSY_COBBLESTONE)
B(7,11,16,MOSSY_COBBLESTONE)
B(8,11,16,STONEBRICK:1)
B(0,12,16,STONEBRICK:1)
B(1,12,16,EMERALD_ORE)
B(2,12,16,MOSSY_COBBLESTONE)
B(3,12,16,MOSSY_COBBLESTONE)
B(4,12,16,STONE)
B(5,12,16,STONE)
B(6,12,16,STONE)
B(7,12,16,MOSSY_COBBLESTONE)
B(8,12,16,STONEBRICK)
B(0,13,16,STONEBRICK:1)
B(1,13,16,MOSSY_COBBLESTONE)
B(2,13,16,STONE)
B(3,13,16,EMERALD_ORE)
B(4,13,16,EMERALD_ORE)
B(5,13,16,STONE)
B(6,13,16,STONE)
B(7,13,16,MOSSY_COBBLESTONE)
B(8,13,16,STONEBRICK:2)
B(0,14,16,STONEBRICK:2)
B(1,14,16,MOSSY_COBBLESTONE)
B(2,14,16,MOSSY_COBBLESTONE)
B(3,14,16,STONE)
B(4,14,16,STONE)
B(5,14,16,MOSSY_COBBLESTONE)
B(6,14,16,MOSSY_COBBLESTONE)
B(7,14,16,MOSSY_COBBLESTONE)
B(8,14,16,STONEBRICK:1)
B(0,15,16,STONEBRICK)
B(1,15,16,MOSSY_COBBLESTONE)
B(2,15,16,MOSSY_COBBLESTONE)
B(3,15,16,STONE)
B(4,15,16,STONE)
B(5,15,16,MOSSY_COBBLESTONE)
B(6,15,16,STONE)
B(7,15,16,MOSSY_COBBLESTONE)
B(8,15,16,STONEBRICK:2)
B(0,16,16,STONEBRICK:1)
B(1,16,16,STONEBRICK:2)
B(2,16,16,STONEBRICK:2)
B(3,16,16,STONEBRICK)
B(4,16,16,STONEBRICK:2)
B(5,16,16,STONEBRICK:2)
B(6,16,16,STONEBRICK:2)
B(7,16,16,STONEBRICK:1)
B(8,16,16,STONEBRICK:2)
B(10,5,1,AIR)
B(11,5,1,AIR)
B(13,5,1,AIR)
B(14,5,1,AIR)
B(10,6,1,AIR)
B(11,6,1,AIR)
B(12,6,1,AIR)
B(13,6,1,AIR)
B(14,6,1,AIR)
B(10,7,1,AIR)
B(11,7,1,AIR)
B(12,7,1,AIR)
B(13,7,1,AIR)
B(14,7,1,AIR)
B(10,8,1,AIR)
B(11,8,1,AIR)
B(12,8,1,AIR)
B(13,8,1,AIR)
B(14,8,1,AIR)
B(10,9,1,AIR)
B(11,9,1,AIR)
B(12,9,1,AIR)
B(13,9,1,AIR)
B(14,9,1,AIR)
B(10,10,1,STONE_BRICK_STAIRS:5)
B(11,10,1,AIR)
B(12,10,1,AIR)
B(13,10,1,AIR)
B(14,10,1,STONE_BRICK_STAIRS:4)
B(9,5,2,AIR)
B(10,5,2,AIR)
B(11,5,2,AIR)
B(12,5,2,AIR)
B(13,5,2,AIR)
B(14,5,2,AIR)
B(15,5,2,AIR)
B(9,6,2,AIR)
B(10,6,2,AIR)
B(11,6,2,AIR)
B(12,6,2,AIR)
B(13,6,2,AIR)
B(14,6,2,AIR)
B(15,6,2,AIR)
B(9,7,2,AIR)
B(10,7,2,AIR)
B(11,7,2,AIR)
B(12,7,2,AIR)
B(13,7,2,AIR)
B(14,7,2,AIR)
B(15,7,2,AIR)
B(9,8,2,AIR)
B(10,8,2,AIR)
B(11,8,2,AIR)
B(12,8,2,AIR)
B(13,8,2,AIR)
B(14,8,2,AIR)
B(15,8,2,AIR)
B(9,9,2,AIR)
B(10,9,2,AIR)
B(11,9,2,AIR)
B(12,9,2,AIR)
B(13,9,2,AIR)
B(14,9,2,AIR)
B(15,9,2,AIR)
B(9,10,2,STONE_BRICK_STAIRS:7)
B(10,10,2,AIR)
B(11,10,2,AIR)
B(12,10,2,AIR)
B(13,10,2,AIR)
B(14,10,2,AIR)
B(15,10,2,STONE_BRICK_STAIRS:7)
B(10,11,2,AIR)
B(11,11,2,AIR)
B(12,11,2,AIR)
B(13,11,2,AIR)
B(14,11,2,AIR)
B(9,5,3,AIR)
B(10,5,3,AIR)
B(11,5,3,AIR)
B(12,5,3,TALLGRASS:2)
B(13,5,3,TALLGRASS:2)
B(14,5,3,AIR)
B(15,5,3,AIR)
B(9,6,3,AIR)
B(10,6,3,AIR)
B(11,6,3,AIR)
B(12,6,3,AIR)
B(13,6,3,AIR)
B(14,6,3,AIR)
B(15,6,3,AIR)
B(9,7,3,AIR)
B(10,7,3,AIR)
B(11,7,3,AIR)
B(12,7,3,AIR)
B(13,7,3,AIR)
B(14,7,3,AIR)
B(15,7,3,AIR)
B(9,8,3,AIR)
B(10,8,3,AIR)
B(11,8,3,AIR)
B(12,8,3,AIR)
B(13,8,3,AIR)
B(14,8,3,AIR)
B(15,8,3,AIR)
B(9,9,3,AIR)
B(10,9,3,AIR)
B(11,9,3,AIR)
B(12,9,3,AIR)
B(13,9,3,AIR)
B(14,9,3,AIR)
B(15,9,3,AIR)
B(9,10,3,AIR)
B(10,10,3,AIR)
B(11,10,3,AIR)
B(12,10,3,AIR)
B(13,10,3,AIR)
B(14,10,3,AIR)
B(15,10,3,AIR)
B(10,11,3,AIR)
B(11,11,3,AIR)
B(12,11,3,AIR)
B(13,11,3,AIR)
B(14,11,3,AIR)
B(11,12,3,AIR)
B(12,12,3,AIR)
B(13,12,3,AIR)
B(4,3,4,AIR)
B(5,3,4,STONE_SLAB)
B(4,4,4,AIR)
B(5,4,4,AIR)
B(6,4,4,AIR)
B(7,4,4,STONE_SLAB)
B(4,5,4,AIR)
B(5,5,4,AIR)
B(6,5,4,AIR)
B(7,5,4,AIR)
B(8,5,4,AIR)
B(9,5,4,AIR)
B(10,5,4,AIR)
B(11,5,4,AIR)
B(13,5,4,AIR)
B(14,5,4,AIR)
B(5,6,4,STONE_SLAB)
B(6,6,4,AIR)
B(7,6,4,AIR)
B(8,6,4,AIR)
B(9,6,4,AIR)
B(10,6,4,AIR)
B(11,6,4,AIR)
B(12,6,4,AIR)
B(13,6,4,AIR)
B(14,6,4,AIR)
B(15,6,4,AIR)
B(7,7,4,STONE_SLAB)
B(8,7,4,AIR)
B(9,7,4,AIR)
B(10,7,4,AIR)
B(11,7,4,AIR)
B(12,7,4,AIR)
B(13,7,4,AIR)
B(14,7,4,AIR)
B(15,7,4,AIR)
B(9,8,4,AIR)
B(10,8,4,AIR)
B(11,8,4,AIR)
B(12,8,4,AIR)
B(13,8,4,AIR)
B(14,8,4,AIR)
B(15,8,4,AIR)
B(9,9,4,AIR)
B(10,9,4,AIR)
B(11,9,4,AIR)
B(12,9,4,AIR)
B(13,9,4,AIR)
B(14,9,4,AIR)
B(15,9,4,AIR)
B(9,10,4,AIR)
B(10,10,4,AIR)
B(11,10,4,AIR)
B(12,10,4,AIR)
B(13,10,4,AIR)
B(14,10,4,AIR)
B(15,10,4,AIR)
B(10,11,4,AIR)
B(11,11,4,AIR)
B(12,11,4,AIR)
B(13,11,4,AIR)
B(14,11,4,AIR)
B(11,12,4,AIR)
B(12,12,4,AIR)
B(13,12,4,AIR)
B(4,2,5,STONE_SLAB)
B(4,3,5,AIR)
B(4,4,5,AIR)
B(4,5,5,STONE_SLAB)
B(9,5,5,AIR)
B(10,5,5,AIR)
B(11,5,5,AIR)
B(12,5,5,AIR)
B(13,5,5,TALLGRASS:2)
B(14,5,5,AIR)
B(15,5,5,AIR)
B(9,6,5,AIR)
B(10,6,5,AIR)
B(11,6,5,AIR)
B(12,6,5,AIR)
B(13,6,5,AIR)
B(14,6,5,AIR)
B(15,6,5,AIR)
B(9,7,5,AIR)
B(10,7,5,AIR)
B(11,7,5,AIR)
B(12,7,5,AIR)
B(13,7,5,AIR)
B(14,7,5,AIR)
B(15,7,5,AIR)
B(9,8,5,AIR)
B(10,8,5,AIR)
B(11,8,5,AIR)
B(12,8,5,AIR)
B(13,8,5,AIR)
B(14,8,5,AIR)
B(15,8,5,AIR)
B(9,9,5,AIR)
B(10,9,5,AIR)
B(11,9,5,AIR)
B(12,9,5,AIR)
B(13,9,5,AIR)
B(14,9,5,AIR)
B(15,9,5,AIR)
B(9,10,5,AIR)
B(10,10,5,AIR)
B(11,10,5,AIR)
B(12,10,5,AIR)
B(13,10,5,AIR)
B(14,10,5,AIR)
B(15,10,5,AIR)
B(10,11,5,AIR)
B(11,11,5,AIR)
B(12,11,5,AIR)
B(13,11,5,AIR)
B(14,11,5,AIR)
B(11,12,5,AIR)
B(12,12,5,AIR)
B(13,12,5,AIR)
B(4,2,6,AIR)
B(4,3,6,AIR)
B(4,4,6,AIR)
B(9,5,6,AIR)
B(10,5,6,AIR)
B(11,5,6,AIR)
B(12,5,6,AIR)
B(13,5,6,AIR)
B(14,5,6,AIR)
B(15,5,6,AIR)
B(9,6,6,AIR)
B(10,6,6,AIR)
B(11,6,6,AIR)
B(12,6,6,AIR)
B(13,6,6,AIR)
B(14,6,6,AIR)
B(15,6,6,AIR)
B(9,7,6,AIR)
B(10,7,6,AIR)
B(11,7,6,AIR)
B(12,7,6,AIR)
B(13,7,6,AIR)
B(14,7,6,AIR)
B(15,7,6,AIR)
B(9,8,6,AIR)
B(10,8,6,AIR)
B(11,8,6,AIR)
B(12,8,6,AIR)
B(13,8,6,AIR)
B(14,8,6,AIR)
B(15,8,6,AIR)
B(9,9,6,AIR)
B(10,9,6,AIR)
B(11,9,6,AIR)
B(12,9,6,AIR)
B(13,9,6,AIR)
B(14,9,6,AIR)
B(15,9,6,AIR)
B(9,10,6,STONE_BRICK_STAIRS:6)
B(10,10,6,AIR)
B(11,10,6,AIR)
B(12,10,6,AIR)
B(13,10,6,AIR)
B(14,10,6,AIR)
B(15,10,6,STONE_BRICK_STAIRS:6)
B(10,11,6,AIR)
B(11,11,6,AIR)
B(12,11,6,AIR)
B(13,11,6,AIR)
B(14,11,6,AIR)
B(4,1,7,STONE_SLAB)
B(4,2,7,AIR)
B(4,3,7,AIR)
B(4,4,7,STONE_SLAB)
B(10,5,7,AIR)
B(11,5,7,AIR)
B(12,5,7,AIR)
B(13,5,7,AIR)
B(14,5,7,AIR)
B(10,6,7,AIR)
B(11,6,7,AIR)
B(12,6,7,AIR)
B(13,6,7,AIR)
B(14,6,7,AIR)
B(10,7,7,AIR)
B(11,7,7,AIR)
B(12,7,7,AIR)
B(13,7,7,AIR)
B(14,7,7,AIR)
B(10,8,7,AIR)
B(11,8,7,AIR)
B(12,8,7,AIR)
B(13,8,7,AIR)
B(14,8,7,AIR)
B(10,9,7,AIR)
B(11,9,7,AIR)
B(12,9,7,AIR)
B(13,9,7,AIR)
B(14,9,7,AIR)
B(10,10,7,STONE_BRICK_STAIRS:5)
B(11,10,7,AIR)
B(12,10,7,AIR)
B(13,10,7,AIR)
B(14,10,7,STONE_BRICK_STAIRS:4)
B(4,1,8,AIR)
B(4,2,8,AIR)
B(4,3,8,AIR)
B(12,5,8,AIR)
B(12,6,8,AIR)
B(12,7,8,AIR)
B(2,1,9,AIR)
B(3,1,9,AIR)
B(4,1,9,AIR)
B(5,1,9,AIR)
B(6,1,9,AIR)
B(2,2,9,AIR)
B(3,2,9,AIR)
B(4,2,9,AIR)
B(5,2,9,AIR)
B(6,2,9,AIR)
B(2,3,9,AIR)
B(3,3,9,AIR)
B(4,3,9,AIR)
B(5,3,9,AIR)
B(6,3,9,AIR)
B(2,4,9,AIR)
B(3,4,9,AIR)
B(4,4,9,AIR)
B(5,4,9,AIR)
B(6,4,9,AIR)
B(2,5,9,AIR)
B(3,5,9,AIR)
B(4,5,9,AIR)
B(5,5,9,AIR)
B(6,5,9,AIR)
B(12,5,9,STONE_SLAB)
B(2,6,9,STONE_BRICK_STAIRS:5)
B(3,6,9,AIR)
B(4,6,9,AIR)
B(5,6,9,AIR)
B(6,6,9,STONE_BRICK_STAIRS:4)
B(12,6,9,AIR)
B(12,7,9,AIR)
B(12,8,9,STONE_SLAB)
B(2,9,9,AIR)
B(3,9,9,AIR)
B(5,9,9,AIR)
B(6,9,9,AIR)
B(2,10,9,AIR)
B(3,10,9,AIR)
B(4,10,9,AIR)
B(5,10,9,AIR)
B(6,10,9,AIR)
B(2,11,9,AIR)
B(3,11,9,AIR)
B(4,11,9,AIR)
B(5,11,9,AIR)
B(6,11,9,AIR)
B(2,12,9,AIR)
B(3,12,9,AIR)
B(4,12,9,AIR)
B(5,12,9,AIR)
B(6,12,9,AIR)
B(2,13,9,AIR)
B(3,13,9,AIR)
B(4,13,9,AIR)
B(5,13,9,AIR)
B(6,13,9,AIR)
B(2,14,9,STONE_BRICK_STAIRS:5)
B(3,14,9,AIR)
B(4,14,9,AIR)
B(5,14,9,AIR)
B(6,14,9,STONE_BRICK_STAIRS:4)
B(1,1,10,AIR)
B(2,1,10,AIR)
B(3,1,10,AIR)
B(4,1,10,AIR)
B(5,1,10,AIR)
B(6,1,10,AIR)
B(7,1,10,AIR)
B(1,2,10,AIR)
B(2,2,10,AIR)
B(3,2,10,AIR)
B(4,2,10,AIR)
B(5,2,10,AIR)
B(6,2,10,AIR)
B(7,2,10,AIR)
B(1,3,10,AIR)
B(2,3,10,AIR)
B(3,3,10,AIR)
B(4,3,10,AIR)
B(5,3,10,AIR)
B(6,3,10,AIR)
B(7,3,10,AIR)
B(1,4,10,AIR)
B(2,4,10,AIR)
B(3,4,10,AIR)
B(4,4,10,AIR)
B(5,4,10,AIR)
B(6,4,10,AIR)
B(7,4,10,AIR)
B(1,5,10,AIR)
B(2,5,10,AIR)
B(3,5,10,AIR)
B(4,5,10,AIR)
B(5,5,10,AIR)
B(6,5,10,AIR)
B(7,5,10,AIR)
B(1,6,10,STONE_BRICK_STAIRS:7)
B(2,6,10,AIR)
B(3,6,10,AIR)
B(4,6,10,AIR)
B(5,6,10,AIR)
B(6,6,10,AIR)
B(7,6,10,STONE_BRICK_STAIRS:7)
B(12,6,10,AIR)
B(2,7,10,AIR)
B(3,7,10,AIR)
B(4,7,10,AIR)
B(5,7,10,AIR)
B(6,7,10,AIR)
B(12,7,10,AIR)
B(12,8,10,AIR)
B(1,9,10,AIR)
B(2,9,10,AIR)
B(3,9,10,AIR)
B(4,9,10,AIR)
B(5,9,10,AIR)
B(6,9,10,AIR)
B(7,9,10,AIR)
B(1,10,10,AIR)
B(2,10,10,AIR)
B(3,10,10,AIR)
B(4,10,10,AIR)
B(5,10,10,AIR)
B(6,10,10,AIR)
B(7,10,10,AIR)
B(1,11,10,AIR)
B(2,11,10,AIR)
B(3,11,10,AIR)
B(4,11,10,AIR)
B(5,11,10,AIR)
B(6,11,10,AIR)
B(7,11,10,AIR)
B(1,12,10,AIR)
B(2,12,10,AIR)
B(3,12,10,AIR)
B(4,12,10,AIR)
B(5,12,10,AIR)
B(6,12,10,AIR)
B(7,12,10,AIR)
B(1,13,10,AIR)
B(2,13,10,AIR)
B(3,13,10,AIR)
B(4,13,10,AIR)
B(5,13,10,AIR)
B(6,13,10,AIR)
B(7,13,10,AIR)
B(1,14,10,STONE_BRICK_STAIRS:7)
B(2,14,10,AIR)
B(3,14,10,AIR)
B(4,14,10,AIR)
B(5,14,10,AIR)
B(6,14,10,AIR)
B(7,14,10,STONE_BRICK_STAIRS:7)
B(2,15,10,AIR)
B(3,15,10,AIR)
B(4,15,10,AIR)
B(5,15,10,AIR)
B(6,15,10,AIR)
B(1,1,11,AIR)
B(2,1,11,AIR)
B(3,1,11,TALLGRASS:1)
B(4,1,11,TALLGRASS:1)
B(5,1,11,TALLGRASS:1)
B(6,1,11,AIR)
B(7,1,11,AIR)
B(1,2,11,AIR)
B(2,2,11,AIR)
B(3,2,11,AIR)
B(4,2,11,AIR)
B(5,2,11,AIR)
B(6,2,11,AIR)
B(7,2,11,AIR)
B(1,3,11,AIR)
B(2,3,11,AIR)
B(3,3,11,AIR)
B(4,3,11,AIR)
B(5,3,11,AIR)
B(6,3,11,AIR)
B(7,3,11,AIR)
B(1,4,11,AIR)
B(2,4,11,AIR)
B(3,4,11,AIR)
B(4,4,11,AIR)
B(5,4,11,AIR)
B(6,4,11,AIR)
B(7,4,11,AIR)
B(1,5,11,AIR)
B(2,5,11,AIR)
B(3,5,11,AIR)
B(4,5,11,AIR)
B(5,5,11,AIR)
B(6,5,11,AIR)
B(7,5,11,AIR)
B(1,6,11,AIR)
B(2,6,11,AIR)
B(3,6,11,AIR)
B(4,6,11,AIR)
B(5,6,11,AIR)
B(6,6,11,AIR)
B(7,6,11,AIR)
B(12,6,11,STONE_SLAB)
B(2,7,11,AIR)
B(3,7,11,AIR)
B(4,7,11,AIR)
B(5,7,11,AIR)
B(6,7,11,AIR)
B(12,7,11,AIR)
B(3,8,11,AIR)
B(4,8,11,AIR)
B(5,8,11,AIR)
B(12,8,11,AIR)
B(1,9,11,AIR)
B(2,9,11,AIR)
B(3,9,11,AIR)
B(4,9,11,AIR)
B(5,9,11,AIR)
B(6,9,11,AIR)
B(7,9,11,AIR)
B(12,9,11,STONE_SLAB)
B(1,10,11,AIR)
B(2,10,11,AIR)
B(3,10,11,AIR)
B(4,10,11,AIR)
B(5,10,11,AIR)
B(6,10,11,AIR)
B(7,10,11,AIR)
B(1,11,11,AIR)
B(2,11,11,AIR)
B(3,11,11,AIR)
B(4,11,11,AIR)
B(5,11,11,AIR)
B(6,11,11,AIR)
B(7,11,11,AIR)
B(1,12,11,AIR)
B(2,12,11,AIR)
B(3,12,11,AIR)
B(4,12,11,AIR)
B(5,12,11,AIR)
B(6,12,11,AIR)
B(7,12,11,AIR)
B(1,13,11,AIR)
B(2,13,11,AIR)
B(3,13,11,AIR)
B(4,13,11,AIR)
B(5,13,11,AIR)
B(6,13,11,AIR)
B(7,13,11,AIR)
B(1,14,11,AIR)
B(2,14,11,AIR)
B(3,14,11,AIR)
B(4,14,11,AIR)
B(5,14,11,AIR)
B(6,14,11,AIR)
B(7,14,11,AIR)
B(2,15,11,AIR)
B(3,15,11,AIR)
B(4,15,11,AIR)
B(5,15,11,AIR)
B(6,15,11,AIR)
B(3,16,11,AIR)
B(4,16,11,AIR)
B(5,16,11,AIR)
B(2,1,12,AIR)
B(3,1,12,AIR)
B(5,1,12,TALLGRASS:1)
B(6,1,12,AIR)
B(1,2,12,AIR)
B(2,2,12,AIR)
B(3,2,12,AIR)
B(4,2,12,AIR)
B(5,2,12,AIR)
B(6,2,12,AIR)
B(7,2,12,AIR)
B(1,3,12,AIR)
B(2,3,12,AIR)
B(3,3,12,AIR)
B(4,3,12,AIR)
B(5,3,12,AIR)
B(6,3,12,AIR)
B(7,3,12,AIR)
B(1,4,12,AIR)
B(2,4,12,AIR)
B(3,4,12,AIR)
B(4,4,12,AIR)
B(5,4,12,AIR)
B(6,4,12,AIR)
B(7,4,12,AIR)
B(1,5,12,AIR)
B(2,5,12,AIR)
B(3,5,12,AIR)
B(4,5,12,AIR)
B(5,5,12,AIR)
B(6,5,12,AIR)
B(7,5,12,AIR)
B(1,6,12,AIR)
B(2,6,12,AIR)
B(3,6,12,AIR)
B(4,6,12,AIR)
B(5,6,12,AIR)
B(6,6,12,AIR)
B(7,6,12,AIR)
B(2,7,12,AIR)
B(3,7,12,AIR)
B(4,7,12,AIR)
B(5,7,12,AIR)
B(6,7,12,AIR)
B(11,7,12,STONE_SLAB)
B(12,7,12,AIR)
B(3,8,12,AIR)
B(4,8,12,AIR)
B(5,8,12,AIR)
B(9,8,12,STONE_SLAB)
B(10,8,12,AIR)
B(11,8,12,AIR)
B(12,8,12,AIR)
B(0,9,12,AIR)
B(1,9,12,AIR)
B(2,9,12,AIR)
B(3,9,12,AIR)
B(4,9,12,AIR)
B(5,9,12,AIR)
B(6,9,12,AIR)
B(7,9,12,AIR)
B(8,9,12,AIR)
B(9,9,12,AIR)
B(10,9,12,AIR)
B(11,9,12,AIR)
B(12,9,12,AIR)
B(0,10,12,AIR)
B(1,10,12,AIR)
B(2,10,12,AIR)
B(3,10,12,AIR)
B(4,10,12,AIR)
B(5,10,12,AIR)
B(6,10,12,AIR)
B(7,10,12,AIR)
B(8,10,12,AIR)
B(9,10,12,AIR)
B(10,10,12,AIR)
B(11,10,12,STONE_SLAB)
B(0,11,12,AIR)
B(1,11,12,AIR)
B(2,11,12,AIR)
B(3,11,12,AIR)
B(4,11,12,AIR)
B(5,11,12,AIR)
B(6,11,12,AIR)
B(7,11,12,AIR)
B(8,11,12,AIR)
B(9,11,12,STONE_SLAB)
B(1,12,12,AIR)
B(2,12,12,AIR)
B(3,12,12,AIR)
B(4,12,12,AIR)
B(5,12,12,AIR)
B(6,12,12,AIR)
B(7,12,12,AIR)
B(1,13,12,AIR)
B(2,13,12,AIR)
B(3,13,12,AIR)
B(4,13,12,AIR)
B(5,13,12,AIR)
B(6,13,12,AIR)
B(7,13,12,AIR)
B(1,14,12,AIR)
B(2,14,12,AIR)
B(3,14,12,AIR)
B(4,14,12,AIR)
B(5,14,12,AIR)
B(6,14,12,AIR)
B(7,14,12,AIR)
B(2,15,12,AIR)
B(3,15,12,AIR)
B(4,15,12,AIR)
B(5,15,12,AIR)
B(6,15,12,AIR)
B(3,16,12,AIR)
B(4,16,12,AIR)
B(5,16,12,AIR)
B(1,1,13,AIR)
B(2,1,13,AIR)
B(3,1,13,TALLGRASS:2)
B(4,1,13,TALLGRASS:2)
B(5,1,13,AIR)
B(6,1,13,AIR)
B(7,1,13,AIR)
B(1,2,13,AIR)
B(2,2,13,AIR)
B(3,2,13,AIR)
B(4,2,13,AIR)
B(5,2,13,AIR)
B(6,2,13,AIR)
B(7,2,13,AIR)
B(1,3,13,AIR)
B(2,3,13,AIR)
B(3,3,13,AIR)
B(4,3,13,AIR)
B(5,3,13,AIR)
B(6,3,13,AIR)
B(7,3,13,AIR)
B(1,4,13,AIR)
B(2,4,13,AIR)
B(3,4,13,AIR)
B(4,4,13,AIR)
B(5,4,13,AIR)
B(6,4,13,AIR)
B(7,4,13,AIR)
B(1,5,13,AIR)
B(2,5,13,AIR)
B(3,5,13,AIR)
B(4,5,13,AIR)
B(5,5,13,AIR)
B(6,5,13,AIR)
B(7,5,13,AIR)
B(1,6,13,AIR)
B(2,6,13,AIR)
B(3,6,13,AIR)
B(4,6,13,AIR)
B(5,6,13,AIR)
B(6,6,13,AIR)
B(7,6,13,AIR)
B(2,7,13,AIR)
B(3,7,13,AIR)
B(4,7,13,AIR)
B(5,7,13,AIR)
B(6,7,13,AIR)
B(3,8,13,AIR)
B(4,8,13,AIR)
B(5,8,13,AIR)
B(1,9,13,AIR)
B(2,9,13,AIR)
B(3,9,13,AIR)
B(4,9,13,AIR)
B(5,9,13,AIR)
B(6,9,13,AIR)
B(7,9,13,AIR)
B(1,10,13,AIR)
B(2,10,13,AIR)
B(3,10,13,AIR)
B(4,10,13,AIR)
B(5,10,13,AIR)
B(6,10,13,AIR)
B(7,10,13,AIR)
B(1,11,13,AIR)
B(2,11,13,AIR)
B(3,11,13,AIR)
B(4,11,13,AIR)
B(5,11,13,AIR)
B(6,11,13,AIR)
B(7,11,13,AIR)
B(1,12,13,AIR)
B(2,12,13,AIR)
B(3,12,13,AIR)
B(4,12,13,AIR)
B(5,12,13,AIR)
B(6,12,13,AIR)
B(7,12,13,AIR)
B(1,13,13,AIR)
B(2,13,13,AIR)
B(3,13,13,AIR)
B(4,13,13,AIR)
B(5,13,13,AIR)
B(6,13,13,AIR)
B(7,13,13,AIR)
B(1,14,13,AIR)
B(2,14,13,AIR)
B(3,14,13,AIR)
B(4,14,13,AIR)
B(5,14,13,AIR)
B(6,14,13,AIR)
B(7,14,13,AIR)
B(2,15,13,AIR)
B(3,15,13,AIR)
B(4,15,13,AIR)
B(5,15,13,AIR)
B(6,15,13,AIR)
B(3,16,13,AIR)
B(4,16,13,AIR)
B(5,16,13,AIR)
B(1,1,14,AIR)
B(2,1,14,AIR)
B(3,1,14,AIR)
B(4,1,14,AIR)
B(5,1,14,AIR)
B(6,1,14,AIR)
B(7,1,14,AIR)
B(1,2,14,AIR)
B(2,2,14,AIR)
B(3,2,14,AIR)
B(4,2,14,AIR)
B(5,2,14,AIR)
B(6,2,14,AIR)
B(7,2,14,AIR)
B(1,3,14,AIR)
B(2,3,14,AIR)
B(3,3,14,AIR)
B(4,3,14,AIR)
B(5,3,14,AIR)
B(6,3,14,AIR)
B(7,3,14,AIR)
B(1,4,14,AIR)
B(2,4,14,AIR)
B(3,4,14,AIR)
B(4,4,14,AIR)
B(5,4,14,AIR)
B(6,4,14,AIR)
B(7,4,14,AIR)
B(1,5,14,AIR)
B(2,5,14,AIR)
B(3,5,14,AIR)
B(4,5,14,AIR)
B(5,5,14,AIR)
B(6,5,14,AIR)
B(7,5,14,AIR)
B(1,6,14,STONE_BRICK_STAIRS:6)
B(2,6,14,AIR)
B(3,6,14,AIR)
B(4,6,14,AIR)
B(5,6,14,AIR)
B(6,6,14,AIR)
B(7,6,14,STONE_BRICK_STAIRS:6)
B(2,7,14,AIR)
B(3,7,14,AIR)
B(4,7,14,AIR)
B(5,7,14,AIR)
B(6,7,14,AIR)
B(1,9,14,AIR)
B(2,9,14,AIR)
B(3,9,14,AIR)
B(4,9,14,AIR)
B(5,9,14,AIR)
B(6,9,14,AIR)
B(7,9,14,AIR)
B(1,10,14,AIR)
B(2,10,14,AIR)
B(3,10,14,AIR)
B(4,10,14,AIR)
B(5,10,14,AIR)
B(6,10,14,AIR)
B(7,10,14,AIR)
B(1,11,14,AIR)
B(2,11,14,AIR)
B(3,11,14,AIR)
B(4,11,14,AIR)
B(5,11,14,AIR)
B(6,11,14,AIR)
B(7,11,14,AIR)
B(1,12,14,AIR)
B(2,12,14,AIR)
B(3,12,14,AIR)
B(4,12,14,AIR)
B(5,12,14,AIR)
B(6,12,14,AIR)
B(7,12,14,AIR)
B(1,13,14,AIR)
B(2,13,14,AIR)
B(3,13,14,AIR)
B(4,13,14,AIR)
B(5,13,14,AIR)
B(6,13,14,AIR)
B(7,13,14,AIR)
B(1,14,14,STONE_BRICK_STAIRS:6)
B(2,14,14,AIR)
B(3,14,14,AIR)
B(4,14,14,AIR)
B(5,14,14,AIR)
B(6,14,14,AIR)
B(7,14,14,STONE_BRICK_STAIRS:6)
B(2,15,14,AIR)
B(3,15,14,AIR)
B(4,15,14,AIR)
B(5,15,14,AIR)
B(6,15,14,AIR)
B(2,1,15,AIR)
B(3,1,15,AIR)
B(4,1,15,AIR)
B(5,1,15,AIR)
B(6,1,15,AIR)
B(2,2,15,AIR)
B(3,2,15,AIR)
B(4,2,15,AIR)
B(5,2,15,AIR)
B(6,2,15,AIR)
B(2,3,15,AIR)
B(3,3,15,AIR)
B(4,3,15,AIR)
B(5,3,15,AIR)
B(6,3,15,AIR)
B(2,4,15,AIR)
B(3,4,15,AIR)
B(4,4,15,AIR)
B(5,4,15,AIR)
B(6,4,15,AIR)
B(2,5,15,AIR)
B(3,5,15,AIR)
B(4,5,15,AIR)
B(5,5,15,AIR)
B(6,5,15,AIR)
B(2,6,15,STONE_BRICK_STAIRS:5)
B(3,6,15,AIR)
B(4,6,15,AIR)
B(5,6,15,AIR)
B(6,6,15,STONE_BRICK_STAIRS:4)
B(2,9,15,AIR)
B(3,9,15,AIR)
B(5,9,15,AIR)
B(6,9,15,AIR)
B(2,10,15,AIR)
B(3,10,15,AIR)
B(4,10,15,AIR)
B(5,10,15,AIR)
B(6,10,15,AIR)
B(2,11,15,AIR)
B(3,11,15,AIR)
B(4,11,15,AIR)
B(5,11,15,AIR)
B(6,11,15,AIR)
B(2,12,15,AIR)
B(3,12,15,AIR)
B(4,12,15,AIR)
B(5,12,15,AIR)
B(6,12,15,AIR)
B(2,13,15,AIR)
B(3,13,15,AIR)
B(4,13,15,AIR)
B(5,13,15,AIR)
B(6,13,15,AIR)
B(2,14,15,STONE_BRICK_STAIRS:5)
B(3,14,15,AIR)
B(4,14,15,AIR)
B(5,14,15,AIR)
B(6,14,15,STONE_BRICK_STAIRS:4)
B(4,1,16,AIR)
B(4,2,16,AIR)
B(4,3,16,AIR)

RB(12,5,4,MOB_SPAWNER,../../NBT/Spawners/Zombie.nbt,50,MOB_SPAWNER,../../NBT/Spawners/Skeleton.nbt,50,MOB_SPAWNER,../../NBT/Spawners/Spider.nbt,100)
RB(4,1,12,MOB_SPAWNER,../../NBT/Spawners/Zombie.nbt,50,MOB_SPAWNER,../../NBT/Spawners/Skeleton.nbt,50,MOB_SPAWNER,../../NBT/Spawners/Spider.nbt,100)

B(12,5,1,CHEST:3,../../NBT/Chests/SimpleDungeon.nbt)
B(15,5,4,CHEST:4,../../NBT/Chests/SimpleDungeon.nbt)
B(4,9,9,CHEST:3,../../NBT/Chests/SimpleDungeon.nbt)
B(1,1,12,CHEST:5,../../NBT/Chests/SimpleDungeon.nbt)
B(7,1,12,CHEST:4,../../NBT/Chests/SimpleDungeon.nbt)
B(4,9,15,CHEST:2,../../NBT/Chests/SimpleDungeon.nbt)

# Size (X*Y*Z): 17*17*17

#######################################################################
# +-----------------------------------------------------------------+ #
# |                            BO3 checks                           | #
# +-----------------------------------------------------------------+ #
#######################################################################

# Require a condition at a certain location in order for the BO3 to be spawned.
# BlockCheck(x,y,z,BlockName[,BlockName[,...]]) - one of the blocks must be at the location
# BlockCheckNot(x,y,z,BlockName[,BlockName[,...]]) - all the blocks must not be at the location
# LightCheck(x,y,z,minLightLevel,maxLightLevel) - light must be between min and max (inclusive)

# You can use "Solid" as a BlockName for matching all solid blocks or "All" to match all blocks that aren't air.

# Examples:
#   BlockCheck(0,-1,0,GRASS,DIRT)  Require grass or dirt just below the object
#   BlockCheck(0,-1,0,Solid)       Require any solid block just below the object
#   BlockCheck(0,-1,0,WOOL)        Require any type of wool just below the object
#   BlockCheck(0,-1,0,WOOL:0)      Require white wool just below the object
#   BlockCheckNot(0,0,0,WOOL:0)   Require that there is no white wool below the object
#   LightCheck(0,0,0,0,1)          Require almost complete darkness just below the object

# Ensure the ceiling is sufficiently covered in solid blocks.
BlockCheck(0,17,0,Solid)
BlockCheck(0,17,17,Solid)
BlockCheck(17,17,0,Solid)
BlockCheck(17,17,17,Solid)

#######################################################################
# +-----------------------------------------------------------------+ #
# |                             Branches                            | #
# +-----------------------------------------------------------------+ #
#######################################################################

# Branches are objects that will spawn when this object spawns when it is used in
# the CustomStructure resource. Branches can also have branches, making complex
# structures possible. See the wiki for more details.

# Regular Branches spawn each branch with an independent chance of spawning.
# Branch(x,y,z,branchName,rotation,chance[,anotherBranchName,rotation,chance[,...]][IndividualChance])
# branchName - name of the object to spawn.
# rotation - NORTH, SOUTH, EAST or WEST.
# IndividualChance - The chance each branch has to spawn, assumed to be 100 when left blank

# Weighted Branches spawn branches with a dependent chance of spawning.
# WBR(x,y,z,branchName,rotation,chance[,anotherBranchName,rotation,chance[,...]][MaxChanceOutOf])
# MaxChanceOutOf - The chance all branches have to spawn out of, assumed to be 100 when left blank
