
#######################################################################
# +-----------------------------------------------------------------+ #
# |                            BO3 object                           | #
# +-----------------------------------------------------------------+ #
#######################################################################

# This is the config file of a custom object.
# If you add this object correctly to your BiomeConfigs, it will spawn in the world.

# This is the creator of this BO3 object
# See: https://imgur.com/a/JanPA
Author: Arcensoth, designed by McNoodlor

# A short description of this BO3 object
Description: No description given

# The BO3 version, don't change this! It can be used by external applications to do a version check.
Version: 3

# The settings mode, WriteAll, WriteWithoutComments or WriteDisable. See WorldConfig.
SettingsMode: WriteDisable


#######################################################################
# +-----------------------------------------------------------------+ #
# |                          Main settings                          | #
# +-----------------------------------------------------------------+ #
#######################################################################

# This needs to be set to true to spawn the object in the Tree and Sapling resources.
Tree: false

# The frequency of the BO3 from 1 to 200. Tries this many times to spawn this BO3 when using the CustomObject(...) resource.
# Ignored by Tree(..), Sapling(..) and CustomStructure(..)
Frequency: 1

# The rarity of the BO3 from 0 to 100. Each spawn attempt has rarity% chance to succeed when using the CustomObject(...) resource.
# Ignored by Tree(..), Sapling(..) and CustomStructure(..)
Rarity: 1.0

# If you set this to true, the BO3 will be placed with a random rotation.
RotateRandomly: false

# The spawn height of the BO3 - randomY, highestBlock or highestSolidBlock.
SpawnHeight: randomY

# The height limits for the BO3.
MinHeight: 0

MaxHeight: 255

# Objects can have other objects attacthed to it: branches. Branches can also
# have branches attached to it, which can also have branches, etc. This is the
# maximum branch depth for this objects.
MaxBranchDepth: 10

# When spawned with the UseWorld keyword, this BO3 should NOT spawn in the following biomes.
# If you writer.write the BO3 name directly in the BiomeConfigs, this will be ignored.
ExcludedBiomes: All


#######################################################################
# +-----------------------------------------------------------------+ #
# |                      Source block settings                      | #
# +-----------------------------------------------------------------+ #
#######################################################################

# The B(s) the BO3 should spawn in.
SourceBlocks: STONE,STONE:1,STONE:3,STONE:5,COBBLESTONE,MOSSY_COBBLESTONE,SANDSTONE,HARD_CLAY,STAINED_CLAY,PRISMARINE,DIRT,DIRT:1,GRASS,SAND,GRAVEL,CLAY,OBSIDIAN,COAL_ORE,IRON_ORE,GOLD_ORE,REDSTONE_ORE,DIAMOND_ORE,LAPIS_ORE,EMERALD_ORE,STATIONARY_WATER,STATIONARY_LAVA

# The maximum percentage of the BO3 that can be outside the SourceBlock.
# The BO3 won't be placed on a location with more blocks outside the SourceBlock than this percentage.
MaxPercentageOutsideSourceBlock: 45

# What to do when a block is about to be placed outside the SourceBlock? (dontPlace, placeAnyway)
OutsideSourceBlock: dontPlace


#######################################################################
# +-----------------------------------------------------------------+ #
# |                              Blocks                             | #
# +-----------------------------------------------------------------+ #
#######################################################################

# All the blocks used in the BO3 are listed here. Possible blocks:
# B(x,y,z,id[.data][,nbtfile.nbt)
# RB(x,y,z,id[:data][,nbtfile.nbt],chance[,id[:data][,nbtfile.nbt],chance[,...]])
# So RB(0,0,0,CHEST,chest.nbt,50,CHEST,anotherchest.nbt,100) will spawn a chest at
# the BO3 origin, and give it a 50% chance to have the contents of chest.nbt, or, if that
# fails, a 100% percent chance to have the contents of anotherchest.nbt.
B(0,4,0,STONEBRICK)
B(1,4,0,STONEBRICK:1)
B(2,4,0,STONEBRICK)
B(3,4,0,STONEBRICK)
B(4,4,0,STONEBRICK)
B(5,4,0,STONEBRICK:2)
B(6,4,0,STONEBRICK)
B(7,4,0,STONEBRICK:2)
B(8,4,0,STONEBRICK:1)
B(0,5,0,STONEBRICK)
B(1,5,0,MOSSY_COBBLESTONE)
B(2,5,0,STONE)
B(3,5,0,MOSSY_COBBLESTONE)
B(4,5,0,STONE)
B(5,5,0,MOSSY_COBBLESTONE)
B(6,5,0,STONE)
B(7,5,0,MOSSY_COBBLESTONE)
B(8,5,0,STONEBRICK:1)
B(0,6,0,STONEBRICK)
B(1,6,0,STONE)
B(2,6,0,STONE)
B(3,6,0,MOSSY_COBBLESTONE)
B(4,6,0,EMERALD_ORE)
B(5,6,0,EMERALD_ORE)
B(6,6,0,MOSSY_COBBLESTONE)
B(7,6,0,EMERALD_ORE)
B(8,6,0,STONEBRICK:1)
B(0,7,0,STONEBRICK:2)
B(1,7,0,STONE)
B(2,7,0,STONE)
B(3,7,0,MOSSY_COBBLESTONE)
B(4,7,0,MOSSY_COBBLESTONE)
B(5,7,0,STONE)
B(6,7,0,EMERALD_ORE)
B(7,7,0,STONE)
B(8,7,0,STONEBRICK)
B(0,8,0,STONEBRICK:2)
B(1,8,0,MOSSY_COBBLESTONE)
B(2,8,0,STONE)
B(3,8,0,MOSSY_COBBLESTONE)
B(4,8,0,STONE)
B(5,8,0,MOSSY_COBBLESTONE)
B(6,8,0,MOSSY_COBBLESTONE)
B(7,8,0,MOSSY_COBBLESTONE)
B(8,8,0,STONEBRICK:2)
B(16,8,0,STONEBRICK:1)
B(17,8,0,STONEBRICK:2)
B(18,8,0,STONEBRICK)
B(19,8,0,STONEBRICK:1)
B(20,8,0,STONEBRICK:1)
B(21,8,0,STONEBRICK:2)
B(22,8,0,STONEBRICK:2)
B(23,8,0,STONEBRICK:2)
B(24,8,0,STONEBRICK:2)
B(0,9,0,STONEBRICK:1)
B(1,9,0,STONE)
B(2,9,0,STONE)
B(3,9,0,MOSSY_COBBLESTONE)
B(4,9,0,EMERALD_ORE)
B(5,9,0,STONE)
B(6,9,0,EMERALD_ORE)
B(7,9,0,MOSSY_COBBLESTONE)
B(8,9,0,STONEBRICK:1)
B(16,9,0,STONEBRICK:2)
B(17,9,0,MOSSY_COBBLESTONE)
B(18,9,0,MOSSY_COBBLESTONE)
B(19,9,0,MOSSY_COBBLESTONE)
B(20,9,0,EMERALD_ORE)
B(21,9,0,STONE)
B(22,9,0,EMERALD_ORE)
B(23,9,0,MOSSY_COBBLESTONE)
B(24,9,0,STONEBRICK)
B(0,10,0,STONEBRICK:2)
B(1,10,0,STONE)
B(2,10,0,MOSSY_COBBLESTONE)
B(3,10,0,STONE)
B(4,10,0,MOSSY_COBBLESTONE)
B(5,10,0,MOSSY_COBBLESTONE)
B(6,10,0,STONE)
B(7,10,0,MOSSY_COBBLESTONE)
B(8,10,0,STONEBRICK)
B(16,10,0,STONEBRICK:1)
B(17,10,0,MOSSY_COBBLESTONE)
B(18,10,0,MOSSY_COBBLESTONE)
B(19,10,0,MOSSY_COBBLESTONE)
B(20,10,0,STONE)
B(21,10,0,MOSSY_COBBLESTONE)
B(22,10,0,STONE)
B(23,10,0,STONE)
B(24,10,0,STONEBRICK)
B(0,11,0,STONEBRICK:2)
B(1,11,0,MOSSY_COBBLESTONE)
B(2,11,0,STONE)
B(3,11,0,MOSSY_COBBLESTONE)
B(4,11,0,EMERALD_ORE)
B(5,11,0,MOSSY_COBBLESTONE)
B(6,11,0,MOSSY_COBBLESTONE)
B(7,11,0,MOSSY_COBBLESTONE)
B(8,11,0,STONEBRICK:1)
B(16,11,0,STONEBRICK:1)
B(17,11,0,STONE)
B(18,11,0,STONE)
B(19,11,0,MOSSY_COBBLESTONE)
B(20,11,0,MOSSY_COBBLESTONE)
B(21,11,0,STONE)
B(22,11,0,MOSSY_COBBLESTONE)
B(23,11,0,MOSSY_COBBLESTONE)
B(24,11,0,STONEBRICK:1)
B(0,12,0,STONEBRICK:1)
B(1,12,0,STONEBRICK:2)
B(2,12,0,STONEBRICK)
B(3,12,0,STONEBRICK:1)
B(4,12,0,STONEBRICK:2)
B(5,12,0,STONEBRICK:1)
B(6,12,0,STONEBRICK:2)
B(7,12,0,STONEBRICK:1)
B(8,12,0,STONEBRICK:1)
B(16,12,0,STONEBRICK)
B(17,12,0,EMERALD_ORE)
B(18,12,0,MOSSY_COBBLESTONE)
B(19,12,0,MOSSY_COBBLESTONE)
B(20,12,0,STONE)
B(21,12,0,MOSSY_COBBLESTONE)
B(22,12,0,MOSSY_COBBLESTONE)
B(23,12,0,MOSSY_COBBLESTONE)
B(24,12,0,STONEBRICK:2)
B(16,13,0,STONEBRICK:2)
B(17,13,0,STONE)
B(18,13,0,STONE)
B(19,13,0,MOSSY_COBBLESTONE)
B(20,13,0,STONE)
B(21,13,0,EMERALD_ORE)
B(22,13,0,MOSSY_COBBLESTONE)
B(23,13,0,MOSSY_COBBLESTONE)
B(24,13,0,STONEBRICK:1)
B(16,14,0,STONEBRICK:2)
B(17,14,0,EMERALD_ORE)
B(18,14,0,STONE)
B(19,14,0,STONE)
B(20,14,0,STONE)
B(21,14,0,MOSSY_COBBLESTONE)
B(22,14,0,MOSSY_COBBLESTONE)
B(23,14,0,STONE)
B(24,14,0,STONEBRICK)
B(16,15,0,STONEBRICK)
B(17,15,0,STONE)
B(18,15,0,MOSSY_COBBLESTONE)
B(19,15,0,STONE)
B(20,15,0,STONE)
B(21,15,0,STONE)
B(22,15,0,STONE)
B(23,15,0,MOSSY_COBBLESTONE)
B(24,15,0,STONEBRICK:2)
B(16,16,0,STONEBRICK:2)
B(17,16,0,STONEBRICK:2)
B(18,16,0,STONEBRICK)
B(19,16,0,STONEBRICK)
B(20,16,0,STONEBRICK:1)
B(21,16,0,STONEBRICK)
B(22,16,0,STONEBRICK:2)
B(23,16,0,STONEBRICK)
B(24,16,0,STONEBRICK:2)
B(0,4,1,STONEBRICK:2)
B(1,4,1,STONEBRICK:2)
B(2,4,1,STONEBRICK)
B(3,4,1,STONEBRICK)
B(4,4,1,STONEBRICK)
B(5,4,1,STONEBRICK:2)
B(6,4,1,STONEBRICK)
B(7,4,1,STONEBRICK)
B(8,4,1,STONEBRICK:2)
B(0,5,1,MOSSY_COBBLESTONE)
B(1,5,1,EMERALD_ORE)
B(7,5,1,STONE)
B(8,5,1,STONE)
B(0,6,1,MOSSY_COBBLESTONE)
B(1,6,1,MOSSY_COBBLESTONE)
B(7,6,1,MOSSY_COBBLESTONE)
B(8,6,1,STONE)
B(0,7,1,STONE)
B(1,7,1,MOSSY_COBBLESTONE)
B(7,7,1,MOSSY_COBBLESTONE)
B(8,7,1,MOSSY_COBBLESTONE)
B(0,8,1,MOSSY_COBBLESTONE)
B(1,8,1,STONEBRICK:3)
B(7,8,1,STONEBRICK:3)
B(8,8,1,MOSSY_COBBLESTONE)
B(16,8,1,STONEBRICK:2)
B(17,8,1,STONEBRICK:2)
B(18,8,1,STONEBRICK:2)
B(19,8,1,STONEBRICK)
B(20,8,1,STONEBRICK:2)
B(21,8,1,STONEBRICK:1)
B(22,8,1,STONEBRICK)
B(23,8,1,STONEBRICK)
B(24,8,1,STONEBRICK:1)
B(0,9,1,MOSSY_COBBLESTONE)
B(1,9,1,STONEBRICK)
B(7,9,1,STONEBRICK:1)
B(8,9,1,MOSSY_COBBLESTONE)
B(16,9,1,MOSSY_COBBLESTONE)
B(17,9,1,MOSSY_COBBLESTONE)
B(23,9,1,STONE)
B(24,9,1,STONE)
B(0,10,1,STONE)
B(1,10,1,STONEBRICK:2)
B(7,10,1,STONEBRICK)
B(8,10,1,MOSSY_COBBLESTONE)
B(16,10,1,MOSSY_COBBLESTONE)
B(17,10,1,MOSSY_COBBLESTONE)
B(23,10,1,STONE)
B(24,10,1,STONE)
B(0,11,1,MOSSY_COBBLESTONE)
B(1,11,1,STONEBRICK:2)
B(2,11,1,STONEBRICK:1)
B(3,11,1,STONEBRICK:1)
B(4,11,1,STONEBRICK:1)
B(5,11,1,STONEBRICK:1)
B(6,11,1,STONEBRICK:1)
B(7,11,1,STONEBRICK:1)
B(8,11,1,STONE)
B(16,11,1,EMERALD_ORE)
B(17,11,1,MOSSY_COBBLESTONE)
B(23,11,1,STONE)
B(24,11,1,STONE)
B(0,12,1,STONEBRICK:2)
B(1,12,1,STONE)
B(2,12,1,MOSSY_COBBLESTONE)
B(3,12,1,STONE)
B(4,12,1,STONE)
B(5,12,1,MOSSY_COBBLESTONE)
B(6,12,1,STONE)
B(7,12,1,MOSSY_COBBLESTONE)
B(8,12,1,STONEBRICK:1)
B(16,12,1,MOSSY_COBBLESTONE)
B(17,12,1,STONEBRICK:3)
B(23,12,1,STONEBRICK:3)
B(24,12,1,MOSSY_COBBLESTONE)
B(16,13,1,EMERALD_ORE)
B(17,13,1,STONEBRICK)
B(23,13,1,STONEBRICK:2)
B(24,13,1,MOSSY_COBBLESTONE)
B(16,14,1,STONE)
B(17,14,1,STONEBRICK)
B(23,14,1,STONEBRICK:1)
B(24,14,1,MOSSY_COBBLESTONE)
B(16,15,1,STONE)
B(17,15,1,STONEBRICK)
B(18,15,1,STONEBRICK:1)
B(19,15,1,STONEBRICK:2)
B(20,15,1,STONEBRICK:1)
B(21,15,1,STONEBRICK:1)
B(22,15,1,STONEBRICK)
B(23,15,1,STONEBRICK:2)
B(24,15,1,MOSSY_COBBLESTONE)
B(16,16,1,STONEBRICK)
B(17,16,1,MOSSY_COBBLESTONE)
B(18,16,1,STONE)
B(19,16,1,STONE)
B(20,16,1,STONE)
B(21,16,1,STONE)
B(22,16,1,MOSSY_COBBLESTONE)
B(23,16,1,MOSSY_COBBLESTONE)
B(24,16,1,STONEBRICK)
B(0,4,2,STONEBRICK:1)
B(1,4,2,STONEBRICK:1)
B(2,4,2,STONEBRICK:1)
B(3,4,2,STONEBRICK)
B(4,4,2,STONEBRICK)
B(5,4,2,STONEBRICK)
B(6,4,2,STONEBRICK)
B(7,4,2,STONEBRICK)
B(8,4,2,STONEBRICK:2)
B(0,5,2,STONE)
B(8,5,2,STONE)
B(0,6,2,STONE)
B(8,6,2,MOSSY_COBBLESTONE)
B(0,7,2,EMERALD_ORE)
B(8,7,2,MOSSY_COBBLESTONE)
B(0,8,2,STONE)
B(8,8,2,MOSSY_COBBLESTONE)
B(16,8,2,STONEBRICK)
B(17,8,2,STONEBRICK:2)
B(18,8,2,STONEBRICK:1)
B(19,8,2,STONEBRICK)
B(20,8,2,STONEBRICK:1)
B(21,8,2,STONEBRICK:2)
B(22,8,2,STONEBRICK)
B(23,8,2,STONEBRICK:2)
B(24,8,2,STONEBRICK:2)
B(0,9,2,STONE)
B(8,9,2,STONE)
B(16,9,2,MOSSY_COBBLESTONE)
B(24,9,2,STONE)
B(0,10,2,MOSSY_COBBLESTONE)
B(8,10,2,MOSSY_COBBLESTONE)
B(16,10,2,MOSSY_COBBLESTONE)
B(24,10,2,MOSSY_COBBLESTONE)
B(0,11,2,STONE)
B(1,11,2,STONEBRICK)
B(7,11,2,STONEBRICK:1)
B(8,11,2,MOSSY_COBBLESTONE)
B(16,11,2,MOSSY_COBBLESTONE)
B(24,11,2,MOSSY_COBBLESTONE)
B(0,12,2,STONEBRICK)
B(1,12,2,STONE)
B(2,12,2,STONEBRICK:1)
B(3,12,2,STONEBRICK:1)
B(4,12,2,STONEBRICK:1)
B(5,12,2,STONEBRICK:2)
B(6,12,2,STONEBRICK:2)
B(7,12,2,STONE)
B(8,12,2,STONEBRICK:2)
B(16,12,2,STONE)
B(24,12,2,STONE)
B(16,13,2,MOSSY_COBBLESTONE)
B(24,13,2,STONE)
B(16,14,2,STONE)
B(24,14,2,MOSSY_COBBLESTONE)
B(16,15,2,MOSSY_COBBLESTONE)
B(17,15,2,STONEBRICK)
B(23,15,2,STONEBRICK:2)
B(24,15,2,MOSSY_COBBLESTONE)
B(16,16,2,STONEBRICK:1)
B(17,16,2,STONE)
B(18,16,2,STONEBRICK:1)
B(19,16,2,STONEBRICK)
B(20,16,2,STONEBRICK)
B(21,16,2,STONEBRICK:1)
B(22,16,2,STONEBRICK)
B(23,16,2,MOSSY_COBBLESTONE)
B(24,16,2,STONEBRICK:1)
B(0,4,3,STONEBRICK:1)
B(1,4,3,STONEBRICK)
B(2,4,3,STONEBRICK)
B(3,4,3,DIRT:1)
B(4,4,3,DIRT:1)
B(5,4,3,DIRT:1)
B(6,4,3,STONEBRICK:1)
B(7,4,3,STONEBRICK:2)
B(8,4,3,STONEBRICK)
B(9,4,3,STONEBRICK:2)
B(0,5,3,STONE)
B(8,5,3,STONEBRICK:1)
B(9,5,3,STONEBRICK:1)
B(10,5,3,STONEBRICK:2)
B(11,5,3,STONEBRICK:2)
B(0,6,3,STONE)
B(8,6,3,STONEBRICK)
B(9,6,3,STONEBRICK:1)
B(10,6,3,STONEBRICK:1)
B(11,6,3,STONEBRICK:1)
B(12,6,3,STONEBRICK:2)
B(13,6,3,STONEBRICK)
B(0,7,3,EMERALD_ORE)
B(8,7,3,STONEBRICK)
B(9,7,3,STONEBRICK:1)
B(10,7,3,STONEBRICK:1)
B(11,7,3,STONEBRICK:1)
B(12,7,3,STONEBRICK:1)
B(13,7,3,STONEBRICK)
B(14,7,3,STONEBRICK:2)
B(15,7,3,STONEBRICK)
B(0,8,3,MOSSY_COBBLESTONE)
B(8,8,3,STONEBRICK:3)
B(9,8,3,STONEBRICK:1)
B(10,8,3,STONEBRICK)
B(11,8,3,STONEBRICK:1)
B(12,8,3,STONEBRICK:2)
B(13,8,3,STONEBRICK:1)
B(14,8,3,STONEBRICK:2)
B(15,8,3,STONEBRICK:1)
B(16,8,3,STONEBRICK)
B(17,8,3,STONEBRICK:2)
B(18,8,3,STONEBRICK)
B(19,8,3,DIRT:1)
B(20,8,3,GRASS)
B(21,8,3,DIRT:1)
B(22,8,3,STONEBRICK:1)
B(23,8,3,STONEBRICK)
B(24,8,3,STONEBRICK:2)
B(0,9,3,MOSSY_COBBLESTONE)
B(8,9,3,STONE)
B(9,9,3,STONEBRICK)
B(10,9,3,STONEBRICK:2)
B(11,9,3,STONEBRICK:1)
B(12,9,3,STONEBRICK)
B(13,9,3,STONEBRICK:2)
B(14,9,3,STONEBRICK:2)
B(15,9,3,STONEBRICK:1)
B(16,9,3,STONEBRICK)
B(24,9,3,MOSSY_COBBLESTONE)
B(0,10,3,STONE)
B(8,10,3,MOSSY_COBBLESTONE)
B(11,10,3,STONEBRICK:1)
B(12,10,3,STONEBRICK:2)
B(13,10,3,STONEBRICK:2)
B(14,10,3,STONEBRICK:1)
B(15,10,3,STONEBRICK:2)
B(16,10,3,STONEBRICK:2)
B(24,10,3,STONE)
B(0,11,3,STONE)
B(1,11,3,STONEBRICK:1)
B(7,11,3,STONEBRICK:1)
B(8,11,3,MOSSY_COBBLESTONE)
B(13,11,3,STONEBRICK:2)
B(14,11,3,STONEBRICK:2)
B(15,11,3,STONEBRICK:2)
B(16,11,3,STONEBRICK)
B(24,11,3,EMERALD_ORE)
B(0,12,3,STONEBRICK:2)
B(1,12,3,STONE)
B(2,12,3,STONEBRICK)
B(6,12,3,STONEBRICK)
B(7,12,3,MOSSY_COBBLESTONE)
B(8,12,3,STONEBRICK:2)
B(15,12,3,STONEBRICK)
B(16,12,3,STONEBRICK:3)
B(24,12,3,MOSSY_COBBLESTONE)
B(16,13,3,STONE)
B(24,13,3,MOSSY_COBBLESTONE)
B(16,14,3,MOSSY_COBBLESTONE)
B(24,14,3,STONE)
B(16,15,3,STONE)
B(17,15,3,STONEBRICK)
B(23,15,3,STONEBRICK:2)
B(24,15,3,EMERALD_ORE)
B(16,16,3,STONEBRICK)
B(17,16,3,MOSSY_COBBLESTONE)
B(18,16,3,STONEBRICK:2)
B(22,16,3,STONEBRICK)
B(23,16,3,STONE)
B(24,16,3,STONEBRICK)
B(0,4,4,STONEBRICK:1)
B(1,4,4,STONEBRICK:1)
B(2,4,4,STONEBRICK:2)
B(3,4,4,GRASS)
B(4,4,4,DIRT:1)
B(5,4,4,DIRT:1)
B(6,4,4,STONEBRICK:2)
B(7,4,4,STONEBRICK:1)
B(8,4,4,STONEBRICK:1)
B(9,4,4,STONEBRICK:2)
B(0,5,4,MOSSY_COBBLESTONE)
B(10,5,4,STONEBRICK:1)
B(11,5,4,STONEBRICK:2)
B(0,6,4,MOSSY_COBBLESTONE)
B(12,6,4,STONEBRICK:2)
B(13,6,4,STONEBRICK:1)
B(0,7,4,STONE)
B(14,7,4,STONEBRICK:2)
B(15,7,4,STONEBRICK:2)
B(0,8,4,MOSSY_COBBLESTONE)
B(8,8,4,STONEBRICK:3)
B(16,8,4,STONEBRICK:2)
B(17,8,4,STONEBRICK:2)
B(18,8,4,STONEBRICK:2)
B(19,8,4,GRASS)
B(20,8,4,DIRT:1)
B(21,8,4,GRASS)
B(22,8,4,STONEBRICK:2)
B(23,8,4,STONEBRICK:2)
B(24,8,4,STONEBRICK)
B(0,9,4,MOSSY_COBBLESTONE)
B(8,9,4,EMERALD_ORE)
B(9,9,4,STONEBRICK)
B(10,9,4,STONEBRICK:2)
B(24,9,4,MOSSY_COBBLESTONE)
B(0,10,4,STONE)
B(8,10,4,STONE)
B(11,10,4,STONEBRICK:1)
B(12,10,4,STONEBRICK:2)
B(24,10,4,MOSSY_COBBLESTONE)
B(0,11,4,MOSSY_COBBLESTONE)
B(1,11,4,STONEBRICK:2)
B(7,11,4,STONEBRICK:2)
B(8,11,4,STONE)
B(13,11,4,STONEBRICK:2)
B(14,11,4,STONEBRICK)
B(24,11,4,MOSSY_COBBLESTONE)
B(0,12,4,STONEBRICK)
B(1,12,4,STONE)
B(2,12,4,STONEBRICK:2)
B(6,12,4,STONEBRICK:1)
B(7,12,4,MOSSY_COBBLESTONE)
B(8,12,4,STONEBRICK)
B(15,12,4,STONEBRICK:1)
B(16,12,4,STONEBRICK:3)
B(24,12,4,STONE)
B(16,13,4,EMERALD_ORE)
B(24,13,4,STONE)
B(16,14,4,STONE)
B(24,14,4,STONE)
B(16,15,4,STONE)
B(17,15,4,STONEBRICK:2)
B(23,15,4,STONEBRICK:1)
B(24,15,4,MOSSY_COBBLESTONE)
B(16,16,4,STONEBRICK:2)
B(17,16,4,EMERALD_ORE)
B(18,16,4,STONEBRICK)
B(22,16,4,STONEBRICK:1)
B(23,16,4,EMERALD_ORE)
B(24,16,4,STONEBRICK:2)
B(0,4,5,STONEBRICK)
B(1,4,5,STONEBRICK:1)
B(2,4,5,STONEBRICK:1)
B(3,4,5,DIRT:1)
B(4,4,5,GRASS)
B(5,4,5,DIRT:1)
B(6,4,5,STONEBRICK)
B(7,4,5,STONEBRICK:2)
B(8,4,5,STONEBRICK)
B(9,4,5,STONEBRICK)
B(0,5,5,MOSSY_COBBLESTONE)
B(8,5,5,STONEBRICK:2)
B(9,5,5,STONEBRICK:2)
B(10,5,5,STONEBRICK:1)
B(11,5,5,STONEBRICK)
B(0,6,5,MOSSY_COBBLESTONE)
B(8,6,5,STONEBRICK:2)
B(9,6,5,STONEBRICK:1)
B(10,6,5,STONEBRICK)
B(11,6,5,STONEBRICK:1)
B(12,6,5,STONEBRICK:1)
B(13,6,5,STONEBRICK)
B(0,7,5,STONE)
B(8,7,5,STONEBRICK:2)
B(9,7,5,STONEBRICK:1)
B(10,7,5,STONEBRICK:2)
B(11,7,5,STONEBRICK:1)
B(12,7,5,STONEBRICK)
B(13,7,5,STONEBRICK)
B(14,7,5,STONEBRICK)
B(15,7,5,STONEBRICK)
B(0,8,5,MOSSY_COBBLESTONE)
B(8,8,5,STONEBRICK:3)
B(9,8,5,STONEBRICK:2)
B(10,8,5,STONEBRICK)
B(11,8,5,STONEBRICK:1)
B(12,8,5,STONEBRICK:1)
B(13,8,5,STONEBRICK:2)
B(14,8,5,STONEBRICK)
B(15,8,5,STONEBRICK)
B(16,8,5,STONEBRICK:2)
B(17,8,5,STONEBRICK:1)
B(18,8,5,STONEBRICK)
B(19,8,5,DIRT:1)
B(20,8,5,GRASS)
B(21,8,5,GRASS)
B(22,8,5,STONEBRICK:1)
B(23,8,5,STONEBRICK:1)
B(24,8,5,STONEBRICK)
B(0,9,5,STONE)
B(8,9,5,MOSSY_COBBLESTONE)
B(9,9,5,STONEBRICK)
B(10,9,5,STONEBRICK)
B(11,9,5,STONEBRICK)
B(12,9,5,STONEBRICK)
B(13,9,5,STONEBRICK:1)
B(14,9,5,STONEBRICK)
B(15,9,5,STONEBRICK:2)
B(16,9,5,STONEBRICK:1)
B(24,9,5,STONE)
B(0,10,5,STONE)
B(8,10,5,STONE)
B(11,10,5,STONEBRICK:2)
B(12,10,5,STONEBRICK:2)
B(13,10,5,STONEBRICK:1)
B(14,10,5,STONEBRICK:1)
B(15,10,5,STONEBRICK:1)
B(16,10,5,STONEBRICK:1)
B(24,10,5,STONE)
B(0,11,5,MOSSY_COBBLESTONE)
B(1,11,5,STONEBRICK:1)
B(7,11,5,STONEBRICK:1)
B(8,11,5,STONE)
B(13,11,5,STONEBRICK)
B(14,11,5,STONEBRICK:2)
B(15,11,5,STONEBRICK:2)
B(16,11,5,STONEBRICK:1)
B(24,11,5,MOSSY_COBBLESTONE)
B(0,12,5,STONEBRICK:1)
B(1,12,5,MOSSY_COBBLESTONE)
B(2,12,5,STONEBRICK)
B(6,12,5,STONEBRICK:1)
B(7,12,5,MOSSY_COBBLESTONE)
B(8,12,5,STONEBRICK)
B(15,12,5,STONEBRICK)
B(16,12,5,STONEBRICK:3)
B(24,12,5,MOSSY_COBBLESTONE)
B(16,13,5,MOSSY_COBBLESTONE)
B(24,13,5,MOSSY_COBBLESTONE)
B(16,14,5,MOSSY_COBBLESTONE)
B(24,14,5,STONE)
B(16,15,5,MOSSY_COBBLESTONE)
B(17,15,5,STONEBRICK:1)
B(23,15,5,STONEBRICK:2)
B(24,15,5,MOSSY_COBBLESTONE)
B(16,16,5,STONEBRICK)
B(17,16,5,MOSSY_COBBLESTONE)
B(18,16,5,STONEBRICK:1)
B(22,16,5,STONEBRICK:1)
B(23,16,5,STONE)
B(24,16,5,STONEBRICK:1)
B(0,4,6,STONEBRICK)
B(1,4,6,STONEBRICK:1)
B(2,4,6,STONEBRICK)
B(3,4,6,STONEBRICK)
B(4,4,6,STONEBRICK:2)
B(5,4,6,STONEBRICK)
B(6,4,6,STONEBRICK:2)
B(7,4,6,STONEBRICK:1)
B(8,4,6,STONEBRICK:1)
B(0,5,6,EMERALD_ORE)
B(8,5,6,STONE)
B(0,6,6,MOSSY_COBBLESTONE)
B(8,6,6,MOSSY_COBBLESTONE)
B(0,7,6,MOSSY_COBBLESTONE)
B(8,7,6,MOSSY_COBBLESTONE)
B(0,8,6,STONE)
B(8,8,6,MOSSY_COBBLESTONE)
B(16,8,6,STONEBRICK:1)
B(17,8,6,STONEBRICK:2)
B(18,8,6,STONEBRICK)
B(19,8,6,STONEBRICK)
B(20,8,6,STONEBRICK:1)
B(21,8,6,STONEBRICK:2)
B(22,8,6,STONEBRICK:1)
B(23,8,6,STONEBRICK:1)
B(24,8,6,STONEBRICK:2)
B(0,9,6,STONE)
B(8,9,6,EMERALD_ORE)
B(16,9,6,STONE)
B(24,9,6,MOSSY_COBBLESTONE)
B(0,10,6,EMERALD_ORE)
B(8,10,6,MOSSY_COBBLESTONE)
B(16,10,6,MOSSY_COBBLESTONE)
B(24,10,6,STONE)
B(0,11,6,MOSSY_COBBLESTONE)
B(1,11,6,STONEBRICK)
B(7,11,6,STONEBRICK:1)
B(8,11,6,MOSSY_COBBLESTONE)
B(16,11,6,STONE)
B(24,11,6,STONE)
B(0,12,6,STONEBRICK:2)
B(1,12,6,STONE)
B(2,12,6,STONEBRICK:2)
B(3,12,6,STONEBRICK:1)
B(4,12,6,STONEBRICK:1)
B(5,12,6,STONEBRICK:2)
B(6,12,6,STONEBRICK:1)
B(7,12,6,STONE)
B(8,12,6,STONEBRICK)
B(16,12,6,MOSSY_COBBLESTONE)
B(24,12,6,MOSSY_COBBLESTONE)
B(16,13,6,EMERALD_ORE)
B(24,13,6,STONE)
B(16,14,6,STONE)
B(24,14,6,STONE)
B(16,15,6,EMERALD_ORE)
B(17,15,6,STONEBRICK)
B(23,15,6,STONEBRICK)
B(24,15,6,STONE)
B(16,16,6,STONEBRICK:2)
B(17,16,6,STONE)
B(18,16,6,STONEBRICK:1)
B(19,16,6,STONEBRICK:1)
B(20,16,6,STONEBRICK)
B(21,16,6,STONEBRICK:2)
B(22,16,6,STONEBRICK:2)
B(23,16,6,STONE)
B(24,16,6,STONEBRICK:1)
B(0,4,7,STONEBRICK:1)
B(1,4,7,STONEBRICK:1)
B(2,4,7,STONEBRICK)
B(3,4,7,STONEBRICK)
B(4,4,7,STONEBRICK:2)
B(5,4,7,STONEBRICK)
B(6,4,7,STONEBRICK:1)
B(7,4,7,STONEBRICK)
B(8,4,7,STONEBRICK:2)
B(0,5,7,STONE)
B(1,5,7,MOSSY_COBBLESTONE)
B(7,5,7,STONE)
B(8,5,7,STONE)
B(0,6,7,EMERALD_ORE)
B(1,6,7,STONE)
B(7,6,7,MOSSY_COBBLESTONE)
B(8,6,7,STONE)
B(0,7,7,MOSSY_COBBLESTONE)
B(1,7,7,STONE)
B(7,7,7,MOSSY_COBBLESTONE)
B(8,7,7,STONE)
B(0,8,7,STONE)
B(1,8,7,STONEBRICK:3)
B(7,8,7,STONEBRICK:3)
B(8,8,7,STONE)
B(16,8,7,STONEBRICK)
B(17,8,7,STONEBRICK:2)
B(18,8,7,STONEBRICK)
B(19,8,7,STONEBRICK)
B(20,8,7,STONEBRICK:1)
B(21,8,7,STONEBRICK:2)
B(22,8,7,STONEBRICK)
B(23,8,7,STONEBRICK)
B(24,8,7,STONEBRICK)
B(0,9,7,MOSSY_COBBLESTONE)
B(1,9,7,STONEBRICK)
B(7,9,7,STONEBRICK:1)
B(8,9,7,EMERALD_ORE)
B(16,9,7,MOSSY_COBBLESTONE)
B(17,9,7,STONE)
B(23,9,7,MOSSY_COBBLESTONE)
B(24,9,7,STONE)
B(0,10,7,MOSSY_COBBLESTONE)
B(1,10,7,STONEBRICK)
B(7,10,7,STONEBRICK:2)
B(8,10,7,STONE)
B(16,10,7,STONE)
B(17,10,7,MOSSY_COBBLESTONE)
B(23,10,7,MOSSY_COBBLESTONE)
B(24,10,7,STONE)
B(0,11,7,MOSSY_COBBLESTONE)
B(1,11,7,STONEBRICK:1)
B(2,11,7,STONEBRICK:2)
B(3,11,7,STONEBRICK:1)
B(4,11,7,STONEBRICK:1)
B(5,11,7,STONEBRICK:2)
B(6,11,7,STONEBRICK:2)
B(7,11,7,STONEBRICK:1)
B(8,11,7,STONE)
B(16,11,7,STONE)
B(17,11,7,STONE)
B(23,11,7,STONE)
B(24,11,7,STONE)
B(0,12,7,STONEBRICK:2)
B(1,12,7,STONE)
B(2,12,7,MOSSY_COBBLESTONE)
B(3,12,7,STONE)
B(4,12,7,EMERALD_ORE)
B(5,12,7,STONE)
B(6,12,7,EMERALD_ORE)
B(7,12,7,STONE)
B(8,12,7,STONEBRICK:2)
B(16,12,7,MOSSY_COBBLESTONE)
B(17,12,7,STONEBRICK:3)
B(23,12,7,STONEBRICK:3)
B(24,12,7,STONE)
B(16,13,7,MOSSY_COBBLESTONE)
B(17,13,7,STONEBRICK:1)
B(23,13,7,STONEBRICK)
B(24,13,7,STONE)
B(16,14,7,MOSSY_COBBLESTONE)
B(17,14,7,STONEBRICK:2)
B(23,14,7,STONEBRICK:1)
B(24,14,7,MOSSY_COBBLESTONE)
B(16,15,7,STONE)
B(17,15,7,STONEBRICK)
B(18,15,7,STONEBRICK)
B(19,15,7,STONEBRICK)
B(20,15,7,STONEBRICK:2)
B(21,15,7,STONEBRICK:1)
B(22,15,7,STONEBRICK)
B(23,15,7,STONEBRICK:2)
B(24,15,7,STONE)
B(16,16,7,STONEBRICK:2)
B(17,16,7,STONE)
B(18,16,7,MOSSY_COBBLESTONE)
B(19,16,7,STONE)
B(20,16,7,STONE)
B(21,16,7,MOSSY_COBBLESTONE)
B(22,16,7,MOSSY_COBBLESTONE)
B(23,16,7,MOSSY_COBBLESTONE)
B(24,16,7,STONEBRICK)
B(0,4,8,STONEBRICK:2)
B(1,4,8,STONEBRICK)
B(2,4,8,STONEBRICK)
B(3,4,8,STONEBRICK)
B(4,4,8,STONEBRICK:2)
B(5,4,8,STONEBRICK)
B(6,4,8,STONEBRICK:1)
B(7,4,8,STONEBRICK)
B(8,4,8,STONEBRICK:2)
B(0,5,8,STONEBRICK:2)
B(1,5,8,STONE)
B(2,5,8,MOSSY_COBBLESTONE)
B(3,5,8,STONEBRICK:2)
B(5,5,8,STONEBRICK:2)
B(6,5,8,STONE)
B(7,5,8,STONE)
B(8,5,8,STONEBRICK:2)
B(0,6,8,STONEBRICK:1)
B(1,6,8,MOSSY_COBBLESTONE)
B(2,6,8,STONE)
B(3,6,8,STONEBRICK:2)
B(5,6,8,STONEBRICK)
B(6,6,8,STONE)
B(7,6,8,STONE)
B(8,6,8,STONEBRICK)
B(0,7,8,STONEBRICK:2)
B(1,7,8,MOSSY_COBBLESTONE)
B(2,7,8,MOSSY_COBBLESTONE)
B(3,7,8,STONEBRICK:1)
B(5,7,8,STONEBRICK:2)
B(6,7,8,STONE)
B(7,7,8,STONE)
B(8,7,8,STONEBRICK)
B(0,8,8,STONEBRICK:1)
B(1,8,8,MOSSY_COBBLESTONE)
B(2,8,8,STONE)
B(3,8,8,STONEBRICK:3)
B(4,8,8,STONEBRICK:3)
B(5,8,8,STONEBRICK:3)
B(6,8,8,MOSSY_COBBLESTONE)
B(7,8,8,MOSSY_COBBLESTONE)
B(8,8,8,STONEBRICK:1)
B(16,8,8,STONEBRICK)
B(17,8,8,STONEBRICK:1)
B(18,8,8,STONEBRICK:2)
B(19,8,8,STONEBRICK:2)
B(20,8,8,STONEBRICK:2)
B(21,8,8,STONEBRICK:2)
B(22,8,8,STONEBRICK:2)
B(23,8,8,STONEBRICK:2)
B(24,8,8,STONEBRICK:1)
B(0,9,8,STONEBRICK)
B(1,9,8,MOSSY_COBBLESTONE)
B(2,9,8,MOSSY_COBBLESTONE)
B(3,9,8,MOSSY_COBBLESTONE)
B(4,9,8,MOSSY_COBBLESTONE)
B(5,9,8,MOSSY_COBBLESTONE)
B(6,9,8,STONE)
B(7,9,8,STONE)
B(8,9,8,STONEBRICK)
B(16,9,8,STONEBRICK:1)
B(17,9,8,MOSSY_COBBLESTONE)
B(18,9,8,STONE)
B(19,9,8,STONEBRICK:1)
B(21,9,8,STONEBRICK:2)
B(22,9,8,MOSSY_COBBLESTONE)
B(23,9,8,MOSSY_COBBLESTONE)
B(24,9,8,STONEBRICK)
B(0,10,8,STONEBRICK:1)
B(1,10,8,MOSSY_COBBLESTONE)
B(2,10,8,MOSSY_COBBLESTONE)
B(3,10,8,STONE)
B(4,10,8,STONE)
B(5,10,8,MOSSY_COBBLESTONE)
B(6,10,8,EMERALD_ORE)
B(7,10,8,MOSSY_COBBLESTONE)
B(8,10,8,STONEBRICK)
B(16,10,8,STONEBRICK)
B(17,10,8,MOSSY_COBBLESTONE)
B(18,10,8,EMERALD_ORE)
B(19,10,8,STONEBRICK:1)
B(21,10,8,STONEBRICK)
B(22,10,8,EMERALD_ORE)
B(23,10,8,STONE)
B(24,10,8,STONEBRICK:1)
B(0,11,8,STONEBRICK:1)
B(1,11,8,MOSSY_COBBLESTONE)
B(2,11,8,MOSSY_COBBLESTONE)
B(3,11,8,STONE)
B(4,11,8,STONE)
B(5,11,8,MOSSY_COBBLESTONE)
B(6,11,8,MOSSY_COBBLESTONE)
B(7,11,8,MOSSY_COBBLESTONE)
B(8,11,8,STONEBRICK:1)
B(16,11,8,STONEBRICK:2)
B(17,11,8,STONE)
B(18,11,8,EMERALD_ORE)
B(19,11,8,STONEBRICK)
B(21,11,8,STONEBRICK:1)
B(22,11,8,STONE)
B(23,11,8,STONE)
B(24,11,8,STONEBRICK)
B(0,12,8,STONEBRICK:2)
B(1,12,8,STONEBRICK:1)
B(2,12,8,STONEBRICK:1)
B(3,12,8,STONEBRICK)
B(4,12,8,STONEBRICK:2)
B(5,12,8,STONEBRICK:2)
B(6,12,8,STONEBRICK:1)
B(7,12,8,STONEBRICK)
B(8,12,8,STONEBRICK)
B(16,12,8,STONEBRICK:2)
B(17,12,8,STONE)
B(18,12,8,STONE)
B(19,12,8,STONEBRICK:3)
B(20,12,8,STONEBRICK:3)
B(21,12,8,STONEBRICK:3)
B(22,12,8,MOSSY_COBBLESTONE)
B(23,12,8,MOSSY_COBBLESTONE)
B(24,12,8,STONEBRICK:2)
B(16,13,8,STONEBRICK:2)
B(17,13,8,MOSSY_COBBLESTONE)
B(18,13,8,MOSSY_COBBLESTONE)
B(19,13,8,EMERALD_ORE)
B(20,13,8,EMERALD_ORE)
B(21,13,8,STONE)
B(22,13,8,STONE)
B(23,13,8,STONE)
B(24,13,8,STONEBRICK)
B(16,14,8,STONEBRICK:2)
B(17,14,8,EMERALD_ORE)
B(18,14,8,MOSSY_COBBLESTONE)
B(19,14,8,STONE)
B(20,14,8,MOSSY_COBBLESTONE)
B(21,14,8,MOSSY_COBBLESTONE)
B(22,14,8,MOSSY_COBBLESTONE)
B(23,14,8,MOSSY_COBBLESTONE)
B(24,14,8,STONEBRICK)
B(16,15,8,STONEBRICK:2)
B(17,15,8,MOSSY_COBBLESTONE)
B(18,15,8,MOSSY_COBBLESTONE)
B(19,15,8,STONE)
B(20,15,8,STONE)
B(21,15,8,STONE)
B(22,15,8,MOSSY_COBBLESTONE)
B(23,15,8,MOSSY_COBBLESTONE)
B(24,15,8,STONEBRICK)
B(16,16,8,STONEBRICK)
B(17,16,8,STONEBRICK:2)
B(18,16,8,STONEBRICK:1)
B(19,16,8,STONEBRICK:2)
B(20,16,8,STONEBRICK:2)
B(21,16,8,STONEBRICK:2)
B(22,16,8,STONEBRICK)
B(23,16,8,STONEBRICK:2)
B(24,16,8,STONEBRICK:1)
B(3,3,9,STONEBRICK)
B(4,3,9,STONEBRICK:2)
B(5,3,9,STONEBRICK)
B(3,4,9,STONEBRICK:1)
B(5,4,9,STONEBRICK:2)
B(3,5,9,STONEBRICK:1)
B(5,5,9,STONEBRICK)
B(3,6,9,STONEBRICK:1)
B(5,6,9,STONEBRICK)
B(3,7,9,STONEBRICK)
B(5,7,9,STONEBRICK)
B(3,8,9,STONEBRICK:2)
B(4,8,9,STONEBRICK:2)
B(5,8,9,STONEBRICK:1)
B(19,8,9,STONEBRICK:2)
B(20,8,9,STONEBRICK)
B(21,8,9,STONEBRICK:1)
B(19,9,9,STONEBRICK:1)
B(21,9,9,STONEBRICK:1)
B(19,10,9,STONEBRICK)
B(21,10,9,STONEBRICK:2)
B(19,11,9,STONEBRICK:1)
B(21,11,9,STONEBRICK)
B(19,12,9,STONEBRICK:2)
B(21,12,9,STONEBRICK)
B(19,13,9,STONEBRICK:2)
B(20,13,9,STONEBRICK:2)
B(21,13,9,STONEBRICK:2)
B(3,3,10,STONEBRICK:1)
B(4,3,10,STONEBRICK)
B(5,3,10,STONEBRICK:1)
B(3,4,10,STONEBRICK:1)
B(5,4,10,STONEBRICK:1)
B(3,5,10,STONEBRICK:1)
B(5,5,10,STONEBRICK)
B(3,6,10,STONEBRICK:1)
B(5,6,10,STONEBRICK:1)
B(3,7,10,STONEBRICK:2)
B(4,7,10,STONEBRICK:1)
B(5,7,10,STONEBRICK)
B(19,9,10,STONEBRICK:1)
B(20,9,10,STONEBRICK:2)
B(21,9,10,STONEBRICK:1)
B(19,10,10,STONEBRICK)
B(21,10,10,STONEBRICK)
B(19,11,10,STONEBRICK:1)
B(21,11,10,STONEBRICK)
B(19,12,10,STONEBRICK)
B(21,12,10,STONEBRICK:2)
B(19,13,10,STONEBRICK:2)
B(20,13,10,STONEBRICK:2)
B(21,13,10,STONEBRICK)
B(3,2,11,STONEBRICK:2)
B(4,2,11,STONEBRICK)
B(5,2,11,STONEBRICK:2)
B(3,3,11,STONEBRICK)
B(5,3,11,STONEBRICK:2)
B(3,4,11,STONEBRICK)
B(5,4,11,STONEBRICK:1)
B(3,5,11,STONEBRICK)
B(5,5,11,STONEBRICK:2)
B(3,6,11,STONEBRICK)
B(5,6,11,STONEBRICK)
B(3,7,11,STONEBRICK:2)
B(4,7,11,STONEBRICK)
B(5,7,11,STONEBRICK:1)
B(19,9,11,STONEBRICK:1)
B(20,9,11,STONEBRICK:1)
B(21,9,11,STONEBRICK:1)
B(19,10,11,STONEBRICK)
B(21,10,11,STONEBRICK)
B(19,11,11,STONEBRICK)
B(21,11,11,STONEBRICK)
B(19,12,11,STONEBRICK:1)
B(21,12,11,STONEBRICK:1)
B(19,13,11,STONEBRICK:1)
B(21,13,11,STONEBRICK)
B(19,14,11,STONEBRICK:1)
B(20,14,11,STONEBRICK)
B(21,14,11,STONEBRICK:2)
B(3,2,12,STONEBRICK:2)
B(4,2,12,STONEBRICK:2)
B(5,2,12,STONEBRICK:2)
B(3,3,12,STONEBRICK:1)
B(5,3,12,STONEBRICK:2)
B(3,4,12,STONEBRICK)
B(5,4,12,STONEBRICK)
B(3,5,12,STONEBRICK)
B(5,5,12,STONEBRICK)
B(3,6,12,STONEBRICK)
B(4,6,12,STONEBRICK:1)
B(5,6,12,STONEBRICK:1)
B(19,10,12,STONEBRICK:2)
B(20,10,12,STONEBRICK)
B(21,10,12,STONEBRICK)
B(19,11,12,STONEBRICK:1)
B(21,11,12,STONEBRICK:1)
B(19,12,12,STONEBRICK)
B(21,12,12,STONEBRICK:2)
B(19,13,12,STONEBRICK)
B(21,13,12,STONEBRICK:1)
B(19,14,12,STONEBRICK:1)
B(20,14,12,STONEBRICK)
B(21,14,12,STONEBRICK:2)
B(3,1,13,STONEBRICK:2)
B(4,1,13,STONEBRICK:2)
B(5,1,13,STONEBRICK:2)
B(3,2,13,STONEBRICK:1)
B(5,2,13,STONEBRICK:2)
B(3,3,13,STONEBRICK:2)
B(5,3,13,STONEBRICK:1)
B(3,4,13,STONEBRICK:2)
B(5,4,13,STONEBRICK)
B(3,5,13,STONEBRICK:2)
B(5,5,13,STONEBRICK:2)
B(3,6,13,STONEBRICK:1)
B(4,6,13,STONEBRICK:1)
B(5,6,13,STONEBRICK:2)
B(19,10,13,STONEBRICK)
B(20,10,13,STONEBRICK)
B(21,10,13,STONEBRICK:1)
B(19,11,13,STONEBRICK:1)
B(21,11,13,STONEBRICK:2)
B(19,12,13,STONEBRICK)
B(21,12,13,STONEBRICK)
B(19,13,13,STONEBRICK:1)
B(21,13,13,STONEBRICK)
B(19,14,13,STONEBRICK:2)
B(21,14,13,STONEBRICK:2)
B(19,15,13,STONEBRICK)
B(20,15,13,STONEBRICK:1)
B(21,15,13,STONEBRICK)
B(3,1,14,STONEBRICK:2)
B(4,1,14,STONEBRICK)
B(5,1,14,STONEBRICK)
B(3,2,14,STONEBRICK)
B(5,2,14,STONEBRICK:1)
B(3,3,14,STONEBRICK:2)
B(5,3,14,STONEBRICK:1)
B(3,4,14,STONEBRICK)
B(5,4,14,STONEBRICK)
B(3,5,14,STONEBRICK)
B(4,5,14,STONEBRICK)
B(5,5,14,STONEBRICK:1)
B(19,11,14,STONEBRICK)
B(20,11,14,STONEBRICK:2)
B(21,11,14,STONEBRICK:1)
B(19,12,14,STONEBRICK:1)
B(21,12,14,STONEBRICK:2)
B(19,13,14,STONEBRICK)
B(21,13,14,STONEBRICK)
B(19,14,14,STONEBRICK:2)
B(21,14,14,STONEBRICK)
B(19,15,14,STONEBRICK)
B(20,15,14,STONEBRICK)
B(21,15,14,STONEBRICK:2)
B(3,0,15,STONEBRICK)
B(4,0,15,STONEBRICK)
B(5,0,15,STONEBRICK:2)
B(3,1,15,STONEBRICK:2)
B(5,1,15,STONEBRICK:2)
B(3,2,15,STONEBRICK)
B(5,2,15,STONEBRICK)
B(3,3,15,STONEBRICK:2)
B(5,3,15,STONEBRICK)
B(3,4,15,STONEBRICK)
B(5,4,15,STONEBRICK)
B(3,5,15,STONEBRICK:2)
B(4,5,15,STONEBRICK:2)
B(5,5,15,STONEBRICK:1)
B(19,11,15,STONEBRICK)
B(20,11,15,STONEBRICK:1)
B(21,11,15,STONEBRICK:2)
B(19,12,15,STONEBRICK:2)
B(21,12,15,STONEBRICK)
B(19,13,15,STONEBRICK:1)
B(21,13,15,STONEBRICK:1)
B(19,14,15,STONEBRICK:1)
B(21,14,15,STONEBRICK:1)
B(19,15,15,STONEBRICK)
B(21,15,15,STONEBRICK)
B(19,16,15,STONEBRICK)
B(20,16,15,STONEBRICK:1)
B(21,16,15,STONEBRICK:1)
B(0,0,16,STONEBRICK:2)
B(1,0,16,STONEBRICK:2)
B(2,0,16,STONEBRICK)
B(3,0,16,STONEBRICK:1)
B(4,0,16,STONEBRICK)
B(5,0,16,STONEBRICK:2)
B(6,0,16,STONEBRICK)
B(7,0,16,STONEBRICK)
B(8,0,16,STONEBRICK:2)
B(0,1,16,STONEBRICK:2)
B(1,1,16,MOSSY_COBBLESTONE)
B(2,1,16,STONE)
B(3,1,16,STONEBRICK)
B(5,1,16,STONEBRICK:2)
B(6,1,16,STONE)
B(7,1,16,STONE)
B(8,1,16,STONEBRICK:2)
B(0,2,16,STONEBRICK)
B(1,2,16,STONE)
B(2,2,16,MOSSY_COBBLESTONE)
B(3,2,16,STONEBRICK:1)
B(5,2,16,STONEBRICK:2)
B(6,2,16,STONE)
B(7,2,16,STONE)
B(8,2,16,STONEBRICK:2)
B(0,3,16,STONEBRICK)
B(1,3,16,MOSSY_COBBLESTONE)
B(2,3,16,STONE)
B(3,3,16,STONEBRICK:2)
B(5,3,16,STONEBRICK:2)
B(6,3,16,EMERALD_ORE)
B(7,3,16,STONE)
B(8,3,16,STONEBRICK:1)
B(0,4,16,STONEBRICK:1)
B(1,4,16,MOSSY_COBBLESTONE)
B(2,4,16,STONE)
B(3,4,16,STONEBRICK:3)
B(4,4,16,STONEBRICK:3)
B(5,4,16,STONEBRICK:3)
B(6,4,16,STONE)
B(7,4,16,STONE)
B(8,4,16,STONEBRICK)
B(0,5,16,STONEBRICK:2)
B(1,5,16,EMERALD_ORE)
B(2,5,16,STONE)
B(3,5,16,STONE)
B(4,5,16,MOSSY_COBBLESTONE)
B(5,5,16,STONE)
B(6,5,16,STONE)
B(7,5,16,STONE)
B(8,5,16,STONEBRICK:2)
B(0,6,16,STONEBRICK:1)
B(1,6,16,MOSSY_COBBLESTONE)
B(2,6,16,STONE)
B(3,6,16,STONE)
B(4,6,16,MOSSY_COBBLESTONE)
B(5,6,16,EMERALD_ORE)
B(6,6,16,STONE)
B(7,6,16,STONE)
B(8,6,16,STONEBRICK:1)
B(0,7,16,STONEBRICK:1)
B(1,7,16,STONE)
B(2,7,16,STONE)
B(3,7,16,STONE)
B(4,7,16,STONE)
B(5,7,16,MOSSY_COBBLESTONE)
B(6,7,16,STONE)
B(7,7,16,MOSSY_COBBLESTONE)
B(8,7,16,STONEBRICK:2)
B(0,8,16,STONEBRICK:2)
B(1,8,16,STONEBRICK:1)
B(2,8,16,STONEBRICK:2)
B(3,8,16,STONEBRICK)
B(4,8,16,STONEBRICK)
B(5,8,16,STONEBRICK:1)
B(6,8,16,STONEBRICK:2)
B(7,8,16,STONEBRICK:1)
B(8,8,16,STONEBRICK:2)
B(16,12,16,STONEBRICK:1)
B(17,12,16,STONEBRICK:1)
B(18,12,16,STONEBRICK:1)
B(19,12,16,STONEBRICK)
B(20,12,16,STONEBRICK:1)
B(21,12,16,STONEBRICK)
B(22,12,16,STONEBRICK:1)
B(23,12,16,STONEBRICK:2)
B(24,12,16,STONEBRICK)
B(16,13,16,STONEBRICK:1)
B(17,13,16,STONE)
B(18,13,16,STONE)
B(19,13,16,STONEBRICK)
B(21,13,16,STONEBRICK)
B(22,13,16,MOSSY_COBBLESTONE)
B(23,13,16,STONE)
B(24,13,16,STONEBRICK:2)
B(16,14,16,STONEBRICK:1)
B(17,14,16,MOSSY_COBBLESTONE)
B(18,14,16,MOSSY_COBBLESTONE)
B(19,14,16,STONEBRICK:1)
B(21,14,16,STONEBRICK)
B(22,14,16,STONE)
B(23,14,16,MOSSY_COBBLESTONE)
B(24,14,16,STONEBRICK:2)
B(16,15,16,STONEBRICK:1)
B(17,15,16,EMERALD_ORE)
B(18,15,16,STONE)
B(19,15,16,STONEBRICK:1)
B(21,15,16,STONEBRICK:2)
B(22,15,16,EMERALD_ORE)
B(23,15,16,MOSSY_COBBLESTONE)
B(24,15,16,STONEBRICK)
B(0,16,16,STONEBRICK)
B(1,16,16,STONEBRICK)
B(2,16,16,STONEBRICK)
B(3,16,16,STONEBRICK)
B(4,16,16,STONEBRICK:1)
B(5,16,16,STONEBRICK:1)
B(6,16,16,STONEBRICK:1)
B(7,16,16,STONEBRICK:1)
B(8,16,16,STONEBRICK:2)
B(16,16,16,STONEBRICK:2)
B(17,16,16,MOSSY_COBBLESTONE)
B(18,16,16,EMERALD_ORE)
B(19,16,16,STONEBRICK:3)
B(20,16,16,STONEBRICK:3)
B(21,16,16,STONEBRICK:3)
B(22,16,16,MOSSY_COBBLESTONE)
B(23,16,16,MOSSY_COBBLESTONE)
B(24,16,16,STONEBRICK:2)
B(0,17,16,STONEBRICK:1)
B(1,17,16,STONE)
B(2,17,16,MOSSY_COBBLESTONE)
B(3,17,16,STONEBRICK)
B(5,17,16,STONEBRICK)
B(6,17,16,MOSSY_COBBLESTONE)
B(7,17,16,STONE)
B(8,17,16,STONEBRICK:1)
B(16,17,16,STONEBRICK:1)
B(17,17,16,MOSSY_COBBLESTONE)
B(18,17,16,STONE)
B(19,17,16,STONE)
B(20,17,16,STONE)
B(21,17,16,STONE)
B(22,17,16,STONE)
B(23,17,16,STONE)
B(24,17,16,STONEBRICK:2)
B(0,18,16,STONEBRICK)
B(1,18,16,MOSSY_COBBLESTONE)
B(2,18,16,MOSSY_COBBLESTONE)
B(3,18,16,STONEBRICK:1)
B(5,18,16,STONEBRICK:2)
B(6,18,16,EMERALD_ORE)
B(7,18,16,STONE)
B(8,18,16,STONEBRICK:2)
B(16,18,16,STONEBRICK)
B(17,18,16,MOSSY_COBBLESTONE)
B(18,18,16,MOSSY_COBBLESTONE)
B(19,18,16,MOSSY_COBBLESTONE)
B(20,18,16,MOSSY_COBBLESTONE)
B(21,18,16,MOSSY_COBBLESTONE)
B(22,18,16,STONE)
B(23,18,16,MOSSY_COBBLESTONE)
B(24,18,16,STONEBRICK:1)
B(0,19,16,STONEBRICK:2)
B(1,19,16,STONE)
B(2,19,16,EMERALD_ORE)
B(3,19,16,STONEBRICK)
B(5,19,16,STONEBRICK:2)
B(6,19,16,MOSSY_COBBLESTONE)
B(7,19,16,STONE)
B(8,19,16,STONEBRICK)
B(16,19,16,STONEBRICK:2)
B(17,19,16,MOSSY_COBBLESTONE)
B(18,19,16,STONE)
B(19,19,16,EMERALD_ORE)
B(20,19,16,MOSSY_COBBLESTONE)
B(21,19,16,MOSSY_COBBLESTONE)
B(22,19,16,MOSSY_COBBLESTONE)
B(23,19,16,MOSSY_COBBLESTONE)
B(24,19,16,STONEBRICK)
B(0,20,16,STONEBRICK:1)
B(1,20,16,MOSSY_COBBLESTONE)
B(2,20,16,MOSSY_COBBLESTONE)
B(3,20,16,STONEBRICK:3)
B(4,20,16,STONEBRICK:3)
B(5,20,16,STONEBRICK:3)
B(6,20,16,STONE)
B(7,20,16,EMERALD_ORE)
B(8,20,16,STONEBRICK:1)
B(16,20,16,STONEBRICK)
B(17,20,16,STONEBRICK:1)
B(18,20,16,STONEBRICK:1)
B(19,20,16,STONEBRICK:2)
B(20,20,16,STONEBRICK:1)
B(21,20,16,STONEBRICK)
B(22,20,16,STONEBRICK)
B(23,20,16,STONEBRICK:1)
B(24,20,16,STONEBRICK:1)
B(0,21,16,STONEBRICK)
B(1,21,16,MOSSY_COBBLESTONE)
B(2,21,16,STONE)
B(3,21,16,MOSSY_COBBLESTONE)
B(4,21,16,STONE)
B(5,21,16,STONE)
B(6,21,16,STONE)
B(7,21,16,MOSSY_COBBLESTONE)
B(8,21,16,STONEBRICK:2)
B(0,22,16,STONEBRICK:2)
B(1,22,16,MOSSY_COBBLESTONE)
B(2,22,16,STONE)
B(3,22,16,MOSSY_COBBLESTONE)
B(4,22,16,STONE)
B(5,22,16,MOSSY_COBBLESTONE)
B(6,22,16,STONE)
B(7,22,16,STONE)
B(8,22,16,STONEBRICK:2)
B(0,23,16,STONEBRICK)
B(1,23,16,EMERALD_ORE)
B(2,23,16,STONE)
B(3,23,16,STONE)
B(4,23,16,MOSSY_COBBLESTONE)
B(5,23,16,EMERALD_ORE)
B(6,23,16,STONE)
B(7,23,16,MOSSY_COBBLESTONE)
B(8,23,16,STONEBRICK:1)
B(0,24,16,STONEBRICK:2)
B(1,24,16,STONEBRICK:1)
B(2,24,16,STONEBRICK)
B(3,24,16,STONEBRICK:1)
B(4,24,16,STONEBRICK)
B(5,24,16,STONEBRICK:2)
B(6,24,16,STONEBRICK)
B(7,24,16,STONEBRICK)
B(8,24,16,STONEBRICK)
B(0,0,17,STONEBRICK)
B(1,0,17,STONEBRICK:1)
B(2,0,17,STONEBRICK)
B(3,0,17,STONEBRICK:1)
B(4,0,17,STONEBRICK)
B(5,0,17,STONEBRICK)
B(6,0,17,STONEBRICK)
B(7,0,17,STONEBRICK:2)
B(8,0,17,STONEBRICK:2)
B(0,1,17,STONE)
B(1,1,17,MOSSY_COBBLESTONE)
B(7,1,17,STONE)
B(8,1,17,MOSSY_COBBLESTONE)
B(0,2,17,STONE)
B(1,2,17,MOSSY_COBBLESTONE)
B(7,2,17,STONE)
B(8,2,17,EMERALD_ORE)
B(0,3,17,STONE)
B(1,3,17,MOSSY_COBBLESTONE)
B(7,3,17,STONE)
B(8,3,17,STONE)
B(0,4,17,STONE)
B(1,4,17,STONEBRICK:3)
B(7,4,17,STONEBRICK:3)
B(8,4,17,STONE)
B(0,5,17,MOSSY_COBBLESTONE)
B(1,5,17,STONEBRICK:1)
B(7,5,17,STONEBRICK)
B(8,5,17,STONE)
B(0,6,17,STONE)
B(1,6,17,STONEBRICK:1)
B(7,6,17,STONEBRICK)
B(8,6,17,STONE)
B(0,7,17,MOSSY_COBBLESTONE)
B(1,7,17,STONEBRICK:2)
B(2,7,17,STONEBRICK:2)
B(3,7,17,STONEBRICK:2)
B(4,7,17,STONEBRICK:1)
B(5,7,17,STONEBRICK:2)
B(6,7,17,STONEBRICK:2)
B(7,7,17,STONEBRICK:1)
B(8,7,17,MOSSY_COBBLESTONE)
B(0,8,17,STONEBRICK)
B(1,8,17,STONE)
B(2,8,17,STONE)
B(3,8,17,EMERALD_ORE)
B(4,8,17,STONE)
B(5,8,17,MOSSY_COBBLESTONE)
B(6,8,17,STONE)
B(7,8,17,STONE)
B(8,8,17,STONEBRICK)
B(16,12,17,STONEBRICK)
B(17,12,17,STONEBRICK:2)
B(18,12,17,STONEBRICK:2)
B(19,12,17,STONEBRICK:1)
B(20,12,17,STONEBRICK)
B(21,12,17,STONEBRICK:1)
B(22,12,17,STONEBRICK:2)
B(23,12,17,STONEBRICK:1)
B(24,12,17,STONEBRICK:2)
B(16,13,17,MOSSY_COBBLESTONE)
B(17,13,17,EMERALD_ORE)
B(23,13,17,STONE)
B(24,13,17,MOSSY_COBBLESTONE)
B(16,14,17,STONE)
B(17,14,17,MOSSY_COBBLESTONE)
B(23,14,17,MOSSY_COBBLESTONE)
B(24,14,17,EMERALD_ORE)
B(16,15,17,STONE)
B(17,15,17,MOSSY_COBBLESTONE)
B(23,15,17,STONE)
B(24,15,17,MOSSY_COBBLESTONE)
B(0,16,17,STONEBRICK)
B(1,16,17,STONEBRICK:1)
B(2,16,17,STONEBRICK:2)
B(3,16,17,STONEBRICK:1)
B(4,16,17,STONEBRICK:1)
B(5,16,17,STONEBRICK)
B(6,16,17,STONEBRICK:2)
B(7,16,17,STONEBRICK)
B(8,16,17,STONEBRICK:2)
B(16,16,17,STONE)
B(17,16,17,STONEBRICK:3)
B(23,16,17,STONEBRICK:3)
B(24,16,17,STONE)
B(0,17,17,EMERALD_ORE)
B(1,17,17,MOSSY_COBBLESTONE)
B(7,17,17,MOSSY_COBBLESTONE)
B(8,17,17,STONE)
B(16,17,17,MOSSY_COBBLESTONE)
B(17,17,17,STONEBRICK)
B(23,17,17,STONEBRICK)
B(24,17,17,EMERALD_ORE)
B(0,18,17,STONE)
B(1,18,17,MOSSY_COBBLESTONE)
B(7,18,17,STONE)
B(8,18,17,MOSSY_COBBLESTONE)
B(16,18,17,MOSSY_COBBLESTONE)
B(17,18,17,STONEBRICK:1)
B(23,18,17,STONEBRICK)
B(24,18,17,MOSSY_COBBLESTONE)
B(0,19,17,STONE)
B(1,19,17,MOSSY_COBBLESTONE)
B(7,19,17,STONE)
B(8,19,17,MOSSY_COBBLESTONE)
B(16,19,17,STONE)
B(17,19,17,STONEBRICK:1)
B(18,19,17,STONEBRICK:1)
B(19,19,17,STONEBRICK)
B(20,19,17,STONEBRICK:1)
B(21,19,17,STONEBRICK:1)
B(22,19,17,STONEBRICK:2)
B(23,19,17,STONEBRICK:1)
B(24,19,17,MOSSY_COBBLESTONE)
B(0,20,17,MOSSY_COBBLESTONE)
B(1,20,17,STONEBRICK:3)
B(7,20,17,STONEBRICK:3)
B(8,20,17,MOSSY_COBBLESTONE)
B(16,20,17,STONEBRICK)
B(17,20,17,STONE)
B(18,20,17,MOSSY_COBBLESTONE)
B(19,20,17,STONE)
B(20,20,17,STONE)
B(21,20,17,MOSSY_COBBLESTONE)
B(22,20,17,STONE)
B(23,20,17,MOSSY_COBBLESTONE)
B(24,20,17,STONEBRICK)
B(0,21,17,STONE)
B(1,21,17,STONEBRICK)
B(7,21,17,STONEBRICK)
B(8,21,17,STONE)
B(0,22,17,STONE)
B(1,22,17,STONEBRICK:2)
B(7,22,17,STONEBRICK:1)
B(8,22,17,STONE)
B(0,23,17,EMERALD_ORE)
B(1,23,17,STONEBRICK:2)
B(2,23,17,STONEBRICK:2)
B(3,23,17,STONEBRICK:1)
B(4,23,17,STONEBRICK:2)
B(5,23,17,STONEBRICK:2)
B(6,23,17,STONEBRICK)
B(7,23,17,STONEBRICK:1)
B(8,23,17,STONE)
B(0,24,17,STONEBRICK:2)
B(1,24,17,MOSSY_COBBLESTONE)
B(2,24,17,MOSSY_COBBLESTONE)
B(3,24,17,STONE)
B(4,24,17,MOSSY_COBBLESTONE)
B(5,24,17,STONE)
B(6,24,17,STONE)
B(7,24,17,MOSSY_COBBLESTONE)
B(8,24,17,STONEBRICK:1)
B(0,0,18,STONEBRICK:1)
B(1,0,18,STONEBRICK)
B(2,0,18,STONEBRICK:1)
B(3,0,18,STONEBRICK:1)
B(4,0,18,STONEBRICK:2)
B(5,0,18,STONEBRICK)
B(6,0,18,STONEBRICK:2)
B(7,0,18,STONEBRICK:1)
B(8,0,18,STONEBRICK:1)
B(0,1,18,STONE)
B(8,1,18,MOSSY_COBBLESTONE)
B(0,2,18,EMERALD_ORE)
B(8,2,18,STONE)
B(0,3,18,MOSSY_COBBLESTONE)
B(8,3,18,STONE)
B(0,4,18,STONE)
B(8,4,18,STONE)
B(0,5,18,STONE)
B(8,5,18,STONE)
B(0,6,18,STONE)
B(8,6,18,EMERALD_ORE)
B(0,7,18,STONE)
B(1,7,18,STONEBRICK)
B(7,7,18,STONEBRICK)
B(8,7,18,STONE)
B(0,8,18,STONEBRICK:1)
B(1,8,18,STONE)
B(2,8,18,STONEBRICK)
B(3,8,18,STONEBRICK:1)
B(4,8,18,STONEBRICK:2)
B(5,8,18,STONEBRICK:1)
B(6,8,18,STONEBRICK:1)
B(7,8,18,STONE)
B(8,8,18,STONEBRICK)
B(2,9,18,STONEBRICK:1)
B(3,9,18,STONE)
B(4,9,18,MOSSY_COBBLESTONE)
B(5,9,18,MOSSY_COBBLESTONE)
B(6,9,18,STONEBRICK:2)
B(2,10,18,STONEBRICK)
B(3,10,18,MOSSY_COBBLESTONE)
B(4,10,18,STONE)
B(5,10,18,STONE)
B(6,10,18,STONEBRICK:2)
B(2,11,18,STONEBRICK)
B(3,11,18,MOSSY_COBBLESTONE)
B(4,11,18,MOSSY_COBBLESTONE)
B(5,11,18,STONE)
B(6,11,18,STONEBRICK:2)
B(2,12,18,STONEBRICK:2)
B(3,12,18,MOSSY_COBBLESTONE)
B(4,12,18,MOSSY_COBBLESTONE)
B(5,12,18,MOSSY_COBBLESTONE)
B(6,12,18,STONEBRICK:2)
B(16,12,18,STONEBRICK)
B(17,12,18,STONEBRICK:2)
B(18,12,18,STONEBRICK:2)
B(19,12,18,STONEBRICK:1)
B(20,12,18,STONEBRICK)
B(21,12,18,STONEBRICK:1)
B(22,12,18,STONEBRICK:1)
B(23,12,18,STONEBRICK:1)
B(24,12,18,STONEBRICK)
B(2,13,18,STONEBRICK:1)
B(3,13,18,STONE)
B(4,13,18,MOSSY_COBBLESTONE)
B(5,13,18,MOSSY_COBBLESTONE)
B(6,13,18,STONEBRICK:2)
B(16,13,18,STONE)
B(24,13,18,STONE)
B(2,14,18,STONEBRICK)
B(3,14,18,STONE)
B(4,14,18,STONE)
B(5,14,18,STONE)
B(6,14,18,STONEBRICK:1)
B(16,14,18,MOSSY_COBBLESTONE)
B(24,14,18,STONE)
B(2,15,18,STONEBRICK)
B(3,15,18,STONE)
B(4,15,18,MOSSY_COBBLESTONE)
B(5,15,18,STONE)
B(6,15,18,STONEBRICK:2)
B(16,15,18,MOSSY_COBBLESTONE)
B(24,15,18,MOSSY_COBBLESTONE)
B(0,16,18,STONEBRICK:1)
B(1,16,18,STONEBRICK:2)
B(2,16,18,STONEBRICK:1)
B(3,16,18,STONEBRICK:2)
B(4,16,18,STONEBRICK:1)
B(5,16,18,STONEBRICK:1)
B(6,16,18,STONEBRICK)
B(7,16,18,STONEBRICK)
B(8,16,18,STONEBRICK:2)
B(16,16,18,MOSSY_COBBLESTONE)
B(24,16,18,MOSSY_COBBLESTONE)
B(0,17,18,STONE)
B(8,17,18,STONE)
B(16,17,18,MOSSY_COBBLESTONE)
B(24,17,18,STONE)
B(0,18,18,MOSSY_COBBLESTONE)
B(8,18,18,MOSSY_COBBLESTONE)
B(16,18,18,STONE)
B(24,18,18,MOSSY_COBBLESTONE)
B(0,19,18,EMERALD_ORE)
B(8,19,18,STONE)
B(16,19,18,MOSSY_COBBLESTONE)
B(17,19,18,STONEBRICK:1)
B(23,19,18,STONEBRICK:2)
B(24,19,18,EMERALD_ORE)
B(0,20,18,MOSSY_COBBLESTONE)
B(8,20,18,STONE)
B(16,20,18,STONEBRICK:1)
B(17,20,18,MOSSY_COBBLESTONE)
B(18,20,18,STONEBRICK)
B(19,20,18,STONEBRICK)
B(20,20,18,STONEBRICK:1)
B(21,20,18,STONEBRICK)
B(22,20,18,STONEBRICK:2)
B(23,20,18,STONE)
B(24,20,18,STONEBRICK:2)
B(0,21,18,MOSSY_COBBLESTONE)
B(8,21,18,MOSSY_COBBLESTONE)
B(0,22,18,STONE)
B(8,22,18,MOSSY_COBBLESTONE)
B(0,23,18,STONE)
B(1,23,18,STONEBRICK:1)
B(7,23,18,STONEBRICK:1)
B(8,23,18,STONE)
B(0,24,18,STONEBRICK)
B(1,24,18,EMERALD_ORE)
B(2,24,18,STONEBRICK)
B(3,24,18,STONEBRICK)
B(4,24,18,STONEBRICK:2)
B(5,24,18,STONEBRICK)
B(6,24,18,STONEBRICK:2)
B(7,24,18,MOSSY_COBBLESTONE)
B(8,24,18,STONEBRICK)
B(0,0,19,STONEBRICK:2)
B(1,0,19,STONEBRICK)
B(2,0,19,STONEBRICK:1)
B(3,0,19,GRASS)
B(4,0,19,DIRT:1)
B(5,0,19,GRASS)
B(6,0,19,STONEBRICK:2)
B(7,0,19,STONEBRICK)
B(8,0,19,STONEBRICK:2)
B(0,1,19,STONE)
B(8,1,19,STONEBRICK)
B(0,2,19,MOSSY_COBBLESTONE)
B(8,2,19,STONEBRICK:1)
B(0,3,19,STONE)
B(8,3,19,STONEBRICK:1)
B(0,4,19,STONE)
B(8,4,19,STONEBRICK:3)
B(0,5,19,STONE)
B(8,5,19,MOSSY_COBBLESTONE)
B(0,6,19,STONE)
B(8,6,19,STONE)
B(0,7,19,MOSSY_COBBLESTONE)
B(1,7,19,STONEBRICK:2)
B(7,7,19,STONEBRICK:2)
B(8,7,19,STONE)
B(0,8,19,STONEBRICK)
B(1,8,19,STONE)
B(2,8,19,STONEBRICK:2)
B(6,8,19,STONEBRICK:2)
B(7,8,19,STONE)
B(8,8,19,STONEBRICK:2)
B(2,9,19,STONE)
B(6,9,19,STONE)
B(2,10,19,STONE)
B(6,10,19,MOSSY_COBBLESTONE)
B(2,11,19,STONE)
B(6,11,19,MOSSY_COBBLESTONE)
B(2,12,19,MOSSY_COBBLESTONE)
B(6,12,19,MOSSY_COBBLESTONE)
B(15,12,19,STONEBRICK)
B(16,12,19,STONEBRICK:1)
B(17,12,19,STONEBRICK)
B(18,12,19,STONEBRICK:2)
B(19,12,19,DIRT:1)
B(20,12,19,DIRT:1)
B(21,12,19,GRASS)
B(22,12,19,STONEBRICK:2)
B(23,12,19,STONEBRICK:1)
B(24,12,19,STONEBRICK)
B(2,13,19,EMERALD_ORE)
B(6,13,19,EMERALD_ORE)
B(13,13,19,STONEBRICK:2)
B(14,13,19,STONEBRICK)
B(15,13,19,STONEBRICK)
B(16,13,19,STONEBRICK:1)
B(24,13,19,MOSSY_COBBLESTONE)
B(2,14,19,STONE)
B(6,14,19,STONE)
B(11,14,19,STONEBRICK:1)
B(12,14,19,STONEBRICK)
B(13,14,19,STONEBRICK:2)
B(14,14,19,STONEBRICK:2)
B(15,14,19,STONEBRICK:1)
B(16,14,19,STONEBRICK:2)
B(24,14,19,STONE)
B(2,15,19,STONE)
B(6,15,19,MOSSY_COBBLESTONE)
B(9,15,19,STONEBRICK:1)
B(10,15,19,STONEBRICK:1)
B(11,15,19,STONEBRICK:2)
B(12,15,19,STONEBRICK)
B(13,15,19,STONEBRICK:1)
B(14,15,19,STONEBRICK:1)
B(15,15,19,STONEBRICK:1)
B(16,15,19,STONEBRICK)
B(24,15,19,EMERALD_ORE)
B(0,16,19,STONEBRICK:1)
B(1,16,19,STONEBRICK:1)
B(2,16,19,STONEBRICK:2)
B(6,16,19,STONEBRICK)
B(7,16,19,STONEBRICK:1)
B(8,16,19,STONEBRICK:1)
B(9,16,19,STONEBRICK)
B(10,16,19,STONEBRICK:2)
B(11,16,19,STONEBRICK)
B(12,16,19,STONEBRICK)
B(13,16,19,STONEBRICK:2)
B(14,16,19,STONEBRICK)
B(15,16,19,DOUBLE_STONE_SLAB)
B(16,16,19,STONEBRICK:3)
B(24,16,19,MOSSY_COBBLESTONE)
B(0,17,19,MOSSY_COBBLESTONE)
B(8,17,19,STONEBRICK:1)
B(9,17,19,STONEBRICK)
B(10,17,19,STONEBRICK)
B(11,17,19,STONEBRICK:1)
B(12,17,19,STONEBRICK:1)
B(13,17,19,STONEBRICK:2)
B(14,17,19,STONEBRICK:2)
B(15,17,19,STONEBRICK:2)
B(16,17,19,MOSSY_COBBLESTONE)
B(24,17,19,MOSSY_COBBLESTONE)
B(0,18,19,MOSSY_COBBLESTONE)
B(8,18,19,STONEBRICK)
B(9,18,19,STONEBRICK:2)
B(10,18,19,STONEBRICK:2)
B(11,18,19,STONEBRICK)
B(12,18,19,STONEBRICK:1)
B(13,18,19,STONEBRICK:1)
B(16,18,19,MOSSY_COBBLESTONE)
B(24,18,19,MOSSY_COBBLESTONE)
B(0,19,19,MOSSY_COBBLESTONE)
B(8,19,19,STONEBRICK)
B(9,19,19,STONEBRICK:2)
B(10,19,19,STONEBRICK:2)
B(11,19,19,STONEBRICK:2)
B(16,19,19,STONE)
B(17,19,19,STONEBRICK)
B(23,19,19,STONEBRICK:2)
B(24,19,19,STONE)
B(0,20,19,STONE)
B(8,20,19,STONEBRICK:3)
B(9,20,19,STONEBRICK)
B(16,20,19,STONEBRICK:1)
B(17,20,19,STONE)
B(18,20,19,STONEBRICK)
B(22,20,19,STONEBRICK:1)
B(23,20,19,MOSSY_COBBLESTONE)
B(24,20,19,STONEBRICK:1)
B(0,21,19,EMERALD_ORE)
B(8,21,19,STONE)
B(0,22,19,MOSSY_COBBLESTONE)
B(8,22,19,STONE)
B(0,23,19,STONE)
B(1,23,19,STONEBRICK:1)
B(7,23,19,STONEBRICK:1)
B(8,23,19,MOSSY_COBBLESTONE)
B(0,24,19,STONEBRICK)
B(1,24,19,MOSSY_COBBLESTONE)
B(2,24,19,STONEBRICK:1)
B(6,24,19,STONEBRICK)
B(7,24,19,MOSSY_COBBLESTONE)
B(8,24,19,STONEBRICK:1)
B(0,0,20,STONEBRICK)
B(1,0,20,STONEBRICK)
B(2,0,20,STONEBRICK:1)
B(3,0,20,GRASS)
B(4,0,20,DIRT:1)
B(5,0,20,GRASS)
B(6,0,20,STONEBRICK:1)
B(7,0,20,STONEBRICK:1)
B(8,0,20,STONEBRICK)
B(0,1,20,STONE)
B(0,2,20,MOSSY_COBBLESTONE)
B(0,3,20,STONE)
B(0,4,20,MOSSY_COBBLESTONE)
B(8,4,20,STONEBRICK:3)
B(0,5,20,STONE)
B(8,5,20,EMERALD_ORE)
B(0,6,20,STONE)
B(8,6,20,MOSSY_COBBLESTONE)
B(0,7,20,STONE)
B(1,7,20,STONEBRICK)
B(7,7,20,STONEBRICK)
B(8,7,20,MOSSY_COBBLESTONE)
B(0,8,20,STONEBRICK)
B(1,8,20,MOSSY_COBBLESTONE)
B(2,8,20,STONEBRICK:2)
B(6,8,20,STONEBRICK:2)
B(7,8,20,MOSSY_COBBLESTONE)
B(8,8,20,STONEBRICK:2)
B(2,9,20,STONE)
B(6,9,20,EMERALD_ORE)
B(2,10,20,MOSSY_COBBLESTONE)
B(6,10,20,STONE)
B(2,11,20,STONE)
B(6,11,20,MOSSY_COBBLESTONE)
B(2,12,20,EMERALD_ORE)
B(6,12,20,STONE)
B(15,12,20,STONEBRICK:2)
B(16,12,20,STONEBRICK:1)
B(17,12,20,STONEBRICK)
B(18,12,20,STONEBRICK:1)
B(19,12,20,GRASS)
B(20,12,20,GRASS)
B(21,12,20,DIRT:1)
B(22,12,20,STONEBRICK:2)
B(23,12,20,STONEBRICK)
B(24,12,20,STONEBRICK:1)
B(2,13,20,STONE)
B(6,13,20,EMERALD_ORE)
B(13,13,20,STONEBRICK:1)
B(14,13,20,STONEBRICK)
B(24,13,20,STONE)
B(2,14,20,STONE)
B(6,14,20,STONE)
B(11,14,20,STONEBRICK:2)
B(12,14,20,STONEBRICK)
B(24,14,20,MOSSY_COBBLESTONE)
B(2,15,20,MOSSY_COBBLESTONE)
B(6,15,20,MOSSY_COBBLESTONE)
B(9,15,20,STONEBRICK)
B(10,15,20,STONEBRICK)
B(24,15,20,MOSSY_COBBLESTONE)
B(0,16,20,STONEBRICK)
B(1,16,20,STONEBRICK:1)
B(2,16,20,STONEBRICK:2)
B(6,16,20,STONEBRICK)
B(7,16,20,STONEBRICK:2)
B(8,16,20,STONEBRICK:2)
B(16,16,20,STONEBRICK:3)
B(24,16,20,STONE)
B(0,17,20,MOSSY_COBBLESTONE)
B(14,17,20,STONEBRICK:2)
B(15,17,20,STONEBRICK:2)
B(16,17,20,STONE)
B(24,17,20,MOSSY_COBBLESTONE)
B(0,18,20,STONE)
B(12,18,20,STONEBRICK:2)
B(13,18,20,STONEBRICK:2)
B(16,18,20,EMERALD_ORE)
B(24,18,20,MOSSY_COBBLESTONE)
B(0,19,20,STONE)
B(10,19,20,STONEBRICK:2)
B(11,19,20,STONEBRICK:1)
B(16,19,20,STONE)
B(17,19,20,STONEBRICK)
B(23,19,20,STONEBRICK:2)
B(24,19,20,EMERALD_ORE)
B(0,20,20,STONE)
B(8,20,20,STONEBRICK:3)
B(9,20,20,STONEBRICK)
B(16,20,20,STONEBRICK)
B(17,20,20,MOSSY_COBBLESTONE)
B(18,20,20,STONEBRICK)
B(22,20,20,STONEBRICK:2)
B(23,20,20,MOSSY_COBBLESTONE)
B(24,20,20,STONEBRICK:1)
B(0,21,20,STONE)
B(8,21,20,MOSSY_COBBLESTONE)
B(0,22,20,STONE)
B(8,22,20,MOSSY_COBBLESTONE)
B(0,23,20,STONE)
B(1,23,20,STONEBRICK:2)
B(7,23,20,STONEBRICK:1)
B(8,23,20,MOSSY_COBBLESTONE)
B(0,24,20,STONEBRICK)
B(1,24,20,MOSSY_COBBLESTONE)
B(2,24,20,STONEBRICK:1)
B(6,24,20,STONEBRICK:1)
B(7,24,20,MOSSY_COBBLESTONE)
B(8,24,20,STONEBRICK:1)
B(0,0,21,STONEBRICK:2)
B(1,0,21,STONEBRICK:2)
B(2,0,21,STONEBRICK)
B(3,0,21,DIRT:1)
B(4,0,21,DIRT:1)
B(5,0,21,DIRT:1)
B(6,0,21,STONEBRICK)
B(7,0,21,STONEBRICK:1)
B(8,0,21,STONEBRICK:1)
B(0,1,21,EMERALD_ORE)
B(8,1,21,STONEBRICK:2)
B(0,2,21,STONE)
B(8,2,21,STONEBRICK:1)
B(0,3,21,MOSSY_COBBLESTONE)
B(8,3,21,STONEBRICK:2)
B(0,4,21,MOSSY_COBBLESTONE)
B(8,4,21,STONEBRICK:3)
B(0,5,21,MOSSY_COBBLESTONE)
B(8,5,21,MOSSY_COBBLESTONE)
B(0,6,21,STONE)
B(8,6,21,STONE)
B(0,7,21,MOSSY_COBBLESTONE)
B(1,7,21,STONEBRICK:2)
B(7,7,21,STONEBRICK)
B(8,7,21,EMERALD_ORE)
B(0,8,21,STONEBRICK)
B(1,8,21,STONE)
B(2,8,21,STONEBRICK:2)
B(6,8,21,STONEBRICK:2)
B(7,8,21,MOSSY_COBBLESTONE)
B(8,8,21,STONEBRICK:2)
B(2,9,21,STONE)
B(6,9,21,STONE)
B(2,10,21,STONE)
B(6,10,21,STONE)
B(2,11,21,STONE)
B(6,11,21,EMERALD_ORE)
B(2,12,21,MOSSY_COBBLESTONE)
B(6,12,21,STONE)
B(15,12,21,STONEBRICK:2)
B(16,12,21,STONEBRICK)
B(17,12,21,STONEBRICK)
B(18,12,21,STONEBRICK:1)
B(19,12,21,DIRT:1)
B(20,12,21,DIRT:1)
B(21,12,21,DIRT:1)
B(22,12,21,STONEBRICK)
B(23,12,21,STONEBRICK:2)
B(24,12,21,STONEBRICK:1)
B(2,13,21,STONE)
B(6,13,21,STONE)
B(13,13,21,STONEBRICK:2)
B(14,13,21,STONEBRICK:2)
B(15,13,21,STONEBRICK)
B(16,13,21,STONEBRICK:1)
B(24,13,21,MOSSY_COBBLESTONE)
B(2,14,21,MOSSY_COBBLESTONE)
B(6,14,21,STONE)
B(11,14,21,STONEBRICK:1)
B(12,14,21,STONEBRICK:2)
B(13,14,21,STONEBRICK:1)
B(14,14,21,STONEBRICK:1)
B(15,14,21,STONEBRICK:2)
B(16,14,21,STONEBRICK:2)
B(24,14,21,MOSSY_COBBLESTONE)
B(2,15,21,MOSSY_COBBLESTONE)
B(6,15,21,MOSSY_COBBLESTONE)
B(9,15,21,STONEBRICK:1)
B(10,15,21,STONEBRICK:2)
B(11,15,21,STONEBRICK:2)
B(12,15,21,STONEBRICK:1)
B(13,15,21,STONEBRICK:2)
B(14,15,21,STONEBRICK)
B(15,15,21,STONEBRICK:2)
B(16,15,21,STONEBRICK:2)
B(24,15,21,STONE)
B(0,16,21,STONEBRICK:1)
B(1,16,21,STONEBRICK:1)
B(2,16,21,STONEBRICK)
B(6,16,21,STONEBRICK:1)
B(7,16,21,STONEBRICK)
B(8,16,21,STONEBRICK:2)
B(9,16,21,STONEBRICK)
B(10,16,21,STONEBRICK:1)
B(11,16,21,STONEBRICK)
B(12,16,21,STONEBRICK:2)
B(13,16,21,STONEBRICK:2)
B(14,16,21,STONEBRICK:2)
B(15,16,21,DOUBLE_STONE_SLAB)
B(16,16,21,STONEBRICK:3)
B(24,16,21,MOSSY_COBBLESTONE)
B(0,17,21,STONE)
B(8,17,21,STONEBRICK)
B(9,17,21,STONEBRICK:2)
B(10,17,21,STONEBRICK:2)
B(11,17,21,STONEBRICK:2)
B(12,17,21,STONEBRICK:2)
B(13,17,21,STONEBRICK)
B(14,17,21,STONEBRICK)
B(15,17,21,STONEBRICK:2)
B(16,17,21,STONE)
B(24,17,21,STONE)
B(0,18,21,MOSSY_COBBLESTONE)
B(8,18,21,STONEBRICK:1)
B(9,18,21,STONEBRICK:1)
B(10,18,21,STONEBRICK:1)
B(11,18,21,STONEBRICK)
B(12,18,21,STONEBRICK)
B(13,18,21,STONEBRICK)
B(16,18,21,STONE)
B(24,18,21,STONE)
B(0,19,21,STONE)
B(8,19,21,STONEBRICK:2)
B(9,19,21,STONEBRICK:1)
B(10,19,21,STONEBRICK:1)
B(11,19,21,STONEBRICK)
B(16,19,21,STONE)
B(17,19,21,STONEBRICK)
B(23,19,21,STONEBRICK:1)
B(24,19,21,MOSSY_COBBLESTONE)
B(0,20,21,STONE)
B(8,20,21,STONEBRICK:3)
B(9,20,21,STONEBRICK:1)
B(16,20,21,STONEBRICK:1)
B(17,20,21,MOSSY_COBBLESTONE)
B(18,20,21,STONEBRICK:2)
B(22,20,21,STONEBRICK:2)
B(23,20,21,EMERALD_ORE)
B(24,20,21,STONEBRICK:1)
B(0,21,21,STONE)
B(8,21,21,STONE)
B(0,22,21,MOSSY_COBBLESTONE)
B(8,22,21,MOSSY_COBBLESTONE)
B(0,23,21,EMERALD_ORE)
B(1,23,21,STONEBRICK:2)
B(7,23,21,STONEBRICK:1)
B(8,23,21,STONE)
B(0,24,21,STONEBRICK)
B(1,24,21,MOSSY_COBBLESTONE)
B(2,24,21,STONEBRICK)
B(6,24,21,STONEBRICK:2)
B(7,24,21,MOSSY_COBBLESTONE)
B(8,24,21,STONEBRICK:2)
B(0,0,22,STONEBRICK)
B(1,0,22,STONEBRICK)
B(2,0,22,STONEBRICK)
B(3,0,22,STONEBRICK:2)
B(4,0,22,STONEBRICK)
B(5,0,22,STONEBRICK)
B(6,0,22,STONEBRICK:1)
B(7,0,22,STONEBRICK)
B(8,0,22,STONEBRICK:2)
B(0,1,22,STONE)
B(8,1,22,MOSSY_COBBLESTONE)
B(0,2,22,MOSSY_COBBLESTONE)
B(8,2,22,MOSSY_COBBLESTONE)
B(0,3,22,MOSSY_COBBLESTONE)
B(8,3,22,STONE)
B(0,4,22,STONE)
B(8,4,22,STONE)
B(0,5,22,MOSSY_COBBLESTONE)
B(8,5,22,MOSSY_COBBLESTONE)
B(0,6,22,MOSSY_COBBLESTONE)
B(8,6,22,MOSSY_COBBLESTONE)
B(0,7,22,MOSSY_COBBLESTONE)
B(1,7,22,STONEBRICK:2)
B(7,7,22,STONEBRICK)
B(8,7,22,STONE)
B(0,8,22,STONEBRICK:1)
B(1,8,22,MOSSY_COBBLESTONE)
B(2,8,22,STONEBRICK:2)
B(3,8,22,STONEBRICK)
B(4,8,22,STONEBRICK:2)
B(5,8,22,STONEBRICK)
B(6,8,22,STONEBRICK:2)
B(7,8,22,STONE)
B(8,8,22,STONEBRICK:2)
B(2,9,22,STONEBRICK:2)
B(3,9,22,MOSSY_COBBLESTONE)
B(4,9,22,STONE)
B(5,9,22,STONE)
B(6,9,22,STONEBRICK)
B(2,10,22,STONEBRICK:1)
B(3,10,22,MOSSY_COBBLESTONE)
B(4,10,22,STONE)
B(5,10,22,STONE)
B(6,10,22,STONEBRICK:1)
B(2,11,22,STONEBRICK:2)
B(3,11,22,STONE)
B(4,11,22,MOSSY_COBBLESTONE)
B(5,11,22,MOSSY_COBBLESTONE)
B(6,11,22,STONEBRICK)
B(2,12,22,STONEBRICK)
B(3,12,22,MOSSY_COBBLESTONE)
B(4,12,22,MOSSY_COBBLESTONE)
B(5,12,22,MOSSY_COBBLESTONE)
B(6,12,22,STONEBRICK:2)
B(16,12,22,STONEBRICK:1)
B(17,12,22,STONEBRICK)
B(18,12,22,STONEBRICK)
B(19,12,22,STONEBRICK:1)
B(20,12,22,STONEBRICK:1)
B(21,12,22,STONEBRICK:1)
B(22,12,22,STONEBRICK:2)
B(23,12,22,STONEBRICK:1)
B(24,12,22,STONEBRICK:1)
B(2,13,22,STONEBRICK)
B(3,13,22,MOSSY_COBBLESTONE)
B(4,13,22,STONE)
B(5,13,22,STONE)
B(6,13,22,STONEBRICK:2)
B(16,13,22,STONE)
B(24,13,22,MOSSY_COBBLESTONE)
B(2,14,22,STONEBRICK:2)
B(3,14,22,STONE)
B(4,14,22,MOSSY_COBBLESTONE)
B(5,14,22,MOSSY_COBBLESTONE)
B(6,14,22,STONEBRICK:2)
B(16,14,22,MOSSY_COBBLESTONE)
B(24,14,22,MOSSY_COBBLESTONE)
B(2,15,22,STONEBRICK)
B(3,15,22,MOSSY_COBBLESTONE)
B(4,15,22,STONE)
B(5,15,22,MOSSY_COBBLESTONE)
B(6,15,22,STONEBRICK:2)
B(16,15,22,MOSSY_COBBLESTONE)
B(24,15,22,STONE)
B(0,16,22,STONEBRICK)
B(1,16,22,STONEBRICK:2)
B(2,16,22,STONEBRICK:1)
B(3,16,22,STONEBRICK)
B(4,16,22,STONEBRICK:2)
B(5,16,22,STONEBRICK)
B(6,16,22,STONEBRICK)
B(7,16,22,STONEBRICK:2)
B(8,16,22,STONEBRICK:1)
B(16,16,22,MOSSY_COBBLESTONE)
B(24,16,22,MOSSY_COBBLESTONE)
B(0,17,22,STONE)
B(8,17,22,STONE)
B(16,17,22,MOSSY_COBBLESTONE)
B(24,17,22,EMERALD_ORE)
B(0,18,22,STONE)
B(8,18,22,MOSSY_COBBLESTONE)
B(16,18,22,MOSSY_COBBLESTONE)
B(24,18,22,STONE)
B(0,19,22,MOSSY_COBBLESTONE)
B(8,19,22,MOSSY_COBBLESTONE)
B(16,19,22,STONE)
B(17,19,22,STONEBRICK:2)
B(23,19,22,STONEBRICK:2)
B(24,19,22,EMERALD_ORE)
B(0,20,22,MOSSY_COBBLESTONE)
B(8,20,22,MOSSY_COBBLESTONE)
B(16,20,22,STONEBRICK)
B(17,20,22,MOSSY_COBBLESTONE)
B(18,20,22,STONEBRICK:2)
B(19,20,22,STONEBRICK:1)
B(20,20,22,STONEBRICK:1)
B(21,20,22,STONEBRICK:2)
B(22,20,22,STONEBRICK:1)
B(23,20,22,EMERALD_ORE)
B(24,20,22,STONEBRICK)
B(0,21,22,MOSSY_COBBLESTONE)
B(8,21,22,STONE)
B(0,22,22,STONE)
B(8,22,22,STONE)
B(0,23,22,MOSSY_COBBLESTONE)
B(1,23,22,STONEBRICK:1)
B(7,23,22,STONEBRICK:1)
B(8,23,22,MOSSY_COBBLESTONE)
B(0,24,22,STONEBRICK:1)
B(1,24,22,STONE)
B(2,24,22,STONEBRICK:2)
B(3,24,22,STONEBRICK:2)
B(4,24,22,STONEBRICK)
B(5,24,22,STONEBRICK)
B(6,24,22,STONEBRICK:2)
B(7,24,22,MOSSY_COBBLESTONE)
B(8,24,22,STONEBRICK:1)
B(0,0,23,STONEBRICK:2)
B(1,0,23,STONEBRICK)
B(2,0,23,STONEBRICK:2)
B(3,0,23,STONEBRICK)
B(4,0,23,STONEBRICK)
B(5,0,23,STONEBRICK)
B(6,0,23,STONEBRICK:2)
B(7,0,23,STONEBRICK)
B(8,0,23,STONEBRICK:2)
B(0,1,23,STONE)
B(1,1,23,EMERALD_ORE)
B(7,1,23,MOSSY_COBBLESTONE)
B(8,1,23,STONE)
B(0,2,23,STONE)
B(1,2,23,EMERALD_ORE)
B(7,2,23,STONE)
B(8,2,23,MOSSY_COBBLESTONE)
B(0,3,23,MOSSY_COBBLESTONE)
B(1,3,23,MOSSY_COBBLESTONE)
B(7,3,23,MOSSY_COBBLESTONE)
B(8,3,23,STONE)
B(0,4,23,MOSSY_COBBLESTONE)
B(1,4,23,STONEBRICK:3)
B(7,4,23,STONEBRICK:3)
B(8,4,23,STONE)
B(0,5,23,MOSSY_COBBLESTONE)
B(1,5,23,STONEBRICK:2)
B(7,5,23,STONEBRICK)
B(8,5,23,MOSSY_COBBLESTONE)
B(0,6,23,STONE)
B(1,6,23,STONEBRICK:2)
B(7,6,23,STONEBRICK:2)
B(8,6,23,EMERALD_ORE)
B(0,7,23,STONE)
B(1,7,23,STONEBRICK:2)
B(2,7,23,STONEBRICK:2)
B(3,7,23,STONEBRICK)
B(4,7,23,STONEBRICK)
B(5,7,23,STONEBRICK)
B(6,7,23,STONEBRICK:1)
B(7,7,23,STONEBRICK)
B(8,7,23,STONE)
B(0,8,23,STONEBRICK:2)
B(1,8,23,STONE)
B(2,8,23,EMERALD_ORE)
B(3,8,23,STONE)
B(4,8,23,STONE)
B(5,8,23,MOSSY_COBBLESTONE)
B(6,8,23,EMERALD_ORE)
B(7,8,23,MOSSY_COBBLESTONE)
B(8,8,23,STONEBRICK)
B(16,12,23,STONEBRICK)
B(17,12,23,STONEBRICK)
B(18,12,23,STONEBRICK)
B(19,12,23,STONEBRICK)
B(20,12,23,STONEBRICK)
B(21,12,23,STONEBRICK:1)
B(22,12,23,STONEBRICK)
B(23,12,23,STONEBRICK:1)
B(24,12,23,STONEBRICK)
B(16,13,23,MOSSY_COBBLESTONE)
B(17,13,23,MOSSY_COBBLESTONE)
B(23,13,23,STONE)
B(24,13,23,EMERALD_ORE)
B(16,14,23,MOSSY_COBBLESTONE)
B(17,14,23,MOSSY_COBBLESTONE)
B(23,14,23,MOSSY_COBBLESTONE)
B(24,14,23,STONE)
B(16,15,23,STONE)
B(17,15,23,MOSSY_COBBLESTONE)
B(23,15,23,MOSSY_COBBLESTONE)
B(24,15,23,STONE)
B(0,16,23,STONEBRICK:2)
B(1,16,23,STONEBRICK:1)
B(2,16,23,STONEBRICK:2)
B(3,16,23,STONEBRICK:1)
B(4,16,23,STONEBRICK)
B(5,16,23,STONEBRICK:1)
B(6,16,23,STONEBRICK:1)
B(7,16,23,STONEBRICK:2)
B(8,16,23,STONEBRICK:2)
B(16,16,23,STONE)
B(17,16,23,STONEBRICK:3)
B(23,16,23,STONEBRICK:3)
B(24,16,23,STONE)
B(0,17,23,MOSSY_COBBLESTONE)
B(1,17,23,MOSSY_COBBLESTONE)
B(7,17,23,MOSSY_COBBLESTONE)
B(8,17,23,MOSSY_COBBLESTONE)
B(16,17,23,MOSSY_COBBLESTONE)
B(17,17,23,STONEBRICK:1)
B(23,17,23,STONEBRICK)
B(24,17,23,STONE)
B(0,18,23,EMERALD_ORE)
B(1,18,23,STONE)
B(7,18,23,STONE)
B(8,18,23,STONE)
B(16,18,23,EMERALD_ORE)
B(17,18,23,STONEBRICK)
B(23,18,23,STONEBRICK)
B(24,18,23,STONE)
B(0,19,23,STONE)
B(1,19,23,MOSSY_COBBLESTONE)
B(7,19,23,MOSSY_COBBLESTONE)
B(8,19,23,STONE)
B(16,19,23,STONE)
B(17,19,23,STONEBRICK:2)
B(18,19,23,STONEBRICK)
B(19,19,23,STONEBRICK:1)
B(20,19,23,STONEBRICK:1)
B(21,19,23,STONEBRICK)
B(22,19,23,STONEBRICK:1)
B(23,19,23,STONEBRICK:1)
B(24,19,23,STONE)
B(0,20,23,STONE)
B(1,20,23,STONEBRICK:3)
B(7,20,23,STONEBRICK:3)
B(8,20,23,STONE)
B(16,20,23,STONEBRICK)
B(17,20,23,MOSSY_COBBLESTONE)
B(18,20,23,STONE)
B(19,20,23,STONE)
B(20,20,23,MOSSY_COBBLESTONE)
B(21,20,23,MOSSY_COBBLESTONE)
B(22,20,23,MOSSY_COBBLESTONE)
B(23,20,23,EMERALD_ORE)
B(24,20,23,STONEBRICK:1)
B(0,21,23,MOSSY_COBBLESTONE)
B(1,21,23,STONEBRICK:2)
B(7,21,23,STONEBRICK)
B(8,21,23,STONE)
B(0,22,23,MOSSY_COBBLESTONE)
B(1,22,23,STONEBRICK)
B(7,22,23,STONEBRICK:1)
B(8,22,23,STONE)
B(0,23,23,STONE)
B(1,23,23,STONEBRICK:2)
B(2,23,23,STONEBRICK:1)
B(3,23,23,STONEBRICK:1)
B(4,23,23,STONEBRICK:1)
B(5,23,23,STONEBRICK:2)
B(6,23,23,STONEBRICK:2)
B(7,23,23,STONEBRICK)
B(8,23,23,MOSSY_COBBLESTONE)
B(0,24,23,STONEBRICK:2)
B(1,24,23,MOSSY_COBBLESTONE)
B(2,24,23,MOSSY_COBBLESTONE)
B(3,24,23,STONE)
B(4,24,23,MOSSY_COBBLESTONE)
B(5,24,23,STONE)
B(6,24,23,MOSSY_COBBLESTONE)
B(7,24,23,MOSSY_COBBLESTONE)
B(8,24,23,STONEBRICK:1)
B(0,0,24,STONEBRICK:1)
B(1,0,24,STONEBRICK:1)
B(2,0,24,STONEBRICK:1)
B(3,0,24,STONEBRICK:1)
B(4,0,24,STONEBRICK)
B(5,0,24,STONEBRICK:2)
B(6,0,24,STONEBRICK:1)
B(7,0,24,STONEBRICK:2)
B(8,0,24,STONEBRICK:1)
B(0,1,24,STONEBRICK:2)
B(1,1,24,STONE)
B(2,1,24,MOSSY_COBBLESTONE)
B(3,1,24,STONE)
B(4,1,24,MOSSY_COBBLESTONE)
B(5,1,24,MOSSY_COBBLESTONE)
B(6,1,24,STONE)
B(7,1,24,MOSSY_COBBLESTONE)
B(8,1,24,STONEBRICK)
B(0,2,24,STONEBRICK:1)
B(1,2,24,STONE)
B(2,2,24,EMERALD_ORE)
B(3,2,24,STONE)
B(4,2,24,MOSSY_COBBLESTONE)
B(5,2,24,STONE)
B(6,2,24,STONE)
B(7,2,24,STONE)
B(8,2,24,STONEBRICK)
B(0,3,24,STONEBRICK:1)
B(1,3,24,MOSSY_COBBLESTONE)
B(2,3,24,STONE)
B(3,3,24,STONE)
B(4,3,24,MOSSY_COBBLESTONE)
B(5,3,24,MOSSY_COBBLESTONE)
B(6,3,24,MOSSY_COBBLESTONE)
B(7,3,24,STONE)
B(8,3,24,STONEBRICK)
B(0,4,24,STONEBRICK)
B(1,4,24,EMERALD_ORE)
B(2,4,24,STONE)
B(3,4,24,EMERALD_ORE)
B(4,4,24,MOSSY_COBBLESTONE)
B(5,4,24,STONE)
B(6,4,24,STONE)
B(7,4,24,MOSSY_COBBLESTONE)
B(8,4,24,STONEBRICK:2)
B(0,5,24,STONEBRICK:2)
B(1,5,24,STONE)
B(2,5,24,STONE)
B(3,5,24,MOSSY_COBBLESTONE)
B(4,5,24,STONE)
B(5,5,24,MOSSY_COBBLESTONE)
B(6,5,24,MOSSY_COBBLESTONE)
B(7,5,24,MOSSY_COBBLESTONE)
B(8,5,24,STONEBRICK:2)
B(0,6,24,STONEBRICK)
B(1,6,24,STONE)
B(2,6,24,MOSSY_COBBLESTONE)
B(3,6,24,STONE)
B(4,6,24,MOSSY_COBBLESTONE)
B(5,6,24,MOSSY_COBBLESTONE)
B(6,6,24,MOSSY_COBBLESTONE)
B(7,6,24,STONE)
B(8,6,24,STONEBRICK:2)
B(0,7,24,STONEBRICK:1)
B(1,7,24,MOSSY_COBBLESTONE)
B(2,7,24,EMERALD_ORE)
B(3,7,24,STONE)
B(4,7,24,EMERALD_ORE)
B(5,7,24,MOSSY_COBBLESTONE)
B(6,7,24,MOSSY_COBBLESTONE)
B(7,7,24,MOSSY_COBBLESTONE)
B(8,7,24,STONEBRICK)
B(0,8,24,STONEBRICK:1)
B(1,8,24,STONEBRICK)
B(2,8,24,STONEBRICK:1)
B(3,8,24,STONEBRICK)
B(4,8,24,STONEBRICK:2)
B(5,8,24,STONEBRICK:2)
B(6,8,24,STONEBRICK)
B(7,8,24,STONEBRICK:1)
B(8,8,24,STONEBRICK:2)
B(16,12,24,STONEBRICK:1)
B(17,12,24,STONEBRICK)
B(18,12,24,STONEBRICK:1)
B(19,12,24,STONEBRICK:2)
B(20,12,24,STONEBRICK:1)
B(21,12,24,STONEBRICK:2)
B(22,12,24,STONEBRICK:2)
B(23,12,24,STONEBRICK:1)
B(24,12,24,STONEBRICK:2)
B(16,13,24,STONEBRICK:1)
B(17,13,24,STONE)
B(18,13,24,MOSSY_COBBLESTONE)
B(19,13,24,STONE)
B(20,13,24,MOSSY_COBBLESTONE)
B(21,13,24,STONE)
B(22,13,24,STONE)
B(23,13,24,MOSSY_COBBLESTONE)
B(24,13,24,STONEBRICK)
B(16,14,24,STONEBRICK)
B(17,14,24,MOSSY_COBBLESTONE)
B(18,14,24,STONE)
B(19,14,24,MOSSY_COBBLESTONE)
B(20,14,24,STONE)
B(21,14,24,MOSSY_COBBLESTONE)
B(22,14,24,STONE)
B(23,14,24,STONE)
B(24,14,24,STONEBRICK)
B(16,15,24,STONEBRICK:2)
B(17,15,24,STONE)
B(18,15,24,STONE)
B(19,15,24,MOSSY_COBBLESTONE)
B(20,15,24,STONE)
B(21,15,24,MOSSY_COBBLESTONE)
B(22,15,24,MOSSY_COBBLESTONE)
B(23,15,24,STONE)
B(24,15,24,STONEBRICK:1)
B(0,16,24,STONEBRICK:2)
B(1,16,24,STONEBRICK:1)
B(2,16,24,STONEBRICK:2)
B(3,16,24,STONEBRICK:1)
B(4,16,24,STONEBRICK:1)
B(5,16,24,STONEBRICK:1)
B(6,16,24,STONEBRICK:2)
B(7,16,24,STONEBRICK:2)
B(8,16,24,STONEBRICK:2)
B(16,16,24,STONEBRICK)
B(17,16,24,MOSSY_COBBLESTONE)
B(18,16,24,STONE)
B(19,16,24,STONE)
B(20,16,24,STONE)
B(21,16,24,MOSSY_COBBLESTONE)
B(22,16,24,MOSSY_COBBLESTONE)
B(23,16,24,MOSSY_COBBLESTONE)
B(24,16,24,STONEBRICK:2)
B(0,17,24,STONEBRICK:1)
B(1,17,24,EMERALD_ORE)
B(2,17,24,STONE)
B(3,17,24,EMERALD_ORE)
B(4,17,24,EMERALD_ORE)
B(5,17,24,MOSSY_COBBLESTONE)
B(6,17,24,MOSSY_COBBLESTONE)
B(7,17,24,STONE)
B(8,17,24,STONEBRICK:1)
B(16,17,24,STONEBRICK:2)
B(17,17,24,STONE)
B(18,17,24,MOSSY_COBBLESTONE)
B(19,17,24,MOSSY_COBBLESTONE)
B(20,17,24,STONE)
B(21,17,24,MOSSY_COBBLESTONE)
B(22,17,24,STONE)
B(23,17,24,EMERALD_ORE)
B(24,17,24,STONEBRICK:2)
B(0,18,24,STONEBRICK:2)
B(1,18,24,MOSSY_COBBLESTONE)
B(2,18,24,MOSSY_COBBLESTONE)
B(3,18,24,EMERALD_ORE)
B(4,18,24,STONE)
B(5,18,24,MOSSY_COBBLESTONE)
B(6,18,24,MOSSY_COBBLESTONE)
B(7,18,24,MOSSY_COBBLESTONE)
B(8,18,24,STONEBRICK)
B(16,18,24,STONEBRICK:2)
B(17,18,24,MOSSY_COBBLESTONE)
B(18,18,24,STONE)
B(19,18,24,STONE)
B(20,18,24,MOSSY_COBBLESTONE)
B(21,18,24,EMERALD_ORE)
B(22,18,24,MOSSY_COBBLESTONE)
B(23,18,24,STONE)
B(24,18,24,STONEBRICK)
B(0,19,24,STONEBRICK:1)
B(1,19,24,MOSSY_COBBLESTONE)
B(2,19,24,MOSSY_COBBLESTONE)
B(3,19,24,EMERALD_ORE)
B(4,19,24,MOSSY_COBBLESTONE)
B(5,19,24,MOSSY_COBBLESTONE)
B(6,19,24,STONE)
B(7,19,24,STONE)
B(8,19,24,STONEBRICK:2)
B(16,19,24,STONEBRICK:1)
B(17,19,24,STONE)
B(18,19,24,MOSSY_COBBLESTONE)
B(19,19,24,MOSSY_COBBLESTONE)
B(20,19,24,STONE)
B(21,19,24,MOSSY_COBBLESTONE)
B(22,19,24,MOSSY_COBBLESTONE)
B(23,19,24,EMERALD_ORE)
B(24,19,24,STONEBRICK:2)
B(0,20,24,STONEBRICK:1)
B(1,20,24,MOSSY_COBBLESTONE)
B(2,20,24,STONE)
B(3,20,24,MOSSY_COBBLESTONE)
B(4,20,24,STONE)
B(5,20,24,MOSSY_COBBLESTONE)
B(6,20,24,STONE)
B(7,20,24,MOSSY_COBBLESTONE)
B(8,20,24,STONEBRICK)
B(16,20,24,STONEBRICK)
B(17,20,24,STONEBRICK:1)
B(18,20,24,STONEBRICK:1)
B(19,20,24,STONEBRICK)
B(20,20,24,STONEBRICK:2)
B(21,20,24,STONEBRICK:2)
B(22,20,24,STONEBRICK)
B(23,20,24,STONEBRICK:2)
B(24,20,24,STONEBRICK)
B(0,21,24,STONEBRICK:1)
B(1,21,24,MOSSY_COBBLESTONE)
B(2,21,24,EMERALD_ORE)
B(3,21,24,STONE)
B(4,21,24,MOSSY_COBBLESTONE)
B(5,21,24,STONE)
B(6,21,24,MOSSY_COBBLESTONE)
B(7,21,24,STONE)
B(8,21,24,STONEBRICK:1)
B(0,22,24,STONEBRICK)
B(1,22,24,MOSSY_COBBLESTONE)
B(2,22,24,MOSSY_COBBLESTONE)
B(3,22,24,MOSSY_COBBLESTONE)
B(4,22,24,STONE)
B(5,22,24,STONE)
B(6,22,24,EMERALD_ORE)
B(7,22,24,STONE)
B(8,22,24,STONEBRICK:2)
B(0,23,24,STONEBRICK)
B(1,23,24,STONE)
B(2,23,24,STONE)
B(3,23,24,MOSSY_COBBLESTONE)
B(4,23,24,EMERALD_ORE)
B(5,23,24,STONE)
B(6,23,24,STONE)
B(7,23,24,STONE)
B(8,23,24,STONEBRICK:1)
B(0,24,24,STONEBRICK)
B(1,24,24,STONEBRICK:2)
B(2,24,24,STONEBRICK:2)
B(3,24,24,STONEBRICK:2)
B(4,24,24,STONEBRICK:2)
B(5,24,24,STONEBRICK)
B(6,24,24,STONEBRICK:1)
B(7,24,24,STONEBRICK)
B(8,24,24,STONEBRICK)
B(2,5,1,AIR)
B(3,5,1,AIR)
B(5,5,1,AIR)
B(6,5,1,AIR)
B(2,6,1,AIR)
B(3,6,1,AIR)
B(4,6,1,AIR)
B(5,6,1,AIR)
B(6,6,1,AIR)
B(2,7,1,AIR)
B(3,7,1,AIR)
B(4,7,1,AIR)
B(5,7,1,AIR)
B(6,7,1,AIR)
B(2,8,1,AIR)
B(3,8,1,AIR)
B(4,8,1,AIR)
B(5,8,1,AIR)
B(6,8,1,AIR)
B(2,9,1,AIR)
B(3,9,1,AIR)
B(4,9,1,AIR)
B(5,9,1,AIR)
B(6,9,1,AIR)
B(18,9,1,AIR)
B(19,9,1,AIR)
B(21,9,1,AIR)
B(22,9,1,AIR)
B(2,10,1,STONE_BRICK_STAIRS:5)
B(3,10,1,AIR)
B(4,10,1,AIR)
B(5,10,1,AIR)
B(6,10,1,STONE_BRICK_STAIRS:4)
B(18,10,1,AIR)
B(19,10,1,AIR)
B(20,10,1,AIR)
B(21,10,1,AIR)
B(22,10,1,AIR)
B(18,11,1,AIR)
B(19,11,1,AIR)
B(20,11,1,AIR)
B(21,11,1,AIR)
B(22,11,1,AIR)
B(18,12,1,AIR)
B(19,12,1,AIR)
B(20,12,1,AIR)
B(21,12,1,AIR)
B(22,12,1,AIR)
B(18,13,1,AIR)
B(19,13,1,AIR)
B(20,13,1,AIR)
B(21,13,1,AIR)
B(22,13,1,AIR)
B(18,14,1,STONE_BRICK_STAIRS:5)
B(19,14,1,AIR)
B(20,14,1,AIR)
B(21,14,1,AIR)
B(22,14,1,STONE_BRICK_STAIRS:4)
B(1,5,2,AIR)
B(2,5,2,AIR)
B(3,5,2,AIR)
B(4,5,2,AIR)
B(5,5,2,AIR)
B(6,5,2,AIR)
B(7,5,2,AIR)
B(1,6,2,AIR)
B(2,6,2,AIR)
B(3,6,2,AIR)
B(4,6,2,AIR)
B(5,6,2,AIR)
B(6,6,2,AIR)
B(7,6,2,AIR)
B(1,7,2,AIR)
B(2,7,2,AIR)
B(3,7,2,AIR)
B(4,7,2,AIR)
B(5,7,2,AIR)
B(6,7,2,AIR)
B(7,7,2,AIR)
B(1,8,2,AIR)
B(2,8,2,AIR)
B(3,8,2,AIR)
B(4,8,2,AIR)
B(5,8,2,AIR)
B(6,8,2,AIR)
B(7,8,2,AIR)
B(1,9,2,AIR)
B(2,9,2,AIR)
B(3,9,2,AIR)
B(4,9,2,AIR)
B(5,9,2,AIR)
B(6,9,2,AIR)
B(7,9,2,AIR)
B(17,9,2,AIR)
B(18,9,2,AIR)
B(19,9,2,AIR)
B(20,9,2,AIR)
B(21,9,2,AIR)
B(22,9,2,AIR)
B(23,9,2,AIR)
B(1,10,2,STONE_BRICK_STAIRS:7)
B(2,10,2,AIR)
B(3,10,2,AIR)
B(4,10,2,AIR)
B(5,10,2,AIR)
B(6,10,2,AIR)
B(7,10,2,STONE_BRICK_STAIRS:7)
B(17,10,2,AIR)
B(18,10,2,AIR)
B(19,10,2,AIR)
B(20,10,2,AIR)
B(21,10,2,AIR)
B(22,10,2,AIR)
B(23,10,2,AIR)
B(2,11,2,AIR)
B(3,11,2,AIR)
B(4,11,2,AIR)
B(5,11,2,AIR)
B(6,11,2,AIR)
B(17,11,2,AIR)
B(18,11,2,AIR)
B(19,11,2,AIR)
B(20,11,2,AIR)
B(21,11,2,AIR)
B(22,11,2,AIR)
B(23,11,2,AIR)
B(17,12,2,AIR)
B(18,12,2,AIR)
B(19,12,2,AIR)
B(20,12,2,AIR)
B(21,12,2,AIR)
B(22,12,2,AIR)
B(23,12,2,AIR)
B(17,13,2,AIR)
B(18,13,2,AIR)
B(19,13,2,AIR)
B(20,13,2,AIR)
B(21,13,2,AIR)
B(22,13,2,AIR)
B(23,13,2,AIR)
B(17,14,2,STONE_BRICK_STAIRS:7)
B(18,14,2,AIR)
B(19,14,2,AIR)
B(20,14,2,AIR)
B(21,14,2,AIR)
B(22,14,2,AIR)
B(23,14,2,STONE_BRICK_STAIRS:7)
B(18,15,2,AIR)
B(19,15,2,AIR)
B(20,15,2,AIR)
B(21,15,2,AIR)
B(22,15,2,AIR)
B(1,5,3,AIR)
B(2,5,3,AIR)
B(3,5,3,AIR)
B(4,5,3,TALLGRASS:2)
B(5,5,3,AIR)
B(6,5,3,AIR)
B(7,5,3,AIR)
B(1,6,3,AIR)
B(2,6,3,AIR)
B(3,6,3,AIR)
B(4,6,3,AIR)
B(5,6,3,AIR)
B(6,6,3,AIR)
B(7,6,3,AIR)
B(1,7,3,AIR)
B(2,7,3,AIR)
B(3,7,3,AIR)
B(4,7,3,AIR)
B(5,7,3,AIR)
B(6,7,3,AIR)
B(7,7,3,AIR)
B(1,8,3,AIR)
B(2,8,3,AIR)
B(3,8,3,AIR)
B(4,8,3,AIR)
B(5,8,3,AIR)
B(6,8,3,AIR)
B(7,8,3,AIR)
B(1,9,3,AIR)
B(2,9,3,AIR)
B(3,9,3,AIR)
B(4,9,3,AIR)
B(5,9,3,AIR)
B(6,9,3,AIR)
B(7,9,3,AIR)
B(17,9,3,AIR)
B(18,9,3,AIR)
B(19,9,3,AIR)
B(20,9,3,TALLGRASS:2)
B(21,9,3,TALLGRASS:2)
B(22,9,3,AIR)
B(23,9,3,AIR)
B(1,10,3,AIR)
B(2,10,3,AIR)
B(3,10,3,AIR)
B(4,10,3,AIR)
B(5,10,3,AIR)
B(6,10,3,AIR)
B(7,10,3,AIR)
B(17,10,3,AIR)
B(18,10,3,AIR)
B(19,10,3,AIR)
B(20,10,3,AIR)
B(21,10,3,AIR)
B(22,10,3,AIR)
B(23,10,3,AIR)
B(2,11,3,AIR)
B(3,11,3,AIR)
B(4,11,3,AIR)
B(5,11,3,AIR)
B(6,11,3,AIR)
B(17,11,3,AIR)
B(18,11,3,AIR)
B(19,11,3,AIR)
B(20,11,3,AIR)
B(21,11,3,AIR)
B(22,11,3,AIR)
B(23,11,3,AIR)
B(3,12,3,AIR)
B(4,12,3,AIR)
B(5,12,3,AIR)
B(17,12,3,AIR)
B(18,12,3,AIR)
B(19,12,3,AIR)
B(20,12,3,AIR)
B(21,12,3,AIR)
B(22,12,3,AIR)
B(23,12,3,AIR)
B(17,13,3,AIR)
B(18,13,3,AIR)
B(19,13,3,AIR)
B(20,13,3,AIR)
B(21,13,3,AIR)
B(22,13,3,AIR)
B(23,13,3,AIR)
B(17,14,3,AIR)
B(18,14,3,AIR)
B(19,14,3,AIR)
B(20,14,3,AIR)
B(21,14,3,AIR)
B(22,14,3,AIR)
B(23,14,3,AIR)
B(18,15,3,AIR)
B(19,15,3,AIR)
B(20,15,3,AIR)
B(21,15,3,AIR)
B(22,15,3,AIR)
B(19,16,3,AIR)
B(20,16,3,AIR)
B(21,16,3,AIR)
B(2,5,4,AIR)
B(3,5,4,TALLGRASS:1)
B(5,5,4,AIR)
B(6,5,4,AIR)
B(7,5,4,AIR)
B(8,5,4,AIR)
B(9,5,4,STONE_SLAB)
B(1,6,4,AIR)
B(2,6,4,AIR)
B(3,6,4,AIR)
B(4,6,4,AIR)
B(5,6,4,AIR)
B(6,6,4,AIR)
B(7,6,4,AIR)
B(8,6,4,AIR)
B(9,6,4,AIR)
B(10,6,4,AIR)
B(11,6,4,STONE_SLAB)
B(1,7,4,AIR)
B(2,7,4,AIR)
B(3,7,4,AIR)
B(4,7,4,AIR)
B(5,7,4,AIR)
B(6,7,4,AIR)
B(7,7,4,AIR)
B(8,7,4,AIR)
B(9,7,4,AIR)
B(10,7,4,AIR)
B(11,7,4,AIR)
B(12,7,4,AIR)
B(13,7,4,STONE_SLAB)
B(1,8,4,AIR)
B(2,8,4,AIR)
B(3,8,4,AIR)
B(4,8,4,AIR)
B(5,8,4,AIR)
B(6,8,4,AIR)
B(7,8,4,AIR)
B(9,8,4,STONE_SLAB)
B(10,8,4,AIR)
B(11,8,4,AIR)
B(12,8,4,AIR)
B(13,8,4,AIR)
B(14,8,4,AIR)
B(15,8,4,STONE_SLAB)
B(1,9,4,AIR)
B(2,9,4,AIR)
B(3,9,4,AIR)
B(4,9,4,AIR)
B(5,9,4,AIR)
B(6,9,4,AIR)
B(7,9,4,AIR)
B(11,9,4,STONE_SLAB)
B(12,9,4,AIR)
B(13,9,4,AIR)
B(14,9,4,AIR)
B(15,9,4,AIR)
B(16,9,4,AIR)
B(17,9,4,AIR)
B(18,9,4,AIR)
B(19,9,4,TALLGRASS:2)
B(21,9,4,TALLGRASS:2)
B(22,9,4,AIR)
B(1,10,4,AIR)
B(2,10,4,AIR)
B(3,10,4,AIR)
B(4,10,4,AIR)
B(5,10,4,AIR)
B(6,10,4,AIR)
B(7,10,4,AIR)
B(13,10,4,STONE_SLAB)
B(14,10,4,AIR)
B(15,10,4,AIR)
B(16,10,4,AIR)
B(17,10,4,AIR)
B(18,10,4,AIR)
B(19,10,4,AIR)
B(20,10,4,AIR)
B(21,10,4,AIR)
B(22,10,4,AIR)
B(23,10,4,AIR)
B(2,11,4,AIR)
B(3,11,4,AIR)
B(4,11,4,AIR)
B(5,11,4,AIR)
B(6,11,4,AIR)
B(15,11,4,STONE_SLAB)
B(16,11,4,AIR)
B(17,11,4,AIR)
B(18,11,4,AIR)
B(19,11,4,AIR)
B(20,11,4,AIR)
B(21,11,4,AIR)
B(22,11,4,AIR)
B(23,11,4,AIR)
B(3,12,4,AIR)
B(4,12,4,AIR)
B(5,12,4,AIR)
B(17,12,4,AIR)
B(18,12,4,AIR)
B(19,12,4,AIR)
B(20,12,4,AIR)
B(21,12,4,AIR)
B(22,12,4,AIR)
B(23,12,4,AIR)
B(17,13,4,AIR)
B(18,13,4,AIR)
B(19,13,4,AIR)
B(20,13,4,AIR)
B(21,13,4,AIR)
B(22,13,4,AIR)
B(23,13,4,AIR)
B(17,14,4,AIR)
B(18,14,4,AIR)
B(19,14,4,AIR)
B(20,14,4,AIR)
B(21,14,4,AIR)
B(22,14,4,AIR)
B(23,14,4,AIR)
B(18,15,4,AIR)
B(19,15,4,AIR)
B(20,15,4,AIR)
B(21,15,4,AIR)
B(22,15,4,AIR)
B(19,16,4,AIR)
B(20,16,4,AIR)
B(21,16,4,AIR)
B(1,5,5,AIR)
B(2,5,5,AIR)
B(3,5,5,AIR)
B(4,5,5,AIR)
B(5,5,5,TALLGRASS:1)
B(6,5,5,AIR)
B(7,5,5,AIR)
B(1,6,5,AIR)
B(2,6,5,AIR)
B(3,6,5,AIR)
B(4,6,5,AIR)
B(5,6,5,AIR)
B(6,6,5,AIR)
B(7,6,5,AIR)
B(1,7,5,AIR)
B(2,7,5,AIR)
B(3,7,5,AIR)
B(4,7,5,AIR)
B(5,7,5,AIR)
B(6,7,5,AIR)
B(7,7,5,AIR)
B(1,8,5,AIR)
B(2,8,5,AIR)
B(3,8,5,AIR)
B(4,8,5,AIR)
B(5,8,5,AIR)
B(6,8,5,AIR)
B(7,8,5,AIR)
B(1,9,5,AIR)
B(2,9,5,AIR)
B(3,9,5,AIR)
B(4,9,5,AIR)
B(5,9,5,AIR)
B(6,9,5,AIR)
B(7,9,5,AIR)
B(17,9,5,AIR)
B(18,9,5,AIR)
B(19,9,5,AIR)
B(20,9,5,TALLGRASS:2)
B(21,9,5,TALLGRASS:2)
B(22,9,5,AIR)
B(23,9,5,AIR)
B(1,10,5,AIR)
B(2,10,5,AIR)
B(3,10,5,AIR)
B(4,10,5,AIR)
B(5,10,5,AIR)
B(6,10,5,AIR)
B(7,10,5,AIR)
B(17,10,5,AIR)
B(18,10,5,AIR)
B(19,10,5,AIR)
B(20,10,5,AIR)
B(21,10,5,AIR)
B(22,10,5,AIR)
B(23,10,5,AIR)
B(2,11,5,AIR)
B(3,11,5,AIR)
B(4,11,5,AIR)
B(5,11,5,AIR)
B(6,11,5,AIR)
B(17,11,5,AIR)
B(18,11,5,AIR)
B(19,11,5,AIR)
B(20,11,5,AIR)
B(21,11,5,AIR)
B(22,11,5,AIR)
B(23,11,5,AIR)
B(3,12,5,AIR)
B(4,12,5,AIR)
B(5,12,5,AIR)
B(17,12,5,AIR)
B(18,12,5,AIR)
B(19,12,5,AIR)
B(20,12,5,AIR)
B(21,12,5,AIR)
B(22,12,5,AIR)
B(23,12,5,AIR)
B(17,13,5,AIR)
B(18,13,5,AIR)
B(19,13,5,AIR)
B(20,13,5,AIR)
B(21,13,5,AIR)
B(22,13,5,AIR)
B(23,13,5,AIR)
B(17,14,5,AIR)
B(18,14,5,AIR)
B(19,14,5,AIR)
B(20,14,5,AIR)
B(21,14,5,AIR)
B(22,14,5,AIR)
B(23,14,5,AIR)
B(18,15,5,AIR)
B(19,15,5,AIR)
B(20,15,5,AIR)
B(21,15,5,AIR)
B(22,15,5,AIR)
B(19,16,5,AIR)
B(20,16,5,AIR)
B(21,16,5,AIR)
B(1,5,6,AIR)
B(2,5,6,AIR)
B(3,5,6,AIR)
B(4,5,6,AIR)
B(5,5,6,AIR)
B(6,5,6,AIR)
B(7,5,6,AIR)
B(1,6,6,AIR)
B(2,6,6,AIR)
B(3,6,6,AIR)
B(4,6,6,AIR)
B(5,6,6,AIR)
B(6,6,6,AIR)
B(7,6,6,AIR)
B(1,7,6,AIR)
B(2,7,6,AIR)
B(3,7,6,AIR)
B(4,7,6,AIR)
B(5,7,6,AIR)
B(6,7,6,AIR)
B(7,7,6,AIR)
B(1,8,6,AIR)
B(2,8,6,AIR)
B(3,8,6,AIR)
B(4,8,6,AIR)
B(5,8,6,AIR)
B(6,8,6,AIR)
B(7,8,6,AIR)
B(1,9,6,AIR)
B(2,9,6,AIR)
B(3,9,6,AIR)
B(4,9,6,AIR)
B(5,9,6,AIR)
B(6,9,6,AIR)
B(7,9,6,AIR)
B(17,9,6,AIR)
B(18,9,6,AIR)
B(19,9,6,AIR)
B(20,9,6,AIR)
B(21,9,6,AIR)
B(22,9,6,AIR)
B(23,9,6,AIR)
B(1,10,6,STONE_BRICK_STAIRS:6)
B(2,10,6,AIR)
B(3,10,6,AIR)
B(4,10,6,AIR)
B(5,10,6,AIR)
B(6,10,6,AIR)
B(7,10,6,STONE_BRICK_STAIRS:6)
B(17,10,6,AIR)
B(18,10,6,AIR)
B(19,10,6,AIR)
B(20,10,6,AIR)
B(21,10,6,AIR)
B(22,10,6,AIR)
B(23,10,6,AIR)
B(2,11,6,AIR)
B(3,11,6,AIR)
B(4,11,6,AIR)
B(5,11,6,AIR)
B(6,11,6,AIR)
B(17,11,6,AIR)
B(18,11,6,AIR)
B(19,11,6,AIR)
B(20,11,6,AIR)
B(21,11,6,AIR)
B(22,11,6,AIR)
B(23,11,6,AIR)
B(17,12,6,AIR)
B(18,12,6,AIR)
B(19,12,6,AIR)
B(20,12,6,AIR)
B(21,12,6,AIR)
B(22,12,6,AIR)
B(23,12,6,AIR)
B(17,13,6,AIR)
B(18,13,6,AIR)
B(19,13,6,AIR)
B(20,13,6,AIR)
B(21,13,6,AIR)
B(22,13,6,AIR)
B(23,13,6,AIR)
B(17,14,6,STONE_BRICK_STAIRS:6)
B(18,14,6,AIR)
B(19,14,6,AIR)
B(20,14,6,AIR)
B(21,14,6,AIR)
B(22,14,6,AIR)
B(23,14,6,STONE_BRICK_STAIRS:6)
B(18,15,6,AIR)
B(19,15,6,AIR)
B(20,15,6,AIR)
B(21,15,6,AIR)
B(22,15,6,AIR)
B(2,5,7,AIR)
B(3,5,7,AIR)
B(4,5,7,AIR)
B(5,5,7,AIR)
B(6,5,7,AIR)
B(2,6,7,AIR)
B(3,6,7,AIR)
B(4,6,7,AIR)
B(5,6,7,AIR)
B(6,6,7,AIR)
B(2,7,7,AIR)
B(3,7,7,AIR)
B(4,7,7,AIR)
B(5,7,7,AIR)
B(6,7,7,AIR)
B(2,8,7,AIR)
B(3,8,7,AIR)
B(4,8,7,AIR)
B(5,8,7,AIR)
B(6,8,7,AIR)
B(2,9,7,AIR)
B(3,9,7,AIR)
B(4,9,7,AIR)
B(5,9,7,AIR)
B(6,9,7,AIR)
B(18,9,7,AIR)
B(19,9,7,AIR)
B(20,9,7,AIR)
B(21,9,7,AIR)
B(22,9,7,AIR)
B(2,10,7,STONE_BRICK_STAIRS:5)
B(3,10,7,AIR)
B(4,10,7,AIR)
B(5,10,7,AIR)
B(6,10,7,STONE_BRICK_STAIRS:4)
B(18,10,7,AIR)
B(19,10,7,AIR)
B(20,10,7,AIR)
B(21,10,7,AIR)
B(22,10,7,AIR)
B(18,11,7,AIR)
B(19,11,7,AIR)
B(20,11,7,AIR)
B(21,11,7,AIR)
B(22,11,7,AIR)
B(18,12,7,AIR)
B(19,12,7,AIR)
B(20,12,7,AIR)
B(21,12,7,AIR)
B(22,12,7,AIR)
B(18,13,7,AIR)
B(19,13,7,AIR)
B(20,13,7,AIR)
B(21,13,7,AIR)
B(22,13,7,AIR)
B(18,14,7,STONE_BRICK_STAIRS:5)
B(19,14,7,AIR)
B(20,14,7,AIR)
B(21,14,7,AIR)
B(22,14,7,STONE_BRICK_STAIRS:4)
B(4,5,8,AIR)
B(4,6,8,AIR)
B(4,7,8,AIR)
B(20,9,8,AIR)
B(20,10,8,AIR)
B(20,11,8,AIR)
B(4,4,9,STONE_SLAB)
B(4,5,9,AIR)
B(4,6,9,AIR)
B(4,7,9,STONE_SLAB)
B(20,9,9,STONE_SLAB)
B(20,10,9,AIR)
B(20,11,9,AIR)
B(20,12,9,STONE_SLAB)
B(4,4,10,AIR)
B(4,5,10,AIR)
B(4,6,10,AIR)
B(20,10,10,AIR)
B(20,11,10,AIR)
B(20,12,10,AIR)
B(4,3,11,STONE_SLAB)
B(4,4,11,AIR)
B(4,5,11,AIR)
B(4,6,11,STONE_SLAB)
B(20,10,11,STONE_SLAB)
B(20,11,11,AIR)
B(20,12,11,AIR)
B(20,13,11,STONE_SLAB)
B(4,3,12,AIR)
B(4,4,12,AIR)
B(4,5,12,AIR)
B(20,11,12,AIR)
B(20,12,12,AIR)
B(20,13,12,AIR)
B(4,2,13,STONE_SLAB)
B(4,3,13,AIR)
B(4,4,13,AIR)
B(4,5,13,STONE_SLAB)
B(20,11,13,STONE_SLAB)
B(20,12,13,AIR)
B(20,13,13,AIR)
B(20,14,13,STONE_SLAB)
B(4,2,14,AIR)
B(4,3,14,AIR)
B(4,4,14,AIR)
B(20,12,14,AIR)
B(20,13,14,AIR)
B(20,14,14,AIR)
B(4,1,15,STONE_SLAB)
B(4,2,15,AIR)
B(4,3,15,AIR)
B(4,4,15,STONE_SLAB)
B(20,12,15,STONE_SLAB)
B(20,13,15,AIR)
B(20,14,15,AIR)
B(20,15,15,STONE_SLAB)
B(4,1,16,AIR)
B(4,2,16,AIR)
B(4,3,16,AIR)
B(20,13,16,AIR)
B(20,14,16,AIR)
B(20,15,16,AIR)
B(4,17,16,AIR)
B(4,18,16,AIR)
B(4,19,16,AIR)
B(2,1,17,AIR)
B(3,1,17,AIR)
B(4,1,17,AIR)
B(5,1,17,AIR)
B(6,1,17,AIR)
B(2,2,17,AIR)
B(3,2,17,AIR)
B(4,2,17,AIR)
B(5,2,17,AIR)
B(6,2,17,AIR)
B(2,3,17,AIR)
B(3,3,17,AIR)
B(4,3,17,AIR)
B(5,3,17,AIR)
B(6,3,17,AIR)
B(2,4,17,AIR)
B(3,4,17,AIR)
B(4,4,17,AIR)
B(5,4,17,AIR)
B(6,4,17,AIR)
B(2,5,17,AIR)
B(3,5,17,AIR)
B(4,5,17,AIR)
B(5,5,17,AIR)
B(6,5,17,AIR)
B(2,6,17,STONE_BRICK_STAIRS:5)
B(3,6,17,AIR)
B(4,6,17,AIR)
B(5,6,17,AIR)
B(6,6,17,STONE_BRICK_STAIRS:4)
B(18,13,17,AIR)
B(19,13,17,AIR)
B(20,13,17,AIR)
B(21,13,17,AIR)
B(22,13,17,AIR)
B(18,14,17,AIR)
B(19,14,17,AIR)
B(20,14,17,AIR)
B(21,14,17,AIR)
B(22,14,17,AIR)
B(18,15,17,AIR)
B(19,15,17,AIR)
B(20,15,17,AIR)
B(21,15,17,AIR)
B(22,15,17,AIR)
B(18,16,17,AIR)
B(19,16,17,AIR)
B(20,16,17,AIR)
B(21,16,17,AIR)
B(22,16,17,AIR)
B(2,17,17,AIR)
B(3,17,17,AIR)
B(4,17,17,AIR)
B(5,17,17,AIR)
B(6,17,17,AIR)
B(18,17,17,AIR)
B(19,17,17,AIR)
B(20,17,17,AIR)
B(21,17,17,AIR)
B(22,17,17,AIR)
B(2,18,17,AIR)
B(3,18,17,AIR)
B(4,18,17,AIR)
B(5,18,17,AIR)
B(6,18,17,AIR)
B(18,18,17,STONE_BRICK_STAIRS:5)
B(19,18,17,AIR)
B(20,18,17,AIR)
B(21,18,17,AIR)
B(22,18,17,STONE_BRICK_STAIRS:4)
B(2,19,17,AIR)
B(3,19,17,AIR)
B(4,19,17,AIR)
B(5,19,17,AIR)
B(6,19,17,AIR)
B(2,20,17,AIR)
B(3,20,17,AIR)
B(4,20,17,AIR)
B(5,20,17,AIR)
B(6,20,17,AIR)
B(2,21,17,AIR)
B(3,21,17,AIR)
B(4,21,17,AIR)
B(5,21,17,AIR)
B(6,21,17,AIR)
B(2,22,17,STONE_BRICK_STAIRS:5)
B(3,22,17,AIR)
B(4,22,17,AIR)
B(5,22,17,AIR)
B(6,22,17,STONE_BRICK_STAIRS:4)
B(1,1,18,AIR)
B(2,1,18,AIR)
B(3,1,18,AIR)
B(4,1,18,AIR)
B(5,1,18,AIR)
B(6,1,18,AIR)
B(7,1,18,AIR)
B(1,2,18,AIR)
B(2,2,18,AIR)
B(3,2,18,AIR)
B(4,2,18,AIR)
B(5,2,18,AIR)
B(6,2,18,AIR)
B(7,2,18,AIR)
B(1,3,18,AIR)
B(2,3,18,AIR)
B(3,3,18,AIR)
B(4,3,18,AIR)
B(5,3,18,AIR)
B(6,3,18,AIR)
B(7,3,18,AIR)
B(1,4,18,AIR)
B(2,4,18,AIR)
B(3,4,18,AIR)
B(4,4,18,AIR)
B(5,4,18,AIR)
B(6,4,18,AIR)
B(7,4,18,AIR)
B(1,5,18,AIR)
B(2,5,18,AIR)
B(3,5,18,AIR)
B(4,5,18,AIR)
B(5,5,18,AIR)
B(6,5,18,AIR)
B(7,5,18,AIR)
B(1,6,18,STONE_BRICK_STAIRS:7)
B(2,6,18,AIR)
B(3,6,18,AIR)
B(4,6,18,AIR)
B(5,6,18,AIR)
B(6,6,18,AIR)
B(7,6,18,STONE_BRICK_STAIRS:7)
B(2,7,18,AIR)
B(3,7,18,AIR)
B(4,7,18,AIR)
B(5,7,18,AIR)
B(6,7,18,AIR)
B(17,13,18,AIR)
B(18,13,18,AIR)
B(19,13,18,AIR)
B(20,13,18,AIR)
B(21,13,18,AIR)
B(22,13,18,AIR)
B(23,13,18,AIR)
B(17,14,18,AIR)
B(18,14,18,AIR)
B(19,14,18,AIR)
B(20,14,18,AIR)
B(21,14,18,AIR)
B(22,14,18,AIR)
B(23,14,18,AIR)
B(17,15,18,AIR)
B(18,15,18,AIR)
B(19,15,18,AIR)
B(20,15,18,AIR)
B(21,15,18,AIR)
B(22,15,18,AIR)
B(23,15,18,AIR)
B(17,16,18,AIR)
B(18,16,18,AIR)
B(19,16,18,AIR)
B(20,16,18,AIR)
B(21,16,18,AIR)
B(22,16,18,AIR)
B(23,16,18,AIR)
B(1,17,18,AIR)
B(2,17,18,AIR)
B(3,17,18,AIR)
B(4,17,18,AIR)
B(5,17,18,AIR)
B(6,17,18,AIR)
B(7,17,18,AIR)
B(17,17,18,AIR)
B(18,17,18,AIR)
B(19,17,18,AIR)
B(20,17,18,AIR)
B(21,17,18,AIR)
B(22,17,18,AIR)
B(23,17,18,AIR)
B(1,18,18,AIR)
B(2,18,18,AIR)
B(3,18,18,AIR)
B(4,18,18,AIR)
B(5,18,18,AIR)
B(6,18,18,AIR)
B(7,18,18,AIR)
B(17,18,18,STONE_BRICK_STAIRS:7)
B(18,18,18,AIR)
B(19,18,18,AIR)
B(20,18,18,AIR)
B(21,18,18,AIR)
B(22,18,18,AIR)
B(23,18,18,STONE_BRICK_STAIRS:7)
B(1,19,18,AIR)
B(2,19,18,AIR)
B(3,19,18,AIR)
B(4,19,18,AIR)
B(5,19,18,AIR)
B(6,19,18,AIR)
B(7,19,18,AIR)
B(18,19,18,AIR)
B(19,19,18,AIR)
B(20,19,18,AIR)
B(21,19,18,AIR)
B(22,19,18,AIR)
B(1,20,18,AIR)
B(2,20,18,AIR)
B(3,20,18,AIR)
B(4,20,18,AIR)
B(5,20,18,AIR)
B(6,20,18,AIR)
B(7,20,18,AIR)
B(1,21,18,AIR)
B(2,21,18,AIR)
B(3,21,18,AIR)
B(4,21,18,AIR)
B(5,21,18,AIR)
B(6,21,18,AIR)
B(7,21,18,AIR)
B(1,22,18,STONE_BRICK_STAIRS:7)
B(2,22,18,AIR)
B(3,22,18,AIR)
B(4,22,18,AIR)
B(5,22,18,AIR)
B(6,22,18,AIR)
B(7,22,18,STONE_BRICK_STAIRS:7)
B(2,23,18,AIR)
B(3,23,18,AIR)
B(4,23,18,AIR)
B(5,23,18,AIR)
B(6,23,18,AIR)
B(1,1,19,AIR)
B(2,1,19,AIR)
B(3,1,19,AIR)
B(4,1,19,TALLGRASS:1)
B(5,1,19,TALLGRASS:1)
B(6,1,19,AIR)
B(7,1,19,AIR)
B(1,2,19,AIR)
B(2,2,19,AIR)
B(3,2,19,AIR)
B(4,2,19,AIR)
B(5,2,19,AIR)
B(6,2,19,AIR)
B(7,2,19,AIR)
B(1,3,19,AIR)
B(2,3,19,AIR)
B(3,3,19,AIR)
B(4,3,19,AIR)
B(5,3,19,AIR)
B(6,3,19,AIR)
B(7,3,19,AIR)
B(1,4,19,AIR)
B(2,4,19,AIR)
B(3,4,19,AIR)
B(4,4,19,AIR)
B(5,4,19,AIR)
B(6,4,19,AIR)
B(7,4,19,AIR)
B(1,5,19,AIR)
B(2,5,19,AIR)
B(3,5,19,AIR)
B(4,5,19,AIR)
B(5,5,19,AIR)
B(6,5,19,AIR)
B(7,5,19,AIR)
B(1,6,19,AIR)
B(2,6,19,AIR)
B(3,6,19,AIR)
B(4,6,19,AIR)
B(5,6,19,AIR)
B(6,6,19,AIR)
B(7,6,19,AIR)
B(2,7,19,AIR)
B(3,7,19,AIR)
B(4,7,19,AIR)
B(5,7,19,AIR)
B(6,7,19,AIR)
B(3,8,19,AIR)
B(4,8,19,AIR)
B(5,8,19,AIR)
B(3,9,19,AIR)
B(4,9,19,AIR)
B(5,9,19,AIR)
B(3,10,19,AIR)
B(4,10,19,AIR)
B(5,10,19,AIR)
B(3,11,19,AIR)
B(4,11,19,AIR)
B(5,11,19,AIR)
B(3,12,19,AIR)
B(4,12,19,AIR)
B(5,12,19,AIR)
B(3,13,19,AIR)
B(4,13,19,AIR)
B(5,13,19,AIR)
B(17,13,19,AIR)
B(18,13,19,AIR)
B(19,13,19,TALLGRASS:1)
B(20,13,19,AIR)
B(21,13,19,AIR)
B(22,13,19,AIR)
B(23,13,19,AIR)
B(3,14,19,AIR)
B(4,14,19,AIR)
B(5,14,19,AIR)
B(17,14,19,AIR)
B(18,14,19,AIR)
B(19,14,19,AIR)
B(20,14,19,AIR)
B(21,14,19,AIR)
B(22,14,19,AIR)
B(23,14,19,AIR)
B(3,15,19,AIR)
B(4,15,19,AIR)
B(5,15,19,AIR)
B(17,15,19,AIR)
B(18,15,19,AIR)
B(19,15,19,AIR)
B(20,15,19,AIR)
B(21,15,19,AIR)
B(22,15,19,AIR)
B(23,15,19,AIR)
B(3,16,19,AIR)
B(4,16,19,AIR)
B(5,16,19,AIR)
B(17,16,19,AIR)
B(18,16,19,AIR)
B(19,16,19,AIR)
B(20,16,19,AIR)
B(21,16,19,AIR)
B(22,16,19,AIR)
B(23,16,19,AIR)
B(1,17,19,AIR)
B(2,17,19,AIR)
B(3,17,19,AIR)
B(4,17,19,AIR)
B(5,17,19,AIR)
B(6,17,19,AIR)
B(7,17,19,AIR)
B(17,17,19,AIR)
B(18,17,19,AIR)
B(19,17,19,AIR)
B(20,17,19,AIR)
B(21,17,19,AIR)
B(22,17,19,AIR)
B(23,17,19,AIR)
B(1,18,19,AIR)
B(2,18,19,AIR)
B(3,18,19,AIR)
B(4,18,19,AIR)
B(5,18,19,AIR)
B(6,18,19,AIR)
B(7,18,19,AIR)
B(17,18,19,AIR)
B(18,18,19,AIR)
B(19,18,19,AIR)
B(20,18,19,AIR)
B(21,18,19,AIR)
B(22,18,19,AIR)
B(23,18,19,AIR)
B(1,19,19,AIR)
B(2,19,19,AIR)
B(3,19,19,AIR)
B(4,19,19,AIR)
B(5,19,19,AIR)
B(6,19,19,AIR)
B(7,19,19,AIR)
B(18,19,19,AIR)
B(19,19,19,AIR)
B(20,19,19,AIR)
B(21,19,19,AIR)
B(22,19,19,AIR)
B(1,20,19,AIR)
B(2,20,19,AIR)
B(3,20,19,AIR)
B(4,20,19,AIR)
B(5,20,19,AIR)
B(6,20,19,AIR)
B(7,20,19,AIR)
B(19,20,19,AIR)
B(20,20,19,AIR)
B(21,20,19,AIR)
B(1,21,19,AIR)
B(2,21,19,AIR)
B(3,21,19,AIR)
B(4,21,19,AIR)
B(5,21,19,AIR)
B(6,21,19,AIR)
B(7,21,19,AIR)
B(1,22,19,AIR)
B(2,22,19,AIR)
B(3,22,19,AIR)
B(4,22,19,AIR)
B(5,22,19,AIR)
B(6,22,19,AIR)
B(7,22,19,AIR)
B(2,23,19,AIR)
B(3,23,19,AIR)
B(4,23,19,AIR)
B(5,23,19,AIR)
B(6,23,19,AIR)
B(3,24,19,AIR)
B(4,24,19,AIR)
B(5,24,19,AIR)
B(2,1,20,AIR)
B(3,1,20,TALLGRASS:1)
B(5,1,20,TALLGRASS:2)
B(6,1,20,AIR)
B(7,1,20,AIR)
B(8,1,20,AIR)
B(1,2,20,AIR)
B(2,2,20,AIR)
B(3,2,20,AIR)
B(4,2,20,AIR)
B(5,2,20,AIR)
B(6,2,20,AIR)
B(7,2,20,AIR)
B(8,2,20,AIR)
B(1,3,20,AIR)
B(2,3,20,AIR)
B(3,3,20,AIR)
B(4,3,20,AIR)
B(5,3,20,AIR)
B(6,3,20,AIR)
B(7,3,20,AIR)
B(8,3,20,AIR)
B(1,4,20,AIR)
B(2,4,20,AIR)
B(3,4,20,AIR)
B(4,4,20,AIR)
B(5,4,20,AIR)
B(6,4,20,AIR)
B(7,4,20,AIR)
B(1,5,20,AIR)
B(2,5,20,AIR)
B(3,5,20,AIR)
B(4,5,20,AIR)
B(5,5,20,AIR)
B(6,5,20,AIR)
B(7,5,20,AIR)
B(1,6,20,AIR)
B(2,6,20,AIR)
B(3,6,20,AIR)
B(4,6,20,AIR)
B(5,6,20,AIR)
B(6,6,20,AIR)
B(7,6,20,AIR)
B(2,7,20,AIR)
B(3,7,20,AIR)
B(4,7,20,AIR)
B(5,7,20,AIR)
B(6,7,20,AIR)
B(3,8,20,AIR)
B(4,8,20,AIR)
B(5,8,20,AIR)
B(3,9,20,AIR)
B(4,9,20,AIR)
B(5,9,20,AIR)
B(3,10,20,AIR)
B(4,10,20,AIR)
B(5,10,20,AIR)
B(3,11,20,AIR)
B(4,11,20,AIR)
B(5,11,20,AIR)
B(3,12,20,AIR)
B(4,12,20,AIR)
B(5,12,20,AIR)
B(3,13,20,AIR)
B(4,13,20,AIR)
B(5,13,20,AIR)
B(15,13,20,STONE_SLAB)
B(16,13,20,AIR)
B(17,13,20,AIR)
B(18,13,20,AIR)
B(19,13,20,AIR)
B(21,13,20,TALLGRASS:1)
B(22,13,20,AIR)
B(3,14,20,AIR)
B(4,14,20,AIR)
B(5,14,20,AIR)
B(13,14,20,STONE_SLAB)
B(14,14,20,AIR)
B(15,14,20,AIR)
B(16,14,20,AIR)
B(17,14,20,AIR)
B(18,14,20,AIR)
B(19,14,20,AIR)
B(20,14,20,AIR)
B(21,14,20,AIR)
B(22,14,20,AIR)
B(23,14,20,AIR)
B(3,15,20,AIR)
B(4,15,20,AIR)
B(5,15,20,AIR)
B(11,15,20,STONE_SLAB)
B(12,15,20,AIR)
B(13,15,20,AIR)
B(14,15,20,AIR)
B(15,15,20,AIR)
B(16,15,20,AIR)
B(17,15,20,AIR)
B(18,15,20,AIR)
B(19,15,20,AIR)
B(20,15,20,AIR)
B(21,15,20,AIR)
B(22,15,20,AIR)
B(23,15,20,AIR)
B(3,16,20,AIR)
B(4,16,20,AIR)
B(5,16,20,AIR)
B(9,16,20,STONE_SLAB)
B(10,16,20,AIR)
B(11,16,20,AIR)
B(12,16,20,AIR)
B(13,16,20,AIR)
B(14,16,20,AIR)
B(15,16,20,STONE_SLAB)
B(17,16,20,AIR)
B(18,16,20,AIR)
B(19,16,20,AIR)
B(20,16,20,AIR)
B(21,16,20,AIR)
B(22,16,20,AIR)
B(23,16,20,AIR)
B(2,17,20,AIR)
B(3,17,20,AIR)
B(4,17,20,AIR)
B(5,17,20,AIR)
B(6,17,20,AIR)
B(7,17,20,AIR)
B(8,17,20,AIR)
B(9,17,20,AIR)
B(10,17,20,AIR)
B(11,17,20,AIR)
B(12,17,20,AIR)
B(13,17,20,STONE_SLAB)
B(17,17,20,AIR)
B(18,17,20,AIR)
B(19,17,20,AIR)
B(20,17,20,AIR)
B(21,17,20,AIR)
B(22,17,20,AIR)
B(23,17,20,AIR)
B(1,18,20,AIR)
B(2,18,20,AIR)
B(3,18,20,AIR)
B(4,18,20,AIR)
B(5,18,20,AIR)
B(6,18,20,AIR)
B(7,18,20,AIR)
B(8,18,20,AIR)
B(9,18,20,AIR)
B(10,18,20,AIR)
B(11,18,20,STONE_SLAB)
B(17,18,20,AIR)
B(18,18,20,AIR)
B(19,18,20,AIR)
B(20,18,20,AIR)
B(21,18,20,AIR)
B(22,18,20,AIR)
B(23,18,20,AIR)
B(1,19,20,AIR)
B(2,19,20,AIR)
B(3,19,20,AIR)
B(4,19,20,AIR)
B(5,19,20,AIR)
B(6,19,20,AIR)
B(7,19,20,AIR)
B(8,19,20,AIR)
B(9,19,20,STONE_SLAB)
B(18,19,20,AIR)
B(19,19,20,AIR)
B(20,19,20,AIR)
B(21,19,20,AIR)
B(22,19,20,AIR)
B(1,20,20,AIR)
B(2,20,20,AIR)
B(3,20,20,AIR)
B(4,20,20,AIR)
B(5,20,20,AIR)
B(6,20,20,AIR)
B(7,20,20,AIR)
B(19,20,20,AIR)
B(20,20,20,AIR)
B(21,20,20,AIR)
B(1,21,20,AIR)
B(2,21,20,AIR)
B(3,21,20,AIR)
B(4,21,20,AIR)
B(5,21,20,AIR)
B(6,21,20,AIR)
B(7,21,20,AIR)
B(1,22,20,AIR)
B(2,22,20,AIR)
B(3,22,20,AIR)
B(4,22,20,AIR)
B(5,22,20,AIR)
B(6,22,20,AIR)
B(7,22,20,AIR)
B(2,23,20,AIR)
B(3,23,20,AIR)
B(4,23,20,AIR)
B(5,23,20,AIR)
B(6,23,20,AIR)
B(3,24,20,AIR)
B(4,24,20,AIR)
B(5,24,20,AIR)
B(1,1,21,AIR)
B(2,1,21,AIR)
B(3,1,21,TALLGRASS:1)
B(4,1,21,TALLGRASS:1)
B(5,1,21,TALLGRASS:1)
B(6,1,21,AIR)
B(7,1,21,AIR)
B(1,2,21,AIR)
B(2,2,21,AIR)
B(3,2,21,AIR)
B(4,2,21,AIR)
B(5,2,21,AIR)
B(6,2,21,AIR)
B(7,2,21,AIR)
B(1,3,21,AIR)
B(2,3,21,AIR)
B(3,3,21,AIR)
B(4,3,21,AIR)
B(5,3,21,AIR)
B(6,3,21,AIR)
B(7,3,21,AIR)
B(1,4,21,AIR)
B(2,4,21,AIR)
B(3,4,21,AIR)
B(4,4,21,AIR)
B(5,4,21,AIR)
B(6,4,21,AIR)
B(7,4,21,AIR)
B(1,5,21,AIR)
B(2,5,21,AIR)
B(3,5,21,AIR)
B(4,5,21,AIR)
B(5,5,21,AIR)
B(6,5,21,AIR)
B(7,5,21,AIR)
B(1,6,21,AIR)
B(2,6,21,AIR)
B(3,6,21,AIR)
B(4,6,21,AIR)
B(5,6,21,AIR)
B(6,6,21,AIR)
B(7,6,21,AIR)
B(2,7,21,AIR)
B(3,7,21,AIR)
B(4,7,21,AIR)
B(5,7,21,AIR)
B(6,7,21,AIR)
B(3,8,21,AIR)
B(4,8,21,AIR)
B(5,8,21,AIR)
B(3,9,21,AIR)
B(4,9,21,AIR)
B(5,9,21,AIR)
B(3,10,21,AIR)
B(4,10,21,AIR)
B(5,10,21,AIR)
B(3,11,21,AIR)
B(4,11,21,AIR)
B(5,11,21,AIR)
B(3,12,21,AIR)
B(4,12,21,AIR)
B(5,12,21,AIR)
B(3,13,21,AIR)
B(4,13,21,AIR)
B(5,13,21,AIR)
B(17,13,21,AIR)
B(18,13,21,AIR)
B(19,13,21,TALLGRASS:2)
B(20,13,21,AIR)
B(21,13,21,TALLGRASS:1)
B(22,13,21,AIR)
B(23,13,21,AIR)
B(3,14,21,AIR)
B(4,14,21,AIR)
B(5,14,21,AIR)
B(17,14,21,AIR)
B(18,14,21,AIR)
B(19,14,21,AIR)
B(20,14,21,AIR)
B(21,14,21,AIR)
B(22,14,21,AIR)
B(23,14,21,AIR)
B(3,15,21,AIR)
B(4,15,21,AIR)
B(5,15,21,AIR)
B(17,15,21,AIR)
B(18,15,21,AIR)
B(19,15,21,AIR)
B(20,15,21,AIR)
B(21,15,21,AIR)
B(22,15,21,AIR)
B(23,15,21,AIR)
B(3,16,21,AIR)
B(4,16,21,AIR)
B(5,16,21,AIR)
B(17,16,21,AIR)
B(18,16,21,AIR)
B(19,16,21,AIR)
B(20,16,21,AIR)
B(21,16,21,AIR)
B(22,16,21,AIR)
B(23,16,21,AIR)
B(1,17,21,AIR)
B(2,17,21,AIR)
B(3,17,21,AIR)
B(4,17,21,AIR)
B(5,17,21,AIR)
B(6,17,21,AIR)
B(7,17,21,AIR)
B(17,17,21,AIR)
B(18,17,21,AIR)
B(19,17,21,AIR)
B(20,17,21,AIR)
B(21,17,21,AIR)
B(22,17,21,AIR)
B(23,17,21,AIR)
B(1,18,21,AIR)
B(2,18,21,AIR)
B(3,18,21,AIR)
B(4,18,21,AIR)
B(5,18,21,AIR)
B(6,18,21,AIR)
B(7,18,21,AIR)
B(17,18,21,AIR)
B(18,18,21,AIR)
B(19,18,21,AIR)
B(20,18,21,AIR)
B(21,18,21,AIR)
B(22,18,21,AIR)
B(23,18,21,AIR)
B(1,19,21,AIR)
B(2,19,21,AIR)
B(3,19,21,AIR)
B(4,19,21,AIR)
B(5,19,21,AIR)
B(6,19,21,AIR)
B(7,19,21,AIR)
B(18,19,21,AIR)
B(19,19,21,AIR)
B(20,19,21,AIR)
B(21,19,21,AIR)
B(22,19,21,AIR)
B(1,20,21,AIR)
B(2,20,21,AIR)
B(3,20,21,AIR)
B(4,20,21,AIR)
B(5,20,21,AIR)
B(6,20,21,AIR)
B(7,20,21,AIR)
B(19,20,21,AIR)
B(20,20,21,AIR)
B(21,20,21,AIR)
B(1,21,21,AIR)
B(2,21,21,AIR)
B(3,21,21,AIR)
B(4,21,21,AIR)
B(5,21,21,AIR)
B(6,21,21,AIR)
B(7,21,21,AIR)
B(1,22,21,AIR)
B(2,22,21,AIR)
B(3,22,21,AIR)
B(4,22,21,AIR)
B(5,22,21,AIR)
B(6,22,21,AIR)
B(7,22,21,AIR)
B(2,23,21,AIR)
B(3,23,21,AIR)
B(4,23,21,AIR)
B(5,23,21,AIR)
B(6,23,21,AIR)
B(3,24,21,AIR)
B(4,24,21,AIR)
B(5,24,21,AIR)
B(1,1,22,AIR)
B(2,1,22,AIR)
B(3,1,22,AIR)
B(4,1,22,AIR)
B(5,1,22,AIR)
B(6,1,22,AIR)
B(7,1,22,AIR)
B(1,2,22,AIR)
B(2,2,22,AIR)
B(3,2,22,AIR)
B(4,2,22,AIR)
B(5,2,22,AIR)
B(6,2,22,AIR)
B(7,2,22,AIR)
B(1,3,22,AIR)
B(2,3,22,AIR)
B(3,3,22,AIR)
B(4,3,22,AIR)
B(5,3,22,AIR)
B(6,3,22,AIR)
B(7,3,22,AIR)
B(1,4,22,AIR)
B(2,4,22,AIR)
B(3,4,22,AIR)
B(4,4,22,AIR)
B(5,4,22,AIR)
B(6,4,22,AIR)
B(7,4,22,AIR)
B(1,5,22,AIR)
B(2,5,22,AIR)
B(3,5,22,AIR)
B(4,5,22,AIR)
B(5,5,22,AIR)
B(6,5,22,AIR)
B(7,5,22,AIR)
B(1,6,22,STONE_BRICK_STAIRS:6)
B(2,6,22,AIR)
B(3,6,22,AIR)
B(4,6,22,AIR)
B(5,6,22,AIR)
B(6,6,22,AIR)
B(7,6,22,STONE_BRICK_STAIRS:6)
B(2,7,22,AIR)
B(3,7,22,AIR)
B(4,7,22,AIR)
B(5,7,22,AIR)
B(6,7,22,AIR)
B(17,13,22,AIR)
B(18,13,22,AIR)
B(19,13,22,AIR)
B(20,13,22,AIR)
B(21,13,22,AIR)
B(22,13,22,AIR)
B(23,13,22,AIR)
B(17,14,22,AIR)
B(18,14,22,AIR)
B(19,14,22,AIR)
B(20,14,22,AIR)
B(21,14,22,AIR)
B(22,14,22,AIR)
B(23,14,22,AIR)
B(17,15,22,AIR)
B(18,15,22,AIR)
B(19,15,22,AIR)
B(20,15,22,AIR)
B(21,15,22,AIR)
B(22,15,22,AIR)
B(23,15,22,AIR)
B(17,16,22,AIR)
B(18,16,22,AIR)
B(19,16,22,AIR)
B(20,16,22,AIR)
B(21,16,22,AIR)
B(22,16,22,AIR)
B(23,16,22,AIR)
B(1,17,22,AIR)
B(2,17,22,AIR)
B(3,17,22,AIR)
B(4,17,22,AIR)
B(5,17,22,AIR)
B(6,17,22,AIR)
B(7,17,22,AIR)
B(17,17,22,AIR)
B(18,17,22,AIR)
B(19,17,22,AIR)
B(20,17,22,AIR)
B(21,17,22,AIR)
B(22,17,22,AIR)
B(23,17,22,AIR)
B(1,18,22,AIR)
B(2,18,22,AIR)
B(3,18,22,AIR)
B(4,18,22,AIR)
B(5,18,22,AIR)
B(6,18,22,AIR)
B(7,18,22,AIR)
B(17,18,22,STONE_BRICK_STAIRS:6)
B(18,18,22,AIR)
B(19,18,22,AIR)
B(20,18,22,AIR)
B(21,18,22,AIR)
B(22,18,22,AIR)
B(23,18,22,STONE_BRICK_STAIRS:6)
B(1,19,22,AIR)
B(2,19,22,AIR)
B(3,19,22,AIR)
B(4,19,22,AIR)
B(5,19,22,AIR)
B(6,19,22,AIR)
B(7,19,22,AIR)
B(18,19,22,AIR)
B(19,19,22,AIR)
B(20,19,22,AIR)
B(21,19,22,AIR)
B(22,19,22,AIR)
B(1,20,22,AIR)
B(2,20,22,AIR)
B(3,20,22,AIR)
B(4,20,22,AIR)
B(5,20,22,AIR)
B(6,20,22,AIR)
B(7,20,22,AIR)
B(1,21,22,AIR)
B(2,21,22,AIR)
B(3,21,22,AIR)
B(4,21,22,AIR)
B(5,21,22,AIR)
B(6,21,22,AIR)
B(7,21,22,AIR)
B(1,22,22,STONE_BRICK_STAIRS:6)
B(2,22,22,AIR)
B(3,22,22,AIR)
B(4,22,22,AIR)
B(5,22,22,AIR)
B(6,22,22,AIR)
B(7,22,22,STONE_BRICK_STAIRS:6)
B(2,23,22,AIR)
B(3,23,22,AIR)
B(4,23,22,AIR)
B(5,23,22,AIR)
B(6,23,22,AIR)
B(2,1,23,AIR)
B(3,1,23,AIR)
B(5,1,23,AIR)
B(6,1,23,AIR)
B(2,2,23,AIR)
B(3,2,23,AIR)
B(4,2,23,AIR)
B(5,2,23,AIR)
B(6,2,23,AIR)
B(2,3,23,AIR)
B(3,3,23,AIR)
B(4,3,23,AIR)
B(5,3,23,AIR)
B(6,3,23,AIR)
B(2,4,23,AIR)
B(3,4,23,AIR)
B(4,4,23,AIR)
B(5,4,23,AIR)
B(6,4,23,AIR)
B(2,5,23,AIR)
B(3,5,23,AIR)
B(4,5,23,AIR)
B(5,5,23,AIR)
B(6,5,23,AIR)
B(2,6,23,STONE_BRICK_STAIRS:5)
B(3,6,23,AIR)
B(4,6,23,AIR)
B(5,6,23,AIR)
B(6,6,23,STONE_BRICK_STAIRS:4)
B(18,13,23,AIR)
B(19,13,23,AIR)
B(21,13,23,AIR)
B(22,13,23,AIR)
B(18,14,23,AIR)
B(19,14,23,AIR)
B(20,14,23,AIR)
B(21,14,23,AIR)
B(22,14,23,AIR)
B(18,15,23,AIR)
B(19,15,23,AIR)
B(20,15,23,AIR)
B(21,15,23,AIR)
B(22,15,23,AIR)
B(18,16,23,AIR)
B(19,16,23,AIR)
B(20,16,23,AIR)
B(21,16,23,AIR)
B(22,16,23,AIR)
B(2,17,23,AIR)
B(3,17,23,AIR)
B(5,17,23,AIR)
B(6,17,23,AIR)
B(18,17,23,AIR)
B(19,17,23,AIR)
B(20,17,23,AIR)
B(21,17,23,AIR)
B(22,17,23,AIR)
B(2,18,23,AIR)
B(3,18,23,AIR)
B(4,18,23,AIR)
B(5,18,23,AIR)
B(6,18,23,AIR)
B(18,18,23,STONE_BRICK_STAIRS:5)
B(19,18,23,AIR)
B(20,18,23,AIR)
B(21,18,23,AIR)
B(22,18,23,STONE_BRICK_STAIRS:4)
B(2,19,23,AIR)
B(3,19,23,AIR)
B(4,19,23,AIR)
B(5,19,23,AIR)
B(6,19,23,AIR)
B(2,20,23,AIR)
B(3,20,23,AIR)
B(4,20,23,AIR)
B(5,20,23,AIR)
B(6,20,23,AIR)
B(2,21,23,AIR)
B(3,21,23,AIR)
B(4,21,23,AIR)
B(5,21,23,AIR)
B(6,21,23,AIR)
B(2,22,23,STONE_BRICK_STAIRS:5)
B(3,22,23,AIR)
B(4,22,23,AIR)
B(5,22,23,AIR)
B(6,22,23,STONE_BRICK_STAIRS:4)

RB(4,5,4,MOB_SPAWNER,../../NBT/Spawners/Zombie.nbt,50,MOB_SPAWNER,../../NBT/Spawners/Skeleton.nbt,50,MOB_SPAWNER,../../NBT/Spawners/Spider.nbt,100)
RB(20,9,4,MOB_SPAWNER,../../NBT/Spawners/Zombie.nbt,50,MOB_SPAWNER,../../NBT/Spawners/Skeleton.nbt,50,MOB_SPAWNER,../../NBT/Spawners/Spider.nbt,100)
RB(4,1,20,MOB_SPAWNER,../../NBT/Spawners/Zombie.nbt,50,MOB_SPAWNER,../../NBT/Spawners/Skeleton.nbt,50,MOB_SPAWNER,../../NBT/Spawners/Spider.nbt,100)
RB(20,13,20,MOB_SPAWNER,../../NBT/Spawners/Zombie.nbt,50,MOB_SPAWNER,../../NBT/Spawners/Skeleton.nbt,50,MOB_SPAWNER,../../NBT/Spawners/Spider.nbt,100)

B(4,5,1,CHEST:3,../../NBT/Chests/SimpleDungeon.nbt)
B(20,9,1,CHEST:3,../../NBT/Chests/SimpleDungeon.nbt)
B(1,5,4,CHEST:5,../../NBT/Chests/SimpleDungeon.nbt)
B(23,9,4,CHEST:4,../../NBT/Chests/SimpleDungeon.nbt)
B(1,1,20,CHEST:5,../../NBT/Chests/SimpleDungeon.nbt)
B(23,13,20,CHEST:4,../../NBT/Chests/SimpleDungeon.nbt)
B(1,17,20,CHEST:5,../../NBT/Chests/SimpleDungeon.nbt)
B(4,1,23,CHEST:2,../../NBT/Chests/SimpleDungeon.nbt)
B(20,13,23,CHEST:2,../../NBT/Chests/SimpleDungeon.nbt)
B(4,17,23,CHEST:2,../../NBT/Chests/SimpleDungeon.nbt)

# Size (X*Y*Z): 25*25*25

#######################################################################
# +-----------------------------------------------------------------+ #
# |                            BO3 checks                           | #
# +-----------------------------------------------------------------+ #
#######################################################################

# Require a condition at a certain location in order for the BO3 to be spawned.
# BlockCheck(x,y,z,BlockName[,BlockName[,...]]) - one of the blocks must be at the location
# BlockCheckNot(x,y,z,BlockName[,BlockName[,...]]) - all the blocks must not be at the location
# LightCheck(x,y,z,minLightLevel,maxLightLevel) - light must be between min and max (inclusive)

# You can use "Solid" as a BlockName for matching all solid blocks or "All" to match all blocks that aren't air.

# Examples:
#   BlockCheck(0,-1,0,GRASS,DIRT)  Require grass or dirt just below the object
#   BlockCheck(0,-1,0,Solid)       Require any solid block just below the object
#   BlockCheck(0,-1,0,WOOL)        Require any type of wool just below the object
#   BlockCheck(0,-1,0,WOOL:0)      Require white wool just below the object
#   BlockCheckNot(0,0,0,WOOL:0)   Require that there is no white wool below the object
#   LightCheck(0,0,0,0,1)          Require almost complete darkness just below the object

# Ensure the ceiling is sufficiently covered in solid blocks.
BlockCheck(0,25,0,Solid)
BlockCheck(0,25,25,Solid)
BlockCheck(25,25,0,Solid)
BlockCheck(25,25,25,Solid)

#######################################################################
# +-----------------------------------------------------------------+ #
# |                             Branches                            | #
# +-----------------------------------------------------------------+ #
#######################################################################

# Branches are objects that will spawn when this object spawns when it is used in
# the CustomStructure resource. Branches can also have branches, making complex
# structures possible. See the wiki for more details.

# Regular Branches spawn each branch with an independent chance of spawning.
# Branch(x,y,z,branchName,rotation,chance[,anotherBranchName,rotation,chance[,...]][IndividualChance])
# branchName - name of the object to spawn.
# rotation - NORTH, SOUTH, EAST or WEST.
# IndividualChance - The chance each branch has to spawn, assumed to be 100 when left blank

# Weighted Branches spawn branches with a dependent chance of spawning.
# WBR(x,y,z,branchName,rotation,chance[,anotherBranchName,rotation,chance[,...]][MaxChanceOutOf])
# MaxChanceOutOf - The chance all branches have to spawn out of, assumed to be 100 when left blank
