
#######################################################################
# +-----------------------------------------------------------------+ #
# |                            BO3 object                           | #
# +-----------------------------------------------------------------+ #
#######################################################################

# This is the config file of a custom object.
# If you add this object correctly to your BiomeConfigs, it will spawn in the world.

# This is the creator of this BO3 object
# See: https://imgur.com/a/JanPA
Author: Arcensoth, designed by McNoodlor

# A short description of this BO3 object
Description: No description given

# The BO3 version, don't change this! It can be used by external applications to do a version check.
Version: 3

# The settings mode, WriteAll, WriteWithoutComments or WriteDisable. See WorldConfig.
SettingsMode: WriteDisable


#######################################################################
# +-----------------------------------------------------------------+ #
# |                          Main settings                          | #
# +-----------------------------------------------------------------+ #
#######################################################################

# This needs to be set to true to spawn the object in the Tree and Sapling resources.
Tree: false

# The frequency of the BO3 from 1 to 200. Tries this many times to spawn this BO3 when using the CustomObject(...) resource.
# Ignored by Tree(..), Sapling(..) and CustomStructure(..)
Frequency: 1

# The rarity of the BO3 from 0 to 100. Each spawn attempt has rarity% chance to succeed when using the CustomObject(...) resource.
# Ignored by Tree(..), Sapling(..) and CustomStructure(..)
Rarity: 1.0

# If you set this to true, the BO3 will be placed with a random rotation.
RotateRandomly: false

# The spawn height of the BO3 - randomY, highestBlock or highestSolidBlock.
SpawnHeight: randomY

# The height limits for the BO3.
MinHeight: 0

MaxHeight: 255

# Objects can have other objects attacthed to it: branches. Branches can also
# have branches attached to it, which can also have branches, etc. This is the
# maximum branch depth for this objects.
MaxBranchDepth: 10

# When spawned with the UseWorld keyword, this BO3 should NOT spawn in the following biomes.
# If you writer.write the BO3 name directly in the BiomeConfigs, this will be ignored.
ExcludedBiomes: All


#######################################################################
# +-----------------------------------------------------------------+ #
# |                      Source block settings                      | #
# +-----------------------------------------------------------------+ #
#######################################################################

# The B(s) the BO3 should spawn in.
SourceBlocks: STONE,STONE:1,STONE:3,STONE:5,COBBLESTONE,MOSSY_COBBLESTONE,SANDSTONE,HARD_CLAY,STAINED_CLAY,PRISMARINE,DIRT,DIRT:1,GRASS,SAND,GRAVEL,CLAY,OBSIDIAN,COAL_ORE,IRON_ORE,GOLD_ORE,REDSTONE_ORE,DIAMOND_ORE,LAPIS_ORE,EMERALD_ORE,STATIONARY_WATER,STATIONARY_LAVA

# The maximum percentage of the BO3 that can be outside the SourceBlock.
# The BO3 won't be placed on a location with more blocks outside the SourceBlock than this percentage.
MaxPercentageOutsideSourceBlock: 45

# What to do when a block is about to be placed outside the SourceBlock? (dontPlace, placeAnyway)
OutsideSourceBlock: dontPlace


#######################################################################
# +-----------------------------------------------------------------+ #
# |                              Blocks                             | #
# +-----------------------------------------------------------------+ #
#######################################################################

# All the blocks used in the BO3 are listed here. Possible blocks:
# B(x,y,z,id[.data][,nbtfile.nbt)
# RB(x,y,z,id[:data][,nbtfile.nbt],chance[,id[:data][,nbtfile.nbt],chance[,...]])
# So RB(0,0,0,CHEST,chest.nbt,50,CHEST,anotherchest.nbt,100) will spawn a chest at
# the BO3 origin, and give it a 50% chance to have the contents of chest.nbt, or, if that
# fails, a 100% percent chance to have the contents of anotherchest.nbt.
B(0,4,0,STONEBRICK:2)
B(1,4,0,STONEBRICK:2)
B(2,4,0,STONEBRICK:2)
B(3,4,0,STONEBRICK:2)
B(4,4,0,STONEBRICK:2)
B(5,4,0,STONEBRICK)
B(6,4,0,STONEBRICK:2)
B(7,4,0,STONEBRICK:2)
B(8,4,0,STONEBRICK:2)
B(9,4,0,STONEBRICK)
B(10,4,0,STONEBRICK:2)
B(11,4,0,STONEBRICK)
B(12,4,0,STONEBRICK)
B(13,4,0,STONEBRICK:1)
B(14,4,0,STONEBRICK)
B(15,4,0,STONEBRICK:1)
B(16,4,0,STONEBRICK)
B(0,5,0,STONEBRICK)
B(1,5,0,MOSSY_COBBLESTONE)
B(2,5,0,MOSSY_COBBLESTONE)
B(3,5,0,STONE)
B(4,5,0,MOSSY_COBBLESTONE)
B(5,5,0,MOSSY_COBBLESTONE)
B(6,5,0,MOSSY_COBBLESTONE)
B(7,5,0,MOSSY_COBBLESTONE)
B(8,5,0,STONEBRICK:1)
B(9,5,0,MOSSY_COBBLESTONE)
B(10,5,0,EMERALD_ORE)
B(11,5,0,MOSSY_COBBLESTONE)
B(12,5,0,STONE)
B(13,5,0,MOSSY_COBBLESTONE)
B(14,5,0,EMERALD_ORE)
B(15,5,0,MOSSY_COBBLESTONE)
B(16,5,0,STONEBRICK)
B(0,6,0,STONEBRICK)
B(1,6,0,STONE)
B(2,6,0,MOSSY_COBBLESTONE)
B(3,6,0,MOSSY_COBBLESTONE)
B(4,6,0,MOSSY_COBBLESTONE)
B(5,6,0,STONE)
B(6,6,0,MOSSY_COBBLESTONE)
B(7,6,0,STONE)
B(8,6,0,STONEBRICK:1)
B(9,6,0,MOSSY_COBBLESTONE)
B(10,6,0,STONE)
B(11,6,0,STONE)
B(12,6,0,STONE)
B(13,6,0,MOSSY_COBBLESTONE)
B(14,6,0,MOSSY_COBBLESTONE)
B(15,6,0,MOSSY_COBBLESTONE)
B(16,6,0,STONEBRICK)
B(0,7,0,STONEBRICK:2)
B(1,7,0,EMERALD_ORE)
B(2,7,0,STONE)
B(3,7,0,EMERALD_ORE)
B(4,7,0,EMERALD_ORE)
B(5,7,0,MOSSY_COBBLESTONE)
B(6,7,0,STONE)
B(7,7,0,MOSSY_COBBLESTONE)
B(8,7,0,STONEBRICK:1)
B(9,7,0,MOSSY_COBBLESTONE)
B(10,7,0,MOSSY_COBBLESTONE)
B(11,7,0,MOSSY_COBBLESTONE)
B(12,7,0,MOSSY_COBBLESTONE)
B(13,7,0,MOSSY_COBBLESTONE)
B(14,7,0,MOSSY_COBBLESTONE)
B(15,7,0,STONE)
B(16,7,0,STONEBRICK:1)
B(0,8,0,STONEBRICK)
B(1,8,0,MOSSY_COBBLESTONE)
B(2,8,0,STONE)
B(3,8,0,STONE)
B(4,8,0,EMERALD_ORE)
B(5,8,0,EMERALD_ORE)
B(6,8,0,STONE)
B(7,8,0,MOSSY_COBBLESTONE)
B(8,8,0,STONEBRICK:2)
B(9,8,0,MOSSY_COBBLESTONE)
B(10,8,0,MOSSY_COBBLESTONE)
B(11,8,0,STONE)
B(12,8,0,MOSSY_COBBLESTONE)
B(13,8,0,EMERALD_ORE)
B(14,8,0,MOSSY_COBBLESTONE)
B(15,8,0,MOSSY_COBBLESTONE)
B(16,8,0,STONEBRICK)
B(0,9,0,STONEBRICK)
B(1,9,0,STONE)
B(2,9,0,MOSSY_COBBLESTONE)
B(3,9,0,MOSSY_COBBLESTONE)
B(4,9,0,MOSSY_COBBLESTONE)
B(5,9,0,MOSSY_COBBLESTONE)
B(6,9,0,MOSSY_COBBLESTONE)
B(7,9,0,STONE)
B(8,9,0,STONEBRICK)
B(9,9,0,MOSSY_COBBLESTONE)
B(10,9,0,STONE)
B(11,9,0,STONE)
B(12,9,0,STONE)
B(13,9,0,MOSSY_COBBLESTONE)
B(14,9,0,STONE)
B(15,9,0,MOSSY_COBBLESTONE)
B(16,9,0,STONEBRICK)
B(0,10,0,STONEBRICK:1)
B(1,10,0,STONE)
B(2,10,0,MOSSY_COBBLESTONE)
B(3,10,0,STONE)
B(4,10,0,STONE)
B(5,10,0,STONE)
B(6,10,0,MOSSY_COBBLESTONE)
B(7,10,0,EMERALD_ORE)
B(8,10,0,STONEBRICK:1)
B(9,10,0,MOSSY_COBBLESTONE)
B(10,10,0,STONE)
B(11,10,0,MOSSY_COBBLESTONE)
B(12,10,0,STONE)
B(13,10,0,MOSSY_COBBLESTONE)
B(14,10,0,STONE)
B(15,10,0,STONE)
B(16,10,0,STONEBRICK:2)
B(0,11,0,STONEBRICK)
B(1,11,0,EMERALD_ORE)
B(2,11,0,MOSSY_COBBLESTONE)
B(3,11,0,MOSSY_COBBLESTONE)
B(4,11,0,STONE)
B(5,11,0,MOSSY_COBBLESTONE)
B(6,11,0,EMERALD_ORE)
B(7,11,0,EMERALD_ORE)
B(8,11,0,STONEBRICK:1)
B(9,11,0,MOSSY_COBBLESTONE)
B(10,11,0,MOSSY_COBBLESTONE)
B(11,11,0,MOSSY_COBBLESTONE)
B(12,11,0,MOSSY_COBBLESTONE)
B(13,11,0,MOSSY_COBBLESTONE)
B(14,11,0,STONE)
B(15,11,0,MOSSY_COBBLESTONE)
B(16,11,0,STONEBRICK:2)
B(0,12,0,STONEBRICK:1)
B(1,12,0,STONEBRICK)
B(2,12,0,STONEBRICK:2)
B(3,12,0,STONEBRICK)
B(4,12,0,STONEBRICK:1)
B(5,12,0,STONEBRICK:2)
B(6,12,0,STONEBRICK:2)
B(7,12,0,STONEBRICK:1)
B(8,12,0,STONEBRICK)
B(9,12,0,STONEBRICK:1)
B(10,12,0,STONEBRICK)
B(11,12,0,STONEBRICK)
B(12,12,0,STONEBRICK)
B(13,12,0,STONEBRICK:2)
B(14,12,0,STONEBRICK:1)
B(15,12,0,STONEBRICK:2)
B(16,12,0,STONEBRICK:1)
B(0,4,1,STONEBRICK:1)
B(1,4,1,STONEBRICK:2)
B(2,4,1,STONEBRICK:2)
B(3,4,1,STONEBRICK:1)
B(4,4,1,STONEBRICK:1)
B(5,4,1,STONEBRICK:2)
B(6,4,1,STONEBRICK:1)
B(7,4,1,STONEBRICK)
B(8,4,1,STONEBRICK)
B(9,4,1,STONEBRICK)
B(10,4,1,STONEBRICK)
B(11,4,1,STONEBRICK:2)
B(12,4,1,STONEBRICK:2)
B(13,4,1,STONEBRICK)
B(14,4,1,STONEBRICK:1)
B(15,4,1,STONEBRICK:2)
B(16,4,1,STONEBRICK:2)
B(0,5,1,STONE)
B(1,5,1,STONE)
B(7,5,1,EMERALD_ORE)
B(8,5,1,MOSSY_COBBLESTONE)
B(9,5,1,STONE)
B(15,5,1,STONE)
B(16,5,1,MOSSY_COBBLESTONE)
B(0,6,1,STONE)
B(1,6,1,STONE)
B(7,6,1,STONE)
B(8,6,1,STONE)
B(9,6,1,MOSSY_COBBLESTONE)
B(15,6,1,STONE)
B(16,6,1,MOSSY_COBBLESTONE)
B(0,7,1,STONE)
B(1,7,1,MOSSY_COBBLESTONE)
B(7,7,1,MOSSY_COBBLESTONE)
B(8,7,1,STONE)
B(9,7,1,STONE)
B(15,7,1,MOSSY_COBBLESTONE)
B(16,7,1,STONE)
B(0,8,1,STONE)
B(1,8,1,STONEBRICK)
B(7,8,1,STONEBRICK:1)
B(8,8,1,STONEBRICK:1)
B(9,8,1,STONEBRICK:2)
B(15,8,1,STONEBRICK:1)
B(16,8,1,MOSSY_COBBLESTONE)
B(0,9,1,STONE)
B(1,9,1,STONEBRICK)
B(7,9,1,STONEBRICK)
B(8,9,1,STONEBRICK)
B(9,9,1,STONEBRICK:1)
B(15,9,1,STONEBRICK:1)
B(16,9,1,EMERALD_ORE)
B(0,10,1,STONE)
B(1,10,1,STONEBRICK:2)
B(7,10,1,STONEBRICK)
B(8,10,1,STONEBRICK:1)
B(9,10,1,STONEBRICK:1)
B(15,10,1,STONEBRICK:1)
B(16,10,1,EMERALD_ORE)
B(0,11,1,STONE)
B(1,11,1,STONEBRICK:2)
B(2,11,1,STONEBRICK:1)
B(3,11,1,STONEBRICK:1)
B(4,11,1,STONEBRICK)
B(5,11,1,STONEBRICK:1)
B(6,11,1,STONEBRICK:1)
B(7,11,1,STONEBRICK:2)
B(8,11,1,STONEBRICK:1)
B(9,11,1,STONEBRICK)
B(10,11,1,STONEBRICK)
B(11,11,1,STONEBRICK)
B(12,11,1,STONEBRICK)
B(13,11,1,STONEBRICK:2)
B(14,11,1,STONEBRICK:2)
B(15,11,1,STONEBRICK:2)
B(16,11,1,STONE)
B(0,12,1,STONEBRICK)
B(1,12,1,EMERALD_ORE)
B(2,12,1,STONE)
B(3,12,1,MOSSY_COBBLESTONE)
B(4,12,1,STONE)
B(5,12,1,MOSSY_COBBLESTONE)
B(6,12,1,MOSSY_COBBLESTONE)
B(7,12,1,MOSSY_COBBLESTONE)
B(8,12,1,STONEBRICK:1)
B(9,12,1,EMERALD_ORE)
B(10,12,1,MOSSY_COBBLESTONE)
B(11,12,1,MOSSY_COBBLESTONE)
B(12,12,1,MOSSY_COBBLESTONE)
B(13,12,1,MOSSY_COBBLESTONE)
B(14,12,1,EMERALD_ORE)
B(15,12,1,MOSSY_COBBLESTONE)
B(16,12,1,STONEBRICK:2)
B(0,4,2,STONEBRICK)
B(1,4,2,STONEBRICK:2)
B(2,4,2,STONEBRICK:2)
B(3,4,2,STONEBRICK:1)
B(4,4,2,STONEBRICK:2)
B(5,4,2,STONEBRICK)
B(6,4,2,STONEBRICK)
B(7,4,2,STONEBRICK)
B(8,4,2,STONEBRICK:2)
B(9,4,2,STONEBRICK)
B(10,4,2,STONEBRICK:1)
B(11,4,2,STONEBRICK:1)
B(12,4,2,STONEBRICK:2)
B(13,4,2,STONEBRICK:2)
B(14,4,2,STONEBRICK:2)
B(15,4,2,STONEBRICK)
B(16,4,2,STONEBRICK:2)
B(0,5,2,MOSSY_COBBLESTONE)
B(16,5,2,STONE)
B(0,6,2,MOSSY_COBBLESTONE)
B(16,6,2,EMERALD_ORE)
B(0,7,2,MOSSY_COBBLESTONE)
B(16,7,2,MOSSY_COBBLESTONE)
B(0,8,2,STONE)
B(16,8,2,MOSSY_COBBLESTONE)
B(0,9,2,STONE)
B(16,9,2,EMERALD_ORE)
B(0,10,2,MOSSY_COBBLESTONE)
B(16,10,2,STONE)
B(0,11,2,MOSSY_COBBLESTONE)
B(1,11,2,STONEBRICK:1)
B(7,11,2,STONEBRICK:2)
B(8,11,2,STONEBRICK:1)
B(9,11,2,STONEBRICK:2)
B(15,11,2,STONEBRICK:2)
B(16,11,2,MOSSY_COBBLESTONE)
B(0,12,2,STONEBRICK:1)
B(1,12,2,STONE)
B(2,12,2,STONEBRICK:2)
B(3,12,2,STONEBRICK)
B(4,12,2,STONEBRICK)
B(5,12,2,STONEBRICK:2)
B(6,12,2,STONEBRICK)
B(7,12,2,STONE)
B(8,12,2,STONEBRICK:1)
B(9,12,2,MOSSY_COBBLESTONE)
B(10,12,2,STONEBRICK)
B(11,12,2,STONEBRICK:1)
B(12,12,2,STONEBRICK:2)
B(13,12,2,STONEBRICK)
B(14,12,2,STONEBRICK:1)
B(15,12,2,EMERALD_ORE)
B(16,12,2,STONEBRICK:2)
B(0,4,3,STONEBRICK:2)
B(1,4,3,STONEBRICK:1)
B(2,4,3,STONEBRICK:1)
B(3,4,3,GRASS)
B(4,4,3,GRASS)
B(5,4,3,DIRT:1)
B(6,4,3,GRASS)
B(7,4,3,DIRT:1)
B(8,4,3,DIRT:1)
B(9,4,3,DIRT:1)
B(10,4,3,DIRT:1)
B(11,4,3,DIRT:1)
B(12,4,3,DIRT:1)
B(13,4,3,DIRT:1)
B(14,4,3,STONEBRICK:2)
B(15,4,3,STONEBRICK)
B(16,4,3,STONEBRICK)
B(0,5,3,STONE)
B(16,5,3,STONE)
B(0,6,3,STONE)
B(16,6,3,STONE)
B(0,7,3,EMERALD_ORE)
B(16,7,3,STONE)
B(0,8,3,MOSSY_COBBLESTONE)
B(16,8,3,MOSSY_COBBLESTONE)
B(0,9,3,MOSSY_COBBLESTONE)
B(16,9,3,STONE)
B(0,10,3,STONE)
B(16,10,3,STONE)
B(0,11,3,MOSSY_COBBLESTONE)
B(1,11,3,STONEBRICK:1)
B(7,11,3,STONEBRICK:1)
B(8,11,3,STONEBRICK:2)
B(9,11,3,STONEBRICK:2)
B(15,11,3,STONEBRICK:2)
B(16,11,3,STONE)
B(0,12,3,STONEBRICK)
B(1,12,3,STONE)
B(2,12,3,STONEBRICK:1)
B(6,12,3,STONEBRICK:2)
B(7,12,3,STONE)
B(8,12,3,STONEBRICK:1)
B(9,12,3,STONE)
B(10,12,3,STONEBRICK:2)
B(14,12,3,STONEBRICK:2)
B(15,12,3,STONE)
B(16,12,3,STONEBRICK:1)
B(0,4,4,STONEBRICK:1)
B(1,4,4,STONEBRICK:2)
B(2,4,4,STONEBRICK)
B(3,4,4,GRASS)
B(4,4,4,GRASS)
B(5,4,4,GRASS)
B(6,4,4,DIRT:1)
B(7,4,4,GRASS)
B(8,4,4,DIRT:1)
B(9,4,4,GRASS)
B(10,4,4,GRASS)
B(11,4,4,DIRT:1)
B(12,4,4,DIRT:1)
B(13,4,4,DIRT:1)
B(14,4,4,STONEBRICK:1)
B(15,4,4,STONEBRICK:2)
B(16,4,4,STONEBRICK:1)
B(0,5,4,MOSSY_COBBLESTONE)
B(1,5,4,STONEBRICK:3)
B(15,5,4,STONEBRICK:3)
B(16,5,4,STONE)
B(0,6,4,STONE)
B(16,6,4,STONE)
B(0,7,4,MOSSY_COBBLESTONE)
B(16,7,4,STONE)
B(0,8,4,MOSSY_COBBLESTONE)
B(16,8,4,MOSSY_COBBLESTONE)
B(0,9,4,MOSSY_COBBLESTONE)
B(16,9,4,STONE)
B(0,10,4,EMERALD_ORE)
B(16,10,4,MOSSY_COBBLESTONE)
B(0,11,4,MOSSY_COBBLESTONE)
B(1,11,4,STONEBRICK:2)
B(7,11,4,STONEBRICK)
B(8,11,4,STONEBRICK:2)
B(9,11,4,STONEBRICK:1)
B(15,11,4,STONEBRICK)
B(16,11,4,MOSSY_COBBLESTONE)
B(0,12,4,STONEBRICK)
B(1,12,4,MOSSY_COBBLESTONE)
B(2,12,4,STONEBRICK:2)
B(6,12,4,STONEBRICK:1)
B(7,12,4,STONE)
B(8,12,4,STONEBRICK:1)
B(9,12,4,MOSSY_COBBLESTONE)
B(10,12,4,STONEBRICK)
B(14,12,4,STONEBRICK)
B(15,12,4,EMERALD_ORE)
B(16,12,4,STONEBRICK)
B(0,4,5,STONEBRICK)
B(1,4,5,STONEBRICK)
B(2,4,5,STONEBRICK)
B(3,4,5,GRASS)
B(4,4,5,DIRT:1)
B(5,4,5,GRASS)
B(6,4,5,DIRT:1)
B(7,4,5,GRASS)
B(8,4,5,DIRT:1)
B(9,4,5,GRASS)
B(10,4,5,GRASS)
B(11,4,5,DIRT:1)
B(12,4,5,DIRT:1)
B(13,4,5,GRASS)
B(14,4,5,STONEBRICK)
B(15,4,5,STONEBRICK)
B(16,4,5,STONEBRICK:1)
B(0,5,5,MOSSY_COBBLESTONE)
B(16,5,5,STONE)
B(0,6,5,EMERALD_ORE)
B(16,6,5,MOSSY_COBBLESTONE)
B(0,7,5,MOSSY_COBBLESTONE)
B(16,7,5,STONE)
B(0,8,5,STONE)
B(16,8,5,EMERALD_ORE)
B(0,9,5,STONE)
B(16,9,5,STONE)
B(0,10,5,STONE)
B(16,10,5,STONE)
B(0,11,5,STONE)
B(1,11,5,STONEBRICK:2)
B(7,11,5,STONEBRICK:1)
B(8,11,5,STONEBRICK:1)
B(9,11,5,STONEBRICK)
B(15,11,5,STONEBRICK)
B(16,11,5,STONE)
B(0,12,5,STONEBRICK:1)
B(1,12,5,MOSSY_COBBLESTONE)
B(2,12,5,STONEBRICK)
B(6,12,5,STONEBRICK:2)
B(7,12,5,MOSSY_COBBLESTONE)
B(8,12,5,STONEBRICK:2)
B(9,12,5,MOSSY_COBBLESTONE)
B(10,12,5,STONEBRICK:1)
B(14,12,5,STONEBRICK:2)
B(15,12,5,MOSSY_COBBLESTONE)
B(16,12,5,STONEBRICK:2)
B(0,4,6,STONEBRICK:1)
B(1,4,6,STONEBRICK:2)
B(2,4,6,STONEBRICK)
B(3,4,6,STONEBRICK)
B(4,4,6,STONEBRICK:2)
B(5,4,6,STONEBRICK:2)
B(6,4,6,STONEBRICK:2)
B(7,4,6,STONEBRICK:1)
B(8,4,6,STONEBRICK:2)
B(9,4,6,STONEBRICK:2)
B(10,4,6,STONEBRICK)
B(11,4,6,STONEBRICK)
B(12,4,6,STONEBRICK:2)
B(13,4,6,STONEBRICK:1)
B(14,4,6,STONEBRICK:2)
B(15,4,6,STONEBRICK:2)
B(16,4,6,STONEBRICK)
B(0,5,6,MOSSY_COBBLESTONE)
B(16,5,6,STONE)
B(0,6,6,MOSSY_COBBLESTONE)
B(16,6,6,STONE)
B(0,7,6,MOSSY_COBBLESTONE)
B(16,7,6,MOSSY_COBBLESTONE)
B(0,8,6,EMERALD_ORE)
B(16,8,6,STONE)
B(0,9,6,EMERALD_ORE)
B(16,9,6,STONE)
B(0,10,6,STONE)
B(16,10,6,MOSSY_COBBLESTONE)
B(0,11,6,MOSSY_COBBLESTONE)
B(1,11,6,STONEBRICK:2)
B(7,11,6,STONEBRICK:1)
B(8,11,6,STONEBRICK)
B(9,11,6,STONEBRICK)
B(15,11,6,STONEBRICK:1)
B(16,11,6,EMERALD_ORE)
B(0,12,6,STONEBRICK:1)
B(1,12,6,MOSSY_COBBLESTONE)
B(2,12,6,STONEBRICK:2)
B(3,12,6,STONEBRICK:2)
B(4,12,6,STONEBRICK:1)
B(5,12,6,STONEBRICK)
B(6,12,6,STONEBRICK:2)
B(7,12,6,MOSSY_COBBLESTONE)
B(8,12,6,STONEBRICK:2)
B(9,12,6,MOSSY_COBBLESTONE)
B(10,12,6,STONEBRICK:2)
B(11,12,6,STONEBRICK:2)
B(12,12,6,STONEBRICK)
B(13,12,6,STONEBRICK:1)
B(14,12,6,STONEBRICK:1)
B(15,12,6,MOSSY_COBBLESTONE)
B(16,12,6,STONEBRICK)
B(0,4,7,STONEBRICK:2)
B(1,4,7,STONEBRICK:2)
B(2,4,7,STONEBRICK:2)
B(3,4,7,STONEBRICK)
B(4,4,7,STONEBRICK)
B(5,4,7,STONEBRICK:2)
B(6,4,7,STONEBRICK:1)
B(7,4,7,STONEBRICK)
B(8,4,7,STONEBRICK)
B(9,4,7,STONEBRICK:2)
B(10,4,7,STONEBRICK)
B(11,4,7,STONEBRICK:1)
B(12,4,7,STONEBRICK:2)
B(13,4,7,STONEBRICK:2)
B(14,4,7,STONEBRICK)
B(15,4,7,STONEBRICK:2)
B(16,4,7,STONEBRICK)
B(0,5,7,STONE)
B(1,5,7,STONE)
B(7,5,7,STONE)
B(8,5,7,STONE)
B(9,5,7,STONE)
B(15,5,7,MOSSY_COBBLESTONE)
B(16,5,7,STONE)
B(0,6,7,STONE)
B(1,6,7,STONE)
B(7,6,7,STONE)
B(8,6,7,STONE)
B(9,6,7,MOSSY_COBBLESTONE)
B(15,6,7,MOSSY_COBBLESTONE)
B(16,6,7,STONE)
B(0,7,7,MOSSY_COBBLESTONE)
B(1,7,7,MOSSY_COBBLESTONE)
B(7,7,7,STONE)
B(8,7,7,STONE)
B(9,7,7,STONE)
B(15,7,7,STONE)
B(16,7,7,MOSSY_COBBLESTONE)
B(0,8,7,STONE)
B(1,8,7,STONEBRICK)
B(7,8,7,STONEBRICK:1)
B(8,8,7,STONEBRICK:2)
B(9,8,7,STONEBRICK)
B(15,8,7,STONEBRICK:2)
B(16,8,7,MOSSY_COBBLESTONE)
B(0,9,7,MOSSY_COBBLESTONE)
B(1,9,7,STONEBRICK:2)
B(7,9,7,STONEBRICK:1)
B(8,9,7,STONEBRICK:1)
B(9,9,7,STONEBRICK:2)
B(15,9,7,STONEBRICK:2)
B(16,9,7,STONE)
B(0,10,7,MOSSY_COBBLESTONE)
B(1,10,7,STONEBRICK:1)
B(7,10,7,STONEBRICK:2)
B(8,10,7,STONEBRICK:2)
B(9,10,7,STONEBRICK:1)
B(15,10,7,STONEBRICK:1)
B(16,10,7,MOSSY_COBBLESTONE)
B(0,11,7,MOSSY_COBBLESTONE)
B(1,11,7,STONEBRICK:1)
B(2,11,7,STONEBRICK)
B(3,11,7,STONEBRICK:1)
B(4,11,7,STONEBRICK)
B(5,11,7,STONEBRICK:1)
B(6,11,7,STONEBRICK)
B(7,11,7,STONEBRICK:2)
B(8,11,7,STONEBRICK:1)
B(9,11,7,STONEBRICK:1)
B(10,11,7,STONEBRICK:1)
B(11,11,7,STONEBRICK:2)
B(12,11,7,STONEBRICK:1)
B(13,11,7,STONEBRICK:1)
B(14,11,7,STONEBRICK:2)
B(15,11,7,STONEBRICK)
B(16,11,7,MOSSY_COBBLESTONE)
B(0,12,7,STONEBRICK:1)
B(1,12,7,MOSSY_COBBLESTONE)
B(2,12,7,STONE)
B(3,12,7,STONE)
B(4,12,7,STONE)
B(5,12,7,STONE)
B(6,12,7,MOSSY_COBBLESTONE)
B(7,12,7,STONE)
B(8,12,7,STONEBRICK)
B(9,12,7,EMERALD_ORE)
B(10,12,7,STONE)
B(11,12,7,STONE)
B(12,12,7,MOSSY_COBBLESTONE)
B(13,12,7,MOSSY_COBBLESTONE)
B(14,12,7,STONE)
B(15,12,7,EMERALD_ORE)
B(16,12,7,STONEBRICK:1)
B(0,4,8,STONEBRICK)
B(1,4,8,STONEBRICK)
B(2,4,8,STONEBRICK:2)
B(3,4,8,STONEBRICK:2)
B(4,4,8,STONEBRICK:2)
B(5,4,8,STONEBRICK)
B(6,4,8,STONEBRICK:2)
B(7,4,8,STONEBRICK)
B(8,4,8,STONEBRICK:2)
B(9,4,8,STONEBRICK:1)
B(10,4,8,STONEBRICK:1)
B(11,4,8,STONEBRICK)
B(12,4,8,STONEBRICK:2)
B(13,4,8,STONEBRICK:2)
B(14,4,8,STONEBRICK:1)
B(15,4,8,STONEBRICK:1)
B(16,4,8,STONEBRICK:2)
B(0,5,8,STONEBRICK)
B(1,5,8,EMERALD_ORE)
B(2,5,8,STONE)
B(3,5,8,STONEBRICK:2)
B(5,5,8,STONEBRICK:2)
B(6,5,8,MOSSY_COBBLESTONE)
B(7,5,8,EMERALD_ORE)
B(8,5,8,STONEBRICK:2)
B(9,5,8,MOSSY_COBBLESTONE)
B(10,5,8,MOSSY_COBBLESTONE)
B(11,5,8,STONEBRICK:2)
B(13,5,8,STONEBRICK)
B(14,5,8,MOSSY_COBBLESTONE)
B(15,5,8,STONE)
B(16,5,8,STONEBRICK:1)
B(0,6,8,STONEBRICK:2)
B(1,6,8,STONE)
B(2,6,8,STONE)
B(3,6,8,STONEBRICK:1)
B(5,6,8,STONEBRICK)
B(6,6,8,MOSSY_COBBLESTONE)
B(7,6,8,EMERALD_ORE)
B(8,6,8,STONEBRICK:1)
B(9,6,8,EMERALD_ORE)
B(10,6,8,MOSSY_COBBLESTONE)
B(11,6,8,STONEBRICK:1)
B(13,6,8,STONEBRICK:2)
B(14,6,8,MOSSY_COBBLESTONE)
B(15,6,8,STONE)
B(16,6,8,STONEBRICK)
B(0,7,8,STONEBRICK:1)
B(1,7,8,MOSSY_COBBLESTONE)
B(2,7,8,MOSSY_COBBLESTONE)
B(3,7,8,STONEBRICK)
B(5,7,8,STONEBRICK:1)
B(6,7,8,STONE)
B(7,7,8,STONE)
B(8,7,8,STONEBRICK)
B(9,7,8,MOSSY_COBBLESTONE)
B(10,7,8,STONE)
B(11,7,8,STONEBRICK:1)
B(13,7,8,STONEBRICK:1)
B(14,7,8,STONE)
B(15,7,8,STONE)
B(16,7,8,STONEBRICK:2)
B(0,8,8,STONEBRICK)
B(1,8,8,STONE)
B(2,8,8,MOSSY_COBBLESTONE)
B(3,8,8,STONEBRICK)
B(4,8,8,STONEBRICK:1)
B(5,8,8,STONEBRICK:2)
B(6,8,8,MOSSY_COBBLESTONE)
B(7,8,8,STONE)
B(8,8,8,STONEBRICK:1)
B(9,8,8,MOSSY_COBBLESTONE)
B(10,8,8,EMERALD_ORE)
B(11,8,8,STONEBRICK:1)
B(12,8,8,STONEBRICK:1)
B(13,8,8,STONEBRICK:2)
B(14,8,8,STONE)
B(15,8,8,STONE)
B(16,8,8,STONEBRICK:2)
B(0,9,8,STONEBRICK:2)
B(1,9,8,STONE)
B(2,9,8,MOSSY_COBBLESTONE)
B(3,9,8,MOSSY_COBBLESTONE)
B(4,9,8,EMERALD_ORE)
B(5,9,8,STONE)
B(6,9,8,EMERALD_ORE)
B(7,9,8,MOSSY_COBBLESTONE)
B(8,9,8,STONEBRICK)
B(9,9,8,STONE)
B(10,9,8,STONE)
B(11,9,8,STONE)
B(12,9,8,MOSSY_COBBLESTONE)
B(13,9,8,MOSSY_COBBLESTONE)
B(14,9,8,EMERALD_ORE)
B(15,9,8,EMERALD_ORE)
B(16,9,8,STONEBRICK:1)
B(0,10,8,STONEBRICK:1)
B(1,10,8,STONE)
B(2,10,8,MOSSY_COBBLESTONE)
B(3,10,8,MOSSY_COBBLESTONE)
B(4,10,8,MOSSY_COBBLESTONE)
B(5,10,8,STONE)
B(6,10,8,MOSSY_COBBLESTONE)
B(7,10,8,MOSSY_COBBLESTONE)
B(8,10,8,STONEBRICK)
B(9,10,8,EMERALD_ORE)
B(10,10,8,STONE)
B(11,10,8,STONE)
B(12,10,8,MOSSY_COBBLESTONE)
B(13,10,8,MOSSY_COBBLESTONE)
B(14,10,8,MOSSY_COBBLESTONE)
B(15,10,8,EMERALD_ORE)
B(16,10,8,STONEBRICK:1)
B(0,11,8,STONEBRICK)
B(1,11,8,MOSSY_COBBLESTONE)
B(2,11,8,MOSSY_COBBLESTONE)
B(3,11,8,STONE)
B(4,11,8,STONE)
B(5,11,8,MOSSY_COBBLESTONE)
B(6,11,8,STONE)
B(7,11,8,STONE)
B(8,11,8,STONEBRICK:1)
B(9,11,8,MOSSY_COBBLESTONE)
B(10,11,8,STONE)
B(11,11,8,MOSSY_COBBLESTONE)
B(12,11,8,STONE)
B(13,11,8,STONE)
B(14,11,8,MOSSY_COBBLESTONE)
B(15,11,8,MOSSY_COBBLESTONE)
B(16,11,8,STONEBRICK)
B(0,12,8,STONEBRICK)
B(1,12,8,STONEBRICK)
B(2,12,8,STONEBRICK)
B(3,12,8,STONEBRICK:1)
B(4,12,8,STONEBRICK:2)
B(5,12,8,STONEBRICK)
B(6,12,8,STONEBRICK:1)
B(7,12,8,STONEBRICK:1)
B(8,12,8,STONEBRICK)
B(9,12,8,STONEBRICK:2)
B(10,12,8,STONEBRICK:1)
B(11,12,8,STONEBRICK)
B(12,12,8,STONEBRICK:2)
B(13,12,8,STONEBRICK:1)
B(14,12,8,STONEBRICK:1)
B(15,12,8,STONEBRICK:2)
B(16,12,8,STONEBRICK)
B(3,3,9,STONEBRICK:2)
B(4,3,9,STONEBRICK)
B(5,3,9,STONEBRICK:2)
B(3,4,9,STONEBRICK)
B(5,4,9,STONEBRICK)
B(11,4,9,STONEBRICK:2)
B(12,4,9,STONEBRICK)
B(13,4,9,STONEBRICK:1)
B(3,5,9,STONEBRICK:1)
B(5,5,9,STONEBRICK:1)
B(11,5,9,STONEBRICK)
B(13,5,9,STONEBRICK)
B(3,6,9,STONEBRICK:1)
B(5,6,9,STONEBRICK:1)
B(11,6,9,STONEBRICK)
B(13,6,9,STONEBRICK:2)
B(3,7,9,STONEBRICK)
B(5,7,9,STONEBRICK:2)
B(11,7,9,STONEBRICK:1)
B(13,7,9,STONEBRICK:2)
B(3,8,9,STONEBRICK:2)
B(4,8,9,STONEBRICK)
B(5,8,9,STONEBRICK:2)
B(11,8,9,STONEBRICK:1)
B(13,8,9,STONEBRICK)
B(11,9,9,STONEBRICK:1)
B(12,9,9,STONEBRICK:2)
B(13,9,9,STONEBRICK:2)
B(3,3,10,STONEBRICK:2)
B(4,3,10,STONEBRICK:2)
B(5,3,10,STONEBRICK:1)
B(3,4,10,STONEBRICK)
B(5,4,10,STONEBRICK:1)
B(3,5,10,STONEBRICK)
B(5,5,10,STONEBRICK:1)
B(11,5,10,STONEBRICK:2)
B(12,5,10,STONEBRICK)
B(13,5,10,STONEBRICK:2)
B(3,6,10,STONEBRICK:1)
B(5,6,10,STONEBRICK:1)
B(11,6,10,STONEBRICK)
B(13,6,10,STONEBRICK)
B(3,7,10,STONEBRICK)
B(4,7,10,STONEBRICK)
B(5,7,10,STONEBRICK:1)
B(11,7,10,STONEBRICK)
B(13,7,10,STONEBRICK:1)
B(11,8,10,STONEBRICK:2)
B(13,8,10,STONEBRICK:2)
B(11,9,10,STONEBRICK:1)
B(12,9,10,STONEBRICK:2)
B(13,9,10,STONEBRICK:2)
B(3,2,11,STONEBRICK:1)
B(4,2,11,STONEBRICK)
B(5,2,11,STONEBRICK:2)
B(3,3,11,STONEBRICK:2)
B(5,3,11,STONEBRICK)
B(3,4,11,STONEBRICK:1)
B(5,4,11,STONEBRICK:2)
B(3,5,11,STONEBRICK)
B(5,5,11,STONEBRICK)
B(11,5,11,STONEBRICK:1)
B(12,5,11,STONEBRICK:1)
B(13,5,11,STONEBRICK:1)
B(3,6,11,STONEBRICK)
B(5,6,11,STONEBRICK:2)
B(11,6,11,STONEBRICK:1)
B(13,6,11,STONEBRICK)
B(3,7,11,STONEBRICK:1)
B(4,7,11,STONEBRICK)
B(5,7,11,STONEBRICK:1)
B(11,7,11,STONEBRICK:2)
B(13,7,11,STONEBRICK:1)
B(11,8,11,STONEBRICK:1)
B(13,8,11,STONEBRICK:1)
B(11,9,11,STONEBRICK)
B(13,9,11,STONEBRICK:1)
B(11,10,11,STONEBRICK:1)
B(12,10,11,STONEBRICK:1)
B(13,10,11,STONEBRICK)
B(3,2,12,STONEBRICK:2)
B(4,2,12,STONEBRICK:1)
B(5,2,12,STONEBRICK:1)
B(3,3,12,STONEBRICK:1)
B(5,3,12,STONEBRICK)
B(3,4,12,STONEBRICK:2)
B(5,4,12,STONEBRICK:2)
B(3,5,12,STONEBRICK:2)
B(5,5,12,STONEBRICK:2)
B(3,6,12,STONEBRICK:1)
B(4,6,12,STONEBRICK:1)
B(5,6,12,STONEBRICK)
B(11,6,12,STONEBRICK:2)
B(12,6,12,STONEBRICK:2)
B(13,6,12,STONEBRICK:2)
B(11,7,12,STONEBRICK)
B(13,7,12,STONEBRICK:1)
B(11,8,12,STONEBRICK:1)
B(13,8,12,STONEBRICK:1)
B(11,9,12,STONEBRICK)
B(13,9,12,STONEBRICK:2)
B(11,10,12,STONEBRICK)
B(12,10,12,STONEBRICK)
B(13,10,12,STONEBRICK:2)
B(3,1,13,STONEBRICK:2)
B(4,1,13,STONEBRICK:2)
B(5,1,13,STONEBRICK:2)
B(3,2,13,STONEBRICK)
B(5,2,13,STONEBRICK:1)
B(3,3,13,STONEBRICK:1)
B(5,3,13,STONEBRICK:2)
B(3,4,13,STONEBRICK:1)
B(5,4,13,STONEBRICK)
B(3,5,13,STONEBRICK)
B(5,5,13,STONEBRICK:1)
B(3,6,13,STONEBRICK:1)
B(4,6,13,STONEBRICK:1)
B(5,6,13,STONEBRICK:2)
B(11,6,13,STONEBRICK:1)
B(12,6,13,STONEBRICK)
B(13,6,13,STONEBRICK)
B(11,7,13,STONEBRICK:2)
B(13,7,13,STONEBRICK:1)
B(11,8,13,STONEBRICK:1)
B(13,8,13,STONEBRICK:1)
B(11,9,13,STONEBRICK)
B(13,9,13,STONEBRICK:2)
B(11,10,13,STONEBRICK)
B(13,10,13,STONEBRICK:1)
B(11,11,13,STONEBRICK:1)
B(12,11,13,STONEBRICK:1)
B(13,11,13,STONEBRICK:1)
B(3,1,14,STONEBRICK:2)
B(4,1,14,STONEBRICK)
B(5,1,14,STONEBRICK:2)
B(3,2,14,STONEBRICK:1)
B(5,2,14,STONEBRICK:1)
B(3,3,14,STONEBRICK)
B(5,3,14,STONEBRICK:2)
B(3,4,14,STONEBRICK)
B(5,4,14,STONEBRICK:2)
B(3,5,14,STONEBRICK:2)
B(4,5,14,STONEBRICK:1)
B(5,5,14,STONEBRICK:1)
B(11,7,14,STONEBRICK)
B(12,7,14,STONEBRICK)
B(13,7,14,STONEBRICK)
B(11,8,14,STONEBRICK:1)
B(13,8,14,STONEBRICK:2)
B(11,9,14,STONEBRICK:1)
B(13,9,14,STONEBRICK:1)
B(11,10,14,STONEBRICK:2)
B(13,10,14,STONEBRICK:2)
B(11,11,14,STONEBRICK)
B(12,11,14,STONEBRICK)
B(13,11,14,STONEBRICK:1)
B(3,0,15,STONEBRICK:1)
B(4,0,15,STONEBRICK:2)
B(5,0,15,STONEBRICK)
B(3,1,15,STONEBRICK)
B(5,1,15,STONEBRICK)
B(3,2,15,STONEBRICK:2)
B(5,2,15,STONEBRICK:1)
B(3,3,15,STONEBRICK:1)
B(5,3,15,STONEBRICK:2)
B(3,4,15,STONEBRICK)
B(5,4,15,STONEBRICK:2)
B(3,5,15,STONEBRICK:1)
B(4,5,15,STONEBRICK)
B(5,5,15,STONEBRICK)
B(11,7,15,STONEBRICK)
B(12,7,15,STONEBRICK:2)
B(13,7,15,STONEBRICK:2)
B(11,8,15,STONEBRICK)
B(13,8,15,STONEBRICK:1)
B(11,9,15,STONEBRICK:1)
B(13,9,15,STONEBRICK)
B(11,10,15,STONEBRICK:2)
B(13,10,15,STONEBRICK)
B(11,11,15,STONEBRICK:2)
B(13,11,15,STONEBRICK:2)
B(11,12,15,STONEBRICK:2)
B(12,12,15,STONEBRICK:1)
B(13,12,15,STONEBRICK:1)
B(0,0,16,STONEBRICK:1)
B(1,0,16,STONEBRICK:1)
B(2,0,16,STONEBRICK:2)
B(3,0,16,STONEBRICK:1)
B(4,0,16,STONEBRICK:2)
B(5,0,16,STONEBRICK:1)
B(6,0,16,STONEBRICK:1)
B(7,0,16,STONEBRICK:2)
B(8,0,16,STONEBRICK:2)
B(9,0,16,STONEBRICK)
B(10,0,16,STONEBRICK:2)
B(11,0,16,STONEBRICK:2)
B(12,0,16,STONEBRICK)
B(13,0,16,STONEBRICK)
B(14,0,16,STONEBRICK:1)
B(15,0,16,STONEBRICK)
B(16,0,16,STONEBRICK:1)
B(0,1,16,STONEBRICK:2)
B(1,1,16,MOSSY_COBBLESTONE)
B(2,1,16,STONE)
B(3,1,16,STONEBRICK)
B(5,1,16,STONEBRICK:2)
B(6,1,16,MOSSY_COBBLESTONE)
B(7,1,16,STONE)
B(8,1,16,STONEBRICK:2)
B(9,1,16,MOSSY_COBBLESTONE)
B(10,1,16,MOSSY_COBBLESTONE)
B(11,1,16,STONEBRICK:1)
B(13,1,16,STONEBRICK)
B(14,1,16,STONE)
B(15,1,16,STONE)
B(16,1,16,STONEBRICK:1)
B(0,2,16,STONEBRICK)
B(1,2,16,MOSSY_COBBLESTONE)
B(2,2,16,EMERALD_ORE)
B(3,2,16,STONEBRICK:1)
B(5,2,16,STONEBRICK)
B(6,2,16,STONE)
B(7,2,16,STONE)
B(8,2,16,STONEBRICK:1)
B(9,2,16,STONE)
B(10,2,16,EMERALD_ORE)
B(11,2,16,STONEBRICK:1)
B(13,2,16,STONEBRICK:2)
B(14,2,16,STONE)
B(15,2,16,MOSSY_COBBLESTONE)
B(16,2,16,STONEBRICK)
B(0,3,16,STONEBRICK:2)
B(1,3,16,STONE)
B(2,3,16,STONE)
B(3,3,16,STONEBRICK:1)
B(5,3,16,STONEBRICK:2)
B(6,3,16,STONE)
B(7,3,16,EMERALD_ORE)
B(8,3,16,STONEBRICK)
B(9,3,16,MOSSY_COBBLESTONE)
B(10,3,16,EMERALD_ORE)
B(11,3,16,STONEBRICK:2)
B(13,3,16,STONEBRICK)
B(14,3,16,MOSSY_COBBLESTONE)
B(15,3,16,STONE)
B(16,3,16,STONEBRICK:2)
B(0,4,16,STONEBRICK:2)
B(1,4,16,EMERALD_ORE)
B(2,4,16,MOSSY_COBBLESTONE)
B(3,4,16,STONEBRICK)
B(4,4,16,STONEBRICK:2)
B(5,4,16,STONEBRICK)
B(6,4,16,EMERALD_ORE)
B(7,4,16,MOSSY_COBBLESTONE)
B(8,4,16,STONEBRICK:2)
B(9,4,16,STONE)
B(10,4,16,MOSSY_COBBLESTONE)
B(11,4,16,STONEBRICK:1)
B(12,4,16,STONEBRICK:1)
B(13,4,16,STONEBRICK:1)
B(14,4,16,MOSSY_COBBLESTONE)
B(15,4,16,MOSSY_COBBLESTONE)
B(16,4,16,STONEBRICK)
B(0,5,16,STONEBRICK)
B(1,5,16,STONE)
B(2,5,16,STONE)
B(3,5,16,EMERALD_ORE)
B(4,5,16,MOSSY_COBBLESTONE)
B(5,5,16,STONE)
B(6,5,16,STONE)
B(7,5,16,MOSSY_COBBLESTONE)
B(8,5,16,STONEBRICK:1)
B(9,5,16,EMERALD_ORE)
B(10,5,16,MOSSY_COBBLESTONE)
B(11,5,16,EMERALD_ORE)
B(12,5,16,STONE)
B(13,5,16,MOSSY_COBBLESTONE)
B(14,5,16,STONE)
B(15,5,16,MOSSY_COBBLESTONE)
B(16,5,16,STONEBRICK:1)
B(0,6,16,STONEBRICK:2)
B(1,6,16,STONE)
B(2,6,16,MOSSY_COBBLESTONE)
B(3,6,16,MOSSY_COBBLESTONE)
B(4,6,16,STONE)
B(5,6,16,EMERALD_ORE)
B(6,6,16,EMERALD_ORE)
B(7,6,16,STONE)
B(8,6,16,STONEBRICK)
B(9,6,16,STONE)
B(10,6,16,MOSSY_COBBLESTONE)
B(11,6,16,MOSSY_COBBLESTONE)
B(12,6,16,STONE)
B(13,6,16,STONE)
B(14,6,16,MOSSY_COBBLESTONE)
B(15,6,16,MOSSY_COBBLESTONE)
B(16,6,16,STONEBRICK:2)
B(0,7,16,STONEBRICK:2)
B(1,7,16,MOSSY_COBBLESTONE)
B(2,7,16,MOSSY_COBBLESTONE)
B(3,7,16,MOSSY_COBBLESTONE)
B(4,7,16,EMERALD_ORE)
B(5,7,16,STONE)
B(6,7,16,STONE)
B(7,7,16,MOSSY_COBBLESTONE)
B(8,7,16,STONEBRICK:2)
B(9,7,16,MOSSY_COBBLESTONE)
B(10,7,16,EMERALD_ORE)
B(11,7,16,STONE)
B(12,7,16,STONE)
B(13,7,16,MOSSY_COBBLESTONE)
B(14,7,16,MOSSY_COBBLESTONE)
B(15,7,16,STONE)
B(16,7,16,STONEBRICK:2)
B(0,8,16,STONEBRICK:1)
B(1,8,16,STONEBRICK:2)
B(2,8,16,STONEBRICK:2)
B(3,8,16,STONEBRICK:2)
B(4,8,16,STONEBRICK:1)
B(5,8,16,STONEBRICK:1)
B(6,8,16,STONEBRICK:2)
B(7,8,16,STONEBRICK:2)
B(8,8,16,STONEBRICK)
B(9,8,16,STONEBRICK:1)
B(10,8,16,STONEBRICK:1)
B(11,8,16,STONEBRICK:1)
B(12,8,16,STONEBRICK)
B(13,8,16,STONEBRICK)
B(14,8,16,STONEBRICK:2)
B(15,8,16,STONEBRICK:2)
B(16,8,16,STONEBRICK)
B(0,9,16,STONEBRICK)
B(1,9,16,STONE)
B(2,9,16,MOSSY_COBBLESTONE)
B(3,9,16,STONEBRICK)
B(5,9,16,STONEBRICK:1)
B(6,9,16,MOSSY_COBBLESTONE)
B(7,9,16,MOSSY_COBBLESTONE)
B(8,9,16,STONEBRICK)
B(9,9,16,STONE)
B(10,9,16,STONE)
B(11,9,16,STONEBRICK:1)
B(13,9,16,STONEBRICK:1)
B(14,9,16,MOSSY_COBBLESTONE)
B(15,9,16,STONE)
B(16,9,16,STONEBRICK:1)
B(0,10,16,STONEBRICK:1)
B(1,10,16,STONE)
B(2,10,16,STONE)
B(3,10,16,STONEBRICK)
B(5,10,16,STONEBRICK)
B(6,10,16,MOSSY_COBBLESTONE)
B(7,10,16,STONE)
B(8,10,16,STONEBRICK:2)
B(9,10,16,STONE)
B(10,10,16,STONE)
B(11,10,16,STONEBRICK)
B(13,10,16,STONEBRICK:1)
B(14,10,16,MOSSY_COBBLESTONE)
B(15,10,16,STONE)
B(16,10,16,STONEBRICK)
B(0,11,16,STONEBRICK)
B(1,11,16,STONE)
B(2,11,16,MOSSY_COBBLESTONE)
B(3,11,16,STONEBRICK)
B(5,11,16,STONEBRICK)
B(6,11,16,STONE)
B(7,11,16,MOSSY_COBBLESTONE)
B(8,11,16,STONEBRICK)
B(9,11,16,STONE)
B(10,11,16,STONE)
B(11,11,16,STONEBRICK:2)
B(13,11,16,STONEBRICK:1)
B(14,11,16,MOSSY_COBBLESTONE)
B(15,11,16,MOSSY_COBBLESTONE)
B(16,11,16,STONEBRICK:2)
B(0,12,16,STONEBRICK)
B(1,12,16,STONE)
B(2,12,16,MOSSY_COBBLESTONE)
B(3,12,16,STONEBRICK:1)
B(4,12,16,STONEBRICK:2)
B(5,12,16,STONEBRICK)
B(6,12,16,MOSSY_COBBLESTONE)
B(7,12,16,EMERALD_ORE)
B(8,12,16,STONEBRICK:2)
B(9,12,16,STONE)
B(10,12,16,STONE)
B(11,12,16,STONEBRICK)
B(12,12,16,STONEBRICK:2)
B(13,12,16,STONEBRICK:1)
B(14,12,16,STONE)
B(15,12,16,STONE)
B(16,12,16,STONEBRICK:1)
B(0,13,16,STONEBRICK:2)
B(1,13,16,MOSSY_COBBLESTONE)
B(2,13,16,STONE)
B(3,13,16,MOSSY_COBBLESTONE)
B(4,13,16,STONE)
B(5,13,16,MOSSY_COBBLESTONE)
B(6,13,16,STONE)
B(7,13,16,MOSSY_COBBLESTONE)
B(8,13,16,STONEBRICK)
B(9,13,16,MOSSY_COBBLESTONE)
B(10,13,16,STONE)
B(11,13,16,MOSSY_COBBLESTONE)
B(12,13,16,MOSSY_COBBLESTONE)
B(13,13,16,STONE)
B(14,13,16,MOSSY_COBBLESTONE)
B(15,13,16,STONE)
B(16,13,16,STONEBRICK:1)
B(0,14,16,STONEBRICK:2)
B(1,14,16,MOSSY_COBBLESTONE)
B(2,14,16,STONE)
B(3,14,16,MOSSY_COBBLESTONE)
B(4,14,16,EMERALD_ORE)
B(5,14,16,MOSSY_COBBLESTONE)
B(6,14,16,MOSSY_COBBLESTONE)
B(7,14,16,STONE)
B(8,14,16,STONEBRICK:2)
B(9,14,16,EMERALD_ORE)
B(10,14,16,STONE)
B(11,14,16,STONE)
B(12,14,16,STONE)
B(13,14,16,MOSSY_COBBLESTONE)
B(14,14,16,STONE)
B(15,14,16,STONE)
B(16,14,16,STONEBRICK:1)
B(0,15,16,STONEBRICK)
B(1,15,16,STONE)
B(2,15,16,MOSSY_COBBLESTONE)
B(3,15,16,MOSSY_COBBLESTONE)
B(4,15,16,STONE)
B(5,15,16,STONE)
B(6,15,16,EMERALD_ORE)
B(7,15,16,STONE)
B(8,15,16,STONEBRICK)
B(9,15,16,STONE)
B(10,15,16,MOSSY_COBBLESTONE)
B(11,15,16,STONE)
B(12,15,16,STONE)
B(13,15,16,STONE)
B(14,15,16,MOSSY_COBBLESTONE)
B(15,15,16,MOSSY_COBBLESTONE)
B(16,15,16,STONEBRICK)
B(0,16,16,STONEBRICK:1)
B(1,16,16,STONEBRICK:2)
B(2,16,16,STONEBRICK)
B(3,16,16,STONEBRICK:2)
B(4,16,16,STONEBRICK)
B(5,16,16,STONEBRICK:1)
B(6,16,16,STONEBRICK)
B(7,16,16,STONEBRICK:2)
B(8,16,16,STONEBRICK)
B(9,16,16,STONEBRICK:2)
B(10,16,16,STONEBRICK:1)
B(11,16,16,STONEBRICK:1)
B(12,16,16,STONEBRICK:1)
B(13,16,16,STONEBRICK:2)
B(14,16,16,STONEBRICK:1)
B(15,16,16,STONEBRICK:2)
B(16,16,16,STONEBRICK:1)
B(0,0,17,STONEBRICK:2)
B(1,0,17,STONEBRICK:1)
B(2,0,17,STONEBRICK:1)
B(3,0,17,STONEBRICK:1)
B(4,0,17,STONEBRICK)
B(5,0,17,STONEBRICK:1)
B(6,0,17,STONEBRICK:1)
B(7,0,17,STONEBRICK:1)
B(8,0,17,STONEBRICK)
B(9,0,17,STONEBRICK:1)
B(10,0,17,STONEBRICK)
B(11,0,17,STONEBRICK:1)
B(12,0,17,STONEBRICK:1)
B(13,0,17,STONEBRICK:2)
B(14,0,17,STONEBRICK:2)
B(15,0,17,STONEBRICK:2)
B(16,0,17,STONEBRICK)
B(0,1,17,MOSSY_COBBLESTONE)
B(1,1,17,MOSSY_COBBLESTONE)
B(7,1,17,MOSSY_COBBLESTONE)
B(8,1,17,STONE)
B(9,1,17,MOSSY_COBBLESTONE)
B(15,1,17,EMERALD_ORE)
B(16,1,17,MOSSY_COBBLESTONE)
B(0,2,17,STONE)
B(1,2,17,MOSSY_COBBLESTONE)
B(7,2,17,STONE)
B(8,2,17,STONE)
B(9,2,17,MOSSY_COBBLESTONE)
B(15,2,17,MOSSY_COBBLESTONE)
B(16,2,17,MOSSY_COBBLESTONE)
B(0,3,17,MOSSY_COBBLESTONE)
B(1,3,17,MOSSY_COBBLESTONE)
B(7,3,17,MOSSY_COBBLESTONE)
B(8,3,17,MOSSY_COBBLESTONE)
B(9,3,17,STONE)
B(15,3,17,STONE)
B(16,3,17,STONE)
B(0,4,17,MOSSY_COBBLESTONE)
B(1,4,17,STONEBRICK)
B(7,4,17,STONEBRICK)
B(8,4,17,STONEBRICK:1)
B(9,4,17,STONEBRICK:1)
B(15,4,17,STONEBRICK:1)
B(16,4,17,MOSSY_COBBLESTONE)
B(0,5,17,STONE)
B(1,5,17,STONEBRICK:2)
B(7,5,17,STONEBRICK)
B(8,5,17,STONEBRICK:1)
B(9,5,17,STONEBRICK:1)
B(15,5,17,STONEBRICK:1)
B(16,5,17,STONE)
B(0,6,17,STONE)
B(1,6,17,STONEBRICK:2)
B(7,6,17,STONEBRICK:1)
B(8,6,17,STONEBRICK:1)
B(9,6,17,STONEBRICK)
B(15,6,17,STONEBRICK:1)
B(16,6,17,STONE)
B(0,7,17,MOSSY_COBBLESTONE)
B(1,7,17,STONEBRICK:1)
B(2,7,17,STONEBRICK)
B(3,7,17,STONEBRICK:1)
B(4,7,17,STONEBRICK:1)
B(5,7,17,STONEBRICK:1)
B(6,7,17,STONEBRICK)
B(7,7,17,STONEBRICK:1)
B(8,7,17,STONEBRICK:2)
B(9,7,17,STONEBRICK:2)
B(10,7,17,STONEBRICK:1)
B(11,7,17,STONEBRICK:1)
B(12,7,17,STONEBRICK:2)
B(13,7,17,STONEBRICK:1)
B(14,7,17,STONEBRICK:2)
B(15,7,17,STONEBRICK:1)
B(16,7,17,STONE)
B(0,8,17,STONEBRICK)
B(1,8,17,STONEBRICK)
B(2,8,17,STONEBRICK:1)
B(3,8,17,STONEBRICK:2)
B(4,8,17,STONEBRICK:1)
B(5,8,17,STONEBRICK:2)
B(6,8,17,STONEBRICK:2)
B(7,8,17,STONEBRICK:2)
B(8,8,17,STONEBRICK:2)
B(9,8,17,STONEBRICK:2)
B(10,8,17,STONEBRICK:1)
B(11,8,17,STONEBRICK)
B(12,8,17,STONEBRICK)
B(13,8,17,STONEBRICK:2)
B(14,8,17,STONEBRICK:1)
B(15,8,17,STONEBRICK:2)
B(16,8,17,STONEBRICK:1)
B(0,9,17,EMERALD_ORE)
B(1,9,17,MOSSY_COBBLESTONE)
B(7,9,17,EMERALD_ORE)
B(8,9,17,STONE)
B(9,9,17,STONE)
B(15,9,17,STONE)
B(16,9,17,MOSSY_COBBLESTONE)
B(0,10,17,MOSSY_COBBLESTONE)
B(1,10,17,MOSSY_COBBLESTONE)
B(7,10,17,MOSSY_COBBLESTONE)
B(8,10,17,STONE)
B(9,10,17,MOSSY_COBBLESTONE)
B(15,10,17,STONE)
B(16,10,17,STONE)
B(0,11,17,STONE)
B(1,11,17,MOSSY_COBBLESTONE)
B(7,11,17,MOSSY_COBBLESTONE)
B(8,11,17,MOSSY_COBBLESTONE)
B(9,11,17,STONE)
B(15,11,17,MOSSY_COBBLESTONE)
B(16,11,17,MOSSY_COBBLESTONE)
B(0,12,17,STONE)
B(1,12,17,STONEBRICK:2)
B(7,12,17,STONEBRICK)
B(8,12,17,STONEBRICK:2)
B(9,12,17,STONEBRICK:1)
B(15,12,17,STONEBRICK)
B(16,12,17,MOSSY_COBBLESTONE)
B(0,13,17,MOSSY_COBBLESTONE)
B(1,13,17,STONEBRICK)
B(7,13,17,STONEBRICK)
B(8,13,17,STONEBRICK)
B(9,13,17,STONEBRICK:1)
B(15,13,17,STONEBRICK:1)
B(16,13,17,STONE)
B(0,14,17,STONE)
B(1,14,17,STONEBRICK:1)
B(7,14,17,STONEBRICK:1)
B(8,14,17,STONEBRICK:2)
B(9,14,17,STONEBRICK:1)
B(15,14,17,STONEBRICK:2)
B(16,14,17,STONE)
B(0,15,17,MOSSY_COBBLESTONE)
B(1,15,17,STONEBRICK:1)
B(2,15,17,STONEBRICK)
B(3,15,17,STONEBRICK:2)
B(4,15,17,STONEBRICK:2)
B(5,15,17,STONEBRICK)
B(6,15,17,STONEBRICK:2)
B(7,15,17,STONEBRICK)
B(8,15,17,STONEBRICK:1)
B(9,15,17,STONEBRICK)
B(10,15,17,STONEBRICK)
B(11,15,17,STONEBRICK:1)
B(12,15,17,STONEBRICK)
B(13,15,17,STONEBRICK)
B(14,15,17,STONEBRICK)
B(15,15,17,STONEBRICK)
B(16,15,17,MOSSY_COBBLESTONE)
B(0,16,17,STONEBRICK:2)
B(1,16,17,MOSSY_COBBLESTONE)
B(2,16,17,MOSSY_COBBLESTONE)
B(3,16,17,STONE)
B(4,16,17,EMERALD_ORE)
B(5,16,17,MOSSY_COBBLESTONE)
B(6,16,17,EMERALD_ORE)
B(7,16,17,MOSSY_COBBLESTONE)
B(8,16,17,STONEBRICK:1)
B(9,16,17,MOSSY_COBBLESTONE)
B(10,16,17,MOSSY_COBBLESTONE)
B(11,16,17,STONE)
B(12,16,17,STONE)
B(13,16,17,STONE)
B(14,16,17,EMERALD_ORE)
B(15,16,17,STONE)
B(16,16,17,STONEBRICK)
B(0,0,18,STONEBRICK)
B(1,0,18,STONEBRICK:2)
B(2,0,18,STONEBRICK)
B(3,0,18,STONEBRICK)
B(4,0,18,STONEBRICK:1)
B(5,0,18,STONEBRICK:1)
B(6,0,18,STONEBRICK:2)
B(7,0,18,STONEBRICK:2)
B(8,0,18,STONEBRICK)
B(9,0,18,STONEBRICK)
B(10,0,18,STONEBRICK:2)
B(11,0,18,STONEBRICK:2)
B(12,0,18,STONEBRICK:2)
B(13,0,18,STONEBRICK:1)
B(14,0,18,STONEBRICK:2)
B(15,0,18,STONEBRICK)
B(16,0,18,STONEBRICK:2)
B(0,1,18,MOSSY_COBBLESTONE)
B(16,1,18,MOSSY_COBBLESTONE)
B(0,2,18,MOSSY_COBBLESTONE)
B(16,2,18,STONE)
B(0,3,18,MOSSY_COBBLESTONE)
B(16,3,18,MOSSY_COBBLESTONE)
B(0,4,18,STONE)
B(16,4,18,STONE)
B(0,5,18,MOSSY_COBBLESTONE)
B(16,5,18,MOSSY_COBBLESTONE)
B(0,6,18,MOSSY_COBBLESTONE)
B(16,6,18,MOSSY_COBBLESTONE)
B(0,7,18,STONE)
B(1,7,18,STONEBRICK:1)
B(7,7,18,STONEBRICK:2)
B(8,7,18,STONEBRICK:1)
B(9,7,18,STONEBRICK)
B(15,7,18,STONEBRICK:1)
B(16,7,18,MOSSY_COBBLESTONE)
B(0,8,18,STONEBRICK:2)
B(1,8,18,STONEBRICK)
B(2,8,18,STONEBRICK:1)
B(3,8,18,STONEBRICK)
B(4,8,18,STONEBRICK:2)
B(5,8,18,STONEBRICK:2)
B(6,8,18,STONEBRICK:1)
B(7,8,18,STONEBRICK)
B(8,8,18,STONEBRICK:2)
B(9,8,18,STONEBRICK:2)
B(10,8,18,STONEBRICK:1)
B(11,8,18,STONEBRICK:2)
B(12,8,18,STONEBRICK:1)
B(13,8,18,STONEBRICK:2)
B(14,8,18,STONEBRICK)
B(15,8,18,STONEBRICK)
B(16,8,18,STONEBRICK)
B(0,9,18,MOSSY_COBBLESTONE)
B(16,9,18,STONE)
B(0,10,18,MOSSY_COBBLESTONE)
B(16,10,18,MOSSY_COBBLESTONE)
B(0,11,18,STONE)
B(16,11,18,STONE)
B(0,12,18,STONE)
B(16,12,18,STONE)
B(0,13,18,MOSSY_COBBLESTONE)
B(16,13,18,MOSSY_COBBLESTONE)
B(0,14,18,MOSSY_COBBLESTONE)
B(16,14,18,MOSSY_COBBLESTONE)
B(0,15,18,MOSSY_COBBLESTONE)
B(1,15,18,STONEBRICK)
B(7,15,18,STONEBRICK:2)
B(8,15,18,STONEBRICK)
B(9,15,18,STONEBRICK:1)
B(15,15,18,STONEBRICK)
B(16,15,18,STONE)
B(0,16,18,STONEBRICK:1)
B(1,16,18,STONE)
B(2,16,18,STONEBRICK)
B(3,16,18,STONEBRICK:1)
B(4,16,18,STONEBRICK)
B(5,16,18,STONEBRICK)
B(6,16,18,STONEBRICK:2)
B(7,16,18,EMERALD_ORE)
B(8,16,18,STONEBRICK:1)
B(9,16,18,STONE)
B(10,16,18,STONEBRICK:1)
B(11,16,18,STONEBRICK:2)
B(12,16,18,STONEBRICK)
B(13,16,18,STONEBRICK:2)
B(14,16,18,STONEBRICK:1)
B(15,16,18,EMERALD_ORE)
B(16,16,18,STONEBRICK:1)
B(0,0,19,STONEBRICK:2)
B(1,0,19,STONEBRICK:1)
B(2,0,19,STONEBRICK:2)
B(3,0,19,DIRT:1)
B(4,0,19,DIRT:1)
B(5,0,19,DIRT:1)
B(6,0,19,GRASS)
B(7,0,19,DIRT:1)
B(8,0,19,DIRT:1)
B(9,0,19,GRASS)
B(10,0,19,DIRT:1)
B(11,0,19,GRASS)
B(12,0,19,GRASS)
B(13,0,19,DIRT:1)
B(14,0,19,STONEBRICK)
B(15,0,19,STONEBRICK:2)
B(16,0,19,STONEBRICK)
B(0,1,19,STONEBRICK:2)
B(16,1,19,STONEBRICK:1)
B(0,2,19,STONEBRICK:2)
B(16,2,19,STONEBRICK)
B(0,3,19,STONEBRICK)
B(16,3,19,STONEBRICK)
B(0,4,19,STONEBRICK)
B(16,4,19,STONEBRICK)
B(0,5,19,MOSSY_COBBLESTONE)
B(16,5,19,EMERALD_ORE)
B(0,6,19,MOSSY_COBBLESTONE)
B(16,6,19,MOSSY_COBBLESTONE)
B(0,7,19,MOSSY_COBBLESTONE)
B(1,7,19,STONEBRICK:2)
B(7,7,19,STONEBRICK:1)
B(8,7,19,STONEBRICK:2)
B(9,7,19,STONEBRICK)
B(15,7,19,STONEBRICK)
B(16,7,19,EMERALD_ORE)
B(0,8,19,STONEBRICK:1)
B(1,8,19,STONEBRICK:2)
B(2,8,19,STONEBRICK)
B(6,8,19,STONEBRICK:1)
B(7,8,19,STONEBRICK:2)
B(8,8,19,STONEBRICK)
B(9,8,19,STONEBRICK:1)
B(10,8,19,STONEBRICK:1)
B(14,8,19,STONEBRICK)
B(15,8,19,STONEBRICK:2)
B(16,8,19,STONEBRICK:1)
B(0,9,19,EMERALD_ORE)
B(16,9,19,MOSSY_COBBLESTONE)
B(0,10,19,STONE)
B(16,10,19,STONE)
B(0,11,19,MOSSY_COBBLESTONE)
B(16,11,19,MOSSY_COBBLESTONE)
B(0,12,19,STONE)
B(16,12,19,MOSSY_COBBLESTONE)
B(0,13,19,MOSSY_COBBLESTONE)
B(16,13,19,MOSSY_COBBLESTONE)
B(0,14,19,MOSSY_COBBLESTONE)
B(16,14,19,STONE)
B(0,15,19,STONE)
B(1,15,19,STONEBRICK:2)
B(7,15,19,STONEBRICK:1)
B(8,15,19,STONEBRICK:2)
B(9,15,19,STONEBRICK:2)
B(15,15,19,STONEBRICK)
B(16,15,19,MOSSY_COBBLESTONE)
B(0,16,19,STONEBRICK)
B(1,16,19,MOSSY_COBBLESTONE)
B(2,16,19,STONEBRICK:2)
B(6,16,19,STONEBRICK:1)
B(7,16,19,STONE)
B(8,16,19,STONEBRICK)
B(9,16,19,MOSSY_COBBLESTONE)
B(10,16,19,STONEBRICK)
B(14,16,19,STONEBRICK:1)
B(15,16,19,STONE)
B(16,16,19,STONEBRICK:1)
B(0,0,20,STONEBRICK)
B(1,0,20,STONEBRICK)
B(2,0,20,STONEBRICK:1)
B(3,0,20,GRASS)
B(4,0,20,DIRT:1)
B(5,0,20,GRASS)
B(6,0,20,GRASS)
B(7,0,20,GRASS)
B(8,0,20,GRASS)
B(9,0,20,GRASS)
B(10,0,20,GRASS)
B(11,0,20,DIRT:1)
B(12,0,20,DIRT:1)
B(13,0,20,GRASS)
B(14,0,20,STONEBRICK:2)
B(15,0,20,STONEBRICK)
B(16,0,20,STONEBRICK)
B(0,4,20,STONEBRICK)
B(16,4,20,STONEBRICK)
B(0,5,20,MOSSY_COBBLESTONE)
B(16,5,20,STONE)
B(0,6,20,MOSSY_COBBLESTONE)
B(16,6,20,MOSSY_COBBLESTONE)
B(0,7,20,MOSSY_COBBLESTONE)
B(1,7,20,STONEBRICK:1)
B(7,7,20,STONEBRICK)
B(8,7,20,STONEBRICK:2)
B(9,7,20,STONEBRICK:1)
B(15,7,20,STONEBRICK:2)
B(16,7,20,MOSSY_COBBLESTONE)
B(0,8,20,STONEBRICK:1)
B(1,8,20,STONEBRICK:1)
B(2,8,20,STONEBRICK:1)
B(6,8,20,STONEBRICK:1)
B(7,8,20,STONEBRICK:1)
B(8,8,20,STONEBRICK)
B(9,8,20,STONEBRICK)
B(10,8,20,STONEBRICK:1)
B(14,8,20,STONEBRICK:1)
B(15,8,20,STONEBRICK)
B(16,8,20,STONEBRICK:2)
B(0,9,20,MOSSY_COBBLESTONE)
B(1,9,20,STONEBRICK:3)
B(15,9,20,STONEBRICK:3)
B(16,9,20,MOSSY_COBBLESTONE)
B(0,10,20,MOSSY_COBBLESTONE)
B(16,10,20,EMERALD_ORE)
B(0,11,20,STONE)
B(16,11,20,STONE)
B(0,12,20,MOSSY_COBBLESTONE)
B(16,12,20,EMERALD_ORE)
B(0,13,20,STONE)
B(16,13,20,MOSSY_COBBLESTONE)
B(0,14,20,STONE)
B(16,14,20,MOSSY_COBBLESTONE)
B(0,15,20,STONE)
B(1,15,20,STONEBRICK)
B(7,15,20,STONEBRICK:1)
B(8,15,20,STONEBRICK:2)
B(9,15,20,STONEBRICK:2)
B(15,15,20,STONEBRICK:2)
B(16,15,20,STONE)
B(0,16,20,STONEBRICK)
B(1,16,20,STONE)
B(2,16,20,STONEBRICK)
B(6,16,20,STONEBRICK)
B(7,16,20,STONE)
B(8,16,20,STONEBRICK:1)
B(9,16,20,MOSSY_COBBLESTONE)
B(10,16,20,STONEBRICK:2)
B(14,16,20,STONEBRICK)
B(15,16,20,STONE)
B(16,16,20,STONEBRICK:2)
B(0,0,21,STONEBRICK:1)
B(1,0,21,STONEBRICK:2)
B(2,0,21,STONEBRICK:2)
B(3,0,21,GRASS)
B(4,0,21,GRASS)
B(5,0,21,DIRT:1)
B(6,0,21,GRASS)
B(7,0,21,DIRT:1)
B(8,0,21,GRASS)
B(9,0,21,DIRT:1)
B(10,0,21,GRASS)
B(11,0,21,GRASS)
B(12,0,21,DIRT:1)
B(13,0,21,GRASS)
B(14,0,21,STONEBRICK:2)
B(15,0,21,STONEBRICK:1)
B(16,0,21,STONEBRICK:2)
B(0,1,21,STONEBRICK)
B(16,1,21,STONEBRICK:2)
B(0,2,21,STONEBRICK:2)
B(16,2,21,STONEBRICK:2)
B(0,3,21,STONEBRICK)
B(16,3,21,STONEBRICK:2)
B(0,4,21,STONEBRICK)
B(16,4,21,STONEBRICK:1)
B(0,5,21,STONE)
B(16,5,21,STONE)
B(0,6,21,STONE)
B(16,6,21,MOSSY_COBBLESTONE)
B(0,7,21,MOSSY_COBBLESTONE)
B(1,7,21,STONEBRICK:2)
B(7,7,21,STONEBRICK)
B(8,7,21,STONEBRICK:1)
B(9,7,21,STONEBRICK)
B(15,7,21,STONEBRICK)
B(16,7,21,STONE)
B(0,8,21,STONEBRICK)
B(1,8,21,STONEBRICK)
B(2,8,21,STONEBRICK:2)
B(6,8,21,STONEBRICK)
B(7,8,21,STONEBRICK)
B(8,8,21,STONEBRICK:1)
B(9,8,21,STONEBRICK:1)
B(10,8,21,STONEBRICK:1)
B(14,8,21,STONEBRICK:1)
B(15,8,21,STONEBRICK)
B(16,8,21,STONEBRICK)
B(0,9,21,STONE)
B(16,9,21,MOSSY_COBBLESTONE)
B(0,10,21,MOSSY_COBBLESTONE)
B(16,10,21,STONE)
B(0,11,21,MOSSY_COBBLESTONE)
B(16,11,21,MOSSY_COBBLESTONE)
B(0,12,21,STONE)
B(16,12,21,EMERALD_ORE)
B(0,13,21,STONE)
B(16,13,21,STONE)
B(0,14,21,STONE)
B(16,14,21,MOSSY_COBBLESTONE)
B(0,15,21,MOSSY_COBBLESTONE)
B(1,15,21,STONEBRICK:1)
B(7,15,21,STONEBRICK)
B(8,15,21,STONEBRICK:2)
B(9,15,21,STONEBRICK:2)
B(15,15,21,STONEBRICK:1)
B(16,15,21,MOSSY_COBBLESTONE)
B(0,16,21,STONEBRICK:2)
B(1,16,21,STONE)
B(2,16,21,STONEBRICK:1)
B(6,16,21,STONEBRICK:2)
B(7,16,21,STONE)
B(8,16,21,STONEBRICK:1)
B(9,16,21,MOSSY_COBBLESTONE)
B(10,16,21,STONEBRICK)
B(14,16,21,STONEBRICK:2)
B(15,16,21,MOSSY_COBBLESTONE)
B(16,16,21,STONEBRICK:2)
B(0,0,22,STONEBRICK:1)
B(1,0,22,STONEBRICK:1)
B(2,0,22,STONEBRICK:2)
B(3,0,22,STONEBRICK:1)
B(4,0,22,STONEBRICK:2)
B(5,0,22,STONEBRICK:2)
B(6,0,22,STONEBRICK)
B(7,0,22,STONEBRICK)
B(8,0,22,STONEBRICK)
B(9,0,22,STONEBRICK:1)
B(10,0,22,STONEBRICK:2)
B(11,0,22,STONEBRICK)
B(12,0,22,STONEBRICK)
B(13,0,22,STONEBRICK)
B(14,0,22,STONEBRICK)
B(15,0,22,STONEBRICK:2)
B(16,0,22,STONEBRICK)
B(0,1,22,STONE)
B(16,1,22,MOSSY_COBBLESTONE)
B(0,2,22,MOSSY_COBBLESTONE)
B(16,2,22,STONE)
B(0,3,22,STONE)
B(16,3,22,STONE)
B(0,4,22,STONE)
B(16,4,22,MOSSY_COBBLESTONE)
B(0,5,22,STONE)
B(16,5,22,MOSSY_COBBLESTONE)
B(0,6,22,MOSSY_COBBLESTONE)
B(16,6,22,MOSSY_COBBLESTONE)
B(0,7,22,MOSSY_COBBLESTONE)
B(1,7,22,STONEBRICK:2)
B(7,7,22,STONEBRICK:1)
B(8,7,22,STONEBRICK:2)
B(9,7,22,STONEBRICK:2)
B(15,7,22,STONEBRICK:2)
B(16,7,22,STONE)
B(0,8,22,STONEBRICK:1)
B(1,8,22,STONEBRICK:1)
B(2,8,22,STONEBRICK)
B(3,8,22,STONEBRICK:2)
B(4,8,22,STONEBRICK)
B(5,8,22,STONEBRICK)
B(6,8,22,STONEBRICK:2)
B(7,8,22,STONEBRICK)
B(8,8,22,STONEBRICK:2)
B(9,8,22,STONEBRICK)
B(10,8,22,STONEBRICK:2)
B(11,8,22,STONEBRICK:2)
B(12,8,22,STONEBRICK:1)
B(13,8,22,STONEBRICK:2)
B(14,8,22,STONEBRICK:2)
B(15,8,22,STONEBRICK:2)
B(16,8,22,STONEBRICK:1)
B(0,9,22,MOSSY_COBBLESTONE)
B(16,9,22,EMERALD_ORE)
B(0,10,22,STONE)
B(16,10,22,STONE)
B(0,11,22,STONE)
B(16,11,22,STONE)
B(0,12,22,STONE)
B(16,12,22,STONE)
B(0,13,22,STONE)
B(16,13,22,MOSSY_COBBLESTONE)
B(0,14,22,STONE)
B(16,14,22,MOSSY_COBBLESTONE)
B(0,15,22,EMERALD_ORE)
B(1,15,22,STONEBRICK)
B(7,15,22,STONEBRICK:2)
B(8,15,22,STONEBRICK:1)
B(9,15,22,STONEBRICK:1)
B(15,15,22,STONEBRICK:1)
B(16,15,22,STONE)
B(0,16,22,STONEBRICK:1)
B(1,16,22,STONE)
B(2,16,22,STONEBRICK:1)
B(3,16,22,STONEBRICK:2)
B(4,16,22,STONEBRICK:2)
B(5,16,22,STONEBRICK:1)
B(6,16,22,STONEBRICK)
B(7,16,22,MOSSY_COBBLESTONE)
B(8,16,22,STONEBRICK:2)
B(9,16,22,STONE)
B(10,16,22,STONEBRICK)
B(11,16,22,STONEBRICK)
B(12,16,22,STONEBRICK:2)
B(13,16,22,STONEBRICK:2)
B(14,16,22,STONEBRICK:1)
B(15,16,22,STONE)
B(16,16,22,STONEBRICK:2)
B(0,0,23,STONEBRICK:2)
B(1,0,23,STONEBRICK)
B(2,0,23,STONEBRICK:2)
B(3,0,23,STONEBRICK:1)
B(4,0,23,STONEBRICK)
B(5,0,23,STONEBRICK:1)
B(6,0,23,STONEBRICK:2)
B(7,0,23,STONEBRICK:2)
B(8,0,23,STONEBRICK:2)
B(9,0,23,STONEBRICK:1)
B(10,0,23,STONEBRICK:1)
B(11,0,23,STONEBRICK)
B(12,0,23,STONEBRICK)
B(13,0,23,STONEBRICK:1)
B(14,0,23,STONEBRICK:2)
B(15,0,23,STONEBRICK)
B(16,0,23,STONEBRICK)
B(0,1,23,MOSSY_COBBLESTONE)
B(1,1,23,STONE)
B(7,1,23,MOSSY_COBBLESTONE)
B(8,1,23,STONE)
B(9,1,23,STONE)
B(15,1,23,MOSSY_COBBLESTONE)
B(16,1,23,MOSSY_COBBLESTONE)
B(0,2,23,STONE)
B(1,2,23,STONE)
B(7,2,23,STONE)
B(8,2,23,STONE)
B(9,2,23,STONE)
B(15,2,23,MOSSY_COBBLESTONE)
B(16,2,23,STONE)
B(0,3,23,STONE)
B(1,3,23,MOSSY_COBBLESTONE)
B(7,3,23,MOSSY_COBBLESTONE)
B(8,3,23,STONE)
B(9,3,23,STONE)
B(15,3,23,MOSSY_COBBLESTONE)
B(16,3,23,EMERALD_ORE)
B(0,4,23,EMERALD_ORE)
B(1,4,23,STONEBRICK:1)
B(7,4,23,STONEBRICK:1)
B(8,4,23,STONEBRICK:2)
B(9,4,23,STONEBRICK:2)
B(15,4,23,STONEBRICK:2)
B(16,4,23,MOSSY_COBBLESTONE)
B(0,5,23,MOSSY_COBBLESTONE)
B(1,5,23,STONEBRICK:2)
B(7,5,23,STONEBRICK)
B(8,5,23,STONEBRICK)
B(9,5,23,STONEBRICK)
B(15,5,23,STONEBRICK)
B(16,5,23,MOSSY_COBBLESTONE)
B(0,6,23,STONE)
B(1,6,23,STONEBRICK:1)
B(7,6,23,STONEBRICK:1)
B(8,6,23,STONEBRICK)
B(9,6,23,STONEBRICK)
B(15,6,23,STONEBRICK:2)
B(16,6,23,STONE)
B(0,7,23,STONE)
B(1,7,23,STONEBRICK:1)
B(2,7,23,STONEBRICK)
B(3,7,23,STONEBRICK)
B(4,7,23,STONEBRICK:1)
B(5,7,23,STONEBRICK:1)
B(6,7,23,STONEBRICK)
B(7,7,23,STONEBRICK:1)
B(8,7,23,STONEBRICK:1)
B(9,7,23,STONEBRICK:1)
B(10,7,23,STONEBRICK)
B(11,7,23,STONEBRICK:2)
B(12,7,23,STONEBRICK:1)
B(13,7,23,STONEBRICK:2)
B(14,7,23,STONEBRICK:1)
B(15,7,23,STONEBRICK)
B(16,7,23,MOSSY_COBBLESTONE)
B(0,8,23,STONEBRICK)
B(1,8,23,STONEBRICK)
B(2,8,23,STONEBRICK:1)
B(3,8,23,STONEBRICK:2)
B(4,8,23,STONEBRICK:1)
B(5,8,23,STONEBRICK)
B(6,8,23,STONEBRICK:1)
B(7,8,23,STONEBRICK:2)
B(8,8,23,STONEBRICK:2)
B(9,8,23,STONEBRICK)
B(10,8,23,STONEBRICK:1)
B(11,8,23,STONEBRICK:1)
B(12,8,23,STONEBRICK)
B(13,8,23,STONEBRICK:1)
B(14,8,23,STONEBRICK)
B(15,8,23,STONEBRICK:1)
B(16,8,23,STONEBRICK:2)
B(0,9,23,EMERALD_ORE)
B(1,9,23,STONE)
B(7,9,23,MOSSY_COBBLESTONE)
B(8,9,23,STONE)
B(9,9,23,MOSSY_COBBLESTONE)
B(15,9,23,EMERALD_ORE)
B(16,9,23,STONE)
B(0,10,23,STONE)
B(1,10,23,EMERALD_ORE)
B(7,10,23,STONE)
B(8,10,23,STONE)
B(9,10,23,STONE)
B(15,10,23,STONE)
B(16,10,23,STONE)
B(0,11,23,EMERALD_ORE)
B(1,11,23,STONE)
B(7,11,23,STONE)
B(8,11,23,STONE)
B(9,11,23,MOSSY_COBBLESTONE)
B(15,11,23,MOSSY_COBBLESTONE)
B(16,11,23,STONE)
B(0,12,23,STONE)
B(1,12,23,STONEBRICK:2)
B(7,12,23,STONEBRICK:1)
B(8,12,23,STONEBRICK:2)
B(9,12,23,STONEBRICK)
B(15,12,23,STONEBRICK:1)
B(16,12,23,STONE)
B(0,13,23,STONE)
B(1,13,23,STONEBRICK:1)
B(7,13,23,STONEBRICK:2)
B(8,13,23,STONEBRICK:1)
B(9,13,23,STONEBRICK)
B(15,13,23,STONEBRICK:2)
B(16,13,23,STONE)
B(0,14,23,STONE)
B(1,14,23,STONEBRICK)
B(7,14,23,STONEBRICK:2)
B(8,14,23,STONEBRICK:2)
B(9,14,23,STONEBRICK:2)
B(15,14,23,STONEBRICK:1)
B(16,14,23,MOSSY_COBBLESTONE)
B(0,15,23,STONE)
B(1,15,23,STONEBRICK)
B(2,15,23,STONEBRICK)
B(3,15,23,STONEBRICK:2)
B(4,15,23,STONEBRICK)
B(5,15,23,STONEBRICK:2)
B(6,15,23,STONEBRICK:2)
B(7,15,23,STONEBRICK:1)
B(8,15,23,STONEBRICK)
B(9,15,23,STONEBRICK:1)
B(10,15,23,STONEBRICK:2)
B(11,15,23,STONEBRICK:2)
B(12,15,23,STONEBRICK:2)
B(13,15,23,STONEBRICK:1)
B(14,15,23,STONEBRICK)
B(15,15,23,STONEBRICK)
B(16,15,23,MOSSY_COBBLESTONE)
B(0,16,23,STONEBRICK:1)
B(1,16,23,MOSSY_COBBLESTONE)
B(2,16,23,STONE)
B(3,16,23,MOSSY_COBBLESTONE)
B(4,16,23,MOSSY_COBBLESTONE)
B(5,16,23,STONE)
B(6,16,23,MOSSY_COBBLESTONE)
B(7,16,23,STONE)
B(8,16,23,STONEBRICK:2)
B(9,16,23,STONE)
B(10,16,23,MOSSY_COBBLESTONE)
B(11,16,23,STONE)
B(12,16,23,STONE)
B(13,16,23,STONE)
B(14,16,23,STONE)
B(15,16,23,EMERALD_ORE)
B(16,16,23,STONEBRICK:1)
B(0,0,24,STONEBRICK:2)
B(1,0,24,STONEBRICK:1)
B(2,0,24,STONEBRICK:1)
B(3,0,24,STONEBRICK:2)
B(4,0,24,STONEBRICK:1)
B(5,0,24,STONEBRICK:2)
B(6,0,24,STONEBRICK)
B(7,0,24,STONEBRICK)
B(8,0,24,STONEBRICK)
B(9,0,24,STONEBRICK:2)
B(10,0,24,STONEBRICK:1)
B(11,0,24,STONEBRICK)
B(12,0,24,STONEBRICK:1)
B(13,0,24,STONEBRICK:2)
B(14,0,24,STONEBRICK:2)
B(15,0,24,STONEBRICK)
B(16,0,24,STONEBRICK)
B(0,1,24,STONEBRICK)
B(1,1,24,MOSSY_COBBLESTONE)
B(2,1,24,MOSSY_COBBLESTONE)
B(3,1,24,EMERALD_ORE)
B(4,1,24,EMERALD_ORE)
B(5,1,24,STONE)
B(6,1,24,MOSSY_COBBLESTONE)
B(7,1,24,STONE)
B(8,1,24,STONEBRICK)
B(9,1,24,STONE)
B(10,1,24,STONE)
B(11,1,24,STONE)
B(12,1,24,MOSSY_COBBLESTONE)
B(13,1,24,STONE)
B(14,1,24,STONE)
B(15,1,24,EMERALD_ORE)
B(16,1,24,STONEBRICK:2)
B(0,2,24,STONEBRICK:1)
B(1,2,24,MOSSY_COBBLESTONE)
B(2,2,24,STONE)
B(3,2,24,STONE)
B(4,2,24,MOSSY_COBBLESTONE)
B(5,2,24,MOSSY_COBBLESTONE)
B(6,2,24,MOSSY_COBBLESTONE)
B(7,2,24,MOSSY_COBBLESTONE)
B(8,2,24,STONEBRICK)
B(9,2,24,STONE)
B(10,2,24,STONE)
B(11,2,24,MOSSY_COBBLESTONE)
B(12,2,24,STONE)
B(13,2,24,STONE)
B(14,2,24,STONE)
B(15,2,24,STONE)
B(16,2,24,STONEBRICK:2)
B(0,3,24,STONEBRICK:1)
B(1,3,24,STONE)
B(2,3,24,STONE)
B(3,3,24,EMERALD_ORE)
B(4,3,24,STONE)
B(5,3,24,STONE)
B(6,3,24,STONE)
B(7,3,24,MOSSY_COBBLESTONE)
B(8,3,24,STONEBRICK)
B(9,3,24,MOSSY_COBBLESTONE)
B(10,3,24,MOSSY_COBBLESTONE)
B(11,3,24,MOSSY_COBBLESTONE)
B(12,3,24,MOSSY_COBBLESTONE)
B(13,3,24,MOSSY_COBBLESTONE)
B(14,3,24,STONE)
B(15,3,24,STONE)
B(16,3,24,STONEBRICK:1)
B(0,4,24,STONEBRICK)
B(1,4,24,STONE)
B(2,4,24,STONE)
B(3,4,24,MOSSY_COBBLESTONE)
B(4,4,24,MOSSY_COBBLESTONE)
B(5,4,24,MOSSY_COBBLESTONE)
B(6,4,24,STONE)
B(7,4,24,MOSSY_COBBLESTONE)
B(8,4,24,STONEBRICK:2)
B(9,4,24,STONE)
B(10,4,24,MOSSY_COBBLESTONE)
B(11,4,24,STONE)
B(12,4,24,MOSSY_COBBLESTONE)
B(13,4,24,MOSSY_COBBLESTONE)
B(14,4,24,MOSSY_COBBLESTONE)
B(15,4,24,STONE)
B(16,4,24,STONEBRICK:1)
B(0,5,24,STONEBRICK)
B(1,5,24,STONE)
B(2,5,24,STONE)
B(3,5,24,MOSSY_COBBLESTONE)
B(4,5,24,MOSSY_COBBLESTONE)
B(5,5,24,MOSSY_COBBLESTONE)
B(6,5,24,STONE)
B(7,5,24,MOSSY_COBBLESTONE)
B(8,5,24,STONEBRICK)
B(9,5,24,MOSSY_COBBLESTONE)
B(10,5,24,MOSSY_COBBLESTONE)
B(11,5,24,MOSSY_COBBLESTONE)
B(12,5,24,EMERALD_ORE)
B(13,5,24,STONE)
B(14,5,24,MOSSY_COBBLESTONE)
B(15,5,24,STONE)
B(16,5,24,STONEBRICK)
B(0,6,24,STONEBRICK:1)
B(1,6,24,MOSSY_COBBLESTONE)
B(2,6,24,STONE)
B(3,6,24,STONE)
B(4,6,24,STONE)
B(5,6,24,MOSSY_COBBLESTONE)
B(6,6,24,MOSSY_COBBLESTONE)
B(7,6,24,MOSSY_COBBLESTONE)
B(8,6,24,STONEBRICK)
B(9,6,24,MOSSY_COBBLESTONE)
B(10,6,24,STONE)
B(11,6,24,STONE)
B(12,6,24,MOSSY_COBBLESTONE)
B(13,6,24,MOSSY_COBBLESTONE)
B(14,6,24,EMERALD_ORE)
B(15,6,24,STONE)
B(16,6,24,STONEBRICK:2)
B(0,7,24,STONEBRICK:2)
B(1,7,24,STONE)
B(2,7,24,STONE)
B(3,7,24,STONE)
B(4,7,24,STONE)
B(5,7,24,STONE)
B(6,7,24,MOSSY_COBBLESTONE)
B(7,7,24,STONE)
B(8,7,24,STONEBRICK)
B(9,7,24,MOSSY_COBBLESTONE)
B(10,7,24,MOSSY_COBBLESTONE)
B(11,7,24,MOSSY_COBBLESTONE)
B(12,7,24,STONE)
B(13,7,24,MOSSY_COBBLESTONE)
B(14,7,24,STONE)
B(15,7,24,STONE)
B(16,7,24,STONEBRICK:1)
B(0,8,24,STONEBRICK)
B(1,8,24,STONEBRICK:1)
B(2,8,24,STONEBRICK:1)
B(3,8,24,STONEBRICK)
B(4,8,24,STONEBRICK:1)
B(5,8,24,STONEBRICK)
B(6,8,24,STONEBRICK)
B(7,8,24,STONEBRICK)
B(8,8,24,STONEBRICK:1)
B(9,8,24,STONEBRICK:2)
B(10,8,24,STONEBRICK)
B(11,8,24,STONEBRICK)
B(12,8,24,STONEBRICK:2)
B(13,8,24,STONEBRICK:1)
B(14,8,24,STONEBRICK:1)
B(15,8,24,STONEBRICK)
B(16,8,24,STONEBRICK:1)
B(0,9,24,STONEBRICK:1)
B(1,9,24,STONE)
B(2,9,24,STONE)
B(3,9,24,STONE)
B(4,9,24,EMERALD_ORE)
B(5,9,24,MOSSY_COBBLESTONE)
B(6,9,24,STONE)
B(7,9,24,MOSSY_COBBLESTONE)
B(8,9,24,STONEBRICK:1)
B(9,9,24,STONE)
B(10,9,24,MOSSY_COBBLESTONE)
B(11,9,24,STONE)
B(12,9,24,STONE)
B(13,9,24,MOSSY_COBBLESTONE)
B(14,9,24,STONE)
B(15,9,24,MOSSY_COBBLESTONE)
B(16,9,24,STONEBRICK:1)
B(0,10,24,STONEBRICK:2)
B(1,10,24,MOSSY_COBBLESTONE)
B(2,10,24,MOSSY_COBBLESTONE)
B(3,10,24,STONE)
B(4,10,24,STONE)
B(5,10,24,STONE)
B(6,10,24,STONE)
B(7,10,24,STONE)
B(8,10,24,STONEBRICK)
B(9,10,24,STONE)
B(10,10,24,STONE)
B(11,10,24,STONE)
B(12,10,24,MOSSY_COBBLESTONE)
B(13,10,24,STONE)
B(14,10,24,MOSSY_COBBLESTONE)
B(15,10,24,MOSSY_COBBLESTONE)
B(16,10,24,STONEBRICK:2)
B(0,11,24,STONEBRICK:1)
B(1,11,24,MOSSY_COBBLESTONE)
B(2,11,24,STONE)
B(3,11,24,MOSSY_COBBLESTONE)
B(4,11,24,STONE)
B(5,11,24,STONE)
B(6,11,24,MOSSY_COBBLESTONE)
B(7,11,24,STONE)
B(8,11,24,STONEBRICK:2)
B(9,11,24,MOSSY_COBBLESTONE)
B(10,11,24,STONE)
B(11,11,24,MOSSY_COBBLESTONE)
B(12,11,24,MOSSY_COBBLESTONE)
B(13,11,24,STONE)
B(14,11,24,STONE)
B(15,11,24,STONE)
B(16,11,24,STONEBRICK)
B(0,12,24,STONEBRICK)
B(1,12,24,STONE)
B(2,12,24,MOSSY_COBBLESTONE)
B(3,12,24,MOSSY_COBBLESTONE)
B(4,12,24,STONE)
B(5,12,24,STONE)
B(6,12,24,STONE)
B(7,12,24,EMERALD_ORE)
B(8,12,24,STONEBRICK:2)
B(9,12,24,STONE)
B(10,12,24,STONE)
B(11,12,24,MOSSY_COBBLESTONE)
B(12,12,24,STONE)
B(13,12,24,MOSSY_COBBLESTONE)
B(14,12,24,STONE)
B(15,12,24,MOSSY_COBBLESTONE)
B(16,12,24,STONEBRICK)
B(0,13,24,STONEBRICK)
B(1,13,24,MOSSY_COBBLESTONE)
B(2,13,24,STONE)
B(3,13,24,MOSSY_COBBLESTONE)
B(4,13,24,MOSSY_COBBLESTONE)
B(5,13,24,STONE)
B(6,13,24,STONE)
B(7,13,24,STONE)
B(8,13,24,STONEBRICK)
B(9,13,24,STONE)
B(10,13,24,EMERALD_ORE)
B(11,13,24,STONE)
B(12,13,24,STONE)
B(13,13,24,MOSSY_COBBLESTONE)
B(14,13,24,MOSSY_COBBLESTONE)
B(15,13,24,MOSSY_COBBLESTONE)
B(16,13,24,STONEBRICK:1)
B(0,14,24,STONEBRICK)
B(1,14,24,STONE)
B(2,14,24,MOSSY_COBBLESTONE)
B(3,14,24,STONE)
B(4,14,24,STONE)
B(5,14,24,MOSSY_COBBLESTONE)
B(6,14,24,MOSSY_COBBLESTONE)
B(7,14,24,STONE)
B(8,14,24,STONEBRICK)
B(9,14,24,MOSSY_COBBLESTONE)
B(10,14,24,MOSSY_COBBLESTONE)
B(11,14,24,STONE)
B(12,14,24,EMERALD_ORE)
B(13,14,24,MOSSY_COBBLESTONE)
B(14,14,24,MOSSY_COBBLESTONE)
B(15,14,24,MOSSY_COBBLESTONE)
B(16,14,24,STONEBRICK)
B(0,15,24,STONEBRICK:1)
B(1,15,24,MOSSY_COBBLESTONE)
B(2,15,24,STONE)
B(3,15,24,STONE)
B(4,15,24,MOSSY_COBBLESTONE)
B(5,15,24,MOSSY_COBBLESTONE)
B(6,15,24,MOSSY_COBBLESTONE)
B(7,15,24,STONE)
B(8,15,24,STONEBRICK)
B(9,15,24,EMERALD_ORE)
B(10,15,24,STONE)
B(11,15,24,MOSSY_COBBLESTONE)
B(12,15,24,STONE)
B(13,15,24,STONE)
B(14,15,24,MOSSY_COBBLESTONE)
B(15,15,24,EMERALD_ORE)
B(16,15,24,STONEBRICK)
B(0,16,24,STONEBRICK:1)
B(1,16,24,STONEBRICK:2)
B(2,16,24,STONEBRICK:2)
B(3,16,24,STONEBRICK:1)
B(4,16,24,STONEBRICK:2)
B(5,16,24,STONEBRICK:2)
B(6,16,24,STONEBRICK)
B(7,16,24,STONEBRICK)
B(8,16,24,STONEBRICK)
B(9,16,24,STONEBRICK:2)
B(10,16,24,STONEBRICK:1)
B(11,16,24,STONEBRICK:2)
B(12,16,24,STONEBRICK:1)
B(13,16,24,STONEBRICK:1)
B(14,16,24,STONEBRICK)
B(15,16,24,STONEBRICK)
B(16,16,24,STONEBRICK:1)
B(2,5,1,AIR)
B(3,5,1,AIR)
B(5,5,1,AIR)
B(6,5,1,AIR)
B(10,5,1,AIR)
B(11,5,1,AIR)
B(13,5,1,AIR)
B(14,5,1,AIR)
B(2,6,1,AIR)
B(3,6,1,AIR)
B(4,6,1,AIR)
B(5,6,1,AIR)
B(6,6,1,AIR)
B(10,6,1,AIR)
B(11,6,1,AIR)
B(12,6,1,AIR)
B(13,6,1,AIR)
B(14,6,1,AIR)
B(2,7,1,AIR)
B(3,7,1,AIR)
B(4,7,1,AIR)
B(5,7,1,AIR)
B(6,7,1,AIR)
B(10,7,1,AIR)
B(11,7,1,AIR)
B(12,7,1,AIR)
B(13,7,1,AIR)
B(14,7,1,AIR)
B(2,8,1,AIR)
B(3,8,1,AIR)
B(4,8,1,AIR)
B(5,8,1,AIR)
B(6,8,1,AIR)
B(10,8,1,AIR)
B(11,8,1,AIR)
B(12,8,1,AIR)
B(13,8,1,AIR)
B(14,8,1,AIR)
B(2,9,1,AIR)
B(3,9,1,AIR)
B(4,9,1,AIR)
B(5,9,1,AIR)
B(6,9,1,AIR)
B(10,9,1,AIR)
B(11,9,1,AIR)
B(12,9,1,AIR)
B(13,9,1,AIR)
B(14,9,1,AIR)
B(2,10,1,STONE_BRICK_STAIRS:5)
B(3,10,1,AIR)
B(4,10,1,AIR)
B(5,10,1,AIR)
B(6,10,1,STONE_BRICK_STAIRS:4)
B(10,10,1,STONE_BRICK_STAIRS:5)
B(11,10,1,AIR)
B(12,10,1,AIR)
B(13,10,1,AIR)
B(14,10,1,STONE_BRICK_STAIRS:4)
B(1,5,2,AIR)
B(2,5,2,AIR)
B(3,5,2,AIR)
B(4,5,2,AIR)
B(5,5,2,AIR)
B(6,5,2,AIR)
B(7,5,2,AIR)
B(8,5,2,AIR)
B(9,5,2,AIR)
B(10,5,2,AIR)
B(11,5,2,AIR)
B(12,5,2,AIR)
B(13,5,2,AIR)
B(14,5,2,AIR)
B(15,5,2,AIR)
B(1,6,2,AIR)
B(2,6,2,AIR)
B(3,6,2,AIR)
B(4,6,2,AIR)
B(5,6,2,AIR)
B(6,6,2,AIR)
B(7,6,2,AIR)
B(8,6,2,AIR)
B(9,6,2,AIR)
B(10,6,2,AIR)
B(11,6,2,AIR)
B(12,6,2,AIR)
B(13,6,2,AIR)
B(14,6,2,AIR)
B(15,6,2,AIR)
B(1,7,2,AIR)
B(2,7,2,AIR)
B(3,7,2,AIR)
B(4,7,2,AIR)
B(5,7,2,AIR)
B(6,7,2,AIR)
B(7,7,2,AIR)
B(8,7,2,AIR)
B(9,7,2,AIR)
B(10,7,2,AIR)
B(11,7,2,AIR)
B(12,7,2,AIR)
B(13,7,2,AIR)
B(14,7,2,AIR)
B(15,7,2,AIR)
B(1,8,2,AIR)
B(2,8,2,AIR)
B(3,8,2,AIR)
B(4,8,2,AIR)
B(5,8,2,AIR)
B(6,8,2,AIR)
B(7,8,2,AIR)
B(8,8,2,AIR)
B(9,8,2,AIR)
B(10,8,2,AIR)
B(11,8,2,AIR)
B(12,8,2,AIR)
B(13,8,2,AIR)
B(14,8,2,AIR)
B(15,8,2,AIR)
B(1,9,2,AIR)
B(2,9,2,AIR)
B(3,9,2,AIR)
B(4,9,2,AIR)
B(5,9,2,AIR)
B(6,9,2,AIR)
B(7,9,2,AIR)
B(8,9,2,AIR)
B(9,9,2,AIR)
B(10,9,2,AIR)
B(11,9,2,AIR)
B(12,9,2,AIR)
B(13,9,2,AIR)
B(14,9,2,AIR)
B(15,9,2,AIR)
B(1,10,2,STONE_BRICK_STAIRS:7)
B(2,10,2,AIR)
B(3,10,2,AIR)
B(4,10,2,AIR)
B(5,10,2,AIR)
B(6,10,2,AIR)
B(7,10,2,STONE_BRICK_STAIRS:7)
B(8,10,2,STONE_BRICK_STAIRS:7)
B(9,10,2,STONE_BRICK_STAIRS:7)
B(10,10,2,AIR)
B(11,10,2,AIR)
B(12,10,2,AIR)
B(13,10,2,AIR)
B(14,10,2,AIR)
B(15,10,2,STONE_BRICK_STAIRS:7)
B(2,11,2,AIR)
B(3,11,2,AIR)
B(4,11,2,AIR)
B(5,11,2,AIR)
B(6,11,2,AIR)
B(10,11,2,AIR)
B(11,11,2,AIR)
B(12,11,2,AIR)
B(13,11,2,AIR)
B(14,11,2,AIR)
B(1,5,3,AIR)
B(2,5,3,AIR)
B(3,5,3,TALLGRASS:2)
B(4,5,3,TALLGRASS:1)
B(5,5,3,TALLGRASS:2)
B(6,5,3,TALLGRASS:2)
B(7,5,3,AIR)
B(8,5,3,AIR)
B(9,5,3,AIR)
B(10,5,3,AIR)
B(11,5,3,AIR)
B(12,5,3,TALLGRASS:2)
B(13,5,3,TALLGRASS:2)
B(14,5,3,AIR)
B(15,5,3,AIR)
B(1,6,3,AIR)
B(2,6,3,AIR)
B(3,6,3,AIR)
B(4,6,3,AIR)
B(5,6,3,AIR)
B(6,6,3,AIR)
B(7,6,3,AIR)
B(8,6,3,AIR)
B(9,6,3,AIR)
B(10,6,3,AIR)
B(11,6,3,AIR)
B(12,6,3,AIR)
B(13,6,3,AIR)
B(14,6,3,AIR)
B(15,6,3,AIR)
B(1,7,3,AIR)
B(2,7,3,AIR)
B(3,7,3,AIR)
B(4,7,3,AIR)
B(5,7,3,AIR)
B(6,7,3,AIR)
B(7,7,3,AIR)
B(8,7,3,AIR)
B(9,7,3,AIR)
B(10,7,3,AIR)
B(11,7,3,AIR)
B(12,7,3,AIR)
B(13,7,3,AIR)
B(14,7,3,AIR)
B(15,7,3,AIR)
B(1,8,3,AIR)
B(2,8,3,AIR)
B(3,8,3,AIR)
B(4,8,3,AIR)
B(5,8,3,AIR)
B(6,8,3,AIR)
B(7,8,3,AIR)
B(8,8,3,AIR)
B(9,8,3,AIR)
B(10,8,3,AIR)
B(11,8,3,AIR)
B(12,8,3,AIR)
B(13,8,3,AIR)
B(14,8,3,AIR)
B(15,8,3,AIR)
B(1,9,3,AIR)
B(2,9,3,AIR)
B(3,9,3,AIR)
B(4,9,3,AIR)
B(5,9,3,AIR)
B(6,9,3,AIR)
B(7,9,3,AIR)
B(8,9,3,AIR)
B(9,9,3,AIR)
B(10,9,3,AIR)
B(11,9,3,AIR)
B(12,9,3,AIR)
B(13,9,3,AIR)
B(14,9,3,AIR)
B(15,9,3,AIR)
B(1,10,3,AIR)
B(2,10,3,AIR)
B(3,10,3,AIR)
B(4,10,3,AIR)
B(5,10,3,AIR)
B(6,10,3,AIR)
B(7,10,3,AIR)
B(8,10,3,AIR)
B(9,10,3,AIR)
B(10,10,3,AIR)
B(11,10,3,AIR)
B(12,10,3,AIR)
B(13,10,3,AIR)
B(14,10,3,AIR)
B(15,10,3,AIR)
B(2,11,3,AIR)
B(3,11,3,AIR)
B(4,11,3,AIR)
B(5,11,3,AIR)
B(6,11,3,AIR)
B(10,11,3,AIR)
B(11,11,3,AIR)
B(12,11,3,AIR)
B(13,11,3,AIR)
B(14,11,3,AIR)
B(3,12,3,AIR)
B(4,12,3,AIR)
B(5,12,3,AIR)
B(11,12,3,AIR)
B(12,12,3,AIR)
B(13,12,3,AIR)
B(2,5,4,AIR)
B(3,5,4,TALLGRASS:1)
B(4,5,4,AIR)
B(5,5,4,AIR)
B(6,5,4,AIR)
B(7,5,4,AIR)
B(8,5,4,TALLGRASS:2)
B(9,5,4,TALLGRASS:2)
B(10,5,4,AIR)
B(11,5,4,AIR)
B(12,5,4,TALLGRASS:2)
B(13,5,4,AIR)
B(14,5,4,AIR)
B(2,6,4,AIR)
B(3,6,4,AIR)
B(4,6,4,AIR)
B(5,6,4,AIR)
B(6,6,4,AIR)
B(7,6,4,AIR)
B(8,6,4,AIR)
B(9,6,4,AIR)
B(10,6,4,AIR)
B(11,6,4,AIR)
B(12,6,4,AIR)
B(13,6,4,AIR)
B(14,6,4,AIR)
B(1,7,4,AIR)
B(2,7,4,AIR)
B(3,7,4,AIR)
B(4,7,4,AIR)
B(5,7,4,AIR)
B(6,7,4,AIR)
B(7,7,4,AIR)
B(8,7,4,AIR)
B(9,7,4,AIR)
B(10,7,4,AIR)
B(11,7,4,AIR)
B(12,7,4,AIR)
B(13,7,4,AIR)
B(14,7,4,AIR)
B(15,7,4,AIR)
B(1,8,4,AIR)
B(2,8,4,AIR)
B(3,8,4,AIR)
B(4,8,4,AIR)
B(5,8,4,AIR)
B(6,8,4,AIR)
B(7,8,4,AIR)
B(8,8,4,AIR)
B(9,8,4,AIR)
B(10,8,4,AIR)
B(11,8,4,AIR)
B(12,8,4,AIR)
B(13,8,4,AIR)
B(14,8,4,AIR)
B(15,8,4,AIR)
B(1,9,4,AIR)
B(2,9,4,AIR)
B(3,9,4,AIR)
B(4,9,4,AIR)
B(5,9,4,AIR)
B(6,9,4,AIR)
B(7,9,4,AIR)
B(8,9,4,AIR)
B(9,9,4,AIR)
B(10,9,4,AIR)
B(11,9,4,AIR)
B(12,9,4,AIR)
B(13,9,4,AIR)
B(14,9,4,AIR)
B(15,9,4,AIR)
B(1,10,4,AIR)
B(2,10,4,AIR)
B(3,10,4,AIR)
B(4,10,4,AIR)
B(5,10,4,AIR)
B(6,10,4,AIR)
B(7,10,4,AIR)
B(8,10,4,AIR)
B(9,10,4,AIR)
B(10,10,4,AIR)
B(11,10,4,AIR)
B(12,10,4,AIR)
B(13,10,4,AIR)
B(14,10,4,AIR)
B(15,10,4,AIR)
B(2,11,4,AIR)
B(3,11,4,AIR)
B(4,11,4,AIR)
B(5,11,4,AIR)
B(6,11,4,AIR)
B(10,11,4,AIR)
B(11,11,4,AIR)
B(12,11,4,AIR)
B(13,11,4,AIR)
B(14,11,4,AIR)
B(3,12,4,AIR)
B(4,12,4,AIR)
B(5,12,4,AIR)
B(11,12,4,AIR)
B(12,12,4,AIR)
B(13,12,4,AIR)
B(1,5,5,AIR)
B(2,5,5,AIR)
B(3,5,5,AIR)
B(4,5,5,TALLGRASS:1)
B(5,5,5,AIR)
B(6,5,5,AIR)
B(7,5,5,TALLGRASS:1)
B(8,5,5,TALLGRASS:2)
B(9,5,5,TALLGRASS:2)
B(10,5,5,TALLGRASS:1)
B(11,5,5,AIR)
B(12,5,5,TALLGRASS:1)
B(13,5,5,TALLGRASS:1)
B(14,5,5,AIR)
B(15,5,5,AIR)
B(1,6,5,AIR)
B(2,6,5,AIR)
B(3,6,5,AIR)
B(4,6,5,AIR)
B(5,6,5,AIR)
B(6,6,5,AIR)
B(7,6,5,AIR)
B(8,6,5,AIR)
B(9,6,5,AIR)
B(10,6,5,AIR)
B(11,6,5,AIR)
B(12,6,5,AIR)
B(13,6,5,AIR)
B(14,6,5,AIR)
B(15,6,5,AIR)
B(1,7,5,AIR)
B(2,7,5,AIR)
B(3,7,5,AIR)
B(4,7,5,AIR)
B(5,7,5,AIR)
B(6,7,5,AIR)
B(7,7,5,AIR)
B(8,7,5,AIR)
B(9,7,5,AIR)
B(10,7,5,AIR)
B(11,7,5,AIR)
B(12,7,5,AIR)
B(13,7,5,AIR)
B(14,7,5,AIR)
B(15,7,5,AIR)
B(1,8,5,AIR)
B(2,8,5,AIR)
B(3,8,5,AIR)
B(4,8,5,AIR)
B(5,8,5,AIR)
B(6,8,5,AIR)
B(7,8,5,AIR)
B(8,8,5,AIR)
B(9,8,5,AIR)
B(10,8,5,AIR)
B(11,8,5,AIR)
B(12,8,5,AIR)
B(13,8,5,AIR)
B(14,8,5,AIR)
B(15,8,5,AIR)
B(1,9,5,AIR)
B(2,9,5,AIR)
B(3,9,5,AIR)
B(4,9,5,AIR)
B(5,9,5,AIR)
B(6,9,5,AIR)
B(7,9,5,AIR)
B(8,9,5,AIR)
B(9,9,5,AIR)
B(10,9,5,AIR)
B(11,9,5,AIR)
B(12,9,5,AIR)
B(13,9,5,AIR)
B(14,9,5,AIR)
B(15,9,5,AIR)
B(1,10,5,AIR)
B(2,10,5,AIR)
B(3,10,5,AIR)
B(4,10,5,AIR)
B(5,10,5,AIR)
B(6,10,5,AIR)
B(7,10,5,AIR)
B(8,10,5,AIR)
B(9,10,5,AIR)
B(10,10,5,AIR)
B(11,10,5,AIR)
B(12,10,5,AIR)
B(13,10,5,AIR)
B(14,10,5,AIR)
B(15,10,5,AIR)
B(2,11,5,AIR)
B(3,11,5,AIR)
B(4,11,5,AIR)
B(5,11,5,AIR)
B(6,11,5,AIR)
B(10,11,5,AIR)
B(11,11,5,AIR)
B(12,11,5,AIR)
B(13,11,5,AIR)
B(14,11,5,AIR)
B(3,12,5,AIR)
B(4,12,5,AIR)
B(5,12,5,AIR)
B(11,12,5,AIR)
B(12,12,5,AIR)
B(13,12,5,AIR)
B(1,5,6,AIR)
B(2,5,6,AIR)
B(3,5,6,AIR)
B(4,5,6,AIR)
B(5,5,6,AIR)
B(6,5,6,AIR)
B(7,5,6,AIR)
B(8,5,6,AIR)
B(9,5,6,AIR)
B(10,5,6,AIR)
B(11,5,6,AIR)
B(12,5,6,AIR)
B(13,5,6,AIR)
B(14,5,6,AIR)
B(15,5,6,AIR)
B(1,6,6,AIR)
B(2,6,6,AIR)
B(3,6,6,AIR)
B(4,6,6,AIR)
B(5,6,6,AIR)
B(6,6,6,AIR)
B(7,6,6,AIR)
B(8,6,6,AIR)
B(9,6,6,AIR)
B(10,6,6,AIR)
B(11,6,6,AIR)
B(12,6,6,AIR)
B(13,6,6,AIR)
B(14,6,6,AIR)
B(15,6,6,AIR)
B(1,7,6,AIR)
B(2,7,6,AIR)
B(3,7,6,AIR)
B(4,7,6,AIR)
B(5,7,6,AIR)
B(6,7,6,AIR)
B(7,7,6,AIR)
B(8,7,6,AIR)
B(9,7,6,AIR)
B(10,7,6,AIR)
B(11,7,6,AIR)
B(12,7,6,AIR)
B(13,7,6,AIR)
B(14,7,6,AIR)
B(15,7,6,AIR)
B(1,8,6,AIR)
B(2,8,6,AIR)
B(3,8,6,AIR)
B(4,8,6,AIR)
B(5,8,6,AIR)
B(6,8,6,AIR)
B(7,8,6,AIR)
B(8,8,6,AIR)
B(9,8,6,AIR)
B(10,8,6,AIR)
B(11,8,6,AIR)
B(12,8,6,AIR)
B(13,8,6,AIR)
B(14,8,6,AIR)
B(15,8,6,AIR)
B(1,9,6,AIR)
B(2,9,6,AIR)
B(3,9,6,AIR)
B(4,9,6,AIR)
B(5,9,6,AIR)
B(6,9,6,AIR)
B(7,9,6,AIR)
B(8,9,6,AIR)
B(9,9,6,AIR)
B(10,9,6,AIR)
B(11,9,6,AIR)
B(12,9,6,AIR)
B(13,9,6,AIR)
B(14,9,6,AIR)
B(15,9,6,AIR)
B(1,10,6,STONE_BRICK_STAIRS:6)
B(2,10,6,AIR)
B(3,10,6,AIR)
B(4,10,6,AIR)
B(5,10,6,AIR)
B(6,10,6,AIR)
B(7,10,6,STONE_BRICK_STAIRS:6)
B(8,10,6,STONE_BRICK_STAIRS:6)
B(9,10,6,STONE_BRICK_STAIRS:6)
B(10,10,6,AIR)
B(11,10,6,AIR)
B(12,10,6,AIR)
B(13,10,6,AIR)
B(14,10,6,AIR)
B(15,10,6,STONE_BRICK_STAIRS:6)
B(2,11,6,AIR)
B(3,11,6,AIR)
B(4,11,6,AIR)
B(5,11,6,AIR)
B(6,11,6,AIR)
B(10,11,6,AIR)
B(11,11,6,AIR)
B(12,11,6,AIR)
B(13,11,6,AIR)
B(14,11,6,AIR)
B(2,5,7,AIR)
B(3,5,7,AIR)
B(4,5,7,AIR)
B(5,5,7,AIR)
B(6,5,7,AIR)
B(10,5,7,AIR)
B(11,5,7,AIR)
B(12,5,7,AIR)
B(13,5,7,AIR)
B(14,5,7,AIR)
B(2,6,7,AIR)
B(3,6,7,AIR)
B(4,6,7,AIR)
B(5,6,7,AIR)
B(6,6,7,AIR)
B(10,6,7,AIR)
B(11,6,7,AIR)
B(12,6,7,AIR)
B(13,6,7,AIR)
B(14,6,7,AIR)
B(2,7,7,AIR)
B(3,7,7,AIR)
B(4,7,7,AIR)
B(5,7,7,AIR)
B(6,7,7,AIR)
B(10,7,7,AIR)
B(11,7,7,AIR)
B(12,7,7,AIR)
B(13,7,7,AIR)
B(14,7,7,AIR)
B(2,8,7,AIR)
B(3,8,7,AIR)
B(4,8,7,AIR)
B(5,8,7,AIR)
B(6,8,7,AIR)
B(10,8,7,AIR)
B(11,8,7,AIR)
B(12,8,7,AIR)
B(13,8,7,AIR)
B(14,8,7,AIR)
B(2,9,7,AIR)
B(3,9,7,AIR)
B(4,9,7,AIR)
B(5,9,7,AIR)
B(6,9,7,AIR)
B(10,9,7,AIR)
B(11,9,7,AIR)
B(12,9,7,AIR)
B(13,9,7,AIR)
B(14,9,7,AIR)
B(2,10,7,STONE_BRICK_STAIRS:5)
B(3,10,7,AIR)
B(4,10,7,AIR)
B(5,10,7,AIR)
B(6,10,7,STONE_BRICK_STAIRS:4)
B(10,10,7,STONE_BRICK_STAIRS:5)
B(11,10,7,AIR)
B(12,10,7,AIR)
B(13,10,7,AIR)
B(14,10,7,STONE_BRICK_STAIRS:4)
B(4,5,8,AIR)
B(12,5,8,AIR)
B(4,6,8,AIR)
B(12,6,8,AIR)
B(4,7,8,AIR)
B(12,7,8,AIR)
B(4,4,9,STONE_SLAB)
B(4,5,9,AIR)
B(12,5,9,STONE_SLAB)
B(4,6,9,AIR)
B(12,6,9,AIR)
B(4,7,9,STONE_SLAB)
B(12,7,9,AIR)
B(12,8,9,STONE_SLAB)
B(4,4,10,AIR)
B(4,5,10,AIR)
B(4,6,10,AIR)
B(12,6,10,AIR)
B(12,7,10,AIR)
B(12,8,10,AIR)
B(4,3,11,STONE_SLAB)
B(4,4,11,AIR)
B(4,5,11,AIR)
B(4,6,11,STONE_SLAB)
B(12,6,11,STONE_SLAB)
B(12,7,11,AIR)
B(12,8,11,AIR)
B(12,9,11,STONE_SLAB)
B(4,3,12,AIR)
B(4,4,12,AIR)
B(4,5,12,AIR)
B(12,7,12,AIR)
B(12,8,12,AIR)
B(12,9,12,AIR)
B(4,2,13,STONE_SLAB)
B(4,3,13,AIR)
B(4,4,13,AIR)
B(4,5,13,STONE_SLAB)
B(12,7,13,STONE_SLAB)
B(12,8,13,AIR)
B(12,9,13,AIR)
B(12,10,13,STONE_SLAB)
B(4,2,14,AIR)
B(4,3,14,AIR)
B(4,4,14,AIR)
B(12,8,14,AIR)
B(12,9,14,AIR)
B(12,10,14,AIR)
B(4,1,15,STONE_SLAB)
B(4,2,15,AIR)
B(4,3,15,AIR)
B(4,4,15,STONE_SLAB)
B(12,8,15,STONE_SLAB)
B(12,9,15,AIR)
B(12,10,15,AIR)
B(12,11,15,STONE_SLAB)
B(4,1,16,AIR)
B(12,1,16,AIR)
B(4,2,16,AIR)
B(12,2,16,AIR)
B(4,3,16,AIR)
B(12,3,16,AIR)
B(4,9,16,AIR)
B(12,9,16,AIR)
B(4,10,16,AIR)
B(12,10,16,AIR)
B(4,11,16,AIR)
B(12,11,16,AIR)
B(2,1,17,AIR)
B(3,1,17,AIR)
B(4,1,17,AIR)
B(5,1,17,AIR)
B(6,1,17,AIR)
B(10,1,17,AIR)
B(11,1,17,AIR)
B(12,1,17,AIR)
B(13,1,17,AIR)
B(14,1,17,AIR)
B(2,2,17,AIR)
B(3,2,17,AIR)
B(4,2,17,AIR)
B(5,2,17,AIR)
B(6,2,17,AIR)
B(10,2,17,AIR)
B(11,2,17,AIR)
B(12,2,17,AIR)
B(13,2,17,AIR)
B(14,2,17,AIR)
B(2,3,17,AIR)
B(3,3,17,AIR)
B(4,3,17,AIR)
B(5,3,17,AIR)
B(6,3,17,AIR)
B(10,3,17,AIR)
B(11,3,17,AIR)
B(12,3,17,AIR)
B(13,3,17,AIR)
B(14,3,17,AIR)
B(2,4,17,AIR)
B(3,4,17,AIR)
B(4,4,17,AIR)
B(5,4,17,AIR)
B(6,4,17,AIR)
B(10,4,17,AIR)
B(11,4,17,AIR)
B(12,4,17,AIR)
B(13,4,17,AIR)
B(14,4,17,AIR)
B(2,5,17,AIR)
B(3,5,17,AIR)
B(4,5,17,AIR)
B(5,5,17,AIR)
B(6,5,17,AIR)
B(10,5,17,AIR)
B(11,5,17,AIR)
B(12,5,17,AIR)
B(13,5,17,AIR)
B(14,5,17,AIR)
B(2,6,17,STONE_BRICK_STAIRS:5)
B(3,6,17,AIR)
B(4,6,17,AIR)
B(5,6,17,AIR)
B(6,6,17,STONE_BRICK_STAIRS:4)
B(10,6,17,STONE_BRICK_STAIRS:5)
B(11,6,17,AIR)
B(12,6,17,AIR)
B(13,6,17,AIR)
B(14,6,17,STONE_BRICK_STAIRS:4)
B(2,9,17,AIR)
B(3,9,17,AIR)
B(4,9,17,AIR)
B(5,9,17,AIR)
B(6,9,17,AIR)
B(10,9,17,AIR)
B(11,9,17,AIR)
B(12,9,17,AIR)
B(13,9,17,AIR)
B(14,9,17,AIR)
B(2,10,17,AIR)
B(3,10,17,AIR)
B(4,10,17,AIR)
B(5,10,17,AIR)
B(6,10,17,AIR)
B(10,10,17,AIR)
B(11,10,17,AIR)
B(12,10,17,AIR)
B(13,10,17,AIR)
B(14,10,17,AIR)
B(2,11,17,AIR)
B(3,11,17,AIR)
B(4,11,17,AIR)
B(5,11,17,AIR)
B(6,11,17,AIR)
B(10,11,17,AIR)
B(11,11,17,AIR)
B(12,11,17,AIR)
B(13,11,17,AIR)
B(14,11,17,AIR)
B(2,12,17,AIR)
B(3,12,17,AIR)
B(4,12,17,AIR)
B(5,12,17,AIR)
B(6,12,17,AIR)
B(10,12,17,AIR)
B(11,12,17,AIR)
B(12,12,17,AIR)
B(13,12,17,AIR)
B(14,12,17,AIR)
B(2,13,17,AIR)
B(3,13,17,AIR)
B(4,13,17,AIR)
B(5,13,17,AIR)
B(6,13,17,AIR)
B(10,13,17,AIR)
B(11,13,17,AIR)
B(12,13,17,AIR)
B(13,13,17,AIR)
B(14,13,17,AIR)
B(2,14,17,STONE_BRICK_STAIRS:5)
B(3,14,17,AIR)
B(4,14,17,AIR)
B(5,14,17,AIR)
B(6,14,17,STONE_BRICK_STAIRS:4)
B(10,14,17,STONE_BRICK_STAIRS:5)
B(11,14,17,AIR)
B(12,14,17,AIR)
B(13,14,17,AIR)
B(14,14,17,STONE_BRICK_STAIRS:4)
B(1,1,18,AIR)
B(2,1,18,AIR)
B(3,1,18,AIR)
B(4,1,18,AIR)
B(5,1,18,AIR)
B(6,1,18,AIR)
B(7,1,18,AIR)
B(8,1,18,AIR)
B(9,1,18,AIR)
B(10,1,18,AIR)
B(11,1,18,AIR)
B(12,1,18,AIR)
B(13,1,18,AIR)
B(14,1,18,AIR)
B(15,1,18,AIR)
B(1,2,18,AIR)
B(2,2,18,AIR)
B(3,2,18,AIR)
B(4,2,18,AIR)
B(5,2,18,AIR)
B(6,2,18,AIR)
B(7,2,18,AIR)
B(8,2,18,AIR)
B(9,2,18,AIR)
B(10,2,18,AIR)
B(11,2,18,AIR)
B(12,2,18,AIR)
B(13,2,18,AIR)
B(14,2,18,AIR)
B(15,2,18,AIR)
B(1,3,18,AIR)
B(2,3,18,AIR)
B(3,3,18,AIR)
B(4,3,18,AIR)
B(5,3,18,AIR)
B(6,3,18,AIR)
B(7,3,18,AIR)
B(8,3,18,AIR)
B(9,3,18,AIR)
B(10,3,18,AIR)
B(11,3,18,AIR)
B(12,3,18,AIR)
B(13,3,18,AIR)
B(14,3,18,AIR)
B(15,3,18,AIR)
B(1,4,18,AIR)
B(2,4,18,AIR)
B(3,4,18,AIR)
B(4,4,18,AIR)
B(5,4,18,AIR)
B(6,4,18,AIR)
B(7,4,18,AIR)
B(8,4,18,AIR)
B(9,4,18,AIR)
B(10,4,18,AIR)
B(11,4,18,AIR)
B(12,4,18,AIR)
B(13,4,18,AIR)
B(14,4,18,AIR)
B(15,4,18,AIR)
B(1,5,18,AIR)
B(2,5,18,AIR)
B(3,5,18,AIR)
B(4,5,18,AIR)
B(5,5,18,AIR)
B(6,5,18,AIR)
B(7,5,18,AIR)
B(8,5,18,AIR)
B(9,5,18,AIR)
B(10,5,18,AIR)
B(11,5,18,AIR)
B(12,5,18,AIR)
B(13,5,18,AIR)
B(14,5,18,AIR)
B(15,5,18,AIR)
B(1,6,18,STONE_BRICK_STAIRS:7)
B(2,6,18,AIR)
B(3,6,18,AIR)
B(4,6,18,AIR)
B(5,6,18,AIR)
B(6,6,18,AIR)
B(7,6,18,STONE_BRICK_STAIRS:7)
B(8,6,18,STONE_BRICK_STAIRS:7)
B(9,6,18,STONE_BRICK_STAIRS:7)
B(10,6,18,AIR)
B(11,6,18,AIR)
B(12,6,18,AIR)
B(13,6,18,AIR)
B(14,6,18,AIR)
B(15,6,18,STONE_BRICK_STAIRS:7)
B(2,7,18,AIR)
B(3,7,18,AIR)
B(4,7,18,AIR)
B(5,7,18,AIR)
B(6,7,18,AIR)
B(10,7,18,AIR)
B(11,7,18,AIR)
B(12,7,18,AIR)
B(13,7,18,AIR)
B(14,7,18,AIR)
B(1,9,18,AIR)
B(2,9,18,AIR)
B(3,9,18,AIR)
B(4,9,18,AIR)
B(5,9,18,AIR)
B(6,9,18,AIR)
B(7,9,18,AIR)
B(8,9,18,AIR)
B(9,9,18,AIR)
B(10,9,18,AIR)
B(11,9,18,AIR)
B(12,9,18,AIR)
B(13,9,18,AIR)
B(14,9,18,AIR)
B(15,9,18,AIR)
B(1,10,18,AIR)
B(2,10,18,AIR)
B(3,10,18,AIR)
B(4,10,18,AIR)
B(5,10,18,AIR)
B(6,10,18,AIR)
B(7,10,18,AIR)
B(8,10,18,AIR)
B(9,10,18,AIR)
B(10,10,18,AIR)
B(11,10,18,AIR)
B(12,10,18,AIR)
B(13,10,18,AIR)
B(14,10,18,AIR)
B(15,10,18,AIR)
B(1,11,18,AIR)
B(2,11,18,AIR)
B(3,11,18,AIR)
B(4,11,18,AIR)
B(5,11,18,AIR)
B(6,11,18,AIR)
B(7,11,18,AIR)
B(8,11,18,AIR)
B(9,11,18,AIR)
B(10,11,18,AIR)
B(11,11,18,AIR)
B(12,11,18,AIR)
B(13,11,18,AIR)
B(14,11,18,AIR)
B(15,11,18,AIR)
B(1,12,18,AIR)
B(2,12,18,AIR)
B(3,12,18,AIR)
B(4,12,18,AIR)
B(5,12,18,AIR)
B(6,12,18,AIR)
B(7,12,18,AIR)
B(8,12,18,AIR)
B(9,12,18,AIR)
B(10,12,18,AIR)
B(11,12,18,AIR)
B(12,12,18,AIR)
B(13,12,18,AIR)
B(14,12,18,AIR)
B(15,12,18,AIR)
B(1,13,18,AIR)
B(2,13,18,AIR)
B(3,13,18,AIR)
B(4,13,18,AIR)
B(5,13,18,AIR)
B(6,13,18,AIR)
B(7,13,18,AIR)
B(8,13,18,AIR)
B(9,13,18,AIR)
B(10,13,18,AIR)
B(11,13,18,AIR)
B(12,13,18,AIR)
B(13,13,18,AIR)
B(14,13,18,AIR)
B(15,13,18,AIR)
B(1,14,18,STONE_BRICK_STAIRS:7)
B(2,14,18,AIR)
B(3,14,18,AIR)
B(4,14,18,AIR)
B(5,14,18,AIR)
B(6,14,18,AIR)
B(7,14,18,STONE_BRICK_STAIRS:7)
B(8,14,18,STONE_BRICK_STAIRS:7)
B(9,14,18,STONE_BRICK_STAIRS:7)
B(10,14,18,AIR)
B(11,14,18,AIR)
B(12,14,18,AIR)
B(13,14,18,AIR)
B(14,14,18,AIR)
B(15,14,18,STONE_BRICK_STAIRS:7)
B(2,15,18,AIR)
B(3,15,18,AIR)
B(4,15,18,AIR)
B(5,15,18,AIR)
B(6,15,18,AIR)
B(10,15,18,AIR)
B(11,15,18,AIR)
B(12,15,18,AIR)
B(13,15,18,AIR)
B(14,15,18,AIR)
B(1,1,19,AIR)
B(2,1,19,AIR)
B(3,1,19,TALLGRASS:2)
B(4,1,19,AIR)
B(5,1,19,AIR)
B(6,1,19,TALLGRASS:1)
B(7,1,19,TALLGRASS:1)
B(8,1,19,TALLGRASS:2)
B(9,1,19,TALLGRASS:1)
B(10,1,19,TALLGRASS:1)
B(11,1,19,AIR)
B(12,1,19,TALLGRASS:1)
B(13,1,19,TALLGRASS:2)
B(14,1,19,AIR)
B(15,1,19,AIR)
B(1,2,19,AIR)
B(2,2,19,AIR)
B(3,2,19,AIR)
B(4,2,19,AIR)
B(5,2,19,AIR)
B(6,2,19,AIR)
B(7,2,19,AIR)
B(8,2,19,AIR)
B(9,2,19,AIR)
B(10,2,19,AIR)
B(11,2,19,AIR)
B(12,2,19,AIR)
B(13,2,19,AIR)
B(14,2,19,AIR)
B(15,2,19,AIR)
B(1,3,19,AIR)
B(2,3,19,AIR)
B(3,3,19,AIR)
B(4,3,19,AIR)
B(5,3,19,AIR)
B(6,3,19,AIR)
B(7,3,19,AIR)
B(8,3,19,AIR)
B(9,3,19,AIR)
B(10,3,19,AIR)
B(11,3,19,AIR)
B(12,3,19,AIR)
B(13,3,19,AIR)
B(14,3,19,AIR)
B(15,3,19,AIR)
B(1,4,19,AIR)
B(2,4,19,AIR)
B(3,4,19,AIR)
B(4,4,19,AIR)
B(5,4,19,AIR)
B(6,4,19,AIR)
B(7,4,19,AIR)
B(8,4,19,AIR)
B(9,4,19,AIR)
B(10,4,19,AIR)
B(11,4,19,AIR)
B(12,4,19,AIR)
B(13,4,19,AIR)
B(14,4,19,AIR)
B(15,4,19,AIR)
B(1,5,19,AIR)
B(2,5,19,AIR)
B(3,5,19,AIR)
B(4,5,19,AIR)
B(5,5,19,AIR)
B(6,5,19,AIR)
B(7,5,19,AIR)
B(8,5,19,AIR)
B(9,5,19,AIR)
B(10,5,19,AIR)
B(11,5,19,AIR)
B(12,5,19,AIR)
B(13,5,19,AIR)
B(14,5,19,AIR)
B(15,5,19,AIR)
B(1,6,19,AIR)
B(2,6,19,AIR)
B(3,6,19,AIR)
B(4,6,19,AIR)
B(5,6,19,AIR)
B(6,6,19,AIR)
B(7,6,19,AIR)
B(8,6,19,AIR)
B(9,6,19,AIR)
B(10,6,19,AIR)
B(11,6,19,AIR)
B(12,6,19,AIR)
B(13,6,19,AIR)
B(14,6,19,AIR)
B(15,6,19,AIR)
B(2,7,19,AIR)
B(3,7,19,AIR)
B(4,7,19,AIR)
B(5,7,19,AIR)
B(6,7,19,AIR)
B(10,7,19,AIR)
B(11,7,19,AIR)
B(12,7,19,AIR)
B(13,7,19,AIR)
B(14,7,19,AIR)
B(3,8,19,AIR)
B(4,8,19,AIR)
B(5,8,19,AIR)
B(11,8,19,AIR)
B(12,8,19,AIR)
B(13,8,19,AIR)
B(1,9,19,AIR)
B(2,9,19,AIR)
B(3,9,19,AIR)
B(4,9,19,AIR)
B(5,9,19,AIR)
B(6,9,19,AIR)
B(7,9,19,AIR)
B(8,9,19,AIR)
B(9,9,19,AIR)
B(10,9,19,AIR)
B(11,9,19,AIR)
B(12,9,19,AIR)
B(13,9,19,AIR)
B(14,9,19,AIR)
B(15,9,19,AIR)
B(1,10,19,AIR)
B(2,10,19,AIR)
B(3,10,19,AIR)
B(4,10,19,AIR)
B(5,10,19,AIR)
B(6,10,19,AIR)
B(7,10,19,AIR)
B(8,10,19,AIR)
B(9,10,19,AIR)
B(10,10,19,AIR)
B(11,10,19,AIR)
B(12,10,19,AIR)
B(13,10,19,AIR)
B(14,10,19,AIR)
B(15,10,19,AIR)
B(1,11,19,AIR)
B(2,11,19,AIR)
B(3,11,19,AIR)
B(4,11,19,AIR)
B(5,11,19,AIR)
B(6,11,19,AIR)
B(7,11,19,AIR)
B(8,11,19,AIR)
B(9,11,19,AIR)
B(10,11,19,AIR)
B(11,11,19,AIR)
B(12,11,19,AIR)
B(13,11,19,AIR)
B(14,11,19,AIR)
B(15,11,19,AIR)
B(1,12,19,AIR)
B(2,12,19,AIR)
B(3,12,19,AIR)
B(4,12,19,AIR)
B(5,12,19,AIR)
B(6,12,19,AIR)
B(7,12,19,AIR)
B(8,12,19,AIR)
B(9,12,19,AIR)
B(10,12,19,AIR)
B(11,12,19,AIR)
B(12,12,19,AIR)
B(13,12,19,AIR)
B(14,12,19,AIR)
B(15,12,19,AIR)
B(1,13,19,AIR)
B(2,13,19,AIR)
B(3,13,19,AIR)
B(4,13,19,AIR)
B(5,13,19,AIR)
B(6,13,19,AIR)
B(7,13,19,AIR)
B(8,13,19,AIR)
B(9,13,19,AIR)
B(10,13,19,AIR)
B(11,13,19,AIR)
B(12,13,19,AIR)
B(13,13,19,AIR)
B(14,13,19,AIR)
B(15,13,19,AIR)
B(1,14,19,AIR)
B(2,14,19,AIR)
B(3,14,19,AIR)
B(4,14,19,AIR)
B(5,14,19,AIR)
B(6,14,19,AIR)
B(7,14,19,AIR)
B(8,14,19,AIR)
B(9,14,19,AIR)
B(10,14,19,AIR)
B(11,14,19,AIR)
B(12,14,19,AIR)
B(13,14,19,AIR)
B(14,14,19,AIR)
B(15,14,19,AIR)
B(2,15,19,AIR)
B(3,15,19,AIR)
B(4,15,19,AIR)
B(5,15,19,AIR)
B(6,15,19,AIR)
B(10,15,19,AIR)
B(11,15,19,AIR)
B(12,15,19,AIR)
B(13,15,19,AIR)
B(14,15,19,AIR)
B(3,16,19,AIR)
B(4,16,19,AIR)
B(5,16,19,AIR)
B(11,16,19,AIR)
B(12,16,19,AIR)
B(13,16,19,AIR)
B(0,1,20,AIR)
B(1,1,20,AIR)
B(2,1,20,AIR)
B(3,1,20,TALLGRASS:2)
B(4,1,20,TALLGRASS:1)
B(5,1,20,TALLGRASS:2)
B(6,1,20,AIR)
B(7,1,20,TALLGRASS:1)
B(9,1,20,TALLGRASS:2)
B(10,1,20,AIR)
B(11,1,20,TALLGRASS:2)
B(12,1,20,TALLGRASS:2)
B(13,1,20,TALLGRASS:1)
B(14,1,20,AIR)
B(15,1,20,AIR)
B(16,1,20,AIR)
B(0,2,20,AIR)
B(1,2,20,AIR)
B(2,2,20,AIR)
B(3,2,20,AIR)
B(4,2,20,AIR)
B(5,2,20,AIR)
B(6,2,20,AIR)
B(7,2,20,AIR)
B(8,2,20,AIR)
B(9,2,20,AIR)
B(10,2,20,AIR)
B(11,2,20,AIR)
B(12,2,20,AIR)
B(13,2,20,AIR)
B(14,2,20,AIR)
B(15,2,20,AIR)
B(16,2,20,AIR)
B(0,3,20,AIR)
B(1,3,20,AIR)
B(2,3,20,AIR)
B(3,3,20,AIR)
B(4,3,20,AIR)
B(5,3,20,AIR)
B(6,3,20,AIR)
B(7,3,20,AIR)
B(8,3,20,AIR)
B(9,3,20,AIR)
B(10,3,20,AIR)
B(11,3,20,AIR)
B(12,3,20,AIR)
B(13,3,20,AIR)
B(14,3,20,AIR)
B(15,3,20,AIR)
B(16,3,20,AIR)
B(1,4,20,AIR)
B(2,4,20,AIR)
B(3,4,20,AIR)
B(4,4,20,AIR)
B(5,4,20,AIR)
B(6,4,20,AIR)
B(7,4,20,AIR)
B(8,4,20,AIR)
B(9,4,20,AIR)
B(10,4,20,AIR)
B(11,4,20,AIR)
B(12,4,20,AIR)
B(13,4,20,AIR)
B(14,4,20,AIR)
B(15,4,20,AIR)
B(1,5,20,AIR)
B(2,5,20,AIR)
B(3,5,20,AIR)
B(4,5,20,AIR)
B(5,5,20,AIR)
B(6,5,20,AIR)
B(7,5,20,AIR)
B(8,5,20,AIR)
B(9,5,20,AIR)
B(10,5,20,AIR)
B(11,5,20,AIR)
B(12,5,20,AIR)
B(13,5,20,AIR)
B(14,5,20,AIR)
B(15,5,20,AIR)
B(1,6,20,AIR)
B(2,6,20,AIR)
B(3,6,20,AIR)
B(4,6,20,AIR)
B(5,6,20,AIR)
B(6,6,20,AIR)
B(7,6,20,AIR)
B(8,6,20,AIR)
B(9,6,20,AIR)
B(10,6,20,AIR)
B(11,6,20,AIR)
B(12,6,20,AIR)
B(13,6,20,AIR)
B(14,6,20,AIR)
B(15,6,20,AIR)
B(2,7,20,AIR)
B(3,7,20,AIR)
B(4,7,20,AIR)
B(5,7,20,AIR)
B(6,7,20,AIR)
B(10,7,20,AIR)
B(11,7,20,AIR)
B(12,7,20,AIR)
B(13,7,20,AIR)
B(14,7,20,AIR)
B(3,8,20,AIR)
B(4,8,20,AIR)
B(5,8,20,AIR)
B(11,8,20,AIR)
B(12,8,20,AIR)
B(13,8,20,AIR)
B(2,9,20,AIR)
B(3,9,20,AIR)
B(4,9,20,AIR)
B(5,9,20,AIR)
B(6,9,20,AIR)
B(7,9,20,AIR)
B(9,9,20,AIR)
B(10,9,20,AIR)
B(11,9,20,AIR)
B(12,9,20,AIR)
B(13,9,20,AIR)
B(14,9,20,AIR)
B(2,10,20,AIR)
B(3,10,20,AIR)
B(4,10,20,AIR)
B(5,10,20,AIR)
B(6,10,20,AIR)
B(7,10,20,AIR)
B(8,10,20,AIR)
B(9,10,20,AIR)
B(10,10,20,AIR)
B(11,10,20,AIR)
B(12,10,20,AIR)
B(13,10,20,AIR)
B(14,10,20,AIR)
B(1,11,20,AIR)
B(2,11,20,AIR)
B(3,11,20,AIR)
B(4,11,20,AIR)
B(5,11,20,AIR)
B(6,11,20,AIR)
B(7,11,20,AIR)
B(8,11,20,AIR)
B(9,11,20,AIR)
B(10,11,20,AIR)
B(11,11,20,AIR)
B(12,11,20,AIR)
B(13,11,20,AIR)
B(14,11,20,AIR)
B(15,11,20,AIR)
B(1,12,20,AIR)
B(2,12,20,AIR)
B(3,12,20,AIR)
B(4,12,20,AIR)
B(5,12,20,AIR)
B(6,12,20,AIR)
B(7,12,20,AIR)
B(8,12,20,AIR)
B(9,12,20,AIR)
B(10,12,20,AIR)
B(11,12,20,AIR)
B(12,12,20,AIR)
B(13,12,20,AIR)
B(14,12,20,AIR)
B(15,12,20,AIR)
B(1,13,20,AIR)
B(2,13,20,AIR)
B(3,13,20,AIR)
B(4,13,20,AIR)
B(5,13,20,AIR)
B(6,13,20,AIR)
B(7,13,20,AIR)
B(8,13,20,AIR)
B(9,13,20,AIR)
B(10,13,20,AIR)
B(11,13,20,AIR)
B(12,13,20,AIR)
B(13,13,20,AIR)
B(14,13,20,AIR)
B(15,13,20,AIR)
B(1,14,20,AIR)
B(2,14,20,AIR)
B(3,14,20,AIR)
B(4,14,20,AIR)
B(5,14,20,AIR)
B(6,14,20,AIR)
B(7,14,20,AIR)
B(8,14,20,AIR)
B(9,14,20,AIR)
B(10,14,20,AIR)
B(11,14,20,AIR)
B(12,14,20,AIR)
B(13,14,20,AIR)
B(14,14,20,AIR)
B(15,14,20,AIR)
B(2,15,20,AIR)
B(3,15,20,AIR)
B(4,15,20,AIR)
B(5,15,20,AIR)
B(6,15,20,AIR)
B(10,15,20,AIR)
B(11,15,20,AIR)
B(12,15,20,AIR)
B(13,15,20,AIR)
B(14,15,20,AIR)
B(3,16,20,AIR)
B(4,16,20,AIR)
B(5,16,20,AIR)
B(11,16,20,AIR)
B(12,16,20,AIR)
B(13,16,20,AIR)
B(1,1,21,AIR)
B(2,1,21,AIR)
B(3,1,21,TALLGRASS:2)
B(4,1,21,TALLGRASS:2)
B(5,1,21,TALLGRASS:2)
B(6,1,21,TALLGRASS:1)
B(7,1,21,AIR)
B(8,1,21,TALLGRASS:2)
B(9,1,21,AIR)
B(10,1,21,AIR)
B(11,1,21,TALLGRASS:1)
B(12,1,21,AIR)
B(13,1,21,TALLGRASS:2)
B(14,1,21,AIR)
B(15,1,21,AIR)
B(1,2,21,AIR)
B(2,2,21,AIR)
B(3,2,21,AIR)
B(4,2,21,AIR)
B(5,2,21,AIR)
B(6,2,21,AIR)
B(7,2,21,AIR)
B(8,2,21,AIR)
B(9,2,21,AIR)
B(10,2,21,AIR)
B(11,2,21,AIR)
B(12,2,21,AIR)
B(13,2,21,AIR)
B(14,2,21,AIR)
B(15,2,21,AIR)
B(1,3,21,AIR)
B(2,3,21,AIR)
B(3,3,21,AIR)
B(4,3,21,AIR)
B(5,3,21,AIR)
B(6,3,21,AIR)
B(7,3,21,AIR)
B(8,3,21,AIR)
B(9,3,21,AIR)
B(10,3,21,AIR)
B(11,3,21,AIR)
B(12,3,21,AIR)
B(13,3,21,AIR)
B(14,3,21,AIR)
B(15,3,21,AIR)
B(1,4,21,AIR)
B(2,4,21,AIR)
B(3,4,21,AIR)
B(4,4,21,AIR)
B(5,4,21,AIR)
B(6,4,21,AIR)
B(7,4,21,AIR)
B(8,4,21,AIR)
B(9,4,21,AIR)
B(10,4,21,AIR)
B(11,4,21,AIR)
B(12,4,21,AIR)
B(13,4,21,AIR)
B(14,4,21,AIR)
B(15,4,21,AIR)
B(1,5,21,AIR)
B(2,5,21,AIR)
B(3,5,21,AIR)
B(4,5,21,AIR)
B(5,5,21,AIR)
B(6,5,21,AIR)
B(7,5,21,AIR)
B(8,5,21,AIR)
B(9,5,21,AIR)
B(10,5,21,AIR)
B(11,5,21,AIR)
B(12,5,21,AIR)
B(13,5,21,AIR)
B(14,5,21,AIR)
B(15,5,21,AIR)
B(1,6,21,AIR)
B(2,6,21,AIR)
B(3,6,21,AIR)
B(4,6,21,AIR)
B(5,6,21,AIR)
B(6,6,21,AIR)
B(7,6,21,AIR)
B(8,6,21,AIR)
B(9,6,21,AIR)
B(10,6,21,AIR)
B(11,6,21,AIR)
B(12,6,21,AIR)
B(13,6,21,AIR)
B(14,6,21,AIR)
B(15,6,21,AIR)
B(2,7,21,AIR)
B(3,7,21,AIR)
B(4,7,21,AIR)
B(5,7,21,AIR)
B(6,7,21,AIR)
B(10,7,21,AIR)
B(11,7,21,AIR)
B(12,7,21,AIR)
B(13,7,21,AIR)
B(14,7,21,AIR)
B(3,8,21,AIR)
B(4,8,21,AIR)
B(5,8,21,AIR)
B(11,8,21,AIR)
B(12,8,21,AIR)
B(13,8,21,AIR)
B(1,9,21,AIR)
B(2,9,21,AIR)
B(3,9,21,AIR)
B(4,9,21,AIR)
B(5,9,21,AIR)
B(6,9,21,AIR)
B(7,9,21,AIR)
B(8,9,21,AIR)
B(9,9,21,AIR)
B(10,9,21,AIR)
B(11,9,21,AIR)
B(12,9,21,AIR)
B(13,9,21,AIR)
B(14,9,21,AIR)
B(15,9,21,AIR)
B(1,10,21,AIR)
B(2,10,21,AIR)
B(3,10,21,AIR)
B(4,10,21,AIR)
B(5,10,21,AIR)
B(6,10,21,AIR)
B(7,10,21,AIR)
B(8,10,21,AIR)
B(9,10,21,AIR)
B(10,10,21,AIR)
B(11,10,21,AIR)
B(12,10,21,AIR)
B(13,10,21,AIR)
B(14,10,21,AIR)
B(15,10,21,AIR)
B(1,11,21,AIR)
B(2,11,21,AIR)
B(3,11,21,AIR)
B(4,11,21,AIR)
B(5,11,21,AIR)
B(6,11,21,AIR)
B(7,11,21,AIR)
B(8,11,21,AIR)
B(9,11,21,AIR)
B(10,11,21,AIR)
B(11,11,21,AIR)
B(12,11,21,AIR)
B(13,11,21,AIR)
B(14,11,21,AIR)
B(15,11,21,AIR)
B(1,12,21,AIR)
B(2,12,21,AIR)
B(3,12,21,AIR)
B(4,12,21,AIR)
B(5,12,21,AIR)
B(6,12,21,AIR)
B(7,12,21,AIR)
B(8,12,21,AIR)
B(9,12,21,AIR)
B(10,12,21,AIR)
B(11,12,21,AIR)
B(12,12,21,AIR)
B(13,12,21,AIR)
B(14,12,21,AIR)
B(15,12,21,AIR)
B(1,13,21,AIR)
B(2,13,21,AIR)
B(3,13,21,AIR)
B(4,13,21,AIR)
B(5,13,21,AIR)
B(6,13,21,AIR)
B(7,13,21,AIR)
B(8,13,21,AIR)
B(9,13,21,AIR)
B(10,13,21,AIR)
B(11,13,21,AIR)
B(12,13,21,AIR)
B(13,13,21,AIR)
B(14,13,21,AIR)
B(15,13,21,AIR)
B(1,14,21,AIR)
B(2,14,21,AIR)
B(3,14,21,AIR)
B(4,14,21,AIR)
B(5,14,21,AIR)
B(6,14,21,AIR)
B(7,14,21,AIR)
B(8,14,21,AIR)
B(9,14,21,AIR)
B(10,14,21,AIR)
B(11,14,21,AIR)
B(12,14,21,AIR)
B(13,14,21,AIR)
B(14,14,21,AIR)
B(15,14,21,AIR)
B(2,15,21,AIR)
B(3,15,21,AIR)
B(4,15,21,AIR)
B(5,15,21,AIR)
B(6,15,21,AIR)
B(10,15,21,AIR)
B(11,15,21,AIR)
B(12,15,21,AIR)
B(13,15,21,AIR)
B(14,15,21,AIR)
B(3,16,21,AIR)
B(4,16,21,AIR)
B(5,16,21,AIR)
B(11,16,21,AIR)
B(12,16,21,AIR)
B(13,16,21,AIR)
B(1,1,22,AIR)
B(2,1,22,AIR)
B(3,1,22,AIR)
B(4,1,22,AIR)
B(5,1,22,AIR)
B(6,1,22,AIR)
B(7,1,22,AIR)
B(8,1,22,AIR)
B(9,1,22,AIR)
B(10,1,22,AIR)
B(11,1,22,AIR)
B(12,1,22,AIR)
B(13,1,22,AIR)
B(14,1,22,AIR)
B(15,1,22,AIR)
B(1,2,22,AIR)
B(2,2,22,AIR)
B(3,2,22,AIR)
B(4,2,22,AIR)
B(5,2,22,AIR)
B(6,2,22,AIR)
B(7,2,22,AIR)
B(8,2,22,AIR)
B(9,2,22,AIR)
B(10,2,22,AIR)
B(11,2,22,AIR)
B(12,2,22,AIR)
B(13,2,22,AIR)
B(14,2,22,AIR)
B(15,2,22,AIR)
B(1,3,22,AIR)
B(2,3,22,AIR)
B(3,3,22,AIR)
B(4,3,22,AIR)
B(5,3,22,AIR)
B(6,3,22,AIR)
B(7,3,22,AIR)
B(8,3,22,AIR)
B(9,3,22,AIR)
B(10,3,22,AIR)
B(11,3,22,AIR)
B(12,3,22,AIR)
B(13,3,22,AIR)
B(14,3,22,AIR)
B(15,3,22,AIR)
B(1,4,22,AIR)
B(2,4,22,AIR)
B(3,4,22,AIR)
B(4,4,22,AIR)
B(5,4,22,AIR)
B(6,4,22,AIR)
B(7,4,22,AIR)
B(8,4,22,AIR)
B(9,4,22,AIR)
B(10,4,22,AIR)
B(11,4,22,AIR)
B(12,4,22,AIR)
B(13,4,22,AIR)
B(14,4,22,AIR)
B(15,4,22,AIR)
B(1,5,22,AIR)
B(2,5,22,AIR)
B(3,5,22,AIR)
B(4,5,22,AIR)
B(5,5,22,AIR)
B(6,5,22,AIR)
B(7,5,22,AIR)
B(8,5,22,AIR)
B(9,5,22,AIR)
B(10,5,22,AIR)
B(11,5,22,AIR)
B(12,5,22,AIR)
B(13,5,22,AIR)
B(14,5,22,AIR)
B(15,5,22,AIR)
B(1,6,22,STONE_BRICK_STAIRS:6)
B(2,6,22,AIR)
B(3,6,22,AIR)
B(4,6,22,AIR)
B(5,6,22,AIR)
B(6,6,22,AIR)
B(7,6,22,STONE_BRICK_STAIRS:6)
B(8,6,22,STONE_BRICK_STAIRS:6)
B(9,6,22,STONE_BRICK_STAIRS:6)
B(10,6,22,AIR)
B(11,6,22,AIR)
B(12,6,22,AIR)
B(13,6,22,AIR)
B(14,6,22,AIR)
B(15,6,22,STONE_BRICK_STAIRS:6)
B(2,7,22,AIR)
B(3,7,22,AIR)
B(4,7,22,AIR)
B(5,7,22,AIR)
B(6,7,22,AIR)
B(10,7,22,AIR)
B(11,7,22,AIR)
B(12,7,22,AIR)
B(13,7,22,AIR)
B(14,7,22,AIR)
B(1,9,22,AIR)
B(2,9,22,AIR)
B(3,9,22,AIR)
B(4,9,22,AIR)
B(5,9,22,AIR)
B(6,9,22,AIR)
B(7,9,22,AIR)
B(8,9,22,AIR)
B(9,9,22,AIR)
B(10,9,22,AIR)
B(11,9,22,AIR)
B(12,9,22,AIR)
B(13,9,22,AIR)
B(14,9,22,AIR)
B(15,9,22,AIR)
B(1,10,22,AIR)
B(2,10,22,AIR)
B(3,10,22,AIR)
B(4,10,22,AIR)
B(5,10,22,AIR)
B(6,10,22,AIR)
B(7,10,22,AIR)
B(8,10,22,AIR)
B(9,10,22,AIR)
B(10,10,22,AIR)
B(11,10,22,AIR)
B(12,10,22,AIR)
B(13,10,22,AIR)
B(14,10,22,AIR)
B(15,10,22,AIR)
B(1,11,22,AIR)
B(2,11,22,AIR)
B(3,11,22,AIR)
B(4,11,22,AIR)
B(5,11,22,AIR)
B(6,11,22,AIR)
B(7,11,22,AIR)
B(8,11,22,AIR)
B(9,11,22,AIR)
B(10,11,22,AIR)
B(11,11,22,AIR)
B(12,11,22,AIR)
B(13,11,22,AIR)
B(14,11,22,AIR)
B(15,11,22,AIR)
B(1,12,22,AIR)
B(2,12,22,AIR)
B(3,12,22,AIR)
B(4,12,22,AIR)
B(5,12,22,AIR)
B(6,12,22,AIR)
B(7,12,22,AIR)
B(8,12,22,AIR)
B(9,12,22,AIR)
B(10,12,22,AIR)
B(11,12,22,AIR)
B(12,12,22,AIR)
B(13,12,22,AIR)
B(14,12,22,AIR)
B(15,12,22,AIR)
B(1,13,22,AIR)
B(2,13,22,AIR)
B(3,13,22,AIR)
B(4,13,22,AIR)
B(5,13,22,AIR)
B(6,13,22,AIR)
B(7,13,22,AIR)
B(8,13,22,AIR)
B(9,13,22,AIR)
B(10,13,22,AIR)
B(11,13,22,AIR)
B(12,13,22,AIR)
B(13,13,22,AIR)
B(14,13,22,AIR)
B(15,13,22,AIR)
B(1,14,22,STONE_BRICK_STAIRS:6)
B(2,14,22,AIR)
B(3,14,22,AIR)
B(4,14,22,AIR)
B(5,14,22,AIR)
B(6,14,22,AIR)
B(7,14,22,STONE_BRICK_STAIRS:6)
B(8,14,22,STONE_BRICK_STAIRS:6)
B(9,14,22,STONE_BRICK_STAIRS:6)
B(10,14,22,AIR)
B(11,14,22,AIR)
B(12,14,22,AIR)
B(13,14,22,AIR)
B(14,14,22,AIR)
B(15,14,22,STONE_BRICK_STAIRS:6)
B(2,15,22,AIR)
B(3,15,22,AIR)
B(4,15,22,AIR)
B(5,15,22,AIR)
B(6,15,22,AIR)
B(10,15,22,AIR)
B(11,15,22,AIR)
B(12,15,22,AIR)
B(13,15,22,AIR)
B(14,15,22,AIR)
B(2,1,23,AIR)
B(3,1,23,AIR)
B(5,1,23,AIR)
B(6,1,23,AIR)
B(10,1,23,AIR)
B(11,1,23,AIR)
B(13,1,23,AIR)
B(14,1,23,AIR)
B(2,2,23,AIR)
B(3,2,23,AIR)
B(4,2,23,AIR)
B(5,2,23,AIR)
B(6,2,23,AIR)
B(10,2,23,AIR)
B(11,2,23,AIR)
B(12,2,23,AIR)
B(13,2,23,AIR)
B(14,2,23,AIR)
B(2,3,23,AIR)
B(3,3,23,AIR)
B(4,3,23,AIR)
B(5,3,23,AIR)
B(6,3,23,AIR)
B(10,3,23,AIR)
B(11,3,23,AIR)
B(12,3,23,AIR)
B(13,3,23,AIR)
B(14,3,23,AIR)
B(2,4,23,AIR)
B(3,4,23,AIR)
B(4,4,23,AIR)
B(5,4,23,AIR)
B(6,4,23,AIR)
B(10,4,23,AIR)
B(11,4,23,AIR)
B(12,4,23,AIR)
B(13,4,23,AIR)
B(14,4,23,AIR)
B(2,5,23,AIR)
B(3,5,23,AIR)
B(4,5,23,AIR)
B(5,5,23,AIR)
B(6,5,23,AIR)
B(10,5,23,AIR)
B(11,5,23,AIR)
B(12,5,23,AIR)
B(13,5,23,AIR)
B(14,5,23,AIR)
B(2,6,23,STONE_BRICK_STAIRS:5)
B(3,6,23,AIR)
B(4,6,23,AIR)
B(5,6,23,AIR)
B(6,6,23,STONE_BRICK_STAIRS:4)
B(10,6,23,STONE_BRICK_STAIRS:5)
B(11,6,23,AIR)
B(12,6,23,AIR)
B(13,6,23,AIR)
B(14,6,23,STONE_BRICK_STAIRS:4)
B(2,9,23,AIR)
B(3,9,23,AIR)
B(5,9,23,AIR)
B(6,9,23,AIR)
B(10,9,23,AIR)
B(11,9,23,AIR)
B(13,9,23,AIR)
B(14,9,23,AIR)
B(2,10,23,AIR)
B(3,10,23,AIR)
B(4,10,23,AIR)
B(5,10,23,AIR)
B(6,10,23,AIR)
B(10,10,23,AIR)
B(11,10,23,AIR)
B(12,10,23,AIR)
B(13,10,23,AIR)
B(14,10,23,AIR)
B(2,11,23,AIR)
B(3,11,23,AIR)
B(4,11,23,AIR)
B(5,11,23,AIR)
B(6,11,23,AIR)
B(10,11,23,AIR)
B(11,11,23,AIR)
B(12,11,23,AIR)
B(13,11,23,AIR)
B(14,11,23,AIR)
B(2,12,23,AIR)
B(3,12,23,AIR)
B(4,12,23,AIR)
B(5,12,23,AIR)
B(6,12,23,AIR)
B(10,12,23,AIR)
B(11,12,23,AIR)
B(12,12,23,AIR)
B(13,12,23,AIR)
B(14,12,23,AIR)
B(2,13,23,AIR)
B(3,13,23,AIR)
B(4,13,23,AIR)
B(5,13,23,AIR)
B(6,13,23,AIR)
B(10,13,23,AIR)
B(11,13,23,AIR)
B(12,13,23,AIR)
B(13,13,23,AIR)
B(14,13,23,AIR)
B(2,14,23,STONE_BRICK_STAIRS:5)
B(3,14,23,AIR)
B(4,14,23,AIR)
B(5,14,23,AIR)
B(6,14,23,STONE_BRICK_STAIRS:4)
B(10,14,23,STONE_BRICK_STAIRS:5)
B(11,14,23,AIR)
B(12,14,23,AIR)
B(13,14,23,AIR)
B(14,14,23,STONE_BRICK_STAIRS:4)

B(1,6,4,SKULL:1,../../nbt/Skull/Skeleton4.nbt)
B(15,6,4,SKULL:1,../../nbt/Skull/Skeleton12.nbt)
B(1,10,20,SKULL:1,../../nbt/Skull/Skeleton4.nbt)
B(15,10,20,SKULL:1,../../nbt/Skull/Skeleton12.nbt)

RB(8,1,20,MOB_SPAWNER,../../nbt/Spawner/Zombie.nbt,50,MOB_SPAWNER,../../nbt/Spawner/Skeleton.nbt,50,MOB_SPAWNER,../../nbt/Spawner/Spider.nbt,100)
RB(8,9,20,MOB_SPAWNER,../../nbt/Spawner/Zombie.nbt,50,MOB_SPAWNER,../../nbt/Spawner/Skeleton.nbt,50,MOB_SPAWNER,../../nbt/Spawner/Spider.nbt,100)

B(4,5,1,CHEST:3,../../nbt/VanillaLoot/simple_dungeon.nbt)
B(12,5,1,CHEST:3,../../nbt/VanillaLoot/simple_dungeon.nbt)
B(4,1,23,CHEST:2,../../nbt/VanillaLoot/simple_dungeon.nbt)
B(12,1,23,CHEST:2,../../nbt/VanillaLoot/simple_dungeon.nbt)
B(4,9,23,CHEST:2,../../nbt/VanillaLoot/simple_dungeon.nbt)
B(12,9,23,CHEST:2,../../nbt/VanillaLoot/simple_dungeon.nbt)

# Size (X*Y*Z): 17*17*25

#######################################################################
# +-----------------------------------------------------------------+ #
# |                            BO3 checks                           | #
# +-----------------------------------------------------------------+ #
#######################################################################

# Require a condition at a certain location in order for the BO3 to be spawned.
# BlockCheck(x,y,z,BlockName[,BlockName[,...]]) - one of the blocks must be at the location
# BlockCheckNot(x,y,z,BlockName[,BlockName[,...]]) - all the blocks must not be at the location
# LightCheck(x,y,z,minLightLevel,maxLightLevel) - light must be between min and max (inclusive)

# You can use "Solid" as a BlockName for matching all solid blocks or "All" to match all blocks that aren't air.

# Examples:
#   BlockCheck(0,-1,0,GRASS,DIRT)  Require grass or dirt just below the object
#   BlockCheck(0,-1,0,Solid)       Require any solid block just below the object
#   BlockCheck(0,-1,0,WOOL)        Require any type of wool just below the object
#   BlockCheck(0,-1,0,WOOL:0)      Require white wool just below the object
#   BlockCheckNot(0,0,0,WOOL:0)   Require that there is no white wool below the object
#   LightCheck(0,0,0,0,1)          Require almost complete darkness just below the object

# Ensure the ceiling is sufficiently covered in solid blocks.
BlockCheck(0,17,0,Solid)
BlockCheck(0,17,25,Solid)
BlockCheck(17,17,0,Solid)
BlockCheck(17,17,25,Solid)

#######################################################################
# +-----------------------------------------------------------------+ #
# |                             Branches                            | #
# +-----------------------------------------------------------------+ #
#######################################################################

# Branches are objects that will spawn when this object spawns when it is used in
# the CustomStructure resource. Branches can also have branches, making complex
# structures possible. See the wiki for more details.

# Regular Branches spawn each branch with an independent chance of spawning.
# Branch(x,y,z,branchName,rotation,chance[,anotherBranchName,rotation,chance[,...]][IndividualChance])
# branchName - name of the object to spawn.
# rotation - NORTH, SOUTH, EAST or WEST.
# IndividualChance - The chance each branch has to spawn, assumed to be 100 when left blank

# Weighted Branches spawn branches with a dependent chance of spawning.
# WBR(x,y,z,branchName,rotation,chance[,anotherBranchName,rotation,chance[,...]][MaxChanceOutOf])
# MaxChanceOutOf - The chance all branches have to spawn out of, assumed to be 100 when left blank
