
#######################################################################
# +-----------------------------------------------------------------+ #
# |                            BO3 object                           | #
# +-----------------------------------------------------------------+ #
#######################################################################

# This is the config file of a custom object.
# If you add this object correctly to your BiomeConfigs, it will spawn in the world.

# This is the creator of this BO3 object
# See: https://imgur.com/a/JanPA
Author: Arcensoth, designed by McNoodlor

# A short description of this BO3 object
Description: No description given

# The BO3 version, don't change this! It can be used by external applications to do a version check.
Version: 3

# The settings mode, WriteAll, WriteWithoutComments or WriteDisable. See WorldConfig.
SettingsMode: WriteDisable


#######################################################################
# +-----------------------------------------------------------------+ #
# |                          Main settings                          | #
# +-----------------------------------------------------------------+ #
#######################################################################

# This needs to be set to true to spawn the object in the Tree and Sapling resources.
Tree: false

# The frequency of the BO3 from 1 to 200. Tries this many times to spawn this BO3 when using the CustomObject(...) resource.
# Ignored by Tree(..), Sapling(..) and CustomStructure(..)
Frequency: 1

# The rarity of the BO3 from 0 to 100. Each spawn attempt has rarity% chance to succeed when using the CustomObject(...) resource.
# Ignored by Tree(..), Sapling(..) and CustomStructure(..)
Rarity: 1.0

# If you set this to true, the BO3 will be placed with a random rotation.
RotateRandomly: false

# The spawn height of the BO3 - randomY, highestBlock or highestSolidBlock.
SpawnHeight: randomY

# The height limits for the BO3.
MinHeight: 0

MaxHeight: 255

# Objects can have other objects attacthed to it: branches. Branches can also
# have branches attached to it, which can also have branches, etc. This is the
# maximum branch depth for this objects.
MaxBranchDepth: 10

# When spawned with the UseWorld keyword, this BO3 should NOT spawn in the following biomes.
# If you writer.write the BO3 name directly in the BiomeConfigs, this will be ignored.
ExcludedBiomes: All


#######################################################################
# +-----------------------------------------------------------------+ #
# |                      Source block settings                      | #
# +-----------------------------------------------------------------+ #
#######################################################################

# The B(s) the BO3 should spawn in.
SourceBlocks: STONE,STONE:1,STONE:3,STONE:5,COBBLESTONE,MOSSY_COBBLESTONE,SANDSTONE,HARD_CLAY,STAINED_CLAY,PRISMARINE,DIRT,DIRT:1,GRASS,SAND,GRAVEL,CLAY,OBSIDIAN,COAL_ORE,IRON_ORE,GOLD_ORE,REDSTONE_ORE,DIAMOND_ORE,LAPIS_ORE,EMERALD_ORE,STATIONARY_WATER,STATIONARY_LAVA

# The maximum percentage of the BO3 that can be outside the SourceBlock.
# The BO3 won't be placed on a location with more blocks outside the SourceBlock than this percentage.
MaxPercentageOutsideSourceBlock: 45

# What to do when a block is about to be placed outside the SourceBlock? (dontPlace, placeAnyway)
OutsideSourceBlock: dontPlace


#######################################################################
# +-----------------------------------------------------------------+ #
# |                              Blocks                             | #
# +-----------------------------------------------------------------+ #
#######################################################################

# All the blocks used in the BO3 are listed here. Possible blocks:
# B(x,y,z,id[.data][,nbtfile.nbt)
# RB(x,y,z,id[:data][,nbtfile.nbt],chance[,id[:data][,nbtfile.nbt],chance[,...]])
# So RB(0,0,0,CHEST,chest.nbt,50,CHEST,anotherchest.nbt,100) will spawn a chest at
# the BO3 origin, and give it a 50% chance to have the contents of chest.nbt, or, if that
# fails, a 100% percent chance to have the contents of anotherchest.nbt.
B(8,4,0,STONEBRICK:1)
B(9,4,0,STONEBRICK:2)
B(10,4,0,STONEBRICK)
B(11,4,0,STONEBRICK:1)
B(12,4,0,STONEBRICK:2)
B(13,4,0,STONEBRICK:1)
B(14,4,0,STONEBRICK:2)
B(15,4,0,STONEBRICK:2)
B(16,4,0,STONEBRICK:1)
B(8,5,0,STONEBRICK:1)
B(9,5,0,MOSSY_COBBLESTONE)
B(10,5,0,STONE)
B(11,5,0,MOSSY_COBBLESTONE)
B(12,5,0,MOSSY_COBBLESTONE)
B(13,5,0,MOSSY_COBBLESTONE)
B(14,5,0,STONE)
B(15,5,0,EMERALD_ORE)
B(16,5,0,STONEBRICK:2)
B(8,6,0,STONEBRICK:2)
B(9,6,0,STONE)
B(10,6,0,MOSSY_COBBLESTONE)
B(11,6,0,MOSSY_COBBLESTONE)
B(12,6,0,STONE)
B(13,6,0,MOSSY_COBBLESTONE)
B(14,6,0,MOSSY_COBBLESTONE)
B(15,6,0,STONE)
B(16,6,0,STONEBRICK:1)
B(8,7,0,STONEBRICK:2)
B(9,7,0,EMERALD_ORE)
B(10,7,0,STONE)
B(11,7,0,MOSSY_COBBLESTONE)
B(12,7,0,MOSSY_COBBLESTONE)
B(13,7,0,STONE)
B(14,7,0,MOSSY_COBBLESTONE)
B(15,7,0,MOSSY_COBBLESTONE)
B(16,7,0,STONEBRICK)
B(8,8,0,STONEBRICK)
B(9,8,0,EMERALD_ORE)
B(10,8,0,STONE)
B(11,8,0,STONE)
B(12,8,0,MOSSY_COBBLESTONE)
B(13,8,0,EMERALD_ORE)
B(14,8,0,STONE)
B(15,8,0,STONE)
B(16,8,0,STONEBRICK:2)
B(8,9,0,STONEBRICK:2)
B(9,9,0,EMERALD_ORE)
B(10,9,0,EMERALD_ORE)
B(11,9,0,MOSSY_COBBLESTONE)
B(12,9,0,EMERALD_ORE)
B(13,9,0,EMERALD_ORE)
B(14,9,0,STONE)
B(15,9,0,EMERALD_ORE)
B(16,9,0,STONEBRICK:1)
B(8,10,0,STONEBRICK:1)
B(9,10,0,STONE)
B(10,10,0,MOSSY_COBBLESTONE)
B(11,10,0,STONE)
B(12,10,0,MOSSY_COBBLESTONE)
B(13,10,0,STONE)
B(14,10,0,EMERALD_ORE)
B(15,10,0,EMERALD_ORE)
B(16,10,0,STONEBRICK:2)
B(8,11,0,STONEBRICK)
B(9,11,0,MOSSY_COBBLESTONE)
B(10,11,0,STONE)
B(11,11,0,MOSSY_COBBLESTONE)
B(12,11,0,STONE)
B(13,11,0,STONE)
B(14,11,0,STONE)
B(15,11,0,MOSSY_COBBLESTONE)
B(16,11,0,STONEBRICK:1)
B(8,12,0,STONEBRICK)
B(9,12,0,STONEBRICK:1)
B(10,12,0,STONEBRICK:1)
B(11,12,0,STONEBRICK:1)
B(12,12,0,STONEBRICK:2)
B(13,12,0,STONEBRICK:2)
B(14,12,0,STONEBRICK:1)
B(15,12,0,STONEBRICK:1)
B(16,12,0,STONEBRICK:2)
B(8,4,1,STONEBRICK:2)
B(9,4,1,STONEBRICK:2)
B(10,4,1,STONEBRICK:2)
B(11,4,1,STONEBRICK)
B(12,4,1,STONEBRICK)
B(13,4,1,STONEBRICK:2)
B(14,4,1,STONEBRICK)
B(15,4,1,STONEBRICK)
B(16,4,1,STONEBRICK:2)
B(8,5,1,STONE)
B(9,5,1,STONE)
B(15,5,1,STONE)
B(16,5,1,STONE)
B(8,6,1,MOSSY_COBBLESTONE)
B(9,6,1,MOSSY_COBBLESTONE)
B(15,6,1,MOSSY_COBBLESTONE)
B(16,6,1,STONE)
B(8,7,1,MOSSY_COBBLESTONE)
B(9,7,1,MOSSY_COBBLESTONE)
B(15,7,1,STONE)
B(16,7,1,STONE)
B(8,8,1,STONE)
B(9,8,1,STONEBRICK:3)
B(15,8,1,STONEBRICK:3)
B(16,8,1,STONE)
B(8,9,1,STONE)
B(9,9,1,STONEBRICK:2)
B(15,9,1,STONEBRICK:2)
B(16,9,1,MOSSY_COBBLESTONE)
B(8,10,1,MOSSY_COBBLESTONE)
B(9,10,1,STONEBRICK)
B(15,10,1,STONEBRICK:2)
B(16,10,1,MOSSY_COBBLESTONE)
B(8,11,1,EMERALD_ORE)
B(9,11,1,STONEBRICK)
B(10,11,1,STONEBRICK:1)
B(11,11,1,STONEBRICK)
B(12,11,1,STONEBRICK:1)
B(13,11,1,STONEBRICK:2)
B(14,11,1,STONEBRICK:2)
B(15,11,1,STONEBRICK)
B(16,11,1,MOSSY_COBBLESTONE)
B(8,12,1,STONEBRICK:1)
B(9,12,1,STONE)
B(10,12,1,MOSSY_COBBLESTONE)
B(11,12,1,MOSSY_COBBLESTONE)
B(12,12,1,STONE)
B(13,12,1,STONE)
B(14,12,1,STONE)
B(15,12,1,MOSSY_COBBLESTONE)
B(16,12,1,STONEBRICK)
B(8,4,2,STONEBRICK:1)
B(9,4,2,STONEBRICK:2)
B(10,4,2,STONEBRICK:1)
B(11,4,2,STONEBRICK)
B(12,4,2,STONEBRICK:2)
B(13,4,2,STONEBRICK:1)
B(14,4,2,STONEBRICK:2)
B(15,4,2,STONEBRICK:1)
B(16,4,2,STONEBRICK:1)
B(8,5,2,STONE)
B(16,5,2,MOSSY_COBBLESTONE)
B(8,6,2,MOSSY_COBBLESTONE)
B(16,6,2,STONE)
B(8,7,2,EMERALD_ORE)
B(16,7,2,STONE)
B(8,8,2,MOSSY_COBBLESTONE)
B(16,8,2,MOSSY_COBBLESTONE)
B(8,9,2,MOSSY_COBBLESTONE)
B(16,9,2,STONE)
B(8,10,2,EMERALD_ORE)
B(16,10,2,MOSSY_COBBLESTONE)
B(8,11,2,MOSSY_COBBLESTONE)
B(9,11,2,STONEBRICK:2)
B(15,11,2,STONEBRICK:1)
B(16,11,2,STONE)
B(8,12,2,STONEBRICK)
B(9,12,2,STONE)
B(10,12,2,STONEBRICK:2)
B(11,12,2,STONEBRICK:1)
B(12,12,2,STONEBRICK:2)
B(13,12,2,STONEBRICK:2)
B(14,12,2,STONEBRICK:1)
B(15,12,2,EMERALD_ORE)
B(16,12,2,STONEBRICK)
B(3,2,3,STONEBRICK:2)
B(4,2,3,STONEBRICK)
B(5,2,3,STONEBRICK:2)
B(3,3,3,STONEBRICK)
B(4,3,3,STONEBRICK:1)
B(5,3,3,STONEBRICK:1)
B(6,3,3,STONEBRICK)
B(7,3,3,STONEBRICK:1)
B(3,4,3,STONEBRICK:2)
B(4,4,3,STONEBRICK:2)
B(5,4,3,STONEBRICK)
B(6,4,3,STONEBRICK:2)
B(7,4,3,STONEBRICK:1)
B(8,4,3,STONEBRICK:1)
B(9,4,3,STONEBRICK:2)
B(10,4,3,STONEBRICK:2)
B(11,4,3,DIRT:1)
B(12,4,3,GRASS)
B(13,4,3,GRASS)
B(14,4,3,STONEBRICK:1)
B(15,4,3,STONEBRICK:2)
B(16,4,3,STONEBRICK:2)
B(17,4,3,STONEBRICK:2)
B(3,5,3,STONEBRICK:1)
B(4,5,3,STONEBRICK:2)
B(5,5,3,STONEBRICK:1)
B(6,5,3,STONEBRICK:1)
B(7,5,3,STONEBRICK:2)
B(8,5,3,STONEBRICK:1)
B(16,5,3,STONEBRICK)
B(17,5,3,STONEBRICK:2)
B(18,5,3,STONEBRICK:2)
B(19,5,3,STONEBRICK:2)
B(3,6,3,STONEBRICK)
B(4,6,3,STONEBRICK)
B(5,6,3,STONEBRICK)
B(6,6,3,STONEBRICK:2)
B(7,6,3,STONEBRICK)
B(8,6,3,STONEBRICK:1)
B(16,6,3,STONEBRICK:1)
B(17,6,3,STONEBRICK:2)
B(18,6,3,STONEBRICK)
B(19,6,3,STONEBRICK)
B(20,6,3,STONEBRICK:2)
B(21,6,3,STONEBRICK:1)
B(5,7,3,STONEBRICK:2)
B(6,7,3,STONEBRICK:1)
B(7,7,3,STONEBRICK:1)
B(8,7,3,STONEBRICK)
B(16,7,3,STONEBRICK:1)
B(17,7,3,STONEBRICK)
B(18,7,3,STONEBRICK:2)
B(19,7,3,STONEBRICK:2)
B(20,7,3,STONEBRICK:2)
B(21,7,3,STONEBRICK:2)
B(7,8,3,STONEBRICK:2)
B(8,8,3,STONEBRICK:3)
B(16,8,3,STONEBRICK:3)
B(17,8,3,STONEBRICK)
B(18,8,3,STONEBRICK)
B(19,8,3,STONEBRICK)
B(20,8,3,STONEBRICK:1)
B(21,8,3,STONEBRICK)
B(8,9,3,EMERALD_ORE)
B(16,9,3,EMERALD_ORE)
B(17,9,3,STONEBRICK)
B(18,9,3,STONEBRICK)
B(19,9,3,STONEBRICK:2)
B(20,9,3,STONEBRICK)
B(21,9,3,STONEBRICK:1)
B(8,10,3,EMERALD_ORE)
B(16,10,3,STONE)
B(19,10,3,STONEBRICK)
B(20,10,3,STONEBRICK)
B(21,10,3,STONEBRICK:2)
B(8,11,3,STONE)
B(9,11,3,STONEBRICK:1)
B(15,11,3,STONEBRICK)
B(16,11,3,STONE)
B(8,12,3,STONEBRICK)
B(9,12,3,MOSSY_COBBLESTONE)
B(10,12,3,STONEBRICK:2)
B(14,12,3,STONEBRICK)
B(15,12,3,MOSSY_COBBLESTONE)
B(16,12,3,STONEBRICK)
B(3,2,4,STONEBRICK:2)
B(4,2,4,STONEBRICK:2)
B(5,2,4,STONEBRICK)
B(3,3,4,STONEBRICK)
B(6,3,4,STONEBRICK:1)
B(7,3,4,STONEBRICK:1)
B(3,4,4,STONEBRICK)
B(8,4,4,STONEBRICK:2)
B(9,4,4,STONEBRICK:1)
B(10,4,4,STONEBRICK:1)
B(11,4,4,DIRT:1)
B(12,4,4,GRASS)
B(13,4,4,DIRT:1)
B(14,4,4,STONEBRICK:1)
B(15,4,4,STONEBRICK:1)
B(16,4,4,STONEBRICK)
B(17,4,4,STONEBRICK:2)
B(3,5,4,STONEBRICK:1)
B(18,5,4,STONEBRICK:2)
B(19,5,4,STONEBRICK:1)
B(3,6,4,STONEBRICK:2)
B(4,6,4,STONEBRICK)
B(20,6,4,STONEBRICK)
B(21,6,4,STONEBRICK:2)
B(5,7,4,STONEBRICK:1)
B(6,7,4,STONEBRICK)
B(21,7,4,STONEBRICK)
B(7,8,4,STONEBRICK)
B(8,8,4,STONEBRICK:3)
B(16,8,4,STONEBRICK:3)
B(21,8,4,STONEBRICK)
B(8,9,4,MOSSY_COBBLESTONE)
B(16,9,4,EMERALD_ORE)
B(17,9,4,STONEBRICK)
B(18,9,4,STONEBRICK:1)
B(21,9,4,STONEBRICK:2)
B(8,10,4,MOSSY_COBBLESTONE)
B(16,10,4,STONE)
B(19,10,4,STONEBRICK)
B(20,10,4,STONEBRICK:2)
B(21,10,4,STONEBRICK:2)
B(8,11,4,STONE)
B(9,11,4,STONEBRICK)
B(15,11,4,STONEBRICK:1)
B(16,11,4,MOSSY_COBBLESTONE)
B(8,12,4,STONEBRICK)
B(9,12,4,STONE)
B(10,12,4,STONEBRICK:1)
B(14,12,4,STONEBRICK:1)
B(15,12,4,MOSSY_COBBLESTONE)
B(16,12,4,STONEBRICK:2)
B(3,1,5,STONEBRICK)
B(4,1,5,STONEBRICK)
B(5,1,5,STONEBRICK:1)
B(3,2,5,STONEBRICK)
B(5,2,5,STONEBRICK:1)
B(3,3,5,STONEBRICK:2)
B(5,3,5,STONEBRICK:2)
B(6,3,5,STONEBRICK:2)
B(7,3,5,STONEBRICK:2)
B(3,4,5,STONEBRICK:2)
B(5,4,5,STONEBRICK:2)
B(6,4,5,STONEBRICK:2)
B(7,4,5,STONEBRICK)
B(8,4,5,STONEBRICK)
B(9,4,5,STONEBRICK:2)
B(10,4,5,STONEBRICK)
B(11,4,5,DIRT:1)
B(12,4,5,GRASS)
B(13,4,5,DIRT:1)
B(14,4,5,STONEBRICK)
B(15,4,5,STONEBRICK)
B(16,4,5,STONEBRICK:1)
B(17,4,5,STONEBRICK:2)
B(3,5,5,STONEBRICK:2)
B(5,5,5,STONEBRICK:1)
B(6,5,5,STONEBRICK)
B(7,5,5,STONEBRICK:2)
B(8,5,5,STONEBRICK)
B(16,5,5,STONEBRICK:2)
B(17,5,5,STONEBRICK:2)
B(18,5,5,STONEBRICK)
B(19,5,5,STONEBRICK:2)
B(3,6,5,STONEBRICK:1)
B(4,6,5,STONEBRICK)
B(5,6,5,STONEBRICK:1)
B(6,6,5,STONEBRICK:2)
B(7,6,5,STONEBRICK)
B(8,6,5,STONEBRICK:2)
B(16,6,5,STONEBRICK:2)
B(17,6,5,STONEBRICK)
B(18,6,5,STONEBRICK)
B(19,6,5,STONEBRICK:2)
B(20,6,5,STONEBRICK:2)
B(21,6,5,STONEBRICK:1)
B(5,7,5,STONEBRICK:1)
B(6,7,5,STONEBRICK:1)
B(7,7,5,STONEBRICK)
B(8,7,5,STONEBRICK:1)
B(16,7,5,STONEBRICK:1)
B(17,7,5,STONEBRICK:2)
B(18,7,5,STONEBRICK)
B(19,7,5,STONEBRICK:1)
B(21,7,5,STONEBRICK)
B(7,8,5,STONEBRICK:2)
B(8,8,5,STONEBRICK:3)
B(16,8,5,STONEBRICK:3)
B(17,8,5,STONEBRICK:2)
B(18,8,5,STONEBRICK:2)
B(19,8,5,STONEBRICK)
B(21,8,5,STONEBRICK:2)
B(8,9,5,MOSSY_COBBLESTONE)
B(16,9,5,STONE)
B(17,9,5,STONEBRICK)
B(18,9,5,STONEBRICK:1)
B(19,9,5,STONEBRICK:1)
B(21,9,5,STONEBRICK)
B(8,10,5,STONE)
B(16,10,5,STONE)
B(19,10,5,STONEBRICK:1)
B(21,10,5,STONEBRICK:1)
B(8,11,5,STONE)
B(9,11,5,STONEBRICK)
B(15,11,5,STONEBRICK)
B(16,11,5,STONE)
B(19,11,5,STONEBRICK:2)
B(20,11,5,STONEBRICK:2)
B(21,11,5,STONEBRICK)
B(8,12,5,STONEBRICK)
B(9,12,5,MOSSY_COBBLESTONE)
B(10,12,5,STONEBRICK:2)
B(14,12,5,STONEBRICK)
B(15,12,5,EMERALD_ORE)
B(16,12,5,STONEBRICK)
B(3,1,6,STONEBRICK:2)
B(4,1,6,STONEBRICK:2)
B(5,1,6,STONEBRICK:2)
B(3,2,6,STONEBRICK:2)
B(5,2,6,STONEBRICK:1)
B(3,3,6,STONEBRICK:1)
B(5,3,6,STONEBRICK)
B(3,4,6,STONEBRICK:2)
B(5,4,6,STONEBRICK:2)
B(8,4,6,STONEBRICK:2)
B(9,4,6,STONEBRICK:1)
B(10,4,6,STONEBRICK:1)
B(11,4,6,STONEBRICK:2)
B(12,4,6,STONEBRICK:1)
B(13,4,6,STONEBRICK:1)
B(14,4,6,STONEBRICK:2)
B(15,4,6,STONEBRICK)
B(16,4,6,STONEBRICK:2)
B(3,5,6,STONEBRICK:1)
B(4,5,6,STONEBRICK)
B(5,5,6,STONEBRICK:1)
B(8,5,6,STONE)
B(16,5,6,STONE)
B(8,6,6,EMERALD_ORE)
B(16,6,6,STONE)
B(8,7,6,STONE)
B(16,7,6,MOSSY_COBBLESTONE)
B(19,7,6,STONEBRICK:1)
B(20,7,6,STONEBRICK)
B(21,7,6,STONEBRICK:1)
B(8,8,6,MOSSY_COBBLESTONE)
B(16,8,6,MOSSY_COBBLESTONE)
B(19,8,6,STONEBRICK:2)
B(21,8,6,STONEBRICK)
B(8,9,6,STONE)
B(16,9,6,MOSSY_COBBLESTONE)
B(19,9,6,STONEBRICK:1)
B(21,9,6,STONEBRICK:2)
B(8,10,6,STONE)
B(16,10,6,STONE)
B(19,10,6,STONEBRICK)
B(21,10,6,STONEBRICK:1)
B(8,11,6,EMERALD_ORE)
B(9,11,6,STONEBRICK)
B(15,11,6,STONEBRICK)
B(16,11,6,STONE)
B(19,11,6,STONEBRICK)
B(20,11,6,STONEBRICK:2)
B(21,11,6,STONEBRICK:1)
B(8,12,6,STONEBRICK:2)
B(9,12,6,MOSSY_COBBLESTONE)
B(10,12,6,STONEBRICK)
B(11,12,6,STONEBRICK:1)
B(12,12,6,STONEBRICK)
B(13,12,6,STONEBRICK:1)
B(14,12,6,STONEBRICK:2)
B(15,12,6,EMERALD_ORE)
B(16,12,6,STONEBRICK:1)
B(3,0,7,STONEBRICK)
B(4,0,7,STONEBRICK:1)
B(5,0,7,STONEBRICK:1)
B(3,1,7,STONEBRICK:2)
B(5,1,7,STONEBRICK:2)
B(3,2,7,STONEBRICK:2)
B(5,2,7,STONEBRICK:2)
B(3,3,7,STONEBRICK)
B(5,3,7,STONEBRICK:1)
B(3,4,7,STONEBRICK:1)
B(5,4,7,STONEBRICK)
B(8,4,7,STONEBRICK:2)
B(9,4,7,STONEBRICK:2)
B(10,4,7,STONEBRICK)
B(11,4,7,STONEBRICK:2)
B(12,4,7,STONEBRICK:1)
B(13,4,7,STONEBRICK:1)
B(14,4,7,STONEBRICK)
B(15,4,7,STONEBRICK:2)
B(16,4,7,STONEBRICK:1)
B(3,5,7,STONEBRICK:1)
B(4,5,7,STONEBRICK:1)
B(5,5,7,STONEBRICK)
B(8,5,7,MOSSY_COBBLESTONE)
B(9,5,7,STONE)
B(15,5,7,STONE)
B(16,5,7,STONE)
B(8,6,7,STONE)
B(9,6,7,STONE)
B(15,6,7,STONE)
B(16,6,7,STONE)
B(8,7,7,MOSSY_COBBLESTONE)
B(9,7,7,MOSSY_COBBLESTONE)
B(15,7,7,MOSSY_COBBLESTONE)
B(16,7,7,STONE)
B(19,7,7,STONEBRICK:1)
B(20,7,7,STONEBRICK:2)
B(21,7,7,STONEBRICK:2)
B(8,8,7,STONE)
B(9,8,7,STONEBRICK:3)
B(15,8,7,STONEBRICK:3)
B(16,8,7,STONE)
B(19,8,7,STONEBRICK)
B(21,8,7,STONEBRICK:1)
B(8,9,7,MOSSY_COBBLESTONE)
B(9,9,7,STONEBRICK)
B(15,9,7,STONEBRICK:1)
B(16,9,7,EMERALD_ORE)
B(19,9,7,STONEBRICK:1)
B(21,9,7,STONEBRICK:1)
B(8,10,7,STONE)
B(9,10,7,STONEBRICK)
B(15,10,7,STONEBRICK:2)
B(16,10,7,STONE)
B(19,10,7,STONEBRICK:2)
B(21,10,7,STONEBRICK:1)
B(8,11,7,MOSSY_COBBLESTONE)
B(9,11,7,STONEBRICK)
B(10,11,7,STONEBRICK)
B(11,11,7,STONEBRICK:1)
B(12,11,7,STONEBRICK:2)
B(13,11,7,STONEBRICK)
B(14,11,7,STONEBRICK:1)
B(15,11,7,STONEBRICK:2)
B(16,11,7,MOSSY_COBBLESTONE)
B(19,11,7,STONEBRICK)
B(21,11,7,STONEBRICK:1)
B(8,12,7,STONEBRICK:2)
B(9,12,7,STONE)
B(10,12,7,STONE)
B(11,12,7,STONE)
B(12,12,7,STONE)
B(13,12,7,MOSSY_COBBLESTONE)
B(14,12,7,EMERALD_ORE)
B(15,12,7,MOSSY_COBBLESTONE)
B(16,12,7,STONEBRICK:2)
B(19,12,7,STONEBRICK:2)
B(20,12,7,STONEBRICK)
B(21,12,7,STONEBRICK:1)
B(0,0,8,STONEBRICK:2)
B(1,0,8,STONEBRICK)
B(2,0,8,STONEBRICK:2)
B(3,0,8,STONEBRICK:2)
B(4,0,8,STONEBRICK:2)
B(5,0,8,STONEBRICK)
B(6,0,8,STONEBRICK)
B(7,0,8,STONEBRICK)
B(8,0,8,STONEBRICK:1)
B(9,0,8,STONEBRICK)
B(10,0,8,STONEBRICK:1)
B(11,0,8,STONEBRICK:1)
B(12,0,8,STONEBRICK:1)
B(13,0,8,STONEBRICK:2)
B(14,0,8,STONEBRICK:2)
B(15,0,8,STONEBRICK:1)
B(16,0,8,STONEBRICK)
B(17,0,8,STONEBRICK:2)
B(18,0,8,STONEBRICK:1)
B(19,0,8,STONEBRICK:2)
B(20,0,8,STONEBRICK:1)
B(21,0,8,STONEBRICK:1)
B(22,0,8,STONEBRICK)
B(23,0,8,STONEBRICK:1)
B(24,0,8,STONEBRICK)
B(0,1,8,STONEBRICK:1)
B(1,1,8,EMERALD_ORE)
B(2,1,8,EMERALD_ORE)
B(3,1,8,STONEBRICK:1)
B(5,1,8,STONEBRICK:1)
B(6,1,8,STONE)
B(7,1,8,STONE)
B(8,1,8,STONEBRICK:1)
B(9,1,8,STONE)
B(10,1,8,STONE)
B(11,1,8,STONE)
B(12,1,8,STONE)
B(13,1,8,STONE)
B(14,1,8,STONE)
B(15,1,8,MOSSY_COBBLESTONE)
B(16,1,8,STONEBRICK:2)
B(17,1,8,MOSSY_COBBLESTONE)
B(18,1,8,STONE)
B(19,1,8,STONE)
B(20,1,8,STONE)
B(21,1,8,STONE)
B(22,1,8,MOSSY_COBBLESTONE)
B(23,1,8,MOSSY_COBBLESTONE)
B(24,1,8,STONEBRICK:1)
B(0,2,8,STONEBRICK:2)
B(1,2,8,EMERALD_ORE)
B(2,2,8,MOSSY_COBBLESTONE)
B(3,2,8,STONEBRICK:2)
B(5,2,8,STONEBRICK)
B(6,2,8,EMERALD_ORE)
B(7,2,8,MOSSY_COBBLESTONE)
B(8,2,8,STONEBRICK)
B(9,2,8,MOSSY_COBBLESTONE)
B(10,2,8,MOSSY_COBBLESTONE)
B(11,2,8,MOSSY_COBBLESTONE)
B(12,2,8,STONE)
B(13,2,8,MOSSY_COBBLESTONE)
B(14,2,8,MOSSY_COBBLESTONE)
B(15,2,8,STONE)
B(16,2,8,STONEBRICK:1)
B(17,2,8,STONE)
B(18,2,8,STONE)
B(19,2,8,MOSSY_COBBLESTONE)
B(20,2,8,MOSSY_COBBLESTONE)
B(21,2,8,MOSSY_COBBLESTONE)
B(22,2,8,MOSSY_COBBLESTONE)
B(23,2,8,MOSSY_COBBLESTONE)
B(24,2,8,STONEBRICK)
B(0,3,8,STONEBRICK:1)
B(1,3,8,EMERALD_ORE)
B(2,3,8,MOSSY_COBBLESTONE)
B(3,3,8,STONEBRICK:1)
B(5,3,8,STONEBRICK:2)
B(6,3,8,STONE)
B(7,3,8,MOSSY_COBBLESTONE)
B(8,3,8,STONEBRICK:2)
B(9,3,8,EMERALD_ORE)
B(10,3,8,STONE)
B(11,3,8,MOSSY_COBBLESTONE)
B(12,3,8,MOSSY_COBBLESTONE)
B(13,3,8,STONE)
B(14,3,8,STONE)
B(15,3,8,STONE)
B(16,3,8,STONEBRICK:2)
B(17,3,8,MOSSY_COBBLESTONE)
B(18,3,8,STONE)
B(19,3,8,STONE)
B(20,3,8,STONE)
B(21,3,8,MOSSY_COBBLESTONE)
B(22,3,8,MOSSY_COBBLESTONE)
B(23,3,8,MOSSY_COBBLESTONE)
B(24,3,8,STONEBRICK:1)
B(0,4,8,STONEBRICK:1)
B(1,4,8,MOSSY_COBBLESTONE)
B(2,4,8,STONE)
B(3,4,8,STONEBRICK:3)
B(4,4,8,STONEBRICK:3)
B(5,4,8,STONEBRICK:3)
B(6,4,8,STONE)
B(7,4,8,EMERALD_ORE)
B(8,4,8,STONEBRICK:1)
B(9,4,8,EMERALD_ORE)
B(10,4,8,STONE)
B(11,4,8,STONEBRICK)
B(12,4,8,STONEBRICK)
B(13,4,8,STONEBRICK:2)
B(14,4,8,STONE)
B(15,4,8,MOSSY_COBBLESTONE)
B(16,4,8,STONEBRICK:2)
B(17,4,8,STONE)
B(18,4,8,EMERALD_ORE)
B(19,4,8,EMERALD_ORE)
B(20,4,8,STONE)
B(21,4,8,STONE)
B(22,4,8,MOSSY_COBBLESTONE)
B(23,4,8,STONE)
B(24,4,8,STONEBRICK:1)
B(0,5,8,STONEBRICK:1)
B(1,5,8,EMERALD_ORE)
B(2,5,8,STONE)
B(3,5,8,MOSSY_COBBLESTONE)
B(4,5,8,STONE)
B(5,5,8,MOSSY_COBBLESTONE)
B(6,5,8,STONE)
B(7,5,8,MOSSY_COBBLESTONE)
B(8,5,8,STONEBRICK:2)
B(9,5,8,EMERALD_ORE)
B(10,5,8,MOSSY_COBBLESTONE)
B(11,5,8,STONEBRICK:2)
B(13,5,8,STONEBRICK:1)
B(14,5,8,MOSSY_COBBLESTONE)
B(15,5,8,MOSSY_COBBLESTONE)
B(16,5,8,STONEBRICK:2)
B(17,5,8,STONE)
B(18,5,8,STONE)
B(19,5,8,MOSSY_COBBLESTONE)
B(20,5,8,STONE)
B(21,5,8,STONE)
B(22,5,8,MOSSY_COBBLESTONE)
B(23,5,8,STONE)
B(24,5,8,STONEBRICK)
B(0,6,8,STONEBRICK:1)
B(1,6,8,MOSSY_COBBLESTONE)
B(2,6,8,MOSSY_COBBLESTONE)
B(3,6,8,STONE)
B(4,6,8,MOSSY_COBBLESTONE)
B(5,6,8,MOSSY_COBBLESTONE)
B(6,6,8,STONE)
B(7,6,8,STONE)
B(8,6,8,STONEBRICK:2)
B(9,6,8,MOSSY_COBBLESTONE)
B(10,6,8,STONE)
B(11,6,8,STONEBRICK)
B(13,6,8,STONEBRICK:1)
B(14,6,8,STONE)
B(15,6,8,EMERALD_ORE)
B(16,6,8,STONEBRICK:1)
B(17,6,8,STONE)
B(18,6,8,MOSSY_COBBLESTONE)
B(19,6,8,EMERALD_ORE)
B(20,6,8,STONE)
B(21,6,8,MOSSY_COBBLESTONE)
B(22,6,8,EMERALD_ORE)
B(23,6,8,STONE)
B(24,6,8,STONEBRICK)
B(0,7,8,STONEBRICK:2)
B(1,7,8,MOSSY_COBBLESTONE)
B(2,7,8,EMERALD_ORE)
B(3,7,8,MOSSY_COBBLESTONE)
B(4,7,8,MOSSY_COBBLESTONE)
B(5,7,8,STONE)
B(6,7,8,STONE)
B(7,7,8,MOSSY_COBBLESTONE)
B(8,7,8,STONEBRICK:2)
B(9,7,8,STONE)
B(10,7,8,EMERALD_ORE)
B(11,7,8,STONEBRICK:1)
B(13,7,8,STONEBRICK)
B(14,7,8,STONE)
B(15,7,8,MOSSY_COBBLESTONE)
B(16,7,8,STONEBRICK:2)
B(17,7,8,STONE)
B(18,7,8,STONE)
B(19,7,8,STONE)
B(20,7,8,STONE)
B(21,7,8,STONE)
B(22,7,8,MOSSY_COBBLESTONE)
B(23,7,8,MOSSY_COBBLESTONE)
B(24,7,8,STONEBRICK:2)
B(0,8,8,STONEBRICK:2)
B(1,8,8,STONEBRICK:1)
B(2,8,8,STONEBRICK)
B(3,8,8,STONEBRICK:2)
B(4,8,8,STONEBRICK:2)
B(5,8,8,STONEBRICK)
B(6,8,8,STONEBRICK)
B(7,8,8,STONEBRICK:1)
B(8,8,8,STONEBRICK)
B(9,8,8,MOSSY_COBBLESTONE)
B(10,8,8,MOSSY_COBBLESTONE)
B(11,8,8,STONEBRICK:3)
B(12,8,8,STONEBRICK:3)
B(13,8,8,STONEBRICK:3)
B(14,8,8,STONE)
B(15,8,8,MOSSY_COBBLESTONE)
B(16,8,8,STONEBRICK:1)
B(17,8,8,STONEBRICK)
B(18,8,8,STONEBRICK)
B(19,8,8,STONEBRICK)
B(20,8,8,STONEBRICK)
B(21,8,8,STONEBRICK:1)
B(22,8,8,STONEBRICK:2)
B(23,8,8,STONEBRICK:1)
B(24,8,8,STONEBRICK)
B(0,9,8,STONEBRICK:1)
B(1,9,8,MOSSY_COBBLESTONE)
B(2,9,8,EMERALD_ORE)
B(3,9,8,MOSSY_COBBLESTONE)
B(4,9,8,STONE)
B(5,9,8,STONE)
B(6,9,8,MOSSY_COBBLESTONE)
B(7,9,8,STONE)
B(8,9,8,STONEBRICK:1)
B(9,9,8,MOSSY_COBBLESTONE)
B(10,9,8,EMERALD_ORE)
B(11,9,8,MOSSY_COBBLESTONE)
B(12,9,8,STONE)
B(13,9,8,MOSSY_COBBLESTONE)
B(14,9,8,STONE)
B(15,9,8,MOSSY_COBBLESTONE)
B(16,9,8,STONEBRICK:2)
B(17,9,8,EMERALD_ORE)
B(18,9,8,MOSSY_COBBLESTONE)
B(19,9,8,STONEBRICK:1)
B(21,9,8,STONEBRICK:2)
B(22,9,8,STONE)
B(23,9,8,MOSSY_COBBLESTONE)
B(24,9,8,STONEBRICK:2)
B(0,10,8,STONEBRICK)
B(1,10,8,STONE)
B(2,10,8,STONE)
B(3,10,8,STONE)
B(4,10,8,STONE)
B(5,10,8,STONE)
B(6,10,8,STONE)
B(7,10,8,MOSSY_COBBLESTONE)
B(8,10,8,STONEBRICK)
B(9,10,8,STONE)
B(10,10,8,MOSSY_COBBLESTONE)
B(11,10,8,STONE)
B(12,10,8,MOSSY_COBBLESTONE)
B(13,10,8,MOSSY_COBBLESTONE)
B(14,10,8,MOSSY_COBBLESTONE)
B(15,10,8,STONE)
B(16,10,8,STONEBRICK)
B(17,10,8,STONE)
B(18,10,8,STONE)
B(19,10,8,STONEBRICK:1)
B(21,10,8,STONEBRICK:1)
B(22,10,8,EMERALD_ORE)
B(23,10,8,MOSSY_COBBLESTONE)
B(24,10,8,STONEBRICK:1)
B(0,11,8,STONEBRICK:2)
B(1,11,8,MOSSY_COBBLESTONE)
B(2,11,8,MOSSY_COBBLESTONE)
B(3,11,8,MOSSY_COBBLESTONE)
B(4,11,8,MOSSY_COBBLESTONE)
B(5,11,8,STONE)
B(6,11,8,STONE)
B(7,11,8,MOSSY_COBBLESTONE)
B(8,11,8,STONEBRICK:1)
B(9,11,8,MOSSY_COBBLESTONE)
B(10,11,8,STONE)
B(11,11,8,STONE)
B(12,11,8,MOSSY_COBBLESTONE)
B(13,11,8,MOSSY_COBBLESTONE)
B(14,11,8,STONE)
B(15,11,8,STONE)
B(16,11,8,STONEBRICK)
B(17,11,8,EMERALD_ORE)
B(18,11,8,STONE)
B(19,11,8,STONEBRICK)
B(21,11,8,STONEBRICK:1)
B(22,11,8,MOSSY_COBBLESTONE)
B(23,11,8,STONE)
B(24,11,8,STONEBRICK:1)
B(0,12,8,STONEBRICK)
B(1,12,8,STONE)
B(2,12,8,MOSSY_COBBLESTONE)
B(3,12,8,MOSSY_COBBLESTONE)
B(4,12,8,MOSSY_COBBLESTONE)
B(5,12,8,MOSSY_COBBLESTONE)
B(6,12,8,MOSSY_COBBLESTONE)
B(7,12,8,EMERALD_ORE)
B(8,12,8,STONEBRICK:1)
B(9,12,8,STONE)
B(10,12,8,MOSSY_COBBLESTONE)
B(11,12,8,STONE)
B(12,12,8,MOSSY_COBBLESTONE)
B(13,12,8,MOSSY_COBBLESTONE)
B(14,12,8,MOSSY_COBBLESTONE)
B(15,12,8,STONE)
B(16,12,8,STONEBRICK:1)
B(17,12,8,MOSSY_COBBLESTONE)
B(18,12,8,EMERALD_ORE)
B(19,12,8,STONEBRICK:3)
B(20,12,8,STONEBRICK:3)
B(21,12,8,STONEBRICK:3)
B(22,12,8,EMERALD_ORE)
B(23,12,8,EMERALD_ORE)
B(24,12,8,STONEBRICK)
B(0,13,8,STONEBRICK)
B(1,13,8,MOSSY_COBBLESTONE)
B(2,13,8,STONE)
B(3,13,8,MOSSY_COBBLESTONE)
B(4,13,8,EMERALD_ORE)
B(5,13,8,MOSSY_COBBLESTONE)
B(6,13,8,MOSSY_COBBLESTONE)
B(7,13,8,STONE)
B(8,13,8,STONEBRICK:2)
B(9,13,8,STONE)
B(10,13,8,MOSSY_COBBLESTONE)
B(11,13,8,STONE)
B(12,13,8,MOSSY_COBBLESTONE)
B(13,13,8,MOSSY_COBBLESTONE)
B(14,13,8,MOSSY_COBBLESTONE)
B(15,13,8,MOSSY_COBBLESTONE)
B(16,13,8,STONEBRICK)
B(17,13,8,MOSSY_COBBLESTONE)
B(18,13,8,MOSSY_COBBLESTONE)
B(19,13,8,MOSSY_COBBLESTONE)
B(20,13,8,MOSSY_COBBLESTONE)
B(21,13,8,STONE)
B(22,13,8,MOSSY_COBBLESTONE)
B(23,13,8,MOSSY_COBBLESTONE)
B(24,13,8,STONEBRICK)
B(0,14,8,STONEBRICK)
B(1,14,8,STONE)
B(2,14,8,STONE)
B(3,14,8,MOSSY_COBBLESTONE)
B(4,14,8,MOSSY_COBBLESTONE)
B(5,14,8,STONE)
B(6,14,8,EMERALD_ORE)
B(7,14,8,MOSSY_COBBLESTONE)
B(8,14,8,STONEBRICK:2)
B(9,14,8,STONE)
B(10,14,8,STONE)
B(11,14,8,MOSSY_COBBLESTONE)
B(12,14,8,STONE)
B(13,14,8,MOSSY_COBBLESTONE)
B(14,14,8,STONE)
B(15,14,8,MOSSY_COBBLESTONE)
B(16,14,8,STONEBRICK:2)
B(17,14,8,STONE)
B(18,14,8,MOSSY_COBBLESTONE)
B(19,14,8,MOSSY_COBBLESTONE)
B(20,14,8,MOSSY_COBBLESTONE)
B(21,14,8,STONE)
B(22,14,8,MOSSY_COBBLESTONE)
B(23,14,8,STONE)
B(24,14,8,STONEBRICK:1)
B(0,15,8,STONEBRICK)
B(1,15,8,STONE)
B(2,15,8,MOSSY_COBBLESTONE)
B(3,15,8,MOSSY_COBBLESTONE)
B(4,15,8,MOSSY_COBBLESTONE)
B(5,15,8,MOSSY_COBBLESTONE)
B(6,15,8,STONE)
B(7,15,8,STONE)
B(8,15,8,STONEBRICK)
B(9,15,8,EMERALD_ORE)
B(10,15,8,STONE)
B(11,15,8,MOSSY_COBBLESTONE)
B(12,15,8,STONE)
B(13,15,8,MOSSY_COBBLESTONE)
B(14,15,8,STONE)
B(15,15,8,EMERALD_ORE)
B(16,15,8,STONEBRICK:2)
B(17,15,8,STONE)
B(18,15,8,MOSSY_COBBLESTONE)
B(19,15,8,MOSSY_COBBLESTONE)
B(20,15,8,STONE)
B(21,15,8,STONE)
B(22,15,8,STONE)
B(23,15,8,MOSSY_COBBLESTONE)
B(24,15,8,STONEBRICK:1)
B(0,16,8,STONEBRICK:1)
B(1,16,8,STONEBRICK:2)
B(2,16,8,STONEBRICK:2)
B(3,16,8,STONEBRICK:1)
B(4,16,8,STONEBRICK:1)
B(5,16,8,STONEBRICK:1)
B(6,16,8,STONEBRICK)
B(7,16,8,STONEBRICK)
B(8,16,8,STONEBRICK:1)
B(9,16,8,STONEBRICK:2)
B(10,16,8,STONEBRICK:2)
B(11,16,8,STONEBRICK)
B(12,16,8,STONEBRICK:2)
B(13,16,8,STONEBRICK)
B(14,16,8,STONEBRICK)
B(15,16,8,STONEBRICK:2)
B(16,16,8,STONEBRICK:2)
B(17,16,8,STONEBRICK:1)
B(18,16,8,STONEBRICK:1)
B(19,16,8,STONEBRICK:2)
B(20,16,8,STONEBRICK:2)
B(21,16,8,STONEBRICK)
B(22,16,8,STONEBRICK)
B(23,16,8,STONEBRICK)
B(24,16,8,STONEBRICK)
B(0,0,9,STONEBRICK:1)
B(1,0,9,STONEBRICK:2)
B(2,0,9,STONEBRICK:1)
B(3,0,9,STONEBRICK:1)
B(4,0,9,STONEBRICK:1)
B(5,0,9,STONEBRICK)
B(6,0,9,STONEBRICK:1)
B(7,0,9,STONEBRICK:2)
B(8,0,9,STONEBRICK:1)
B(9,0,9,STONEBRICK)
B(10,0,9,STONEBRICK)
B(11,0,9,STONEBRICK)
B(12,0,9,STONEBRICK)
B(13,0,9,STONEBRICK:2)
B(14,0,9,STONEBRICK)
B(15,0,9,STONEBRICK:2)
B(16,0,9,STONEBRICK:1)
B(17,0,9,STONEBRICK:2)
B(18,0,9,STONEBRICK:2)
B(19,0,9,STONEBRICK)
B(20,0,9,STONEBRICK:2)
B(21,0,9,STONEBRICK:1)
B(22,0,9,STONEBRICK)
B(23,0,9,STONEBRICK)
B(24,0,9,STONEBRICK:2)
B(0,1,9,STONE)
B(1,1,9,EMERALD_ORE)
B(7,1,9,MOSSY_COBBLESTONE)
B(8,1,9,MOSSY_COBBLESTONE)
B(9,1,9,MOSSY_COBBLESTONE)
B(15,1,9,STONE)
B(16,1,9,MOSSY_COBBLESTONE)
B(17,1,9,EMERALD_ORE)
B(23,1,9,STONE)
B(24,1,9,STONE)
B(0,2,9,MOSSY_COBBLESTONE)
B(1,2,9,STONE)
B(7,2,9,STONE)
B(8,2,9,MOSSY_COBBLESTONE)
B(9,2,9,STONE)
B(15,2,9,STONE)
B(16,2,9,EMERALD_ORE)
B(17,2,9,STONE)
B(23,2,9,MOSSY_COBBLESTONE)
B(24,2,9,STONE)
B(0,3,9,STONE)
B(1,3,9,STONE)
B(7,3,9,MOSSY_COBBLESTONE)
B(8,3,9,MOSSY_COBBLESTONE)
B(9,3,9,MOSSY_COBBLESTONE)
B(15,3,9,MOSSY_COBBLESTONE)
B(16,3,9,STONE)
B(17,3,9,STONE)
B(23,3,9,STONE)
B(24,3,9,EMERALD_ORE)
B(0,4,9,STONE)
B(1,4,9,STONEBRICK:3)
B(7,4,9,STONEBRICK:3)
B(8,4,9,MOSSY_COBBLESTONE)
B(9,4,9,STONE)
B(15,4,9,STONE)
B(16,4,9,MOSSY_COBBLESTONE)
B(17,4,9,STONEBRICK:3)
B(23,4,9,STONEBRICK:3)
B(24,4,9,MOSSY_COBBLESTONE)
B(0,5,9,MOSSY_COBBLESTONE)
B(1,5,9,STONEBRICK:1)
B(7,5,9,STONEBRICK:1)
B(8,5,9,STONE)
B(9,5,9,MOSSY_COBBLESTONE)
B(15,5,9,STONE)
B(16,5,9,MOSSY_COBBLESTONE)
B(17,5,9,STONEBRICK:2)
B(23,5,9,STONEBRICK:1)
B(24,5,9,STONE)
B(0,6,9,STONE)
B(1,6,9,STONEBRICK:1)
B(7,6,9,STONEBRICK:1)
B(8,6,9,STONE)
B(9,6,9,STONE)
B(15,6,9,STONE)
B(16,6,9,EMERALD_ORE)
B(17,6,9,STONEBRICK)
B(23,6,9,STONEBRICK:1)
B(24,6,9,STONE)
B(0,7,9,MOSSY_COBBLESTONE)
B(1,7,9,STONEBRICK:2)
B(2,7,9,STONEBRICK:1)
B(3,7,9,STONEBRICK:2)
B(4,7,9,STONEBRICK:2)
B(5,7,9,STONEBRICK:2)
B(6,7,9,STONEBRICK)
B(7,7,9,STONEBRICK)
B(8,7,9,STONE)
B(9,7,9,STONE)
B(15,7,9,MOSSY_COBBLESTONE)
B(16,7,9,MOSSY_COBBLESTONE)
B(17,7,9,STONEBRICK:1)
B(18,7,9,STONEBRICK:1)
B(19,7,9,STONEBRICK:2)
B(20,7,9,STONEBRICK:1)
B(21,7,9,STONEBRICK)
B(22,7,9,STONEBRICK)
B(23,7,9,STONEBRICK)
B(24,7,9,STONE)
B(0,8,9,STONEBRICK:1)
B(1,8,9,STONEBRICK:2)
B(2,8,9,STONEBRICK:2)
B(3,8,9,STONEBRICK:2)
B(4,8,9,STONEBRICK)
B(5,8,9,STONEBRICK)
B(6,8,9,STONEBRICK:1)
B(7,8,9,STONEBRICK:1)
B(8,8,9,EMERALD_ORE)
B(9,8,9,STONE)
B(15,8,9,STONE)
B(16,8,9,MOSSY_COBBLESTONE)
B(17,8,9,STONEBRICK)
B(18,8,9,STONEBRICK)
B(19,8,9,STONEBRICK:1)
B(20,8,9,STONEBRICK:1)
B(21,8,9,STONEBRICK:1)
B(22,8,9,STONEBRICK)
B(23,8,9,STONEBRICK)
B(24,8,9,STONEBRICK)
B(0,9,9,STONE)
B(1,9,9,STONE)
B(7,9,9,MOSSY_COBBLESTONE)
B(8,9,9,MOSSY_COBBLESTONE)
B(9,9,9,MOSSY_COBBLESTONE)
B(15,9,9,STONE)
B(16,9,9,STONE)
B(17,9,9,MOSSY_COBBLESTONE)
B(23,9,9,EMERALD_ORE)
B(24,9,9,STONE)
B(0,10,9,MOSSY_COBBLESTONE)
B(1,10,9,MOSSY_COBBLESTONE)
B(7,10,9,STONE)
B(8,10,9,STONE)
B(9,10,9,EMERALD_ORE)
B(15,10,9,MOSSY_COBBLESTONE)
B(16,10,9,STONE)
B(17,10,9,MOSSY_COBBLESTONE)
B(23,10,9,MOSSY_COBBLESTONE)
B(24,10,9,MOSSY_COBBLESTONE)
B(0,11,9,STONE)
B(1,11,9,STONE)
B(7,11,9,STONE)
B(8,11,9,STONE)
B(9,11,9,STONE)
B(15,11,9,EMERALD_ORE)
B(16,11,9,STONE)
B(17,11,9,MOSSY_COBBLESTONE)
B(23,11,9,MOSSY_COBBLESTONE)
B(24,11,9,STONE)
B(0,12,9,STONE)
B(1,12,9,STONEBRICK:3)
B(7,12,9,STONEBRICK:3)
B(8,12,9,STONE)
B(9,12,9,STONEBRICK:3)
B(15,12,9,STONEBRICK:3)
B(16,12,9,MOSSY_COBBLESTONE)
B(17,12,9,STONEBRICK:3)
B(23,12,9,STONEBRICK:3)
B(24,12,9,STONE)
B(0,13,9,MOSSY_COBBLESTONE)
B(1,13,9,STONEBRICK:1)
B(7,13,9,STONEBRICK)
B(8,13,9,MOSSY_COBBLESTONE)
B(9,13,9,STONEBRICK:1)
B(15,13,9,STONEBRICK)
B(16,13,9,EMERALD_ORE)
B(17,13,9,STONEBRICK)
B(23,13,9,STONEBRICK)
B(24,13,9,STONE)
B(0,14,9,MOSSY_COBBLESTONE)
B(1,14,9,STONEBRICK:1)
B(7,14,9,STONEBRICK:1)
B(8,14,9,MOSSY_COBBLESTONE)
B(9,14,9,STONEBRICK)
B(15,14,9,STONEBRICK)
B(16,14,9,EMERALD_ORE)
B(17,14,9,STONEBRICK:2)
B(23,14,9,STONEBRICK:2)
B(24,14,9,MOSSY_COBBLESTONE)
B(0,15,9,EMERALD_ORE)
B(1,15,9,STONEBRICK)
B(2,15,9,STONEBRICK:1)
B(3,15,9,STONEBRICK:2)
B(4,15,9,STONEBRICK)
B(5,15,9,STONEBRICK:2)
B(6,15,9,STONEBRICK:2)
B(7,15,9,STONEBRICK)
B(8,15,9,EMERALD_ORE)
B(9,15,9,STONEBRICK:1)
B(10,15,9,STONEBRICK:2)
B(11,15,9,STONEBRICK:2)
B(12,15,9,STONEBRICK)
B(13,15,9,STONEBRICK:2)
B(14,15,9,STONEBRICK)
B(15,15,9,STONEBRICK)
B(16,15,9,STONE)
B(17,15,9,STONEBRICK:1)
B(18,15,9,STONEBRICK:2)
B(19,15,9,STONEBRICK:1)
B(20,15,9,STONEBRICK:1)
B(21,15,9,STONEBRICK)
B(22,15,9,STONEBRICK:2)
B(23,15,9,STONEBRICK)
B(24,15,9,STONE)
B(0,16,9,STONEBRICK:1)
B(1,16,9,STONE)
B(2,16,9,STONE)
B(3,16,9,STONE)
B(4,16,9,STONE)
B(5,16,9,STONE)
B(6,16,9,EMERALD_ORE)
B(7,16,9,STONE)
B(8,16,9,STONEBRICK:1)
B(9,16,9,STONE)
B(10,16,9,STONE)
B(11,16,9,STONE)
B(12,16,9,STONE)
B(13,16,9,MOSSY_COBBLESTONE)
B(14,16,9,STONE)
B(15,16,9,MOSSY_COBBLESTONE)
B(16,16,9,STONEBRICK)
B(17,16,9,STONE)
B(18,16,9,EMERALD_ORE)
B(19,16,9,MOSSY_COBBLESTONE)
B(20,16,9,STONE)
B(21,16,9,MOSSY_COBBLESTONE)
B(22,16,9,EMERALD_ORE)
B(23,16,9,STONE)
B(24,16,9,STONEBRICK)
B(0,0,10,STONEBRICK:1)
B(1,0,10,STONEBRICK:1)
B(2,0,10,STONEBRICK)
B(3,0,10,STONEBRICK)
B(4,0,10,STONEBRICK:1)
B(5,0,10,STONEBRICK)
B(6,0,10,STONEBRICK:2)
B(7,0,10,STONEBRICK:2)
B(8,0,10,STONEBRICK:2)
B(9,0,10,STONEBRICK)
B(10,0,10,STONEBRICK:1)
B(11,0,10,STONEBRICK:2)
B(12,0,10,STONEBRICK)
B(13,0,10,STONEBRICK:1)
B(14,0,10,STONEBRICK:1)
B(15,0,10,STONEBRICK:1)
B(16,0,10,STONEBRICK)
B(17,0,10,STONEBRICK)
B(18,0,10,STONEBRICK:1)
B(19,0,10,STONEBRICK:2)
B(20,0,10,STONEBRICK)
B(21,0,10,STONEBRICK)
B(22,0,10,STONEBRICK:1)
B(23,0,10,STONEBRICK:1)
B(24,0,10,STONEBRICK:2)
B(0,1,10,MOSSY_COBBLESTONE)
B(8,1,10,MOSSY_COBBLESTONE)
B(16,1,10,MOSSY_COBBLESTONE)
B(24,1,10,STONE)
B(0,2,10,STONE)
B(8,2,10,STONE)
B(16,2,10,STONE)
B(24,2,10,MOSSY_COBBLESTONE)
B(0,3,10,MOSSY_COBBLESTONE)
B(8,3,10,STONE)
B(16,3,10,EMERALD_ORE)
B(24,3,10,STONE)
B(0,4,10,MOSSY_COBBLESTONE)
B(8,4,10,STONE)
B(16,4,10,MOSSY_COBBLESTONE)
B(24,4,10,EMERALD_ORE)
B(0,5,10,MOSSY_COBBLESTONE)
B(8,5,10,MOSSY_COBBLESTONE)
B(16,5,10,MOSSY_COBBLESTONE)
B(24,5,10,MOSSY_COBBLESTONE)
B(0,6,10,MOSSY_COBBLESTONE)
B(8,6,10,MOSSY_COBBLESTONE)
B(16,6,10,MOSSY_COBBLESTONE)
B(24,6,10,EMERALD_ORE)
B(0,7,10,STONE)
B(1,7,10,STONEBRICK)
B(7,7,10,STONEBRICK:1)
B(8,7,10,MOSSY_COBBLESTONE)
B(16,7,10,MOSSY_COBBLESTONE)
B(17,7,10,STONEBRICK)
B(23,7,10,STONEBRICK)
B(24,7,10,MOSSY_COBBLESTONE)
B(0,8,10,STONEBRICK:1)
B(1,8,10,STONEBRICK)
B(2,8,10,STONEBRICK:1)
B(3,8,10,STONEBRICK:2)
B(4,8,10,STONEBRICK)
B(5,8,10,STONEBRICK)
B(6,8,10,STONEBRICK:1)
B(7,8,10,STONEBRICK:1)
B(8,8,10,STONE)
B(16,8,10,MOSSY_COBBLESTONE)
B(17,8,10,STONEBRICK)
B(18,8,10,STONEBRICK:1)
B(19,8,10,STONEBRICK:1)
B(20,8,10,STONEBRICK:2)
B(21,8,10,STONEBRICK:2)
B(22,8,10,STONEBRICK)
B(23,8,10,STONEBRICK:2)
B(24,8,10,STONEBRICK:1)
B(0,9,10,STONE)
B(8,9,10,MOSSY_COBBLESTONE)
B(16,9,10,STONE)
B(24,9,10,STONE)
B(0,10,10,MOSSY_COBBLESTONE)
B(8,10,10,MOSSY_COBBLESTONE)
B(16,10,10,STONE)
B(24,10,10,MOSSY_COBBLESTONE)
B(0,11,10,EMERALD_ORE)
B(8,11,10,EMERALD_ORE)
B(16,11,10,MOSSY_COBBLESTONE)
B(24,11,10,MOSSY_COBBLESTONE)
B(0,12,10,STONE)
B(8,12,10,STONE)
B(16,12,10,MOSSY_COBBLESTONE)
B(24,12,10,STONE)
B(0,13,10,MOSSY_COBBLESTONE)
B(8,13,10,MOSSY_COBBLESTONE)
B(16,13,10,STONE)
B(24,13,10,EMERALD_ORE)
B(0,14,10,EMERALD_ORE)
B(8,14,10,STONE)
B(16,14,10,MOSSY_COBBLESTONE)
B(24,14,10,EMERALD_ORE)
B(0,15,10,MOSSY_COBBLESTONE)
B(1,15,10,STONEBRICK)
B(7,15,10,STONEBRICK:1)
B(8,15,10,STONE)
B(9,15,10,STONEBRICK:1)
B(15,15,10,STONEBRICK:1)
B(16,15,10,EMERALD_ORE)
B(17,15,10,STONEBRICK:2)
B(23,15,10,STONEBRICK)
B(24,15,10,STONE)
B(0,16,10,STONEBRICK:1)
B(1,16,10,MOSSY_COBBLESTONE)
B(2,16,10,STONEBRICK:2)
B(3,16,10,STONEBRICK:1)
B(4,16,10,STONEBRICK:2)
B(5,16,10,STONEBRICK)
B(6,16,10,STONEBRICK:1)
B(7,16,10,MOSSY_COBBLESTONE)
B(8,16,10,STONEBRICK:1)
B(9,16,10,MOSSY_COBBLESTONE)
B(10,16,10,STONEBRICK:1)
B(11,16,10,STONEBRICK:1)
B(12,16,10,STONEBRICK:1)
B(13,16,10,STONEBRICK:2)
B(14,16,10,STONEBRICK)
B(15,16,10,STONE)
B(16,16,10,STONEBRICK:2)
B(17,16,10,MOSSY_COBBLESTONE)
B(18,16,10,STONEBRICK)
B(19,16,10,STONEBRICK)
B(20,16,10,STONEBRICK)
B(21,16,10,STONEBRICK)
B(22,16,10,STONEBRICK:2)
B(23,16,10,STONE)
B(24,16,10,STONEBRICK)
B(0,0,11,STONEBRICK:1)
B(1,0,11,STONEBRICK:2)
B(2,0,11,STONEBRICK:2)
B(3,0,11,GRASS)
B(4,0,11,DIRT:1)
B(5,0,11,DIRT:1)
B(6,0,11,STONEBRICK:1)
B(7,0,11,STONEBRICK)
B(8,0,11,STONEBRICK)
B(9,0,11,STONEBRICK:2)
B(10,0,11,STONEBRICK:1)
B(11,0,11,DIRT:1)
B(12,0,11,GRASS)
B(13,0,11,GRASS)
B(14,0,11,STONEBRICK)
B(15,0,11,STONEBRICK:1)
B(16,0,11,STONEBRICK)
B(17,0,11,STONEBRICK:2)
B(18,0,11,STONEBRICK)
B(19,0,11,GRASS)
B(20,0,11,DIRT:1)
B(21,0,11,GRASS)
B(22,0,11,STONEBRICK:1)
B(23,0,11,STONEBRICK)
B(24,0,11,STONEBRICK)
B(0,1,11,STONE)
B(8,1,11,STONEBRICK:2)
B(16,1,11,STONEBRICK:2)
B(24,1,11,STONE)
B(0,2,11,STONE)
B(8,2,11,STONEBRICK)
B(16,2,11,STONEBRICK:2)
B(24,2,11,EMERALD_ORE)
B(0,3,11,STONE)
B(8,3,11,STONEBRICK:1)
B(16,3,11,STONEBRICK:1)
B(24,3,11,MOSSY_COBBLESTONE)
B(0,4,11,EMERALD_ORE)
B(8,4,11,STONEBRICK:3)
B(16,4,11,STONEBRICK:3)
B(24,4,11,EMERALD_ORE)
B(0,5,11,EMERALD_ORE)
B(8,5,11,EMERALD_ORE)
B(16,5,11,MOSSY_COBBLESTONE)
B(24,5,11,STONE)
B(0,6,11,MOSSY_COBBLESTONE)
B(8,6,11,MOSSY_COBBLESTONE)
B(16,6,11,STONE)
B(24,6,11,EMERALD_ORE)
B(0,7,11,EMERALD_ORE)
B(1,7,11,STONEBRICK:1)
B(7,7,11,STONEBRICK)
B(8,7,11,MOSSY_COBBLESTONE)
B(16,7,11,STONE)
B(17,7,11,STONEBRICK:2)
B(23,7,11,STONEBRICK:2)
B(24,7,11,MOSSY_COBBLESTONE)
B(0,8,11,STONEBRICK:1)
B(1,8,11,STONEBRICK)
B(2,8,11,STONEBRICK)
B(6,8,11,STONEBRICK:1)
B(7,8,11,STONEBRICK:2)
B(8,8,11,STONEBRICK:1)
B(16,8,11,STONEBRICK:2)
B(17,8,11,STONEBRICK:1)
B(18,8,11,STONEBRICK:1)
B(22,8,11,STONEBRICK:2)
B(23,8,11,STONEBRICK:1)
B(24,8,11,STONEBRICK:1)
B(0,9,11,MOSSY_COBBLESTONE)
B(8,9,11,STONEBRICK:1)
B(16,9,11,STONEBRICK:2)
B(24,9,11,MOSSY_COBBLESTONE)
B(0,10,11,STONE)
B(8,10,11,STONEBRICK:2)
B(16,10,11,STONEBRICK:2)
B(24,10,11,MOSSY_COBBLESTONE)
B(0,11,11,STONE)
B(8,11,11,STONEBRICK:2)
B(16,11,11,STONEBRICK:2)
B(24,11,11,STONE)
B(0,12,11,STONE)
B(8,12,11,STONEBRICK:3)
B(16,12,11,STONEBRICK:3)
B(24,12,11,STONE)
B(0,13,11,STONE)
B(8,13,11,STONE)
B(16,13,11,MOSSY_COBBLESTONE)
B(24,13,11,STONE)
B(0,14,11,MOSSY_COBBLESTONE)
B(8,14,11,EMERALD_ORE)
B(16,14,11,EMERALD_ORE)
B(24,14,11,MOSSY_COBBLESTONE)
B(0,15,11,MOSSY_COBBLESTONE)
B(1,15,11,STONEBRICK:1)
B(7,15,11,STONEBRICK)
B(8,15,11,STONE)
B(9,15,11,STONEBRICK:1)
B(15,15,11,STONEBRICK:2)
B(16,15,11,MOSSY_COBBLESTONE)
B(17,15,11,STONEBRICK:1)
B(23,15,11,STONEBRICK)
B(24,15,11,STONE)
B(0,16,11,STONEBRICK)
B(1,16,11,STONE)
B(2,16,11,STONEBRICK:1)
B(6,16,11,STONEBRICK:2)
B(7,16,11,MOSSY_COBBLESTONE)
B(8,16,11,STONEBRICK:1)
B(9,16,11,MOSSY_COBBLESTONE)
B(10,16,11,STONEBRICK)
B(14,16,11,STONEBRICK:1)
B(15,16,11,STONE)
B(16,16,11,STONEBRICK)
B(17,16,11,MOSSY_COBBLESTONE)
B(18,16,11,STONEBRICK:2)
B(22,16,11,STONEBRICK:1)
B(23,16,11,EMERALD_ORE)
B(24,16,11,STONEBRICK)
B(0,0,12,STONEBRICK)
B(1,0,12,STONEBRICK:2)
B(2,0,12,STONEBRICK:1)
B(3,0,12,DIRT:1)
B(4,0,12,GRASS)
B(5,0,12,DIRT:1)
B(6,0,12,STONEBRICK:2)
B(7,0,12,STONEBRICK:2)
B(8,0,12,STONEBRICK:1)
B(9,0,12,STONEBRICK)
B(10,0,12,STONEBRICK:1)
B(11,0,12,DIRT:1)
B(12,0,12,DIRT:1)
B(13,0,12,GRASS)
B(14,0,12,STONEBRICK:1)
B(15,0,12,STONEBRICK)
B(16,0,12,STONEBRICK:1)
B(17,0,12,STONEBRICK)
B(18,0,12,STONEBRICK)
B(19,0,12,DIRT:1)
B(20,0,12,GRASS)
B(21,0,12,GRASS)
B(22,0,12,STONEBRICK:1)
B(23,0,12,STONEBRICK:2)
B(24,0,12,STONEBRICK)
B(0,1,12,STONE)
B(24,1,12,MOSSY_COBBLESTONE)
B(0,2,12,STONE)
B(24,2,12,MOSSY_COBBLESTONE)
B(0,3,12,MOSSY_COBBLESTONE)
B(24,3,12,STONE)
B(0,4,12,STONE)
B(8,4,12,STONEBRICK:3)
B(16,4,12,STONEBRICK:3)
B(24,4,12,EMERALD_ORE)
B(0,5,12,MOSSY_COBBLESTONE)
B(8,5,12,EMERALD_ORE)
B(16,5,12,EMERALD_ORE)
B(24,5,12,STONE)
B(0,6,12,STONE)
B(8,6,12,MOSSY_COBBLESTONE)
B(16,6,12,STONE)
B(24,6,12,STONE)
B(0,7,12,EMERALD_ORE)
B(1,7,12,STONEBRICK)
B(7,7,12,STONEBRICK:1)
B(8,7,12,MOSSY_COBBLESTONE)
B(16,7,12,STONE)
B(17,7,12,STONEBRICK:1)
B(23,7,12,STONEBRICK:2)
B(24,7,12,MOSSY_COBBLESTONE)
B(0,8,12,STONEBRICK:1)
B(1,8,12,STONEBRICK:2)
B(2,8,12,STONEBRICK:2)
B(6,8,12,STONEBRICK:1)
B(7,8,12,STONEBRICK:2)
B(8,8,12,STONEBRICK:2)
B(16,8,12,STONEBRICK:2)
B(17,8,12,STONEBRICK)
B(18,8,12,STONEBRICK:1)
B(22,8,12,STONEBRICK:2)
B(23,8,12,STONEBRICK:1)
B(24,8,12,STONEBRICK)
B(0,9,12,MOSSY_COBBLESTONE)
B(24,9,12,STONE)
B(0,10,12,MOSSY_COBBLESTONE)
B(24,10,12,MOSSY_COBBLESTONE)
B(0,11,12,MOSSY_COBBLESTONE)
B(24,11,12,MOSSY_COBBLESTONE)
B(0,12,12,MOSSY_COBBLESTONE)
B(8,12,12,STONEBRICK:3)
B(16,12,12,STONEBRICK:3)
B(24,12,12,STONE)
B(0,13,12,MOSSY_COBBLESTONE)
B(8,13,12,MOSSY_COBBLESTONE)
B(16,13,12,STONE)
B(24,13,12,EMERALD_ORE)
B(0,14,12,STONE)
B(8,14,12,MOSSY_COBBLESTONE)
B(16,14,12,MOSSY_COBBLESTONE)
B(24,14,12,STONE)
B(0,15,12,MOSSY_COBBLESTONE)
B(1,15,12,STONEBRICK:1)
B(7,15,12,STONEBRICK)
B(8,15,12,MOSSY_COBBLESTONE)
B(9,15,12,STONEBRICK:1)
B(15,15,12,STONEBRICK)
B(16,15,12,MOSSY_COBBLESTONE)
B(17,15,12,STONEBRICK:2)
B(23,15,12,STONEBRICK)
B(24,15,12,MOSSY_COBBLESTONE)
B(0,16,12,STONEBRICK)
B(1,16,12,MOSSY_COBBLESTONE)
B(2,16,12,STONEBRICK:2)
B(6,16,12,STONEBRICK:1)
B(7,16,12,MOSSY_COBBLESTONE)
B(8,16,12,STONEBRICK:1)
B(9,16,12,MOSSY_COBBLESTONE)
B(10,16,12,STONEBRICK:1)
B(14,16,12,STONEBRICK:1)
B(15,16,12,MOSSY_COBBLESTONE)
B(16,16,12,STONEBRICK:1)
B(17,16,12,STONE)
B(18,16,12,STONEBRICK)
B(22,16,12,STONEBRICK:2)
B(23,16,12,MOSSY_COBBLESTONE)
B(24,16,12,STONEBRICK:2)
B(0,0,13,STONEBRICK)
B(1,0,13,STONEBRICK)
B(2,0,13,STONEBRICK:2)
B(3,0,13,GRASS)
B(4,0,13,DIRT:1)
B(5,0,13,GRASS)
B(6,0,13,STONEBRICK:2)
B(7,0,13,STONEBRICK:2)
B(8,0,13,STONEBRICK:1)
B(9,0,13,STONEBRICK)
B(10,0,13,STONEBRICK)
B(11,0,13,GRASS)
B(12,0,13,GRASS)
B(13,0,13,DIRT:1)
B(14,0,13,STONEBRICK:2)
B(15,0,13,STONEBRICK:1)
B(16,0,13,STONEBRICK:2)
B(17,0,13,STONEBRICK)
B(18,0,13,STONEBRICK:1)
B(19,0,13,GRASS)
B(20,0,13,DIRT:1)
B(21,0,13,GRASS)
B(22,0,13,STONEBRICK)
B(23,0,13,STONEBRICK:1)
B(24,0,13,STONEBRICK:1)
B(0,1,13,MOSSY_COBBLESTONE)
B(8,1,13,STONEBRICK:2)
B(16,1,13,STONEBRICK:2)
B(24,1,13,STONE)
B(0,2,13,MOSSY_COBBLESTONE)
B(8,2,13,STONEBRICK)
B(16,2,13,STONEBRICK)
B(24,2,13,STONE)
B(0,3,13,MOSSY_COBBLESTONE)
B(8,3,13,STONEBRICK)
B(16,3,13,STONEBRICK:2)
B(24,3,13,EMERALD_ORE)
B(0,4,13,MOSSY_COBBLESTONE)
B(8,4,13,STONEBRICK:3)
B(16,4,13,STONEBRICK:3)
B(24,4,13,STONE)
B(0,5,13,STONE)
B(8,5,13,STONE)
B(16,5,13,MOSSY_COBBLESTONE)
B(24,5,13,EMERALD_ORE)
B(0,6,13,MOSSY_COBBLESTONE)
B(8,6,13,MOSSY_COBBLESTONE)
B(16,6,13,STONE)
B(24,6,13,EMERALD_ORE)
B(0,7,13,STONE)
B(1,7,13,STONEBRICK:2)
B(7,7,13,STONEBRICK:2)
B(8,7,13,STONE)
B(16,7,13,MOSSY_COBBLESTONE)
B(17,7,13,STONEBRICK)
B(23,7,13,STONEBRICK:1)
B(24,7,13,MOSSY_COBBLESTONE)
B(0,8,13,STONEBRICK)
B(1,8,13,STONEBRICK:1)
B(2,8,13,STONEBRICK:1)
B(6,8,13,STONEBRICK)
B(7,8,13,STONEBRICK)
B(8,8,13,STONEBRICK)
B(16,8,13,STONEBRICK:1)
B(17,8,13,STONEBRICK)
B(18,8,13,STONEBRICK:1)
B(22,8,13,STONEBRICK:2)
B(23,8,13,STONEBRICK)
B(24,8,13,STONEBRICK:2)
B(0,9,13,MOSSY_COBBLESTONE)
B(8,9,13,STONEBRICK)
B(16,9,13,STONEBRICK:1)
B(24,9,13,EMERALD_ORE)
B(0,10,13,MOSSY_COBBLESTONE)
B(8,10,13,STONEBRICK)
B(16,10,13,STONEBRICK:2)
B(24,10,13,STONE)
B(0,11,13,EMERALD_ORE)
B(8,11,13,STONEBRICK)
B(16,11,13,STONEBRICK)
B(24,11,13,MOSSY_COBBLESTONE)
B(0,12,13,MOSSY_COBBLESTONE)
B(8,12,13,STONEBRICK:3)
B(16,12,13,STONEBRICK:3)
B(24,12,13,STONE)
B(0,13,13,MOSSY_COBBLESTONE)
B(8,13,13,MOSSY_COBBLESTONE)
B(16,13,13,EMERALD_ORE)
B(24,13,13,STONE)
B(0,14,13,STONE)
B(8,14,13,STONE)
B(16,14,13,MOSSY_COBBLESTONE)
B(24,14,13,MOSSY_COBBLESTONE)
B(0,15,13,MOSSY_COBBLESTONE)
B(1,15,13,STONEBRICK:2)
B(7,15,13,STONEBRICK:1)
B(8,15,13,MOSSY_COBBLESTONE)
B(9,15,13,STONEBRICK:2)
B(15,15,13,STONEBRICK:1)
B(16,15,13,MOSSY_COBBLESTONE)
B(17,15,13,STONEBRICK)
B(23,15,13,STONEBRICK)
B(24,15,13,STONE)
B(0,16,13,STONEBRICK:2)
B(1,16,13,MOSSY_COBBLESTONE)
B(2,16,13,STONEBRICK:2)
B(6,16,13,STONEBRICK:2)
B(7,16,13,STONE)
B(8,16,13,STONEBRICK:2)
B(9,16,13,MOSSY_COBBLESTONE)
B(10,16,13,STONEBRICK:1)
B(14,16,13,STONEBRICK:2)
B(15,16,13,STONE)
B(16,16,13,STONEBRICK)
B(17,16,13,STONE)
B(18,16,13,STONEBRICK:2)
B(22,16,13,STONEBRICK)
B(23,16,13,MOSSY_COBBLESTONE)
B(24,16,13,STONEBRICK)
B(0,0,14,STONEBRICK:2)
B(1,0,14,STONEBRICK)
B(2,0,14,STONEBRICK:1)
B(3,0,14,STONEBRICK:2)
B(4,0,14,STONEBRICK:2)
B(5,0,14,STONEBRICK)
B(6,0,14,STONEBRICK:1)
B(7,0,14,STONEBRICK:2)
B(8,0,14,STONEBRICK:1)
B(9,0,14,STONEBRICK:2)
B(10,0,14,STONEBRICK:2)
B(11,0,14,STONEBRICK)
B(12,0,14,STONEBRICK:1)
B(13,0,14,STONEBRICK)
B(14,0,14,STONEBRICK:1)
B(15,0,14,STONEBRICK:1)
B(16,0,14,STONEBRICK:1)
B(17,0,14,STONEBRICK:1)
B(18,0,14,STONEBRICK:1)
B(19,0,14,STONEBRICK:1)
B(20,0,14,STONEBRICK:1)
B(21,0,14,STONEBRICK)
B(22,0,14,STONEBRICK:2)
B(23,0,14,STONEBRICK:2)
B(24,0,14,STONEBRICK)
B(0,1,14,STONE)
B(8,1,14,MOSSY_COBBLESTONE)
B(16,1,14,STONE)
B(24,1,14,MOSSY_COBBLESTONE)
B(0,2,14,STONE)
B(8,2,14,MOSSY_COBBLESTONE)
B(16,2,14,STONE)
B(24,2,14,MOSSY_COBBLESTONE)
B(0,3,14,MOSSY_COBBLESTONE)
B(8,3,14,MOSSY_COBBLESTONE)
B(16,3,14,STONE)
B(24,3,14,EMERALD_ORE)
B(0,4,14,MOSSY_COBBLESTONE)
B(8,4,14,STONE)
B(16,4,14,STONE)
B(24,4,14,STONE)
B(0,5,14,MOSSY_COBBLESTONE)
B(8,5,14,STONE)
B(16,5,14,STONE)
B(24,5,14,MOSSY_COBBLESTONE)
B(0,6,14,MOSSY_COBBLESTONE)
B(8,6,14,STONE)
B(16,6,14,MOSSY_COBBLESTONE)
B(24,6,14,STONE)
B(0,7,14,MOSSY_COBBLESTONE)
B(1,7,14,STONEBRICK:1)
B(7,7,14,STONEBRICK)
B(8,7,14,EMERALD_ORE)
B(16,7,14,STONE)
B(17,7,14,STONEBRICK:2)
B(23,7,14,STONEBRICK)
B(24,7,14,STONE)
B(0,8,14,STONEBRICK:2)
B(1,8,14,STONEBRICK:1)
B(2,8,14,STONEBRICK)
B(3,8,14,STONEBRICK:1)
B(4,8,14,STONEBRICK:2)
B(5,8,14,STONEBRICK)
B(6,8,14,STONEBRICK:1)
B(7,8,14,STONEBRICK)
B(8,8,14,STONE)
B(16,8,14,MOSSY_COBBLESTONE)
B(17,8,14,STONEBRICK)
B(18,8,14,STONEBRICK)
B(19,8,14,STONEBRICK:2)
B(20,8,14,STONEBRICK:2)
B(21,8,14,STONEBRICK:1)
B(22,8,14,STONEBRICK:1)
B(23,8,14,STONEBRICK:2)
B(24,8,14,STONEBRICK:1)
B(0,9,14,STONE)
B(8,9,14,MOSSY_COBBLESTONE)
B(16,9,14,EMERALD_ORE)
B(24,9,14,MOSSY_COBBLESTONE)
B(0,10,14,STONE)
B(8,10,14,STONE)
B(16,10,14,MOSSY_COBBLESTONE)
B(24,10,14,STONE)
B(0,11,14,MOSSY_COBBLESTONE)
B(8,11,14,STONE)
B(16,11,14,MOSSY_COBBLESTONE)
B(24,11,14,EMERALD_ORE)
B(0,12,14,MOSSY_COBBLESTONE)
B(8,12,14,STONE)
B(16,12,14,MOSSY_COBBLESTONE)
B(24,12,14,MOSSY_COBBLESTONE)
B(0,13,14,EMERALD_ORE)
B(8,13,14,STONE)
B(16,13,14,STONE)
B(24,13,14,MOSSY_COBBLESTONE)
B(0,14,14,EMERALD_ORE)
B(8,14,14,STONE)
B(16,14,14,EMERALD_ORE)
B(24,14,14,STONE)
B(0,15,14,STONE)
B(1,15,14,STONEBRICK:2)
B(7,15,14,STONEBRICK)
B(8,15,14,MOSSY_COBBLESTONE)
B(9,15,14,STONEBRICK:1)
B(15,15,14,STONEBRICK)
B(16,15,14,STONE)
B(17,15,14,STONEBRICK:2)
B(23,15,14,STONEBRICK:2)
B(24,15,14,MOSSY_COBBLESTONE)
B(0,16,14,STONEBRICK:2)
B(1,16,14,MOSSY_COBBLESTONE)
B(2,16,14,STONEBRICK:1)
B(3,16,14,STONEBRICK)
B(4,16,14,STONEBRICK)
B(5,16,14,STONEBRICK)
B(6,16,14,STONEBRICK)
B(7,16,14,MOSSY_COBBLESTONE)
B(8,16,14,STONEBRICK:1)
B(9,16,14,MOSSY_COBBLESTONE)
B(10,16,14,STONEBRICK:1)
B(11,16,14,STONEBRICK)
B(12,16,14,STONEBRICK:2)
B(13,16,14,STONEBRICK:1)
B(14,16,14,STONEBRICK:1)
B(15,16,14,MOSSY_COBBLESTONE)
B(16,16,14,STONEBRICK:1)
B(17,16,14,STONE)
B(18,16,14,STONEBRICK)
B(19,16,14,STONEBRICK:2)
B(20,16,14,STONEBRICK:1)
B(21,16,14,STONEBRICK:2)
B(22,16,14,STONEBRICK)
B(23,16,14,EMERALD_ORE)
B(24,16,14,STONEBRICK:1)
B(0,0,15,STONEBRICK:2)
B(1,0,15,STONEBRICK)
B(2,0,15,STONEBRICK)
B(3,0,15,STONEBRICK:2)
B(4,0,15,STONEBRICK)
B(5,0,15,STONEBRICK)
B(6,0,15,STONEBRICK)
B(7,0,15,STONEBRICK:1)
B(8,0,15,STONEBRICK:2)
B(9,0,15,STONEBRICK:1)
B(10,0,15,STONEBRICK:1)
B(11,0,15,STONEBRICK)
B(12,0,15,STONEBRICK)
B(13,0,15,STONEBRICK)
B(14,0,15,STONEBRICK:2)
B(15,0,15,STONEBRICK)
B(16,0,15,STONEBRICK)
B(17,0,15,STONEBRICK)
B(18,0,15,STONEBRICK:2)
B(19,0,15,STONEBRICK)
B(20,0,15,STONEBRICK:2)
B(21,0,15,STONEBRICK:1)
B(22,0,15,STONEBRICK:2)
B(23,0,15,STONEBRICK)
B(24,0,15,STONEBRICK:1)
B(0,1,15,MOSSY_COBBLESTONE)
B(1,1,15,STONE)
B(7,1,15,STONE)
B(8,1,15,MOSSY_COBBLESTONE)
B(9,1,15,MOSSY_COBBLESTONE)
B(15,1,15,STONE)
B(16,1,15,MOSSY_COBBLESTONE)
B(17,1,15,EMERALD_ORE)
B(23,1,15,STONE)
B(24,1,15,MOSSY_COBBLESTONE)
B(0,2,15,STONE)
B(1,2,15,EMERALD_ORE)
B(7,2,15,STONE)
B(8,2,15,MOSSY_COBBLESTONE)
B(9,2,15,MOSSY_COBBLESTONE)
B(15,2,15,STONE)
B(16,2,15,MOSSY_COBBLESTONE)
B(17,2,15,EMERALD_ORE)
B(23,2,15,MOSSY_COBBLESTONE)
B(24,2,15,MOSSY_COBBLESTONE)
B(0,3,15,STONE)
B(1,3,15,MOSSY_COBBLESTONE)
B(7,3,15,MOSSY_COBBLESTONE)
B(8,3,15,MOSSY_COBBLESTONE)
B(9,3,15,STONE)
B(15,3,15,MOSSY_COBBLESTONE)
B(16,3,15,STONE)
B(17,3,15,STONE)
B(23,3,15,STONE)
B(24,3,15,MOSSY_COBBLESTONE)
B(0,4,15,STONE)
B(1,4,15,STONEBRICK:3)
B(7,4,15,STONEBRICK:3)
B(8,4,15,STONE)
B(9,4,15,STONE)
B(15,4,15,STONE)
B(16,4,15,MOSSY_COBBLESTONE)
B(17,4,15,STONEBRICK:3)
B(23,4,15,STONEBRICK:3)
B(24,4,15,EMERALD_ORE)
B(0,5,15,MOSSY_COBBLESTONE)
B(1,5,15,STONEBRICK)
B(7,5,15,STONEBRICK:2)
B(8,5,15,EMERALD_ORE)
B(9,5,15,STONE)
B(15,5,15,STONE)
B(16,5,15,MOSSY_COBBLESTONE)
B(17,5,15,STONEBRICK:2)
B(23,5,15,STONEBRICK:2)
B(24,5,15,MOSSY_COBBLESTONE)
B(0,6,15,MOSSY_COBBLESTONE)
B(1,6,15,STONEBRICK:1)
B(7,6,15,STONEBRICK)
B(8,6,15,EMERALD_ORE)
B(9,6,15,MOSSY_COBBLESTONE)
B(15,6,15,STONE)
B(16,6,15,MOSSY_COBBLESTONE)
B(17,6,15,STONEBRICK:2)
B(23,6,15,STONEBRICK:1)
B(24,6,15,MOSSY_COBBLESTONE)
B(0,7,15,STONE)
B(1,7,15,STONEBRICK:1)
B(2,7,15,STONEBRICK:1)
B(3,7,15,STONEBRICK:2)
B(4,7,15,STONEBRICK:2)
B(5,7,15,STONEBRICK:2)
B(6,7,15,STONEBRICK:1)
B(7,7,15,STONEBRICK:1)
B(8,7,15,MOSSY_COBBLESTONE)
B(9,7,15,STONE)
B(15,7,15,MOSSY_COBBLESTONE)
B(16,7,15,STONE)
B(17,7,15,STONEBRICK:2)
B(18,7,15,STONEBRICK)
B(19,7,15,STONEBRICK:1)
B(20,7,15,STONEBRICK)
B(21,7,15,STONEBRICK)
B(22,7,15,STONEBRICK:1)
B(23,7,15,STONEBRICK:1)
B(24,7,15,STONE)
B(0,8,15,STONEBRICK)
B(1,8,15,STONEBRICK:1)
B(2,8,15,STONEBRICK)
B(3,8,15,STONEBRICK)
B(4,8,15,STONEBRICK)
B(5,8,15,STONEBRICK:2)
B(6,8,15,STONEBRICK:2)
B(7,8,15,STONEBRICK:2)
B(8,8,15,STONE)
B(9,8,15,MOSSY_COBBLESTONE)
B(15,8,15,MOSSY_COBBLESTONE)
B(16,8,15,MOSSY_COBBLESTONE)
B(17,8,15,STONEBRICK:2)
B(18,8,15,STONEBRICK:1)
B(19,8,15,STONEBRICK:1)
B(20,8,15,STONEBRICK)
B(21,8,15,STONEBRICK)
B(22,8,15,STONEBRICK:1)
B(23,8,15,STONEBRICK)
B(24,8,15,STONEBRICK:2)
B(0,9,15,MOSSY_COBBLESTONE)
B(1,9,15,STONE)
B(7,9,15,STONE)
B(8,9,15,STONE)
B(9,9,15,MOSSY_COBBLESTONE)
B(15,9,15,STONE)
B(16,9,15,EMERALD_ORE)
B(17,9,15,MOSSY_COBBLESTONE)
B(23,9,15,MOSSY_COBBLESTONE)
B(24,9,15,EMERALD_ORE)
B(0,10,15,EMERALD_ORE)
B(1,10,15,MOSSY_COBBLESTONE)
B(7,10,15,MOSSY_COBBLESTONE)
B(8,10,15,STONE)
B(9,10,15,MOSSY_COBBLESTONE)
B(15,10,15,STONE)
B(16,10,15,MOSSY_COBBLESTONE)
B(17,10,15,MOSSY_COBBLESTONE)
B(23,10,15,MOSSY_COBBLESTONE)
B(24,10,15,MOSSY_COBBLESTONE)
B(0,11,15,MOSSY_COBBLESTONE)
B(1,11,15,STONE)
B(7,11,15,STONE)
B(8,11,15,MOSSY_COBBLESTONE)
B(9,11,15,MOSSY_COBBLESTONE)
B(15,11,15,MOSSY_COBBLESTONE)
B(16,11,15,MOSSY_COBBLESTONE)
B(17,11,15,STONE)
B(23,11,15,EMERALD_ORE)
B(24,11,15,STONE)
B(0,12,15,STONE)
B(1,12,15,STONEBRICK:3)
B(7,12,15,STONEBRICK:3)
B(8,12,15,STONE)
B(9,12,15,STONEBRICK:3)
B(15,12,15,STONEBRICK:3)
B(16,12,15,MOSSY_COBBLESTONE)
B(17,12,15,STONEBRICK:3)
B(23,12,15,STONEBRICK:3)
B(24,12,15,MOSSY_COBBLESTONE)
B(0,13,15,MOSSY_COBBLESTONE)
B(1,13,15,STONEBRICK)
B(7,13,15,STONEBRICK:2)
B(8,13,15,STONE)
B(9,13,15,STONEBRICK:1)
B(15,13,15,STONEBRICK)
B(16,13,15,MOSSY_COBBLESTONE)
B(17,13,15,STONEBRICK)
B(23,13,15,STONEBRICK:2)
B(24,13,15,MOSSY_COBBLESTONE)
B(0,14,15,MOSSY_COBBLESTONE)
B(1,14,15,STONEBRICK)
B(7,14,15,STONEBRICK:2)
B(8,14,15,STONE)
B(9,14,15,STONEBRICK)
B(15,14,15,STONEBRICK)
B(16,14,15,MOSSY_COBBLESTONE)
B(17,14,15,STONEBRICK:2)
B(23,14,15,STONEBRICK:2)
B(24,14,15,EMERALD_ORE)
B(0,15,15,STONE)
B(1,15,15,STONEBRICK:1)
B(2,15,15,STONEBRICK)
B(3,15,15,STONEBRICK)
B(4,15,15,STONEBRICK:2)
B(5,15,15,STONEBRICK:2)
B(6,15,15,STONEBRICK)
B(7,15,15,STONEBRICK:2)
B(8,15,15,EMERALD_ORE)
B(9,15,15,STONEBRICK:1)
B(10,15,15,STONEBRICK:2)
B(11,15,15,STONEBRICK:2)
B(12,15,15,STONEBRICK:1)
B(13,15,15,STONEBRICK)
B(14,15,15,STONEBRICK)
B(15,15,15,STONEBRICK:2)
B(16,15,15,MOSSY_COBBLESTONE)
B(17,15,15,STONEBRICK:2)
B(18,15,15,STONEBRICK:1)
B(19,15,15,STONEBRICK)
B(20,15,15,STONEBRICK:2)
B(21,15,15,STONEBRICK)
B(22,15,15,STONEBRICK)
B(23,15,15,STONEBRICK:2)
B(24,15,15,MOSSY_COBBLESTONE)
B(0,16,15,STONEBRICK)
B(1,16,15,MOSSY_COBBLESTONE)
B(2,16,15,MOSSY_COBBLESTONE)
B(3,16,15,MOSSY_COBBLESTONE)
B(4,16,15,STONE)
B(5,16,15,STONE)
B(6,16,15,MOSSY_COBBLESTONE)
B(7,16,15,MOSSY_COBBLESTONE)
B(8,16,15,STONEBRICK:1)
B(9,16,15,STONE)
B(10,16,15,EMERALD_ORE)
B(11,16,15,MOSSY_COBBLESTONE)
B(12,16,15,STONE)
B(13,16,15,STONE)
B(14,16,15,MOSSY_COBBLESTONE)
B(15,16,15,MOSSY_COBBLESTONE)
B(16,16,15,STONEBRICK:2)
B(17,16,15,MOSSY_COBBLESTONE)
B(18,16,15,MOSSY_COBBLESTONE)
B(19,16,15,STONE)
B(20,16,15,STONE)
B(21,16,15,MOSSY_COBBLESTONE)
B(22,16,15,MOSSY_COBBLESTONE)
B(23,16,15,STONE)
B(24,16,15,STONEBRICK:2)
B(0,0,16,STONEBRICK:1)
B(1,0,16,STONEBRICK:1)
B(2,0,16,STONEBRICK:2)
B(3,0,16,STONEBRICK:2)
B(4,0,16,STONEBRICK:1)
B(5,0,16,STONEBRICK)
B(6,0,16,STONEBRICK:1)
B(7,0,16,STONEBRICK:2)
B(8,0,16,STONEBRICK:1)
B(9,0,16,STONEBRICK:2)
B(10,0,16,STONEBRICK:1)
B(11,0,16,STONEBRICK:1)
B(12,0,16,STONEBRICK:1)
B(13,0,16,STONEBRICK:2)
B(14,0,16,STONEBRICK)
B(15,0,16,STONEBRICK)
B(16,0,16,STONEBRICK)
B(17,0,16,STONEBRICK)
B(18,0,16,STONEBRICK:1)
B(19,0,16,STONEBRICK:2)
B(20,0,16,STONEBRICK:1)
B(21,0,16,STONEBRICK)
B(22,0,16,STONEBRICK:1)
B(23,0,16,STONEBRICK:2)
B(24,0,16,STONEBRICK:2)
B(0,1,16,STONEBRICK:2)
B(1,1,16,MOSSY_COBBLESTONE)
B(2,1,16,MOSSY_COBBLESTONE)
B(3,1,16,EMERALD_ORE)
B(4,1,16,MOSSY_COBBLESTONE)
B(5,1,16,MOSSY_COBBLESTONE)
B(6,1,16,STONE)
B(7,1,16,EMERALD_ORE)
B(8,1,16,STONEBRICK:1)
B(9,1,16,MOSSY_COBBLESTONE)
B(10,1,16,EMERALD_ORE)
B(11,1,16,STONE)
B(12,1,16,MOSSY_COBBLESTONE)
B(13,1,16,MOSSY_COBBLESTONE)
B(14,1,16,STONE)
B(15,1,16,STONE)
B(16,1,16,STONEBRICK:1)
B(17,1,16,MOSSY_COBBLESTONE)
B(18,1,16,STONE)
B(19,1,16,STONEBRICK:2)
B(21,1,16,STONEBRICK:1)
B(22,1,16,STONE)
B(23,1,16,MOSSY_COBBLESTONE)
B(24,1,16,STONEBRICK:1)
B(0,2,16,STONEBRICK:2)
B(1,2,16,STONE)
B(2,2,16,STONE)
B(3,2,16,STONE)
B(4,2,16,MOSSY_COBBLESTONE)
B(5,2,16,MOSSY_COBBLESTONE)
B(6,2,16,MOSSY_COBBLESTONE)
B(7,2,16,MOSSY_COBBLESTONE)
B(8,2,16,STONEBRICK)
B(9,2,16,MOSSY_COBBLESTONE)
B(10,2,16,STONE)
B(11,2,16,EMERALD_ORE)
B(12,2,16,MOSSY_COBBLESTONE)
B(13,2,16,MOSSY_COBBLESTONE)
B(14,2,16,STONE)
B(15,2,16,MOSSY_COBBLESTONE)
B(16,2,16,STONEBRICK:2)
B(17,2,16,MOSSY_COBBLESTONE)
B(18,2,16,STONE)
B(19,2,16,STONEBRICK)
B(21,2,16,STONEBRICK)
B(22,2,16,MOSSY_COBBLESTONE)
B(23,2,16,MOSSY_COBBLESTONE)
B(24,2,16,STONEBRICK:1)
B(0,3,16,STONEBRICK:2)
B(1,3,16,MOSSY_COBBLESTONE)
B(2,3,16,EMERALD_ORE)
B(3,3,16,MOSSY_COBBLESTONE)
B(4,3,16,STONE)
B(5,3,16,MOSSY_COBBLESTONE)
B(6,3,16,STONE)
B(7,3,16,STONE)
B(8,3,16,STONEBRICK)
B(9,3,16,MOSSY_COBBLESTONE)
B(10,3,16,STONE)
B(11,3,16,MOSSY_COBBLESTONE)
B(12,3,16,MOSSY_COBBLESTONE)
B(13,3,16,STONE)
B(14,3,16,STONE)
B(15,3,16,MOSSY_COBBLESTONE)
B(16,3,16,STONEBRICK:2)
B(17,3,16,MOSSY_COBBLESTONE)
B(18,3,16,STONE)
B(19,3,16,STONEBRICK:2)
B(21,3,16,STONEBRICK:2)
B(22,3,16,MOSSY_COBBLESTONE)
B(23,3,16,MOSSY_COBBLESTONE)
B(24,3,16,STONEBRICK:2)
B(0,4,16,STONEBRICK:2)
B(1,4,16,STONE)
B(2,4,16,MOSSY_COBBLESTONE)
B(3,4,16,MOSSY_COBBLESTONE)
B(4,4,16,MOSSY_COBBLESTONE)
B(5,4,16,MOSSY_COBBLESTONE)
B(6,4,16,MOSSY_COBBLESTONE)
B(7,4,16,MOSSY_COBBLESTONE)
B(8,4,16,STONEBRICK:1)
B(9,4,16,MOSSY_COBBLESTONE)
B(10,4,16,STONE)
B(11,4,16,STONEBRICK:2)
B(12,4,16,STONEBRICK:2)
B(13,4,16,STONEBRICK:1)
B(14,4,16,MOSSY_COBBLESTONE)
B(15,4,16,STONE)
B(16,4,16,STONEBRICK)
B(17,4,16,MOSSY_COBBLESTONE)
B(18,4,16,MOSSY_COBBLESTONE)
B(19,4,16,STONEBRICK:3)
B(20,4,16,STONEBRICK:3)
B(21,4,16,STONEBRICK:3)
B(22,4,16,STONE)
B(23,4,16,STONE)
B(24,4,16,STONEBRICK:1)
B(0,5,16,STONEBRICK:2)
B(1,5,16,STONE)
B(2,5,16,STONE)
B(3,5,16,EMERALD_ORE)
B(4,5,16,MOSSY_COBBLESTONE)
B(5,5,16,MOSSY_COBBLESTONE)
B(6,5,16,MOSSY_COBBLESTONE)
B(7,5,16,STONE)
B(8,5,16,STONEBRICK:2)
B(9,5,16,STONE)
B(10,5,16,STONE)
B(11,5,16,STONEBRICK)
B(13,5,16,STONEBRICK:1)
B(14,5,16,STONE)
B(15,5,16,STONE)
B(16,5,16,STONEBRICK:1)
B(17,5,16,STONE)
B(18,5,16,EMERALD_ORE)
B(19,5,16,MOSSY_COBBLESTONE)
B(20,5,16,STONE)
B(21,5,16,MOSSY_COBBLESTONE)
B(22,5,16,EMERALD_ORE)
B(23,5,16,MOSSY_COBBLESTONE)
B(24,5,16,STONEBRICK:2)
B(0,6,16,STONEBRICK)
B(1,6,16,MOSSY_COBBLESTONE)
B(2,6,16,STONE)
B(3,6,16,STONE)
B(4,6,16,STONE)
B(5,6,16,STONE)
B(6,6,16,STONE)
B(7,6,16,STONE)
B(8,6,16,STONEBRICK)
B(9,6,16,STONE)
B(10,6,16,MOSSY_COBBLESTONE)
B(11,6,16,STONEBRICK:2)
B(13,6,16,STONEBRICK:1)
B(14,6,16,STONE)
B(15,6,16,STONE)
B(16,6,16,STONEBRICK)
B(17,6,16,STONE)
B(18,6,16,STONE)
B(19,6,16,MOSSY_COBBLESTONE)
B(20,6,16,MOSSY_COBBLESTONE)
B(21,6,16,STONE)
B(22,6,16,MOSSY_COBBLESTONE)
B(23,6,16,STONE)
B(24,6,16,STONEBRICK)
B(0,7,16,STONEBRICK:1)
B(1,7,16,MOSSY_COBBLESTONE)
B(2,7,16,MOSSY_COBBLESTONE)
B(3,7,16,MOSSY_COBBLESTONE)
B(4,7,16,STONE)
B(5,7,16,MOSSY_COBBLESTONE)
B(6,7,16,EMERALD_ORE)
B(7,7,16,MOSSY_COBBLESTONE)
B(8,7,16,STONEBRICK:1)
B(9,7,16,MOSSY_COBBLESTONE)
B(10,7,16,STONE)
B(11,7,16,STONEBRICK:1)
B(13,7,16,STONEBRICK:2)
B(14,7,16,EMERALD_ORE)
B(15,7,16,STONE)
B(16,7,16,STONEBRICK)
B(17,7,16,STONE)
B(18,7,16,MOSSY_COBBLESTONE)
B(19,7,16,STONE)
B(20,7,16,MOSSY_COBBLESTONE)
B(21,7,16,MOSSY_COBBLESTONE)
B(22,7,16,MOSSY_COBBLESTONE)
B(23,7,16,MOSSY_COBBLESTONE)
B(24,7,16,STONEBRICK:1)
B(0,8,16,STONEBRICK:2)
B(1,8,16,STONEBRICK:1)
B(2,8,16,STONEBRICK:1)
B(3,8,16,STONEBRICK)
B(4,8,16,STONEBRICK:2)
B(5,8,16,STONEBRICK)
B(6,8,16,STONEBRICK)
B(7,8,16,STONEBRICK:1)
B(8,8,16,STONEBRICK:1)
B(9,8,16,STONE)
B(10,8,16,MOSSY_COBBLESTONE)
B(11,8,16,STONEBRICK:3)
B(12,8,16,STONEBRICK:3)
B(13,8,16,STONEBRICK:3)
B(14,8,16,EMERALD_ORE)
B(15,8,16,MOSSY_COBBLESTONE)
B(16,8,16,STONEBRICK:2)
B(17,8,16,STONEBRICK:2)
B(18,8,16,STONEBRICK:1)
B(19,8,16,STONEBRICK)
B(20,8,16,STONEBRICK:1)
B(21,8,16,STONEBRICK:1)
B(22,8,16,STONEBRICK:1)
B(23,8,16,STONEBRICK:1)
B(24,8,16,STONEBRICK:1)
B(0,9,16,STONEBRICK:2)
B(1,9,16,MOSSY_COBBLESTONE)
B(2,9,16,MOSSY_COBBLESTONE)
B(3,9,16,STONEBRICK)
B(5,9,16,STONEBRICK:1)
B(6,9,16,STONE)
B(7,9,16,STONE)
B(8,9,16,STONEBRICK)
B(9,9,16,STONE)
B(10,9,16,STONE)
B(11,9,16,STONE)
B(12,9,16,MOSSY_COBBLESTONE)
B(13,9,16,STONE)
B(14,9,16,STONE)
B(15,9,16,MOSSY_COBBLESTONE)
B(16,9,16,STONEBRICK)
B(17,9,16,STONE)
B(18,9,16,MOSSY_COBBLESTONE)
B(19,9,16,STONE)
B(20,9,16,EMERALD_ORE)
B(21,9,16,MOSSY_COBBLESTONE)
B(22,9,16,STONE)
B(23,9,16,STONE)
B(24,9,16,STONEBRICK:2)
B(0,10,16,STONEBRICK)
B(1,10,16,MOSSY_COBBLESTONE)
B(2,10,16,STONE)
B(3,10,16,STONEBRICK:1)
B(5,10,16,STONEBRICK)
B(6,10,16,MOSSY_COBBLESTONE)
B(7,10,16,STONE)
B(8,10,16,STONEBRICK)
B(9,10,16,EMERALD_ORE)
B(10,10,16,STONE)
B(11,10,16,EMERALD_ORE)
B(12,10,16,MOSSY_COBBLESTONE)
B(13,10,16,STONE)
B(14,10,16,MOSSY_COBBLESTONE)
B(15,10,16,STONE)
B(16,10,16,STONEBRICK)
B(17,10,16,MOSSY_COBBLESTONE)
B(18,10,16,MOSSY_COBBLESTONE)
B(19,10,16,STONE)
B(20,10,16,MOSSY_COBBLESTONE)
B(21,10,16,MOSSY_COBBLESTONE)
B(22,10,16,MOSSY_COBBLESTONE)
B(23,10,16,STONE)
B(24,10,16,STONEBRICK)
B(0,11,16,STONEBRICK)
B(1,11,16,MOSSY_COBBLESTONE)
B(2,11,16,MOSSY_COBBLESTONE)
B(3,11,16,STONEBRICK:1)
B(5,11,16,STONEBRICK:2)
B(6,11,16,STONE)
B(7,11,16,EMERALD_ORE)
B(8,11,16,STONEBRICK)
B(9,11,16,MOSSY_COBBLESTONE)
B(10,11,16,STONE)
B(11,11,16,MOSSY_COBBLESTONE)
B(12,11,16,MOSSY_COBBLESTONE)
B(13,11,16,EMERALD_ORE)
B(14,11,16,STONE)
B(15,11,16,STONE)
B(16,11,16,STONEBRICK:2)
B(17,11,16,STONE)
B(18,11,16,STONE)
B(19,11,16,STONE)
B(20,11,16,MOSSY_COBBLESTONE)
B(21,11,16,STONE)
B(22,11,16,STONE)
B(23,11,16,MOSSY_COBBLESTONE)
B(24,11,16,STONEBRICK:2)
B(0,12,16,STONEBRICK:2)
B(1,12,16,MOSSY_COBBLESTONE)
B(2,12,16,EMERALD_ORE)
B(3,12,16,STONEBRICK:3)
B(4,12,16,STONEBRICK:3)
B(5,12,16,STONEBRICK:3)
B(6,12,16,STONE)
B(7,12,16,MOSSY_COBBLESTONE)
B(8,12,16,STONEBRICK:1)
B(9,12,16,STONE)
B(10,12,16,STONE)
B(11,12,16,STONE)
B(12,12,16,STONE)
B(13,12,16,STONE)
B(14,12,16,MOSSY_COBBLESTONE)
B(15,12,16,MOSSY_COBBLESTONE)
B(16,12,16,STONEBRICK)
B(17,12,16,MOSSY_COBBLESTONE)
B(18,12,16,STONE)
B(19,12,16,MOSSY_COBBLESTONE)
B(20,12,16,STONE)
B(21,12,16,STONE)
B(22,12,16,MOSSY_COBBLESTONE)
B(23,12,16,EMERALD_ORE)
B(24,12,16,STONEBRICK:1)
B(0,13,16,STONEBRICK:2)
B(1,13,16,STONE)
B(2,13,16,MOSSY_COBBLESTONE)
B(3,13,16,STONE)
B(4,13,16,MOSSY_COBBLESTONE)
B(5,13,16,MOSSY_COBBLESTONE)
B(6,13,16,STONE)
B(7,13,16,MOSSY_COBBLESTONE)
B(8,13,16,STONEBRICK)
B(9,13,16,MOSSY_COBBLESTONE)
B(10,13,16,MOSSY_COBBLESTONE)
B(11,13,16,MOSSY_COBBLESTONE)
B(12,13,16,MOSSY_COBBLESTONE)
B(13,13,16,STONE)
B(14,13,16,STONE)
B(15,13,16,MOSSY_COBBLESTONE)
B(16,13,16,STONEBRICK)
B(17,13,16,MOSSY_COBBLESTONE)
B(18,13,16,MOSSY_COBBLESTONE)
B(19,13,16,MOSSY_COBBLESTONE)
B(20,13,16,MOSSY_COBBLESTONE)
B(21,13,16,MOSSY_COBBLESTONE)
B(22,13,16,STONE)
B(23,13,16,STONE)
B(24,13,16,STONEBRICK:1)
B(0,14,16,STONEBRICK)
B(1,14,16,MOSSY_COBBLESTONE)
B(2,14,16,MOSSY_COBBLESTONE)
B(3,14,16,STONE)
B(4,14,16,MOSSY_COBBLESTONE)
B(5,14,16,STONE)
B(6,14,16,STONE)
B(7,14,16,MOSSY_COBBLESTONE)
B(8,14,16,STONEBRICK)
B(9,14,16,STONE)
B(10,14,16,MOSSY_COBBLESTONE)
B(11,14,16,STONE)
B(12,14,16,STONE)
B(13,14,16,MOSSY_COBBLESTONE)
B(14,14,16,MOSSY_COBBLESTONE)
B(15,14,16,STONE)
B(16,14,16,STONEBRICK:1)
B(17,14,16,STONE)
B(18,14,16,MOSSY_COBBLESTONE)
B(19,14,16,MOSSY_COBBLESTONE)
B(20,14,16,MOSSY_COBBLESTONE)
B(21,14,16,EMERALD_ORE)
B(22,14,16,MOSSY_COBBLESTONE)
B(23,14,16,STONE)
B(24,14,16,STONEBRICK:2)
B(0,15,16,STONEBRICK:2)
B(1,15,16,STONE)
B(2,15,16,MOSSY_COBBLESTONE)
B(3,15,16,STONE)
B(4,15,16,STONE)
B(5,15,16,MOSSY_COBBLESTONE)
B(6,15,16,STONE)
B(7,15,16,MOSSY_COBBLESTONE)
B(8,15,16,STONEBRICK:2)
B(9,15,16,MOSSY_COBBLESTONE)
B(10,15,16,EMERALD_ORE)
B(11,15,16,STONE)
B(12,15,16,MOSSY_COBBLESTONE)
B(13,15,16,STONE)
B(14,15,16,EMERALD_ORE)
B(15,15,16,MOSSY_COBBLESTONE)
B(16,15,16,STONEBRICK:1)
B(17,15,16,MOSSY_COBBLESTONE)
B(18,15,16,STONE)
B(19,15,16,STONE)
B(20,15,16,STONE)
B(21,15,16,MOSSY_COBBLESTONE)
B(22,15,16,MOSSY_COBBLESTONE)
B(23,15,16,STONE)
B(24,15,16,STONEBRICK:2)
B(0,16,16,STONEBRICK:1)
B(1,16,16,STONEBRICK:1)
B(2,16,16,STONEBRICK)
B(3,16,16,STONEBRICK)
B(4,16,16,STONEBRICK)
B(5,16,16,STONEBRICK:2)
B(6,16,16,STONEBRICK)
B(7,16,16,STONEBRICK:1)
B(8,16,16,STONEBRICK:2)
B(9,16,16,STONEBRICK:2)
B(10,16,16,STONEBRICK:1)
B(11,16,16,STONEBRICK:1)
B(12,16,16,STONEBRICK:1)
B(13,16,16,STONEBRICK:2)
B(14,16,16,STONEBRICK:2)
B(15,16,16,STONEBRICK:2)
B(16,16,16,STONEBRICK:2)
B(17,16,16,STONEBRICK:2)
B(18,16,16,STONEBRICK:1)
B(19,16,16,STONEBRICK)
B(20,16,16,STONEBRICK)
B(21,16,16,STONEBRICK:1)
B(22,16,16,STONEBRICK:1)
B(23,16,16,STONEBRICK)
B(24,16,16,STONEBRICK:2)
B(19,0,17,STONEBRICK)
B(20,0,17,STONEBRICK)
B(21,0,17,STONEBRICK)
B(19,1,17,STONEBRICK:2)
B(21,1,17,STONEBRICK:2)
B(19,2,17,STONEBRICK:1)
B(21,2,17,STONEBRICK:1)
B(19,3,17,STONEBRICK:1)
B(21,3,17,STONEBRICK:2)
B(8,4,17,STONEBRICK)
B(9,4,17,STONEBRICK)
B(10,4,17,STONEBRICK:1)
B(11,4,17,STONEBRICK:2)
B(12,4,17,STONEBRICK:1)
B(13,4,17,STONEBRICK:2)
B(14,4,17,STONEBRICK:1)
B(15,4,17,STONEBRICK)
B(16,4,17,STONEBRICK:1)
B(19,4,17,STONEBRICK:1)
B(21,4,17,STONEBRICK:2)
B(8,5,17,EMERALD_ORE)
B(9,5,17,MOSSY_COBBLESTONE)
B(15,5,17,STONE)
B(16,5,17,MOSSY_COBBLESTONE)
B(19,5,17,STONEBRICK)
B(20,5,17,STONEBRICK:1)
B(21,5,17,STONEBRICK:1)
B(8,6,17,STONE)
B(9,6,17,STONE)
B(15,6,17,MOSSY_COBBLESTONE)
B(16,6,17,STONE)
B(3,7,17,STONEBRICK:2)
B(4,7,17,STONEBRICK)
B(5,7,17,STONEBRICK:2)
B(8,7,17,STONE)
B(9,7,17,MOSSY_COBBLESTONE)
B(15,7,17,MOSSY_COBBLESTONE)
B(16,7,17,MOSSY_COBBLESTONE)
B(3,8,17,STONEBRICK)
B(5,8,17,STONEBRICK)
B(8,8,17,STONE)
B(9,8,17,STONEBRICK:3)
B(15,8,17,STONEBRICK:3)
B(16,8,17,MOSSY_COBBLESTONE)
B(3,9,17,STONEBRICK)
B(5,9,17,STONEBRICK)
B(8,9,17,STONE)
B(9,9,17,STONEBRICK:1)
B(15,9,17,STONEBRICK:2)
B(16,9,17,MOSSY_COBBLESTONE)
B(3,10,17,STONEBRICK:1)
B(5,10,17,STONEBRICK)
B(8,10,17,MOSSY_COBBLESTONE)
B(9,10,17,STONEBRICK:2)
B(15,10,17,STONEBRICK:1)
B(16,10,17,MOSSY_COBBLESTONE)
B(3,11,17,STONEBRICK:2)
B(5,11,17,STONEBRICK)
B(8,11,17,STONE)
B(9,11,17,STONEBRICK:2)
B(10,11,17,STONEBRICK:2)
B(11,11,17,STONEBRICK:2)
B(12,11,17,STONEBRICK:2)
B(13,11,17,STONEBRICK:2)
B(14,11,17,STONEBRICK:1)
B(15,11,17,STONEBRICK:1)
B(16,11,17,MOSSY_COBBLESTONE)
B(3,12,17,STONEBRICK:2)
B(4,12,17,STONEBRICK:2)
B(5,12,17,STONEBRICK)
B(8,12,17,STONEBRICK:1)
B(9,12,17,MOSSY_COBBLESTONE)
B(10,12,17,EMERALD_ORE)
B(11,12,17,STONE)
B(12,12,17,STONE)
B(13,12,17,MOSSY_COBBLESTONE)
B(14,12,17,STONE)
B(15,12,17,STONE)
B(16,12,17,STONEBRICK)
B(19,1,18,STONEBRICK:2)
B(20,1,18,STONEBRICK)
B(21,1,18,STONEBRICK:1)
B(19,2,18,STONEBRICK:2)
B(21,2,18,STONEBRICK:1)
B(19,3,18,STONEBRICK)
B(21,3,18,STONEBRICK)
B(8,4,18,STONEBRICK:2)
B(9,4,18,STONEBRICK:1)
B(10,4,18,STONEBRICK:1)
B(11,4,18,STONEBRICK)
B(12,4,18,STONEBRICK:2)
B(13,4,18,STONEBRICK)
B(14,4,18,STONEBRICK:2)
B(15,4,18,STONEBRICK:1)
B(16,4,18,STONEBRICK:2)
B(19,4,18,STONEBRICK:1)
B(21,4,18,STONEBRICK:1)
B(8,5,18,STONE)
B(16,5,18,MOSSY_COBBLESTONE)
B(19,5,18,STONEBRICK:2)
B(20,5,18,STONEBRICK:1)
B(21,5,18,STONEBRICK:1)
B(8,6,18,STONE)
B(16,6,18,STONE)
B(3,7,18,STONEBRICK:1)
B(4,7,18,STONEBRICK)
B(5,7,18,STONEBRICK:1)
B(8,7,18,EMERALD_ORE)
B(16,7,18,STONE)
B(3,8,18,STONEBRICK:1)
B(5,8,18,STONEBRICK:2)
B(8,8,18,MOSSY_COBBLESTONE)
B(16,8,18,STONE)
B(3,9,18,STONEBRICK:2)
B(5,9,18,STONEBRICK:2)
B(8,9,18,MOSSY_COBBLESTONE)
B(16,9,18,MOSSY_COBBLESTONE)
B(3,10,18,STONEBRICK)
B(5,10,18,STONEBRICK:1)
B(8,10,18,STONE)
B(16,10,18,MOSSY_COBBLESTONE)
B(3,11,18,STONEBRICK:2)
B(4,11,18,STONEBRICK:2)
B(5,11,18,STONEBRICK:1)
B(8,11,18,EMERALD_ORE)
B(9,11,18,STONEBRICK:2)
B(15,11,18,STONEBRICK:2)
B(16,11,18,STONE)
B(8,12,18,STONEBRICK:1)
B(9,12,18,MOSSY_COBBLESTONE)
B(10,12,18,STONEBRICK)
B(11,12,18,STONEBRICK:2)
B(12,12,18,STONEBRICK)
B(13,12,18,STONEBRICK:2)
B(14,12,18,STONEBRICK:1)
B(15,12,18,STONE)
B(16,12,18,STONEBRICK:2)
B(19,1,19,STONEBRICK)
B(20,1,19,STONEBRICK:1)
B(21,1,19,STONEBRICK:1)
B(19,2,19,STONEBRICK)
B(21,2,19,STONEBRICK:2)
B(17,3,19,STONEBRICK:2)
B(18,3,19,STONEBRICK)
B(19,3,19,STONEBRICK)
B(21,3,19,STONEBRICK:1)
B(7,4,19,STONEBRICK:1)
B(8,4,19,STONEBRICK:2)
B(9,4,19,STONEBRICK:1)
B(10,4,19,STONEBRICK:1)
B(11,4,19,DIRT:1)
B(12,4,19,GRASS)
B(13,4,19,DIRT:1)
B(14,4,19,STONEBRICK:2)
B(15,4,19,STONEBRICK:1)
B(16,4,19,STONEBRICK:1)
B(17,4,19,STONEBRICK)
B(18,4,19,STONEBRICK:2)
B(19,4,19,STONEBRICK:1)
B(21,4,19,STONEBRICK:1)
B(5,5,19,STONEBRICK:2)
B(6,5,19,STONEBRICK:2)
B(7,5,19,STONEBRICK:2)
B(8,5,19,STONEBRICK:2)
B(16,5,19,STONEBRICK:2)
B(17,5,19,STONEBRICK)
B(18,5,19,STONEBRICK)
B(19,5,19,STONEBRICK:2)
B(21,5,19,STONEBRICK:1)
B(3,6,19,STONEBRICK:1)
B(4,6,19,STONEBRICK:2)
B(5,6,19,STONEBRICK)
B(6,6,19,STONEBRICK:1)
B(7,6,19,STONEBRICK:1)
B(8,6,19,STONEBRICK:1)
B(16,6,19,STONEBRICK:2)
B(17,6,19,STONEBRICK:1)
B(18,6,19,STONEBRICK)
B(19,6,19,STONEBRICK:1)
B(20,6,19,STONEBRICK:2)
B(21,6,19,STONEBRICK:2)
B(3,7,19,STONEBRICK:1)
B(5,7,19,STONEBRICK:1)
B(6,7,19,STONEBRICK:2)
B(7,7,19,STONEBRICK:2)
B(8,7,19,STONEBRICK)
B(16,7,19,STONEBRICK:1)
B(17,7,19,STONEBRICK:1)
B(18,7,19,STONEBRICK:1)
B(19,7,19,STONEBRICK)
B(3,8,19,STONEBRICK:1)
B(5,8,19,STONEBRICK:1)
B(6,8,19,STONEBRICK)
B(7,8,19,STONEBRICK:2)
B(8,8,19,STONEBRICK:3)
B(16,8,19,STONEBRICK:3)
B(17,8,19,STONEBRICK:1)
B(3,9,19,STONEBRICK)
B(5,9,19,STONEBRICK:2)
B(6,9,19,STONEBRICK:1)
B(7,9,19,STONEBRICK:1)
B(8,9,19,STONE)
B(16,9,19,MOSSY_COBBLESTONE)
B(3,10,19,STONEBRICK:2)
B(5,10,19,STONEBRICK)
B(8,10,19,STONE)
B(16,10,19,STONE)
B(3,11,19,STONEBRICK:1)
B(4,11,19,STONEBRICK:1)
B(5,11,19,STONEBRICK:1)
B(8,11,19,MOSSY_COBBLESTONE)
B(9,11,19,STONEBRICK)
B(15,11,19,STONEBRICK:1)
B(16,11,19,MOSSY_COBBLESTONE)
B(8,12,19,STONEBRICK:1)
B(9,12,19,MOSSY_COBBLESTONE)
B(10,12,19,STONEBRICK:1)
B(14,12,19,STONEBRICK:1)
B(15,12,19,MOSSY_COBBLESTONE)
B(16,12,19,STONEBRICK)
B(19,2,20,STONEBRICK)
B(20,2,20,STONEBRICK:1)
B(21,2,20,STONEBRICK:2)
B(17,3,20,STONEBRICK)
B(18,3,20,STONEBRICK:2)
B(21,3,20,STONEBRICK:1)
B(7,4,20,STONEBRICK:1)
B(8,4,20,STONEBRICK)
B(9,4,20,STONEBRICK)
B(10,4,20,STONEBRICK)
B(11,4,20,GRASS)
B(12,4,20,GRASS)
B(13,4,20,DIRT:1)
B(14,4,20,STONEBRICK:1)
B(15,4,20,STONEBRICK:1)
B(16,4,20,STONEBRICK)
B(21,4,20,STONEBRICK:2)
B(5,5,20,STONEBRICK:1)
B(6,5,20,STONEBRICK:2)
B(21,5,20,STONEBRICK:2)
B(3,6,20,STONEBRICK:1)
B(4,6,20,STONEBRICK:1)
B(20,6,20,STONEBRICK)
B(21,6,20,STONEBRICK:1)
B(3,7,20,STONEBRICK:1)
B(18,7,20,STONEBRICK)
B(19,7,20,STONEBRICK:1)
B(3,8,20,STONEBRICK:2)
B(8,8,20,STONEBRICK:3)
B(16,8,20,STONEBRICK:3)
B(17,8,20,STONEBRICK)
B(3,9,20,STONEBRICK)
B(6,9,20,STONEBRICK:1)
B(7,9,20,STONEBRICK)
B(8,9,20,MOSSY_COBBLESTONE)
B(16,9,20,EMERALD_ORE)
B(3,10,20,STONEBRICK)
B(4,10,20,STONEBRICK)
B(5,10,20,STONEBRICK)
B(8,10,20,STONE)
B(16,10,20,STONE)
B(8,11,20,MOSSY_COBBLESTONE)
B(9,11,20,STONEBRICK:2)
B(15,11,20,STONEBRICK)
B(16,11,20,STONE)
B(8,12,20,STONEBRICK)
B(9,12,20,STONE)
B(10,12,20,STONEBRICK)
B(14,12,20,STONEBRICK:2)
B(15,12,20,STONE)
B(16,12,20,STONEBRICK:2)
B(19,2,21,STONEBRICK:2)
B(20,2,21,STONEBRICK:2)
B(21,2,21,STONEBRICK:2)
B(17,3,21,STONEBRICK:2)
B(18,3,21,STONEBRICK)
B(19,3,21,STONEBRICK:2)
B(20,3,21,STONEBRICK:1)
B(21,3,21,STONEBRICK)
B(7,4,21,STONEBRICK)
B(8,4,21,STONEBRICK:1)
B(9,4,21,STONEBRICK:2)
B(10,4,21,STONEBRICK:2)
B(11,4,21,DIRT:1)
B(12,4,21,DIRT:1)
B(13,4,21,DIRT:1)
B(14,4,21,STONEBRICK:2)
B(15,4,21,STONEBRICK)
B(16,4,21,STONEBRICK:2)
B(17,4,21,STONEBRICK)
B(18,4,21,STONEBRICK)
B(19,4,21,STONEBRICK:2)
B(20,4,21,STONEBRICK:2)
B(21,4,21,STONEBRICK:2)
B(5,5,21,STONEBRICK:2)
B(6,5,21,STONEBRICK:2)
B(7,5,21,STONEBRICK:1)
B(8,5,21,STONEBRICK:1)
B(16,5,21,STONEBRICK)
B(17,5,21,STONEBRICK:2)
B(18,5,21,STONEBRICK)
B(19,5,21,STONEBRICK)
B(20,5,21,STONEBRICK:1)
B(21,5,21,STONEBRICK:2)
B(3,6,21,STONEBRICK)
B(4,6,21,STONEBRICK)
B(5,6,21,STONEBRICK:2)
B(6,6,21,STONEBRICK)
B(7,6,21,STONEBRICK)
B(8,6,21,STONEBRICK)
B(16,6,21,STONEBRICK:2)
B(17,6,21,STONEBRICK:2)
B(18,6,21,STONEBRICK:2)
B(19,6,21,STONEBRICK:1)
B(20,6,21,STONEBRICK)
B(21,6,21,STONEBRICK:2)
B(3,7,21,STONEBRICK:2)
B(4,7,21,STONEBRICK:1)
B(5,7,21,STONEBRICK:1)
B(6,7,21,STONEBRICK:2)
B(7,7,21,STONEBRICK)
B(8,7,21,STONEBRICK:2)
B(16,7,21,STONEBRICK:2)
B(17,7,21,STONEBRICK)
B(18,7,21,STONEBRICK)
B(19,7,21,STONEBRICK:1)
B(3,8,21,STONEBRICK)
B(4,8,21,STONEBRICK)
B(5,8,21,STONEBRICK:2)
B(6,8,21,STONEBRICK)
B(7,8,21,STONEBRICK)
B(8,8,21,STONEBRICK:3)
B(16,8,21,STONEBRICK:3)
B(17,8,21,STONEBRICK)
B(3,9,21,STONEBRICK:2)
B(4,9,21,STONEBRICK:1)
B(5,9,21,STONEBRICK:2)
B(6,9,21,STONEBRICK)
B(7,9,21,STONEBRICK)
B(8,9,21,MOSSY_COBBLESTONE)
B(16,9,21,MOSSY_COBBLESTONE)
B(3,10,21,STONEBRICK:2)
B(4,10,21,STONEBRICK)
B(5,10,21,STONEBRICK)
B(8,10,21,MOSSY_COBBLESTONE)
B(16,10,21,STONE)
B(8,11,21,MOSSY_COBBLESTONE)
B(9,11,21,STONEBRICK:2)
B(15,11,21,STONEBRICK:1)
B(16,11,21,STONE)
B(8,12,21,STONEBRICK:1)
B(9,12,21,MOSSY_COBBLESTONE)
B(10,12,21,STONEBRICK:1)
B(14,12,21,STONEBRICK)
B(15,12,21,STONE)
B(16,12,21,STONEBRICK)
B(8,4,22,STONEBRICK:1)
B(9,4,22,STONEBRICK:1)
B(10,4,22,STONEBRICK)
B(11,4,22,STONEBRICK:2)
B(12,4,22,STONEBRICK:2)
B(13,4,22,STONEBRICK)
B(14,4,22,STONEBRICK:1)
B(15,4,22,STONEBRICK:2)
B(16,4,22,STONEBRICK)
B(8,5,22,STONE)
B(16,5,22,MOSSY_COBBLESTONE)
B(8,6,22,MOSSY_COBBLESTONE)
B(16,6,22,STONE)
B(8,7,22,MOSSY_COBBLESTONE)
B(16,7,22,MOSSY_COBBLESTONE)
B(8,8,22,MOSSY_COBBLESTONE)
B(16,8,22,EMERALD_ORE)
B(8,9,22,STONE)
B(16,9,22,MOSSY_COBBLESTONE)
B(8,10,22,STONE)
B(16,10,22,STONE)
B(8,11,22,MOSSY_COBBLESTONE)
B(9,11,22,STONEBRICK:2)
B(15,11,22,STONEBRICK:2)
B(16,11,22,MOSSY_COBBLESTONE)
B(8,12,22,STONEBRICK)
B(9,12,22,STONE)
B(10,12,22,STONEBRICK:2)
B(11,12,22,STONEBRICK:1)
B(12,12,22,STONEBRICK:1)
B(13,12,22,STONEBRICK)
B(14,12,22,STONEBRICK)
B(15,12,22,STONE)
B(16,12,22,STONEBRICK)
B(8,4,23,STONEBRICK:1)
B(9,4,23,STONEBRICK:1)
B(10,4,23,STONEBRICK:1)
B(11,4,23,STONEBRICK)
B(12,4,23,STONEBRICK:1)
B(13,4,23,STONEBRICK:1)
B(14,4,23,STONEBRICK)
B(15,4,23,STONEBRICK:1)
B(16,4,23,STONEBRICK:1)
B(8,5,23,STONE)
B(9,5,23,STONE)
B(15,5,23,STONE)
B(16,5,23,STONE)
B(8,6,23,STONE)
B(9,6,23,MOSSY_COBBLESTONE)
B(15,6,23,MOSSY_COBBLESTONE)
B(16,6,23,MOSSY_COBBLESTONE)
B(8,7,23,STONE)
B(9,7,23,MOSSY_COBBLESTONE)
B(15,7,23,MOSSY_COBBLESTONE)
B(16,7,23,MOSSY_COBBLESTONE)
B(8,8,23,MOSSY_COBBLESTONE)
B(9,8,23,STONEBRICK:3)
B(15,8,23,STONEBRICK:3)
B(16,8,23,EMERALD_ORE)
B(8,9,23,MOSSY_COBBLESTONE)
B(9,9,23,STONEBRICK:2)
B(15,9,23,STONEBRICK)
B(16,9,23,STONE)
B(8,10,23,MOSSY_COBBLESTONE)
B(9,10,23,STONEBRICK:2)
B(15,10,23,STONEBRICK:1)
B(16,10,23,STONE)
B(8,11,23,STONE)
B(9,11,23,STONEBRICK:1)
B(10,11,23,STONEBRICK:1)
B(11,11,23,STONEBRICK)
B(12,11,23,STONEBRICK:2)
B(13,11,23,STONEBRICK)
B(14,11,23,STONEBRICK:2)
B(15,11,23,STONEBRICK)
B(16,11,23,STONE)
B(8,12,23,STONEBRICK:2)
B(9,12,23,EMERALD_ORE)
B(10,12,23,STONE)
B(11,12,23,STONE)
B(12,12,23,STONE)
B(13,12,23,STONE)
B(14,12,23,MOSSY_COBBLESTONE)
B(15,12,23,STONE)
B(16,12,23,STONEBRICK:2)
B(8,4,24,STONEBRICK)
B(9,4,24,STONEBRICK)
B(10,4,24,STONEBRICK:2)
B(11,4,24,STONEBRICK:1)
B(12,4,24,STONEBRICK:1)
B(13,4,24,STONEBRICK:1)
B(14,4,24,STONEBRICK:2)
B(15,4,24,STONEBRICK:1)
B(16,4,24,STONEBRICK:1)
B(8,5,24,STONEBRICK:2)
B(9,5,24,MOSSY_COBBLESTONE)
B(10,5,24,STONE)
B(11,5,24,STONE)
B(12,5,24,MOSSY_COBBLESTONE)
B(13,5,24,STONE)
B(14,5,24,STONE)
B(15,5,24,STONE)
B(16,5,24,STONEBRICK)
B(8,6,24,STONEBRICK)
B(9,6,24,MOSSY_COBBLESTONE)
B(10,6,24,MOSSY_COBBLESTONE)
B(11,6,24,STONE)
B(12,6,24,EMERALD_ORE)
B(13,6,24,MOSSY_COBBLESTONE)
B(14,6,24,STONE)
B(15,6,24,MOSSY_COBBLESTONE)
B(16,6,24,STONEBRICK)
B(8,7,24,STONEBRICK:2)
B(9,7,24,STONE)
B(10,7,24,STONE)
B(11,7,24,STONE)
B(12,7,24,MOSSY_COBBLESTONE)
B(13,7,24,MOSSY_COBBLESTONE)
B(14,7,24,STONE)
B(15,7,24,MOSSY_COBBLESTONE)
B(16,7,24,STONEBRICK:1)
B(8,8,24,STONEBRICK:1)
B(9,8,24,MOSSY_COBBLESTONE)
B(10,8,24,STONE)
B(11,8,24,MOSSY_COBBLESTONE)
B(12,8,24,MOSSY_COBBLESTONE)
B(13,8,24,MOSSY_COBBLESTONE)
B(14,8,24,MOSSY_COBBLESTONE)
B(15,8,24,MOSSY_COBBLESTONE)
B(16,8,24,STONEBRICK:2)
B(8,9,24,STONEBRICK)
B(9,9,24,MOSSY_COBBLESTONE)
B(10,9,24,MOSSY_COBBLESTONE)
B(11,9,24,MOSSY_COBBLESTONE)
B(12,9,24,MOSSY_COBBLESTONE)
B(13,9,24,STONE)
B(14,9,24,STONE)
B(15,9,24,STONE)
B(16,9,24,STONEBRICK)
B(8,10,24,STONEBRICK:2)
B(9,10,24,MOSSY_COBBLESTONE)
B(10,10,24,MOSSY_COBBLESTONE)
B(11,10,24,STONE)
B(12,10,24,MOSSY_COBBLESTONE)
B(13,10,24,STONE)
B(14,10,24,STONE)
B(15,10,24,STONE)
B(16,10,24,STONEBRICK)
B(8,11,24,STONEBRICK)
B(9,11,24,MOSSY_COBBLESTONE)
B(10,11,24,MOSSY_COBBLESTONE)
B(11,11,24,MOSSY_COBBLESTONE)
B(12,11,24,STONE)
B(13,11,24,STONE)
B(14,11,24,MOSSY_COBBLESTONE)
B(15,11,24,STONE)
B(16,11,24,STONEBRICK)
B(8,12,24,STONEBRICK:1)
B(9,12,24,STONEBRICK:1)
B(10,12,24,STONEBRICK:2)
B(11,12,24,STONEBRICK:2)
B(12,12,24,STONEBRICK)
B(13,12,24,STONEBRICK)
B(14,12,24,STONEBRICK:1)
B(15,12,24,STONEBRICK:1)
B(16,12,24,STONEBRICK:2)
B(10,5,1,AIR)
B(11,5,1,AIR)
B(13,5,1,AIR)
B(14,5,1,AIR)
B(10,6,1,AIR)
B(11,6,1,AIR)
B(12,6,1,AIR)
B(13,6,1,AIR)
B(14,6,1,AIR)
B(10,7,1,AIR)
B(11,7,1,AIR)
B(12,7,1,AIR)
B(13,7,1,AIR)
B(14,7,1,AIR)
B(10,8,1,AIR)
B(11,8,1,AIR)
B(12,8,1,AIR)
B(13,8,1,AIR)
B(14,8,1,AIR)
B(10,9,1,AIR)
B(11,9,1,AIR)
B(12,9,1,AIR)
B(13,9,1,AIR)
B(14,9,1,AIR)
B(10,10,1,STONE_BRICK_STAIRS:5)
B(11,10,1,AIR)
B(12,10,1,AIR)
B(13,10,1,AIR)
B(14,10,1,STONE_BRICK_STAIRS:4)
B(9,5,2,AIR)
B(10,5,2,AIR)
B(11,5,2,AIR)
B(12,5,2,AIR)
B(13,5,2,AIR)
B(14,5,2,AIR)
B(15,5,2,AIR)
B(9,6,2,AIR)
B(10,6,2,AIR)
B(11,6,2,AIR)
B(12,6,2,AIR)
B(13,6,2,AIR)
B(14,6,2,AIR)
B(15,6,2,AIR)
B(9,7,2,AIR)
B(10,7,2,AIR)
B(11,7,2,AIR)
B(12,7,2,AIR)
B(13,7,2,AIR)
B(14,7,2,AIR)
B(15,7,2,AIR)
B(9,8,2,AIR)
B(10,8,2,AIR)
B(11,8,2,AIR)
B(12,8,2,AIR)
B(13,8,2,AIR)
B(14,8,2,AIR)
B(15,8,2,AIR)
B(9,9,2,AIR)
B(10,9,2,AIR)
B(11,9,2,AIR)
B(12,9,2,AIR)
B(13,9,2,AIR)
B(14,9,2,AIR)
B(15,9,2,AIR)
B(9,10,2,STONE_BRICK_STAIRS:7)
B(10,10,2,AIR)
B(11,10,2,AIR)
B(12,10,2,AIR)
B(13,10,2,AIR)
B(14,10,2,AIR)
B(15,10,2,STONE_BRICK_STAIRS:7)
B(10,11,2,AIR)
B(11,11,2,AIR)
B(12,11,2,AIR)
B(13,11,2,AIR)
B(14,11,2,AIR)
B(9,5,3,AIR)
B(10,5,3,AIR)
B(11,5,3,AIR)
B(12,5,3,TALLGRASS:1)
B(13,5,3,TALLGRASS:1)
B(14,5,3,AIR)
B(15,5,3,AIR)
B(9,6,3,AIR)
B(10,6,3,AIR)
B(11,6,3,AIR)
B(12,6,3,AIR)
B(13,6,3,AIR)
B(14,6,3,AIR)
B(15,6,3,AIR)
B(9,7,3,AIR)
B(10,7,3,AIR)
B(11,7,3,AIR)
B(12,7,3,AIR)
B(13,7,3,AIR)
B(14,7,3,AIR)
B(15,7,3,AIR)
B(9,8,3,AIR)
B(10,8,3,AIR)
B(11,8,3,AIR)
B(12,8,3,AIR)
B(13,8,3,AIR)
B(14,8,3,AIR)
B(15,8,3,AIR)
B(9,9,3,AIR)
B(10,9,3,AIR)
B(11,9,3,AIR)
B(12,9,3,AIR)
B(13,9,3,AIR)
B(14,9,3,AIR)
B(15,9,3,AIR)
B(9,10,3,AIR)
B(10,10,3,AIR)
B(11,10,3,AIR)
B(12,10,3,AIR)
B(13,10,3,AIR)
B(14,10,3,AIR)
B(15,10,3,AIR)
B(10,11,3,AIR)
B(11,11,3,AIR)
B(12,11,3,AIR)
B(13,11,3,AIR)
B(14,11,3,AIR)
B(11,12,3,AIR)
B(12,12,3,AIR)
B(13,12,3,AIR)
B(4,3,4,AIR)
B(5,3,4,STONE_SLAB)
B(4,4,4,AIR)
B(5,4,4,AIR)
B(6,4,4,AIR)
B(7,4,4,STONE_SLAB)
B(4,5,4,AIR)
B(5,5,4,AIR)
B(6,5,4,AIR)
B(7,5,4,AIR)
B(8,5,4,AIR)
B(9,5,4,AIR)
B(10,5,4,AIR)
B(11,5,4,TALLGRASS:2)
B(13,5,4,AIR)
B(14,5,4,AIR)
B(15,5,4,AIR)
B(16,5,4,AIR)
B(17,5,4,STONE_SLAB)
B(5,6,4,STONE_SLAB)
B(6,6,4,AIR)
B(7,6,4,AIR)
B(8,6,4,AIR)
B(9,6,4,AIR)
B(10,6,4,AIR)
B(11,6,4,AIR)
B(12,6,4,AIR)
B(13,6,4,AIR)
B(14,6,4,AIR)
B(15,6,4,AIR)
B(16,6,4,AIR)
B(17,6,4,AIR)
B(18,6,4,AIR)
B(19,6,4,STONE_SLAB)
B(7,7,4,STONE_SLAB)
B(8,7,4,AIR)
B(9,7,4,AIR)
B(10,7,4,AIR)
B(11,7,4,AIR)
B(12,7,4,AIR)
B(13,7,4,AIR)
B(14,7,4,AIR)
B(15,7,4,AIR)
B(16,7,4,AIR)
B(17,7,4,AIR)
B(18,7,4,AIR)
B(19,7,4,AIR)
B(20,7,4,AIR)
B(9,8,4,AIR)
B(10,8,4,AIR)
B(11,8,4,AIR)
B(12,8,4,AIR)
B(13,8,4,AIR)
B(14,8,4,AIR)
B(15,8,4,AIR)
B(17,8,4,STONE_SLAB)
B(18,8,4,AIR)
B(19,8,4,AIR)
B(20,8,4,AIR)
B(9,9,4,AIR)
B(10,9,4,AIR)
B(11,9,4,AIR)
B(12,9,4,AIR)
B(13,9,4,AIR)
B(14,9,4,AIR)
B(15,9,4,AIR)
B(19,9,4,STONE_SLAB)
B(20,9,4,AIR)
B(9,10,4,AIR)
B(10,10,4,AIR)
B(11,10,4,AIR)
B(12,10,4,AIR)
B(13,10,4,AIR)
B(14,10,4,AIR)
B(15,10,4,AIR)
B(10,11,4,AIR)
B(11,11,4,AIR)
B(12,11,4,AIR)
B(13,11,4,AIR)
B(14,11,4,AIR)
B(11,12,4,AIR)
B(12,12,4,AIR)
B(13,12,4,AIR)
B(4,2,5,STONE_SLAB)
B(4,3,5,AIR)
B(4,4,5,AIR)
B(4,5,5,STONE_SLAB)
B(9,5,5,AIR)
B(10,5,5,AIR)
B(11,5,5,AIR)
B(12,5,5,TALLGRASS:2)
B(13,5,5,TALLGRASS:2)
B(14,5,5,AIR)
B(15,5,5,AIR)
B(9,6,5,AIR)
B(10,6,5,AIR)
B(11,6,5,AIR)
B(12,6,5,AIR)
B(13,6,5,AIR)
B(14,6,5,AIR)
B(15,6,5,AIR)
B(9,7,5,AIR)
B(10,7,5,AIR)
B(11,7,5,AIR)
B(12,7,5,AIR)
B(13,7,5,AIR)
B(14,7,5,AIR)
B(15,7,5,AIR)
B(20,7,5,STONE_SLAB)
B(9,8,5,AIR)
B(10,8,5,AIR)
B(11,8,5,AIR)
B(12,8,5,AIR)
B(13,8,5,AIR)
B(14,8,5,AIR)
B(15,8,5,AIR)
B(20,8,5,AIR)
B(9,9,5,AIR)
B(10,9,5,AIR)
B(11,9,5,AIR)
B(12,9,5,AIR)
B(13,9,5,AIR)
B(14,9,5,AIR)
B(15,9,5,AIR)
B(20,9,5,AIR)
B(9,10,5,AIR)
B(10,10,5,AIR)
B(11,10,5,AIR)
B(12,10,5,AIR)
B(13,10,5,AIR)
B(14,10,5,AIR)
B(15,10,5,AIR)
B(20,10,5,STONE_SLAB)
B(10,11,5,AIR)
B(11,11,5,AIR)
B(12,11,5,AIR)
B(13,11,5,AIR)
B(14,11,5,AIR)
B(11,12,5,AIR)
B(12,12,5,AIR)
B(13,12,5,AIR)
B(4,2,6,AIR)
B(4,3,6,AIR)
B(4,4,6,AIR)
B(9,5,6,AIR)
B(10,5,6,AIR)
B(11,5,6,AIR)
B(12,5,6,AIR)
B(13,5,6,AIR)
B(14,5,6,AIR)
B(15,5,6,AIR)
B(9,6,6,AIR)
B(10,6,6,AIR)
B(11,6,6,AIR)
B(12,6,6,AIR)
B(13,6,6,AIR)
B(14,6,6,AIR)
B(15,6,6,AIR)
B(9,7,6,AIR)
B(10,7,6,AIR)
B(11,7,6,AIR)
B(12,7,6,AIR)
B(13,7,6,AIR)
B(14,7,6,AIR)
B(15,7,6,AIR)
B(9,8,6,AIR)
B(10,8,6,AIR)
B(11,8,6,AIR)
B(12,8,6,AIR)
B(13,8,6,AIR)
B(14,8,6,AIR)
B(15,8,6,AIR)
B(20,8,6,AIR)
B(9,9,6,AIR)
B(10,9,6,AIR)
B(11,9,6,AIR)
B(12,9,6,AIR)
B(13,9,6,AIR)
B(14,9,6,AIR)
B(15,9,6,AIR)
B(20,9,6,AIR)
B(9,10,6,STONE_BRICK_STAIRS:6)
B(10,10,6,AIR)
B(11,10,6,AIR)
B(12,10,6,AIR)
B(13,10,6,AIR)
B(14,10,6,AIR)
B(15,10,6,STONE_BRICK_STAIRS:6)
B(20,10,6,AIR)
B(10,11,6,AIR)
B(11,11,6,AIR)
B(12,11,6,AIR)
B(13,11,6,AIR)
B(14,11,6,AIR)
B(4,1,7,STONE_SLAB)
B(4,2,7,AIR)
B(4,3,7,AIR)
B(4,4,7,STONE_SLAB)
B(10,5,7,AIR)
B(11,5,7,AIR)
B(12,5,7,AIR)
B(13,5,7,AIR)
B(14,5,7,AIR)
B(10,6,7,AIR)
B(11,6,7,AIR)
B(12,6,7,AIR)
B(13,6,7,AIR)
B(14,6,7,AIR)
B(10,7,7,AIR)
B(11,7,7,AIR)
B(12,7,7,AIR)
B(13,7,7,AIR)
B(14,7,7,AIR)
B(10,8,7,AIR)
B(11,8,7,AIR)
B(12,8,7,AIR)
B(13,8,7,AIR)
B(14,8,7,AIR)
B(20,8,7,STONE_SLAB)
B(10,9,7,AIR)
B(11,9,7,AIR)
B(12,9,7,AIR)
B(13,9,7,AIR)
B(14,9,7,AIR)
B(20,9,7,AIR)
B(10,10,7,STONE_BRICK_STAIRS:5)
B(11,10,7,AIR)
B(12,10,7,AIR)
B(13,10,7,AIR)
B(14,10,7,STONE_BRICK_STAIRS:4)
B(20,10,7,AIR)
B(20,11,7,STONE_SLAB)
B(4,1,8,AIR)
B(4,2,8,AIR)
B(4,3,8,AIR)
B(12,5,8,AIR)
B(12,6,8,AIR)
B(12,7,8,AIR)
B(20,9,8,AIR)
B(20,10,8,AIR)
B(20,11,8,AIR)
B(2,1,9,AIR)
B(3,1,9,AIR)
B(4,1,9,AIR)
B(5,1,9,AIR)
B(6,1,9,AIR)
B(10,1,9,AIR)
B(11,1,9,AIR)
B(12,1,9,AIR)
B(13,1,9,AIR)
B(14,1,9,AIR)
B(18,1,9,AIR)
B(19,1,9,AIR)
B(21,1,9,AIR)
B(22,1,9,AIR)
B(2,2,9,AIR)
B(3,2,9,AIR)
B(4,2,9,AIR)
B(5,2,9,AIR)
B(6,2,9,AIR)
B(10,2,9,AIR)
B(11,2,9,AIR)
B(12,2,9,AIR)
B(13,2,9,AIR)
B(14,2,9,AIR)
B(18,2,9,AIR)
B(19,2,9,AIR)
B(20,2,9,AIR)
B(21,2,9,AIR)
B(22,2,9,AIR)
B(2,3,9,AIR)
B(3,3,9,AIR)
B(4,3,9,AIR)
B(5,3,9,AIR)
B(6,3,9,AIR)
B(10,3,9,AIR)
B(11,3,9,AIR)
B(12,3,9,AIR)
B(13,3,9,AIR)
B(14,3,9,AIR)
B(18,3,9,AIR)
B(19,3,9,AIR)
B(20,3,9,AIR)
B(21,3,9,AIR)
B(22,3,9,AIR)
B(2,4,9,AIR)
B(3,4,9,AIR)
B(4,4,9,AIR)
B(5,4,9,AIR)
B(6,4,9,AIR)
B(10,4,9,AIR)
B(11,4,9,STONE_BRICK_STAIRS:7)
B(12,4,9,STONE_BRICK_STAIRS:7)
B(13,4,9,STONE_BRICK_STAIRS:7)
B(14,4,9,AIR)
B(18,4,9,AIR)
B(19,4,9,AIR)
B(20,4,9,AIR)
B(21,4,9,AIR)
B(22,4,9,AIR)
B(2,5,9,AIR)
B(3,5,9,AIR)
B(4,5,9,AIR)
B(5,5,9,AIR)
B(6,5,9,AIR)
B(10,5,9,AIR)
B(11,5,9,AIR)
B(12,5,9,AIR)
B(13,5,9,AIR)
B(14,5,9,AIR)
B(18,5,9,AIR)
B(19,5,9,AIR)
B(20,5,9,AIR)
B(21,5,9,AIR)
B(22,5,9,AIR)
B(2,6,9,STONE_BRICK_STAIRS:5)
B(3,6,9,AIR)
B(4,6,9,AIR)
B(5,6,9,AIR)
B(6,6,9,STONE_BRICK_STAIRS:4)
B(10,6,9,AIR)
B(11,6,9,AIR)
B(12,6,9,AIR)
B(13,6,9,AIR)
B(14,6,9,AIR)
B(18,6,9,STONE_BRICK_STAIRS:5)
B(19,6,9,AIR)
B(20,6,9,AIR)
B(21,6,9,AIR)
B(22,6,9,STONE_BRICK_STAIRS:4)
B(10,7,9,AIR)
B(11,7,9,AIR)
B(12,7,9,AIR)
B(13,7,9,AIR)
B(14,7,9,AIR)
B(10,8,9,AIR)
B(11,8,9,AIR)
B(12,8,9,AIR)
B(13,8,9,AIR)
B(14,8,9,AIR)
B(2,9,9,AIR)
B(3,9,9,AIR)
B(5,9,9,AIR)
B(6,9,9,AIR)
B(10,9,9,AIR)
B(11,9,9,AIR)
B(12,9,9,AIR)
B(13,9,9,AIR)
B(14,9,9,AIR)
B(18,9,9,AIR)
B(19,9,9,AIR)
B(20,9,9,AIR)
B(21,9,9,AIR)
B(22,9,9,AIR)
B(2,10,9,AIR)
B(3,10,9,AIR)
B(4,10,9,AIR)
B(5,10,9,AIR)
B(6,10,9,AIR)
B(10,10,9,AIR)
B(11,10,9,AIR)
B(12,10,9,AIR)
B(13,10,9,AIR)
B(14,10,9,AIR)
B(18,10,9,AIR)
B(19,10,9,AIR)
B(20,10,9,AIR)
B(21,10,9,AIR)
B(22,10,9,AIR)
B(2,11,9,AIR)
B(3,11,9,AIR)
B(4,11,9,AIR)
B(5,11,9,AIR)
B(6,11,9,AIR)
B(10,11,9,AIR)
B(11,11,9,AIR)
B(12,11,9,AIR)
B(13,11,9,AIR)
B(14,11,9,AIR)
B(18,11,9,AIR)
B(19,11,9,AIR)
B(20,11,9,AIR)
B(21,11,9,AIR)
B(22,11,9,AIR)
B(2,12,9,AIR)
B(3,12,9,AIR)
B(4,12,9,AIR)
B(5,12,9,AIR)
B(6,12,9,AIR)
B(10,12,9,AIR)
B(11,12,9,AIR)
B(12,12,9,AIR)
B(13,12,9,AIR)
B(14,12,9,AIR)
B(18,12,9,AIR)
B(19,12,9,AIR)
B(20,12,9,AIR)
B(21,12,9,AIR)
B(22,12,9,AIR)
B(2,13,9,AIR)
B(3,13,9,AIR)
B(4,13,9,AIR)
B(5,13,9,AIR)
B(6,13,9,AIR)
B(10,13,9,AIR)
B(11,13,9,AIR)
B(12,13,9,AIR)
B(13,13,9,AIR)
B(14,13,9,AIR)
B(18,13,9,AIR)
B(19,13,9,AIR)
B(20,13,9,AIR)
B(21,13,9,AIR)
B(22,13,9,AIR)
B(2,14,9,STONE_BRICK_STAIRS:5)
B(3,14,9,AIR)
B(4,14,9,AIR)
B(5,14,9,AIR)
B(6,14,9,STONE_BRICK_STAIRS:4)
B(10,14,9,STONE_BRICK_STAIRS:5)
B(11,14,9,AIR)
B(12,14,9,AIR)
B(13,14,9,AIR)
B(14,14,9,STONE_BRICK_STAIRS:4)
B(18,14,9,STONE_BRICK_STAIRS:5)
B(19,14,9,AIR)
B(20,14,9,AIR)
B(21,14,9,AIR)
B(22,14,9,STONE_BRICK_STAIRS:4)
B(1,1,10,AIR)
B(2,1,10,AIR)
B(3,1,10,AIR)
B(4,1,10,AIR)
B(5,1,10,AIR)
B(6,1,10,AIR)
B(7,1,10,AIR)
B(9,1,10,AIR)
B(10,1,10,AIR)
B(11,1,10,AIR)
B(12,1,10,AIR)
B(13,1,10,AIR)
B(14,1,10,AIR)
B(15,1,10,AIR)
B(17,1,10,AIR)
B(18,1,10,AIR)
B(19,1,10,AIR)
B(20,1,10,AIR)
B(21,1,10,AIR)
B(22,1,10,AIR)
B(23,1,10,AIR)
B(1,2,10,AIR)
B(2,2,10,AIR)
B(3,2,10,AIR)
B(4,2,10,AIR)
B(5,2,10,AIR)
B(6,2,10,AIR)
B(7,2,10,AIR)
B(9,2,10,AIR)
B(10,2,10,AIR)
B(11,2,10,AIR)
B(12,2,10,AIR)
B(13,2,10,AIR)
B(14,2,10,AIR)
B(15,2,10,AIR)
B(17,2,10,AIR)
B(18,2,10,AIR)
B(19,2,10,AIR)
B(20,2,10,AIR)
B(21,2,10,AIR)
B(22,2,10,AIR)
B(23,2,10,AIR)
B(1,3,10,AIR)
B(2,3,10,AIR)
B(3,3,10,AIR)
B(4,3,10,AIR)
B(5,3,10,AIR)
B(6,3,10,AIR)
B(7,3,10,AIR)
B(9,3,10,AIR)
B(10,3,10,AIR)
B(11,3,10,AIR)
B(12,3,10,AIR)
B(13,3,10,AIR)
B(14,3,10,AIR)
B(15,3,10,AIR)
B(17,3,10,AIR)
B(18,3,10,AIR)
B(19,3,10,AIR)
B(20,3,10,AIR)
B(21,3,10,AIR)
B(22,3,10,AIR)
B(23,3,10,AIR)
B(1,4,10,AIR)
B(2,4,10,AIR)
B(3,4,10,AIR)
B(4,4,10,AIR)
B(5,4,10,AIR)
B(6,4,10,AIR)
B(7,4,10,AIR)
B(9,4,10,AIR)
B(10,4,10,AIR)
B(11,4,10,AIR)
B(12,4,10,AIR)
B(13,4,10,AIR)
B(14,4,10,AIR)
B(15,4,10,AIR)
B(17,4,10,AIR)
B(18,4,10,AIR)
B(19,4,10,AIR)
B(20,4,10,AIR)
B(21,4,10,AIR)
B(22,4,10,AIR)
B(23,4,10,AIR)
B(1,5,10,AIR)
B(2,5,10,AIR)
B(3,5,10,AIR)
B(4,5,10,AIR)
B(5,5,10,AIR)
B(6,5,10,AIR)
B(7,5,10,AIR)
B(9,5,10,AIR)
B(10,5,10,AIR)
B(11,5,10,AIR)
B(12,5,10,AIR)
B(13,5,10,AIR)
B(14,5,10,AIR)
B(15,5,10,AIR)
B(17,5,10,AIR)
B(18,5,10,AIR)
B(19,5,10,AIR)
B(20,5,10,AIR)
B(21,5,10,AIR)
B(22,5,10,AIR)
B(23,5,10,AIR)
B(1,6,10,STONE_BRICK_STAIRS:7)
B(2,6,10,AIR)
B(3,6,10,AIR)
B(4,6,10,AIR)
B(5,6,10,AIR)
B(6,6,10,AIR)
B(7,6,10,STONE_BRICK_STAIRS:7)
B(9,6,10,AIR)
B(10,6,10,AIR)
B(11,6,10,AIR)
B(12,6,10,AIR)
B(13,6,10,AIR)
B(14,6,10,AIR)
B(15,6,10,AIR)
B(17,6,10,STONE_BRICK_STAIRS:7)
B(18,6,10,AIR)
B(19,6,10,AIR)
B(20,6,10,AIR)
B(21,6,10,AIR)
B(22,6,10,AIR)
B(23,6,10,STONE_BRICK_STAIRS:7)
B(2,7,10,AIR)
B(3,7,10,AIR)
B(4,7,10,AIR)
B(5,7,10,AIR)
B(6,7,10,AIR)
B(9,7,10,AIR)
B(10,7,10,AIR)
B(11,7,10,AIR)
B(12,7,10,AIR)
B(13,7,10,AIR)
B(14,7,10,AIR)
B(15,7,10,AIR)
B(18,7,10,AIR)
B(19,7,10,AIR)
B(20,7,10,AIR)
B(21,7,10,AIR)
B(22,7,10,AIR)
B(9,8,10,AIR)
B(10,8,10,AIR)
B(11,8,10,AIR)
B(12,8,10,AIR)
B(13,8,10,AIR)
B(14,8,10,AIR)
B(15,8,10,AIR)
B(1,9,10,AIR)
B(2,9,10,AIR)
B(3,9,10,AIR)
B(4,9,10,AIR)
B(5,9,10,AIR)
B(6,9,10,AIR)
B(7,9,10,AIR)
B(9,9,10,AIR)
B(10,9,10,AIR)
B(11,9,10,AIR)
B(12,9,10,AIR)
B(13,9,10,AIR)
B(14,9,10,AIR)
B(15,9,10,AIR)
B(17,9,10,AIR)
B(18,9,10,AIR)
B(19,9,10,AIR)
B(20,9,10,AIR)
B(21,9,10,AIR)
B(22,9,10,AIR)
B(23,9,10,AIR)
B(1,10,10,AIR)
B(2,10,10,AIR)
B(3,10,10,AIR)
B(4,10,10,AIR)
B(5,10,10,AIR)
B(6,10,10,AIR)
B(7,10,10,AIR)
B(9,10,10,AIR)
B(10,10,10,AIR)
B(11,10,10,AIR)
B(12,10,10,AIR)
B(13,10,10,AIR)
B(14,10,10,AIR)
B(15,10,10,AIR)
B(17,10,10,AIR)
B(18,10,10,AIR)
B(19,10,10,AIR)
B(20,10,10,AIR)
B(21,10,10,AIR)
B(22,10,10,AIR)
B(23,10,10,AIR)
B(1,11,10,AIR)
B(2,11,10,AIR)
B(3,11,10,AIR)
B(4,11,10,AIR)
B(5,11,10,AIR)
B(6,11,10,AIR)
B(7,11,10,AIR)
B(9,11,10,AIR)
B(10,11,10,AIR)
B(11,11,10,AIR)
B(12,11,10,AIR)
B(13,11,10,AIR)
B(14,11,10,AIR)
B(15,11,10,AIR)
B(17,11,10,AIR)
B(18,11,10,AIR)
B(19,11,10,AIR)
B(20,11,10,AIR)
B(21,11,10,AIR)
B(22,11,10,AIR)
B(23,11,10,AIR)
B(1,12,10,AIR)
B(2,12,10,AIR)
B(3,12,10,AIR)
B(4,12,10,AIR)
B(5,12,10,AIR)
B(6,12,10,AIR)
B(7,12,10,AIR)
B(9,12,10,AIR)
B(10,12,10,AIR)
B(11,12,10,AIR)
B(12,12,10,AIR)
B(13,12,10,AIR)
B(14,12,10,AIR)
B(15,12,10,AIR)
B(17,12,10,AIR)
B(18,12,10,AIR)
B(19,12,10,AIR)
B(20,12,10,AIR)
B(21,12,10,AIR)
B(22,12,10,AIR)
B(23,12,10,AIR)
B(1,13,10,AIR)
B(2,13,10,AIR)
B(3,13,10,AIR)
B(4,13,10,AIR)
B(5,13,10,AIR)
B(6,13,10,AIR)
B(7,13,10,AIR)
B(9,13,10,AIR)
B(10,13,10,AIR)
B(11,13,10,AIR)
B(12,13,10,AIR)
B(13,13,10,AIR)
B(14,13,10,AIR)
B(15,13,10,AIR)
B(17,13,10,AIR)
B(18,13,10,AIR)
B(19,13,10,AIR)
B(20,13,10,AIR)
B(21,13,10,AIR)
B(22,13,10,AIR)
B(23,13,10,AIR)
B(1,14,10,STONE_BRICK_STAIRS:7)
B(2,14,10,AIR)
B(3,14,10,AIR)
B(4,14,10,AIR)
B(5,14,10,AIR)
B(6,14,10,AIR)
B(7,14,10,STONE_BRICK_STAIRS:7)
B(9,14,10,STONE_BRICK_STAIRS:7)
B(10,14,10,AIR)
B(11,14,10,AIR)
B(12,14,10,AIR)
B(13,14,10,AIR)
B(14,14,10,AIR)
B(15,14,10,STONE_BRICK_STAIRS:7)
B(17,14,10,STONE_BRICK_STAIRS:7)
B(18,14,10,AIR)
B(19,14,10,AIR)
B(20,14,10,AIR)
B(21,14,10,AIR)
B(22,14,10,AIR)
B(23,14,10,STONE_BRICK_STAIRS:7)
B(2,15,10,AIR)
B(3,15,10,AIR)
B(4,15,10,AIR)
B(5,15,10,AIR)
B(6,15,10,AIR)
B(10,15,10,AIR)
B(11,15,10,AIR)
B(12,15,10,AIR)
B(13,15,10,AIR)
B(14,15,10,AIR)
B(18,15,10,AIR)
B(19,15,10,AIR)
B(20,15,10,AIR)
B(21,15,10,AIR)
B(22,15,10,AIR)
B(1,1,11,AIR)
B(2,1,11,AIR)
B(3,1,11,TALLGRASS:1)
B(4,1,11,TALLGRASS:2)
B(5,1,11,AIR)
B(6,1,11,AIR)
B(7,1,11,AIR)
B(9,1,11,AIR)
B(10,1,11,AIR)
B(11,1,11,TALLGRASS:2)
B(12,1,11,AIR)
B(13,1,11,TALLGRASS:1)
B(14,1,11,AIR)
B(15,1,11,AIR)
B(17,1,11,AIR)
B(18,1,11,AIR)
B(19,1,11,AIR)
B(20,1,11,TALLGRASS:1)
B(21,1,11,AIR)
B(22,1,11,AIR)
B(23,1,11,AIR)
B(1,2,11,AIR)
B(2,2,11,AIR)
B(3,2,11,AIR)
B(4,2,11,AIR)
B(5,2,11,AIR)
B(6,2,11,AIR)
B(7,2,11,AIR)
B(9,2,11,AIR)
B(10,2,11,AIR)
B(11,2,11,AIR)
B(12,2,11,AIR)
B(13,2,11,AIR)
B(14,2,11,AIR)
B(15,2,11,AIR)
B(17,2,11,AIR)
B(18,2,11,AIR)
B(19,2,11,AIR)
B(20,2,11,AIR)
B(21,2,11,AIR)
B(22,2,11,AIR)
B(23,2,11,AIR)
B(1,3,11,AIR)
B(2,3,11,AIR)
B(3,3,11,AIR)
B(4,3,11,AIR)
B(5,3,11,AIR)
B(6,3,11,AIR)
B(7,3,11,AIR)
B(9,3,11,AIR)
B(10,3,11,AIR)
B(11,3,11,AIR)
B(12,3,11,AIR)
B(13,3,11,AIR)
B(14,3,11,AIR)
B(15,3,11,AIR)
B(17,3,11,AIR)
B(18,3,11,AIR)
B(19,3,11,AIR)
B(20,3,11,AIR)
B(21,3,11,AIR)
B(22,3,11,AIR)
B(23,3,11,AIR)
B(1,4,11,AIR)
B(2,4,11,AIR)
B(3,4,11,AIR)
B(4,4,11,AIR)
B(5,4,11,AIR)
B(6,4,11,AIR)
B(7,4,11,AIR)
B(9,4,11,AIR)
B(10,4,11,AIR)
B(11,4,11,AIR)
B(12,4,11,AIR)
B(13,4,11,AIR)
B(14,4,11,AIR)
B(15,4,11,AIR)
B(17,4,11,AIR)
B(18,4,11,AIR)
B(19,4,11,AIR)
B(20,4,11,AIR)
B(21,4,11,AIR)
B(22,4,11,AIR)
B(23,4,11,AIR)
B(1,5,11,AIR)
B(2,5,11,AIR)
B(3,5,11,AIR)
B(4,5,11,AIR)
B(5,5,11,AIR)
B(6,5,11,AIR)
B(7,5,11,AIR)
B(9,5,11,AIR)
B(10,5,11,AIR)
B(11,5,11,AIR)
B(12,5,11,AIR)
B(13,5,11,AIR)
B(14,5,11,AIR)
B(15,5,11,AIR)
B(17,5,11,AIR)
B(18,5,11,AIR)
B(19,5,11,AIR)
B(20,5,11,AIR)
B(21,5,11,AIR)
B(22,5,11,AIR)
B(23,5,11,AIR)
B(1,6,11,AIR)
B(2,6,11,AIR)
B(3,6,11,AIR)
B(4,6,11,AIR)
B(5,6,11,AIR)
B(6,6,11,AIR)
B(7,6,11,AIR)
B(9,6,11,AIR)
B(10,6,11,AIR)
B(11,6,11,AIR)
B(12,6,11,AIR)
B(13,6,11,AIR)
B(14,6,11,AIR)
B(15,6,11,AIR)
B(17,6,11,AIR)
B(18,6,11,AIR)
B(19,6,11,AIR)
B(20,6,11,AIR)
B(21,6,11,AIR)
B(22,6,11,AIR)
B(23,6,11,AIR)
B(2,7,11,AIR)
B(3,7,11,AIR)
B(4,7,11,AIR)
B(5,7,11,AIR)
B(6,7,11,AIR)
B(9,7,11,AIR)
B(10,7,11,AIR)
B(11,7,11,AIR)
B(12,7,11,AIR)
B(13,7,11,AIR)
B(14,7,11,AIR)
B(15,7,11,AIR)
B(18,7,11,AIR)
B(19,7,11,AIR)
B(20,7,11,AIR)
B(21,7,11,AIR)
B(22,7,11,AIR)
B(3,8,11,AIR)
B(4,8,11,AIR)
B(5,8,11,AIR)
B(9,8,11,STONE_BRICK_STAIRS:5)
B(10,8,11,AIR)
B(11,8,11,AIR)
B(12,8,11,AIR)
B(13,8,11,AIR)
B(14,8,11,AIR)
B(15,8,11,STONE_BRICK_STAIRS:4)
B(19,8,11,AIR)
B(20,8,11,AIR)
B(21,8,11,AIR)
B(1,9,11,AIR)
B(2,9,11,AIR)
B(3,9,11,AIR)
B(4,9,11,AIR)
B(5,9,11,AIR)
B(6,9,11,AIR)
B(7,9,11,AIR)
B(9,9,11,AIR)
B(10,9,11,AIR)
B(11,9,11,AIR)
B(12,9,11,AIR)
B(13,9,11,AIR)
B(14,9,11,AIR)
B(15,9,11,AIR)
B(17,9,11,AIR)
B(18,9,11,AIR)
B(19,9,11,AIR)
B(20,9,11,AIR)
B(21,9,11,AIR)
B(22,9,11,AIR)
B(23,9,11,AIR)
B(1,10,11,AIR)
B(2,10,11,AIR)
B(3,10,11,AIR)
B(4,10,11,AIR)
B(5,10,11,AIR)
B(6,10,11,AIR)
B(7,10,11,AIR)
B(9,10,11,AIR)
B(10,10,11,AIR)
B(11,10,11,AIR)
B(12,10,11,AIR)
B(13,10,11,AIR)
B(14,10,11,AIR)
B(15,10,11,AIR)
B(17,10,11,AIR)
B(18,10,11,AIR)
B(19,10,11,AIR)
B(20,10,11,AIR)
B(21,10,11,AIR)
B(22,10,11,AIR)
B(23,10,11,AIR)
B(1,11,11,AIR)
B(2,11,11,AIR)
B(3,11,11,AIR)
B(4,11,11,AIR)
B(5,11,11,AIR)
B(6,11,11,AIR)
B(7,11,11,AIR)
B(9,11,11,AIR)
B(10,11,11,AIR)
B(11,11,11,AIR)
B(12,11,11,AIR)
B(13,11,11,AIR)
B(14,11,11,AIR)
B(15,11,11,AIR)
B(17,11,11,AIR)
B(18,11,11,AIR)
B(19,11,11,AIR)
B(20,11,11,AIR)
B(21,11,11,AIR)
B(22,11,11,AIR)
B(23,11,11,AIR)
B(1,12,11,AIR)
B(2,12,11,AIR)
B(3,12,11,AIR)
B(4,12,11,AIR)
B(5,12,11,AIR)
B(6,12,11,AIR)
B(7,12,11,AIR)
B(9,12,11,AIR)
B(10,12,11,AIR)
B(11,12,11,AIR)
B(12,12,11,AIR)
B(13,12,11,AIR)
B(14,12,11,AIR)
B(15,12,11,AIR)
B(17,12,11,AIR)
B(18,12,11,AIR)
B(19,12,11,AIR)
B(20,12,11,AIR)
B(21,12,11,AIR)
B(22,12,11,AIR)
B(23,12,11,AIR)
B(1,13,11,AIR)
B(2,13,11,AIR)
B(3,13,11,AIR)
B(4,13,11,AIR)
B(5,13,11,AIR)
B(6,13,11,AIR)
B(7,13,11,AIR)
B(9,13,11,AIR)
B(10,13,11,AIR)
B(11,13,11,AIR)
B(12,13,11,AIR)
B(13,13,11,AIR)
B(14,13,11,AIR)
B(15,13,11,AIR)
B(17,13,11,AIR)
B(18,13,11,AIR)
B(19,13,11,AIR)
B(20,13,11,AIR)
B(21,13,11,AIR)
B(22,13,11,AIR)
B(23,13,11,AIR)
B(1,14,11,AIR)
B(2,14,11,AIR)
B(3,14,11,AIR)
B(4,14,11,AIR)
B(5,14,11,AIR)
B(6,14,11,AIR)
B(7,14,11,AIR)
B(9,14,11,AIR)
B(10,14,11,AIR)
B(11,14,11,AIR)
B(12,14,11,AIR)
B(13,14,11,AIR)
B(14,14,11,AIR)
B(15,14,11,AIR)
B(17,14,11,AIR)
B(18,14,11,AIR)
B(19,14,11,AIR)
B(20,14,11,AIR)
B(21,14,11,AIR)
B(22,14,11,AIR)
B(23,14,11,AIR)
B(2,15,11,AIR)
B(3,15,11,AIR)
B(4,15,11,AIR)
B(5,15,11,AIR)
B(6,15,11,AIR)
B(10,15,11,AIR)
B(11,15,11,AIR)
B(12,15,11,AIR)
B(13,15,11,AIR)
B(14,15,11,AIR)
B(18,15,11,AIR)
B(19,15,11,AIR)
B(20,15,11,AIR)
B(21,15,11,AIR)
B(22,15,11,AIR)
B(3,16,11,AIR)
B(4,16,11,AIR)
B(5,16,11,AIR)
B(11,16,11,AIR)
B(12,16,11,AIR)
B(13,16,11,AIR)
B(19,16,11,AIR)
B(20,16,11,AIR)
B(21,16,11,AIR)
B(2,1,12,AIR)
B(3,1,12,TALLGRASS:1)
B(5,1,12,TALLGRASS:1)
B(6,1,12,AIR)
B(7,1,12,AIR)
B(8,1,12,AIR)
B(9,1,12,AIR)
B(10,1,12,AIR)
B(11,1,12,TALLGRASS:1)
B(12,1,12,AIR)
B(13,1,12,TALLGRASS:2)
B(14,1,12,AIR)
B(15,1,12,AIR)
B(16,1,12,AIR)
B(17,1,12,AIR)
B(18,1,12,AIR)
B(19,1,12,TALLGRASS:1)
B(21,1,12,AIR)
B(22,1,12,AIR)
B(1,2,12,AIR)
B(2,2,12,AIR)
B(3,2,12,AIR)
B(4,2,12,AIR)
B(5,2,12,AIR)
B(6,2,12,AIR)
B(7,2,12,AIR)
B(8,2,12,AIR)
B(9,2,12,AIR)
B(10,2,12,AIR)
B(11,2,12,AIR)
B(12,2,12,AIR)
B(13,2,12,AIR)
B(14,2,12,AIR)
B(15,2,12,AIR)
B(16,2,12,AIR)
B(17,2,12,AIR)
B(18,2,12,AIR)
B(19,2,12,AIR)
B(20,2,12,AIR)
B(21,2,12,AIR)
B(22,2,12,AIR)
B(23,2,12,AIR)
B(1,3,12,AIR)
B(2,3,12,AIR)
B(3,3,12,AIR)
B(4,3,12,AIR)
B(5,3,12,AIR)
B(6,3,12,AIR)
B(7,3,12,AIR)
B(8,3,12,AIR)
B(9,3,12,AIR)
B(10,3,12,AIR)
B(11,3,12,AIR)
B(12,3,12,AIR)
B(13,3,12,AIR)
B(14,3,12,AIR)
B(15,3,12,AIR)
B(16,3,12,AIR)
B(17,3,12,AIR)
B(18,3,12,AIR)
B(19,3,12,AIR)
B(20,3,12,AIR)
B(21,3,12,AIR)
B(22,3,12,AIR)
B(23,3,12,AIR)
B(1,4,12,AIR)
B(2,4,12,AIR)
B(3,4,12,AIR)
B(4,4,12,AIR)
B(5,4,12,AIR)
B(6,4,12,AIR)
B(7,4,12,AIR)
B(9,4,12,AIR)
B(10,4,12,AIR)
B(11,4,12,AIR)
B(12,4,12,AIR)
B(13,4,12,AIR)
B(14,4,12,AIR)
B(15,4,12,AIR)
B(17,4,12,AIR)
B(18,4,12,AIR)
B(19,4,12,AIR)
B(20,4,12,AIR)
B(21,4,12,AIR)
B(22,4,12,AIR)
B(23,4,12,AIR)
B(1,5,12,AIR)
B(2,5,12,AIR)
B(3,5,12,AIR)
B(4,5,12,AIR)
B(5,5,12,AIR)
B(6,5,12,AIR)
B(7,5,12,AIR)
B(9,5,12,AIR)
B(10,5,12,AIR)
B(11,5,12,AIR)
B(12,5,12,AIR)
B(13,5,12,AIR)
B(14,5,12,AIR)
B(15,5,12,AIR)
B(17,5,12,AIR)
B(18,5,12,AIR)
B(19,5,12,AIR)
B(20,5,12,AIR)
B(21,5,12,AIR)
B(22,5,12,AIR)
B(23,5,12,AIR)
B(1,6,12,AIR)
B(2,6,12,AIR)
B(3,6,12,AIR)
B(4,6,12,AIR)
B(5,6,12,AIR)
B(6,6,12,AIR)
B(7,6,12,AIR)
B(9,6,12,AIR)
B(10,6,12,AIR)
B(11,6,12,AIR)
B(12,6,12,AIR)
B(13,6,12,AIR)
B(14,6,12,AIR)
B(15,6,12,AIR)
B(17,6,12,AIR)
B(18,6,12,AIR)
B(19,6,12,AIR)
B(20,6,12,AIR)
B(21,6,12,AIR)
B(22,6,12,AIR)
B(23,6,12,AIR)
B(2,7,12,AIR)
B(3,7,12,AIR)
B(4,7,12,AIR)
B(5,7,12,AIR)
B(6,7,12,AIR)
B(9,7,12,AIR)
B(10,7,12,AIR)
B(11,7,12,AIR)
B(12,7,12,AIR)
B(13,7,12,AIR)
B(14,7,12,AIR)
B(15,7,12,AIR)
B(18,7,12,AIR)
B(19,7,12,AIR)
B(20,7,12,AIR)
B(21,7,12,AIR)
B(22,7,12,AIR)
B(3,8,12,AIR)
B(4,8,12,AIR)
B(5,8,12,AIR)
B(9,8,12,STONE_BRICK_STAIRS:5)
B(10,8,12,AIR)
B(11,8,12,AIR)
B(12,8,12,AIR)
B(13,8,12,AIR)
B(14,8,12,AIR)
B(15,8,12,STONE_BRICK_STAIRS:4)
B(19,8,12,AIR)
B(20,8,12,AIR)
B(21,8,12,AIR)
B(2,9,12,AIR)
B(3,9,12,AIR)
B(4,9,12,AIR)
B(5,9,12,AIR)
B(6,9,12,AIR)
B(7,9,12,AIR)
B(8,9,12,AIR)
B(9,9,12,AIR)
B(10,9,12,AIR)
B(11,9,12,AIR)
B(12,9,12,AIR)
B(13,9,12,AIR)
B(14,9,12,AIR)
B(15,9,12,AIR)
B(16,9,12,AIR)
B(17,9,12,AIR)
B(18,9,12,AIR)
B(19,9,12,AIR)
B(20,9,12,AIR)
B(21,9,12,AIR)
B(22,9,12,AIR)
B(1,10,12,AIR)
B(2,10,12,AIR)
B(3,10,12,AIR)
B(4,10,12,AIR)
B(5,10,12,AIR)
B(6,10,12,AIR)
B(7,10,12,AIR)
B(8,10,12,AIR)
B(9,10,12,AIR)
B(10,10,12,AIR)
B(11,10,12,AIR)
B(12,10,12,AIR)
B(13,10,12,AIR)
B(14,10,12,AIR)
B(15,10,12,AIR)
B(16,10,12,AIR)
B(17,10,12,AIR)
B(18,10,12,AIR)
B(19,10,12,AIR)
B(20,10,12,AIR)
B(21,10,12,AIR)
B(22,10,12,AIR)
B(23,10,12,AIR)
B(1,11,12,AIR)
B(2,11,12,AIR)
B(3,11,12,AIR)
B(4,11,12,AIR)
B(5,11,12,AIR)
B(6,11,12,AIR)
B(7,11,12,AIR)
B(8,11,12,AIR)
B(9,11,12,AIR)
B(10,11,12,AIR)
B(11,11,12,AIR)
B(12,11,12,AIR)
B(13,11,12,AIR)
B(14,11,12,AIR)
B(15,11,12,AIR)
B(16,11,12,AIR)
B(17,11,12,AIR)
B(18,11,12,AIR)
B(19,11,12,AIR)
B(20,11,12,AIR)
B(21,11,12,AIR)
B(22,11,12,AIR)
B(23,11,12,AIR)
B(1,12,12,AIR)
B(2,12,12,AIR)
B(3,12,12,AIR)
B(4,12,12,AIR)
B(5,12,12,AIR)
B(6,12,12,AIR)
B(7,12,12,AIR)
B(9,12,12,AIR)
B(10,12,12,AIR)
B(11,12,12,AIR)
B(12,12,12,AIR)
B(13,12,12,AIR)
B(14,12,12,AIR)
B(15,12,12,AIR)
B(17,12,12,AIR)
B(18,12,12,AIR)
B(19,12,12,AIR)
B(20,12,12,AIR)
B(21,12,12,AIR)
B(22,12,12,AIR)
B(23,12,12,AIR)
B(1,13,12,AIR)
B(2,13,12,AIR)
B(3,13,12,AIR)
B(4,13,12,AIR)
B(5,13,12,AIR)
B(6,13,12,AIR)
B(7,13,12,AIR)
B(9,13,12,AIR)
B(10,13,12,AIR)
B(11,13,12,AIR)
B(12,13,12,AIR)
B(13,13,12,AIR)
B(14,13,12,AIR)
B(15,13,12,AIR)
B(17,13,12,AIR)
B(18,13,12,AIR)
B(19,13,12,AIR)
B(20,13,12,AIR)
B(21,13,12,AIR)
B(22,13,12,AIR)
B(23,13,12,AIR)
B(1,14,12,AIR)
B(2,14,12,AIR)
B(3,14,12,AIR)
B(4,14,12,AIR)
B(5,14,12,AIR)
B(6,14,12,AIR)
B(7,14,12,AIR)
B(9,14,12,AIR)
B(10,14,12,AIR)
B(11,14,12,AIR)
B(12,14,12,AIR)
B(13,14,12,AIR)
B(14,14,12,AIR)
B(15,14,12,AIR)
B(17,14,12,AIR)
B(18,14,12,AIR)
B(19,14,12,AIR)
B(20,14,12,AIR)
B(21,14,12,AIR)
B(22,14,12,AIR)
B(23,14,12,AIR)
B(2,15,12,AIR)
B(3,15,12,AIR)
B(4,15,12,AIR)
B(5,15,12,AIR)
B(6,15,12,AIR)
B(10,15,12,AIR)
B(11,15,12,AIR)
B(12,15,12,AIR)
B(13,15,12,AIR)
B(14,15,12,AIR)
B(18,15,12,AIR)
B(19,15,12,AIR)
B(20,15,12,AIR)
B(21,15,12,AIR)
B(22,15,12,AIR)
B(3,16,12,AIR)
B(4,16,12,AIR)
B(5,16,12,AIR)
B(11,16,12,AIR)
B(12,16,12,AIR)
B(13,16,12,AIR)
B(19,16,12,AIR)
B(20,16,12,AIR)
B(21,16,12,AIR)
B(1,1,13,AIR)
B(2,1,13,AIR)
B(3,1,13,AIR)
B(4,1,13,TALLGRASS:2)
B(5,1,13,AIR)
B(6,1,13,AIR)
B(7,1,13,AIR)
B(9,1,13,AIR)
B(10,1,13,AIR)
B(11,1,13,TALLGRASS:1)
B(12,1,13,AIR)
B(13,1,13,AIR)
B(14,1,13,AIR)
B(15,1,13,AIR)
B(17,1,13,AIR)
B(18,1,13,AIR)
B(19,1,13,AIR)
B(20,1,13,AIR)
B(21,1,13,TALLGRASS:1)
B(22,1,13,AIR)
B(23,1,13,AIR)
B(1,2,13,AIR)
B(2,2,13,AIR)
B(3,2,13,AIR)
B(4,2,13,AIR)
B(5,2,13,AIR)
B(6,2,13,AIR)
B(7,2,13,AIR)
B(9,2,13,AIR)
B(10,2,13,AIR)
B(11,2,13,AIR)
B(12,2,13,AIR)
B(13,2,13,AIR)
B(14,2,13,AIR)
B(15,2,13,AIR)
B(17,2,13,AIR)
B(18,2,13,AIR)
B(19,2,13,AIR)
B(20,2,13,AIR)
B(21,2,13,AIR)
B(22,2,13,AIR)
B(23,2,13,AIR)
B(1,3,13,AIR)
B(2,3,13,AIR)
B(3,3,13,AIR)
B(4,3,13,AIR)
B(5,3,13,AIR)
B(6,3,13,AIR)
B(7,3,13,AIR)
B(9,3,13,AIR)
B(10,3,13,AIR)
B(11,3,13,AIR)
B(12,3,13,AIR)
B(13,3,13,AIR)
B(14,3,13,AIR)
B(15,3,13,AIR)
B(17,3,13,AIR)
B(18,3,13,AIR)
B(19,3,13,AIR)
B(20,3,13,AIR)
B(21,3,13,AIR)
B(22,3,13,AIR)
B(23,3,13,AIR)
B(1,4,13,AIR)
B(2,4,13,AIR)
B(3,4,13,AIR)
B(4,4,13,AIR)
B(5,4,13,AIR)
B(6,4,13,AIR)
B(7,4,13,AIR)
B(9,4,13,AIR)
B(10,4,13,AIR)
B(11,4,13,AIR)
B(12,4,13,AIR)
B(13,4,13,AIR)
B(14,4,13,AIR)
B(15,4,13,AIR)
B(17,4,13,AIR)
B(18,4,13,AIR)
B(19,4,13,AIR)
B(20,4,13,AIR)
B(21,4,13,AIR)
B(22,4,13,AIR)
B(23,4,13,AIR)
B(1,5,13,AIR)
B(2,5,13,AIR)
B(3,5,13,AIR)
B(4,5,13,AIR)
B(5,5,13,AIR)
B(6,5,13,AIR)
B(7,5,13,AIR)
B(9,5,13,AIR)
B(10,5,13,AIR)
B(11,5,13,AIR)
B(12,5,13,AIR)
B(13,5,13,AIR)
B(14,5,13,AIR)
B(15,5,13,AIR)
B(17,5,13,AIR)
B(18,5,13,AIR)
B(19,5,13,AIR)
B(20,5,13,AIR)
B(21,5,13,AIR)
B(22,5,13,AIR)
B(23,5,13,AIR)
B(1,6,13,AIR)
B(2,6,13,AIR)
B(3,6,13,AIR)
B(4,6,13,AIR)
B(5,6,13,AIR)
B(6,6,13,AIR)
B(7,6,13,AIR)
B(9,6,13,AIR)
B(10,6,13,AIR)
B(11,6,13,AIR)
B(12,6,13,AIR)
B(13,6,13,AIR)
B(14,6,13,AIR)
B(15,6,13,AIR)
B(17,6,13,AIR)
B(18,6,13,AIR)
B(19,6,13,AIR)
B(20,6,13,AIR)
B(21,6,13,AIR)
B(22,6,13,AIR)
B(23,6,13,AIR)
B(2,7,13,AIR)
B(3,7,13,AIR)
B(4,7,13,AIR)
B(5,7,13,AIR)
B(6,7,13,AIR)
B(9,7,13,AIR)
B(10,7,13,AIR)
B(11,7,13,AIR)
B(12,7,13,AIR)
B(13,7,13,AIR)
B(14,7,13,AIR)
B(15,7,13,AIR)
B(18,7,13,AIR)
B(19,7,13,AIR)
B(20,7,13,AIR)
B(21,7,13,AIR)
B(22,7,13,AIR)
B(3,8,13,AIR)
B(4,8,13,AIR)
B(5,8,13,AIR)
B(9,8,13,STONE_BRICK_STAIRS:5)
B(10,8,13,AIR)
B(11,8,13,AIR)
B(12,8,13,AIR)
B(13,8,13,AIR)
B(14,8,13,AIR)
B(15,8,13,STONE_BRICK_STAIRS:4)
B(19,8,13,AIR)
B(20,8,13,AIR)
B(21,8,13,AIR)
B(1,9,13,AIR)
B(2,9,13,AIR)
B(3,9,13,AIR)
B(4,9,13,AIR)
B(5,9,13,AIR)
B(6,9,13,AIR)
B(7,9,13,AIR)
B(9,9,13,AIR)
B(10,9,13,AIR)
B(11,9,13,AIR)
B(12,9,13,AIR)
B(13,9,13,AIR)
B(14,9,13,AIR)
B(15,9,13,AIR)
B(17,9,13,AIR)
B(18,9,13,AIR)
B(19,9,13,AIR)
B(20,9,13,AIR)
B(21,9,13,AIR)
B(22,9,13,AIR)
B(23,9,13,AIR)
B(1,10,13,AIR)
B(2,10,13,AIR)
B(3,10,13,AIR)
B(4,10,13,AIR)
B(5,10,13,AIR)
B(6,10,13,AIR)
B(7,10,13,AIR)
B(9,10,13,AIR)
B(10,10,13,AIR)
B(11,10,13,AIR)
B(12,10,13,AIR)
B(13,10,13,AIR)
B(14,10,13,AIR)
B(15,10,13,AIR)
B(17,10,13,AIR)
B(18,10,13,AIR)
B(19,10,13,AIR)
B(20,10,13,AIR)
B(21,10,13,AIR)
B(22,10,13,AIR)
B(23,10,13,AIR)
B(1,11,13,AIR)
B(2,11,13,AIR)
B(3,11,13,AIR)
B(4,11,13,AIR)
B(5,11,13,AIR)
B(6,11,13,AIR)
B(7,11,13,AIR)
B(9,11,13,AIR)
B(10,11,13,AIR)
B(11,11,13,AIR)
B(12,11,13,AIR)
B(13,11,13,AIR)
B(14,11,13,AIR)
B(15,11,13,AIR)
B(17,11,13,AIR)
B(18,11,13,AIR)
B(19,11,13,AIR)
B(20,11,13,AIR)
B(21,11,13,AIR)
B(22,11,13,AIR)
B(23,11,13,AIR)
B(1,12,13,AIR)
B(2,12,13,AIR)
B(3,12,13,AIR)
B(4,12,13,AIR)
B(5,12,13,AIR)
B(6,12,13,AIR)
B(7,12,13,AIR)
B(9,12,13,AIR)
B(10,12,13,AIR)
B(11,12,13,AIR)
B(12,12,13,AIR)
B(13,12,13,AIR)
B(14,12,13,AIR)
B(15,12,13,AIR)
B(17,12,13,AIR)
B(18,12,13,AIR)
B(19,12,13,AIR)
B(20,12,13,AIR)
B(21,12,13,AIR)
B(22,12,13,AIR)
B(23,12,13,AIR)
B(1,13,13,AIR)
B(2,13,13,AIR)
B(3,13,13,AIR)
B(4,13,13,AIR)
B(5,13,13,AIR)
B(6,13,13,AIR)
B(7,13,13,AIR)
B(9,13,13,AIR)
B(10,13,13,AIR)
B(11,13,13,AIR)
B(12,13,13,AIR)
B(13,13,13,AIR)
B(14,13,13,AIR)
B(15,13,13,AIR)
B(17,13,13,AIR)
B(18,13,13,AIR)
B(19,13,13,AIR)
B(20,13,13,AIR)
B(21,13,13,AIR)
B(22,13,13,AIR)
B(23,13,13,AIR)
B(1,14,13,AIR)
B(2,14,13,AIR)
B(3,14,13,AIR)
B(4,14,13,AIR)
B(5,14,13,AIR)
B(6,14,13,AIR)
B(7,14,13,AIR)
B(9,14,13,AIR)
B(10,14,13,AIR)
B(11,14,13,AIR)
B(12,14,13,AIR)
B(13,14,13,AIR)
B(14,14,13,AIR)
B(15,14,13,AIR)
B(17,14,13,AIR)
B(18,14,13,AIR)
B(19,14,13,AIR)
B(20,14,13,AIR)
B(21,14,13,AIR)
B(22,14,13,AIR)
B(23,14,13,AIR)
B(2,15,13,AIR)
B(3,15,13,AIR)
B(4,15,13,AIR)
B(5,15,13,AIR)
B(6,15,13,AIR)
B(10,15,13,AIR)
B(11,15,13,AIR)
B(12,15,13,AIR)
B(13,15,13,AIR)
B(14,15,13,AIR)
B(18,15,13,AIR)
B(19,15,13,AIR)
B(20,15,13,AIR)
B(21,15,13,AIR)
B(22,15,13,AIR)
B(3,16,13,AIR)
B(4,16,13,AIR)
B(5,16,13,AIR)
B(11,16,13,AIR)
B(12,16,13,AIR)
B(13,16,13,AIR)
B(19,16,13,AIR)
B(20,16,13,AIR)
B(21,16,13,AIR)
B(1,1,14,AIR)
B(2,1,14,AIR)
B(3,1,14,AIR)
B(4,1,14,AIR)
B(5,1,14,AIR)
B(6,1,14,AIR)
B(7,1,14,AIR)
B(9,1,14,AIR)
B(10,1,14,AIR)
B(11,1,14,AIR)
B(12,1,14,AIR)
B(13,1,14,AIR)
B(14,1,14,AIR)
B(15,1,14,AIR)
B(17,1,14,AIR)
B(18,1,14,AIR)
B(19,1,14,AIR)
B(20,1,14,AIR)
B(21,1,14,AIR)
B(22,1,14,AIR)
B(23,1,14,AIR)
B(1,2,14,AIR)
B(2,2,14,AIR)
B(3,2,14,AIR)
B(4,2,14,AIR)
B(5,2,14,AIR)
B(6,2,14,AIR)
B(7,2,14,AIR)
B(9,2,14,AIR)
B(10,2,14,AIR)
B(11,2,14,AIR)
B(12,2,14,AIR)
B(13,2,14,AIR)
B(14,2,14,AIR)
B(15,2,14,AIR)
B(17,2,14,AIR)
B(18,2,14,AIR)
B(19,2,14,AIR)
B(20,2,14,AIR)
B(21,2,14,AIR)
B(22,2,14,AIR)
B(23,2,14,AIR)
B(1,3,14,AIR)
B(2,3,14,AIR)
B(3,3,14,AIR)
B(4,3,14,AIR)
B(5,3,14,AIR)
B(6,3,14,AIR)
B(7,3,14,AIR)
B(9,3,14,AIR)
B(10,3,14,AIR)
B(11,3,14,AIR)
B(12,3,14,AIR)
B(13,3,14,AIR)
B(14,3,14,AIR)
B(15,3,14,AIR)
B(17,3,14,AIR)
B(18,3,14,AIR)
B(19,3,14,AIR)
B(20,3,14,AIR)
B(21,3,14,AIR)
B(22,3,14,AIR)
B(23,3,14,AIR)
B(1,4,14,AIR)
B(2,4,14,AIR)
B(3,4,14,AIR)
B(4,4,14,AIR)
B(5,4,14,AIR)
B(6,4,14,AIR)
B(7,4,14,AIR)
B(9,4,14,AIR)
B(10,4,14,AIR)
B(11,4,14,AIR)
B(12,4,14,AIR)
B(13,4,14,AIR)
B(14,4,14,AIR)
B(15,4,14,AIR)
B(17,4,14,AIR)
B(18,4,14,AIR)
B(19,4,14,AIR)
B(20,4,14,AIR)
B(21,4,14,AIR)
B(22,4,14,AIR)
B(23,4,14,AIR)
B(1,5,14,AIR)
B(2,5,14,AIR)
B(3,5,14,AIR)
B(4,5,14,AIR)
B(5,5,14,AIR)
B(6,5,14,AIR)
B(7,5,14,AIR)
B(9,5,14,AIR)
B(10,5,14,AIR)
B(11,5,14,AIR)
B(12,5,14,AIR)
B(13,5,14,AIR)
B(14,5,14,AIR)
B(15,5,14,AIR)
B(17,5,14,AIR)
B(18,5,14,AIR)
B(19,5,14,AIR)
B(20,5,14,AIR)
B(21,5,14,AIR)
B(22,5,14,AIR)
